Workbook

Sheet Sheet1
A1: DOCKET NO. | B1: Base Date | C1: ITEM CODE | D1: PROPOSE ERP ITEM NAME | E1: PROPOSE DRUM TYPE | F1: Insulation Screening (Metallic) | G1: RM RATE (Insulation Screening (Metallic)) | H1: Weight (Insulation Screening (Metallic)) | I1: COST(Insulation Screening (Metallic)) | J1: Conductor | K1: RM RATE(Conductor) | L1: WEIGHT(Conductor) | M1: COST(Conductor) | N1: AL ALLOY | O1: RM RATE(Alu Alloy) | P1: WEIGHT(Alu Alloy) | Q1: COST(Alu Alloy) | R1: Insulation Screening (Non-Metallic) | S1: RM RATE(Insulation Screening (Non-Metallic)) | T1: WEIGHT(Insulation Screening (Non-Metallic)) | U1: COST(Insulation Screening (Non-Metallic)) | V1: Insulation | W1: RM RATE(Insulation) | X1: WEIGHT(Insulation) | Y1: COST(Insulation) | Z1: POLY TAPE | AA1: RM RATE (Poly Tape) | AB1: WEIGHT (Poly Tape) | AC1: COST(Poly Tape) | AD1: Inner Sheath | AE1: RM RATE(Inner Sheath) | AF1: WEIGHT(Inner Sheath) | AG1: COST(Inner Sheath) | AH1: Armouring | AI1: RM RATE(Armouring) | AJ1: WEIGHT(Armouring) | AK1: COST(Armouring) | AL1: Outer Sheath | AM1: RM RATE(Outer Sheath) | AN1: WEIGHT(Outer Sheath) | AO1: COST(Outer Sheath) | AP1: FILLER | AQ1: RM RATE(Filler) | AR1: WEIGHT(Filler) | AS1: COST(Filler) | AT1: GREASE | AU1: RM RATE(Grease) | AV1: WEIGHT(Grease) | AW1: COST(Grease) | AX1: Water swellable Tape | AY1: RM RATE(Water swellable Tape) | AZ1: WEIGHT(Water swellable Tape) | BA1: COST(Water swellable Tape) | BB1: Semi conducting Water Swellable tape | BC1: RM RATE(Semi conducting Water Swellable tape) | BD1: WEIGHT(Semi conducting Water Swellable tape) | BE1: COST(Semi conducting Water Swellable tape) | BF1: SEMICON TAPE | BG1: RM RATE(SEMICON TAPE) | BH1: WEIGHT(SEMICON TAPE) | BI1: COST(SEMICON TAPE) | BJ1: GLASS FIBER TAPE | BK1: RM RATE(GLASS FIBER TAPE) | BL1: WEIGHT(GLASS FIBER TAPE) | BM1: COST(GLASS FIBER TAPE) | BN1: COPPER WIRE 0.8 MM | BO1: RM RATE(COPPER WIRE 0.8 MM) | BP1: WEIGHT(COPPER WIRE 0.8 MM) | BQ1: COST(COPPER WIRE 0.8 MM) | BR1: RUBBERIZED COTTON TAPE | BS1: RM RATE(RUBBERIZED COTTON TAPE) | BT1: WEIGHT(RUBBERIZED COTTON TAPE) | BU1: COST(RUBBERIZED COTTON TAPE) | BV1: Water Tight Compound | BW1: RM RATE(Water Tight Compound) | BX1: WEIGHT(Water Tight Compound) | BY1: COST(Water Tight Compound) | BZ1: DRUM COST PER KM | CA1: TOTAL RM COST | CB1: FIRM % | CC1: FIRM VALUE | CD1: MFG% | CE1: MFG VALUE | CF1: PROF% | CG1: PROFIT VALUE | CH1: 1ST EX-WORKS | CI1: Intt % | CJ1: INTT VALUE | CK1: insp% | CL1: INSP VALUE | CM1: EX-WORKS (PER KM) | CN1: FREIGHT PER KM | CO1: PRICE INCLUDING FREIGHT (PER KM) | CP1: GST % | CQ1: GST VALUE | CR1: PRICE INCLUDING GST & FREIGHT (PER KM) | CS1: QTY | CT1: Unit | CU1: TOTAL PRICE OF FULL QTY (INCLUDING FRIGHT & GST) | CV1: DRUM CODE | CW1: DRUM SIZE (FxbXtx Ft) | CX1: PARTY STANDARD LENGTH (MTR)
A2: ENQ-12644-22-23 | B2: 45352 | C2: FA1100002 | D2: 3.5 CORE X 120 SQ. MM. AL/ARD - STRIP (XLPE ) | E2: WOOD | J2: Alumimium | K2: 214 | L2: 1161 | M2: 248454 | P2: 0 | T2: 0 | V2: LT-XLPE | W2: 101.15 | X2: 197 | Y2: 19926.55 | Z2: POLY TAPE | AA2: 118.2 | AB2: 0 | AC2: 0 | AD2: PVC Type ST-2 | AE2: 60.25 | AF2: 111 | AG2: 6687.75 | AH2: Galvanised Steel Flat Strip | AI2: 72.5 | AJ2: 594 | AK2: 43065 | AL2: PVC Type ST-2 | AM2: 60.25 | AN2: 357 | AO2: 21509.25 | AR2: 0 | AV2: 0 | AZ2: 0 | BD2: 0 | BH2: 0 | BL2: 52 | BP2: 0 | BT2: 0 | BX2: 0 | BZ2: 16506.84 | CA2: 356149.39 | CH2: 356149.39 | CM2: 356149.39 | CO2: 356149.39 | CP2: 0.18 | CQ2: 64106.89 | CR2: 420256.28 | CS2: 2.8 | CT2: KMS | CU2: 1176718 | CV2: MD0100021 | CW2: DRUM - 64 X 24 X 32 X 3 | CX2: 500
A3: ENQ-12644-22-23 | B3: 45352 | C3: FA1100006 | D3: 3.5 CORE X 300 SQ. MM. AL/ARD - STRIP (XLPE) | E3: WOOD | J3: Alumimium | K3: 214 | L3: 2835 | M3: 606690 | P3: 0 | T3: 0 | V3: LT-XLPE | W3: 101.15 | X3: 430 | Y3: 43494.5 | AB3: 0 | AD3: PVC Type ST-2 | AE3: 60.25 | AF3: 245 | AG3: 14761.25 | AH3: Galvanised Steel Flat Strip | AI3: 72.5 | AJ3: 914 | AK3: 66265 | AL3: PVC Type ST-2 | AM3: 60.25 | AN3: 698 | AO3: 42054.5 | AR3: 0 | AV3: 0 | AZ3: 0 | BD3: 0 | BH3: 0 | BL3: 0 | BP3: 0 | BT3: 0 | BX3: 0 | BZ3: 43826 | CA3: 817091.25 | CH3: 817091.25 | CM3: 817091.25 | CO3: 817091.25 | CP3: 0.18 | CQ3: 147076.43 | CR3: 964167.68 | CS3: 5 | CT3: KMS | CU3: 4820838 | CV3: MD0100079 | CW3: DRUM - 80 X 35 X 39 X 3 | CX3: 500
A4: ENQ-12644-22-23 | B4: 45352 | C4: FA1100027 | D4: 3.5 CORE X 240 SQ. MM. AL/ARD - STRIP (XLPE) | E4: WOOD | J4: Alumimium | K4: 214 | L4: 2268 | M4: 485352 | P4: 0 | T4: 0 | V4: LT-XLPE | W4: 101.15 | X4: 359 | Y4: 36312.85 | Z4: POLY TAPE | AA4: 118.2 | AB4: 0 | AC4: 0 | AD4: PVC Type ST-2 | AE4: 60.25 | AF4: 175 | AG4: 10543.75 | AH4: Galvanised Steel Flat Strip | AI4: 72.5 | AJ4: 817 | AK4: 59232.5 | AL4: PVC Type ST-2 | AM4: 60.25 | AN4: 579 | AO4: 34884.75 | AR4: 0 | AV4: 0 | AZ4: 0 | BD4: 0 | BH4: 0 | BL4: 43 | BP4: 0 | BT4: 0 | BX4: 0 | BZ4: 18867.25 | CA4: 645193.1 | CH4: 645193.1 | CM4: 645193.1 | CO4: 645193.1 | CP4: 0.18 | CQ4: 116134.76 | CR4: 761327.86 | CS4: 11.5 | CT4: KMS | CU4: 8755270 | CV4: MD0100024 | CW4: DRUM - 70 X 30 X 36 X 3 | CX4: 500
A5: ENQ-12644-22-23 | B5: 45352 | C5: FA0900047 | D5: 3.5 CORE X 50 SQ. MM. AL/ARD - STRIP (XLPE) | E5: WOOD | J5: Alumimium | K5: 214 | L5: 472.5 | M5: 101115 | P5: 0 | T5: 0 | V5: LT-XLPE | W5: 101.15 | X5: 105 | Y5: 10620.75 | AB5: 0 | AD5: PVC Type ST-2 | AE5: 60.25 | AF5: 54 | AG5: 3253.5 | AH5: Galvanised Steel Flat Strip | AI5: 72.5 | AJ5: 401 | AK5: 29072.5 | AL5: PVC Type ST-2 | AM5: 60.25 | AN5: 225 | AO5: 13556.25 | AR5: 0 | AV5: 0 | AZ5: 0 | BD5: 0 | BH5: 0 | BL5: 0 | BP5: 0 | BT5: 0 | BX5: 0 | BZ5: 7317.08 | CA5: 164935.08 | CH5: 164935.08 | CM5: 164935.08 | CO5: 164935.08 | CP5: 0.18 | CQ5: 29688.31 | CR5: 194623.39 | CS5: 12.5 | CT5: KMS | CU5: 2432792 | CV5: MD0100015 | CW5: DRUM - 48 X 20 X 28 X 2.25 - RDSO | CX5: 500
A6: ENQ-12644-22-23 | B6: 45352 | C6: FA1100008 | D6: 3.5 CORE X 70 SQ. MM. AL/ARD - STRIP (XLPE) | E6: WOOD | J6: Alumimium | K6: 214 | L6: 661.5 | M6: 141561 | P6: 0 | T6: 0 | V6: LT-XLPE | W6: 101.15 | X6: 137 | Y6: 13857.55 | AB6: 0 | AD6: PVC Type ST-2 | AE6: 60.25 | AF6: 76 | AG6: 4579 | AH6: Galvanised Steel Flat Strip | AI6: 72.5 | AJ6: 476 | AK6: 34510 | AL6: PVC Type ST-2 | AM6: 60.25 | AN6: 262 | AO6: 15785.5 | AR6: 0 | AV6: 0 | AZ6: 0 | BD6: 0 | BH6: 0 | BL6: 73 | BP6: 0 | BT6: 0 | BX6: 0 | BZ6: 9913.67 | CA6: 220206.72 | CH6: 220206.72 | CM6: 220206.72 | CO6: 220206.72 | CP6: 0.18 | CQ6: 39637.21 | CR6: 259843.93 | CS6: 12.5 | CT6: KMS | CU6: 3248049 | CV6: MD0100017 | CW6: DRUM - 52 X 18 X 36 X 2.5 | CX6: 500
A7: ENQ-12644-22-23 | B7: 45352 | C7: FA1100010 | D7: 3.5 CORE X 95 SQ. MM. AL/ARD - STRIP (XLPE) | E7: WOOD | J7: Alumimium | K7: 214 | L7: 904.5 | M7: 193563 | P7: 0 | T7: 0 | V7: LT-XLPE | W7: 101.15 | X7: 157 | Y7: 15880.55 | AB7: 0 | AD7: PVC Type ST-2 | AE7: 60.25 | AF7: 86 | AG7: 5181.5 | AH7: Galvanised Steel Flat Strip | AI7: 72.5 | AJ7: 535 | AK7: 38787.5 | AL7: PVC Type ST-2 | AM7: 60.25 | AN7: 308 | AO7: 18557 | AR7: 0 | AV7: 0 | AZ7: 0 | BD7: 0 | BH7: 0 | BL7: 0 | BP7: 0 | BT7: 0 | BX7: 0 | BZ7: 12757.48 | CA7: 284727.03 | CH7: 284727.03 | CM7: 284727.03 | CO7: 284727.03 | CP7: 0.18 | CQ7: 51250.87 | CR7: 335977.9 | CS7: 12.5 | CT7: KMS | CU7: 4199724 | CV7: MD0100019 | CW7: DRUM - 54 X 24 X 32 X 3 | CX7: 500
A8: ENQ-12644-22-23 | B8: 45352 | C8: FA1100040 | D8: 3.5 CORE X 150 SQ. MM. AL/ARD - STRIP (XLPE) | E8: WOOD | J8: Alumimium | K8: 214 | L8: 1404 | M8: 300456 | P8: 0 | T8: 0 | V8: LT-XLPE | W8: 101.15 | X8: 244 | Y8: 24680.6 | AB8: 0 | AD8: PVC Type ST-2 | AE8: 60.25 | AF8: 128 | AG8: 7712 | AH8: Galvanised Steel Flat Strip | AI8: 72.5 | AJ8: 625 | AK8: 45312.5 | AL8: FRLSH PVC Type ST-2 | AM8: 91.7 | AN8: 378 | AO8: 34662.6 | AR8: 0 | AV8: 0 | AZ8: 0 | BD8: 0 | BH8: 0 | BL8: 0 | BP8: 0 | BT8: 0 | BX8: 0 | BZ8: 17878.84 | CA8: 430702.54 | CH8: 430702.54 | CM8: 430702.54 | CO8: 430702.54 | CP8: 0.18 | CQ8: 77526.46 | CR8: 508229 | CS8: 12.5 | CT8: KMS | CU8: 6352862 | CV8: MD0100070 | CW8: DRUM - 68 X 24 X 32 X 3 | CX8: 500

Sheet AUTO CALCULATION SHEET (2)
A2: SOUTH BIHAR POWER DISTRIBUTION CO. LTD, PATNA
A4: TENDER SPECIFICATION NO () | B4: 30 /PR/SBPDCL /2024
A5: TENDER DESCRIPTION () | B5: i. 1.1 KV 3.5x 300 Sq mm XLPE Aluminium Conductor, Stranded, armoured UG cable ii. 1.1 KV 3.5x 240 Sq mm XLPE Aluminium Conductor, Stranded, armoured UG cable iii. 1.1 KV 3.5x 150 Sq mm XLPE Aluminium Conductor, Stranded, armoured UG cable iv. 1.1 KV 3.5x 120 Sq mm XLPE Aluminium Conductor, Stranded, armoured UG cable v. 1.1 KV 3.5x 90 Sq mm XLPE Aluminium Conductor, Stranded, armoured UG cable vi. 1.1 KV 3.5x 70 Sq mm XLPE Aluminium Conductor, Stranded, armoured UG cable vii. 1.1 KV 3.5x 50 Sq mm XLPE Aluminium Conductor, Stranded, armoured UG cable
A6: Last Date & Time of Submission () | B6: 03.04.2024 up to 18:00 Hrs.
A7: REVERSE AUCTION | B7: Not Mention.
A8: Price () | B8: Price Variation for 1.1 KV XLPE Aluminium Conductor, Stranded, armoured UG cable shall be applicable as per current IEEMA as applicable on the final date of submission of bid. The price variation shall be limited to the contractual delivery period. In case actual supplies are made beyond the contractual delivery period, the prices prevailing at the time of contractual delivery period or actual date of supply, whichever is less shall be taken
A9: Validity () | B9: The tenderers should specify the validity period of their offer which should be for a minimum period of 180 days from the last date of submission of bid.
A10: Delivery Period () | B10: The material are required to be delivered within 03 (Three) months from the date of issue of Purchase Order as per the following delivery schedule. Within 2 (two) months - at least 40 % of the ordered quantity During 3rd(Third) month - at least 60 % of the ordered quantity
A11: Payment Terms () | B11: 90% payment along with full amount of taxes, duties and freight keeping 10% retention money , on submission of triplicate copy of bills with all relevant documents (Sample check list) enclosed in annexure by the vendor after receipt of the material / equipment in good condition. After successful completion of delivery of entire order or modified quantity as decided during its delivery schedule, 10 % retention money may be released after deduction of penalty. Payment will be released normally within 15 working days from the date of submission of bill along with all required relevant document(s) to Sr. Manager (Finance), NBPDCL/SBPDCL.
A12: Standard length () | B12: The cables shall be supplied in continuous lengths of 1000 m/500 m with 5% tolerance and cable shall on the wooden drums only.
A13: Packing () | B13: The cables, as per specified delivery lengths, shall be securely wound /packed in non-returnable wooden drums, capable of withstanding rough handling during transport by Rail, Road, etc. The packing should withstand storage conditions in open yards. The cable drums shall conform to IS 10418-1982 or equivalent standard.
A14: Technical Specification
N16: =Sheet1!J1 -> Conductor | S16: AL ALLOY | U16: Insulation Screening (Metallic) | AC16: Insulation Screening (Non-Metallic) | AE16: Insulation | AK16: POLY TAPE | AL16: Inner Sheath | AS16: Armouring | BC16: Outer Sheath | BM16: FILLER | BN16: GREASE | BO16: Water swellable Tape | BP16: Semi conducting Water Swellable tape | BQ16: SEMICON TAPE | BR16: GLASS FIBER TAPE | BS16: COPPER WIRE 0.8 MM | BT16: RUBBERIZED COTTON TAPE | BU16: Water Tight Compound | BZ16: DRUM COST PER KM | CA16: TOTAL RM COST | CB16: EXTRA CONSUMPTION | CC16: EXTRA CONSUMPTION VALUE
A17: DOCKET NO. | B17: =Sheet1!B1 -> Base Date | C17: ITEM CODE | D17: PROPOSE ERP ITEM NAME | E17: EX-WORKS (PER KM) | F17: FREIGHT PER KM | G17: PRICE INCLUDING FREIGHT (PER KM) | H17: GST % | I17: GST VALUE | J17: PRICE INCLUDING GST & FREIGHT (PER KM) | K17: QTY | L17: Unit | M17: TOTAL PRICE OF FULL QTY (INCLUDING FRIGHT & GST) | N17: Alumimium | O17: Alumimium ALLOY | P17: Copper | Q17: Flexible Copper | R17: Galvanized steel wire | S17: Alumimium | T17: Alumimium ALLOY | U17: Coper tape - 0.1 mm | V17: Copper Tape - 0.03 mm | W17: Copper Tape - 0.035 mm | X17: Copper Tape - 0.04 mm | Y17: Copper Tape - 0.045 mm | Z17: Copper Tape - 0.050 mm | AA17: Copper Tape - 0.060 mm | AB17: Copper Tape - 0.075 mm(DOUBLE) | AC17: Extruded semiconductive | AD17: Extruded Semiconductive(Stripable) | AE17: HT-XLPE | AF17: LT-XLPE | AG17: TR XLPE | AH17: Type A PVC | AI17: Type C PVC (HR) | AJ17: XLPE | AK17: POLY TAPE | AL17: FR PVC Type ST-1 | AM17: FR PVC Type ST-2 | AN17: FRLSH PVC Type ST-2 | AO17: PVC Type ST-1 | AP17: PVC Type ST-1-PRESSURE EXTRUDED | AQ17: PVC Type ST-2 | AR17: PVC Type ST-2-PRESSURE EXTRUDED | AS17: ACSR CORE WIRE | AT17: ACSR DOG STEEL WIRE | AU17: Aluminium Flat Strip | AV17: Aluminium Round Wire | AW17: Double Steel Tape | AX17: Galvanised Steel Flat Strip | AY17: Galvanised Steel Flat Strip (Double) | AZ17: Galvanised Steel Flat Strip-B | BA17: Galvanised Steel Round Wire | BB17: Galvanised Steel Round Wire (Double) | BC17: FR PVC Type ST-1 | BD17: FR PVC Type ST-2 | BE17: FRLSH PVC Type ST-1 | BF17: FRLSH PVC Type ST-2 | BG17: PE, ST-3 | BH17: PE, ST-7 | BI17: PVC Type ST-1 | BJ17: ATR PVC Type ST-2 | BK17: PVC Type ST-2-PRESSURE EXTRUDED | BL17: UV & Track Resistant XLPE | BM17: FILLER | BN17: Grease | BO17: Water swellable Tape | BP17: Semi conducting Water Swellable tape | BQ17: SEMICON TAPE | BR17: GLASS FIBER TAPE | BS17: COPPER WIRE 0.8 MM | BT17: RUBBERIZED COTTON TAPE | BU17: Water Tight Compound | BV17: =Sheet1!E1 -> PROPOSE DRUM TYPE | BW17: =Sheet1!CV1 -> DRUM CODE | BX17: =Sheet1!CW1 -> DRUM SIZE (FxbXtx Ft) | BY17: =Sheet1!CX1 -> PARTY STANDARD LENGTH (MTR) | BZ17: 1000 rs/drum for special cable end sealing | CD17: MFG% | CE17: MFG VALUE | CF17: PROF% | CG17: PROFIT VALUE | CH17: 1ST EX-WORKS | CI17: Intt % | CJ17: INTT VALUE | CK17: insp% | CL17: INSP VALUE
N18: 216 | O18: =+IFERROR(VLOOKUP($O$17,Sheet1!J:L,2,0),0) -> 0 | P18: =+IFERROR(VLOOKUP($P$17,Sheet1!J:M,2,0),0) -> 0 | Q18: =+IFERROR(VLOOKUP($Q$17,Sheet1!J:M,2,0),0) -> 0 | R18: =+IFERROR(VLOOKUP($R$17,Sheet1!J:M,2,0),0) -> 0 | S18: =+IFERROR(VLOOKUP($S$17,Sheet1!N:Q,2,0),0) -> 0 | T18: =+IFERROR(VLOOKUP($T$17,Sheet1!N:O,2,0),0) -> 0 | U18: =+IFERROR(VLOOKUP($U$17,Sheet1!F:I,2,0),0) -> 0 | V18: =+IFERROR(VLOOKUP($V$17,Sheet1!F:I,2,0),0) -> 0 | W18: =+IFERROR(VLOOKUP($W$17,Sheet1!F:I,2,0),0) -> 0 | X18: =+IFERROR(VLOOKUP($X$17,Sheet1!F:I,2,0),0) -> 0 | Y18: =+IFERROR(VLOOKUP($Y$17,Sheet1!F:I,2,0),0) -> 0 | Z18: =+IFERROR(VLOOKUP($Z$17,Sheet1!F:I,2,0),0) -> 0 | AA18: =+IFERROR(VLOOKUP($AA$17,Sheet1!F:I,2,0),0) -> 0 | AB18: =+IFERROR(VLOOKUP($AB$17,Sheet1!F:I,2,0),0) -> 0 | AC18: =+IFERROR(VLOOKUP($AC$17,Sheet1!R:U,2,0),0) -> 0 | AD18: =+IFERROR(VLOOKUP($AD$17,Sheet1!R:U,2,0),0) -> 0 | AE18: =+IFERROR(VLOOKUP($AE$17,Sheet1!V:Y,2,0),0) -> 0 | AF18: 100 | AG18: =+IFERROR(VLOOKUP($AG$17,Sheet1!V:Y,2,0),0) -> 0 | AH18: =+IFERROR(VLOOKUP($AH$17,Sheet1!V:Y,2,0),0) -> 0 | AI18: =+IFERROR(VLOOKUP($AI$17,Sheet1!V:Y,2,0),0) -> 0 | AJ18: =+IFERROR(VLOOKUP($AJ$17,Sheet1!V:Y,2,0),0) -> 0 | AL18: =+IFERROR(VLOOKUP($AL$17,Sheet1!AD2:AG840,2,0),0) -> 0 | AM18: =+IFERROR(VLOOKUP($AM$17,Sheet1!AD2:AG840,2,0),0) -> 0 | AN18: =+IFERROR(VLOOKUP($AN$17,Sheet1!AD2:AG840,2,0),0) -> 0 | AO18: =+IFERROR(VLOOKUP($AO$17,Sheet1!AD2:AG840,2,0),0) -> 0 | AP18: =+IFERROR(VLOOKUP($AP$17,Sheet1!AD2:AG840,2,0),0) -> 0 | AQ18: 61 | AR18: =+IFERROR(VLOOKUP($AR$17,Sheet1!AD2:AG840,2,0),0) -> 0 | AS18: =+IFERROR(VLOOKUP($AS$17,Sheet1!AH2:AK840,2,0),0) -> 0 | AT18: =+IFERROR(VLOOKUP($AT$17,Sheet1!AH2:AK840,2,0),0) -> 0 | AU18: =+IFERROR(VLOOKUP($AU$17,Sheet1!AH2:AK840,2,0),0) -> 0 | AV18: =+IFERROR(VLOOKUP($AV$17,Sheet1!AH2:AK840,2,0),0) -> 0 | AW18: =+IFERROR(VLOOKUP($AW$17,Sheet1!AH2:AK840,2,0),0) -> 0 | AX18: 72 | AY18: =+IFERROR(VLOOKUP($AY$17,Sheet1!AH2:AK840,2,0),0) -> 0 | AZ18: =+IFERROR(VLOOKUP($AZ$17,Sheet1!AH2:AK840,2,0),0) -> 0 | BA18: =+IFERROR(VLOOKUP($BA$17,Sheet1!AH2:AK840,2,0),0) -> 0 | BB18: =+IFERROR(VLOOKUP($BB$17,Sheet1!AH2:AK840,2,0),0) -> 0 | BC18: =+IFERROR(VLOOKUP($BC$17,Sheet1!AL2:AO840,2,0),0) -> 0 | BD18: =+IFERROR(VLOOKUP($BD$17,Sheet1!AL2:AO840,2,0),0) -> 0 | BE18: =+IFERROR(VLOOKUP($BE$17,Sheet1!AL2:AO840,2,0),0) -> 0 | BG18: =+IFERROR(VLOOKUP($BG$17,Sheet1!AL2:AO840,2,0),0) -> 0 | BH18: =+IFERROR(VLOOKUP($BH$17,Sheet1!AL2:AO840,2,0),0) -> 0 | BI18: =+IFERROR(VLOOKUP($BI$17,Sheet1!AL2:AO840,2,0),0) -> 0 | BJ18: =61+27 -> 88 | BK18: =+IFERROR(VLOOKUP($BK$17,Sheet1!AL2:AO840,2,0),0) -> 0 | BL18: =+IFERROR(VLOOKUP($BL$17,Sheet1!AL2:AO840,2,0),0) -> 0 | BM18: =+IFERROR(VLOOKUP($BM$17,Sheet1!AP2:AS840,2,0),0) -> 0 | BN18: =+IFERROR(VLOOKUP($BN$17,Sheet1!AT2:AW840,2,0),0) -> 0 | BO18: =+IFERROR(VLOOKUP($BO$17,Sheet1!AX2:BA840,2,0),0) -> 0 | BP18: =+IFERROR(VLOOKUP($BP$17,Sheet1!BB2:BE840,2,0),0) -> 0 | BQ18: =+IFERROR(VLOOKUP($BQ$17,Sheet1!BF2:BI840,2,0),0) -> 0 | BR18: =+IFERROR(VLOOKUP($BR$17,Sheet1!BJ2:BM840,2,0),0) -> 0 | BS18: =+IFERROR(VLOOKUP($BS$17,Sheet1!BN2:BQ840,2,0),0) -> 0 | BT18: =+IFERROR(VLOOKUP($BT$17,Sheet1!BR2:BU840,2,0),0) -> 0 | BU18: =+IFERROR(VLOOKUP($BU$17,Sheet1!BV2:BY840,2,0),0) -> 0
A19: =Sheet1!A3 -> ENQ-12644-22-23 | B19: =Sheet1!B3 -> 45352 | C19: =Sheet1!C3 -> FA1100006 | D19: =Sheet1!D3 -> 3.5 CORE X 300 SQ. MM. AL/ARD - STRIP (XLPE) | E19: =CH19+CJ19+CL19 -> 1041160.7 | F19: =ROUNDUP(M29,0) -> 14000 | G19: =E19+F19 -> 1055160.7 | H19: =Sheet1!CP3 -> 0.18 | I19: =G19*H19 -> 189928.92 | J19: =G19+I19 -> 1245089.6 | K19: =Sheet1!CS3 -> 5 | L19: =Sheet1!CT3 -> KMS | M19: =J19*K19 -> 6225447.9 | N19: =+IFERROR(VLOOKUP($N$17,Sheet1!J3:L3,3,0),0) -> 2835 | O19: =+IFERROR(VLOOKUP($O$17,Sheet1!J3:L3,3,0),0) -> 0 | P19: =+IFERROR(VLOOKUP($P$17,Sheet1!J3:M3,3,0),0) -> 0 | Q19: =+IFERROR(VLOOKUP($Q$17,Sheet1!J3:M3,3,0),0) -> 0 | R19: =+IFERROR(VLOOKUP($R$17,Sheet1!J3:M3,3,0),0) -> 0 | S19: =+IFERROR(VLOOKUP($S$17,Sheet1!N3:Q3,3,0),0) -> 0 | T19: =+IFERROR(VLOOKUP($T$17,Sheet1!N3:Q3,3,0),0) -> 0 | U19: =+IFERROR(VLOOKUP($U$17,Sheet1!F3:I3,3,0),0) -> 0 | V19: =+IFERROR(VLOOKUP($V$17,Sheet1!F3:I3,3,0),0) -> 0 | W19: =+IFERROR(VLOOKUP($W$17,Sheet1!F3:I3,3,0),0) -> 0 | X19: =+IFERROR(VLOOKUP($X$17,Sheet1!F3:I3,3,0),0) -> 0 | Y19: =+IFERROR(VLOOKUP($Y$17,Sheet1!F3:I3,3,0),0) -> 0 | Z19: =+IFERROR(VLOOKUP($Z$17,Sheet1!F3:I3,3,0),0) -> 0 | AA19: =+IFERROR(VLOOKUP($AA$17,Sheet1!F3:I3,3,0),0) -> 0 | AB19: =+IFERROR(VLOOKUP($AB$17,Sheet1!F3:I3,3,0),0) -> 0 | AC19: =+IFERROR(VLOOKUP($AC$17,Sheet1!R3:U3,3,0),0) -> 0 | AD19: =+IFERROR(VLOOKUP($AD$17,Sheet1!R3:U3,2,0),0) -> 0 | AE19: =+IFERROR(VLOOKUP($AE$17,Sheet1!V3:Y3,3,0),0) -> 0 | AF19: =+IFERROR(VLOOKUP($AF$17,Sheet1!V3:Y3,3,0),0) -> 430 | AG19: =+IFERROR(VLOOKUP($AG$17,Sheet1!V3:Y3,3,0),0) -> 0 | AH19: =+IFERROR(VLOOKUP($AH$17,Sheet1!V3:Y3,3,0),0) -> 0 | AI19: =+IFERROR(VLOOKUP($AI$17,Sheet1!V3:Y3,3,0),0) -> 0 | AJ19: =+IFERROR(VLOOKUP($AJ$17,Sheet1!V3:Y3,3,0),0) -> 0 | AK19: =+IFERROR(VLOOKUP($AK$17,Sheet1!Z3:AB3,3,0),0) -> 0 | AL19: =+IFERROR(VLOOKUP($AL$17,Sheet1!AD3:AG3,3,0),0) -> 0 | AM19: =+IFERROR(VLOOKUP($AM$17,Sheet1!AD3:AG3,3,0),0) -> 0 | AN19: =+IFERROR(VLOOKUP($AN$17,Sheet1!AD3:AG3,3,0),0) -> 0 | AO19: =+IFERROR(VLOOKUP($AO$17,Sheet1!AD3:AG3,3,0),0) -> 0 | AP19: =+IFERROR(VLOOKUP($AP$17,Sheet1!AD3:AG3,3,0),0) -> 0 | AQ19: =+IFERROR(VLOOKUP($AQ$17,Sheet1!AD3:AG3,3,0),0) -> 245 | AR19: =+IFERROR(VLOOKUP($AR$17,Sheet1!AD3:AG3,3,0),0) -> 0 | AS19: =+IFERROR(VLOOKUP($AS$17,Sheet1!AH3:AK3,3,0),0) -> 0 | AT19: =+IFERROR(VLOOKUP($AT$17,Sheet1!AH3:AK3,3,0),0) -> 0 | AU19: =+IFERROR(VLOOKUP($AU$17,Sheet1!AH3:AK3,3,0),0) -> 0 | AV19: =+IFERROR(VLOOKUP($AV$17,Sheet1!AH3:AK3,3,0),0) -> 0 | AW19: =+IFERROR(VLOOKUP($AW$17,Sheet1!AH3:AK3,3,0),0) -> 0 | AX19: =+IFERROR(VLOOKUP($AX$17,Sheet1!AH3:AK3,3,0),0) -> 914 | AY19: =+IFERROR(VLOOKUP($AY$17,Sheet1!AH3:AK3,3,0),0) -> 0 | AZ19: =+IFERROR(VLOOKUP($AZ$17,Sheet1!AH3:AK3,3,0),0) -> 0 | BA19: =+IFERROR(VLOOKUP($BA$17,Sheet1!AH3:AK3,3,0),0) -> 0 | BB19: =+IFERROR(VLOOKUP($BB$17,Sheet1!AH3:AK3,3,0),0) -> 0 | BC19: =+IFERROR(VLOOKUP($BC$17,Sheet1!AL3:AO3,3,0),0) -> 0 | BD19: =+IFERROR(VLOOKUP($BD$17,Sheet1!AL3:AO3,3,0),0) -> 0 | BE19: =+IFERROR(VLOOKUP($BE$17,Sheet1!AL3:AO3,3,0),0) -> 0 | BF19: =+IFERROR(VLOOKUP($BF$17,Sheet1!AL3:AO3,3,0),0) -> 0 | BG19: =+IFERROR(VLOOKUP($BG$17,Sheet1!AL3:AO3,3,0),0) -> 0 | BH19: =+IFERROR(VLOOKUP($BH$17,Sheet1!AL3:AO3,3,0),0) -> 0 | BI19: =+IFERROR(VLOOKUP($BI$17,Sheet1!AL3:AO3,3,0),0) -> 0 | BJ19: 698 | BK19: =+IFERROR(VLOOKUP($BK$17,Sheet1!AL3:AO3,3,0),0) -> 0 | BL19: =+IFERROR(VLOOKUP($BL$17,Sheet1!AL3:AO3,3,0),0) -> 0 | BM19: =+IFERROR(VLOOKUP($BM$17,Sheet1!AP3:AS3,3,0),0) -> 0 | BN19: =+IFERROR(VLOOKUP($BN$17,Sheet1!AT3:AW3,3,0),0) -> 0 | BO19: =+IFERROR(VLOOKUP($BO$17,Sheet1!AX3:BA3,3,0),0) -> 0 | BP19: =+IFERROR(VLOOKUP($BP$17,Sheet1!BB3:BE3,3,0),0) -> 0 | BQ19: =+IFERROR(VLOOKUP($BQ$17,Sheet1!BF3:BI3,3,0),0) -> 0 | BR19: =+IFERROR(VLOOKUP($BR$17,Sheet1!BJ3:BM3,3,0),0) -> 0 | BS19: =+IFERROR(VLOOKUP($BS$17,Sheet1!BN3:BQ3,3,0),0) -> 0 | BT19: =+IFERROR(VLOOKUP($BT$17,Sheet1!BR3:BU3,3,0),0) -> 0 | BU19: =+IFERROR(VLOOKUP($BU$17,Sheet1!BV3:BY3,3,0),0) -> 0 | BV19: =Sheet1!E3 -> WOOD | BW19: =Sheet1!CV3 -> MD0100079 | BX19: =Sheet1!CW3 -> DRUM - 80 X 35 X 39 X 3 | BY19: =Sheet1!CX3 -> 500 | BZ19: =Sheet1!BZ3+1000 -> 44826 | CA19: =SUMPRODUCT($N$18:$BU$18,N19:BU19)+BZ19 -> 842363 | CB19: =Sheet1!CB3 -> 0 | CC19: =CA19*CB19 -> 0 | CD19: 0.2 | CE19: =CA19*CD19 -> 168472.6 | CF19: 0 | CG19: =CA19*CF19 -> 0 | CH19: =CA19+CC19+CE19+CG19 -> 1010835.6 | CI19: 0.02 | CJ19: =CH19*CI19 -> 20216.712 | CK19: 0.01 | CL19: =CH19*CK19 -> 10108.356
A20: =Sheet1!A4 -> ENQ-12644-22-23 | B20: =Sheet1!B4 -> 45352 | C20: =Sheet1!C4 -> FA1100027 | D20: =Sheet1!D4 -> 3.5 CORE X 240 SQ. MM. AL/ARD - STRIP (XLPE) | E20: =CH20+CJ20+CL20 -> 823307.33 | F20: =ROUNDUP(M30,0) -> 11667 | G20: =E20+F20 -> 834974.33 | H20: =Sheet1!CP4 -> 0.18 | I20: =G20*H20 -> 150295.38 | J20: =G20+I20 -> 985269.7 | K20: 12 | L20: =Sheet1!CT4 -> KMS | M20: =J20*K20 -> 11823236 | N20: =+IFERROR(VLOOKUP($N$17,Sheet1!J4:L4,3,0),0) -> 2268 | O20: =+IFERROR(VLOOKUP($O$17,Sheet1!J4:L4,3,0),0) -> 0 | P20: =+IFERROR(VLOOKUP($P$17,Sheet1!J4:M4,3,0),0) -> 0 | Q20: =+IFERROR(VLOOKUP($Q$17,Sheet1!J4:M4,3,0),0) -> 0 | R20: =+IFERROR(VLOOKUP($R$17,Sheet1!J4:M4,3,0),0) -> 0 | S20: =+IFERROR(VLOOKUP($S$17,Sheet1!N4:Q4,3,0),0) -> 0 | T20: =+IFERROR(VLOOKUP($T$17,Sheet1!N4:Q4,3,0),0) -> 0 | U20: =+IFERROR(VLOOKUP($U$17,Sheet1!F4:I4,3,0),0) -> 0 | V20: =+IFERROR(VLOOKUP($V$17,Sheet1!F4:I4,3,0),0) -> 0 | W20: =+IFERROR(VLOOKUP($W$17,Sheet1!F4:I4,3,0),0) -> 0 | X20: =+IFERROR(VLOOKUP($X$17,Sheet1!F4:I4,3,0),0) -> 0 | Y20: =+IFERROR(VLOOKUP($Y$17,Sheet1!F4:I4,3,0),0) -> 0 | Z20: =+IFERROR(VLOOKUP($Z$17,Sheet1!F4:I4,3,0),0) -> 0 | AA20: =+IFERROR(VLOOKUP($AA$17,Sheet1!F4:I4,3,0),0) -> 0 | AB20: =+IFERROR(VLOOKUP($AB$17,Sheet1!F4:I4,3,0),0) -> 0 | AC20: =+IFERROR(VLOOKUP($AC$17,Sheet1!R4:U4,3,0),0) -> 0 | AD20: =+IFERROR(VLOOKUP($AD$17,Sheet1!R4:U4,2,0),0) -> 0 | AE20: =+IFERROR(VLOOKUP($AE$17,Sheet1!V4:Y4,3,0),0) -> 0 | AF20: =+IFERROR(VLOOKUP($AF$17,Sheet1!V4:Y4,3,0),0) -> 359 | AG20: =+IFERROR(VLOOKUP($AG$17,Sheet1!V4:Y4,3,0),0) -> 0 | AH20: =+IFERROR(VLOOKUP($AH$17,Sheet1!V4:Y4,3,0),0) -> 0 | AI20: =+IFERROR(VLOOKUP($AI$17,Sheet1!V4:Y4,3,0),0) -> 0 | AJ20: =+IFERROR(VLOOKUP($AJ$17,Sheet1!V4:Y4,3,0),0) -> 0 | AK20: =+IFERROR(VLOOKUP($AK$17,Sheet1!Z4:AB4,3,0),0) -> 0 | AL20: =+IFERROR(VLOOKUP($AL$17,Sheet1!AD4:AG4,3,0),0) -> 0 | AM20: =+IFERROR(VLOOKUP($AM$17,Sheet1!AD4:AG4,3,0),0) -> 0 | AN20: =+IFERROR(VLOOKUP($AN$17,Sheet1!AD4:AG4,3,0),0) -> 0 | AO20: =+IFERROR(VLOOKUP($AO$17,Sheet1!AD4:AG4,3,0),0) -> 0 | AP20: =+IFERROR(VLOOKUP($AP$17,Sheet1!AD4:AG4,3,0),0) -> 0 | AQ20: =+IFERROR(VLOOKUP($AQ$17,Sheet1!AD4:AG4,3,0),0) -> 175 | AR20: =+IFERROR(VLOOKUP($AR$17,Sheet1!AD4:AG4,3,0),0) -> 0 | AS20: =+IFERROR(VLOOKUP($AS$17,Sheet1!AH4:AK4,3,0),0) -> 0 | AT20: =+IFERROR(VLOOKUP($AT$17,Sheet1!AH4:AK4,3,0),0) -> 0 | AU20: =+IFERROR(VLOOKUP($AU$17,Sheet1!AH4:AK4,3,0),0) -> 0 | AV20: =+IFERROR(VLOOKUP($AV$17,Sheet1!AH4:AK4,3,0),0) -> 0 | AW20: =+IFERROR(VLOOKUP($AW$17,Sheet1!AH4:AK4,3,0),0) -> 0 | AX20: =+IFERROR(VLOOKUP($AX$17,Sheet1!AH4:AK4,3,0),0) -> 817 | AY20: =+IFERROR(VLOOKUP($AY$17,Sheet1!AH4:AK4,3,0),0) -> 0 | AZ20: =+IFERROR(VLOOKUP($AZ$17,Sheet1!AH4:AK4,3,0),0) -> 0 | BA20: =+IFERROR(VLOOKUP($BA$17,Sheet1!AH4:AK4,3,0),0) -> 0 | BB20: =+IFERROR(VLOOKUP($BB$17,Sheet1!AH4:AK4,3,0),0) -> 0 | BC20: =+IFERROR(VLOOKUP($BC$17,Sheet1!AL4:AO4,3,0),0) -> 0 | BD20: =+IFERROR(VLOOKUP($BD$17,Sheet1!AL4:AO4,3,0),0) -> 0 | BE20: =+IFERROR(VLOOKUP($BE$17,Sheet1!AL4:AO4,3,0),0) -> 0 | BF20: =+IFERROR(VLOOKUP($BF$17,Sheet1!AL4:AO4,3,0),0) -> 0 | BG20: =+IFERROR(VLOOKUP($BG$17,Sheet1!AL4:AO4,3,0),0) -> 0 | BH20: =+IFERROR(VLOOKUP($BH$17,Sheet1!AL4:AO4,3,0),0) -> 0 | BI20: =+IFERROR(VLOOKUP($BI$17,Sheet1!AL4:AO4,3,0),0) -> 0 | BJ20: 579 | BK20: =+IFERROR(VLOOKUP($BK$17,Sheet1!AL4:AO4,3,0),0) -> 0 | BL20: =+IFERROR(VLOOKUP($BL$17,Sheet1!AL4:AO4,3,0),0) -> 0 | BM20: =+IFERROR(VLOOKUP($BM$17,Sheet1!AP4:AS4,3,0),0) -> 0 | BN20: =+IFERROR(VLOOKUP($BN$17,Sheet1!AT4:AW4,3,0),0) -> 0 | BO20: =+IFERROR(VLOOKUP($BO$17,Sheet1!AX4:BA4,3,0),0) -> 0 | BP20: =+IFERROR(VLOOKUP($BP$17,Sheet1!BB4:BE4,3,0),0) -> 0 | BQ20: =+IFERROR(VLOOKUP($BQ$17,Sheet1!BF4:BI4,3,0),0) -> 0 | BR20: =+IFERROR(VLOOKUP($BR$17,Sheet1!BJ4:BM4,3,0),0) -> 0 | BS20: =+IFERROR(VLOOKUP($BS$17,Sheet1!BN4:BQ4,3,0),0) -> 0 | BT20: =+IFERROR(VLOOKUP($BT$17,Sheet1!BR4:BU4,3,0),0) -> 0 | BU20: =+IFERROR(VLOOKUP($BU$17,Sheet1!BV4:BY4,3,0),0) -> 0 | BV20: =Sheet1!E4 -> WOOD | BW20: =Sheet1!CV4 -> MD0100024 | BX20: =Sheet1!CW4 -> DRUM - 70 X 30 X 36 X 3 | BY20: =Sheet1!CX4 -> 500 | BZ20: =Sheet1!BZ4+1000 -> 19867.25 | CA20: =SUMPRODUCT($N$18:$BU$18,N20:BU20)+BZ20 -> 666106.25 | CB20: =Sheet1!CB4 -> 0 | CC20: =CA20*CB20 -> 0 | CD20: 0.2 | CE20: =CA20*CD20 -> 133221.25 | CF20: 0 | CG20: =CA20*CF20 -> 0 | CH20: =CA20+CC20+CE20+CG20 -> 799327.5 | CI20: 0.02 | CJ20: =CH20*CI20 -> 15986.55 | CK20: 0.01 | CL20: =CH20*CK20 -> 7993.275
A21: =Sheet1!A8 -> ENQ-12644-22-23 | B21: =Sheet1!B8 -> 45352 | C21: =Sheet1!C8 -> FA1100040 | D21: =Sheet1!D8 -> 3.5 CORE X 150 SQ. MM. AL/ARD - STRIP (XLPE) | E21: =CH21+CJ21+CL21 -> 534711.94 | F21: =ROUNDUP(M31,0) -> 8750 | G21: =E21+F21 -> 543461.94 | H21: =Sheet1!CP8 -> 0.18 | I21: =G21*H21 -> 97823.15 | J21: =G21+I21 -> 641285.09 | K21: 12 | L21: =Sheet1!CT8 -> KMS | M21: =J21*K21 -> 7695421.1 | N21: =+IFERROR(VLOOKUP($N$17,Sheet1!J8:L8,3,0),0) -> 1404 | O21: =+IFERROR(VLOOKUP($O$17,Sheet1!J8:L8,3,0),0) -> 0 | P21: =+IFERROR(VLOOKUP($P$17,Sheet1!J8:M8,3,0),0) -> 0 | Q21: =+IFERROR(VLOOKUP($Q$17,Sheet1!J8:M8,3,0),0) -> 0 | R21: =+IFERROR(VLOOKUP($R$17,Sheet1!J8:M8,3,0),0) -> 0 | S21: =+IFERROR(VLOOKUP($S$17,Sheet1!N8:Q8,3,0),0) -> 0 | T21: =+IFERROR(VLOOKUP($T$17,Sheet1!N8:Q8,3,0),0) -> 0 | U21: =+IFERROR(VLOOKUP($U$17,Sheet1!F8:I8,3,0),0) -> 0 | V21: =+IFERROR(VLOOKUP($V$17,Sheet1!F8:I8,3,0),0) -> 0 | W21: =+IFERROR(VLOOKUP($W$17,Sheet1!F8:I8,3,0),0) -> 0 | X21: =+IFERROR(VLOOKUP($X$17,Sheet1!F8:I8,3,0),0) -> 0 | Y21: =+IFERROR(VLOOKUP($Y$17,Sheet1!F8:I8,3,0),0) -> 0 | Z21: =+IFERROR(VLOOKUP($Z$17,Sheet1!F8:I8,3,0),0) -> 0 | AA21: =+IFERROR(VLOOKUP($AA$17,Sheet1!F8:I8,3,0),0) -> 0 | AB21: =+IFERROR(VLOOKUP($AB$17,Sheet1!F8:I8,3,0),0) -> 0 | AC21: =+IFERROR(VLOOKUP($AC$17,Sheet1!R8:U8,3,0),0) -> 0 | AD21: =+IFERROR(VLOOKUP($AD$17,Sheet1!R8:U8,2,0),0) -> 0 | AE21: =+IFERROR(VLOOKUP($AE$17,Sheet1!V8:Y8,3,0),0) -> 0 | AF21: =+IFERROR(VLOOKUP($AF$17,Sheet1!V8:Y8,3,0),0) -> 244 | AG21: =+IFERROR(VLOOKUP($AG$17,Sheet1!V8:Y8,3,0),0) -> 0 | AH21: =+IFERROR(VLOOKUP($AH$17,Sheet1!V8:Y8,3,0),0) -> 0 | AI21: =+IFERROR(VLOOKUP($AI$17,Sheet1!V8:Y8,3,0),0) -> 0 | AJ21: =+IFERROR(VLOOKUP($AJ$17,Sheet1!V8:Y8,3,0),0) -> 0 | AK21: =+IFERROR(VLOOKUP($AK$17,Sheet1!Z8:AB8,3,0),0) -> 0 | AL21: =+IFERROR(VLOOKUP($AL$17,Sheet1!AD8:AG8,3,0),0) -> 0 | AM21: =+IFERROR(VLOOKUP($AM$17,Sheet1!AD8:AG8,3,0),0) -> 0 | AN21: =+IFERROR(VLOOKUP($AN$17,Sheet1!AD8:AG8,3,0),0) -> 0 | AO21: =+IFERROR(VLOOKUP($AO$17,Sheet1!AD8:AG8,3,0),0) -> 0 | AP21: =+IFERROR(VLOOKUP($AP$17,Sheet1!AD8:AG8,3,0),0) -> 0 | AQ21: =+IFERROR(VLOOKUP($AQ$17,Sheet1!AD8:AG8,3,0),0) -> 128 | AR21: =+IFERROR(VLOOKUP($AR$17,Sheet1!AD8:AG8,3,0),0) -> 0 | AS21: =+IFERROR(VLOOKUP($AS$17,Sheet1!AH8:AK8,3,0),0) -> 0 | AT21: =+IFERROR(VLOOKUP($AT$17,Sheet1!AH8:AK8,3,0),0) -> 0 | AU21: =+IFERROR(VLOOKUP($AU$17,Sheet1!AH8:AK8,3,0),0) -> 0 | AV21: =+IFERROR(VLOOKUP($AV$17,Sheet1!AH8:AK8,3,0),0) -> 0 | AW21: =+IFERROR(VLOOKUP($AW$17,Sheet1!AH8:AK8,3,0),0) -> 0 | AX21: =+IFERROR(VLOOKUP($AX$17,Sheet1!AH8:AK8,3,0),0) -> 625 | AY21: =+IFERROR(VLOOKUP($AY$17,Sheet1!AH8:AK8,3,0),0) -> 0 | AZ21: =+IFERROR(VLOOKUP($AZ$17,Sheet1!AH8:AK8,3,0),0) -> 0 | BA21: =+IFERROR(VLOOKUP($BA$17,Sheet1!AH8:AK8,3,0),0) -> 0 | BB21: =+IFERROR(VLOOKUP($BB$17,Sheet1!AH8:AK8,3,0),0) -> 0 | BC21: =+IFERROR(VLOOKUP($BC$17,Sheet1!AL8:AO8,3,0),0) -> 0 | BD21: =+IFERROR(VLOOKUP($BD$17,Sheet1!AL8:AO8,3,0),0) -> 0 | BE21: =+IFERROR(VLOOKUP($BE$17,Sheet1!AL8:AO8,3,0),0) -> 0 | BF21: 0 | BG21: =+IFERROR(VLOOKUP($BG$17,Sheet1!AL8:AO8,3,0),0) -> 0 | BH21: =+IFERROR(VLOOKUP($BH$17,Sheet1!AL8:AO8,3,0),0) -> 0 | BI21: =+IFERROR(VLOOKUP($BI$17,Sheet1!AL8:AO8,3,0),0) -> 0 | BJ21: 378 | BK21: =+IFERROR(VLOOKUP($BK$17,Sheet1!AL8:AO8,3,0),0) -> 0 | BL21: =+IFERROR(VLOOKUP($BL$17,Sheet1!AL8:AO8,3,0),0) -> 0 | BM21: =+IFERROR(VLOOKUP($BM$17,Sheet1!AP8:AS8,3,0),0) -> 0 | BN21: =+IFERROR(VLOOKUP($BN$17,Sheet1!AT8:AW8,3,0),0) -> 0 | BO21: =+IFERROR(VLOOKUP($BO$17,Sheet1!AX8:BA8,3,0),0) -> 0 | BP21: =+IFERROR(VLOOKUP($BP$17,Sheet1!BB8:BE8,3,0),0) -> 0 | BQ21: =+IFERROR(VLOOKUP($BQ$17,Sheet1!BF8:BI8,3,0),0) -> 0 | BR21: =+IFERROR(VLOOKUP($BR$17,Sheet1!BJ8:BM8,3,0),0) -> 0 | BS21: =+IFERROR(VLOOKUP($BS$17,Sheet1!BN8:BQ8,3,0),0) -> 0 | BT21: =+IFERROR(VLOOKUP($BT$17,Sheet1!BR8:BU8,3,0),0) -> 0 | BU21: =+IFERROR(VLOOKUP($BU$17,Sheet1!BV8:BY8,3,0),0) -> 0 | BV21: =Sheet1!E8 -> WOOD | BW21: =Sheet1!CV8 -> MD0100070 | BX21: =Sheet1!CW8 -> DRUM - 68 X 24 X 32 X 3 | BY21: =Sheet1!CX8 -> 500 | BZ21: =Sheet1!BZ8+1000 -> 18878.84 | CA21: =SUMPRODUCT($N$18:$BU$18,N21:BU21)+BZ21 -> 432614.84 | CB21: =Sheet1!CB8 -> 0 | CC21: =CA21*CB21 -> 0 | CD21: 0.2 | CE21: =CA21*CD21 -> 86522.968 | CF21: 0 | CG21: =CA21*CF21 -> 0 | CH21: =CA21+CC21+CE21+CG21 -> 519137.81 | CI21: 0.02 | CJ21: =CH21*CI21 -> 10382.756 | CK21: 0.01 | CL21: =CH21*CK21 -> 5191.3781
A22: =Sheet1!A2 -> ENQ-12644-22-23 | B22: =Sheet1!B2 -> 45352 | C22: =Sheet1!C2 -> FA1100002 | D22: =Sheet1!D2 -> 3.5 CORE X 120 SQ. MM. AL/ARD - STRIP (XLPE ) | E22: =CH22+CJ22+CL22 -> 456007.17 | F22: =ROUNDUP(M32,0) -> 12412 | G22: =E22+F22 -> 468419.17 | H22: =Sheet1!CP2 -> 0.18 | I22: =G22*H22 -> 84315.451 | J22: =G22+I22 -> 552734.62 | K22: 2.82 | L22: =Sheet1!CT2 -> KMS | M22: =J22*K22 -> 1558711.6 | N22: =+IFERROR(VLOOKUP($N$17,Sheet1!J2:L2,3,0),0) -> 1161 | O22: =+IFERROR(VLOOKUP($O$17,Sheet1!J2:L2,3,0),0) -> 0 | P22: =+IFERROR(VLOOKUP($P$17,Sheet1!J2:M2,3,0),0) -> 0 | Q22: =+IFERROR(VLOOKUP($Q$17,Sheet1!J2:M2,3,0),0) -> 0 | R22: =+IFERROR(VLOOKUP($R$17,Sheet1!J2:M2,3,0),0) -> 0 | S22: =+IFERROR(VLOOKUP($S$17,Sheet1!N2:Q2,3,0),0) -> 0 | T22: =+IFERROR(VLOOKUP($T$17,Sheet1!N2:Q2,3,0),0) -> 0 | U22: =+IFERROR(VLOOKUP($U$17,Sheet1!F2:I2,3,0),0) -> 0 | V22: =+IFERROR(VLOOKUP($V$17,Sheet1!F2:I2,3,0),0) -> 0 | W22: =+IFERROR(VLOOKUP($W$17,Sheet1!F2:I2,3,0),0) -> 0 | X22: =+IFERROR(VLOOKUP($X$17,Sheet1!F2:I2,3,0),0) -> 0 | Y22: =+IFERROR(VLOOKUP($Y$17,Sheet1!F2:I2,3,0),0) -> 0 | Z22: =+IFERROR(VLOOKUP($Z$17,Sheet1!F2:I2,3,0),0) -> 0 | AA22: =+IFERROR(VLOOKUP($AA$17,Sheet1!F2:I2,3,0),0) -> 0 | AB22: =+IFERROR(VLOOKUP($AB$17,Sheet1!F2:I2,3,0),0) -> 0 | AC22: =+IFERROR(VLOOKUP($AC$17,Sheet1!R2:U2,3,0),0) -> 0 | AD22: =+IFERROR(VLOOKUP($AD$17,Sheet1!R2:U2,2,0),0) -> 0 | AE22: =+IFERROR(VLOOKUP($AE$17,Sheet1!V2:Y2,3,0),0) -> 0 | AF22: =+IFERROR(VLOOKUP($AF$17,Sheet1!V2:Y2,3,0),0) -> 197 | AG22: =+IFERROR(VLOOKUP($AG$17,Sheet1!V2:Y2,3,0),0) -> 0 | AH22: =+IFERROR(VLOOKUP($AH$17,Sheet1!V2:Y2,3,0),0) -> 0 | AI22: =+IFERROR(VLOOKUP($AI$17,Sheet1!V2:Y2,3,0),0) -> 0 | AJ22: =+IFERROR(VLOOKUP($AJ$17,Sheet1!V2:Y2,3,0),0) -> 0 | AK22: =+IFERROR(VLOOKUP($AK$17,Sheet1!Z2:AB2,3,0),0) -> 0 | AL22: =+IFERROR(VLOOKUP($AL$17,Sheet1!AD2:AG2,3,0),0) -> 0 | AM22: =+IFERROR(VLOOKUP($AM$17,Sheet1!AD2:AG2,3,0),0) -> 0 | AN22: =+IFERROR(VLOOKUP($AN$17,Sheet1!AD2:AG2,3,0),0) -> 0 | AO22: =+IFERROR(VLOOKUP($AO$17,Sheet1!AD2:AG2,3,0),0) -> 0 | AP22: =+IFERROR(VLOOKUP($AP$17,Sheet1!AD2:AG2,3,0),0) -> 0 | AQ22: =+IFERROR(VLOOKUP($AQ$17,Sheet1!AD2:AG2,3,0),0) -> 111 | AR22: =+IFERROR(VLOOKUP($AR$17,Sheet1!AD2:AG2,3,0),0) -> 0 | AS22: =+IFERROR(VLOOKUP($AS$17,Sheet1!AH2:AK2,3,0),0) -> 0 | AT22: =+IFERROR(VLOOKUP($AT$17,Sheet1!AH2:AK2,3,0),0) -> 0 | AU22: =+IFERROR(VLOOKUP($AU$17,Sheet1!AH2:AK2,3,0),0) -> 0 | AV22: =+IFERROR(VLOOKUP($AV$17,Sheet1!AH2:AK2,3,0),0) -> 0 | AW22: =+IFERROR(VLOOKUP($AW$17,Sheet1!AH2:AK2,3,0),0) -> 0 | AX22: =+IFERROR(VLOOKUP($AX$17,Sheet1!AH2:AK2,3,0),0) -> 594 | AY22: =+IFERROR(VLOOKUP($AY$17,Sheet1!AH2:AK2,3,0),0) -> 0 | AZ22: =+IFERROR(VLOOKUP($AZ$17,Sheet1!AH2:AK2,3,0),0) -> 0 | BA22: =+IFERROR(VLOOKUP($BA$17,Sheet1!AH2:AK2,3,0),0) -> 0 | BB22: =+IFERROR(VLOOKUP($BB$17,Sheet1!AH2:AK2,3,0),0) -> 0 | BC22: =+IFERROR(VLOOKUP($BC$17,Sheet1!AL2:AO2,3,0),0) -> 0 | BD22: =+IFERROR(VLOOKUP($BD$17,Sheet1!AL2:AO2,3,0),0) -> 0 | BE22: =+IFERROR(VLOOKUP($BE$17,Sheet1!AL2:AO2,3,0),0) -> 0 | BF22: 0 | BG22: =+IFERROR(VLOOKUP($BG$17,Sheet1!AL2:AO2,3,0),0) -> 0 | BH22: =+IFERROR(VLOOKUP($BH$17,Sheet1!AL2:AO2,3,0),0) -> 0 | BI22: =+IFERROR(VLOOKUP($BI$17,Sheet1!AL2:AO2,3,0),0) -> 0 | BJ22: 357 | BK22: =+IFERROR(VLOOKUP($BK$17,Sheet1!AL2:AO2,3,0),0) -> 0 | BL22: =+IFERROR(VLOOKUP($BL$17,Sheet1!AL2:AO2,3,0),0) -> 0 | BM22: =+IFERROR(VLOOKUP($BM$17,Sheet1!AP2:AS2,3,0),0) -> 0 | BN22: =+IFERROR(VLOOKUP($BN$17,Sheet1!AT2:AW2,3,0),0) -> 0 | BO22: =+IFERROR(VLOOKUP($BO$17,Sheet1!AX2:BA2,3,0),0) -> 0 | BP22: =+IFERROR(VLOOKUP($BP$17,Sheet1!BB2:BE2,3,0),0) -> 0 | BQ22: =+IFERROR(VLOOKUP($BQ$17,Sheet1!BF2:BI2,3,0),0) -> 0 | BR22: =+IFERROR(VLOOKUP($BR$17,Sheet1!BJ2:BM2,3,0),0) -> 0 | BS22: =+IFERROR(VLOOKUP($BS$17,Sheet1!BN2:BQ2,3,0),0) -> 0 | BT22: =+IFERROR(VLOOKUP($BT$17,Sheet1!BR2:BU2,3,0),0) -> 0 | BU22: =+IFERROR(VLOOKUP($BU$17,Sheet1!BV2:BY2,3,0),0) -> 0 | BV22: =Sheet1!E2 -> WOOD | BW22: =Sheet1!CV2 -> MD0100021 | BX22: =Sheet1!CW2 -> DRUM - 64 X 24 X 32 X 3 | BY22: =Sheet1!CX2 -> 500 | BZ22: =Sheet1!BZ2+1000 -> 17506.84 | CA22: =SUMPRODUCT($N$18:$BU$18,N22:BU22)+BZ22 -> 368937.84 | CB22: =Sheet1!CB2 -> 0 | CC22: =CA22*CB22 -> 0 | CD22: 0.2 | CE22: =CA22*CD22 -> 73787.568 | CF22: 0 | CG22: =CA22*CF22 -> 0 | CH22: =CA22+CC22+CE22+CG22 -> 442725.41 | CI22: 0.02 | CJ22: =CH22*CI22 -> 8854.5082 | CK22: 0.01 | CL22: =CH22*CK22 -> 4427.2541
A23: =Sheet1!A7 -> ENQ-12644-22-23 | B23: =Sheet1!B7 -> 45352 | C23: =Sheet1!C7 -> FA1100010 | D23: =Sheet1!D7 -> 3.5 CORE X 95 SQ. MM. AL/ARD - STRIP (XLPE) | E23: =CH23+CJ23+CL23 -> 365484.56 | F23: =ROUNDUP(M33,0) -> 8750 | G23: =E23+F23 -> 374234.56 | H23: =Sheet1!CP7 -> 0.18 | I23: =G23*H23 -> 67362.22 | J23: =G23+I23 -> 441596.78 | K23: 12 | L23: =Sheet1!CT7 -> KMS | M23: =J23*K23 -> 5299161.3 | N23: =+IFERROR(VLOOKUP($N$17,Sheet1!J7:L7,3,0),0) -> 904.5 | O23: =+IFERROR(VLOOKUP($O$17,Sheet1!J7:L7,3,0),0) -> 0 | P23: =+IFERROR(VLOOKUP($P$17,Sheet1!J7:M7,3,0),0) -> 0 | Q23: =+IFERROR(VLOOKUP($Q$17,Sheet1!J7:M7,3,0),0) -> 0 | R23: =+IFERROR(VLOOKUP($R$17,Sheet1!J7:M7,3,0),0) -> 0 | S23: =+IFERROR(VLOOKUP($S$17,Sheet1!N7:Q7,3,0),0) -> 0 | T23: =+IFERROR(VLOOKUP($T$17,Sheet1!N7:Q7,3,0),0) -> 0 | U23: =+IFERROR(VLOOKUP($U$17,Sheet1!F7:I7,3,0),0) -> 0 | V23: =+IFERROR(VLOOKUP($V$17,Sheet1!F7:I7,3,0),0) -> 0 | W23: =+IFERROR(VLOOKUP($W$17,Sheet1!F7:I7,3,0),0) -> 0 | X23: =+IFERROR(VLOOKUP($X$17,Sheet1!F7:I7,3,0),0) -> 0 | Y23: =+IFERROR(VLOOKUP($Y$17,Sheet1!F7:I7,3,0),0) -> 0 | Z23: =+IFERROR(VLOOKUP($Z$17,Sheet1!F7:I7,3,0),0) -> 0 | AA23: =+IFERROR(VLOOKUP($AA$17,Sheet1!F7:I7,3,0),0) -> 0 | AB23: =+IFERROR(VLOOKUP($AB$17,Sheet1!F7:I7,3,0),0) -> 0 | AC23: =+IFERROR(VLOOKUP($AC$17,Sheet1!R7:U7,3,0),0) -> 0 | AD23: =+IFERROR(VLOOKUP($AD$17,Sheet1!R7:U7,2,0),0) -> 0 | AE23: =+IFERROR(VLOOKUP($AE$17,Sheet1!V7:Y7,3,0),0) -> 0 | AF23: =+IFERROR(VLOOKUP($AF$17,Sheet1!V7:Y7,3,0),0) -> 157 | AG23: =+IFERROR(VLOOKUP($AG$17,Sheet1!V7:Y7,3,0),0) -> 0 | AH23: =+IFERROR(VLOOKUP($AH$17,Sheet1!V7:Y7,3,0),0) -> 0 | AI23: =+IFERROR(VLOOKUP($AI$17,Sheet1!V7:Y7,3,0),0) -> 0 | AJ23: =+IFERROR(VLOOKUP($AJ$17,Sheet1!V7:Y7,3,0),0) -> 0 | AK23: =+IFERROR(VLOOKUP($AK$17,Sheet1!Z7:AB7,3,0),0) -> 0 | AL23: =+IFERROR(VLOOKUP($AL$17,Sheet1!AD7:AG7,3,0),0) -> 0 | AM23: =+IFERROR(VLOOKUP($AM$17,Sheet1!AD7:AG7,3,0),0) -> 0 | AN23: =+IFERROR(VLOOKUP($AN$17,Sheet1!AD7:AG7,3,0),0) -> 0 | AO23: =+IFERROR(VLOOKUP($AO$17,Sheet1!AD7:AG7,3,0),0) -> 0 | AP23: =+IFERROR(VLOOKUP($AP$17,Sheet1!AD7:AG7,3,0),0) -> 0 | AQ23: =+IFERROR(VLOOKUP($AQ$17,Sheet1!AD7:AG7,3,0),0) -> 86 | AR23: =+IFERROR(VLOOKUP($AR$17,Sheet1!AD7:AG7,3,0),0) -> 0 | AS23: =+IFERROR(VLOOKUP($AS$17,Sheet1!AH7:AK7,3,0),0) -> 0 | AT23: =+IFERROR(VLOOKUP($AT$17,Sheet1!AH7:AK7,3,0),0) -> 0 | AU23: =+IFERROR(VLOOKUP($AU$17,Sheet1!AH7:AK7,3,0),0) -> 0 | AV23: =+IFERROR(VLOOKUP($AV$17,Sheet1!AH7:AK7,3,0),0) -> 0 | AW23: =+IFERROR(VLOOKUP($AW$17,Sheet1!AH7:AK7,3,0),0) -> 0 | AX23: =+IFERROR(VLOOKUP($AX$17,Sheet1!AH7:AK7,3,0),0) -> 535 | AY23: =+IFERROR(VLOOKUP($AY$17,Sheet1!AH7:AK7,3,0),0) -> 0 | AZ23: =+IFERROR(VLOOKUP($AZ$17,Sheet1!AH7:AK7,3,0),0) -> 0 | BA23: =+IFERROR(VLOOKUP($BA$17,Sheet1!AH7:AK7,3,0),0) -> 0 | BB23: =+IFERROR(VLOOKUP($BB$17,Sheet1!AH7:AK7,3,0),0) -> 0 | BC23: =+IFERROR(VLOOKUP($BC$17,Sheet1!AL7:AO7,3,0),0) -> 0 | BD23: =+IFERROR(VLOOKUP($BD$17,Sheet1!AL7:AO7,3,0),0) -> 0 | BE23: =+IFERROR(VLOOKUP($BE$17,Sheet1!AL7:AO7,3,0),0) -> 0 | BF23: =+IFERROR(VLOOKUP($BF$17,Sheet1!AL7:AO7,3,0),0) -> 0 | BG23: =+IFERROR(VLOOKUP($BG$17,Sheet1!AL7:AO7,3,0),0) -> 0 | BH23: =+IFERROR(VLOOKUP($BH$17,Sheet1!AL7:AO7,3,0),0) -> 0 | BI23: =+IFERROR(VLOOKUP($BI$17,Sheet1!AL7:AO7,3,0),0) -> 0 | BJ23: 308 | BK23: =+IFERROR(VLOOKUP($BK$17,Sheet1!AL7:AO7,3,0),0) -> 0 | BL23: =+IFERROR(VLOOKUP($BL$17,Sheet1!AL7:AO7,3,0),0) -> 0 | BM23: =+IFERROR(VLOOKUP($BM$17,Sheet1!AP7:AS7,3,0),0) -> 0 | BN23: =+IFERROR(VLOOKUP($BN$17,Sheet1!AT7:AW7,3,0),0) -> 0 | BO23: =+IFERROR(VLOOKUP($BO$17,Sheet1!AX7:BA7,3,0),0) -> 0 | BP23: =+IFERROR(VLOOKUP($BP$17,Sheet1!BB7:BE7,3,0),0) -> 0 | BQ23: =+IFERROR(VLOOKUP($BQ$17,Sheet1!BF7:BI7,3,0),0) -> 0 | BR23: =+IFERROR(VLOOKUP($BR$17,Sheet1!BJ7:BM7,3,0),0) -> 0 | BS23: =+IFERROR(VLOOKUP($BS$17,Sheet1!BN7:BQ7,3,0),0) -> 0 | BT23: =+IFERROR(VLOOKUP($BT$17,Sheet1!BR7:BU7,3,0),0) -> 0 | BU23: =+IFERROR(VLOOKUP($BU$17,Sheet1!BV7:BY7,3,0),0) -> 0 | BV23: =Sheet1!E7 -> WOOD | BW23: =Sheet1!CV7 -> MD0100019 | BX23: =Sheet1!CW7 -> DRUM - 54 X 24 X 32 X 3 | BY23: =Sheet1!CX7 -> 500 | BZ23: =Sheet1!BZ7+1000 -> 13757.48 | CA23: =SUMPRODUCT($N$18:$BU$18,N23:BU23)+BZ23 -> 295699.48 | CB23: =Sheet1!CB7 -> 0 | CC23: =CA23*CB23 -> 0 | CD23: 0.2 | CE23: =CA23*CD23 -> 59139.896 | CF23: 0 | CG23: =CA23*CF23 -> 0 | CH23: =CA23+CC23+CE23+CG23 -> 354839.38 | CI23: 0.02 | CJ23: =CH23*CI23 -> 7096.7875 | CK23: 0.01 | CL23: =CH23*CK23 -> 3548.3938
A24: =Sheet1!A6 -> ENQ-12644-22-23 | B24: =Sheet1!B6 -> 45352 | C24: =Sheet1!C6 -> FA1100008 | D24: =Sheet1!D6 -> 3.5 CORE X 70 SQ. MM. AL/ARD - STRIP (XLPE) | E24: =CH24+CJ24+CL24 -> 283614.62 | F24: =ROUNDUP(M34,0) -> 8750 | G24: =E24+F24 -> 292364.62 | H24: =Sheet1!CP6 -> 0.18 | I24: =G24*H24 -> 52625.632 | J24: =G24+I24 -> 344990.26 | K24: 12 | L24: =Sheet1!CT6 -> KMS | M24: =J24*K24 -> 4139883.1 | N24: =+IFERROR(VLOOKUP($N$17,Sheet1!J6:L6,3,0),0) -> 661.5 | O24: =+IFERROR(VLOOKUP($O$17,Sheet1!J6:L6,3,0),0) -> 0 | P24: =+IFERROR(VLOOKUP($P$17,Sheet1!J6:M6,3,0),0) -> 0 | Q24: =+IFERROR(VLOOKUP($Q$17,Sheet1!J6:M6,3,0),0) -> 0 | R24: =+IFERROR(VLOOKUP($R$17,Sheet1!J6:M6,3,0),0) -> 0 | S24: =+IFERROR(VLOOKUP($S$17,Sheet1!N6:Q6,3,0),0) -> 0 | T24: =+IFERROR(VLOOKUP($T$17,Sheet1!N6:Q6,3,0),0) -> 0 | U24: =+IFERROR(VLOOKUP($U$17,Sheet1!F6:I6,3,0),0) -> 0 | V24: =+IFERROR(VLOOKUP($V$17,Sheet1!F6:I6,3,0),0) -> 0 | W24: =+IFERROR(VLOOKUP($W$17,Sheet1!F6:I6,3,0),0) -> 0 | X24: =+IFERROR(VLOOKUP($X$17,Sheet1!F6:I6,3,0),0) -> 0 | Y24: =+IFERROR(VLOOKUP($Y$17,Sheet1!F6:I6,3,0),0) -> 0 | Z24: =+IFERROR(VLOOKUP($Z$17,Sheet1!F6:I6,3,0),0) -> 0 | AA24: =+IFERROR(VLOOKUP($AA$17,Sheet1!F6:I6,3,0),0) -> 0 | AB24: =+IFERROR(VLOOKUP($AB$17,Sheet1!F6:I6,3,0),0) -> 0 | AC24: =+IFERROR(VLOOKUP($AC$17,Sheet1!R6:U6,3,0),0) -> 0 | AD24: =+IFERROR(VLOOKUP($AD$17,Sheet1!R6:U6,2,0),0) -> 0 | AE24: =+IFERROR(VLOOKUP($AE$17,Sheet1!V6:Y6,3,0),0) -> 0 | AF24: =+IFERROR(VLOOKUP($AF$17,Sheet1!V6:Y6,3,0),0) -> 137 | AG24: =+IFERROR(VLOOKUP($AG$17,Sheet1!V6:Y6,3,0),0) -> 0 | AH24: =+IFERROR(VLOOKUP($AH$17,Sheet1!V6:Y6,3,0),0) -> 0 | AI24: =+IFERROR(VLOOKUP($AI$17,Sheet1!V6:Y6,3,0),0) -> 0 | AJ24: =+IFERROR(VLOOKUP($AJ$17,Sheet1!V6:Y6,3,0),0) -> 0 | AK24: =+IFERROR(VLOOKUP($AK$17,Sheet1!Z6:AB6,3,0),0) -> 0 | AL24: =+IFERROR(VLOOKUP($AL$17,Sheet1!AD6:AG6,3,0),0) -> 0 | AM24: =+IFERROR(VLOOKUP($AM$17,Sheet1!AD6:AG6,3,0),0) -> 0 | AN24: =+IFERROR(VLOOKUP($AN$17,Sheet1!AD6:AG6,3,0),0) -> 0 | AO24: =+IFERROR(VLOOKUP($AO$17,Sheet1!AD6:AG6,3,0),0) -> 0 | AP24: =+IFERROR(VLOOKUP($AP$17,Sheet1!AD6:AG6,3,0),0) -> 0 | AQ24: =+IFERROR(VLOOKUP($AQ$17,Sheet1!AD6:AG6,3,0),0) -> 76 | AR24: =+IFERROR(VLOOKUP($AR$17,Sheet1!AD6:AG6,3,0),0) -> 0 | AS24: =+IFERROR(VLOOKUP($AS$17,Sheet1!AH6:AK6,3,0),0) -> 0 | AT24: =+IFERROR(VLOOKUP($AT$17,Sheet1!AH6:AK6,3,0),0) -> 0 | AU24: =+IFERROR(VLOOKUP($AU$17,Sheet1!AH6:AK6,3,0),0) -> 0 | AV24: =+IFERROR(VLOOKUP($AV$17,Sheet1!AH6:AK6,3,0),0) -> 0 | AW24: =+IFERROR(VLOOKUP($AW$17,Sheet1!AH6:AK6,3,0),0) -> 0 | AX24: =+IFERROR(VLOOKUP($AX$17,Sheet1!AH6:AK6,3,0),0) -> 476 | AY24: =+IFERROR(VLOOKUP($AY$17,Sheet1!AH6:AK6,3,0),0) -> 0 | AZ24: =+IFERROR(VLOOKUP($AZ$17,Sheet1!AH6:AK6,3,0),0) -> 0 | BA24: =+IFERROR(VLOOKUP($BA$17,Sheet1!AH6:AK6,3,0),0) -> 0 | BB24: =+IFERROR(VLOOKUP($BB$17,Sheet1!AH6:AK6,3,0),0) -> 0 | BC24: =+IFERROR(VLOOKUP($BC$17,Sheet1!AL6:AO6,3,0),0) -> 0 | BD24: =+IFERROR(VLOOKUP($BD$17,Sheet1!AL6:AO6,3,0),0) -> 0 | BE24: =+IFERROR(VLOOKUP($BE$17,Sheet1!AL6:AO6,3,0),0) -> 0 | BF24: =+IFERROR(VLOOKUP($BF$17,Sheet1!AL6:AO6,3,0),0) -> 0 | BG24: =+IFERROR(VLOOKUP($BG$17,Sheet1!AL6:AO6,3,0),0) -> 0 | BH24: =+IFERROR(VLOOKUP($BH$17,Sheet1!AL6:AO6,3,0),0) -> 0 | BI24: =+IFERROR(VLOOKUP($BI$17,Sheet1!AL6:AO6,3,0),0) -> 0 | BJ24: 262 | BK24: =+IFERROR(VLOOKUP($BK$17,Sheet1!AL6:AO6,3,0),0) -> 0 | BL24: =+IFERROR(VLOOKUP($BL$17,Sheet1!AL6:AO6,3,0),0) -> 0 | BM24: =+IFERROR(VLOOKUP($BM$17,Sheet1!AP6:AS6,3,0),0) -> 0 | BN24: =+IFERROR(VLOOKUP($BN$17,Sheet1!AT6:AW6,3,0),0) -> 0 | BO24: =+IFERROR(VLOOKUP($BO$17,Sheet1!AX6:BA6,3,0),0) -> 0 | BP24: =+IFERROR(VLOOKUP($BP$17,Sheet1!BB6:BE6,3,0),0) -> 0 | BQ24: =+IFERROR(VLOOKUP($BQ$17,Sheet1!BF6:BI6,3,0),0) -> 0 | BR24: =+IFERROR(VLOOKUP($BR$17,Sheet1!BJ6:BM6,3,0),0) -> 0 | BS24: =+IFERROR(VLOOKUP($BS$17,Sheet1!BN6:BQ6,3,0),0) -> 0 | BT24: =+IFERROR(VLOOKUP($BT$17,Sheet1!BR6:BU6,3,0),0) -> 0 | BU24: =+IFERROR(VLOOKUP($BU$17,Sheet1!BV6:BY6,3,0),0) -> 0 | BV24: =Sheet1!E6 -> WOOD | BW24: =Sheet1!CV6 -> MD0100017 | BX24: =Sheet1!CW6 -> DRUM - 52 X 18 X 36 X 2.5 | BY24: =Sheet1!CX6 -> 500 | BZ24: =Sheet1!BZ6+1000 -> 10913.67 | CA24: =SUMPRODUCT($N$18:$BU$18,N24:BU24)+BZ24 -> 229461.67 | CB24: =Sheet1!CB6 -> 0 | CC24: =CA24*CB24 -> 0 | CD24: 0.2 | CE24: =CA24*CD24 -> 45892.334 | CF24: 0 | CG24: =CA24*CF24 -> 0 | CH24: =CA24+CC24+CE24+CG24 -> 275354 | CI24: 0.02 | CJ24: =CH24*CI24 -> 5507.0801 | CK24: 0.01 | CL24: =CH24*CK24 -> 2753.54
A25: =Sheet1!A5 -> ENQ-12644-22-23 | B25: =Sheet1!B5 -> 45352 | C25: =Sheet1!C5 -> FA0900047 | D25: =Sheet1!D5 -> 3.5 CORE X 50 SQ. MM. AL/ARD - STRIP (XLPE) | E25: =CH25+CJ25+CL25 -> 213634.05 | F25: =ROUNDUP(M35,0) -> 5385 | G25: =E25+F25 -> 219019.05 | H25: =Sheet1!CP5 -> 0.18 | I25: =G25*H25 -> 39423.428 | J25: =G25+I25 -> 258442.48 | K25: 13 | L25: =Sheet1!CT5 -> KMS | M25: =J25*K25 -> 3359752.2 | N25: =+IFERROR(VLOOKUP($N$17,Sheet1!J5:L5,3,0),0) -> 472.5 | O25: =+IFERROR(VLOOKUP($O$17,Sheet1!J5:L5,3,0),0) -> 0 | P25: =+IFERROR(VLOOKUP($P$17,Sheet1!J5:M5,3,0),0) -> 0 | Q25: =+IFERROR(VLOOKUP($Q$17,Sheet1!J5:M5,3,0),0) -> 0 | R25: =+IFERROR(VLOOKUP($R$17,Sheet1!J5:M5,3,0),0) -> 0 | S25: =+IFERROR(VLOOKUP($S$17,Sheet1!N5:Q5,3,0),0) -> 0 | T25: =+IFERROR(VLOOKUP($T$17,Sheet1!N5:Q5,3,0),0) -> 0 | U25: =+IFERROR(VLOOKUP($U$17,Sheet1!F5:I5,3,0),0) -> 0 | V25: =+IFERROR(VLOOKUP($V$17,Sheet1!F5:I5,3,0),0) -> 0 | W25: =+IFERROR(VLOOKUP($W$17,Sheet1!F5:I5,3,0),0) -> 0 | X25: =+IFERROR(VLOOKUP($X$17,Sheet1!F5:I5,3,0),0) -> 0 | Y25: =+IFERROR(VLOOKUP($Y$17,Sheet1!F5:I5,3,0),0) -> 0 | Z25: =+IFERROR(VLOOKUP($Z$17,Sheet1!F5:I5,3,0),0) -> 0 | AA25: =+IFERROR(VLOOKUP($AA$17,Sheet1!F5:I5,3,0),0) -> 0 | AB25: =+IFERROR(VLOOKUP($AB$17,Sheet1!F5:I5,3,0),0) -> 0 | AC25: =+IFERROR(VLOOKUP($AC$17,Sheet1!R5:U5,3,0),0) -> 0 | AD25: =+IFERROR(VLOOKUP($AD$17,Sheet1!R5:U5,2,0),0) -> 0 | AE25: =+IFERROR(VLOOKUP($AE$17,Sheet1!V5:Y5,3,0),0) -> 0 | AF25: =+IFERROR(VLOOKUP($AF$17,Sheet1!V5:Y5,3,0),0) -> 105 | AG25: =+IFERROR(VLOOKUP($AG$17,Sheet1!V5:Y5,3,0),0) -> 0 | AH25: =+IFERROR(VLOOKUP($AH$17,Sheet1!V5:Y5,3,0),0) -> 0 | AI25: =+IFERROR(VLOOKUP($AI$17,Sheet1!V5:Y5,3,0),0) -> 0 | AJ25: =+IFERROR(VLOOKUP($AJ$17,Sheet1!V5:Y5,3,0),0) -> 0 | AK25: =+IFERROR(VLOOKUP($AK$17,Sheet1!Z5:AB5,3,0),0) -> 0 | AL25: =+IFERROR(VLOOKUP($AL$17,Sheet1!AD5:AG5,3,0),0) -> 0 | AM25: =+IFERROR(VLOOKUP($AM$17,Sheet1!AD5:AG5,3,0),0) -> 0 | AN25: =+IFERROR(VLOOKUP($AN$17,Sheet1!AD5:AG5,3,0),0) -> 0 | AO25: =+IFERROR(VLOOKUP($AO$17,Sheet1!AD5:AG5,3,0),0) -> 0 | AP25: =+IFERROR(VLOOKUP($AP$17,Sheet1!AD5:AG5,3,0),0) -> 0 | AQ25: =+IFERROR(VLOOKUP($AQ$17,Sheet1!AD5:AG5,3,0),0) -> 54 | AR25: =+IFERROR(VLOOKUP($AR$17,Sheet1!AD5:AG5,3,0),0) -> 0 | AS25: =+IFERROR(VLOOKUP($AS$17,Sheet1!AH5:AK5,3,0),0) -> 0 | AT25: =+IFERROR(VLOOKUP($AT$17,Sheet1!AH5:AK5,3,0),0) -> 0 | AU25: =+IFERROR(VLOOKUP($AU$17,Sheet1!AH5:AK5,3,0),0) -> 0 | AV25: =+IFERROR(VLOOKUP($AV$17,Sheet1!AH5:AK5,3,0),0) -> 0 | AW25: =+IFERROR(VLOOKUP($AW$17,Sheet1!AH5:AK5,3,0),0) -> 0 | AX25: =+IFERROR(VLOOKUP($AX$17,Sheet1!AH5:AK5,3,0),0) -> 401 | AY25: =+IFERROR(VLOOKUP($AY$17,Sheet1!AH5:AK5,3,0),0) -> 0 | AZ25: =+IFERROR(VLOOKUP($AZ$17,Sheet1!AH5:AK5,3,0),0) -> 0 | BA25: =+IFERROR(VLOOKUP($BA$17,Sheet1!AH5:AK5,3,0),0) -> 0 | BB25: =+IFERROR(VLOOKUP($BB$17,Sheet1!AH5:AK5,3,0),0) -> 0 | BC25: =+IFERROR(VLOOKUP($BC$17,Sheet1!AL5:AO5,3,0),0) -> 0 | BD25: =+IFERROR(VLOOKUP($BD$17,Sheet1!AL5:AO5,3,0),0) -> 0 | BE25: =+IFERROR(VLOOKUP($BE$17,Sheet1!AL5:AO5,3,0),0) -> 0 | BF25: =+IFERROR(VLOOKUP($BF$17,Sheet1!AL5:AO5,3,0),0) -> 0 | BG25: =+IFERROR(VLOOKUP($BG$17,Sheet1!AL5:AO5,3,0),0) -> 0 | BH25: =+IFERROR(VLOOKUP($BH$17,Sheet1!AL5:AO5,3,0),0) -> 0 | BI25: =+IFERROR(VLOOKUP($BI$17,Sheet1!AL5:AO5,3,0),0) -> 0 | BJ25: 225 | BK25: =+IFERROR(VLOOKUP($BK$17,Sheet1!AL5:AO5,3,0),0) -> 0 | BL25: =+IFERROR(VLOOKUP($BL$17,Sheet1!AL5:AO5,3,0),0) -> 0 | BM25: =+IFERROR(VLOOKUP($BM$17,Sheet1!AP5:AS5,3,0),0) -> 0 | BN25: =+IFERROR(VLOOKUP($BN$17,Sheet1!AT5:AW5,3,0),0) -> 0 | BO25: =+IFERROR(VLOOKUP($BO$17,Sheet1!AX5:BA5,3,0),0) -> 0 | BP25: =+IFERROR(VLOOKUP($BP$17,Sheet1!BB5:BE5,3,0),0) -> 0 | BQ25: =+IFERROR(VLOOKUP($BQ$17,Sheet1!BF5:BI5,3,0),0) -> 0 | BR25: =+IFERROR(VLOOKUP($BR$17,Sheet1!BJ5:BM5,3,0),0) -> 0 | BS25: =+IFERROR(VLOOKUP($BS$17,Sheet1!BN5:BQ5,3,0),0) -> 0 | BT25: =+IFERROR(VLOOKUP($BT$17,Sheet1!BR5:BU5,3,0),0) -> 0 | BU25: =+IFERROR(VLOOKUP($BU$17,Sheet1!BV5:BY5,3,0),0) -> 0 | BV25: =Sheet1!E5 -> WOOD | BW25: =Sheet1!CV5 -> MD0100015 | BX25: =Sheet1!CW5 -> DRUM - 48 X 20 X 28 X 2.25 - RDSO | BY25: =Sheet1!CX5 -> 500 | BZ25: =Sheet1!BZ5+1000 -> 8317.08 | CA25: =SUMPRODUCT($N$18:$BU$18,N25:BU25)+BZ25 -> 172843.08 | CB25: =Sheet1!CB5 -> 0 | CC25: =CA25*CB25 -> 0 | CD25: 0.2 | CE25: =CA25*CD25 -> 34568.616 | CF25: 0 | CG25: =CA25*CF25 -> 0 | CH25: =CA25+CC25+CE25+CG25 -> 207411.7 | CI25: 0.02 | CJ25: =CH25*CI25 -> 4148.2339 | CK25: 0.01 | CL25: =CH25*CK25 -> 2074.117
M26: =SUM(M19:M25) -> 40101614
E28: Order Quantity | F28: Stnd Length | G28: Truck type | H28: Fare of one truck | I28: No of Drum in one truck | J28: Total length in one Truck | K28: No of Truck | L28: Total Freight | M28: Freight per KM | N28: CABLE WEIGHT KG/KM | AF28: DRUM WEIGHT | AQ28: CABLE+DRUM WEIGHT | AX28: TRUCK WEIGHT
C29: =BW19 -> MD0100079 | D29: =D19 -> 3.5 CORE X 300 SQ. MM. AL/ARD - STRIP (XLPE) | E29: =K19 -> 5 | F29: =BY19/1000 -> 0.5 | G29: 16 MT | H29: 35000 | I29: 5 | J29: =F29*I29 -> 2.5 | K29: =ROUNDUP((E29/J29),0) -> 2 | L29: =M29*E29 -> 70000 | M29: =(H29*K29)/E29 -> 14000 | N29: =SUM(N19:BJ19) -> 5122 | AF29: =450+80 -> 530 | AQ29: =((N29*F29)+AF29) -> 3091 | AX29: =I29*AQ29 -> 15455
C30: =BW20 -> MD0100024 | D30: =D20 -> 3.5 CORE X 240 SQ. MM. AL/ARD - STRIP (XLPE) | E30: =K20 -> 12 | F30: =BY20/1000 -> 0.5 | G30: 16 MT | H30: 35000 | I30: 6 | J30: =F30*I30 -> 3 | K30: =ROUNDUP((E30/J30),0) -> 4 | L30: =M30*E30 -> 140000 | M30: =(H30*K30)/E30 -> 11666.667 | N30: =SUM(N20:BJ20) -> 4198 | AF30: =260+55 -> 315 | AQ30: =((N30*F30)+AF30) -> 2414 | AX30: =I30*AQ30 -> 14484
C31: =BW21 -> MD0100070 | D31: =D21 -> 3.5 CORE X 150 SQ. MM. AL/ARD - STRIP (XLPE) | E31: =K21 -> 12 | F31: =BY21/1000 -> 0.5 | G31: 16 MT | H31: 35000 | I31: 9 | J31: =F31*I31 -> 4.5 | K31: =ROUNDUP((E31/J31),0) -> 3 | L31: =M31*E31 -> 105000 | M31: =(H31*K31)/E31 -> 8750 | N31: =SUM(N21:BJ21) -> 2779 | AF31: =250+50 -> 300 | AQ31: =((N31*F31)+AF31) -> 1689.5 | AX31: =I31*AQ31 -> 15205.5
C32: =BW22 -> MD0100021 | D32: =D22 -> 3.5 CORE X 120 SQ. MM. AL/ARD - STRIP (XLPE ) | E32: =K22 -> 2.82 | F32: =BY22/1000 -> 0.5 | G32: 16 MT | H32: 35000 | I32: 9 | J32: =F32*I32 -> 4.5 | K32: =ROUNDUP((E32/J32),0) -> 1 | L32: =M32*E32 -> 35000 | M32: =(H32*K32)/E32 -> 12411.348 | N32: =SUM(N22:BJ22) -> 2420 | AF32: =220+45 -> 265 | AQ32: =((N32*F32)+AF32) -> 1475 | AX32: =I32*AQ32 -> 13275
C33: =BW23 -> MD0100019 | D33: =D23 -> 3.5 CORE X 95 SQ. MM. AL/ARD - STRIP (XLPE) | E33: =K23 -> 12 | F33: =BY23/1000 -> 0.5 | G33: 16 MT | H33: 35000 | I33: 11 | J33: =F33*I33 -> 5.5 | K33: =ROUNDUP((E33/J33),0) -> 3 | L33: =M33*E33 -> 105000 | M33: =(H33*K33)/E33 -> 8750 | N33: =SUM(N23:BJ23) -> 1990.5 | AF33: =150+30 -> 180 | AQ33: =((N33*F33)+AF33) -> 1175.25 | AX33: =I33*AQ33 -> 12927.75
C34: =BW24 -> MD0100017 | D34: =D24 -> 3.5 CORE X 70 SQ. MM. AL/ARD - STRIP (XLPE) | E34: =K24 -> 12 | F34: =BY24/1000 -> 0.5 | G34: 16 MT | H34: 35000 | I34: 11 | J34: =F34*I34 -> 5.5 | K34: =ROUNDUP((E34/J34),0) -> 3 | L34: =M34*E34 -> 105000 | M34: =(H34*K34)/E34 -> 8750 | N34: =SUM(N24:BJ24) -> 1612.5 | AF34: =120+30 -> 150 | AQ34: =((N34*F34)+AF34) -> 956.25 | AX34: =I34*AQ34 -> 10518.75
C35: =BW25 -> MD0100015 | D35: =D25 -> 3.5 CORE X 50 SQ. MM. AL/ARD - STRIP (XLPE) | E35: =K25 -> 13 | F35: =BY25/1000 -> 0.5 | G35: 16 MT | H35: 35000 | I35: 21 | J35: =F35*I35 -> 10.5 | K35: =ROUNDUP((E35/J35),0) -> 2 | L35: =M35*E35 -> 70000 | M35: =(H35*K35)/E35 -> 5384.6154 | N35: =SUM(N25:BJ25) -> 1257.5 | AF35: =100+25 -> 125 | AQ35: =((N35*F35)+AF35) -> 753.75 | AX35: =I35*AQ35 -> 15828.75
L37: estimated Value in INR | M37: 31128982
L38: diff % | M38: =((M26-M37)/M37)*100 -> 28.824045

Sheet PV
A1: Base Date | B1: 45352
A2: PV Terms(Price Variation Formula)
A3: PV FORMULA
A4: P = Po + AIF (Al–Alo) + XLFAL (CC–Cco) + SMIF (SMIF1–SMIF0) + FeF (FeF1–FeF0) + CCFAI (PVCc–PVCco)
A8: Item | B8: Ex-Work
A9: ='AUTO CALCULATION SHEET (2)'!D19 -> 3.5 CORE X 300 SQ. MM. AL/ARD - STRIP (XLPE) | B9: ='AUTO CALCULATION SHEET (2)'!E19 -> 1041160.7
A10: ='AUTO CALCULATION SHEET (2)'!D20 -> 3.5 CORE X 240 SQ. MM. AL/ARD - STRIP (XLPE) | B10: ='AUTO CALCULATION SHEET (2)'!E20 -> 823307.33
A11: ='AUTO CALCULATION SHEET (2)'!D21 -> 3.5 CORE X 150 SQ. MM. AL/ARD - STRIP (XLPE) | B11: ='AUTO CALCULATION SHEET (2)'!E21 -> 534711.94
A12: ='AUTO CALCULATION SHEET (2)'!D22 -> 3.5 CORE X 120 SQ. MM. AL/ARD - STRIP (XLPE ) | B12: ='AUTO CALCULATION SHEET (2)'!E22 -> 456007.17
A13: ='AUTO CALCULATION SHEET (2)'!D23 -> 3.5 CORE X 95 SQ. MM. AL/ARD - STRIP (XLPE) | B13: ='AUTO CALCULATION SHEET (2)'!E23 -> 365484.56
A14: ='AUTO CALCULATION SHEET (2)'!D24 -> 3.5 CORE X 70 SQ. MM. AL/ARD - STRIP (XLPE) | B14: ='AUTO CALCULATION SHEET (2)'!E24 -> 283614.62
A15: ='AUTO CALCULATION SHEET (2)'!D25 -> 3.5 CORE X 50 SQ. MM. AL/ARD - STRIP (XLPE) | B15: ='AUTO CALCULATION SHEET (2)'!E25 -> 213634.05
Y16: VALUE ADDITION CALCULATION
A17: Item | B17: Calculation part | C17: Date of Inspection | D17: Applicable Date | I17: BASE DATE | N17: FACTORS | R17: Ex-Work Po | S17: PVC of al | T17: PVC of XLPE | U17: PVC OF PVC | V17: PVC OF FE | W17: PV/PKM | X17: Billing Price/PKM
D18: Date | E18: Al | F18: Cc | G18: PVCc | H18: Fe | I18: Date | J18: Alo | K18: Cco | L18: PVCco | M18: Feo | Y18: ='AUTO CALCULATION SHEET (2)'!N17 -> Alumimium | Z18: ='AUTO CALCULATION SHEET (2)'!AF17 -> LT-XLPE | AA18: ='AUTO CALCULATION SHEET (2)'!AQ17 -> PVC Type ST-2 | AB18: ='AUTO CALCULATION SHEET (2)'!AX17 -> Galvanised Steel Flat Strip | AC18: ='AUTO CALCULATION SHEET (2)'!BJ17 -> ATR PVC Type ST-2 | AD18: RMC | AE18: Drum | AF18: RMC+Drum | AG18: VA | AH18: Groos VA% | AI18: Mfg % | AJ18: Int % | AK18: Ins% | AL18: Net VA
N19: Alf | O19: XLFAL | P19: CCFAI | Q19: FeF | Y19: 220 | Z19: 100 | AA19: 61 | AB19: 71 | AC19: =61+27 -> 88
F20: 45323 | G20: 45323 | H20: 45323 | K20: 45323 | L20: 45323 | M20: 45323 | Y20: Kg/Km | Z20: Kg/Km | AA20: Kg/Km | AB20: Kg/Km | AC20: Kg/Km
A21: =A9 -> 3.5 CORE X 300 SQ. MM. AL/ARD - STRIP (XLPE) | C21: PROVISIONAL | D21: 45378 | E21: 211779.4 | F21: 149726 | G21: 156825 | H21: 76250 | I21: =$B$1 -> 45352 | J21: 211779.4 | K21: 149726 | L21: 156825 | M21: 76250 | N21: 3.033 | O21: 0.54 | P21: 1.031 | Q21: 1.055 | R21: =B9 -> 1041160.7 | S21: =(N21*(E21-J21)) -> 0 | T21: =(O21*(F21-K21)) -> 0 | U21: =(P21*(G21-L21)) -> 0 | V21: =(Q21*(H21-M21)) -> 0 | W21: =S21+T21+U21+V21 -> 0 | X21: =+R21+W21 -> 1041160.7 | Y21: ='AUTO CALCULATION SHEET (2)'!N19 -> 2835 | Z21: ='AUTO CALCULATION SHEET (2)'!AF19 -> 430 | AA21: ='AUTO CALCULATION SHEET (2)'!AQ19 -> 245 | AB21: ='AUTO CALCULATION SHEET (2)'!AX19 -> 914 | AC21: ='AUTO CALCULATION SHEET (2)'!BJ19 -> 698 | AD21: =SUMPRODUCT(Y21:AC21,$Y$19:$AC$19) -> 807963 | AE21: ='AUTO CALCULATION SHEET (2)'!BZ19 -> 44826 | AF21: =AD21+AE21 -> 852789 | AG21: =X21-AF21 -> 188371.67 | AH21: =ROUND((AG21/AF21)*100,2) -> 22.09 | AI21: 0 | AJ21: 2 | AK21: 1 | AL21: =AH21-AI21-AJ21-AK21 -> 19.09
A22: =A10 -> 3.5 CORE X 240 SQ. MM. AL/ARD - STRIP (XLPE) | C22: PROVISIONAL | D22: 45378 | E22: 211779.4 | F22: 149726 | G22: 156825 | H22: 76250 | I22: =$B$1 -> 45352 | J22: 211779.4 | K22: 149726 | L22: 156825 | M22: 76250 | N22: 2.421 | O22: 0.446 | P22: 0.952 | Q22: 0.937 | R22: =B10 -> 823307.33 | S22: =(N22*(E22-J22)) -> 0 | T22: =(O22*(F22-K22)) -> 0 | U22: =(P22*(G22-L22)) -> 0 | V22: =(Q22*(H22-M22)) -> 0 | W22: =S22+T22+U22+V22 -> 0 | X22: =+R22+W22 -> 823307.33 | Y22: ='AUTO CALCULATION SHEET (2)'!N20 -> 2268 | Z22: ='AUTO CALCULATION SHEET (2)'!AF20 -> 359 | AA22: ='AUTO CALCULATION SHEET (2)'!AQ20 -> 175 | AB22: ='AUTO CALCULATION SHEET (2)'!AX20 -> 817 | AC22: ='AUTO CALCULATION SHEET (2)'!BJ20 -> 579 | AD22: =SUMPRODUCT(Y22:AC22,$Y$19:$AC$19) -> 654494 | AE22: ='AUTO CALCULATION SHEET (2)'!BZ20 -> 19867.25 | AF22: =AD22+AE22 -> 674361.25 | AG22: =X22-AF22 -> 148946.08 | AH22: =ROUND((AG22/AF22)*100,2) -> 22.09 | AI22: 0 | AJ22: 2 | AK22: 1 | AL22: =AH22-AI22-AJ22-AK22 -> 19.09
A23: =A11 -> 3.5 CORE X 150 SQ. MM. AL/ARD - STRIP (XLPE) | C23: PROVISIONAL | D23: 45378 | E23: 211779.4 | F23: 149726 | G23: 156825 | H23: 76250 | I23: =$B$1 -> 45352 | J23: 211779.4 | K23: 149726 | L23: 156825 | M23: 76250 | N23: 1.464 | O23: 0.296 | P23: 0.633 | Q23: 0.731 | R23: =B11 -> 534711.94 | S23: =(N23*(E23-J23)) -> 0 | T23: =(O23*(F23-K23)) -> 0 | U23: =(P23*(G23-L23)) -> 0 | V23: =(Q23*(H23-M23)) -> 0 | W23: =S23+T23+U23+V23 -> 0 | X23: =+R23+W23 -> 534711.94 | Y23: ='AUTO CALCULATION SHEET (2)'!N21 -> 1404 | Z23: ='AUTO CALCULATION SHEET (2)'!AF21 -> 244 | AA23: ='AUTO CALCULATION SHEET (2)'!AQ21 -> 128 | AB23: ='AUTO CALCULATION SHEET (2)'!AX21 -> 625 | AC23: ='AUTO CALCULATION SHEET (2)'!BJ21 -> 378 | AD23: =SUMPRODUCT(Y23:AC23,$Y$19:$AC$19) -> 418727 | AE23: ='AUTO CALCULATION SHEET (2)'!BZ21 -> 18878.84 | AF23: =AD23+AE23 -> 437605.84 | AG23: =X23-AF23 -> 97106.102 | AH23: =ROUND((AG23/AF23)*100,2) -> 22.19 | AI23: 0 | AJ23: 2 | AK23: 1 | AL23: =AH23-AI23-AJ23-AK23 -> 19.19
A24: =A12 -> 3.5 CORE X 120 SQ. MM. AL/ARD - STRIP (XLPE ) | C24: PROVISIONAL | D24: 45378 | E24: 211779.4 | F24: 149726 | G24: 156825 | H24: 76250 | I24: =$B$1 -> 45352 | J24: 211779.4 | K24: 149726 | L24: 156825 | M24: 76250 | N24: 1.221 | O24: 0.239 | P24: 0.538 | Q24: 0.675 | R24: =B12 -> 456007.17 | S24: =(N24*(E24-J24)) -> 0 | T24: =(O24*(F24-K24)) -> 0 | U24: =(P24*(G24-L24)) -> 0 | V24: =(Q24*(H24-M24)) -> 0 | W24: =S24+T24+U24+V24 -> 0 | X24: =+R24+W24 -> 456007.17 | Y24: ='AUTO CALCULATION SHEET (2)'!N22 -> 1161 | Z24: ='AUTO CALCULATION SHEET (2)'!AF22 -> 197 | AA24: ='AUTO CALCULATION SHEET (2)'!AQ22 -> 111 | AB24: ='AUTO CALCULATION SHEET (2)'!AX22 -> 594 | AC24: ='AUTO CALCULATION SHEET (2)'!BJ22 -> 357 | AD24: =SUMPRODUCT(Y24:AC24,$Y$19:$AC$19) -> 355481 | AE24: ='AUTO CALCULATION SHEET (2)'!BZ22 -> 17506.84 | AF24: =AD24+AE24 -> 372987.84 | AG24: =X24-AF24 -> 83019.33 | AH24: =ROUND((AG24/AF24)*100,2) -> 22.26 | AI24: 0 | AJ24: 2 | AK24: 1 | AL24: =AH24-AI24-AJ24-AK24 -> 19.26
A25: =A13 -> 3.5 CORE X 95 SQ. MM. AL/ARD - STRIP (XLPE) | C25: PROVISIONAL | D25: 45378 | E25: 211779.4 | F25: 149726 | G25: 156825 | H25: 76250 | I25: =$B$1 -> 45352 | J25: 211779.4 | K25: 149726 | L25: 156825 | M25: 76250 | N25: 0.949 | O25: 0.19 | P25: 0.471 | Q25: 0.616 | R25: =B13 -> 365484.56 | S25: =(N25*(E25-J25)) -> 0 | T25: =(O25*(F25-K25)) -> 0 | U25: =(P25*(G25-L25)) -> 0 | V25: =(Q25*(H25-M25)) -> 0 | W25: =S25+T25+U25+V25 -> 0 | X25: =+R25+W25 -> 365484.56 | Y25: ='AUTO CALCULATION SHEET (2)'!N23 -> 904.5 | Z25: ='AUTO CALCULATION SHEET (2)'!AF23 -> 157 | AA25: ='AUTO CALCULATION SHEET (2)'!AQ23 -> 86 | AB25: ='AUTO CALCULATION SHEET (2)'!AX23 -> 535 | AC25: ='AUTO CALCULATION SHEET (2)'!BJ23 -> 308 | AD25: =SUMPRODUCT(Y25:AC25,$Y$19:$AC$19) -> 285025 | AE25: ='AUTO CALCULATION SHEET (2)'!BZ23 -> 13757.48 | AF25: =AD25+AE25 -> 298782.48 | AG25: =X25-AF25 -> 66702.077 | AH25: =ROUND((AG25/AF25)*100,2) -> 22.32 | AI25: 0 | AJ25: 2 | AK25: 1 | AL25: =AH25-AI25-AJ25-AK25 -> 19.32
A26: =A14 -> 3.5 CORE X 70 SQ. MM. AL/ARD - STRIP (XLPE) | C26: PROVISIONAL | D26: 45378 | E26: 211779.4 | F26: 149726 | G26: 156825 | H26: 76250 | I26: =$B$1 -> 45352 | J26: 211779.4 | K26: 149726 | L26: 156825 | M26: 76250 | N26: 0.687 | O26: 0.16 | P26: 0.42 | Q26: 0.539 | R26: =B14 -> 283614.62 | S26: =(N26*(E26-J26)) -> 0 | T26: =(O26*(F26-K26)) -> 0 | U26: =(P26*(G26-L26)) -> 0 | V26: =(Q26*(H26-M26)) -> 0 | W26: =S26+T26+U26+V26 -> 0 | X26: =+R26+W26 -> 283614.62 | Y26: ='AUTO CALCULATION SHEET (2)'!N24 -> 661.5 | Z26: ='AUTO CALCULATION SHEET (2)'!AF24 -> 137 | AA26: ='AUTO CALCULATION SHEET (2)'!AQ24 -> 76 | AB26: ='AUTO CALCULATION SHEET (2)'!AX24 -> 476 | AC26: ='AUTO CALCULATION SHEET (2)'!BJ24 -> 262 | AD26: =SUMPRODUCT(Y26:AC26,$Y$19:$AC$19) -> 220718 | AE26: ='AUTO CALCULATION SHEET (2)'!BZ24 -> 10913.67 | AF26: =AD26+AE26 -> 231631.67 | AG26: =X26-AF26 -> 51982.954 | AH26: =ROUND((AG26/AF26)*100,2) -> 22.44 | AI26: 0 | AJ26: 2 | AK26: 1 | AL26: =AH26-AI26-AJ26-AK26 -> 19.44
