Workbook

Sheet Sheet1
A1: DOCKET NO. | B1: Base Date | C1: ITEM CODE | D1: PROPOSE ERP ITEM NAME | E1: Propose Drum Type | F1: Insulation Screening(Metallic) | G1: RM Rate(Insulation Screening(Metallic)) | H1: Weight (Insulation Screening (Metallic)) | I1: Cost Insulation Screening(Metallic) | J1: Conductor | K1: RM Rate(Conductor) | L1: Weight(Conductor) | M1: Cost(Conductor) | N1: AL ALLOY | O1: RM Rate(AL Alloy) | P1: Weight(Al Alloy) | Q1: Cost(AL Alloy) | R1: Insulation Screening(Non-Metallic) | S1: RM Rate(Insulation Screening(Non-Metallic)) | T1: Weight(Insulation Screening(Non-Metallic) | U1: Cost(Insulation Screening(Non-Metallic) | V1: Insulation | W1: RM Rate(Insulation) | X1: Weight(Insulation) | Y1: Cost(Insulation) | Z1: Poly Tape | AA1: RM Rate(Poly Tape) | AB1: Weight(Poly Tape) | AC1: Cost(Poly Tape) | AD1: Inner Sheath | AE1: RM Rate(Inner Sheath) | AF1: Weight(Inner Sheath) | AG1: Cost(Inner Sheath) | AH1: Armouring | AI1: RM Rate(Armouring) | AJ1: Weight(Armouring) | AK1: Cost(Armouring) | AL1: Outer Sheath | AM1: RM Rate(Outer Sheath) | AN1: Weight(Outer Sheath) | AO1: Cost(Outer Sheath) | AP1: Filler | AQ1: RM Rate(Filler) | AR1: Weight(Filler) | AS1: Cost(Filler) | AT1: Grease | AU1: RM Rate(Grease) | AV1: Weight(Grease) | AW1: Cost(Grease) | AX1: Water Swellable Tape | AY1: RM Rate(Water Swellable Tape) | AZ1: Weight(Water Swellable Tape) | BA1: Cost(Water Swellable Tape) | BB1: Semi Conducting Water Swellable Tape | BC1: RM Rate(Semi Conducting Water Swellable Tape) | BD1: Weight(Semi Conducting Water Swellable Tape) | BE1: Cost(Semi Conducting Water Swellable Tape) | BF1: Semicon Tape | BG1: RM Rate(Semicon Tape) | BH1: Weight(Semicon Tape) | BI1: Cost(Semicon Tape) | BJ1: Glass Fiber Tape | BK1: RM Rate(Glass Fiber Tape) | BL1: Weight(Glass Fiber Tape) | BM1: Cost(Glass Fiber Tape) | BN1: Copper Wire 0.8MM | BO1: RM Rate(Copper Wire 0.8MM) | BP1: Weight(Copper Wire 0.8MM) | BQ1: Cost(Copper Wire 0.8MM) | BR1: Rubberized Cotton Tape | BS1: RM Rate(Rubberized Cotton Tape) | BT1: Weight(Rubberized Cotton Tape) | BU1: Cost(Rubberized Cotton Tape) | BV1: Water Tight Compound | BW1: RM Rate(Water Tight Compound) | BX1: Weight(Water Tight Compound) | BY1: Cost(Water Tight Compound) | BZ1: Drum Cost Per KM | CA1: Total RM Cost | CB1: FIRM % | CC1: Firm Value | CD1: MFG% | CE1: MFG Value | CF1: PROF% | CG1: Profit Value | CH1: 1st EX-Works | CI1: Intt % | CJ1: Intt Value | CK1: insp% | CL1: Insp Value | CM1: EX-Works Per KM | CN1: Freight Per KM | CO1: Price Including Freight Per KM | CP1: GST % | CQ1: GST Value | CR1: Price Including GST & Freight Per KM | CS1: QTY | CT1: Unit | CU1: Total Price Of Full QTY(Including Freight&GST) | CV1: DRUM CODE | CW1: DRUM SIZE (FxbXtx Ft) | CX1: Party Standard Length(MTR)
A2: ENQ-15115-22-23 | B2: 45698 | C2: FA0200002 | D2: 10 CORE X 2.5 SQ. MM. CU/ARD - WIRE (PVC) | E2: WOOD | H2: 0 | J2: Copper | K2: 866 | L2: 222 | M2: 192252 | P2: 0 | T2: 0 | V2: Type C PVC (HR) | W2: 103.71 | X2: 130 | Y2: 13482.3 | Z2: POLY TAPE | AA2: 120 | AB2: 5 | AC2: 600 | AD2: PVC Type ST-2 | AE2: 67.67 | AF2: 38 | AG2: 2571.46 | AH2: Galvanised Steel Round Wire | AI2: 82.9 | AJ2: 492 | AK2: 40786.8 | AL2: FRLSH PVC Type ST-2 | AM2: 87.1 | AN2: 166 | AO2: 14458.6 | AR2: 0 | AV2: 0 | AZ2: 0 | BD2: 0 | BH2: 0 | BL2: 28 | BP2: 0 | BT2: 0 | BX2: 0 | BZ2: 5100 | CA2: 269251.16 | CH2: 269251.16 | CM2: 269251.16 | CO2: 269251.16 | CP2: 0.18 | CQ2: 48465.21 | CR2: 317716.37 | CS2: 63.965 | CT2: KMS | CU2: 20322728 | CV2: MD0100066 | CW2: DRUM - 40 X 15 X 23 X 2 | CX2: 500
A3: ENQ-15115-22-23 | B3: 45698 | C3: FA0200003 | D3: 12 CORE X 2.5 SQ. MM. CU/ARD - WIRE (PVC) | E3: WOOD | H3: 0 | J3: Copper | K3: 866 | L3: 266 | M3: 230356 | P3: 0 | T3: 0 | V3: Type C PVC (HR) | W3: 103.71 | X3: 156 | Y3: 16178.76 | Z3: POLY TAPE | AA3: 120 | AB3: 6 | AC3: 720 | AD3: PVC Type ST-2 | AE3: 67.67 | AF3: 40 | AG3: 2706.8 | AH3: Galvanised Steel Round Wire | AI3: 82.9 | AJ3: 508 | AK3: 42113.2 | AL3: FRLSH PVC Type ST-2 | AM3: 87.1 | AN3: 170 | AO3: 14807 | AR3: 0 | AV3: 0 | AZ3: 0 | BD3: 0 | BH3: 0 | BL3: 28 | BP3: 0 | BT3: 0 | BX3: 0 | BZ3: 5100 | CA3: 311981.76 | CH3: 311981.76 | CM3: 311981.76 | CO3: 311981.76 | CP3: 0.18 | CQ3: 56156.72 | CR3: 368138.48 | CS3: 26 | CT3: KMS | CU3: 9571600 | CV3: MD0100066 | CW3: DRUM - 40 X 15 X 23 X 2 | CX3: 500
A4: ENQ-15115-22-23 | B4: 45698 | C4: FA0200005 | D4: 16 CORE X 2.5 SQ. MM. CU/ARD - WIRE (PVC) | E4: WOOD | H4: 0 | J4: Copper | K4: 866 | L4: 355 | M4: 307430 | P4: 0 | T4: 0 | V4: Type C PVC (HR) | W4: 103.71 | X4: 208 | Y4: 21571.68 | Z4: POLY TAPE | AA4: 120 | AB4: 6 | AC4: 720 | AD4: PVC Type ST-2 | AE4: 67.67 | AF4: 46 | AG4: 3112.82 | AH4: Galvanised Steel Round Wire | AI4: 82.9 | AJ4: 574 | AK4: 47584.6 | AL4: FRLSH PVC Type ST-2 | AM4: 87.1 | AN4: 187 | AO4: 16287.7 | AR4: 0 | AV4: 0 | AZ4: 0 | BD4: 0 | BH4: 0 | BL4: 0 | BP4: 0 | BT4: 0 | BX4: 0 | BZ4: 7984 | CA4: 404690.8 | CH4: 404690.8 | CM4: 404690.8 | CO4: 404690.8 | CP4: 0.18 | CQ4: 72844.34 | CR4: 477535.14 | CS4: 13 | CT4: KMS | CU4: 6207957 | CV4: MD0100075 | CW4: DRUM - 42 X 15 X 23 X 2 | CX4: 500
A5: ENQ-15115-22-23 | B5: 45698 | C5: FA0200011 | D5: 4 CORE X 2.5 SQ. MM. CU/ARD - WIRE (PVC) | E5: WOOD | H5: 0 | J5: Copper | K5: 866 | L5: 89 | M5: 77074 | P5: 0 | T5: 0 | V5: Type C PVC (HR) | W5: 103.71 | X5: 52 | Y5: 5392.92 | Z5: POLY TAPE | AA5: 120 | AB5: 3 | AC5: 360 | AD5: PVC Type ST-2 | AE5: 67.67 | AF5: 27 | AG5: 1827.09 | AH5: Galvanised Steel Round Wire | AI5: 82.9 | AJ5: 289 | AK5: 23958.1 | AL5: FRLSH PVC Type ST-2 | AM5: 87.1 | AN5: 104 | AO5: 9058.4 | AR5: 0 | AV5: 0 | AZ5: 0 | BD5: 0 | BH5: 0 | BL5: 19 | BP5: 0 | BT5: 0 | BX5: 0 | BZ5: 4858 | CA5: 122528.51 | CH5: 122528.51 | CM5: 122528.51 | CO5: 122528.51 | CP5: 0.18 | CQ5: 22055.13 | CR5: 144583.64 | CS5: 56.67 | CT5: KMS | CU5: 8193555 | CV5: MD0100005 | CW5: DRUM - 36 X 14 X 23 X 2 | CX5: 500
A6: ENQ-15115-22-23 | B6: 45698 | C6: FA0200018 | D6: 7 CORE X 2.5 SQ. MM. CU/ARD - WIRE (PVC) | E6: WOOD | H6: 0 | J6: Copper | K6: 866 | L6: 155 | M6: 134230 | P6: 0 | T6: 0 | V6: Type C PVC (HR) | W6: 103.71 | X6: 91 | Y6: 9437.61 | Z6: POLY TAPE | AA6: 120 | AB6: 4 | AC6: 480 | AD6: PVC Type ST-2 | AE6: 67.67 | AF6: 30 | AG6: 2030.1 | AH6: Galvanised Steel Round Wire | AI6: 82.9 | AJ6: 339 | AK6: 28103.1 | AL6: FRLSH PVC Type ST-2 | AM6: 87.1 | AN6: 120 | AO6: 10452 | AR6: 0 | AV6: 0 | AZ6: 0 | BD6: 0 | BH6: 0 | BL6: 22 | BP6: 0 | BT6: 0 | BX6: 0 | BZ6: 4858 | CA6: 189590.81 | CH6: 189590.81 | CM6: 189590.81 | CO6: 189590.81 | CP6: 0.18 | CQ6: 34126.35 | CR6: 223717.16 | CS6: 98.845 | CT6: KMS | CU6: 22113322 | CV6: MD0100005 | CW6: DRUM - 36 X 14 X 23 X 2 | CX6: 500
A7: ENQ-15115-22-23 | B7: 45698 | C7: FA0500017 | D7: 1 CORE X 50 SQ. MM. AL/UNARD. (XLPE) | E7: WOOD | H7: 0 | J7: Alumimium | K7: 272.36 | L7: 135 | M7: 36768.6 | P7: 0 | T7: 0 | V7: LT-XLPE | W7: 114 | X7: 37 | Y7: 4218 | AB7: 0 | AF7: 0 | AJ7: 0 | AL7: FRLSH PVC Type ST-2 | AM7: 87.1 | AN7: 110 | AO7: 9581 | AR7: 0 | AV7: 0 | AZ7: 0 | BD7: 0 | BH7: 0 | BL7: 0 | BP7: 0 | BT7: 0 | BX7: 0 | BZ7: 2429 | CA7: 52996.6 | CH7: 52996.6 | CM7: 52996.6 | CO7: 52996.6 | CP7: 0.18 | CQ7: 9539.39 | CR7: 62535.99 | CS7: 24.06 | CT7: KMS | CU7: 1504616 | CV7: MD0100005 | CW7: DRUM - 36 X 14 X 23 X 2 | CX7: 1000
A8: ENQ-15115-22-23 | B8: 45698 | C8: FA0600013 | D8: 1 CORE X 95 SQ. MM. AL/UNARD(XLPE ) | E8: WOOD | H8: 0 | J8: Alumimium | K8: 272.36 | L8: 256 | M8: 69724.16 | P8: 0 | T8: 0 | V8: LT-XLPE | W8: 114 | X8: 53 | Y8: 6042 | AB8: 0 | AF8: 0 | AJ8: 0 | AL8: FRLSH PVC Type ST-2 | AM8: 87.1 | AN8: 139 | AO8: 12106.9 | AR8: 0 | AV8: 0 | AZ8: 0 | BD8: 0 | BH8: 0 | BL8: 0 | BP8: 0 | BT8: 0 | BX8: 0 | BZ8: 2550 | CA8: 90423.06 | CH8: 90423.06 | CM8: 90423.06 | CO8: 90423.06 | CP8: 0.18 | CQ8: 16276.15 | CR8: 106699.21 | CS8: 77.532 | CT8: KMS | CU8: 8272603 | CV8: MD0100066 | CW8: DRUM - 40 X 15 X 23 X 2 | CX8: 1000
A9: ENQ-15115-22-23 | B9: 45698 | C9: FA0600019 | D9: 1 CORE X 150 SQ. MM. AL/UNARD. (XLPE) | E9: WOOD | H9: 0 | J9: Alumimium | K9: 272.36 | L9: 405 | M9: 110305.8 | P9: 0 | T9: 0 | V9: LT-XLPE | W9: 114 | X9: 72 | Y9: 8208 | AB9: 0 | AF9: 0 | AJ9: 0 | AL9: FRLSH PVC Type ST-2 | AM9: 87.1 | AN9: 187 | AO9: 16287.7 | AR9: 0 | AV9: 0 | AX9: Water swellable Tape | AY9: 420 | AZ9: 0 | BA9: 0 | BD9: 0 | BH9: 0 | BL9: 0 | BP9: 0 | BT9: 0 | BX9: 0 | BZ9: 3606 | CA9: 138407.5 | CH9: 138407.5 | CM9: 138407.5 | CO9: 138407.5 | CP9: 0.18 | CQ9: 24913.35 | CR9: 163320.85 | CS9: 57.308 | CT9: KMS | CU9: 9359591 | CV9: MD0100085 | CW9: DRUM - 43 X 15 X 28 X 2.25 | CX9: 1000
A10: ENQ-15115-22-23 | B10: 45698 | C10: FA0600020 | D10: 1 CORE X 300 SQ. MM. AL/UNARD. (XLPE) | E10: WOOD | H10: 0 | J10: Alumimium | K10: 272.36 | L10: 810 | M10: 220611.6 | P10: 0 | T10: 0 | V10: LT-XLPE | W10: 114 | X10: 132 | Y10: 15048 | AB10: 0 | AF10: 0 | AJ10: 0 | AL10: FRLSH PVC Type ST-2 | AM10: 87.1 | AN10: 251 | AO10: 21862.1 | AR10: 0 | AV10: 0 | AX10: Water swellable Tape | AY10: 420 | AZ10: 0 | BA10: 0 | BD10: 0 | BH10: 0 | BL10: 0 | BP10: 0 | BT10: 0 | BX10: 0 | BZ10: 6276 | CA10: 263797.7 | CH10: 263797.7 | CM10: 263797.7 | CO10: 263797.7 | CP10: 0.18 | CQ10: 47483.59 | CR10: 311281.29 | CS10: 73.052 | CT10: KMS | CU10: 22739721 | CV10: MD0100017 | CW10: DRUM - 52 X 18 X 36 X 2.5 | CX10: 1000
A11: ENQ-15115-22-23 | B11: 45698 | C11: FA0600021 | D11: 1 CORE X 185 SQ. MM. AL/UNARD. (XLPE) | E11: WOOD | H11: 0 | J11: Alumimium | K11: 272.36 | L11: 500 | M11: 136180 | P11: 0 | T11: 0 | V11: LT-XLPE | W11: 114 | X11: 90 | Y11: 10260 | AB11: 0 | AF11: 0 | AJ11: 0 | AL11: FRLSH PVC Type ST-2 | AM11: 87.1 | AN11: 207 | AO11: 18029.7 | AR11: 0 | AV11: 0 | AX11: Water swellable Tape | AY11: 420 | AZ11: 0 | BA11: 0 | BD11: 0 | BH11: 0 | BL11: 0 | BP11: 0 | BT11: 0 | BX11: 0 | BZ11: 3881 | CA11: 168350.7 | CH11: 168350.7 | CM11: 168350.7 | CO11: 168350.7 | CP11: 0.18 | CQ11: 30303.13 | CR11: 198653.83 | CS11: 35.75 | CT11: KMS | CU11: 7101874 | CV11: MD0100090 | CW11: DRUM - 43 X 15 X 36 X 2.5 | CX11: 1000
A12: ENQ-15115-22-23 | B12: 45698 | C12: FA0600032 | D12: 1 CORE X 630 SQ. MM. ALU/UNARD (XLPE) | E12: WOOD | H12: 0 | J12: Alumimium | K12: 272.36 | L12: 1701 | M12: 463284.36 | P12: 0 | T12: 0 | V12: LT-XLPE | W12: 114 | X12: 253 | Y12: 28842 | AB12: 0 | AF12: 0 | AJ12: 0 | AL12: FRLSH PVC Type ST-2 | AM12: 87.1 | AN12: 429 | AO12: 37365.9 | AR12: 0 | AV12: 0 | AX12: Water swellable Tape | AY12: 420 | AZ12: 0 | BA12: 0 | BD12: 0 | BH12: 0 | BL12: 0 | BP12: 0 | BT12: 0 | BX12: 0 | BZ12: 13815 | CA12: 543307.26 | CH12: 543307.26 | CM12: 543307.26 | CO12: 543307.26 | CP12: 0.18 | CQ12: 97795.31 | CR12: 641102.57 | CS12: 33.704 | CT12: KMS | CU12: 21607721 | CV12: MD0100062 | CW12: DRUM - 74 X 24 X 32 X 3 | CX12: 1000
A13: ENQ-15115-22-23 | B13: 45698 | C13: FA0800001 | D13: 1 CORE X 16 SQ. MM. AL/ARD. (XLPE) | H13: 0 | L13: 43 | P13: 0 | T13: 0 | X13: 22 | AB13: 0 | AF13: 0 | AJ13: 61 | AN13: 85 | AR13: 0 | AV13: 0 | AZ13: 0 | BD13: 0 | BH13: 0 | BL13: 0 | BP13: 0 | BT13: 0 | BX13: 0 | CP13: 0.18 | CS13: 0.5 | CT13: KMS | CX13: 1000
A14: ENQ-15115-22-23 | B14: 45698 | C14: FA0900020 | D14: 2 CORE X 6 SQ. MM. AL/ARD - WIRE (XLPE) | E14: WOOD | H14: 0 | J14: Alumimium | K14: 272.36 | L14: 32 | M14: 8715.52 | P14: 0 | T14: 0 | V14: LT-XLPE | W14: 114 | X14: 22 | Y14: 2508 | AB14: 0 | AD14: PVC Type ST-2-PRESSURE EXTRUDED | AE14: 88.1 | AF14: 59 | AG14: 5197.9 | AH14: Galvanised Steel Round Wire | AI14: 82.9 | AJ14: 289 | AK14: 23958.1 | AL14: FRLSH PVC Type ST-2 | AM14: 87.1 | AN14: 112 | AO14: 9755.2 | AR14: 0 | AV14: 0 | AZ14: 0 | BD14: 0 | BH14: 0 | BL14: 0 | BP14: 0 | BR14: RUBBERIZED COTTON TAPE | BS14: 370 | BT14: 0 | BU14: 0 | BX14: 0 | BZ14: 2550 | CA14: 52684.72 | CH14: 52684.72 | CM14: 52684.72 | CO14: 52684.72 | CP14: 0.18 | CQ14: 9483.25 | CR14: 62167.97 | CS14: 3000 | CT14: KMS | CU14: 186503909 | CV14: MD0100066 | CW14: DRUM - 40 X 15 X 23 X 2 | CX14: 1000
A15: ENQ-15115-22-23 | B15: 45698 | C15: FA0900024 | D15: 4 CORE X 4 SQ. MM. CU/ARD - WIRE (PVC) | E15: WOOD | H15: 0 | J15: Copper | K15: 866 | L15: 144 | M15: 124704 | P15: 0 | T15: 0 | V15: Type C PVC (HR) | W15: 103.71 | X15: 76 | Y15: 7881.96 | Z15: POLY TAPE | AA15: 120 | AB15: 4 | AC15: 480 | AD15: PVC Type ST-2 | AE15: 67.67 | AF15: 34 | AG15: 2300.78 | AH15: Galvanised Steel Round Wire | AI15: 82.9 | AJ15: 352 | AK15: 29180.8 | AL15: FRLSH PVC Type ST-2 | AM15: 87.1 | AN15: 119 | AO15: 10364.9 | AR15: 0 | AV15: 0 | AZ15: 0 | BD15: 0 | BH15: 0 | BL15: 0 | BP15: 0 | BT15: 0 | BX15: 0 | BZ15: 2550 | CA15: 177462.44 | CH15: 177462.44 | CM15: 177462.44 | CO15: 177462.44 | CP15: 0.18 | CQ15: 31943.24 | CR15: 209405.68 | CS15: 1 | CT15: KMS | CU15: 209406 | CV15: MD0100066 | CW15: DRUM - 40 X 15 X 23 X 2 | CX15: 1000
A16: ENQ-15115-22-23 | B16: 45698 | C16: FA0900041 | D16: 2 CORE X 4 SQ. MM. AL/ARD - WIRE (XLPE) | E16: WOOD | H16: 0 | J16: Alumimium | K16: 272.36 | L16: 22 | M16: 5991.92 | P16: 0 | T16: 0 | V16: LT-XLPE | W16: 114 | X16: 19 | Y16: 2166 | AB16: 4 | AD16: PVC Type ST-2 | AE16: 67.67 | AF16: 47 | AG16: 3180.49 | AH16: Galvanised Steel Round Wire | AI16: 82.9 | AJ16: 264 | AK16: 21885.6 | AL16: FRLSH PVC Type ST-2 | AM16: 87.1 | AN16: 100 | AO16: 8710 | AR16: 0 | AV16: 0 | AZ16: 0 | BD16: 0 | BH16: 0 | BL16: 0 | BP16: 0 | BT16: 0 | BX16: 0 | BZ16: 2550 | CA16: 44484.01 | CH16: 44484.01 | CM16: 44484.01 | CO16: 44484.01 | CP16: 0.18 | CQ16: 8007.12 | CR16: 52491.13 | CS16: 2077.047 | CT16: KMS | CU16: 109026548 | CV16: MD0100066 | CW16: DRUM - 40 X 15 X 23 X 2 | CX16: 1000
A17: ENQ-15115-22-23 | B17: 45698 | C17: FA0900042 | D17: 2 CORE X 10 SQ. MM. ALU/ARD - WIRE (XLPE) | E17: WOOD | H17: 0 | J17: Alumimium | K17: 272.36 | L17: 54 | M17: 14707.44 | P17: 0 | T17: 0 | V17: LT-XLPE | W17: 114 | X17: 26 | Y17: 2964 | AB17: 0 | AD17: PVC Type ST-2-PRESSURE EXTRUDED | AE17: 88.1 | AF17: 74 | AG17: 6519.4 | AH17: Galvanised Steel Round Wire | AI17: 82.9 | AJ17: 340 | AK17: 28186 | AL17: FRLSH PVC Type ST-2 | AM17: 87.1 | AN17: 127 | AO17: 11061.7 | AR17: 0 | AV17: 0 | AZ17: 0 | BD17: 0 | BH17: 0 | BL17: 0 | BP17: 0 | BR17: RUBBERIZED COTTON TAPE | BS17: 370 | BT17: 0 | BU17: 0 | BX17: 0 | BZ17: 3992 | CA17: 67430.54 | CH17: 67430.54 | CM17: 67430.54 | CO17: 67430.54 | CP17: 0.18 | CQ17: 12137.5 | CR17: 79568.04 | CS17: 123.04 | CT17: KMS | CU17: 9790051 | CV17: MD0100075 | CW17: DRUM - 42 X 15 X 23 X 2 | CX17: 1000
A18: ENQ-15115-22-23 | B18: 45698 | C18: FA0900111 | D18: 4 CORE X 25 SQ. MM. ALU/ARD - WIRE (XLPE) | E18: WOOD | H18: 0 | J18: Alumimium | K18: 272.36 | L18: 270 | M18: 73537.2 | P18: 0 | T18: 0 | V18: LT-XLPE | W18: 114 | X18: 95 | Y18: 10830 | AB18: 0 | AD18: PVC Type ST-2 | AE18: 67.67 | AF18: 46 | AG18: 3112.82 | AH18: Galvanised Steel Round Wire | AI18: 82.9 | AJ18: 572 | AK18: 47418.8 | AL18: FRLSH PVC Type ST-2 | AM18: 87.1 | AN18: 185 | AO18: 16113.5 | AR18: 0 | AV18: 0 | AZ18: 0 | BD18: 0 | BH18: 0 | BL18: 0 | BP18: 0 | BT18: 0 | BX18: 0 | BZ18: 3881 | CA18: 154893.32 | CH18: 154893.32 | CM18: 154893.32 | CO18: 154893.32 | CP18: 0.18 | CQ18: 27880.8 | CR18: 182774.12 | CS18: 121.208 | CT18: KMS | CU18: 22153685 | CV18: MD0100090 | CW18: DRUM - 43 X 15 X 36 X 2.5 | CX18: 1000
A19: ENQ-15115-22-23 | B19: 45698 | C19: FA0900112 | D19: 4 CORE X 10 SQ. MM. AL/ARD - WIRE (XLPE) | E19: WOOD | H19: 0 | J19: Alumimium | K19: 272.36 | L19: 108 | M19: 29414.88 | P19: 0 | T19: 0 | V19: LT-XLPE | W19: 114 | X19: 64 | Y19: 7296 | AB19: 0 | AD19: PVC Type ST-2 | AE19: 67.67 | AF19: 35 | AG19: 2368.45 | AH19: Galvanised Steel Round Wire | AI19: 82.9 | AJ19: 441 | AK19: 36558.9 | AL19: FRLSH PVC Type ST-2 | AM19: 87.1 | AN19: 151 | AO19: 13152.1 | AR19: 0 | AV19: 0 | AZ19: 0 | BD19: 0 | BH19: 0 | BL19: 0 | BP19: 0 | BT19: 0 | BX19: 0 | BZ19: 4593 | CA19: 93383.33 | CH19: 93383.33 | CM19: 93383.33 | CO19: 93383.33 | CP19: 0.18 | CQ19: 16809 | CR19: 110192.33 | CS19: 136.832 | CT19: KMS | CU19: 15077837 | CV19: MD0100064 | CW19: DRUM - 42 X 15 X 32 X 2 | CX19: 1000
A20: ENQ-15115-22-23 | B20: 45698 | C20: FA0900116 | D20: 4 CORE X 50 SQ. MM. AL/ARD - WIRE (XLPE) | E20: WOOD | H20: 0 | J20: Alumimium | K20: 272.36 | L20: 541 | M20: 147346.76 | P20: 0 | T20: 0 | V20: LT-XLPE | W20: 114 | X20: 124 | Y20: 14136 | AB20: 0 | AD20: PVC Type ST-2 | AE20: 67.67 | AF20: 69 | AG20: 4669.23 | AH20: Galvanised Steel Round Wire | AI20: 82.9 | AJ20: 898 | AK20: 74444.2 | AL20: FRLSH PVC Type ST-2 | AM20: 87.1 | AN20: 260 | AO20: 22646 | AR20: 0 | AV20: 0 | AZ20: 0 | BD20: 0 | BH20: 0 | BL20: 0 | BP20: 0 | BR20: RUBBERIZED COTTON TAPE | BS20: 370 | BT20: 0 | BU20: 0 | BX20: 0 | BZ20: 6254 | CA20: 269496.19 | CH20: 269496.19 | CM20: 269496.19 | CO20: 269496.19 | CP20: 0.18 | CQ20: 48509.31 | CR20: 318005.5 | CS20: 26.605 | CT20: KMS | CU20: 8460536 | CV20: MD0100068 | CW20: DRUM - 54 X 20 X 36 X 2.5 | CX20: 1000
A21: ENQ-15115-22-23 | B21: 45698 | C21: FA0900117 | D21: 4 CORE X 35 SQ. MM. AL/ARD - WIRE (XLPE) | E21: WOOD | H21: 0 | J21: Alumimium | K21: 272.36 | L21: 378 | M21: 102952.08 | P21: 0 | T21: 0 | V21: LT-XLPE | W21: 114 | X21: 109 | Y21: 12426 | AB21: 0 | AD21: PVC Type ST-2 | AE21: 67.67 | AF21: 51 | AG21: 3451.17 | AH21: Galvanised Steel Round Wire | AI21: 82.9 | AJ21: 639 | AK21: 52973.1 | AL21: FRLSH PVC Type ST-2 | AM21: 87.1 | AN21: 230 | AO21: 20033 | AR21: 0 | AV21: 0 | AZ21: 0 | BD21: 0 | BH21: 0 | BL21: 0 | BP21: 0 | BR21: RUBBERIZED COTTON TAPE | BS21: 370 | BT21: 0 | BU21: 0 | BX21: 0 | BZ21: 4139 | CA21: 195974.35 | CH21: 195974.35 | CM21: 195974.35 | CO21: 195974.35 | CP21: 0.18 | CQ21: 35275.38 | CR21: 231249.73 | CS21: 88.208 | CT21: KMS | CU21: 20398076 | CV21: MD0100013 | CW21: DRUM - 48 X 14 X 36 X 2.25 | CX21: 1000
A22: ENQ-15115-22-23 | B22: 45698 | C22: FA0900132 | D22: 4 CORE X 16 SQ. MM. AL/ARD - WIRE (XLPE) | E22: WOOD | H22: 0 | J22: Alumimium | K22: 272.36 | L22: 173 | M22: 47118.28 | P22: 0 | T22: 0 | V22: LT-XLPE | W22: 114 | X22: 75 | Y22: 8550 | AB22: 0 | AD22: PVC Type ST-2 | AE22: 67.67 | AF22: 40 | AG22: 2706.8 | AH22: Galvanised Steel Round Wire | AI22: 82.9 | AJ22: 498 | AK22: 41284.2 | AL22: FRLSH PVC Type ST-2 | AM22: 87.1 | AN22: 166 | AO22: 14458.6 | AR22: 0 | AV22: 0 | AZ22: 0 | BD22: 0 | BH22: 0 | BL22: 0 | BP22: 0 | BR22: RUBBERIZED COTTON TAPE | BS22: 370 | BT22: 0 | BU22: 0 | BX22: 0 | BZ22: 3881 | CA22: 117998.88 | CH22: 117998.88 | CM22: 117998.88 | CO22: 117998.88 | CP22: 0.18 | CQ22: 21239.8 | CR22: 139238.68 | CS22: 1.5 | CT22: KMS | CU22: 208858 | CV22: MD0100090 | CW22: DRUM - 43 X 15 X 36 X 2.5 | CX22: 1000
A23: ENQ-15115-22-23 | B23: 45698 | C23: FA0900133 | D23: 2 CORE X 16 SQ. MM. AL/ARD - WIRE (XLPE) | E23: WOOD | H23: 0 | J23: Alumimium | K23: 272.36 | L23: 86 | M23: 23422.96 | P23: 0 | T23: 0 | V23: LT-XLPE | W23: 114 | X23: 30 | Y23: 3420 | AB23: 0 | AD23: PVC Type ST-2-PRESSURE EXTRUDED | AE23: 88.1 | AF23: 33 | AG23: 2907.3 | AH23: Galvanised Steel Round Wire | AI23: 82.9 | AJ23: 416 | AK23: 34486.4 | AL23: FRLSH PVC Type ST-2 | AM23: 87.1 | AN23: 144 | AO23: 12542.4 | AR23: 0 | AV23: 0 | AZ23: 0 | BD23: 0 | BH23: 0 | BL23: 0 | BP23: 0 | BR23: RUBBERIZED COTTON TAPE | BS23: 370 | BT23: 0 | BU23: 0 | BX23: 0 | BZ23: 4593 | CA23: 81372.06 | CH23: 81372.06 | CM23: 81372.06 | CO23: 81372.06 | CP23: 0.18 | CQ23: 14646.97 | CR23: 96019.03 | CS23: 0.5 | CT23: KMS | CU23: 48010 | CV23: MD0100064 | CW23: DRUM - 42 X 15 X 32 X 2 (LOMBU) | CX23: 1000
A24: ENQ-15115-22-23 | B24: 45698 | C24: FA0900160 | D24: 2 CORE X 50 SQ. MM. AL/ARD - WIRE (XLPE) | E24: WOOD | H24: 0 | J24: Alumimium | K24: 272.36 | L24: 270 | M24: 73537.2 | P24: 0 | T24: 0 | V24: LT-XLPE | W24: 114 | X24: 63 | Y24: 7182 | AB24: 0 | AD24: PVC Type ST-2-PRESSURE EXTRUDED | AE24: 88.1 | AF24: 38 | AG24: 3347.8 | AH24: Galvanised Steel Round Wire | AI24: 82.9 | AJ24: 483 | AK24: 40040.7 | AL24: FRLSH PVC Type ST-2 | AM24: 87.1 | AN24: 184 | AO24: 16026.4 | AR24: 0 | AV24: 0 | AZ24: 0 | BD24: 0 | BH24: 0 | BL24: 0 | BP24: 0 | BR24: RUBBERIZED COTTON TAPE | BS24: 370 | BT24: 0 | BU24: 0 | BX24: 0 | BZ24: 4139 | CA24: 144273.1 | CH24: 144273.1 | CM24: 144273.1 | CO24: 144273.1 | CP24: 0.18 | CQ24: 25969.16 | CR24: 170242.26 | CS24: 0.5 | CT24: KMS | CU24: 85121 | CV24: MD0100013 | CW24: DRUM - 48 X 14 X 36 X 2.25 | CX24: 1000
A25: ENQ-15115-22-23 | B25: 45698 | C25: FA1100091 | D25: 4 CORE X 240 SQ. MM. AL/ARD - WIRE (XLPE) | E25: WOOD | H25: 0 | J25: Alumimium | K25: 272.36 | L25: 2595 | M25: 706774.2 | P25: 0 | T25: 0 | V25: LT-XLPE | W25: 114 | X25: 438 | Y25: 49932 | AB25: 0 | AD25: PVC Type ST-2 | AE25: 67.67 | AF25: 244 | AG25: 16511.48 | AH25: Galvanised Steel Round Wire | AI25: 82.9 | AJ25: 2364 | AK25: 195975.6 | AL25: FRLSH PVC Type ST-2 | AM25: 87.1 | AN25: 735 | AO25: 64018.5 | AR25: 0 | AV25: 0 | AX25: Water swellable Tape | AY25: 420 | AZ25: 0 | BA25: 0 | BD25: 0 | BH25: 0 | BL25: 0 | BP25: 0 | BR25: RUBBERIZED COTTON TAPE | BS25: 370 | BT25: 0 | BU25: 0 | BX25: 0 | BZ25: 40364 | CA25: 1073575.8 | CH25: 1073575.8 | CM25: 1073575.8 | CO25: 1073575.8 | CP25: 0.18 | CQ25: 193243.64 | CR25: 1266819.4 | CS25: 3 | CT25: KMS | CU25: 3800458 | CV25: MD0100048 | CW25: DRUM - 74 X 35 X 39 X 3 | CX25: 500
A26: ENQ-15115-22-23 | B26: 45698 | C26: FA1100094 | D26: 4 CORE X 95 SQ. MM. ALU/ARD - WIRE (XLPE) | E26: WOOD | H26: 0 | J26: Alumimium | K26: 272.36 | L26: 1027 | M26: 279713.72 | P26: 0 | T26: 0 | V26: LT-XLPE | W26: 114 | X26: 187 | Y26: 21318 | AB26: 0 | AD26: PVC Type ST-2 | AE26: 67.67 | AF26: 93 | AG26: 6293.31 | AH26: Galvanised Steel Round Wire | AI26: 82.9 | AJ26: 1200 | AK26: 99480 | AL26: FRLSH PVC Type ST-2 | AM26: 87.1 | AN26: 370 | AO26: 32227 | AR26: 0 | AV26: 0 | AZ26: 0 | BD26: 0 | BH26: 0 | BL26: 0 | BP26: 0 | BR26: RUBBERIZED COTTON TAPE | BS26: 370 | BT26: 0 | BU26: 0 | BX26: 0 | BZ26: 14928 | CA26: 453960.03 | CH26: 453960.03 | CM26: 453960.03 | CO26: 453960.03 | CP26: 0.18 | CQ26: 81712.81 | CR26: 535672.84 | CS26: 17.586 | CT26: KMS | CU26: 9420342 | CV26: MD0100061 | CW26: DRUM - 56 X 24 X 32 X 3 | CX26: 500
A27: ENQ-15115-22-23 | B27: 45698 | C27: FA1100176 | D27: 4 CORE X 300 SQ. MM. AL/ARD - WIRE (XLPE) | E27: STEEL | H27: 0 | J27: Alumimium | K27: 272.36 | L27: 3240 | M27: 882446.4 | P27: 0 | T27: 0 | V27: LT-XLPE | W27: 114 | X27: 488 | Y27: 55632 | AB27: 0 | AD27: PVC Type ST-2 | AE27: 67.67 | AF27: 255 | AG27: 17255.85 | AH27: Galvanised Steel Round Wire | AI27: 82.9 | AJ27: 3436 | AK27: 284844.4 | AL27: FRLSH PVC Type ST-2 | AM27: 87.1 | AN27: 888 | AO27: 77344.8 | AR27: 0 | AV27: 0 | AX27: Water swellable Tape | AY27: 420 | AZ27: 0 | BA27: 0 | BD27: 90 | BH27: 0 | BL27: 0 | BP27: 0 | BR27: RUBBERIZED COTTON TAPE | BS27: 370 | BT27: 36 | BU27: 13320 | BX27: 0 | BZ27: 78780 | CA27: 1409623.4 | CH27: 1409623.4 | CM27: 1409623.4 | CO27: 1409623.4 | CP27: 0.18 | CQ27: 253732.22 | CR27: 1663355.7 | CS27: 29 | CT27: KMS | CU27: 48237314 | CV27: SP0400139 | CW27: CORRUGATED DISPATCH STEEL DRUM 2130 X 890 X 965 | CX27: 500
A28: ENQ-15115-22-23 | B28: 45698 | C28: FA1100177 | D28: 4 CORE X 150 SQ. MM. AL/ARD - WIRE (XLPE) | E28: WOOD | H28: 0 | J28: Alumimium | K28: 272.36 | L28: 1620 | M28: 441223.2 | P28: 0 | T28: 0 | V28: LT-XLPE | W28: 114 | X28: 276 | Y28: 31464 | AB28: 0 | AD28: PVC Type ST-2 | AE28: 67.67 | AF28: 148 | AG28: 10015.16 | AH28: Galvanised Steel Round Wire | AI28: 82.9 | AJ28: 1965 | AK28: 162898.5 | AL28: FRLSH PVC Type ST-2 | AM28: 87.1 | AN28: 543 | AO28: 47295.3 | AR28: 0 | AV28: 0 | AX28: Water swellable Tape | AY28: 420 | AZ28: 0 | BA28: 0 | BD28: 48 | BH28: 0 | BL28: 0 | BP28: 0 | BR28: RUBBERIZED COTTON TAPE | BS28: 370 | BT28: 26 | BU28: 9620 | BX28: 0 | BZ28: 21178 | CA28: 723694.16 | CH28: 723694.16 | CM28: 723694.16 | CO28: 723694.16 | CP28: 0.18 | CQ28: 130264.95 | CR28: 853959.11 | CS28: 6.866 | CT28: KMS | CU28: 5863283 | CV28: MD0100024 | CW28: DRUM - 70 X 30 X 36 X 3 | CX28: 500

Sheet AUTO CALCULATION SHEET (2)
C2: TPCODL TPNODL TPSODL TPWODL (TATA Power and Odisha Government Joint Venture)
C4: TENDER SPECIFICATION NO () | D4: TPCODL / CCG / FY 25-26 / 1000001917
C5: TENDER DESCRIPTION () | D5: One Year Rate Contract for Supply of 1.1 kV Power and Control Cables at TPWODL, TPCODL & TPSODL.
C6: Last Date & Time of Submission () | D6: 15/Feb/2025 [17:00 Hrs.]
C7: REVERSE AUCTION | D7: Bidders shall be allowed to participate in Reverse auction as per following criteria hence bidders are advised to quote their most competitive rates while submitting the bids to avoid disqualification from participation in Reverse Auction. No of bidders allowed to participate in RA process shall be: Total No of bidders on whom tender would be split PLUS 2 more bidders.
C8: Price () | D8: Base circular shall be January 2025 circular issued in february 2025. Base month for Bid Price shall remain same throughout the negotiation process till Outline Agreement / Rate Contract is finalized.Base month circular has to be attached in the price bid.
C9: Validity () | D9: Bids shall remain valid for 180 days from the due date of submission of the bid.
C10: Delivery Period () | D10: Delivery Period shall be Delivery period shall be 60 + 7 days (considering the approval of CAT-A / drawing / GTP) from date of receipt of release order for the first lot however for remaining lots the delivery period will be 60 days from RO date. Exact delivery location shall be specified in the Release Order. Delivery will be the store locations in TPCODL, TPNODL and TPWODL based on RO Qty.The delivery period for a quantity of up to 200 KM shall be 60 days from the date of issuance of the RO or GTP drawing approval, whichever is later. For quantities exceeding 200 KM, the delivery period shall be mutually agreed upon between the BA and the DISCOM.
C11: Payment Terms () | D11: On delivery of the materials in good condition and certification of acceptance by certified official, Associate shall submit the Bills/ Invoices in original in the name of respective Odisha discom to Invoice Desk. The payment shall be released within 45 days from the date of submission of error free certified bills/ invoices. Any change in statutory taxes, duties and levies during the contract period shall be borne by respective Odisha DISCOMs. However, in case of delay in work execution owing to reasons not attributable to Odisha Disom, any increase in total liability shall be passed on the Bidder, whereas any benefits arising owing to such statutory variation in taxes and duties shall be passed on TP Discom.
C12: Standard length () | D12: Cable length on one drum shall be: (a) 4 Core Cable – 95 sq.mm. to 300 sq.mm. – 500 meters with + 5% tolerance (b) 4 Core Cable – 16 sq.mm. to 50 sq.mm. – 1000 meters with + 5% tolerance (c) 2 Core & 1 Core Cables – 1000 meters with + 5% tolerance (as per PO terms and conditions)
C13: Packing () | D13: Wooden drums shall be free from sharp edges and visual defects
C14: Technical Specification
P16: =Sheet1!J1 -> Conductor | U16: AL ALLOY | W16: Insulation Screening (Metallic) | AE16: Insulation Screening (Non-Metallic) | AG16: Insulation | AM16: POLY TAPE | AN16: Inner Sheath | AU16: Armouring | BE16: UV resistance RS-5/kg | BO16: FILLER | BP16: GREASE | BQ16: Water swellable Tape | BR16: Semi conducting Water Swellable tape | BS16: SEMICON TAPE | BT16: GLASS FIBER TAPE | BU16: COPPER WIRE 0.8 MM | BV16: RUBBERIZED COTTON TAPE | BW16: Water Tight Compound | CB16: DRUM COST PER KM | CC16: TOTAL RM COST | CD16: EXTRA CONSUMPTION | CE16: EXTRA CONSUMPTION VALUE
C17: DOCKET NO. | D17: =Sheet1!B1 -> Base Date | E17: ITEM CODE | F17: PROPOSE ERP ITEM NAME | G17: EX-WORKS (PER KM) | H17: FREIGHT PER KM | I17: PRICE INCLUDING FREIGHT (PER KM) | J17: GST % | K17: GST VALUE | L17: PRICE INCLUDING GST & FREIGHT (PER KM) | M17: QTY | N17: Unit | O17: TOTAL PRICE OF FULL QTY (INCLUDING FRIGHT & GST) | P17: Alumimium | Q17: Alumimium ALLOY | R17: Copper | S17: Flexible Copper | T17: Galvanized steel wire | U17: Alumimium | V17: Alumimium ALLOY | W17: Coper tape - 0.1 mm | X17: Copper Tape - 0.03 mm | Y17: Copper Tape - 0.035 mm | Z17: Copper Tape - 0.04 mm | AA17: Copper Tape - 0.045 mm | AB17: Copper Tape - 0.050 mm | AC17: Copper Tape - 0.060 mm | AD17: Copper Tape - 0.075 mm(DOUBLE) | AE17: Extruded semiconductive | AF17: Extruded Semiconductive(Stripable) | AG17: HT-XLPE | AH17: LT-XLPE | AI17: TR XLPE | AJ17: Type A PVC | AK17: Type C PVC (HR) | AL17: XLPE | AM17: POLY TAPE | AN17: FR PVC Type ST-1 | AO17: FR PVC Type ST-2 | AP17: FRLSH PVC Type ST-2 | AQ17: PVC Type ST-1 | AR17: PVC Type ST-1-PRESSURE EXTRUDED | AS17: PVC Type ST-2 | AT17: PVC Type ST-2-PRESSURE EXTRUDED | AU17: ACSR CORE WIRE | AV17: ACSR DOG STEEL WIRE | AW17: Aluminium Flat Strip | AX17: Aluminium Round Wire | AY17: Double Steel Tape | AZ17: Galvanised Steel Flat Strip | BA17: Galvanised Steel Flat Strip (Double) | BB17: Galvanised Steel Flat Strip-B | BC17: Galvanised Steel Round Wire | BD17: Galvanised Steel Round Wire (Double) | BE17: FR PVC Type ST-1 | BF17: FR PVC Type ST-2 | BG17: FRLSH PVC Type ST-1 | BH17: FRLSH PVC Type ST-2 | BI17: PE, ST-3 | BJ17: PE, ST-7 | BK17: PVC Type ST-1 | BL17: PVC Type ST-2 | BM17: PVC Type ST-2-PRESSURE EXTRUDED | BN17: UV & Track Resistant XLPE | BO17: FILLER | BP17: Grease | BQ17: NCWBT | BR17: Semi conducting Water Swellable tape | BS17: SEMICON TAPE | BT17: GLASS FIBER TAPE | BU17: COPPER WIRE 0.8 MM | BV17: RUBBERIZED COTTON TAPE | BW17: Water Tight Compound | BX17: =Sheet1!E1 -> Propose Drum Type | BY17: =Sheet1!CV1 -> DRUM CODE | BZ17: =Sheet1!CW1 -> DRUM SIZE (FxbXtx Ft) | CA17: =Sheet1!CX1 -> Party Standard Length(MTR) | CD17: 1% extra cost | CF17: MFG% | CG17: MFG VALUE | CH17: PROF% | CI17: PROFIT VALUE | CJ17: 1ST EX-WORKS | CK17: Intt % | CL17: INTT VALUE | CM17: insp% | CN17: INSP VALUE
P18: 262 | R18: 826 | AH18: 114 | AK18: 103 | AM18: 119 | AS18: 69 | AT18: 88 | BC18: 87 | BH18: =88+5 -> 93 | BQ18: 340 | BV18: 375 | BW18: =+IFERROR(VLOOKUP($BW$17,Sheet1!BV2:BY840,2,0),0) -> 0
B19: 1 | C19: =Sheet1!A8 -> ENQ-15115-22-23 | D19: 45658 | E19: =Sheet1!C8 -> FA0600013 | F19: =Sheet1!D8 -> 1 CORE X 95 SQ. MM. AL/UNARD(XLPE ) | G19: =CJ19+CL19+CN19 -> 104733.78 | H19: =ROUNDUP(O49,0) -> 1321 | I19: =G19+H19 -> 106054.78 | J19: =Sheet1!CP8 -> 0.18 | K19: =I19*J19 -> 19089.86 | L19: =I19+K19 -> 125144.64 | M19: 79.532 | N19: =Sheet1!CT8 -> KMS | O19: =L19*M19 -> 9953003.4 | P19: =+IFERROR(VLOOKUP($P$17,Sheet1!J8:L8,3,0),0) -> 256 | Q19: =+IFERROR(VLOOKUP($Q$17,Sheet1!J8:L8,3,0),0) -> 0 | R19: =+IFERROR(VLOOKUP($R$17,Sheet1!J8:M8,3,0),0) -> 0 | S19: =+IFERROR(VLOOKUP($S$17,Sheet1!J8:M8,3,0),0) -> 0 | T19: =+IFERROR(VLOOKUP($T$17,Sheet1!J8:M8,3,0),0) -> 0 | U19: =+IFERROR(VLOOKUP($U$17,Sheet1!N8:Q8,3,0),0) -> 0 | V19: =+IFERROR(VLOOKUP($V$17,Sheet1!N8:Q8,3,0),0) -> 0 | W19: =+IFERROR(VLOOKUP($W$17,Sheet1!F8:I8,3,0),0) -> 0 | X19: =+IFERROR(VLOOKUP($X$17,Sheet1!F8:I8,3,0),0) -> 0 | Y19: =+IFERROR(VLOOKUP($Y$17,Sheet1!F8:I8,3,0),0) -> 0 | Z19: =+IFERROR(VLOOKUP($Z$17,Sheet1!F8:I8,3,0),0) -> 0 | AA19: =+IFERROR(VLOOKUP($AA$17,Sheet1!F8:I8,3,0),0) -> 0 | AB19: =+IFERROR(VLOOKUP($AB$17,Sheet1!F8:I8,3,0),0) -> 0 | AC19: =+IFERROR(VLOOKUP($AC$17,Sheet1!F8:I8,3,0),0) -> 0 | AD19: =+IFERROR(VLOOKUP($AD$17,Sheet1!F8:I8,3,0),0) -> 0 | AE19: =+IFERROR(VLOOKUP($AE$17,Sheet1!R8:U8,3,0),0) -> 0 | AF19: =+IFERROR(VLOOKUP($AF$17,Sheet1!R8:U8,2,0),0) -> 0 | AG19: =+IFERROR(VLOOKUP($AG$17,Sheet1!V8:Y8,3,0),0) -> 0 | AH19: 44 | AI19: =+IFERROR(VLOOKUP($AI$17,Sheet1!V8:Y8,3,0),0) -> 0 | AJ19: =+IFERROR(VLOOKUP($AJ$17,Sheet1!V8:Y8,3,0),0) -> 0 | AK19: =+IFERROR(VLOOKUP($AK$17,Sheet1!V8:Y8,3,0),0) -> 0 | AL19: =+IFERROR(VLOOKUP($AL$17,Sheet1!V8:Y8,3,0),0) -> 0 | AM19: =+IFERROR(VLOOKUP($AM$17,Sheet1!Z8:AB8,3,0),0) -> 0 | AN19: =+IFERROR(VLOOKUP($AN$17,Sheet1!AD8:AG8,3,0),0) -> 0 | AO19: =+IFERROR(VLOOKUP($AO$17,Sheet1!AD8:AG8,3,0),0) -> 0 | AP19: =+IFERROR(VLOOKUP($AP$17,Sheet1!AD8:AG8,3,0),0) -> 0 | AQ19: =+IFERROR(VLOOKUP($AQ$17,Sheet1!AD8:AG8,3,0),0) -> 0 | AR19: =+IFERROR(VLOOKUP($AR$17,Sheet1!AD8:AG8,3,0),0) -> 0 | AS19: =+IFERROR(VLOOKUP($AS$17,Sheet1!AD8:AG8,3,0),0) -> 0 | AT19: =+IFERROR(VLOOKUP($AT$17,Sheet1!AD8:AG8,3,0),0) -> 0 | AU19: =+IFERROR(VLOOKUP($AU$17,Sheet1!AH8:AK8,3,0),0) -> 0 | AV19: =+IFERROR(VLOOKUP($AV$17,Sheet1!AH8:AK8,3,0),0) -> 0 | AW19: =+IFERROR(VLOOKUP($AW$17,Sheet1!AH8:AK8,3,0),0) -> 0 | AX19: =+IFERROR(VLOOKUP($AX$17,Sheet1!AH8:AK8,3,0),0) -> 0 | AY19: =+IFERROR(VLOOKUP($AY$17,Sheet1!AH8:AK8,3,0),0) -> 0 | AZ19: =+IFERROR(VLOOKUP($AZ$17,Sheet1!AH8:AK8,3,0),0) -> 0 | BA19: =+IFERROR(VLOOKUP($BA$17,Sheet1!AH8:AK8,3,0),0) -> 0 | BB19: =+IFERROR(VLOOKUP($BB$17,Sheet1!AH8:AK8,3,0),0) -> 0 | BC19: =+IFERROR(VLOOKUP($BC$17,Sheet1!AH8:AK8,3,0),0) -> 0 | BD19: =+IFERROR(VLOOKUP($BD$17,Sheet1!AH8:AK8,3,0),0) -> 0 | BE19: =+IFERROR(VLOOKUP($BE$17,Sheet1!AL8:AO8,3,0),0) -> 0 | BF19: =+IFERROR(VLOOKUP($BF$17,Sheet1!AL8:AO8,3,0),0) -> 0 | BG19: =+IFERROR(VLOOKUP($BG$17,Sheet1!AL8:AO8,3,0),0) -> 0 | BH19: 140 | BI19: =+IFERROR(VLOOKUP($BI$17,Sheet1!AL8:AO8,3,0),0) -> 0 | BJ19: =+IFERROR(VLOOKUP($BJ$17,Sheet1!AL8:AO8,3,0),0) -> 0 | BK19: =+IFERROR(VLOOKUP($BK$17,Sheet1!AL8:AO8,3,0),0) -> 0 | BL19: =+IFERROR(VLOOKUP($BL$17,Sheet1!AL8:AO8,3,0),0) -> 0 | BM19: =+IFERROR(VLOOKUP($BM$17,Sheet1!AL8:AO8,3,0),0) -> 0 | BN19: =+IFERROR(VLOOKUP($BN$17,Sheet1!AL8:AO8,3,0),0) -> 0 | BO19: =+IFERROR(VLOOKUP($BO$17,Sheet1!AP8:AS8,3,0),0) -> 0 | BP19: =+IFERROR(VLOOKUP($BP$17,Sheet1!AT8:AW8,3,0),0) -> 0 | BQ19: =+IFERROR(VLOOKUP($BQ$17,Sheet1!AX8:BA8,3,0),0) -> 0 | BR19: =+IFERROR(VLOOKUP($BR$17,Sheet1!BB8:BE8,3,0),0) -> 0 | BS19: =+IFERROR(VLOOKUP($BS$17,Sheet1!BF8:BI8,3,0),0) -> 0 | BT19: =+IFERROR(VLOOKUP($BT$17,Sheet1!BJ8:BM8,3,0),0) -> 0 | BU19: =+IFERROR(VLOOKUP($BU$17,Sheet1!BN8:BQ8,3,0),0) -> 0 | BV19: =+IFERROR(VLOOKUP($BV$17,Sheet1!BR8:BU8,3,0),0) -> 0 | BW19: =+IFERROR(VLOOKUP($BW$17,Sheet1!BV8:BY8,3,0),0) -> 0 | BX19: =Sheet1!E8 -> WOOD | BY19: =Sheet1!CV8 -> MD0100066 | BZ19: =Sheet1!CW8 -> DRUM - 40 X 15 X 23 X 2 | CA19: =Sheet1!CX8 -> 1000 | CB19: =Sheet1!BZ8 -> 2550 | CC19: =SUMPRODUCT($P$18:$BW$18,P19:BW19)+CB19 -> 87658 | CD19: 0.01 | CE19: =CC19*CD19 -> 876.58 | CF19: 0.15 | CG19: =CC19*CF19 -> 13148.7 | CH19: 0 | CI19: =CC19*CH19 -> 0 | CJ19: =CC19+CE19+CG19+CI19 -> 101683.28 | CK19: 0.02 | CL19: =CJ19*CK19 -> 2033.6656 | CM19: 0.01 | CN19: =CJ19*CM19 -> 1016.8328
B20: 2 | C20: =Sheet1!A9 -> ENQ-15115-22-23 | D20: 45658 | E20: =Sheet1!C9 -> FA0600019 | F20: =Sheet1!D9 -> 1 CORE X 150 SQ. MM. AL/UNARD. (XLPE) | G20: =CJ20+CL20+CN20 -> 168250.54 | H20: =ROUNDUP(O50,0) -> 1833 | I20: =G20+H20 -> 170083.54 | J20: =Sheet1!CP9 -> 0.18 | K20: =I20*J20 -> 30615.037 | L20: =I20+K20 -> 200698.58 | M20: =Sheet1!CS9 -> 57.308 | N20: =Sheet1!CT9 -> KMS | O20: =L20*M20 -> 11501634 | P20: =+IFERROR(VLOOKUP($P$17,Sheet1!J9:L9,3,0),0) -> 405 | Q20: =+IFERROR(VLOOKUP($Q$17,Sheet1!J9:L9,3,0),0) -> 0 | R20: =+IFERROR(VLOOKUP($R$17,Sheet1!J9:M9,3,0),0) -> 0 | S20: =+IFERROR(VLOOKUP($S$17,Sheet1!J9:M9,3,0),0) -> 0 | T20: =+IFERROR(VLOOKUP($T$17,Sheet1!J9:M9,3,0),0) -> 0 | U20: =+IFERROR(VLOOKUP($U$17,Sheet1!N9:Q9,3,0),0) -> 0 | V20: =+IFERROR(VLOOKUP($V$17,Sheet1!N9:Q9,3,0),0) -> 0 | W20: =+IFERROR(VLOOKUP($W$17,Sheet1!F9:I9,3,0),0) -> 0 | X20: =+IFERROR(VLOOKUP($X$17,Sheet1!F9:I9,3,0),0) -> 0 | Y20: =+IFERROR(VLOOKUP($Y$17,Sheet1!F9:I9,3,0),0) -> 0 | Z20: =+IFERROR(VLOOKUP($Z$17,Sheet1!F9:I9,3,0),0) -> 0 | AA20: =+IFERROR(VLOOKUP($AA$17,Sheet1!F9:I9,3,0),0) -> 0 | AB20: =+IFERROR(VLOOKUP($AB$17,Sheet1!F9:I9,3,0),0) -> 0 | AC20: =+IFERROR(VLOOKUP($AC$17,Sheet1!F9:I9,3,0),0) -> 0 | AD20: =+IFERROR(VLOOKUP($AD$17,Sheet1!F9:I9,3,0),0) -> 0 | AE20: =+IFERROR(VLOOKUP($AE$17,Sheet1!R9:U9,3,0),0) -> 0 | AF20: =+IFERROR(VLOOKUP($AF$17,Sheet1!R9:U9,2,0),0) -> 0 | AG20: =+IFERROR(VLOOKUP($AG$17,Sheet1!V9:Y9,3,0),0) -> 0 | AH20: =+IFERROR(VLOOKUP($AH$17,Sheet1!V9:Y9,3,0),0) -> 72 | AI20: =+IFERROR(VLOOKUP($AI$17,Sheet1!V9:Y9,3,0),0) -> 0 | AJ20: =+IFERROR(VLOOKUP($AJ$17,Sheet1!V9:Y9,3,0),0) -> 0 | AK20: =+IFERROR(VLOOKUP($AK$17,Sheet1!V9:Y9,3,0),0) -> 0 | AL20: =+IFERROR(VLOOKUP($AL$17,Sheet1!V9:Y9,3,0),0) -> 0 | AM20: =+IFERROR(VLOOKUP($AM$17,Sheet1!Z9:AB9,3,0),0) -> 0 | AN20: =+IFERROR(VLOOKUP($AN$17,Sheet1!AD9:AG9,3,0),0) -> 0 | AO20: =+IFERROR(VLOOKUP($AO$17,Sheet1!AD9:AG9,3,0),0) -> 0 | AP20: =+IFERROR(VLOOKUP($AP$17,Sheet1!AD9:AG9,3,0),0) -> 0 | AQ20: =+IFERROR(VLOOKUP($AQ$17,Sheet1!AD9:AG9,3,0),0) -> 0 | AR20: =+IFERROR(VLOOKUP($AR$17,Sheet1!AD9:AG9,3,0),0) -> 0 | AS20: =+IFERROR(VLOOKUP($AS$17,Sheet1!AD9:AG9,3,0),0) -> 0 | AT20: =+IFERROR(VLOOKUP($AT$17,Sheet1!AD9:AG9,3,0),0) -> 0 | AU20: =+IFERROR(VLOOKUP($AU$17,Sheet1!AH9:AK9,3,0),0) -> 0 | AV20: =+IFERROR(VLOOKUP($AV$17,Sheet1!AH9:AK9,3,0),0) -> 0 | AW20: =+IFERROR(VLOOKUP($AW$17,Sheet1!AH9:AK9,3,0),0) -> 0 | AX20: =+IFERROR(VLOOKUP($AX$17,Sheet1!AH9:AK9,3,0),0) -> 0 | AY20: =+IFERROR(VLOOKUP($AY$17,Sheet1!AH9:AK9,3,0),0) -> 0 | AZ20: =+IFERROR(VLOOKUP($AZ$17,Sheet1!AH9:AK9,3,0),0) -> 0 | BA20: =+IFERROR(VLOOKUP($BA$17,Sheet1!AH9:AK9,3,0),0) -> 0 | BB20: =+IFERROR(VLOOKUP($BB$17,Sheet1!AH9:AK9,3,0),0) -> 0 | BC20: =+IFERROR(VLOOKUP($BC$17,Sheet1!AH9:AK9,3,0),0) -> 0 | BD20: =+IFERROR(VLOOKUP($BD$17,Sheet1!AH9:AK9,3,0),0) -> 0 | BE20: =+IFERROR(VLOOKUP($BE$17,Sheet1!AL9:AO9,3,0),0) -> 0 | BF20: =+IFERROR(VLOOKUP($BF$17,Sheet1!AL9:AO9,3,0),0) -> 0 | BG20: =+IFERROR(VLOOKUP($BG$17,Sheet1!AL9:AO9,3,0),0) -> 0 | BH20: 195 | BI20: =+IFERROR(VLOOKUP($BI$17,Sheet1!AL9:AO9,3,0),0) -> 0 | BJ20: =+IFERROR(VLOOKUP($BJ$17,Sheet1!AL9:AO9,3,0),0) -> 0 | BK20: =+IFERROR(VLOOKUP($BK$17,Sheet1!AL9:AO9,3,0),0) -> 0 | BL20: =+IFERROR(VLOOKUP($BL$17,Sheet1!AL9:AO9,3,0),0) -> 0 | BM20: =+IFERROR(VLOOKUP($BM$17,Sheet1!AL9:AO9,3,0),0) -> 0 | BN20: =+IFERROR(VLOOKUP($BN$17,Sheet1!AL9:AO9,3,0),0) -> 0 | BO20: =+IFERROR(VLOOKUP($BO$17,Sheet1!AP9:AS9,3,0),0) -> 0 | BP20: =+IFERROR(VLOOKUP($BP$17,Sheet1!AT9:AW9,3,0),0) -> 0 | BQ20: 14 | BR20: =+IFERROR(VLOOKUP($BR$17,Sheet1!BB9:BE9,3,0),0) -> 0 | BS20: =+IFERROR(VLOOKUP($BS$17,Sheet1!BF9:BI9,3,0),0) -> 0 | BT20: =+IFERROR(VLOOKUP($BT$17,Sheet1!BJ9:BM9,3,0),0) -> 0 | BU20: =+IFERROR(VLOOKUP($BU$17,Sheet1!BN9:BQ9,3,0),0) -> 0 | BV20: =+IFERROR(VLOOKUP($BV$17,Sheet1!BR9:BU9,3,0),0) -> 0 | BW20: =+IFERROR(VLOOKUP($BW$17,Sheet1!BV9:BY9,3,0),0) -> 0 | BX20: =Sheet1!E9 -> WOOD | BY20: =Sheet1!CV9 -> MD0100085 | BZ20: =Sheet1!CW9 -> DRUM - 43 X 15 X 28 X 2.25 | CA20: =Sheet1!CX9 -> 1000 | CB20: =Sheet1!BZ9 -> 3606 | CC20: =SUMPRODUCT($P$18:$BW$18,P20:BW20)+CB20 -> 140819 | CD20: 0.01 | CE20: =CC20*CD20 -> 1408.19 | CF20: 0.15 | CG20: =CC20*CF20 -> 21122.85 | CH20: 0 | CI20: =CC20*CH20 -> 0 | CJ20: =CC20+CE20+CG20+CI20 -> 163350.04 | CK20: 0.02 | CL20: =CJ20*CK20 -> 3267.0008 | CM20: 0.01 | CN20: =CJ20*CM20 -> 1633.5004
B21: 3 | C21: =Sheet1!A11 -> ENQ-15115-22-23 | D21: 45658 | E21: =Sheet1!C11 -> FA0600021 | F21: =Sheet1!D11 -> 1 CORE X 185 SQ. MM. AL/UNARD. (XLPE) | G21: =CJ21+CL21+CN21 -> 206352.71 | H21: =ROUNDUP(O51,0) -> 2938 | I21: =G21+H21 -> 209290.71 | J21: =Sheet1!CP11 -> 0.18 | K21: =I21*J21 -> 37672.328 | L21: =I21+K21 -> 246963.04 | M21: =Sheet1!CS11 -> 35.75 | N21: =Sheet1!CT11 -> KMS | O21: =L21*M21 -> 8828928.7 | P21: =+IFERROR(VLOOKUP($P$17,Sheet1!J11:L11,3,0),0) -> 500 | Q21: =+IFERROR(VLOOKUP($Q$17,Sheet1!J11:L11,3,0),0) -> 0 | R21: =+IFERROR(VLOOKUP($R$17,Sheet1!J11:M11,3,0),0) -> 0 | S21: =+IFERROR(VLOOKUP($S$17,Sheet1!J11:M11,3,0),0) -> 0 | T21: =+IFERROR(VLOOKUP($T$17,Sheet1!J11:M11,3,0),0) -> 0 | U21: =+IFERROR(VLOOKUP($U$17,Sheet1!N11:Q11,3,0),0) -> 0 | V21: =+IFERROR(VLOOKUP($V$17,Sheet1!N11:Q11,3,0),0) -> 0 | W21: =+IFERROR(VLOOKUP($W$17,Sheet1!F11:I11,3,0),0) -> 0 | X21: =+IFERROR(VLOOKUP($X$17,Sheet1!F11:I11,3,0),0) -> 0 | Y21: =+IFERROR(VLOOKUP($Y$17,Sheet1!F11:I11,3,0),0) -> 0 | Z21: =+IFERROR(VLOOKUP($Z$17,Sheet1!F11:I11,3,0),0) -> 0 | AA21: =+IFERROR(VLOOKUP($AA$17,Sheet1!F11:I11,3,0),0) -> 0 | AB21: =+IFERROR(VLOOKUP($AB$17,Sheet1!F11:I11,3,0),0) -> 0 | AC21: =+IFERROR(VLOOKUP($AC$17,Sheet1!F11:I11,3,0),0) -> 0 | AD21: =+IFERROR(VLOOKUP($AD$17,Sheet1!F11:I11,3,0),0) -> 0 | AE21: =+IFERROR(VLOOKUP($AE$17,Sheet1!R11:U11,3,0),0) -> 0 | AF21: =+IFERROR(VLOOKUP($AF$17,Sheet1!R11:U11,2,0),0) -> 0 | AG21: =+IFERROR(VLOOKUP($AG$17,Sheet1!V11:Y11,3,0),0) -> 0 | AH21: =+IFERROR(VLOOKUP($AH$17,Sheet1!V11:Y11,3,0),0) -> 90 | AI21: =+IFERROR(VLOOKUP($AI$17,Sheet1!V11:Y11,3,0),0) -> 0 | AJ21: =+IFERROR(VLOOKUP($AJ$17,Sheet1!V11:Y11,3,0),0) -> 0 | AK21: =+IFERROR(VLOOKUP($AK$17,Sheet1!V11:Y11,3,0),0) -> 0 | AL21: =+IFERROR(VLOOKUP($AL$17,Sheet1!V11:Y11,3,0),0) -> 0 | AM21: =+IFERROR(VLOOKUP($AM$17,Sheet1!Z11:AB11,3,0),0) -> 0 | AN21: =+IFERROR(VLOOKUP($AN$17,Sheet1!AD11:AG11,3,0),0) -> 0 | AO21: =+IFERROR(VLOOKUP($AO$17,Sheet1!AD11:AG11,3,0),0) -> 0 | AP21: =+IFERROR(VLOOKUP($AP$17,Sheet1!AD11:AG11,3,0),0) -> 0 | AQ21: =+IFERROR(VLOOKUP($AQ$17,Sheet1!AD11:AG11,3,0),0) -> 0 | AR21: =+IFERROR(VLOOKUP($AR$17,Sheet1!AD11:AG11,3,0),0) -> 0 | AS21: =+IFERROR(VLOOKUP($AS$17,Sheet1!AD11:AG11,3,0),0) -> 0 | AT21: =+IFERROR(VLOOKUP($AT$17,Sheet1!AD11:AG11,3,0),0) -> 0 | AU21: =+IFERROR(VLOOKUP($AU$17,Sheet1!AH11:AK11,3,0),0) -> 0 | AV21: =+IFERROR(VLOOKUP($AV$17,Sheet1!AH11:AK11,3,0),0) -> 0 | AW21: =+IFERROR(VLOOKUP($AW$17,Sheet1!AH11:AK11,3,0),0) -> 0 | AX21: =+IFERROR(VLOOKUP($AX$17,Sheet1!AH11:AK11,3,0),0) -> 0 | AY21: =+IFERROR(VLOOKUP($AY$17,Sheet1!AH11:AK11,3,0),0) -> 0 | AZ21: =+IFERROR(VLOOKUP($AZ$17,Sheet1!AH11:AK11,3,0),0) -> 0 | BA21: =+IFERROR(VLOOKUP($BA$17,Sheet1!AH11:AK11,3,0),0) -> 0 | BB21: =+IFERROR(VLOOKUP($BB$17,Sheet1!AH11:AK11,3,0),0) -> 0 | BC21: =+IFERROR(VLOOKUP($BC$17,Sheet1!AH11:AK11,3,0),0) -> 0 | BD21: =+IFERROR(VLOOKUP($BD$17,Sheet1!AH11:AK11,3,0),0) -> 0 | BE21: =+IFERROR(VLOOKUP($BE$17,Sheet1!AL11:AO11,3,0),0) -> 0 | BF21: =+IFERROR(VLOOKUP($BF$17,Sheet1!AL11:AO11,3,0),0) -> 0 | BG21: =+IFERROR(VLOOKUP($BG$17,Sheet1!AL11:AO11,3,0),0) -> 0 | BH21: 216 | BI21: =+IFERROR(VLOOKUP($BI$17,Sheet1!AL11:AO11,3,0),0) -> 0 | BJ21: =+IFERROR(VLOOKUP($BJ$17,Sheet1!AL11:AO11,3,0),0) -> 0 | BK21: =+IFERROR(VLOOKUP($BK$17,Sheet1!AL11:AO11,3,0),0) -> 0 | BL21: =+IFERROR(VLOOKUP($BL$17,Sheet1!AL11:AO11,3,0),0) -> 0 | BM21: =+IFERROR(VLOOKUP($BM$17,Sheet1!AL11:AO11,3,0),0) -> 0 | BN21: =+IFERROR(VLOOKUP($BN$17,Sheet1!AL11:AO11,3,0),0) -> 0 | BO21: =+IFERROR(VLOOKUP($BO$17,Sheet1!AP11:AS11,3,0),0) -> 0 | BP21: =+IFERROR(VLOOKUP($BP$17,Sheet1!AT11:AW11,3,0),0) -> 0 | BQ21: 22 | BR21: =+IFERROR(VLOOKUP($BR$17,Sheet1!BB11:BE11,3,0),0) -> 0 | BS21: =+IFERROR(VLOOKUP($BS$17,Sheet1!BF11:BI11,3,0),0) -> 0 | BT21: =+IFERROR(VLOOKUP($BT$17,Sheet1!BJ11:BM11,3,0),0) -> 0 | BU21: =+IFERROR(VLOOKUP($BU$17,Sheet1!BN11:BQ11,3,0),0) -> 0 | BV21: =+IFERROR(VLOOKUP($BV$17,Sheet1!BR11:BU11,3,0),0) -> 0 | BW21: =+IFERROR(VLOOKUP($BW$17,Sheet1!BV11:BY11,3,0),0) -> 0 | BX21: =Sheet1!E11 -> WOOD | BY21: =Sheet1!CV11 -> MD0100090 | BZ21: =Sheet1!CW11 -> DRUM - 43 X 15 X 36 X 2.5 | CA21: =Sheet1!CX11 -> 1000 | CB21: =Sheet1!BZ11 -> 3881 | CC21: =SUMPRODUCT($P$18:$BW$18,P21:BW21)+CB21 -> 172709 | CD21: 0.01 | CE21: =CC21*CD21 -> 1727.09 | CF21: 0.15 | CG21: =CC21*CF21 -> 25906.35 | CH21: 0 | CI21: =CC21*CH21 -> 0 | CJ21: =CC21+CE21+CG21+CI21 -> 200342.44 | CK21: 0.02 | CL21: =CJ21*CK21 -> 4006.8488 | CM21: 0.01 | CN21: =CJ21*CM21 -> 2003.4244
B22: 4 | C22: =Sheet1!A10 -> ENQ-15115-22-23 | D22: 45658 | E22: =Sheet1!C10 -> FA0600020 | F22: =Sheet1!D10 -> 1 CORE X 300 SQ. MM. AL/UNARD. (XLPE) | G22: =CJ22+CL22+CN22 -> 318747.55 | H22: =ROUNDUP(O52,0) -> 4721 | I22: =G22+H22 -> 323468.55 | J22: =Sheet1!CP10 -> 0.18 | K22: =I22*J22 -> 58224.339 | L22: =I22+K22 -> 381692.89 | M22: 81.552 | N22: =Sheet1!CT10 -> KMS | O22: =L22*M22 -> 31127818 | P22: =+IFERROR(VLOOKUP($P$17,Sheet1!J10:L10,3,0),0) -> 810 | Q22: =+IFERROR(VLOOKUP($Q$17,Sheet1!J10:L10,3,0),0) -> 0 | R22: =+IFERROR(VLOOKUP($R$17,Sheet1!J10:M10,3,0),0) -> 0 | S22: =+IFERROR(VLOOKUP($S$17,Sheet1!J10:M10,3,0),0) -> 0 | T22: =+IFERROR(VLOOKUP($T$17,Sheet1!J10:M10,3,0),0) -> 0 | U22: =+IFERROR(VLOOKUP($U$17,Sheet1!N10:Q10,3,0),0) -> 0 | V22: =+IFERROR(VLOOKUP($V$17,Sheet1!N10:Q10,3,0),0) -> 0 | W22: =+IFERROR(VLOOKUP($W$17,Sheet1!F10:I10,3,0),0) -> 0 | X22: =+IFERROR(VLOOKUP($X$17,Sheet1!F10:I10,3,0),0) -> 0 | Y22: =+IFERROR(VLOOKUP($Y$17,Sheet1!F10:I10,3,0),0) -> 0 | Z22: =+IFERROR(VLOOKUP($Z$17,Sheet1!F10:I10,3,0),0) -> 0 | AA22: =+IFERROR(VLOOKUP($AA$17,Sheet1!F10:I10,3,0),0) -> 0 | AB22: =+IFERROR(VLOOKUP($AB$17,Sheet1!F10:I10,3,0),0) -> 0 | AC22: =+IFERROR(VLOOKUP($AC$17,Sheet1!F10:I10,3,0),0) -> 0 | AD22: =+IFERROR(VLOOKUP($AD$17,Sheet1!F10:I10,3,0),0) -> 0 | AE22: =+IFERROR(VLOOKUP($AE$17,Sheet1!R10:U10,3,0),0) -> 0 | AF22: =+IFERROR(VLOOKUP($AF$17,Sheet1!R10:U10,2,0),0) -> 0 | AG22: =+IFERROR(VLOOKUP($AG$17,Sheet1!V10:Y10,3,0),0) -> 0 | AH22: =+IFERROR(VLOOKUP($AH$17,Sheet1!V10:Y10,3,0),0) -> 132 | AI22: =+IFERROR(VLOOKUP($AI$17,Sheet1!V10:Y10,3,0),0) -> 0 | AJ22: =+IFERROR(VLOOKUP($AJ$17,Sheet1!V10:Y10,3,0),0) -> 0 | AK22: =+IFERROR(VLOOKUP($AK$17,Sheet1!V10:Y10,3,0),0) -> 0 | AL22: =+IFERROR(VLOOKUP($AL$17,Sheet1!V10:Y10,3,0),0) -> 0 | AM22: =+IFERROR(VLOOKUP($AM$17,Sheet1!Z10:AB10,3,0),0) -> 0 | AN22: =+IFERROR(VLOOKUP($AN$17,Sheet1!AD10:AG10,3,0),0) -> 0 | AO22: =+IFERROR(VLOOKUP($AO$17,Sheet1!AD10:AG10,3,0),0) -> 0 | AP22: =+IFERROR(VLOOKUP($AP$17,Sheet1!AD10:AG10,3,0),0) -> 0 | AQ22: =+IFERROR(VLOOKUP($AQ$17,Sheet1!AD10:AG10,3,0),0) -> 0 | AR22: =+IFERROR(VLOOKUP($AR$17,Sheet1!AD10:AG10,3,0),0) -> 0 | AS22: =+IFERROR(VLOOKUP($AS$17,Sheet1!AD10:AG10,3,0),0) -> 0 | AT22: =+IFERROR(VLOOKUP($AT$17,Sheet1!AD10:AG10,3,0),0) -> 0 | AU22: =+IFERROR(VLOOKUP($AU$17,Sheet1!AH10:AK10,3,0),0) -> 0 | AV22: =+IFERROR(VLOOKUP($AV$17,Sheet1!AH10:AK10,3,0),0) -> 0 | AW22: =+IFERROR(VLOOKUP($AW$17,Sheet1!AH10:AK10,3,0),0) -> 0 | AX22: =+IFERROR(VLOOKUP($AX$17,Sheet1!AH10:AK10,3,0),0) -> 0 | AY22: =+IFERROR(VLOOKUP($AY$17,Sheet1!AH10:AK10,3,0),0) -> 0 | AZ22: =+IFERROR(VLOOKUP($AZ$17,Sheet1!AH10:AK10,3,0),0) -> 0 | BA22: =+IFERROR(VLOOKUP($BA$17,Sheet1!AH10:AK10,3,0),0) -> 0 | BB22: =+IFERROR(VLOOKUP($BB$17,Sheet1!AH10:AK10,3,0),0) -> 0 | BC22: =+IFERROR(VLOOKUP($BC$17,Sheet1!AH10:AK10,3,0),0) -> 0 | BD22: =+IFERROR(VLOOKUP($BD$17,Sheet1!AH10:AK10,3,0),0) -> 0 | BE22: =+IFERROR(VLOOKUP($BE$17,Sheet1!AL10:AO10,3,0),0) -> 0 | BF22: =+IFERROR(VLOOKUP($BF$17,Sheet1!AL10:AO10,3,0),0) -> 0 | BG22: =+IFERROR(VLOOKUP($BG$17,Sheet1!AL10:AO10,3,0),0) -> 0 | BH22: 255 | BI22: =+IFERROR(VLOOKUP($BI$17,Sheet1!AL10:AO10,3,0),0) -> 0 | BJ22: =+IFERROR(VLOOKUP($BJ$17,Sheet1!AL10:AO10,3,0),0) -> 0 | BK22: =+IFERROR(VLOOKUP($BK$17,Sheet1!AL10:AO10,3,0),0) -> 0 | BL22: =+IFERROR(VLOOKUP($BL$17,Sheet1!AL10:AO10,3,0),0) -> 0 | BM22: =+IFERROR(VLOOKUP($BM$17,Sheet1!AL10:AO10,3,0),0) -> 0 | BN22: =+IFERROR(VLOOKUP($BN$17,Sheet1!AL10:AO10,3,0),0) -> 0 | BO22: =+IFERROR(VLOOKUP($BO$17,Sheet1!AP10:AS10,3,0),0) -> 0 | BP22: =+IFERROR(VLOOKUP($BP$17,Sheet1!AT10:AW10,3,0),0) -> 0 | BQ22: 28 | BR22: =+IFERROR(VLOOKUP($BR$17,Sheet1!BB10:BE10,3,0),0) -> 0 | BS22: =+IFERROR(VLOOKUP($BS$17,Sheet1!BF10:BI10,3,0),0) -> 0 | BT22: =+IFERROR(VLOOKUP($BT$17,Sheet1!BJ10:BM10,3,0),0) -> 0 | BU22: =+IFERROR(VLOOKUP($BU$17,Sheet1!BN10:BQ10,3,0),0) -> 0 | BV22: =+IFERROR(VLOOKUP($BV$17,Sheet1!BR10:BU10,3,0),0) -> 0 | BW22: =+IFERROR(VLOOKUP($BW$17,Sheet1!BV10:BY10,3,0),0) -> 0 | BX22: =Sheet1!E10 -> WOOD | BY22: =Sheet1!CV10 -> MD0100017 | BZ22: =Sheet1!CW10 -> DRUM - 52 X 18 X 36 X 2.5 | CA22: =Sheet1!CX10 -> 1000 | CB22: =Sheet1!BZ10 -> 6276 | CC22: =SUMPRODUCT($P$18:$BW$18,P22:BW22)+CB22 -> 266779 | CD22: 0.01 | CE22: =CC22*CD22 -> 2667.79 | CF22: 0.15 | CG22: =CC22*CF22 -> 40016.85 | CH22: 0 | CI22: =CC22*CH22 -> 0 | CJ22: =CC22+CE22+CG22+CI22 -> 309463.64 | CK22: 0.02 | CL22: =CJ22*CK22 -> 6189.2728 | CM22: 0.01 | CN22: =CJ22*CM22 -> 3094.6364
B23: 5 | C23: =Sheet1!A12 -> ENQ-15115-22-23 | D23: 45658 | E23: =Sheet1!C12 -> FA0600032 | F23: =Sheet1!D12 -> 1 CORE X 630 SQ. MM. ALU/UNARD (XLPE) | G23: =CJ23+CL23+CN23 -> 643530.03 | H23: =ROUNDUP(O53,0) -> 7235 | I23: =G23+H23 -> 650765.03 | J23: =Sheet1!CP12 -> 0.18 | K23: =I23*J23 -> 117137.71 | L23: =I23+K23 -> 767902.74 | M23: 38.704 | N23: =Sheet1!CT12 -> KMS | O23: =L23*M23 -> 29720908 | P23: =+IFERROR(VLOOKUP($P$17,Sheet1!J12:L12,3,0),0) -> 1701 | Q23: =+IFERROR(VLOOKUP($Q$17,Sheet1!J12:L12,3,0),0) -> 0 | R23: =+IFERROR(VLOOKUP($R$17,Sheet1!J12:M12,3,0),0) -> 0 | S23: =+IFERROR(VLOOKUP($S$17,Sheet1!J12:M12,3,0),0) -> 0 | T23: =+IFERROR(VLOOKUP($T$17,Sheet1!J12:M12,3,0),0) -> 0 | U23: =+IFERROR(VLOOKUP($U$17,Sheet1!N12:Q12,3,0),0) -> 0 | V23: =+IFERROR(VLOOKUP($V$17,Sheet1!N12:Q12,3,0),0) -> 0 | W23: =+IFERROR(VLOOKUP($W$17,Sheet1!F12:I12,3,0),0) -> 0 | X23: =+IFERROR(VLOOKUP($X$17,Sheet1!F12:I12,3,0),0) -> 0 | Y23: =+IFERROR(VLOOKUP($Y$17,Sheet1!F12:I12,3,0),0) -> 0 | Z23: =+IFERROR(VLOOKUP($Z$17,Sheet1!F12:I12,3,0),0) -> 0 | AA23: =+IFERROR(VLOOKUP($AA$17,Sheet1!F12:I12,3,0),0) -> 0 | AB23: =+IFERROR(VLOOKUP($AB$17,Sheet1!F12:I12,3,0),0) -> 0 | AC23: =+IFERROR(VLOOKUP($AC$17,Sheet1!F12:I12,3,0),0) -> 0 | AD23: =+IFERROR(VLOOKUP($AD$17,Sheet1!F12:I12,3,0),0) -> 0 | AE23: =+IFERROR(VLOOKUP($AE$17,Sheet1!R12:U12,3,0),0) -> 0 | AF23: =+IFERROR(VLOOKUP($AF$17,Sheet1!R12:U12,2,0),0) -> 0 | AG23: =+IFERROR(VLOOKUP($AG$17,Sheet1!V12:Y12,3,0),0) -> 0 | AH23: 242 | AI23: =+IFERROR(VLOOKUP($AI$17,Sheet1!V12:Y12,3,0),0) -> 0 | AJ23: =+IFERROR(VLOOKUP($AJ$17,Sheet1!V12:Y12,3,0),0) -> 0 | AK23: =+IFERROR(VLOOKUP($AK$17,Sheet1!V12:Y12,3,0),0) -> 0 | AL23: =+IFERROR(VLOOKUP($AL$17,Sheet1!V12:Y12,3,0),0) -> 0 | AM23: =+IFERROR(VLOOKUP($AM$17,Sheet1!Z12:AB12,3,0),0) -> 0 | AN23: =+IFERROR(VLOOKUP($AN$17,Sheet1!AD12:AG12,3,0),0) -> 0 | AO23: =+IFERROR(VLOOKUP($AO$17,Sheet1!AD12:AG12,3,0),0) -> 0 | AP23: =+IFERROR(VLOOKUP($AP$17,Sheet1!AD12:AG12,3,0),0) -> 0 | AQ23: =+IFERROR(VLOOKUP($AQ$17,Sheet1!AD12:AG12,3,0),0) -> 0 | AR23: =+IFERROR(VLOOKUP($AR$17,Sheet1!AD12:AG12,3,0),0) -> 0 | AS23: =+IFERROR(VLOOKUP($AS$17,Sheet1!AD12:AG12,3,0),0) -> 0 | AT23: =+IFERROR(VLOOKUP($AT$17,Sheet1!AD12:AG12,3,0),0) -> 0 | AU23: =+IFERROR(VLOOKUP($AU$17,Sheet1!AH12:AK12,3,0),0) -> 0 | AV23: =+IFERROR(VLOOKUP($AV$17,Sheet1!AH12:AK12,3,0),0) -> 0 | AW23: =+IFERROR(VLOOKUP($AW$17,Sheet1!AH12:AK12,3,0),0) -> 0 | AX23: =+IFERROR(VLOOKUP($AX$17,Sheet1!AH12:AK12,3,0),0) -> 0 | AY23: =+IFERROR(VLOOKUP($AY$17,Sheet1!AH12:AK12,3,0),0) -> 0 | AZ23: =+IFERROR(VLOOKUP($AZ$17,Sheet1!AH12:AK12,3,0),0) -> 0 | BA23: =+IFERROR(VLOOKUP($BA$17,Sheet1!AH12:AK12,3,0),0) -> 0 | BB23: =+IFERROR(VLOOKUP($BB$17,Sheet1!AH12:AK12,3,0),0) -> 0 | BC23: =+IFERROR(VLOOKUP($BC$17,Sheet1!AH12:AK12,3,0),0) -> 0 | BD23: =+IFERROR(VLOOKUP($BD$17,Sheet1!AH12:AK12,3,0),0) -> 0 | BE23: =+IFERROR(VLOOKUP($BE$17,Sheet1!AL12:AO12,3,0),0) -> 0 | BF23: =+IFERROR(VLOOKUP($BF$17,Sheet1!AL12:AO12,3,0),0) -> 0 | BG23: =+IFERROR(VLOOKUP($BG$17,Sheet1!AL12:AO12,3,0),0) -> 0 | BH23: 408 | BI23: =+IFERROR(VLOOKUP($BI$17,Sheet1!AL12:AO12,3,0),0) -> 0 | BJ23: =+IFERROR(VLOOKUP($BJ$17,Sheet1!AL12:AO12,3,0),0) -> 0 | BK23: =+IFERROR(VLOOKUP($BK$17,Sheet1!AL12:AO12,3,0),0) -> 0 | BL23: =+IFERROR(VLOOKUP($BL$17,Sheet1!AL12:AO12,3,0),0) -> 0 | BM23: =+IFERROR(VLOOKUP($BM$17,Sheet1!AL12:AO12,3,0),0) -> 0 | BN23: =+IFERROR(VLOOKUP($BN$17,Sheet1!AL12:AO12,3,0),0) -> 0 | BO23: =+IFERROR(VLOOKUP($BO$17,Sheet1!AP12:AS12,3,0),0) -> 0 | BP23: =+IFERROR(VLOOKUP($BP$17,Sheet1!AT12:AW12,3,0),0) -> 0 | BQ23: 40 | BR23: =+IFERROR(VLOOKUP($BR$17,Sheet1!BB12:BE12,3,0),0) -> 0 | BS23: =+IFERROR(VLOOKUP($BS$17,Sheet1!BF12:BI12,3,0),0) -> 0 | BT23: =+IFERROR(VLOOKUP($BT$17,Sheet1!BJ12:BM12,3,0),0) -> 0 | BU23: =+IFERROR(VLOOKUP($BU$17,Sheet1!BN12:BQ12,3,0),0) -> 0 | BV23: =+IFERROR(VLOOKUP($BV$17,Sheet1!BR12:BU12,3,0),0) -> 0 | BW23: =+IFERROR(VLOOKUP($BW$17,Sheet1!BV12:BY12,3,0),0) -> 0 | BX23: =Sheet1!E12 -> WOOD | BY23: =Sheet1!CV12 -> MD0100062 | BZ23: =Sheet1!CW12 -> DRUM - 74 X 24 X 32 X 3 | CA23: =Sheet1!CX12 -> 1000 | CB23: =Sheet1!BZ12 -> 13815 | CC23: =SUMPRODUCT($P$18:$BW$18,P23:BW23)+CB23 -> 538609 | CD23: 0.01 | CE23: =CC23*CD23 -> 5386.09 | CF23: 0.15 | CG23: =CC23*CF23 -> 80791.35 | CH23: 0 | CI23: =CC23*CH23 -> 0 | CJ23: =CC23+CE23+CG23+CI23 -> 624786.44 | CK23: 0.02 | CL23: =CJ23*CK23 -> 12495.729 | CM23: 0.01 | CN23: =CJ23*CM23 -> 6247.8644
B24: 6 | C24: =Sheet1!A20 -> ENQ-15115-22-23 | D24: 45658 | E24: =Sheet1!C20 -> FA0900116 | F24: =Sheet1!D20 -> 4 CORE X 50 SQ. MM. AL/ARD - WIRE (XLPE) | G24: =CJ24+CL24+CN24 -> 343815.65 | H24: =ROUNDUP(O54,0) -> 5263 | I24: =G24+H24 -> 349078.65 | J24: =Sheet1!CP20 -> 0.18 | K24: =I24*J24 -> 62834.157 | L24: =I24+K24 -> 411912.8 | M24: =Sheet1!CS20 -> 26.605 | N24: =Sheet1!CT20 -> KMS | O24: =L24*M24 -> 10958940 | P24: =+IFERROR(VLOOKUP($P$17,Sheet1!J20:L20,3,0),0) -> 541 | Q24: =+IFERROR(VLOOKUP($Q$17,Sheet1!J20:L20,3,0),0) -> 0 | R24: =+IFERROR(VLOOKUP($R$17,Sheet1!J20:M20,3,0),0) -> 0 | S24: =+IFERROR(VLOOKUP($S$17,Sheet1!J20:M20,3,0),0) -> 0 | T24: =+IFERROR(VLOOKUP($T$17,Sheet1!J20:M20,3,0),0) -> 0 | U24: =+IFERROR(VLOOKUP($U$17,Sheet1!N20:Q20,3,0),0) -> 0 | V24: =+IFERROR(VLOOKUP($V$17,Sheet1!N20:Q20,3,0),0) -> 0 | W24: =+IFERROR(VLOOKUP($W$17,Sheet1!F20:I20,3,0),0) -> 0 | X24: =+IFERROR(VLOOKUP($X$17,Sheet1!F20:I20,3,0),0) -> 0 | Y24: =+IFERROR(VLOOKUP($Y$17,Sheet1!F20:I20,3,0),0) -> 0 | Z24: =+IFERROR(VLOOKUP($Z$17,Sheet1!F20:I20,3,0),0) -> 0 | AA24: =+IFERROR(VLOOKUP($AA$17,Sheet1!F20:I20,3,0),0) -> 0 | AB24: =+IFERROR(VLOOKUP($AB$17,Sheet1!F20:I20,3,0),0) -> 0 | AC24: =+IFERROR(VLOOKUP($AC$17,Sheet1!F20:I20,3,0),0) -> 0 | AD24: =+IFERROR(VLOOKUP($AD$17,Sheet1!F20:I20,3,0),0) -> 0 | AE24: =+IFERROR(VLOOKUP($AE$17,Sheet1!R20:U20,3,0),0) -> 0 | AF24: =+IFERROR(VLOOKUP($AF$17,Sheet1!R20:U20,2,0),0) -> 0 | AG24: =+IFERROR(VLOOKUP($AG$17,Sheet1!V20:Y20,3,0),0) -> 0 | AH24: 119 | AI24: =+IFERROR(VLOOKUP($AI$17,Sheet1!V20:Y20,3,0),0) -> 0 | AJ24: =+IFERROR(VLOOKUP($AJ$17,Sheet1!V20:Y20,3,0),0) -> 0 | AK24: =+IFERROR(VLOOKUP($AK$17,Sheet1!V20:Y20,3,0),0) -> 0 | AL24: =+IFERROR(VLOOKUP($AL$17,Sheet1!V20:Y20,3,0),0) -> 0 | AM24: =+IFERROR(VLOOKUP($AM$17,Sheet1!Z20:AB20,3,0),0) -> 0 | AN24: =+IFERROR(VLOOKUP($AN$17,Sheet1!AD20:AG20,3,0),0) -> 0 | AO24: =+IFERROR(VLOOKUP($AO$17,Sheet1!AD20:AG20,3,0),0) -> 0 | AP24: =+IFERROR(VLOOKUP($AP$17,Sheet1!AD20:AG20,3,0),0) -> 0 | AQ24: =+IFERROR(VLOOKUP($AQ$17,Sheet1!AD20:AG20,3,0),0) -> 0 | AR24: =+IFERROR(VLOOKUP($AR$17,Sheet1!AD20:AG20,3,0),0) -> 0 | AS24: 56 | AT24: =+IFERROR(VLOOKUP($AT$17,Sheet1!AD20:AG20,3,0),0) -> 0 | AU24: =+IFERROR(VLOOKUP($AU$17,Sheet1!AH20:AK20,3,0),0) -> 0 | AV24: =+IFERROR(VLOOKUP($AV$17,Sheet1!AH20:AK20,3,0),0) -> 0 | AW24: =+IFERROR(VLOOKUP($AW$17,Sheet1!AH20:AK20,3,0),0) -> 0 | AX24: =+IFERROR(VLOOKUP($AX$17,Sheet1!AH20:AK20,3,0),0) -> 0 | AY24: =+IFERROR(VLOOKUP($AY$17,Sheet1!AH20:AK20,3,0),0) -> 0 | AZ24: =+IFERROR(VLOOKUP($AZ$17,Sheet1!AH20:AK20,3,0),0) -> 0 | BA24: =+IFERROR(VLOOKUP($BA$17,Sheet1!AH20:AK20,3,0),0) -> 0 | BB24: =+IFERROR(VLOOKUP($BB$17,Sheet1!AH20:AK20,3,0),0) -> 0 | BC24: 1042 | BD24: =+IFERROR(VLOOKUP($BD$17,Sheet1!AH20:AK20,3,0),0) -> 0 | BE24: =+IFERROR(VLOOKUP($BE$17,Sheet1!AL20:AO20,3,0),0) -> 0 | BF24: =+IFERROR(VLOOKUP($BF$17,Sheet1!AL20:AO20,3,0),0) -> 0 | BG24: =+IFERROR(VLOOKUP($BG$17,Sheet1!AL20:AO20,3,0),0) -> 0 | BH24: =+IFERROR(VLOOKUP($BH$17,Sheet1!AL20:AO20,3,0),0) -> 260 | BI24: =+IFERROR(VLOOKUP($BI$17,Sheet1!AL20:AO20,3,0),0) -> 0 | BJ24: =+IFERROR(VLOOKUP($BJ$17,Sheet1!AL20:AO20,3,0),0) -> 0 | BK24: =+IFERROR(VLOOKUP($BK$17,Sheet1!AL20:AO20,3,0),0) -> 0 | BL24: =+IFERROR(VLOOKUP($BL$17,Sheet1!AL20:AO20,3,0),0) -> 0 | BM24: =+IFERROR(VLOOKUP($BM$17,Sheet1!AL20:AO20,3,0),0) -> 0 | BN24: =+IFERROR(VLOOKUP($BN$17,Sheet1!AL20:AO20,3,0),0) -> 0 | BO24: =+IFERROR(VLOOKUP($BO$17,Sheet1!AP20:AS20,3,0),0) -> 0 | BP24: =+IFERROR(VLOOKUP($BP$17,Sheet1!AT20:AW20,3,0),0) -> 0 | BQ24: =+IFERROR(VLOOKUP($BQ$17,Sheet1!AX20:BA20,3,0),0) -> 0 | BR24: =+IFERROR(VLOOKUP($BR$17,Sheet1!BB20:BE20,3,0),0) -> 0 | BS24: =+IFERROR(VLOOKUP($BS$17,Sheet1!BF20:BI20,3,0),0) -> 0 | BT24: =+IFERROR(VLOOKUP($BT$17,Sheet1!BJ20:BM20,3,0),0) -> 0 | BU24: =+IFERROR(VLOOKUP($BU$17,Sheet1!BN20:BQ20,3,0),0) -> 0 | BV24: 20 | BW24: =+IFERROR(VLOOKUP($BW$17,Sheet1!BV20:BY20,3,0),0) -> 0 | BX24: =Sheet1!E20 -> WOOD | BY24: =Sheet1!CV20 -> MD0100068 | BZ24: =Sheet1!CW20 -> DRUM - 54 X 20 X 36 X 2.5 | CA24: =Sheet1!CX20 -> 1000 | CB24: =Sheet1!BZ20 -> 6254 | CC24: =SUMPRODUCT($P$18:$BW$18,P24:BW24)+CB24 -> 287760 | CD24: 0.01 | CE24: =CC24*CD24 -> 2877.6 | CF24: 0.15 | CG24: =CC24*CF24 -> 43164 | CH24: 0 | CI24: =CC24*CH24 -> 0 | CJ24: =CC24+CE24+CG24+CI24 -> 333801.6 | CK24: 0.02 | CL24: =CJ24*CK24 -> 6676.032 | CM24: 0.01 | CN24: =CJ24*CM24 -> 3338.016
