Workbook

Sheet Sheet1
A1: DOCKET NO. | B1: Base Date | C1: ITEM CODE | D1: PROPOSE ERP ITEM NAME | E1: Propose Drum Type | F1: Insulation Screening(Metallic) | G1: RM Rate(Insulation Screening(Metallic)) | H1: Weight (Insulation Screening (Metallic)) | I1: Cost Insulation Screening(Metallic) | J1: Conductor | K1: RM Rate(Conductor) | L1: Weight(Conductor) | M1: Cost(Conductor) | N1: AL ALLOY | O1: RM Rate(AL Alloy) | P1: Weight(Al Alloy) | Q1: Cost(AL Alloy) | R1: Insulation Screening(Non-Metallic) | S1: RM Rate(Insulation Screening(Non-Metallic)) | T1: Weight(Insulation Screening(Non-Metallic) | U1: Cost(Insulation Screening(Non-Metallic) | V1: Insulation | W1: RM Rate(Insulation) | X1: Weight(Insulation) | Y1: Cost(Insulation) | Z1: Poly Tape | AA1: RM Rate(Poly Tape) | AB1: Weight(Poly Tape) | AC1: Cost(Poly Tape) | AD1: Inner Sheath | AE1: RM Rate(Inner Sheath) | AF1: Weight(Inner Sheath) | AG1: Cost(Inner Sheath) | AH1: Armouring | AI1: RM Rate(Armouring) | AJ1: Weight(Armouring) | AK1: Cost(Armouring) | AL1: Outer Sheath | AM1: RM Rate(Outer Sheath) | AN1: Weight(Outer Sheath) | AO1: Cost(Outer Sheath) | AP1: Filler | AQ1: RM Rate(Filler) | AR1: Weight(Filler) | AS1: Cost(Filler) | AT1: Grease | AU1: RM Rate(Grease) | AV1: Weight(Grease) | AW1: Cost(Grease) | AX1: Water Swellable Tape | AY1: RM Rate(Water Swellable Tape) | AZ1: Weight(Water Swellable Tape) | BA1: Cost(Water Swellable Tape) | BB1: Semi Conducting Water Swellable Tape | BC1: RM Rate(Semi Conducting Water Swellable Tape) | BD1: Weight(Semi Conducting Water Swellable Tape) | BE1: Cost(Semi Conducting Water Swellable Tape) | BF1: Semicon Tape | BG1: RM Rate(Semicon Tape) | BH1: Weight(Semicon Tape) | BI1: Cost(Semicon Tape) | BJ1: Glass Fiber Tape | BK1: RM Rate(Glass Fiber Tape) | BL1: Weight(Glass Fiber Tape) | BM1: Cost(Glass Fiber Tape) | BN1: Copper Wire 0.8MM | BO1: RM Rate(Copper Wire 0.8MM) | BP1: Weight(Copper Wire 0.8MM) | BQ1: Cost(Copper Wire 0.8MM) | BR1: Rubberized Cotton Tape | BS1: RM Rate(Rubberized Cotton Tape) | BT1: Weight(Rubberized Cotton Tape) | BU1: Cost(Rubberized Cotton Tape) | BV1: Water Tight Compound | BW1: RM Rate(Water Tight Compound) | BX1: Weight(Water Tight Compound) | BY1: Cost(Water Tight Compound) | BZ1: Drum Cost Per KM | CA1: Total RM Cost | CB1: FIRM % | CC1: Firm Value | CD1: MFG% | CE1: MFG Value | CF1: PROF% | CG1: Profit Value | CH1: 1st EX-Works | CI1: Intt % | CJ1: Intt Value | CK1: insp% | CL1: Insp Value | CM1: EX-Works Per KM | CN1: Freight Per KM | CO1: Price Including Freight Per KM | CP1: GST % | CQ1: GST Value | CR1: Price Including GST & Freight Per KM | CS1: QTY | CT1: Unit | CU1: Total Price Of Full QTY(Including Freight&GST) | CV1: DRUM CODE | CW1: DRUM SIZE (FxbXtx Ft) | CX1: Party Standard Length(MTR)
A2: ENQ-15138-22-23 | B2: 45627 | C2: FA1300079 | D2: 3 CORE X 185 SQ. MM AL/ARM - WIRE (XLPE) - 33 KV | E2: STEEL | F2: Copper Tape - 0.045 mm | G2: 873.4 | H2: 149 | I2: 130136.6 | J2: Alumimium | K2: 257 | L2: 1499 | M2: 385243 | P2: 0 | R2: Extruded Semiconductive | S2: 180 | T2: 326 | U2: 58680 | V2: HT-XLPE | W2: 140 | X2: 2040 | Y2: 285600 | AB2: 0 | AD2: PVC Type ST-2-PRESSURE EXTRUDED | AE2: 87 | AF2: 335 | AG2: 29145 | AH2: Galvanised Steel Round Wire | AI2: 90.2 | AJ2: 5745 | AK2: 518199 | AL2: FRLSH PVC Type ST-2 | AM2: 89 | AN2: 1411 | AO2: 125579 | AP2: Polypropylene Filler | AR2: 1838 | AV2: 0 | AX2: Water swellable Tape | AY2: 420 | AZ2: 0 | BA2: 0 | BB2: Semi conducting Water Swellable tape | BC2: 400 | BD2: 0 | BE2: 0 | BH2: 0 | BL2: 0 | BP2: 0 | BR2: RUBBERIZED COTTON TAPE | BS2: 375 | BT2: 0 | BU2: 0 | BX2: 0 | BZ2: 171000 | CA2: 1703582.6 | CH2: 1703582.6 | CM2: 1703582.6 | CO2: 1703582.6 | CP2: 0.18 | CQ2: 306644.87 | CR2: 2010227.5 | CS2: 12.5 | CT2: KMS | CU2: 25127843 | CV2: SP0400081 | CW2: CORRUGATED DISPATCH STEEL DRUM 2500 X 1400 X 1250 MM | CX2: 250
A3: ENQ-15138-22-23 | B3: 45627 | C3: FA1300083 | D3: 3 CORE X 400 SQ. MM. AL/ARM - WIRE (XLPE) - 11 KV | E3: STEEL | F3: Copper Tape - 0.045 mm | G3: 873.4 | H3: 136 | I3: 118782.4 | J3: Alumimium | K3: 257 | L3: 3240 | M3: 832680 | P3: 0 | R3: Extruded Semiconductive | S3: 180 | T3: 366 | U3: 65880 | V3: HT-XLPE | W3: 140 | X3: 908 | Y3: 127120 | AB3: 0 | AD3: PVC Type ST-2-PRESSURE EXTRUDED | AE3: 87 | AF3: 305 | AG3: 26535 | AH3: Galvanised Steel Round Wire | AI3: 90.2 | AJ3: 5335 | AK3: 481217 | AL3: FRLSH PVC Type ST-2 | AM3: 89 | AN3: 1308 | AO3: 116412 | AP3: Polypropylene Filler | AR3: 1535 | AV3: 0 | AX3: Water swellable Tape | AY3: 420 | AZ3: 0 | BA3: 0 | BB3: Semi conducting Water Swellable tape | BC3: 400 | BD3: 64 | BE3: 25600 | BH3: 0 | BL3: 0 | BP3: 0 | BR3: RUBBERIZED COTTON TAPE | BS3: 375 | BT3: 0 | BU3: 0 | BX3: 0 | BZ3: 182400 | CA3: 1976626.4 | CH3: 1976626.4 | CM3: 1976626.4 | CO3: 1976626.4 | CP3: 0.18 | CQ3: 355792.75 | CR3: 2332419.1 | CS3: 314 | CT3: KMS | CU3: 732379614 | CV3: SP0400105 | CW3: CORRUGATED DISPATCH STEEL DRUM 2500 X 1500 X 1400 | CX3: 250
A4: ENQ-15138-22-23 | B4: 45627 | C4: FA1300120 | D4: 3 CORE X 70 SQ. MM. AL/ARM - WIRE (XLPE) - 33 KV | E4: STEEL | F4: Copper Tape - 0.045 mm | G4: 873.4 | H4: 134 | I4: 117035.6 | J4: Alumimium | K4: 257 | L4: 567 | M4: 145719 | P4: 0 | R4: Extruded Semiconductive | S4: 180 | T4: 245 | U4: 44100 | V4: HT-XLPE | W4: 140 | X4: 1561 | Y4: 218540 | AB4: 0 | AD4: PVC Type ST-2-PRESSURE EXTRUDED | AE4: 87 | AF4: 280 | AG4: 24360 | AH4: Galvanised Steel Round Wire | AI4: 90.2 | AJ4: 3818 | AK4: 344383.6 | AL4: FRLSH PVC Type ST-2 | AM4: 89 | AN4: 1124 | AO4: 100036 | AP4: Polypropylene Filler | AR4: 1267 | AV4: 0 | AX4: Water swellable Tape | AY4: 420 | AZ4: 0 | BA4: 0 | BB4: Semi conducting Water Swellable tape | BC4: 400 | BD4: 0 | BE4: 0 | BH4: 0 | BL4: 0 | BP4: 0 | BR4: RUBBERIZED COTTON TAPE | BS4: 375 | BT4: 0 | BU4: 0 | BX4: 0 | BZ4: 171000 | CA4: 1165174.2 | CH4: 1165174.2 | CM4: 1165174.2 | CO4: 1165174.2 | CP4: 0.18 | CQ4: 209731.36 | CR4: 1374905.6 | CS4: 3 | CT4: KMS | CU4: 4124717 | CV4: SP0400136 | CW4: CORRUGATED DISPATCH STEEL DRUM 2200 X 1300 X 1200 MM | CX4: 250
A5: ENQ-15138-22-23 | B5: 45627 | C5: FA1300200 | D5: 3 CORE X 95 SQ. MM. AL/ARM WIRE (XLPE) - 33 KV | E5: STEEL | F5: Copper Tape - 0.045 mm | G5: 873.4 | H5: 129 | I5: 112668.6 | J5: Alumimium | K5: 257 | L5: 770 | M5: 197890 | P5: 0 | R5: Extruded Semiconductive | S5: 180 | T5: 265 | U5: 47700 | V5: HT-XLPE | W5: 140 | X5: 1670 | Y5: 233800 | AB5: 0 | AD5: PVC Type ST-2-PRESSURE EXTRUDED | AE5: 87 | AF5: 292 | AG5: 25404 | AH5: Galvanised Steel Round Wire | AI5: 90.2 | AJ5: 3945 | AK5: 355839 | AL5: FRLSH PVC Type ST-2 | AM5: 89 | AN5: 1228 | AO5: 109292 | AP5: Polypropylene Filler | AR5: 1389 | AV5: 0 | AX5: Water swellable Tape | AY5: 420 | AZ5: 0 | BA5: 0 | BB5: Semi conducting Water Swellable tape | BC5: 400 | BD5: 0 | BE5: 0 | BH5: 0 | BL5: 0 | BP5: 0 | BR5: RUBBERIZED COTTON TAPE | BS5: 375 | BT5: 0 | BU5: 0 | BX5: 0 | BZ5: 147200 | CA5: 1229793.6 | CH5: 1229793.6 | CM5: 1229793.6 | CO5: 1229793.6 | CP5: 0.18 | CQ5: 221362.85 | CR5: 1451156.4 | CS5: 4 | CT5: KMS | CU5: 5804626 | CV5: SP0400136 | CW5: CORRUGATED DISPATCH STEEL DRUM 2200 X 1300 X 1200 MM | CX5: 250
A6: ENQ-15138-22-23 | B6: 45627 | C6: FA1300091 | D6: 3 CORE X 300 SQ. MM. AL/ARM - WIRE (XLPE) - 11 KV | E6: STEEL | F6: Copper Tape - 0.045 mm | G6: 873.4 | H6: 122 | I6: 106554.8 | J6: Alumimium | K6: 257 | L6: 2430 | M6: 624510 | P6: 0 | R6: Extruded Semiconductive | S6: 180 | T6: 337 | U6: 60660 | V6: HT-XLPE | W6: 140 | X6: 802 | Y6: 112280 | AB6: 0 | AD6: PVC Type ST-2-PRESSURE EXTRUDED | AE6: 87 | AF6: 277 | AG6: 24099 | AH6: Galvanised Steel Round Wire | AI6: 90.2 | AJ6: 3753 | AK6: 338520.6 | AL6: FRLSH PVC Type ST-2 | AM6: 89 | AN6: 1120 | AO6: 99680 | AP6: Polypropylene Filler | AR6: 1258 | AV6: 0 | AX6: Water swellable Tape | AY6: 420 | AZ6: 0 | BA6: 0 | BB6: Semi conducting Water Swellable tape | BC6: 400 | BD6: 115 | BE6: 46000 | BH6: 34 | BL6: 0 | BP6: 0 | BR6: RUBBERIZED COTTON TAPE | BS6: 375 | BT6: 0 | BU6: 0 | BX6: 0 | BZ6: 171000 | CA6: 1583304.4 | CH6: 1583304.4 | CM6: 1583304.4 | CO6: 1583304.4 | CP6: 0.18 | CQ6: 284994.79 | CR6: 1868299.2 | CS6: 43 | CT6: KMS | CU6: 80336865 | CV6: SP0400136 | CW6: CORRUGATED DISPATCH STEEL DRUM 2200 X 1300 X 1200 MM | CX6: 250
A7: ENQ-15138-22-23 | B7: 45627 | C7: FA1300090 | D7: 3 CORE X 185 SQ. MM AL/ARM - WIRE (XLPE) - 11 KV | E7: STEEL | F7: Copper Tape - 0.045 mm | G7: 873.4 | H7: 105 | I7: 91707 | J7: Alumimium | K7: 257 | L7: 1499 | M7: 385243 | P7: 0 | R7: Extruded Semiconductive | S7: 180 | T7: 276 | U7: 49680 | V7: HT-XLPE | W7: 140 | X7: 663 | Y7: 92820 | AB7: 0 | AD7: PVC Type ST-2-PRESSURE EXTRUDED | AE7: 87 | AF7: 237 | AG7: 20619 | AH7: Galvanised Steel Round Wire | AI7: 90.2 | AJ7: 3244 | AK7: 292608.8 | AL7: FRLSH PVC Type ST-2 | AM7: 89 | AN7: 862 | AO7: 76718 | AP7: Polypropylene Filler | AR7: 914 | AV7: 0 | AX7: Water swellable Tape | AY7: 420 | AZ7: 0 | BA7: 0 | BB7: Semi conducting Water Swellable tape | BC7: 400 | BD7: 0 | BE7: 0 | BH7: 0 | BL7: 0 | BP7: 0 | BR7: RUBBERIZED COTTON TAPE | BS7: 375 | BT7: 0 | BU7: 0 | BX7: 0 | BZ7: 76000 | CA7: 1085395.8 | CH7: 1085395.8 | CM7: 1085395.8 | CO7: 1085395.8 | CP7: 0.18 | CQ7: 195371.24 | CR7: 1280767 | CS7: 2 | CT7: KMS | CU7: 2561534 | CV7: SP0400111 | CW7: CORRUGATED DISPATCH STEEL DRUM 1900 X 1000 X 1000 MM | CX7: 250
A8: ENQ-15138-22-23 | B8: 45627 | C8: FA1300176 | D8: 3 CORE X 150 SQ. MM. AL/ARM - WIRE (XLPE) - 11 KV | E8: STEEL | F8: Copper Tape - 0.045 mm | G8: 873.4 | H8: 99 | I8: 86466.6 | J8: Alumimium | K8: 257 | L8: 1215 | M8: 312255 | P8: 0 | R8: Extruded Semiconductive | S8: 180 | T8: 246 | U8: 44280 | V8: HT-XLPE | W8: 140 | X8: 620 | Y8: 86800 | AB8: 0 | AD8: PVC Type ST-2-PRESSURE EXTRUDED | AE8: 87 | AF8: 200 | AG8: 17400 | AH8: Galvanised Steel Round Wire | AI8: 90.2 | AJ8: 2404 | AK8: 216840.8 | AL8: FRLSH PVC Type ST-2 | AM8: 89 | AN8: 755 | AO8: 67195 | AP8: Polypropylene Filler | AR8: 809 | AV8: 0 | AX8: Water swellable Tape | AY8: 420 | AZ8: 0 | BA8: 0 | BB8: Semi conducting Water Swellable tape | BC8: 400 | BD8: 162 | BE8: 64800 | BH8: 0 | BL8: 0 | BP8: 0 | BR8: RUBBERIZED COTTON TAPE | BS8: 375 | BT8: 0 | BU8: 0 | BX8: 0 | BZ8: 108300 | CA8: 1004337.4 | CH8: 1004337.4 | CM8: 1004337.4 | CO8: 1004337.4 | CP8: 0.18 | CQ8: 180780.73 | CR8: 1185118.1 | CS8: 4 | CT8: KMS | CU8: 4740473 | CV8: SP0400111 | CW8: CORRUGATED DISPATCH STEEL DRUM 1900 X 1000 X 1000 MM | CX8: 250
A9: ENQ-15138-22-23 | B9: 45627 | C9: FA1300197 | D9: 3 CORE X 120 SQ. MM. AL/ARM - WIRE (XLPE) - 11 KV | E9: STEEL | F9: Copper Tape - 0.045 mm | G9: 873.4 | H9: 93 | I9: 81226.2 | J9: Alumimium | K9: 257 | L9: 972 | M9: 249804 | P9: 0 | R9: Extruded Semiconductive | S9: 180 | T9: 232 | U9: 41760 | V9: HT-XLPE | W9: 140 | X9: 567 | Y9: 79380 | AB9: 0 | AD9: PVC Type ST-2-PRESSURE EXTRUDED | AE9: 87 | AF9: 185 | AG9: 16095 | AH9: Galvanised Steel Round Wire | AI9: 90.2 | AJ9: 2244 | AK9: 202408.8 | AL9: FRLSH PVC Type ST-2 | AM9: 89 | AN9: 669 | AO9: 59541 | AP9: Polypropylene Filler | AR9: 704 | AV9: 0 | AX9: Water swellable Tape | AY9: 420 | AZ9: 0 | BA9: 0 | BB9: Semi conducting Water Swellable tape | BC9: 400 | BD9: 59 | BE9: 23600 | BH9: 0 | BL9: 0 | BP9: 0 | BR9: RUBBERIZED COTTON TAPE | BS9: 375 | BT9: 0 | BU9: 0 | BX9: 0 | BZ9: 95000 | CA9: 848815 | CH9: 848815 | CM9: 848815 | CO9: 848815 | CP9: 0.18 | CQ9: 152786.7 | CR9: 1001601.7 | CS9: 10 | CT9: KMS | CU9: 10016017 | CV9: SP0400118 | CW9: CORRUGATED DISPATCH STEEL DRUM 1700 X 1000 X 1200 | CX9: 250
A10: ENQ-15138-22-23 | B10: 45627 | C10: FA1300088 | D10: 3 CORE X 95 SQ. MM. AL/ARM - WIRE (XLPE) - 11 KV (E) | E10: STEEL | F10: Copper Tape - 0.045 mm | G10: 873.4 | H10: 86 | I10: 75112.4 | J10: Alumimium | K10: 257 | L10: 770 | M10: 197890 | P10: 0 | R10: Extruded Semiconductive | S10: 180 | T10: 173 | U10: 31140 | V10: HT-XLPE | W10: 140 | X10: 525 | Y10: 73500 | AB10: 0 | AD10: PVC Type ST-2-PRESSURE EXTRUDED | AE10: 87 | AF10: 129 | AG10: 11223 | AH10: Galvanised Steel Round Wire | AI10: 90.2 | AJ10: 2001 | AK10: 180490.2 | AL10: FRLSH PVC Type ST-2 | AM10: 89 | AN10: 605 | AO10: 53845 | AP10: FILLER | AQ10: 28 | AR10: 573 | AS10: 16044 | AV10: 0 | AX10: Water swellable Tape | AY10: 420 | AZ10: 0 | BA10: 0 | BB10: Semi conducting Water Swellable tape | BC10: 400 | BD10: 52 | BE10: 20800 | BH10: 0 | BL10: 0 | BP10: 0 | BT10: 0 | BX10: 0 | BZ10: 72000 | CA10: 732044.6 | CH10: 732044.6 | CM10: 732044.6 | CO10: 732044.6 | CP10: 0.18 | CQ10: 131768.03 | CR10: 863812.63 | CS10: 23 | CT10: KMS | CU10: 19867690 | CV10: SP0400110 | CW10: CORRUGATED DISPATCH STEEL DRUM 1600 X 900 X 1000 MM | CX10: 250
A11: ENQ-15138-22-23 | B11: 45627 | C11: FA1300027 | D11: 1 CORE X 630 SQ. MM. AL/ARM (XLPE) - 33 KV | E11: STEEL | F11: Copper Tape - 0.045 mm | G11: 873.4 | H11: 69 | I11: 60264.6 | J11: Alumimium | K11: 257 | L11: 1701 | M11: 437157 | P11: 0 | R11: Extruded Semiconductive | S11: 180 | T11: 172 | U11: 30960 | V11: HT-XLPE | W11: 140 | X11: 1040 | Y11: 145600 | Z11: POLY TAPE | AA11: 123.8 | AB11: 0 | AC11: 0 | AD11: PVC Type ST-2 | AE11: 62 | AF11: 193 | AG11: 11966 | AH11: Aluminium Round Wire | AI11: 262 | AJ11: 800 | AK11: 209600 | AL11: FRLSH PVC Type ST-2 | AM11: 89 | AN11: 738 | AO11: 65682 | AR11: 0 | AV11: 0 | AX11: Water swellable Tape | AY11: 420 | AZ11: 0 | BA11: 0 | BB11: Semi conducting Water Swellable tape | BC11: 400 | BD11: 0 | BE11: 0 | BH11: 0 | BL11: 0 | BP11: 0 | BR11: RUBBERIZED COTTON TAPE | BS11: 375 | BT11: 0 | BU11: 0 | BX11: 0 | BZ11: 53200 | CA11: 1014429.6 | CH11: 1014429.6 | CM11: 1014429.6 | CO11: 1014429.6 | CP11: 0.18 | CQ11: 182597.33 | CR11: 1197026.9 | CS11: 547.5 | CT11: KMS | CU11: 655372243 | CV11: SP0400123 | CW11: CORRUGATED DISPATCH STEEL DRUM 2000 X 1000 X 1200 MM | CX11: 500
A12: ENQ-15138-22-23 | B12: 45627 | C12: FA1300066 | D12: 1 CORE X 1000 SQ. MM. AL/ARM (XLPE) - 11 KV | E12: STEEL | F12: Copper Tape - 0.045 mm | G12: 873.4 | H12: 66 | I12: 57644.4 | J12: Alumimium | K12: 257 | L12: 2732 | M12: 702124 | P12: 0 | R12: Extruded Semiconductive | S12: 180 | T12: 200 | U12: 36000 | V12: HT-XLPE | W12: 140 | X12: 465 | Y12: 65100 | Z12: POLY TAPE | AA12: 123.8 | AB12: 0 | AC12: 0 | AD12: PVC Type ST-2 | AE12: 62 | AF12: 185 | AG12: 11470 | AH12: Aluminium Round Wire | AI12: 262 | AJ12: 773 | AK12: 202526 | AL12: FRLSH PVC Type ST-2 | AM12: 89 | AN12: 655 | AO12: 58295 | AR12: 0 | AV12: 0 | AX12: Water swellable Tape | AY12: 420 | AZ12: 0 | BA12: 0 | BB12: Semi conducting Water Swellable tape | BC12: 400 | BD12: 99 | BE12: 39600 | BH12: 59 | BL12: 0 | BP12: 0 | BR12: RUBBERIZED COTTON TAPE | BS12: 375 | BT12: 52 | BU12: 19500 | BX12: 0 | BZ12: 66500 | CA12: 1258759.4 | CH12: 1258759.4 | CM12: 1258759.4 | CO12: 1258759.4 | CP12: 0.18 | CQ12: 226576.69 | CR12: 1485336.1 | CS12: 1 | CT12: KMS | CU12: 1485336 | CV12: SP0400107 | CW12: CORRUGATED DISPATCH STEEL DRUM 2150 X 1080 X 1240 MM | CX12: 500
A13: ENQ-15138-22-23 | B13: 45627 | C13: FA1300018 | D13: 1 CORE X 400 SQ. MM. AL/ARM (XLPE) - 33 KV | E13: STEEL | F13: Copper Tape - 0.045 mm | G13: 873.4 | H13: 60 | I13: 52404 | J13: Alumimium | K13: 257 | L13: 1080 | M13: 277560 | P13: 0 | R13: Extruded Semiconductive | S13: 180 | T13: 141 | U13: 25380 | V13: HT-XLPE | W13: 140 | X13: 870 | Y13: 121800 | Z13: POLY TAPE | AA13: 123.8 | AB13: 0 | AC13: 0 | AD13: PVC Type ST-2 | AE13: 62 | AF13: 147 | AG13: 9114 | AH13: Aluminium Round Wire | AI13: 262 | AJ13: 702 | AK13: 183924 | AL13: FRLSH PVC Type ST-2 | AM13: 89 | AN13: 575 | AO13: 51175 | AR13: 0 | AV13: 0 | AX13: Water swellable Tape | AY13: 420 | AZ13: 54 | BA13: 22680 | BB13: Semi conducting Water Swellable tape | BC13: 400 | BD13: 0 | BE13: 0 | BH13: 52 | BL13: 0 | BP13: 0 | BR13: RUBBERIZED COTTON TAPE | BS13: 375 | BT13: 0 | BU13: 0 | BX13: 0 | BZ13: 53200 | CA13: 797237 | CH13: 797237 | CM13: 797237 | CO13: 797237 | CP13: 0.18 | CQ13: 143502.66 | CR13: 940739.66 | CS13: 17.5 | CT13: KMS | CU13: 16462944 | CV13: SP0400112 | CW13: CORRUGATED DISPATCH STEEL DRUM 2000 X 1000 X 1000 MM | CX13: 500
A14: ENQ-15138-22-23 | B14: 45627 | C14: FA1300019 | D14: 1 CORE X 300 SQ. MM. AL/ARM (XLPE) - 33 KV | E14: STEEL | F14: Copper Tape - 0.045 mm | G14: 873.4 | H14: 55 | I14: 48037 | J14: Alumimium | K14: 257 | L14: 810 | M14: 208170 | P14: 0 | R14: Extruded Semiconductive | S14: 180 | T14: 128 | U14: 23040 | V14: HT-XLPE | W14: 140 | X14: 792 | Y14: 110880 | Z14: POLY TAPE | AA14: 123.8 | AB14: 0 | AC14: 0 | AD14: PVC Type ST-2 | AE14: 62 | AF14: 138 | AG14: 8556 | AH14: Aluminium Round Wire | AI14: 262 | AJ14: 648 | AK14: 169776 | AL14: FRLSH PVC Type ST-2 | AM14: 89 | AN14: 542 | AO14: 48238 | AR14: 0 | AV14: 0 | AX14: Water swellable Tape | AY14: 420 | AZ14: 0 | BA14: 0 | BB14: Semi conducting Water Swellable tape | BC14: 400 | BD14: 0 | BE14: 0 | BH14: 0 | BL14: 0 | BP14: 0 | BR14: RUBBERIZED COTTON TAPE | BS14: 375 | BT14: 0 | BU14: 0 | BX14: 0 | BZ14: 47500 | CA14: 664197 | CH14: 664197 | CM14: 664197 | CO14: 664197 | CP14: 0.18 | CQ14: 119555.46 | CR14: 783752.46 | CS14: 7 | CT14: KMS | CU14: 5486267 | CV14: SP0400110 | CW14: CORRUGATED DISPATCH STEEL DRUM 1600 X 900 X 1000 MM | CX14: 500
A15: ENQ-15138-22-23 | B15: 45627 | C15: FA1300016 | D15: 1 CORE X 630 SQ. MM. AL/ARM (XLPE) - 11 KV | E15: STEEL | F15: Copper Tape - 0.045 mm | G15: 873.4 | H15: 54 | I15: 47163.6 | J15: Alumimium | K15: 257 | L15: 1701 | M15: 437157 | P15: 0 | R15: Extruded Semiconductive | S15: 180 | T15: 150 | U15: 27000 | V15: HT-XLPE | W15: 140 | X15: 374 | Y15: 52360 | Z15: POLY TAPE | AA15: 123.8 | AB15: 0 | AC15: 0 | AD15: PVC Type ST-2 | AE15: 62 | AF15: 134 | AG15: 8308 | AH15: Aluminium Round Wire | AI15: 262 | AJ15: 511 | AK15: 133882 | AL15: FRLSH PVC Type ST-2 | AM15: 89 | AN15: 472 | AO15: 42008 | AR15: 0 | AV15: 0 | AX15: Water swellable Tape | AY15: 420 | AZ15: 0 | BA15: 0 | BB15: Semi conducting Water Swellable tape | BC15: 400 | BD15: 70 | BE15: 28000 | BH15: 0 | BL15: 0 | BP15: 0 | BR15: RUBBERIZED COTTON TAPE | BS15: 375 | BT15: 0 | BU15: 0 | BX15: 0 | BZ15: 48450 | CA15: 824328.6 | CH15: 824328.6 | CM15: 824328.6 | CO15: 824328.6 | CP15: 0.18 | CQ15: 148379.15 | CR15: 972707.75 | CS15: 11 | CT15: KMS | CU15: 10699785 | CV15: SP0400091 | CW15: CORRUGATED DISPATCH STEEL DRUM 1800 X 900 X 1000 | CX15: 500
A16: ENQ-15138-22-23 | B16: 45627 | C16: FA1300047 | D16: 1 CORE X 400 SQ. MM. AL/ARM (XLPE) - 11 KV | E16: STEEL | F16: Copper Tape - 0.045 mm | G16: 873.4 | H16: 45 | I16: 39303 | J16: Alumimium | K16: 257 | L16: 1080 | M16: 277560 | P16: 0 | R16: Extruded Semiconductive | S16: 180 | T16: 122 | U16: 21960 | V16: HT-XLPE | W16: 140 | X16: 305 | Y16: 42700 | AB16: 0 | AD16: PVC Type ST-2 | AE16: 62 | AF16: 96 | AG16: 5952 | AH16: Aluminium Round Wire | AI16: 262 | AJ16: 423 | AK16: 110826 | AL16: FRLSH PVC Type ST-2 | AM16: 89 | AN16: 376 | AO16: 33464 | AR16: 0 | AV16: 0 | AX16: Water swellable Tape | AY16: 420 | AZ16: 0 | BA16: 0 | BB16: Semi conducting Water Swellable tape | BC16: 400 | BD16: 54 | BE16: 21600 | BH16: 0 | BL16: 0 | BP16: 0 | BT16: 0 | BX16: 0 | BZ16: 34200 | CA16: 587565 | CH16: 587565 | CM16: 587565 | CO16: 587565 | CP16: 0.18 | CQ16: 105761.7 | CR16: 693326.7 | CS16: 4 | CT16: KMS | CU16: 2773307 | CV16: SP0400125 | CW16: CORRUGATED DISPATCH STEEL DRUM 1600 X 700 X 915 MM | CX16: 500
A17: ENQ-15138-22-23 | B17: 45627 | C17: FA1300022 | D17: 3 CORE X 50 SQ. MM. AL/ARD - WIRE (XLPE) - 33 KV (E) | E17: STEEL | F17: Copper Tape - 0.045 mm | G17: 873.4 | J17: Alumimium | K17: 257 | R17: Extruded Semiconductive | S17: 180 | V17: HT-XLPE | W17: 140 | AD17: PVC Type ST-2-PRESSURE EXTRUDED | AE17: 87 | AH17: Galvanised Steel Round Wire | AI17: 90.2 | AL17: FRLSH PVC Type ST-2 | AM17: 89 | AP17: Polypropylene Filler | AX17: Water swellable Tape | AY17: 420 | BB17: Semi conducting Water Swellable tape | BC17: 400 | BR17: RUBBERIZED COTTON TAPE | BS17: 375 | BZ17: 106400 | CA17: 106400 | CH17: 106400 | CM17: 106400 | CO17: 106400 | CP17: 0.18 | CQ17: 19152 | CR17: 125552 | CS17: 5 | CT17: KMS | CU17: 627760 | CV17: SP0400112 | CW17: CORRUGATED DISPATCH STEEL DRUM 2000 X 1000 X 1000 MM | CX17: 250
A18: ENQ-15138-22-23 | B18: 45627 | C18: FA1300297 | D18: 3 CORE X 35 SQ. MM. AL/ARM - WIRE (XLPE) - 33 KV (E) | E18: STEEL | F18: Copper Tape - 0.045 mm | G18: 873.4 | J18: Alumimium | K18: 257 | R18: Extruded Semiconductive | S18: 180 | V18: HT-XLPE | W18: 140 | AD18: PVC Type ST-2-PRESSURE EXTRUDED | AE18: 87 | AH18: Galvanised Steel Round Wire | AI18: 90.2 | AL18: FRLSH PVC Type ST-2 | AM18: 89 | AP18: Polypropylene Filler | AX18: Water swellable Tape | AY18: 420 | BB18: Semi conducting Water Swellable tape | BC18: 400 | BR18: RUBBERIZED COTTON TAPE | BS18: 375 | BZ18: 80000 | CA18: 80000 | CH18: 80000 | CM18: 80000 | CO18: 80000 | CP18: 0.18 | CQ18: 14400 | CR18: 94400 | CS18: 4 | CT18: KMS | CU18: 377600 | CV18: SP0400112 | CW18: CORRUGATED DISPATCH STEEL DRUM 2000 X 1000 X 1000 MM | CX18: 250
A19: ENQ-15138-22-23 | B19: 45627 | C19: FA1300313 | D19: 3 CORE X 50 SQ. MM. AL/ARD - WIRE (XLPE) - 11 KV | H19: 0 | L19: 405 | P19: 0 | T19: 165 | X19: 423 | AB19: 0 | AF19: 130 | AJ19: 1804 | AN19: 520 | AR19: 448 | AV19: 0 | AZ19: 0 | BD19: 0 | BH19: 0 | BL19: 0 | BP19: 0 | BT19: 0 | BX19: 0 | CP19: 0.18 | CS19: 7.5 | CT19: KMS | CX19: 250
A20: ENQ-15138-22-23 | B20: 45627 | C20: FA1300081 | D20: 3 CORE X 300 SQ. MM. AL/ARM - WIRE (XLPE) - 33 KV | E20: STEEL | F20: Copper Tape - 0.045 mm | G20: 873.4 | H20: 165 | I20: 144111 | J20: Alumimium | K20: 257 | L20: 2430 | M20: 624510 | P20: 0 | R20: Extruded Semiconductive | S20: 180 | T20: 386 | U20: 69480 | V20: HT-XLPE | W20: 140 | X20: 2385 | Y20: 333900 | AB20: 0 | AD20: PVC Type ST-2-PRESSURE EXTRUDED | AE20: 87 | AF20: 378 | AG20: 32886 | AH20: Galvanised Steel Round Wire | AI20: 90.2 | AJ20: 6463 | AK20: 582962.6 | AL20: FRLSH PVC Type ST-2 | AM20: 89 | AN20: 1558 | AO20: 138662 | AP20: Polypropylene Filler | AR20: 2315 | AV20: 0 | AX20: Water swellable Tape | AY20: 420 | AZ20: 0 | BA20: 0 | BB20: Semi conducting Water Swellable tape | BC20: 400 | BD20: 0 | BE20: 0 | BH20: 0 | BL20: 0 | BP20: 0 | BR20: RUBBERIZED COTTON TAPE | BS20: 375 | BT20: 0 | BU20: 0 | BX20: 0 | BZ20: 190000 | CA20: 2116511.6 | CH20: 2116511.6 | CM20: 2116511.6 | CO20: 2116511.6 | CP20: 0.18 | CQ20: 380972.09 | CR20: 2497483.7 | CS20: 17.5 | CT20: KMS | CU20: 43705965 | CV20: SP0400137 | CW20: CORRUGATED DISPATCH STEEL DRUM 2600 X 1600 X 1600 | CX20: 250
A21: ENQ-15138-22-23 | B21: 45627 | C21: FA1300080 | D21: 3 CORE X 400 SQ. MM AL/ARM - WIRE (XLPE) - 33 KV | E21: STEEL | F21: Copper Tape - 0.045 mm | G21: 873.4 | H21: 179 | I21: 156338.6 | J21: Alumimium | K21: 257 | L21: 3240 | M21: 832680 | P21: 0 | R21: Extruded Semiconductive | S21: 180 | T21: 427 | U21: 76860 | V21: HT-XLPE | W21: 140 | X21: 2621 | Y21: 366940 | AB21: 0 | AD21: PVC Type ST-2-PRESSURE EXTRUDED | AE21: 87 | AF21: 405 | AG21: 35235 | AH21: Galvanised Steel Round Wire | AI21: 90.2 | AJ21: 6975 | AK21: 629145 | AL21: FRLSH PVC Type ST-2 | AM21: 89 | AN21: 1660 | AO21: 147740 | AP21: Polypropylene Filler | AR21: 2672 | AV21: 0 | AX21: Water swellable Tape | AY21: 420 | AZ21: 120 | BA21: 50400 | BB21: Semi conducting Water Swellable tape | BC21: 400 | BD21: 0 | BE21: 0 | BH21: 144 | BL21: 0 | BP21: 0 | BR21: RUBBERIZED COTTON TAPE | BS21: 375 | BT21: 0 | BU21: 0 | BX21: 0 | BZ21: 190000 | CA21: 2485338.6 | CH21: 2485338.6 | CM21: 2485338.6 | CO21: 2485338.6 | CP21: 0.18 | CQ21: 447360.95 | CR21: 2932699.5 | CS21: 222.75 | CT21: KMS | CU21: 653258824 | CV21: SP0400137 | CW21: CORRUGATED DISPATCH STEEL DRUM 2600 X 1600 X 1600 MM | CX21: 250
A22: DOCKET NO. | B22: Base Date | C22: ITEM CODE | D22: PROPOSE ERP ITEM NAME | E22: Propose Drum Type | F22: Insulation Screening(Metallic) | G22: RM Rate(Insulation Screening(Metallic)) | H22: Weight (Insulation Screening (Metallic)) | I22: Cost Insulation Screening(Metallic) | J22: Conductor | K22: RM Rate(Conductor) | L22: Weight(Conductor) | M22: Cost(Conductor) | N22: AL ALLOY | O22: RM Rate(AL Alloy) | P22: Weight(Al Alloy) | Q22: Cost(AL Alloy) | R22: Insulation Screening(Non-Metallic) | S22: RM Rate(Insulation Screening(Non-Metallic)) | T22: Weight(Insulation Screening(Non-Metallic) | U22: Cost(Insulation Screening(Non-Metallic) | V22: Insulation | W22: RM Rate(Insulation) | X22: Weight(Insulation) | Y22: Cost(Insulation) | Z22: Poly Tape | AA22: RM Rate(Poly Tape) | AB22: Weight(Poly Tape) | AC22: Cost(Poly Tape) | AD22: Inner Sheath | AE22: RM Rate(Inner Sheath) | AF22: Weight(Inner Sheath) | AG22: Cost(Inner Sheath) | AH22: Armouring | AI22: RM Rate(Armouring) | AJ22: Weight(Armouring) | AK22: Cost(Armouring) | AL22: Outer Sheath | AM22: RM Rate(Outer Sheath) | AN22: Weight(Outer Sheath) | AO22: Cost(Outer Sheath) | AP22: Filler | AQ22: RM Rate(Filler) | AR22: Weight(Filler) | AS22: Cost(Filler) | AT22: Grease | AU22: RM Rate(Grease) | AV22: Weight(Grease) | AW22: Cost(Grease) | AX22: Water Swellable Tape | AY22: RM Rate(Water Swellable Tape) | AZ22: Weight(Water Swellable Tape) | BA22: Cost(Water Swellable Tape) | BB22: Semi Conducting Water Swellable Tape | BC22: RM Rate(Semi Conducting Water Swellable Tape) | BD22: Weight(Semi Conducting Water Swellable Tape) | BE22: Cost(Semi Conducting Water Swellable Tape) | BF22: Semicon Tape | BG22: RM Rate(Semicon Tape) | BH22: Weight(Semicon Tape) | BI22: Cost(Semicon Tape) | BJ22: Glass Fiber Tape | BK22: RM Rate(Glass Fiber Tape) | BL22: Weight(Glass Fiber Tape) | BM22: Cost(Glass Fiber Tape) | BN22: Copper Wire 0.8MM | BO22: RM Rate(Copper Wire 0.8MM) | BP22: Weight(Copper Wire 0.8MM) | BQ22: Cost(Copper Wire 0.8MM) | BR22: Rubberized Cotton Tape | BS22: RM Rate(Rubberized Cotton Tape) | BT22: Weight(Rubberized Cotton Tape) | BU22: Cost(Rubberized Cotton Tape) | BV22: Water Tight Compound | BW22: RM Rate(Water Tight Compound) | BX22: Weight(Water Tight Compound) | BY22: Cost(Water Tight Compound) | BZ22: Drum Cost Per KM | CA22: Total RM Cost | CB22: FIRM % | CC22: Firm Value | CD22: MFG% | CE22: MFG Value | CF22: PROF% | CG22: Profit Value | CH22: 1st EX-Works | CI22: Intt % | CJ22: Intt Value | CK22: insp% | CL22: Insp Value | CM22: EX-Works Per KM | CN22: Freight Per KM | CO22: Price Including Freight Per KM | CP22: GST % | CQ22: GST Value | CR22: Price Including GST & Freight Per KM | CS22: QTY | CT22: Unit | CU22: Total Price Of Full QTY(Including Freight&GST) | CV22: DRUM CODE | CW22: DRUM SIZE (FxbXtx Ft) | CX22: Party Standard Length(MTR)
A23: ENQ-15138-22-23 | B23: 45627 | C23: FA1300009 | D23: 1 CORE X 300 SQ. MM. AL./ARM (XLPE) - 11 KV | E23: STEEL | F23: Copper Tape - 0.045 mm | G23: 873.4 | H23: 41 | I23: 35809.4 | J23: Alumimium | K23: 257 | L23: 810 | M23: 208170 | P23: 0 | R23: Extruded Semiconductive | S23: 180 | T23: 112 | U23: 20160 | V23: HT-XLPE | W23: 140 | X23: 267 | Y23: 37380 | Z23: POLY TAPE | AA23: 123.8 | AB23: 0 | AC23: 0 | AD23: PVC Type ST-2 | AE23: 62 | AF23: 87 | AG23: 5394 | AH23: Aluminium Round Wire | AI23: 262 | AJ23: 388 | AK23: 101656 | AL23: FRLSH PVC Type ST-2 | AM23: 89 | AN23: 318 | AO23: 28302 | AR23: 0 | AV23: 0 | AX23: Water swellable Tape | AY23: 420 | AZ23: 0 | BA23: 0 | BB23: Semi conducting Water Swellable tape | BC23: 400 | BD23: 38 | BE23: 15200 | BH23: 0 | BL23: 0 | BP23: 0 | BR23: RUBBERIZED COTTON TAPE | BS23: 375 | BT23: 0 | BU23: 0 | BX23: 0 | BZ23: 27000 | CA23: 479071.4 | CH23: 479071.4 | CM23: 479071.4 | CO23: 479071.4 | CP23: 0.18 | CQ23: 86232.85 | CR23: 565304.25 | CS23: 6.5 | CT23: KMS | CU23: 3674478 | CV23: SP0400152 | CW23: CORRUGATED DISPATCH STEEL DRUM 1500 X 800 X 915 | CX23: 500

Sheet AUTO CALCULATION SHEET (2)
A2: TP Odisha DISCOMs
A4: TENDER SPECIFICATION NO () | B4: TPCODL / CCG / FY 24-25 / 1000001767
A5: TENDER DESCRIPTION () | B5: One Year Rate Contract for supply of HT Cables at TPCODL, TPNODL, TPSODL & TPWODL
A6: Last Date & Time of Submission () | B6: 17.02.2025 [16:00 Hrs]
A7: REVERSE AUCTION | B7: No of bidders allowed to participate in RA process shall be: Total No of bidders on whom tender would be split PLUS 2 more bidders. Illustrative example: Total no of qualified bidders is 10 & tender needs to split amongst 4 bidders.
A8: Price () | B8: The line-item prices shall be subject to Price Variation clause as per latest IEEMA Circular. (Base Date of IEEMA for price consideration shall be Dec-24).
A9: Validity () | B9: Bids shall remain valid for 180 days from the due date of submission of the bid. Notwithstanding clause above, CCG may solicit the Bidder’s consent to an extension of the Period of Bid Validity. The request and responses thereto shall be made in writing.
A10: Delivery Period () | B10: The delivery period for a quantity of up to 40 KM shall be 90 days from the date of issuance of the RO or GTP drawing approval, whichever is later.
A11: Payment Terms () | B11: 100% payment will be made within 60 days of submission of error-free certified invoice complete in all respects. For MSME payment cycle shall be within 45 days.
A12: Standard length () | B12: Cable length on one drum shall be 250 meters for 3 core cables & 500 meters for 1 core cables max. +/- 5%. (As per PO Terms.)
A13: Packing () | B13: Steel drums shall be provided. Drum shall be free from sharp edges and visual defect. Stencil plate on one flange side of the drum and laminated paper sheet on other side flange of drum.
A14: Technical Specification
N16: =Sheet1!J1 -> Conductor | S16: AL ALLOY | U16: Insulation Screening (Metallic) | AC16: Insulation Screening (Non-Metallic) | AE16: Insulation | AK16: POLY TAPE | AL16: Inner Sheath | AS16: Armouring | BC16: Outer Sheath | BF16: Rs. 15/kg extra | BM16: FILLER | BN16: GREASE | BO16: Water swellable Tape | BP16: Semi conducting Water Swellable tape | BQ16: SEMICON TAPE | BR16: GLASS FIBER TAPE | BS16: COPPER WIRE 0.8 MM | BT16: RUBBERIZED COTTON TAPE | BU16: Water Tight Compound | BZ16: DRUM COST PER KM | CA16: TOTAL RM COST | CB16: EXTRA CONSUMPTION | CC16: EXTRA CONSUMPTION VALUE
A17: DOCKET NO. | B17: =Sheet1!B1 -> Base Date | C17: ITEM CODE | D17: PROPOSE ERP ITEM NAME | E17: EX-WORKS (PER KM) | F17: FREIGHT PER KM | G17: PRICE INCLUDING FREIGHT (PER KM) | H17: GST % | I17: GST VALUE | J17: PRICE INCLUDING GST & FREIGHT (PER KM) | K17: QTY | L17: Unit | M17: TOTAL PRICE OF FULL QTY (INCLUDING FRIGHT & GST) | N17: Alumimium | O17: Alumimium ALLOY | P17: Copper | Q17: Flexible Copper | R17: Galvanized steel wire | S17: Alumimium | T17: Alumimium ALLOY | U17: Coper tape - 0.1 mm | V17: Copper Tape - 0.03 mm | W17: Copper Tape - 0.035 mm | X17: Copper Tape - 0.04 mm | Y17: Copper Tape - 0.045 mm | Z17: Copper Tape - 0.050 mm | AA17: Copper Tape - 0.060 mm | AB17: Copper Tape - 0.075 mm(DOUBLE) | AC17: Extruded semiconductive | AD17: Extruded Semiconductive(Stripable) | AE17: HT-XLPE | AF17: LT-XLPE | AG17: TR XLPE | AH17: Type A PVC | AI17: Type C PVC (HR) | AJ17: XLPE | AK17: POLY TAPE | AL17: FR PVC Type ST-1 | AM17: FR PVC Type ST-2 | AN17: FRLSH PVC Type ST-2 | AO17: PVC Type ST-1 | AP17: PVC Type ST-1-PRESSURE EXTRUDED | AQ17: PVC Type ST-2 | AR17: PVC Type ST-2-PRESSURE EXTRUDED | AS17: ACSR CORE WIRE | AT17: ACSR DOG STEEL WIRE | AU17: Aluminium Flat Strip | AV17: Aluminium Round Wire | AW17: Double Steel Tape | AX17: Galvanised Steel Flat Strip | AY17: Galvanised Steel Flat Strip (Double) | AZ17: Galvanised Steel Flat Strip-B | BA17: Galvanised Steel Round Wire | BB17: Galvanised Steel Round Wire (Double) | BC17: FR PVC Type ST-1 | BD17: FR PVC Type ST-2 | BE17: FRLSH PVC Type ST-1 | BF17: FRLSH PVC Type ST-2 | BG17: PE, ST-3 | BH17: PE, ST-7 | BI17: PVC Type ST-1 | BJ17: PVC Type ST-2 | BK17: PVC Type ST-2-PRESSURE EXTRUDED | BL17: PP FILLER | BM17: FILLER | BN17: NCWBT | BO17: Water swellable Tape | BP17: Semi conducting Water Swellable tape | BQ17: SEMICON TAPE | BR17: GLASS FIBER TAPE | BS17: COPPER WIRE 0.8 MM | BT17: RUBBERIZED COTTON TAPE | BU17: Water Tight Compound | BV17: =Sheet1!E1 -> Propose Drum Type | BW17: =Sheet1!CV1 -> DRUM CODE | BX17: =Sheet1!CW1 -> DRUM SIZE (FxbXtx Ft) | BY17: =Sheet1!CX1 -> Party Standard Length(MTR) | CB17: Consider 1% extra cost for complete cable . | CD17: MFG% | CE17: MFG VALUE | CF17: PROF% | CG17: PROFIT VALUE | CH17: 1ST EX-WORKS | CI17: Intt % | CJ17: INTT VALUE | CK17: insp% | CL17: INSP VALUE
N18: 256 | O18: =+IFERROR(VLOOKUP($O$17,Sheet1!J:L,2,0),0) -> 0 | P18: =+IFERROR(VLOOKUP($P$17,Sheet1!J:M,2,0),0) -> 0 | Q18: =+IFERROR(VLOOKUP($Q$17,Sheet1!J:M,2,0),0) -> 0 | R18: =+IFERROR(VLOOKUP($R$17,Sheet1!J:M,2,0),0) -> 0 | S18: =+IFERROR(VLOOKUP($S$17,Sheet1!N:Q,2,0),0) -> 0 | T18: =+IFERROR(VLOOKUP($T$17,Sheet1!N:O,2,0),0) -> 0 | U18: =+IFERROR(VLOOKUP($U$17,Sheet1!F:I,2,0),0) -> 0 | V18: =+IFERROR(VLOOKUP($V$17,Sheet1!F:I,2,0),0) -> 0 | W18: =+IFERROR(VLOOKUP($W$17,Sheet1!F:I,2,0),0) -> 0 | X18: =+IFERROR(VLOOKUP($X$17,Sheet1!F:I,2,0),0) -> 0 | Y18: 924 | Z18: =+IFERROR(VLOOKUP($Z$17,Sheet1!F:I,2,0),0) -> 0 | AA18: =+IFERROR(VLOOKUP($AA$17,Sheet1!F:I,2,0),0) -> 0 | AB18: =+IFERROR(VLOOKUP($AB$17,Sheet1!F:I,2,0),0) -> 0 | AC18: =+IFERROR(VLOOKUP($AC$17,Sheet1!R:U,2,0),0) -> 180 | AD18: =+IFERROR(VLOOKUP($AD$17,Sheet1!R:U,2,0),0) -> 0 | AE18: =+IFERROR(VLOOKUP($AE$17,Sheet1!V:Y,2,0),0) -> 140 | AF18: =+IFERROR(VLOOKUP($AF$17,Sheet1!V:Y,2,0),0) -> 0 | AG18: =+IFERROR(VLOOKUP($AG$17,Sheet1!V:Y,2,0),0) -> 0 | AH18: =+IFERROR(VLOOKUP($AH$17,Sheet1!V:Y,2,0),0) -> 0 | AI18: =+IFERROR(VLOOKUP($AI$17,Sheet1!V:Y,2,0),0) -> 0 | AJ18: =+IFERROR(VLOOKUP($AJ$17,Sheet1!V:Y,2,0),0) -> 0 | AK18: 124 | AL18: =+IFERROR(VLOOKUP($AL$17,Sheet1!AD2:AG840,2,0),0) -> 0 | AM18: =+IFERROR(VLOOKUP($AM$17,Sheet1!AD2:AG840,2,0),0) -> 0 | AN18: =+IFERROR(VLOOKUP($AN$17,Sheet1!AD2:AG840,2,0),0) -> 0 | AO18: =+IFERROR(VLOOKUP($AO$17,Sheet1!AD2:AG840,2,0),0) -> 0 | AP18: =+IFERROR(VLOOKUP($AP$17,Sheet1!AD2:AG840,2,0),0) -> 0 | AQ18: 69 | AS18: =+IFERROR(VLOOKUP($AS$17,Sheet1!AH2:AK840,2,0),0) -> 0 | AT18: =+IFERROR(VLOOKUP($AT$17,Sheet1!AH2:AK840,2,0),0) -> 0 | AU18: =+IFERROR(VLOOKUP($AU$17,Sheet1!AH2:AK840,2,0),0) -> 0 | AV18: 261 | AW18: =+IFERROR(VLOOKUP($AW$17,Sheet1!AH2:AK840,2,0),0) -> 0 | AX18: =+IFERROR(VLOOKUP($AX$17,Sheet1!AH2:AK840,2,0),0) -> 0 | AY18: =+IFERROR(VLOOKUP($AY$17,Sheet1!AH2:AK840,2,0),0) -> 0 | AZ18: =+IFERROR(VLOOKUP($AZ$17,Sheet1!AH2:AK840,2,0),0) -> 0 | BA18: 89 | BB18: =+IFERROR(VLOOKUP($BB$17,Sheet1!AH2:AK840,2,0),0) -> 0 | BC18: =+IFERROR(VLOOKUP($BC$17,Sheet1!AL2:AO840,2,0),0) -> 0 | BD18: =+IFERROR(VLOOKUP($BD$17,Sheet1!AL2:AO840,2,0),0) -> 0 | BE18: =+IFERROR(VLOOKUP($BE$17,Sheet1!AL2:AO840,2,0),0) -> 0 | BF18: =90+15 -> 105 | BG18: =+IFERROR(VLOOKUP($BG$17,Sheet1!AL2:AO840,2,0),0) -> 0 | BH18: =+IFERROR(VLOOKUP($BH$17,Sheet1!AL2:AO840,2,0),0) -> 0 | BI18: =+IFERROR(VLOOKUP($BI$17,Sheet1!AL2:AO840,2,0),0) -> 0 | BJ18: =+IFERROR(VLOOKUP($BJ$17,Sheet1!AL2:AO840,2,0),0) -> 0 | BK18: =+IFERROR(VLOOKUP($BK$17,Sheet1!AL2:AO840,2,0),0) -> 0 | BL18: 85 | BN18: 340 | BP18: =+IFERROR(VLOOKUP($BP$17,Sheet1!BB2:BE840,2,0),0) -> 400 | BQ18: =+IFERROR(VLOOKUP($BQ$17,Sheet1!BF2:BI840,2,0),0) -> RM Rate(Semicon Tape) | BR18: =+IFERROR(VLOOKUP($BR$17,Sheet1!BJ2:BM840,2,0),0) -> RM Rate(Glass Fiber Tape) | BS18: =+IFERROR(VLOOKUP($BS$17,Sheet1!BN2:BQ840,2,0),0) -> 0 | BT18: =+IFERROR(VLOOKUP($BT$17,Sheet1!BR2:BU840,2,0),0) -> 375 | BU18: =+IFERROR(VLOOKUP($BU$17,Sheet1!BV2:BY840,2,0),0) -> RM Rate(Water Tight Compound) | BX18: Non Returnable Steel Drum
A19: =Sheet1!A3 -> ENQ-15138-22-23 | B19: =Sheet1!B3 -> 45627 | C19: =Sheet1!C3 -> FA1300083 | D19: =Sheet1!D3 -> 3 CORE X 400 SQ. MM. AL/ARM - WIRE (XLPE) - 11 KV | E19: =CH19+CJ19+CL19 -> 2890355 | F19: =ROUNDUP(M43,0) -> 52166 | G19: =E19+F19 -> 2942521 | H19: =Sheet1!CP3 -> 0.18 | I19: =G19*H19 -> 529653.79 | J19: =G19+I19 -> 3472174.8 | K19: =Sheet1!CS3 -> 314 | L19: =Sheet1!CT3 -> KMS | M19: =J19*K19 -> 1.0902629e+09 | N19: =+IFERROR(VLOOKUP($N$17,Sheet1!J3:L3,3,0),0) -> 3240 | O19: =+IFERROR(VLOOKUP($O$17,Sheet1!J3:L3,3,0),0) -> 0 | P19: =+IFERROR(VLOOKUP($P$17,Sheet1!J3:M3,3,0),0) -> 0 | Q19: =+IFERROR(VLOOKUP($Q$17,Sheet1!J3:M3,3,0),0) -> 0 | R19: =+IFERROR(VLOOKUP($R$17,Sheet1!J3:M3,3,0),0) -> 0 | S19: =+IFERROR(VLOOKUP($S$17,Sheet1!N3:Q3,3,0),0) -> 0 | T19: =+IFERROR(VLOOKUP($T$17,Sheet1!N3:Q3,3,0),0) -> 0 | U19: =+IFERROR(VLOOKUP($U$17,Sheet1!F3:I3,3,0),0) -> 0 | V19: =+IFERROR(VLOOKUP($V$17,Sheet1!F3:I3,3,0),0) -> 0 | W19: =+IFERROR(VLOOKUP($W$17,Sheet1!F3:I3,3,0),0) -> 0 | X19: =+IFERROR(VLOOKUP($X$17,Sheet1!F3:I3,3,0),0) -> 0 | Y19: 176 | Z19: =+IFERROR(VLOOKUP($Z$17,Sheet1!F3:I3,3,0),0) -> 0 | AA19: =+IFERROR(VLOOKUP($AA$17,Sheet1!F3:I3,3,0),0) -> 0 | AB19: =+IFERROR(VLOOKUP($AB$17,Sheet1!F3:I3,3,0),0) -> 0 | AC19: 518 | AD19: =+IFERROR(VLOOKUP($AD$17,Sheet1!R3:U3,2,0),0) -> 0 | AE19: 930 | AF19: =+IFERROR(VLOOKUP($AF$17,Sheet1!V3:Y3,3,0),0) -> 0 | AG19: =+IFERROR(VLOOKUP($AG$17,Sheet1!V3:Y3,3,0),0) -> 0 | AH19: =+IFERROR(VLOOKUP($AH$17,Sheet1!V3:Y3,3,0),0) -> 0 | AI19: =+IFERROR(VLOOKUP($AI$17,Sheet1!V3:Y3,3,0),0) -> 0 | AJ19: =+IFERROR(VLOOKUP($AJ$17,Sheet1!V3:Y3,3,0),0) -> 0 | AK19: =+IFERROR(VLOOKUP($AK$17,Sheet1!Z3:AB3,3,0),0) -> 0 | AL19: =+IFERROR(VLOOKUP($AL$17,Sheet1!AD3:AG3,3,0),0) -> 0 | AM19: =+IFERROR(VLOOKUP($AM$17,Sheet1!AD3:AG3,3,0),0) -> 0 | AN19: =+IFERROR(VLOOKUP($AN$17,Sheet1!AD3:AG3,3,0),0) -> 0 | AO19: =+IFERROR(VLOOKUP($AO$17,Sheet1!AD3:AG3,3,0),0) -> 0 | AP19: =+IFERROR(VLOOKUP($AP$17,Sheet1!AD3:AG3,3,0),0) -> 0 | AQ19: 1027 | AS19: =+IFERROR(VLOOKUP($AS$17,Sheet1!AH3:AK3,3,0),0) -> 0 | AT19: =+IFERROR(VLOOKUP($AT$17,Sheet1!AH3:AK3,3,0),0) -> 0 | AU19: =+IFERROR(VLOOKUP($AU$17,Sheet1!AH3:AK3,3,0),0) -> 0 | AV19: =+IFERROR(VLOOKUP($AV$17,Sheet1!AH3:AK3,3,0),0) -> 0 | AW19: =+IFERROR(VLOOKUP($AW$17,Sheet1!AH3:AK3,3,0),0) -> 0 | AX19: =+IFERROR(VLOOKUP($AX$17,Sheet1!AH3:AK3,3,0),0) -> 0 | AY19: =+IFERROR(VLOOKUP($AY$17,Sheet1!AH3:AK3,3,0),0) -> 0 | AZ19: =+IFERROR(VLOOKUP($AZ$17,Sheet1!AH3:AK3,3,0),0) -> 0 | BA19: 5643 | BB19: =+IFERROR(VLOOKUP($BB$17,Sheet1!AH3:AK3,3,0),0) -> 0 | BC19: =+IFERROR(VLOOKUP($BC$17,Sheet1!AL3:AO3,3,0),0) -> 0 | BD19: =+IFERROR(VLOOKUP($BD$17,Sheet1!AL3:AO3,3,0),0) -> 0 | BE19: =+IFERROR(VLOOKUP($BE$17,Sheet1!AL3:AO3,3,0),0) -> 0 | BF19: 1377 | BG19: =+IFERROR(VLOOKUP($BG$17,Sheet1!AL3:AO3,3,0),0) -> 0 | BH19: =+IFERROR(VLOOKUP($BH$17,Sheet1!AL3:AO3,3,0),0) -> 0 | BI19: =+IFERROR(VLOOKUP($BI$17,Sheet1!AL3:AO3,3,0),0) -> 0 | BJ19: =+IFERROR(VLOOKUP($BJ$17,Sheet1!AL3:AO3,3,0),0) -> 0 | BK19: =+IFERROR(VLOOKUP($BK$17,Sheet1!AL3:AO3,3,0),0) -> 0 | BL19: 1032 | BM19: =+IFERROR(VLOOKUP($BM$17,Sheet1!AP3:AS3,3,0),0) -> 0 | BN19: 58 | BO19: =+IFERROR(VLOOKUP($BO$17,Sheet1!AX3:BA3,3,0),0) -> 0 | BP19: 95 | BQ19: =+IFERROR(VLOOKUP($BQ$17,Sheet1!BF3:BI3,3,0),0) -> 0 | BR19: =+IFERROR(VLOOKUP($BR$17,Sheet1!BJ3:BM3,3,0),0) -> 0 | BS19: =+IFERROR(VLOOKUP($BS$17,Sheet1!BN3:BQ3,3,0),0) -> 0 | BT19: 60 | BU19: =+IFERROR(VLOOKUP($BU$17,Sheet1!BV3:BY3,3,0),0) -> 0 | BV19: =Sheet1!E3 -> STEEL | BW19: SP0400136 | BX19: CORRUGATED DISPATCH STEEL DRUM 2200 X 1300 X 1200 MM | BY19: =Sheet1!CX3 -> 250 | BZ19: =31500/0.25 -> 126000 | CA19: =SUMPRODUCT($N$18:$BU$18,N19:BU19)+BZ19 -> 2227119 | CB19: 0.01 | CC19: =CA19*CB19 -> 22271.19 | CD19: 0.25 | CE19: =CA19*CD19 -> 556779.75 | CF19: =Sheet1!CF3 -> 0 | CG19: =CA19*CF19 -> 0 | CH19: =CA19+CC19+CE19+CG19 -> 2806169.9 | CI19: 0.02 | CJ19: =CH19*CI19 -> 56123.399 | CK19: 0.01 | CL19: =CH19*CK19 -> 28061.699
A20: =Sheet1!A6 -> ENQ-15138-22-23 | B20: =Sheet1!B6 -> 45627 | C20: =Sheet1!C6 -> FA1300091 | D20: =Sheet1!D6 -> 3 CORE X 300 SQ. MM. AL/ARM - WIRE (XLPE) - 11 KV | E20: =CH20+CJ20+CL20 -> 2318788.3 | F20: =ROUNDUP(M44,0) -> 52907 | G20: =E20+F20 -> 2371695.3 | H20: =Sheet1!CP6 -> 0.18 | I20: =G20*H20 -> 426905.16 | J20: =G20+I20 -> 2798600.5 | K20: =Sheet1!CS6 -> 43 | L20: =Sheet1!CT6 -> KMS | M20: =J20*K20 -> 1.2033982e+08 | N20: =+IFERROR(VLOOKUP($N$17,Sheet1!J6:L6,3,0),0) -> 2430 | O20: =+IFERROR(VLOOKUP($O$17,Sheet1!J6:L6,3,0),0) -> 0 | P20: =+IFERROR(VLOOKUP($P$17,Sheet1!J6:M6,3,0),0) -> 0 | Q20: =+IFERROR(VLOOKUP($Q$17,Sheet1!J6:M6,3,0),0) -> 0 | R20: =+IFERROR(VLOOKUP($R$17,Sheet1!J6:M6,3,0),0) -> 0 | S20: =+IFERROR(VLOOKUP($S$17,Sheet1!N6:Q6,3,0),0) -> 0 | T20: =+IFERROR(VLOOKUP($T$17,Sheet1!N6:Q6,3,0),0) -> 0 | U20: =+IFERROR(VLOOKUP($U$17,Sheet1!F6:I6,3,0),0) -> 0 | V20: =+IFERROR(VLOOKUP($V$17,Sheet1!F6:I6,3,0),0) -> 0 | W20: =+IFERROR(VLOOKUP($W$17,Sheet1!F6:I6,3,0),0) -> 0 | X20: =+IFERROR(VLOOKUP($X$17,Sheet1!F6:I6,3,0),0) -> 0 | Y20: 161 | Z20: =+IFERROR(VLOOKUP($Z$17,Sheet1!F6:I6,3,0),0) -> 0 | AA20: =+IFERROR(VLOOKUP($AA$17,Sheet1!F6:I6,3,0),0) -> 0 | AB20: =+IFERROR(VLOOKUP($AB$17,Sheet1!F6:I6,3,0),0) -> 0 | AC20: 465 | AD20: =+IFERROR(VLOOKUP($AD$17,Sheet1!R6:U6,2,0),0) -> 0 | AE20: 835 | AF20: =+IFERROR(VLOOKUP($AF$17,Sheet1!V6:Y6,3,0),0) -> 0 | AG20: =+IFERROR(VLOOKUP($AG$17,Sheet1!V6:Y6,3,0),0) -> 0 | AH20: =+IFERROR(VLOOKUP($AH$17,Sheet1!V6:Y6,3,0),0) -> 0 | AI20: =+IFERROR(VLOOKUP($AI$17,Sheet1!V6:Y6,3,0),0) -> 0 | AJ20: =+IFERROR(VLOOKUP($AJ$17,Sheet1!V6:Y6,3,0),0) -> 0 | AK20: =+IFERROR(VLOOKUP($AK$17,Sheet1!Z6:AB6,3,0),0) -> 0 | AL20: =+IFERROR(VLOOKUP($AL$17,Sheet1!AD6:AG6,3,0),0) -> 0 | AM20: =+IFERROR(VLOOKUP($AM$17,Sheet1!AD6:AG6,3,0),0) -> 0 | AN20: =+IFERROR(VLOOKUP($AN$17,Sheet1!AD6:AG6,3,0),0) -> 0 | AO20: =+IFERROR(VLOOKUP($AO$17,Sheet1!AD6:AG6,3,0),0) -> 0 | AP20: =+IFERROR(VLOOKUP($AP$17,Sheet1!AD6:AG6,3,0),0) -> 0 | AQ20: 885 | AS20: =+IFERROR(VLOOKUP($AS$17,Sheet1!AH6:AK6,3,0),0) -> 0 | AT20: =+IFERROR(VLOOKUP($AT$17,Sheet1!AH6:AK6,3,0),0) -> 0 | AU20: =+IFERROR(VLOOKUP($AU$17,Sheet1!AH6:AK6,3,0),0) -> 0 | AV20: =+IFERROR(VLOOKUP($AV$17,Sheet1!AH6:AK6,3,0),0) -> 0 | AW20: =+IFERROR(VLOOKUP($AW$17,Sheet1!AH6:AK6,3,0),0) -> 0 | AX20: =+IFERROR(VLOOKUP($AX$17,Sheet1!AH6:AK6,3,0),0) -> 0 | AY20: =+IFERROR(VLOOKUP($AY$17,Sheet1!AH6:AK6,3,0),0) -> 0 | AZ20: =+IFERROR(VLOOKUP($AZ$17,Sheet1!AH6:AK6,3,0),0) -> 0 | BA20: 4072 | BB20: =+IFERROR(VLOOKUP($BB$17,Sheet1!AH6:AK6,3,0),0) -> 0 | BC20: =+IFERROR(VLOOKUP($BC$17,Sheet1!AL6:AO6,3,0),0) -> 0 | BD20: =+IFERROR(VLOOKUP($BD$17,Sheet1!AL6:AO6,3,0),0) -> 0 | BE20: =+IFERROR(VLOOKUP($BE$17,Sheet1!AL6:AO6,3,0),0) -> 0 | BF20: 1190 | BG20: =+IFERROR(VLOOKUP($BG$17,Sheet1!AL6:AO6,3,0),0) -> 0 | BH20: =+IFERROR(VLOOKUP($BH$17,Sheet1!AL6:AO6,3,0),0) -> 0 | BI20: =+IFERROR(VLOOKUP($BI$17,Sheet1!AL6:AO6,3,0),0) -> 0 | BJ20: =+IFERROR(VLOOKUP($BJ$17,Sheet1!AL6:AO6,3,0),0) -> 0 | BK20: =+IFERROR(VLOOKUP($BK$17,Sheet1!AL6:AO6,3,0),0) -> 0 | BL20: 862 | BM20: =+IFERROR(VLOOKUP($BM$17,Sheet1!AP6:AS6,3,0),0) -> 0 | BN20: 38 | BO20: =+IFERROR(VLOOKUP($BO$17,Sheet1!AX6:BA6,3,0),0) -> 0 | BP20: 86 | BQ20: =+IFERROR(VLOOKUP($BQ$17,Sheet1!BF6:BI6,3,0),0) -> 0 | BR20: =+IFERROR(VLOOKUP($BR$17,Sheet1!BJ6:BM6,3,0),0) -> 0 | BS20: =+IFERROR(VLOOKUP($BS$17,Sheet1!BN6:BQ6,3,0),0) -> 0 | BT20: 54 | BU20: =+IFERROR(VLOOKUP($BU$17,Sheet1!BV6:BY6,3,0),0) -> 0 | BV20: =Sheet1!E6 -> STEEL | BW20: =Sheet1!CV6 -> SP0400136 | BX20: =Sheet1!CW6 -> CORRUGATED DISPATCH STEEL DRUM 2200 X 1300 X 1200 MM | BY20: =Sheet1!CX6 -> 250 | BZ20: =31500/0.25 -> 126000 | CA20: =SUMPRODUCT($N$18:$BU$18,N20:BU20)+BZ20 -> 1786707 | CB20: 0.01 | CC20: =CA20*CB20 -> 17867.07 | CD20: 0.25 | CE20: =CA20*CD20 -> 446676.75 | CF20: =Sheet1!CF6 -> 0 | CG20: =CA20*CF20 -> 0 | CH20: =CA20+CC20+CE20+CG20 -> 2251250.8 | CI20: 0.02 | CJ20: =CH20*CI20 -> 45025.016 | CK20: 0.01 | CL20: =CH20*CK20 -> 22512.508
A21: =Sheet1!A7 -> ENQ-15138-22-23 | B21: =Sheet1!B7 -> 45627 | C21: =Sheet1!C7 -> FA1300090 | D21: =Sheet1!D7 -> 3 CORE X 185 SQ. MM AL/ARM - WIRE (XLPE) - 11 KV | E21: =CH21+CJ21+CL21 -> 1723155.2 | F21: =ROUNDUP(M45,0) -> 65000 | G21: =E21+F21 -> 1788155.2 | H21: =Sheet1!CP7 -> 0.18 | I21: =G21*H21 -> 321867.94 | J21: =G21+I21 -> 2110023.2 | K21: =Sheet1!CS7 -> 2 | L21: =Sheet1!CT7 -> KMS | M21: =J21*K21 -> 4220046.4 | N21: =+IFERROR(VLOOKUP($N$17,Sheet1!J7:L7,3,0),0) -> 1499 | O21: =+IFERROR(VLOOKUP($O$17,Sheet1!J7:L7,3,0),0) -> 0 | P21: =+IFERROR(VLOOKUP($P$17,Sheet1!J7:M7,3,0),0) -> 0 | Q21: =+IFERROR(VLOOKUP($Q$17,Sheet1!J7:M7,3,0),0) -> 0 | R21: =+IFERROR(VLOOKUP($R$17,Sheet1!J7:M7,3,0),0) -> 0 | S21: =+IFERROR(VLOOKUP($S$17,Sheet1!N7:Q7,3,0),0) -> 0 | T21: =+IFERROR(VLOOKUP($T$17,Sheet1!N7:Q7,3,0),0) -> 0 | U21: =+IFERROR(VLOOKUP($U$17,Sheet1!F7:I7,3,0),0) -> 0 | V21: =+IFERROR(VLOOKUP($V$17,Sheet1!F7:I7,3,0),0) -> 0 | W21: =+IFERROR(VLOOKUP($W$17,Sheet1!F7:I7,3,0),0) -> 0 | X21: =+IFERROR(VLOOKUP($X$17,Sheet1!F7:I7,3,0),0) -> 0 | Y21: 138 | Z21: =+IFERROR(VLOOKUP($Z$17,Sheet1!F7:I7,3,0),0) -> 0 | AA21: =+IFERROR(VLOOKUP($AA$17,Sheet1!F7:I7,3,0),0) -> 0 | AB21: =+IFERROR(VLOOKUP($AB$17,Sheet1!F7:I7,3,0),0) -> 0 | AC21: 387 | AD21: =+IFERROR(VLOOKUP($AD$17,Sheet1!R7:U7,2,0),0) -> 0 | AE21: 693 | AF21: =+IFERROR(VLOOKUP($AF$17,Sheet1!V7:Y7,3,0),0) -> 0 | AG21: =+IFERROR(VLOOKUP($AG$17,Sheet1!V7:Y7,3,0),0) -> 0 | AH21: =+IFERROR(VLOOKUP($AH$17,Sheet1!V7:Y7,3,0),0) -> 0 | AI21: =+IFERROR(VLOOKUP($AI$17,Sheet1!V7:Y7,3,0),0) -> 0 | AJ21: =+IFERROR(VLOOKUP($AJ$17,Sheet1!V7:Y7,3,0),0) -> 0 | AK21: =+IFERROR(VLOOKUP($AK$17,Sheet1!Z7:AB7,3,0),0) -> 0 | AL21: =+IFERROR(VLOOKUP($AL$17,Sheet1!AD7:AG7,3,0),0) -> 0 | AM21: =+IFERROR(VLOOKUP($AM$17,Sheet1!AD7:AG7,3,0),0) -> 0 | AN21: =+IFERROR(VLOOKUP($AN$17,Sheet1!AD7:AG7,3,0),0) -> 0 | AO21: =+IFERROR(VLOOKUP($AO$17,Sheet1!AD7:AG7,3,0),0) -> 0 | AP21: =+IFERROR(VLOOKUP($AP$17,Sheet1!AD7:AG7,3,0),0) -> 0 | AQ21: 735 | AS21: =+IFERROR(VLOOKUP($AS$17,Sheet1!AH7:AK7,3,0),0) -> 0 | AT21: =+IFERROR(VLOOKUP($AT$17,Sheet1!AH7:AK7,3,0),0) -> 0 | AU21: =+IFERROR(VLOOKUP($AU$17,Sheet1!AH7:AK7,3,0),0) -> 0 | AV21: =+IFERROR(VLOOKUP($AV$17,Sheet1!AH7:AK7,3,0),0) -> 0 | AW21: =+IFERROR(VLOOKUP($AW$17,Sheet1!AH7:AK7,3,0),0) -> 0 | AX21: =+IFERROR(VLOOKUP($AX$17,Sheet1!AH7:AK7,3,0),0) -> 0 | AY21: =+IFERROR(VLOOKUP($AY$17,Sheet1!AH7:AK7,3,0),0) -> 0 | AZ21: =+IFERROR(VLOOKUP($AZ$17,Sheet1!AH7:AK7,3,0),0) -> 0 | BA21: 3500 | BB21: =+IFERROR(VLOOKUP($BB$17,Sheet1!AH7:AK7,3,0),0) -> 0 | BC21: =+IFERROR(VLOOKUP($BC$17,Sheet1!AL7:AO7,3,0),0) -> 0 | BD21: =+IFERROR(VLOOKUP($BD$17,Sheet1!AL7:AO7,3,0),0) -> 0 | BE21: =+IFERROR(VLOOKUP($BE$17,Sheet1!AL7:AO7,3,0),0) -> 0 | BF21: 945 | BG21: =+IFERROR(VLOOKUP($BG$17,Sheet1!AL7:AO7,3,0),0) -> 0 | BH21: =+IFERROR(VLOOKUP($BH$17,Sheet1!AL7:AO7,3,0),0) -> 0 | BI21: =+IFERROR(VLOOKUP($BI$17,Sheet1!AL7:AO7,3,0),0) -> 0 | BJ21: =+IFERROR(VLOOKUP($BJ$17,Sheet1!AL7:AO7,3,0),0) -> 0 | BK21: =+IFERROR(VLOOKUP($BK$17,Sheet1!AL7:AO7,3,0),0) -> 0 | BL21: 615 | BM21: =+IFERROR(VLOOKUP($BM$17,Sheet1!AP7:AS7,3,0),0) -> 0 | BN21: 35 | BO21: =+IFERROR(VLOOKUP($BO$17,Sheet1!AX7:BA7,3,0),0) -> 0 | BP21: 72 | BQ21: =+IFERROR(VLOOKUP($BQ$17,Sheet1!BF7:BI7,3,0),0) -> 0 | BR21: =+IFERROR(VLOOKUP($BR$17,Sheet1!BJ7:BM7,3,0),0) -> 0 | BS21: =+IFERROR(VLOOKUP($BS$17,Sheet1!BN7:BQ7,3,0),0) -> 0 | BT21: 48 | BU21: =+IFERROR(VLOOKUP($BU$17,Sheet1!BV7:BY7,3,0),0) -> 0 | BV21: =Sheet1!E7 -> STEEL | BW21: =Sheet1!CV7 -> SP0400111 | BX21: =Sheet1!CW7 -> CORRUGATED DISPATCH STEEL DRUM 1900 X 1000 X 1000 MM | BY21: =Sheet1!CX7 -> 250 | BZ21: =19350/0.25 -> 77400 | CA21: =SUMPRODUCT($N$18:$BU$18,N21:BU21)+BZ21 -> 1327751 | CB21: 0.01 | CC21: =CA21*CB21 -> 13277.51 | CD21: 0.25 | CE21: =CA21*CD21 -> 331937.75 | CF21: =Sheet1!CF7 -> 0 | CG21: =CA21*CF21 -> 0 | CH21: =CA21+CC21+CE21+CG21 -> 1672966.3 | CI21: 0.02 | CJ21: =CH21*CI21 -> 33459.325 | CK21: 0.01 | CL21: =CH21*CK21 -> 16729.663
A22: =Sheet1!A8 -> ENQ-15138-22-23 | B22: =Sheet1!B8 -> 45627 | C22: =Sheet1!C8 -> FA1300176 | D22: =Sheet1!D8 -> 3 CORE X 150 SQ. MM. AL/ARM - WIRE (XLPE) - 11 KV | E22: =CH22+CJ22+CL22 -> 1443834.9 | F22: =ROUNDUP(M46,0) -> 32500 | G22: =E22+F22 -> 1476334.9 | H22: =Sheet1!CP8 -> 0.18 | I22: =G22*H22 -> 265740.29 | J22: =G22+I22 -> 1742075.2 | K22: =Sheet1!CS8 -> 4 | L22: =Sheet1!CT8 -> KMS | M22: =J22*K22 -> 6968300.9 | N22: =+IFERROR(VLOOKUP($N$17,Sheet1!J8:L8,3,0),0) -> 1215 | O22: =+IFERROR(VLOOKUP($O$17,Sheet1!J8:L8,3,0),0) -> 0 | P22: =+IFERROR(VLOOKUP($P$17,Sheet1!J8:M8,3,0),0) -> 0 | Q22: =+IFERROR(VLOOKUP($Q$17,Sheet1!J8:M8,3,0),0) -> 0 | R22: =+IFERROR(VLOOKUP($R$17,Sheet1!J8:M8,3,0),0) -> 0 | S22: =+IFERROR(VLOOKUP($S$17,Sheet1!N8:Q8,3,0),0) -> 0 | T22: =+IFERROR(VLOOKUP($T$17,Sheet1!N8:Q8,3,0),0) -> 0 | U22: =+IFERROR(VLOOKUP($U$17,Sheet1!F8:I8,3,0),0) -> 0 | V22: =+IFERROR(VLOOKUP($V$17,Sheet1!F8:I8,3,0),0) -> 0 | W22: =+IFERROR(VLOOKUP($W$17,Sheet1!F8:I8,3,0),0) -> 0 | X22: =+IFERROR(VLOOKUP($X$17,Sheet1!F8:I8,3,0),0) -> 0 | Y22: 130 | Z22: =+IFERROR(VLOOKUP($Z$17,Sheet1!F8:I8,3,0),0) -> 0 | AA22: =+IFERROR(VLOOKUP($AA$17,Sheet1!F8:I8,3,0),0) -> 0 | AB22: =+IFERROR(VLOOKUP($AB$17,Sheet1!F8:I8,3,0),0) -> 0 | AC22: 359 | AD22: =+IFERROR(VLOOKUP($AD$17,Sheet1!R8:U8,2,0),0) -> 0 | AE22: 642 | AF22: =+IFERROR(VLOOKUP($AF$17,Sheet1!V8:Y8,3,0),0) -> 0 | AG22: =+IFERROR(VLOOKUP($AG$17,Sheet1!V8:Y8,3,0),0) -> 0 | AH22: =+IFERROR(VLOOKUP($AH$17,Sheet1!V8:Y8,3,0),0) -> 0 | AI22: =+IFERROR(VLOOKUP($AI$17,Sheet1!V8:Y8,3,0),0) -> 0 | AJ22: =+IFERROR(VLOOKUP($AJ$17,Sheet1!V8:Y8,3,0),0) -> 0 | AK22: =+IFERROR(VLOOKUP($AK$17,Sheet1!Z8:AB8,3,0),0) -> 0 | AL22: =+IFERROR(VLOOKUP($AL$17,Sheet1!AD8:AG8,3,0),0) -> 0 | AM22: =+IFERROR(VLOOKUP($AM$17,Sheet1!AD8:AG8,3,0),0) -> 0 | AN22: =+IFERROR(VLOOKUP($AN$17,Sheet1!AD8:AG8,3,0),0) -> 0 | AO22: =+IFERROR(VLOOKUP($AO$17,Sheet1!AD8:AG8,3,0),0) -> 0 | AP22: =+IFERROR(VLOOKUP($AP$17,Sheet1!AD8:AG8,3,0),0) -> 0 | AQ22: 605 | AS22: =+IFERROR(VLOOKUP($AS$17,Sheet1!AH8:AK8,3,0),0) -> 0 | AT22: =+IFERROR(VLOOKUP($AT$17,Sheet1!AH8:AK8,3,0),0) -> 0 | AU22: =+IFERROR(VLOOKUP($AU$17,Sheet1!AH8:AK8,3,0),0) -> 0 | AV22: =+IFERROR(VLOOKUP($AV$17,Sheet1!AH8:AK8,3,0),0) -> 0 | AW22: =+IFERROR(VLOOKUP($AW$17,Sheet1!AH8:AK8,3,0),0) -> 0 | AX22: =+IFERROR(VLOOKUP($AX$17,Sheet1!AH8:AK8,3,0),0) -> 0 | AY22: =+IFERROR(VLOOKUP($AY$17,Sheet1!AH8:AK8,3,0),0) -> 0 | AZ22: =+IFERROR(VLOOKUP($AZ$17,Sheet1!AH8:AK8,3,0),0) -> 0 | BA22: 2605 | BB22: =+IFERROR(VLOOKUP($BB$17,Sheet1!AH8:AK8,3,0),0) -> 0 | BC22: =+IFERROR(VLOOKUP($BC$17,Sheet1!AL8:AO8,3,0),0) -> 0 | BD22: =+IFERROR(VLOOKUP($BD$17,Sheet1!AL8:AO8,3,0),0) -> 0 | BE22: =+IFERROR(VLOOKUP($BE$17,Sheet1!AL8:AO8,3,0),0) -> 0 | BF22: 812 | BG22: =+IFERROR(VLOOKUP($BG$17,Sheet1!AL8:AO8,3,0),0) -> 0 | BH22: =+IFERROR(VLOOKUP($BH$17,Sheet1!AL8:AO8,3,0),0) -> 0 | BI22: =+IFERROR(VLOOKUP($BI$17,Sheet1!AL8:AO8,3,0),0) -> 0 | BJ22: =+IFERROR(VLOOKUP($BJ$17,Sheet1!AL8:AO8,3,0),0) -> 0 | BK22: =+IFERROR(VLOOKUP($BK$17,Sheet1!AL8:AO8,3,0),0) -> 0 | BL22: 567 | BM22: =+IFERROR(VLOOKUP($BM$17,Sheet1!AP8:AS8,3,0),0) -> 0 | BN22: 18 | BO22: =+IFERROR(VLOOKUP($BO$17,Sheet1!AX8:BA8,3,0),0) -> 0 | BP22: 67 | BQ22: =+IFERROR(VLOOKUP($BQ$17,Sheet1!BF8:BI8,3,0),0) -> 0 | BR22: =+IFERROR(VLOOKUP($BR$17,Sheet1!BJ8:BM8,3,0),0) -> 0 | BS22: =+IFERROR(VLOOKUP($BS$17,Sheet1!BN8:BQ8,3,0),0) -> 0 | BT22: 44 | BU22: =+IFERROR(VLOOKUP($BU$17,Sheet1!BV8:BY8,3,0),0) -> 0 | BV22: =Sheet1!E8 -> STEEL | BW22: SP0400118 | BX22: CORRUGATED DISPATCH STEEL DRUM 1700 X 1000 X 1200 | BY22: =Sheet1!CX8 -> 250 | BZ22: =17600/0.25 -> 70400 | CA22: =SUMPRODUCT($N$18:$BU$18,N22:BU22)+BZ22 -> 1112525 | CB22: 0.01 | CC22: =CA22*CB22 -> 11125.25 | CD22: 0.25 | CE22: =CA22*CD22 -> 278131.25 | CF22: =Sheet1!CF8 -> 0 | CG22: =CA22*CF22 -> 0 | CH22: =CA22+CC22+CE22+CG22 -> 1401781.5 | CI22: 0.02 | CJ22: =CH22*CI22 -> 28035.63 | CK22: 0.01 | CL22: =CH22*CK22 -> 14017.815
A23: =Sheet1!A9 -> ENQ-15138-22-23 | B23: =Sheet1!B9 -> 45627 | C23: =Sheet1!C9 -> FA1300197 | D23: =Sheet1!D9 -> 3 CORE X 120 SQ. MM. AL/ARM - WIRE (XLPE) - 11 KV | E23: =CH23+CJ23+CL23 -> 1297922 | F23: =ROUNDUP(M47,0) -> 32500 | G23: =E23+F23 -> 1330422 | H23: =Sheet1!CP9 -> 0.18 | I23: =G23*H23 -> 239475.96 | J23: =G23+I23 -> 1569898 | K23: =Sheet1!CS9 -> 10 | L23: =Sheet1!CT9 -> KMS | M23: =J23*K23 -> 15698980 | N23: =+IFERROR(VLOOKUP($N$17,Sheet1!J9:L9,3,0),0) -> 972 | O23: =+IFERROR(VLOOKUP($O$17,Sheet1!J9:L9,3,0),0) -> 0 | P23: =+IFERROR(VLOOKUP($P$17,Sheet1!J9:M9,3,0),0) -> 0 | Q23: =+IFERROR(VLOOKUP($Q$17,Sheet1!J9:M9,3,0),0) -> 0 | R23: =+IFERROR(VLOOKUP($R$17,Sheet1!J9:M9,3,0),0) -> 0 | S23: =+IFERROR(VLOOKUP($S$17,Sheet1!N9:Q9,3,0),0) -> 0 | T23: =+IFERROR(VLOOKUP($T$17,Sheet1!N9:Q9,3,0),0) -> 0 | U23: =+IFERROR(VLOOKUP($U$17,Sheet1!F9:I9,3,0),0) -> 0 | V23: =+IFERROR(VLOOKUP($V$17,Sheet1!F9:I9,3,0),0) -> 0 | W23: =+IFERROR(VLOOKUP($W$17,Sheet1!F9:I9,3,0),0) -> 0 | X23: =+IFERROR(VLOOKUP($X$17,Sheet1!F9:I9,3,0),0) -> 0 | Y23: 123 | Z23: =+IFERROR(VLOOKUP($Z$17,Sheet1!F9:I9,3,0),0) -> 0 | AA23: =+IFERROR(VLOOKUP($AA$17,Sheet1!F9:I9,3,0),0) -> 0 | AB23: =+IFERROR(VLOOKUP($AB$17,Sheet1!F9:I9,3,0),0) -> 0 | AC23: 332 | AD23: =+IFERROR(VLOOKUP($AD$17,Sheet1!R9:U9,2,0),0) -> 0 | AE23: 593 | AF23: =+IFERROR(VLOOKUP($AF$17,Sheet1!V9:Y9,3,0),0) -> 0 | AG23: =+IFERROR(VLOOKUP($AG$17,Sheet1!V9:Y9,3,0),0) -> 0 | AH23: =+IFERROR(VLOOKUP($AH$17,Sheet1!V9:Y9,3,0),0) -> 0 | AI23: =+IFERROR(VLOOKUP($AI$17,Sheet1!V9:Y9,3,0),0) -> 0 | AJ23: =+IFERROR(VLOOKUP($AJ$17,Sheet1!V9:Y9,3,0),0) -> 0 | AK23: =+IFERROR(VLOOKUP($AK$17,Sheet1!Z9:AB9,3,0),0) -> 0 | AL23: =+IFERROR(VLOOKUP($AL$17,Sheet1!AD9:AG9,3,0),0) -> 0 | AM23: =+IFERROR(VLOOKUP($AM$17,Sheet1!AD9:AG9,3,0),0) -> 0 | AN23: =+IFERROR(VLOOKUP($AN$17,Sheet1!AD9:AG9,3,0),0) -> 0 | AO23: =+IFERROR(VLOOKUP($AO$17,Sheet1!AD9:AG9,3,0),0) -> 0 | AP23: =+IFERROR(VLOOKUP($AP$17,Sheet1!AD9:AG9,3,0),0) -> 0 | AQ23: 550 | AS23: =+IFERROR(VLOOKUP($AS$17,Sheet1!AH9:AK9,3,0),0) -> 0 | AT23: =+IFERROR(VLOOKUP($AT$17,Sheet1!AH9:AK9,3,0),0) -> 0 | AU23: =+IFERROR(VLOOKUP($AU$17,Sheet1!AH9:AK9,3,0),0) -> 0 | AV23: =+IFERROR(VLOOKUP($AV$17,Sheet1!AH9:AK9,3,0),0) -> 0 | AW23: =+IFERROR(VLOOKUP($AW$17,Sheet1!AH9:AK9,3,0),0) -> 0 | AX23: =+IFERROR(VLOOKUP($AX$17,Sheet1!AH9:AK9,3,0),0) -> 0 | AY23: =+IFERROR(VLOOKUP($AY$17,Sheet1!AH9:AK9,3,0),0) -> 0 | AZ23: =+IFERROR(VLOOKUP($AZ$17,Sheet1!AH9:AK9,3,0),0) -> 0 | BA23: 2485 | BB23: =+IFERROR(VLOOKUP($BB$17,Sheet1!AH9:AK9,3,0),0) -> 0 | BC23: =+IFERROR(VLOOKUP($BC$17,Sheet1!AL9:AO9,3,0),0) -> 0 | BD23: =+IFERROR(VLOOKUP($BD$17,Sheet1!AL9:AO9,3,0),0) -> 0 | BE23: =+IFERROR(VLOOKUP($BE$17,Sheet1!AL9:AO9,3,0),0) -> 0 | BF23: 726 | BG23: =+IFERROR(VLOOKUP($BG$17,Sheet1!AL9:AO9,3,0),0) -> 0 | BH23: =+IFERROR(VLOOKUP($BH$17,Sheet1!AL9:AO9,3,0),0) -> 0 | BI23: =+IFERROR(VLOOKUP($BI$17,Sheet1!AL9:AO9,3,0),0) -> 0 | BJ23: =+IFERROR(VLOOKUP($BJ$17,Sheet1!AL9:AO9,3,0),0) -> 0 | BK23: =+IFERROR(VLOOKUP($BK$17,Sheet1!AL9:AO9,3,0),0) -> 0 | BL23: 503 | BM23: =+IFERROR(VLOOKUP($BM$17,Sheet1!AP9:AS9,3,0),0) -> 0 | BN23: 17 | BO23: =+IFERROR(VLOOKUP($BO$17,Sheet1!AX9:BA9,3,0),0) -> 0 | BP23: 62 | BQ23: =+IFERROR(VLOOKUP($BQ$17,Sheet1!BF9:BI9,3,0),0) -> 0 | BR23: =+IFERROR(VLOOKUP($BR$17,Sheet1!BJ9:BM9,3,0),0) -> 0 | BS23: =+IFERROR(VLOOKUP($BS$17,Sheet1!BN9:BQ9,3,0),0) -> 0 | BT23: 42 | BU23: =+IFERROR(VLOOKUP($BU$17,Sheet1!BV9:BY9,3,0),0) -> 0 | BV23: =Sheet1!E9 -> STEEL | BW23: =Sheet1!CV9 -> SP0400118 | BX23: =Sheet1!CW9 -> CORRUGATED DISPATCH STEEL DRUM 1700 X 1000 X 1200 | BY23: =Sheet1!CX9 -> 250 | BZ23: =17600/0.25 -> 70400 | CA23: =SUMPRODUCT($N$18:$BU$18,N23:BU23)+BZ23 -> 1000094 | CB23: 0.01 | CC23: =CA23*CB23 -> 10000.94 | CD23: 0.25 | CE23: =CA23*CD23 -> 250023.5 | CF23: =Sheet1!CF9 -> 0 | CG23: =CA23*CF23 -> 0 | CH23: =CA23+CC23+CE23+CG23 -> 1260118.4 | CI23: 0.02 | CJ23: =CH23*CI23 -> 25202.369 | CK23: 0.01 | CL23: =CH23*CK23 -> 12601.184
A24: =Sheet1!A10 -> ENQ-15138-22-23 | B24: =Sheet1!B10 -> 45627 | C24: =Sheet1!C10 -> FA1300088 | D24: =Sheet1!D10 -> 3 CORE X 95 SQ. MM. AL/ARM - WIRE (XLPE) - 11 KV (E) | E24: =CH24+CJ24+CL24 -> 1162904.1 | F24: =ROUNDUP(M48,0) -> 33914 | G24: =E24+F24 -> 1196818.1 | H24: =Sheet1!CP10 -> 0.18 | I24: =G24*H24 -> 215427.25 | J24: =G24+I24 -> 1412245.3 | K24: =Sheet1!CS10 -> 23 | L24: =Sheet1!CT10 -> KMS | M24: =J24*K24 -> 32481642 | N24: =+IFERROR(VLOOKUP($N$17,Sheet1!J10:L10,3,0),0) -> 770 | O24: =+IFERROR(VLOOKUP($O$17,Sheet1!J10:L10,3,0),0) -> 0 | P24: =+IFERROR(VLOOKUP($P$17,Sheet1!J10:M10,3,0),0) -> 0 | Q24: =+IFERROR(VLOOKUP($Q$17,Sheet1!J10:M10,3,0),0) -> 0 | R24: =+IFERROR(VLOOKUP($R$17,Sheet1!J10:M10,3,0),0) -> 0 | S24: =+IFERROR(VLOOKUP($S$17,Sheet1!N10:Q10,3,0),0) -> 0 | T24: =+IFERROR(VLOOKUP($T$17,Sheet1!N10:Q10,3,0),0) -> 0 | U24: =+IFERROR(VLOOKUP($U$17,Sheet1!F10:I10,3,0),0) -> 0 | V24: =+IFERROR(VLOOKUP($V$17,Sheet1!F10:I10,3,0),0) -> 0 | W24: =+IFERROR(VLOOKUP($W$17,Sheet1!F10:I10,3,0),0) -> 0 | X24: =+IFERROR(VLOOKUP($X$17,Sheet1!F10:I10,3,0),0) -> 0 | Y24: 115 | Z24: =+IFERROR(VLOOKUP($Z$17,Sheet1!F10:I10,3,0),0) -> 0 | AA24: =+IFERROR(VLOOKUP($AA$17,Sheet1!F10:I10,3,0),0) -> 0 | AB24: =+IFERROR(VLOOKUP($AB$17,Sheet1!F10:I10,3,0),0) -> 0 | AC24: 304 | AD24: =+IFERROR(VLOOKUP($AD$17,Sheet1!R10:U10,2,0),0) -> 0 | AE24: 542 | AF24: =+IFERROR(VLOOKUP($AF$17,Sheet1!V10:Y10,3,0),0) -> 0 | AG24: =+IFERROR(VLOOKUP($AG$17,Sheet1!V10:Y10,3,0),0) -> 0 | AH24: =+IFERROR(VLOOKUP($AH$17,Sheet1!V10:Y10,3,0),0) -> 0 | AI24: =+IFERROR(VLOOKUP($AI$17,Sheet1!V10:Y10,3,0),0) -> 0 | AJ24: =+IFERROR(VLOOKUP($AJ$17,Sheet1!V10:Y10,3,0),0) -> 0 | AK24: =+IFERROR(VLOOKUP($AK$17,Sheet1!Z10:AB10,3,0),0) -> 0 | AL24: =+IFERROR(VLOOKUP($AL$17,Sheet1!AD10:AG10,3,0),0) -> 0 | AM24: =+IFERROR(VLOOKUP($AM$17,Sheet1!AD10:AG10,3,0),0) -> 0 | AN24: =+IFERROR(VLOOKUP($AN$17,Sheet1!AD10:AG10,3,0),0) -> 0 | AO24: =+IFERROR(VLOOKUP($AO$17,Sheet1!AD10:AG10,3,0),0) -> 0 | AP24: =+IFERROR(VLOOKUP($AP$17,Sheet1!AD10:AG10,3,0),0) -> 0 | AQ24: 523 | AR24: 0 | AS24: =+IFERROR(VLOOKUP($AS$17,Sheet1!AH10:AK10,3,0),0) -> 0 | AT24: =+IFERROR(VLOOKUP($AT$17,Sheet1!AH10:AK10,3,0),0) -> 0 | AU24: =+IFERROR(VLOOKUP($AU$17,Sheet1!AH10:AK10,3,0),0) -> 0 | AV24: =+IFERROR(VLOOKUP($AV$17,Sheet1!AH10:AK10,3,0),0) -> 0 | AW24: =+IFERROR(VLOOKUP($AW$17,Sheet1!AH10:AK10,3,0),0) -> 0 | AX24: =+IFERROR(VLOOKUP($AX$17,Sheet1!AH10:AK10,3,0),0) -> 0 | AY24: =+IFERROR(VLOOKUP($AY$17,Sheet1!AH10:AK10,3,0),0) -> 0 | AZ24: =+IFERROR(VLOOKUP($AZ$17,Sheet1!AH10:AK10,3,0),0) -> 0 | BA24: 2324 | BB24: =+IFERROR(VLOOKUP($BB$17,Sheet1!AH10:AK10,3,0),0) -> 0 | BC24: =+IFERROR(VLOOKUP($BC$17,Sheet1!AL10:AO10,3,0),0) -> 0 | BD24: =+IFERROR(VLOOKUP($BD$17,Sheet1!AL10:AO10,3,0),0) -> 0 | BE24: =+IFERROR(VLOOKUP($BE$17,Sheet1!AL10:AO10,3,0),0) -> 0 | BF24: 685 | BG24: =+IFERROR(VLOOKUP($BG$17,Sheet1!AL10:AO10,3,0),0) -> 0 | BH24: =+IFERROR(VLOOKUP($BH$17,Sheet1!AL10:AO10,3,0),0) -> 0 | BI24: =+IFERROR(VLOOKUP($BI$17,Sheet1!AL10:AO10,3,0),0) -> 0 | BJ24: =+IFERROR(VLOOKUP($BJ$17,Sheet1!AL10:AO10,3,0),0) -> 0 | BK24: =+IFERROR(VLOOKUP($BK$17,Sheet1!AL10:AO10,3,0),0) -> 0 | BL24: 418 | BM24: 0 | BN24: 15 | BO24: =+IFERROR(VLOOKUP($BO$17,Sheet1!AX10:BA10,3,0),0) -> 0 | BP24: 57 | BQ24: =+IFERROR(VLOOKUP($BQ$17,Sheet1!BF10:BI10,3,0),0) -> 0 | BR24: =+IFERROR(VLOOKUP($BR$17,Sheet1!BJ10:BM10,3,0),0) -> 0 | BS24: =+IFERROR(VLOOKUP($BS$17,Sheet1!BN10:BQ10,3,0),0) -> 0 | BT24: 40 | BU24: =+IFERROR(VLOOKUP($BU$17,Sheet1!BV10:BY10,3,0),0) -> 0 | BV24: =Sheet1!E10 -> STEEL | BW24: =Sheet1!CV10 -> SP0400110 | BX24: =Sheet1!CW10 -> CORRUGATED DISPATCH STEEL DRUM 1600 X 900 X 1000 MM | BY24: =Sheet1!CX10 -> 250 | BZ24: =17200/0.25 -> 68800 | CA24: =SUMPRODUCT($N$18:$BU$18,N24:BU24)+BZ24 -> 896058 | CB24: 0.01 | CC24: =CA24*CB24 -> 8960.58 | CD24: 0.25 | CE24: =CA24*CD24 -> 224014.5 | CF24: =Sheet1!CF10 -> 0 | CG24: =CA24*CF24 -> 0 | CH24: =CA24+CC24+CE24+CG24 -> 1129033.1 | CI24: 0.02 | CJ24: =CH24*CI24 -> 22580.662 | CK24: 0.01 | CL24: =CH24*CK24 -> 11290.331
