Workbook

Sheet Sheet1
A1: DOCKET NO. | B1: Base Date | C1: ITEM CODE | D1: PROPOSE ERP ITEM NAME | E1: PROPOSE DRUM TYPE | F1: Insulation Screening (Metallic) | G1: RM RATE (Insulation Screening (Metallic)) | H1: Weight (Insulation Screening (Metallic)) | I1: COST(Insulation Screening (Metallic)) | J1: Conductor | K1: RM RATE(Conductor) | L1: WEIGHT(Conductor) | M1: COST(Conductor) | N1: AL ALLOY | O1: RM RATE(Alu Alloy) | P1: WEIGHT(Alu Alloy) | Q1: COST(Alu Alloy) | R1: Insulation Screening (Non-Metallic) | S1: RM RATE(Insulation Screening (Non-Metallic)) | T1: WEIGHT(Insulation Screening (Non-Metallic)) | U1: COST(Insulation Screening (Non-Metallic)) | V1: Insulation | W1: RM RATE(Insulation) | X1: WEIGHT(Insulation) | Y1: COST(Insulation) | Z1: POLY TAPE | AA1: RM RATE (Poly Tape) | AB1: WEIGHT (Poly Tape) | AC1: COST(Poly Tape) | AD1: Inner Sheath | AE1: RM RATE(Inner Sheath) | AF1: WEIGHT(Inner Sheath) | AG1: COST(Inner Sheath) | AH1: Armouring | AI1: RM RATE(Armouring) | AJ1: WEIGHT(Armouring) | AK1: COST(Armouring) | AL1: Outer Sheath | AM1: RM RATE(Outer Sheath) | AN1: WEIGHT(Outer Sheath) | AO1: COST(Outer Sheath) | AP1: FILLER | AQ1: RM RATE(Filler) | AR1: WEIGHT(Filler) | AS1: COST(Filler) | AT1: GREASE | AU1: RM RATE(Grease) | AV1: WEIGHT(Grease) | AW1: COST(Grease) | AX1: Water swellable Tape | AY1: RM RATE(Water swellable Tape) | AZ1: WEIGHT(Water swellable Tape) | BA1: COST(Water swellable Tape) | BB1: Semi conducting Water Swellable tape | BC1: RM RATE(Semi conducting Water Swellable tape) | BD1: WEIGHT(Semi conducting Water Swellable tape) | BE1: COST(Semi conducting Water Swellable tape) | BF1: SEMICON TAPE | BG1: RM RATE(SEMICON TAPE) | BH1: WEIGHT(SEMICON TAPE) | BI1: COST(SEMICON TAPE) | BJ1: GLASS FIBER TAPE | BK1: RM RATE(GLASS FIBER TAPE) | BL1: WEIGHT(GLASS FIBER TAPE) | BM1: COST(GLASS FIBER TAPE) | BN1: COPPER WIRE 0.8 MM | BO1: RM RATE(COPPER WIRE 0.8 MM) | BP1: WEIGHT(COPPER WIRE 0.8 MM) | BQ1: COST(COPPER WIRE 0.8 MM) | BR1: RUBBERIZED COTTON TAPE | BS1: RM RATE(RUBBERIZED COTTON TAPE) | BT1: WEIGHT(RUBBERIZED COTTON TAPE) | BU1: COST(RUBBERIZED COTTON TAPE) | BV1: Water Tight Compound | BW1: RM RATE(Water Tight Compound) | BX1: WEIGHT(Water Tight Compound) | BY1: COST(Water Tight Compound) | BZ1: DRUM COST PER KM | CA1: TOTAL RM COST | CB1: FIRM % | CC1: FIRM VALUE | CD1: MFG% | CE1: MFG VALUE | CF1: PROF% | CG1: PROFIT VALUE | CH1: 1ST EX-WORKS | CI1: Intt % | CJ1: INTT VALUE | CK1: insp% | CL1: INSP VALUE | CM1: EX-WORKS (PER KM) | CN1: FREIGHT PER KM | CO1: PRICE INCLUDING FREIGHT (PER KM) | CP1: GST % | CQ1: GST VALUE | CR1: PRICE INCLUDING GST & FREIGHT (PER KM) | CS1: QTY | CT1: Unit | CU1: TOTAL PRICE OF FULL QTY (INCLUDING FRIGHT & GST) | CV1: DRUM CODE | CW1: DRUM SIZE (FxbXtx Ft) | CX1: PARTY STANDARD LENGTH (MTR)
A2: ENQ-12006-22-23 | B2: 45261 | C2: FA1300027 | D2: 1 CORE X 630 SQ. MM. AL/ARM (XLPE) - 33 KV | E2: STEEL | F2: Copper Tape - 0.045 mm | G2: 853.6 | H2: 68.737 | I2: 58673.91 | J2: Alumimium | K2: 217 | L2: 1701 | M2: 369117 | P2: 0 | R2: Extruded Semiconductive(Stripable) | S2: 200 | T2: 172 | U2: 34400 | V2: HT-XLPE | W2: 145 | X2: 1040 | Y2: 150800 | AB2: 0 | AD2: PVC Type ST-2-PRESSURE EXTRUDED | AE2: 86 | AF2: 193 | AG2: 16598 | AH2: Aluminium Round Wire | AI2: 222 | AJ2: 800 | AK2: 177600 | AL2: PVC Type ST-2 | AM2: 58.2 | AN2: 738 | AO2: 42951.6 | AR2: 0 | AV2: 0 | AX2: Water swellable Tape | AY2: 447 | AZ2: 0 | BA2: 0 | BB2: Semi conducting Water Swellable tape | BC2: 450 | BD2: 0 | BE2: 0 | BH2: 0 | BL2: 0 | BP2: 0 | BR2: RUBBERIZED COTTON TAPE | BS2: 450 | BT2: 0 | BU2: 0 | BX2: 0 | BZ2: 53200 | CA2: 903340.51 | CH2: 903340.51 | CM2: 903340.51 | CO2: 903340.51 | CP2: 0.18 | CQ2: 162601.29 | CR2: 1065941.8 | CS2: 1 | CT2: KMS | CU2: 1065942 | CV2: SP0400123 | CW2: CORRUGATED DISPATCH STEEL DRUM 2000 X 1000 X 1200 MM | CX2: 500
A3: ENQ-12006-22-23 | B3: 45261 | C3: FA1300020 | D3: 1 CORE X 185 SQ. MM. AL./ARM (XLPE) - 11 KV | E3: STEEL | F3: Copper Tape - 0.045 mm | G3: 853.6 | H3: 35.16 | I3: 30012.58 | J3: Alumimium | K3: 217 | L3: 499.5 | M3: 108391.5 | P3: 0 | R3: Extruded Semiconductive(Stripable) | S3: 200 | T3: 92 | U3: 18400 | V3: HT-XLPE | W3: 145 | X3: 221 | Y3: 32045 | AB3: 0 | AD3: PVC Type ST-2-PRESSURE EXTRUDED | AE3: 86 | AF3: 75 | AG3: 6450 | AH3: Aluminium Round Wire | AI3: 222 | AJ3: 335 | AK3: 74370 | AL3: PVC Type ST-2 | AM3: 58.2 | AN3: 280 | AO3: 16296 | AR3: 0 | AV3: 0 | AX3: Water swellable Tape | AY3: 447 | AZ3: 0 | BA3: 0 | BB3: Semi conducting Water Swellable tape | BC3: 450 | BD3: 0 | BE3: 0 | BH3: 0 | BL3: 0 | BP3: 0 | BR3: RUBBERIZED COTTON TAPE | BS3: 450 | BT3: 0 | BU3: 0 | BX3: 0 | BZ3: 41800 | CA3: 327765.08 | CH3: 327765.08 | CM3: 327765.08 | CO3: 327765.08 | CP3: 0.18 | CQ3: 58997.71 | CR3: 386762.79 | CS3: 3 | CT3: KMS | CU3: 1160288 | CV3: SP0400125 | CW3: CORRUGATED DISPATCH STEEL DRUM 1600 X 700 X 915 MM | CX3: 500
A4: ENQ-12006-22-23 | B4: 45261 | C4: FA1300066 | D4: 1 CORE X 1000 SQ. MM. AL/ARM (XLPE) - 11 KV | E4: STEEL | F4: Copper Tape - 0.045 mm | G4: 853.6 | H4: 66.388 | I4: 56668.8 | J4: Alumimium | K4: 217 | L4: 2732 | M4: 592844 | P4: 0 | R4: Extruded Semiconductive(Stripable) | S4: 200 | T4: 200 | U4: 40000 | V4: HT-XLPE | W4: 145 | X4: 465 | Y4: 67425 | Z4: POLY TAPE | AA4: 123 | AB4: 0 | AC4: 0 | AD4: PVC Type ST-2-PRESSURE EXTRUDED | AE4: 86 | AF4: 185 | AG4: 15910 | AH4: Aluminium Round Wire | AI4: 222 | AJ4: 773 | AK4: 171606 | AL4: FRLSH PVC Type ST-2 | AM4: 91 | AN4: 655 | AO4: 59605 | AR4: 0 | AV4: 0 | AX4: Water swellable Tape | AY4: 447 | AZ4: 0 | BA4: 0 | BD4: 99 | BF4: SEMICON TAPE | BG4: 550 | BH4: 59 | BI4: 32450 | BL4: 0 | BP4: 0 | BR4: RUBBERIZED COTTON TAPE | BS4: 450 | BT4: 52 | BU4: 23400 | BX4: 0 | BZ4: 66500 | CA4: 1126408.8 | CH4: 1126408.8 | CM4: 1126408.8 | CO4: 1126408.8 | CP4: 0.18 | CQ4: 202753.58 | CR4: 1329162.4 | CS4: 3 | CT4: KMS | CU4: 3987487 | CV4: SP0400107 | CW4: CORRUGATED DISPATCH STEEL DRUM 2150 X 1080 X 1240 MM | CX4: 500
A5: ENQ-12006-22-23 | B5: 45261 | C5: FA1300122 | D5: 1 CORE X 185 SQ. MM. AL/ARM - WIRE (XLPE) - 22 KV | E5: STEEL | F5: Copper Tape - 0.045 mm | G5: 853.6 | H5: 41.792 | I5: 35673.66 | J5: Alumimium | K5: 217 | L5: 499.5 | M5: 108391.5 | P5: 0 | R5: Extruded Semiconductive(Stripable) | S5: 200 | T5: 82 | U5: 16400 | V5: HT-XLPE | W5: 145 | X5: 419 | Y5: 60755 | AB5: 0 | AD5: PVC Type ST-2-PRESSURE EXTRUDED | AE5: 86 | AF5: 102 | AG5: 8772 | AH5: Aluminium Round Wire | AI5: 222 | AJ5: 380 | AK5: 84360 | AL5: PVC Type ST-2 | AM5: 58.2 | AN5: 284 | AO5: 16528.8 | AR5: 0 | AV5: 0 | AX5: Water swellable Tape | AY5: 447 | AZ5: 0 | BA5: 0 | BB5: Semi conducting Water Swellable tape | BC5: 450 | BD5: 0 | BE5: 0 | BH5: 0 | BL5: 0 | BP5: 0 | BR5: RUBBERIZED COTTON TAPE | BS5: 450 | BT5: 0 | BU5: 0 | BX5: 0 | BZ5: 41800 | CA5: 372680.96 | CH5: 372680.96 | CM5: 372680.96 | CO5: 372680.96 | CP5: 0.18 | CQ5: 67082.57 | CR5: 439763.53 | CS5: 3 | CT5: KMS | CU5: 1319291 | CV5: SP0400125 | CW5: CORRUGATED DISPATCH STEEL DRUM 1600 X 700 X 915 MM | CX5: 500
A6: ENQ-12006-22-23 | B6: 45261 | C6: FA1300202 | D6: 3 CORE X 240 SQ. MM. AL/ARM - WIRE (XLPE) - 22 KV | E6: STEEL | F6: Copper Tape - 0.045 mm | G6: 853.6 | H6: 134.495 | I6: 114804.94 | J6: Alumimium | K6: 217 | L6: 1944 | M6: 421848 | P6: 0 | R6: Extruded Semiconductive(Stripable) | S6: 200 | T6: 272 | U6: 54400 | V6: HT-XLPE | W6: 145 | X6: 1375 | Y6: 199375 | AB6: 0 | AD6: PVC Type ST-2-PRESSURE EXTRUDED | AE6: 86 | AF6: 268 | AG6: 23048 | AH6: Galvanised Steel Round Wire | AI6: 87 | AJ6: 4982 | AK6: 433434 | AL6: PVC Type ST-2 | AM6: 58.2 | AN6: 1170 | AO6: 68094 | AP6: FILLER | AQ6: 28.5 | AR6: 1399 | AS6: 39871.5 | AV6: 0 | AX6: Water swellable Tape | AY6: 447 | AZ6: 0 | BA6: 0 | BB6: Semi conducting Water Swellable tape | BC6: 450 | BD6: 0 | BE6: 0 | BH6: 0 | BL6: 0 | BP6: 0 | BR6: RUBBERIZED COTTON TAPE | BS6: 450 | BT6: 0 | BU6: 0 | BX6: 0 | BZ6: 193800 | CA6: 1548675.4 | CH6: 1548675.4 | CM6: 1548675.4 | CO6: 1548675.4 | CP6: 0.18 | CQ6: 278761.58 | CR6: 1827437 | CS6: 30 | CT6: KMS | CU6: 54823111 | CV6: SP0400081 | CW6: CORRUGATED DISPATCH STEEL DRUM 2500 X 1400 X 1250 MM | CX6: 250
A7: ENQ-12006-22-23 | B7: 45261 | C7: FA1300080 | D7: 3 CORE X 400 SQ. MM AL/ARM - WIRE (XLPE) - 33 KV | E7: STEEL | F7: Copper Tape - 0.045 mm | G7: 853.6 | H7: 179.265 | I7: 153020.61 | J7: Alumimium | K7: 217 | L7: 3240 | M7: 703080 | P7: 0 | R7: Extruded Semiconductive | S7: 190 | T7: 427 | U7: 81130 | V7: HT-XLPE | W7: 145 | X7: 2621 | Y7: 380045 | AB7: 0 | AD7: PVC Type ST-2-PRESSURE EXTRUDED | AE7: 86 | AF7: 405 | AG7: 34830 | AH7: Galvanised Steel Round Wire | AI7: 87 | AJ7: 6975 | AK7: 606825 | AL7: FRLSH PVC Type ST-2 | AM7: 91 | AN7: 1660 | AO7: 151060 | AP7: FILLER | AQ7: 28.5 | AR7: 2672 | AS7: 76152 | AV7: 0 | AX7: Water swellable Tape | AY7: 447 | AZ7: 120 | BA7: 53640 | BD7: 0 | BF7: SEMICON TAPE | BG7: 550 | BH7: 144 | BI7: 79200 | BL7: 0 | BP7: 0 | BR7: RUBBERIZED COTTON TAPE | BS7: 450 | BT7: 0 | BU7: 0 | BX7: 0 | BZ7: 190000 | CA7: 2508982.6 | CH7: 2508982.6 | CM7: 2508982.6 | CO7: 2508982.6 | CP7: 0.18 | CQ7: 451616.87 | CR7: 2960599.5 | CS7: 45 | CT7: KMS | CU7: 133226977 | CV7: SP0400137 | CW7: CORRUGATED DISPATCH STEEL DRUM 2600 X 1600 X 1600 MM | CX7: 250
A8: ENQ-12006-22-23 | B8: 45261 | C8: FA1300091 | D8: 3 CORE X 300 SQ. MM. AL/ARM - WIRE (XLPE) - 11 KV | E8: STEEL | F8: Copper Tape - 0.045 mm | G8: 853.6 | H8: 121.645 | I8: 103836.18 | J8: Alumimium | K8: 217 | L8: 2430 | M8: 527310 | P8: 0 | R8: Extruded Semiconductive(Stripable) | S8: 200 | T8: 337 | U8: 67400 | V8: HT-XLPE | W8: 145 | X8: 802 | Y8: 116290 | AB8: 0 | AD8: PVC Type ST-2-PRESSURE EXTRUDED | AE8: 86 | AF8: 277 | AG8: 23822 | AH8: Galvanised Steel Round Wire | AI8: 87 | AJ8: 3753 | AK8: 326511 | AL8: FRLSH PVC Type ST-2 | AM8: 91 | AN8: 1120 | AO8: 101920 | AP8: Polypropylene Filler | AR8: 1258 | AV8: 0 | AX8: Water swellable Tape | AY8: 447 | AZ8: 0 | BA8: 0 | BD8: 115 | BF8: SEMICON TAPE | BG8: 550 | BH8: 34 | BI8: 18700 | BL8: 0 | BP8: 0 | BR8: RUBBERIZED COTTON TAPE | BS8: 450 | BT8: 0 | BU8: 0 | BX8: 0 | BZ8: 171000 | CA8: 1456789.2 | CH8: 1456789.2 | CM8: 1456789.2 | CO8: 1456789.2 | CP8: 0.18 | CQ8: 262222.05 | CR8: 1719011.2 | CS8: 70 | CT8: KMS | CU8: 120330786 | CV8: SP0400136 | CW8: CORRUGATED DISPATCH STEEL DRUM 2200 X 1300 X 1200 MM | CX8: 250

Sheet AUTO CALCULATION SHEET (2)
A2: The Tata Power Company Limited (Tata Power)
A4: TENDER SPECIFICATION NO () | B4: CC24VJS048
A5: TENDER DESCRIPTION () | B5: Out Line Agreement for 1 year for procurement of HT Cable of Various Ratings 11kV, 22kV, 33 kV for Mumbai Distribution.
A6: Last Date & Time of Submission () | B6: 19th January 2024 by 15:00 Hrs.*
A7: REVERSE AUCTION | B7: Tata Power reserves the right to go for Reverse Auction (RA) for price negotiation and discover the most competitive price on ARIBA portal, Tata Power’s official e‐tendering platform. This will be decided after techno‐commercial evaluation of the bids. Bidders need to give their acceptance with the offer for participation in RA. Non‐acceptance to participate in RA may result in non‐consideration of their bids, in case Tata Power decides to go for RA.
A8: Price () | B8: On Price Variation Basis. Base circular shall be December 2023 circular issued in January 2024. Base month for Bid Price shall remain same throughout the negotiation process till Outline Agreement / Rate Contract is finalized. Base month circular has to be attached in the price bid.
A9: Validity () | B9: Bids shall remain valid for 180 days from the due date of submission of the bid. Notwithstanding clause above, Tata Power may solicit the Bidder’s consent to an extension of the Period of Bid Validity. The request and responses thereto shall be made in writing.
A10: Delivery Period () | B10: The material should be delivered at TPC, Mumbai stores within 45 days from the date of manufacturing, same shall be checked during delivery and overdue material shall not be accepted. Bidders to plan the delivery accordingly.
A11: Payment Terms () | B11: 100% payment shall be made within 60 days from the receipt and acceptance of the material at the Consignee Stores/Site/Location as per the Contractual Terms and Conditions.
A12: Standard length () | B12: The cable shall be supplied in continuous standard length of 250 mtrs (3 cores) & 500 mtrs (Single core) running meters with +/- 5% tolerance.
A13: Packing () | B13: The cable shall be wound on non-returnable steel drums without any extra cost.
A14: Technical Specification
B16: AVG OF DEC'23 | N16: =Sheet1!J1 -> Conductor | S16: AL ALLOY | U16: Insulation Screening (Metallic) | AC16: Insulation Screening (Non-Metallic) | AE16: Insulation | AK16: POLY TAPE | AL16: Inner Sheath | AS16: Armouring | BC16: Outer Sheath | BM16: FILLER | BN16: GREASE | BO16: Water swellable Tape | BP16: Semi conducting Water Swellable tape | BR16: SEMICON TAPE | BS16: GLASS FIBER TAPE | BT16: COPPER WIRE 0.8 MM | BU16: RUBBERIZED COTTON TAPE | BV16: Water Tight Compound | CA16: DRUM COST PER KM | CB16: TOTAL RM COST | CC16: EXTRA CONSUMPTION | CD16: EXTRA CONSUMPTION VALUE
A17: DOCKET NO. | B17: =Sheet1!B1 -> Base Date | C17: ITEM CODE | D17: PROPOSE ERP ITEM NAME | E17: EX-WORKS (PER KM) | F17: FREIGHT PER KM | G17: PRICE INCLUDING FREIGHT (PER KM) | H17: GST % | I17: GST VALUE | J17: PRICE INCLUDING GST & FREIGHT (PER KM) | K17: QTY | L17: Unit | M17: TOTAL PRICE OF FULL QTY (INCLUDING FRIGHT & GST) | N17: Alumimium | O17: Alumimium ALLOY | P17: Copper | Q17: Flexible Copper | R17: Galvanized steel wire | S17: Alumimium | T17: Alumimium ALLOY | U17: Coper tape - 0.1 mm | V17: Copper Tape - 0.03 mm | W17: Copper Tape - 0.035 mm | X17: Copper Tape - 0.04 mm | Y17: Copper Tape - 0.045 mm | Z17: Copper Tape - 0.050 mm | AA17: Copper Tape - 0.060 mm | AB17: Copper Tape - 0.075 mm(DOUBLE) | AC17: Extruded semiconductive | AD17: Extruded Semiconductive(Stripable) | AE17: HT-XLPE | AF17: LT-XLPE | AG17: TR XLPE | AH17: Type A PVC | AI17: Type C PVC (HR) | AJ17: XLPE | AK17: POLY TAPE | AL17: FR PVC Type ST-1 | AM17: FR PVC Type ST-2 | AN17: FRLSH PVC Type ST-2 | AO17: PVC Type ST-1 | AP17: PVC Type ST-1-PRESSURE EXTRUDED | AQ17: PVC Type ST-2 | AR17: PVC Type ST-2-PRESSURE EXTRUDED | AS17: ACSR CORE WIRE | AT17: ACSR DOG STEEL WIRE | AU17: Aluminium Flat Strip | AV17: Aluminium Round Wire | AW17: Double Steel Tape | AX17: Galvanised Steel Flat Strip | AY17: Galvanised Steel Flat Strip (Double) | AZ17: Galvanised Steel Flat Strip-B | BA17: Galvanised Steel Round Wire | BB17: Galvanised Steel Round Wire (Double) | BC17: FR PVC Type ST-1 | BD17: FR PVC Type ST-2 | BE17: FRLSH PVC Type ST-1 | BF17: FRLSH PVC Type ST-2 | BG17: PE, ST-3 | BH17: PE, ST-7 | BI17: PVC Type ST-1 | BJ17: PVC Type ST-2 | BK17: PVC Type ST-2-PRESSURE EXTRUDED | BL17: PP FILLER | BM17: FILLER | BN17: Grease | BO17: Water swellable Tape | BP17: Semi conducting Water Swellable tape | BQ17: NCWBT | BR17: SEMICON TAPE | BS17: GLASS FIBER TAPE | BT17: COPPER WIRE 0.8 MM | BU17: RUBBERIZED COTTON TAPE | BV17: LDPE TAPE | BW17: =Sheet1!E1 -> PROPOSE DRUM TYPE | BX17: =Sheet1!CV1 -> DRUM CODE | BY17: =Sheet1!CW1 -> DRUM SIZE (FxbXtx Ft) | BZ17: =Sheet1!CX1 -> PARTY STANDARD LENGTH (MTR) | CE17: MFG% | CF17: MFG VALUE | CG17: PROF% | CH17: PROFIT VALUE | CI17: 1ST EX-WORKS | CJ17: Intt % | CK17: INTT VALUE | CL17: insp% | CM17: INSP VALUE
N18: 214 | O18: =+IFERROR(VLOOKUP($O$17,Sheet1!J:L,2,0),0) -> 0 | P18: =+IFERROR(VLOOKUP($P$17,Sheet1!J:M,2,0),0) -> 0 | Q18: =+IFERROR(VLOOKUP($Q$17,Sheet1!J:M,2,0),0) -> 0 | R18: =+IFERROR(VLOOKUP($R$17,Sheet1!J:M,2,0),0) -> 0 | S18: =+IFERROR(VLOOKUP($S$17,Sheet1!N:Q,2,0),0) -> 0 | T18: =+IFERROR(VLOOKUP($T$17,Sheet1!N:O,2,0),0) -> 0 | U18: =+IFERROR(VLOOKUP($U$17,Sheet1!F:I,2,0),0) -> 0 | V18: =+IFERROR(VLOOKUP($V$17,Sheet1!F:I,2,0),0) -> 0 | W18: =+IFERROR(VLOOKUP($W$17,Sheet1!F:I,2,0),0) -> 0 | X18: =+IFERROR(VLOOKUP($X$17,Sheet1!F:I,2,0),0) -> 0 | Y18: 858 | AD18: 201 | AE18: 147 | AK18: 122 | AR18: 88 | AV18: 221 | BA18: 86 | BF18: 93 | BG18: =+IFERROR(VLOOKUP($BG$17,Sheet1!AL2:AO840,2,0),0) -> 0 | BH18: =+IFERROR(VLOOKUP($BH$17,Sheet1!AL2:AO840,2,0),0) -> 0 | BI18: =+IFERROR(VLOOKUP($BI$17,Sheet1!AL2:AO840,2,0),0) -> 0 | BK18: =+IFERROR(VLOOKUP($BK$17,Sheet1!AL2:AO840,2,0),0) -> 0 | BL18: 65 | BN18: =+IFERROR(VLOOKUP($BN$17,Sheet1!AT2:AW840,2,0),0) -> 0 | BP18: 454 | BQ18: 348 | BS18: =+IFERROR(VLOOKUP($BS$17,Sheet1!BJ2:BM840,2,0),0) -> 0 | BT18: =+IFERROR(VLOOKUP($BT$17,Sheet1!BN2:BQ840,2,0),0) -> 0 | BU18: 450 | BV18: 190
A19: =Sheet1!A7 -> ENQ-12006-22-23 | B19: =Sheet1!B7 -> 45261 | C19: =Sheet1!C7 -> FA1300080 | D19: =Sheet1!D7 -> 3 CORE X 400 SQ. MM AL/ARM - WIRE (XLPE) - 33 KV | E19: =CI19+CK19+CM19 -> 3593365.1 | F19: =ROUNDUP(M28,0) -> 224000 | G19: =E19+F19 -> 3817365.1 | H19: =Sheet1!CP7 -> 0.18 | I19: =G19*H19 -> 687125.72 | J19: =G19+I19 -> 4504490.8 | K19: =Sheet1!CS7 -> 45 | L19: =Sheet1!CT7 -> KMS | M19: =J19*K19 -> 2.0270209e+08 | N19: 3243 | O19: =+IFERROR(VLOOKUP($O$17,Sheet1!J7:L7,3,0),0) -> 0 | P19: =+IFERROR(VLOOKUP($P$17,Sheet1!J7:M7,3,0),0) -> 0 | Q19: =+IFERROR(VLOOKUP($Q$17,Sheet1!J7:M7,3,0),0) -> 0 | R19: =+IFERROR(VLOOKUP($R$17,Sheet1!J7:M7,3,0),0) -> 0 | S19: =+IFERROR(VLOOKUP($S$17,Sheet1!N7:Q7,3,0),0) -> 0 | T19: =+IFERROR(VLOOKUP($T$17,Sheet1!N7:Q7,3,0),0) -> 0 | U19: =+IFERROR(VLOOKUP($U$17,Sheet1!F7:I7,3,0),0) -> 0 | V19: =+IFERROR(VLOOKUP($V$17,Sheet1!F7:I7,3,0),0) -> 0 | W19: =+IFERROR(VLOOKUP($W$17,Sheet1!F7:I7,3,0),0) -> 0 | X19: =+IFERROR(VLOOKUP($X$17,Sheet1!F7:I7,3,0),0) -> 0 | Y19: 225 | Z19: =+IFERROR(VLOOKUP($Z$17,Sheet1!F7:I7,3,0),0) -> 0 | AA19: =+IFERROR(VLOOKUP($AA$17,Sheet1!F7:I7,3,0),0) -> 0 | AB19: =+IFERROR(VLOOKUP($AB$17,Sheet1!F7:I7,3,0),0) -> 0 | AD19: 588 | AE19: 2670 | AF19: =+IFERROR(VLOOKUP($AF$17,Sheet1!V7:Y7,3,0),0) -> 0 | AG19: =+IFERROR(VLOOKUP($AG$17,Sheet1!V7:Y7,3,0),0) -> 0 | AH19: =+IFERROR(VLOOKUP($AH$17,Sheet1!V7:Y7,3,0),0) -> 0 | AI19: =+IFERROR(VLOOKUP($AI$17,Sheet1!V7:Y7,3,0),0) -> 0 | AJ19: =+IFERROR(VLOOKUP($AJ$17,Sheet1!V7:Y7,3,0),0) -> 0 | AK19: =+IFERROR(VLOOKUP($AK$17,Sheet1!Z7:AB7,3,0),0) -> 0 | AL19: =+IFERROR(VLOOKUP($AL$17,Sheet1!AD7:AG7,3,0),0) -> 0 | AM19: =+IFERROR(VLOOKUP($AM$17,Sheet1!AD7:AG7,3,0),0) -> 0 | AN19: =+IFERROR(VLOOKUP($AN$17,Sheet1!AD7:AG7,3,0),0) -> 0 | AO19: =+IFERROR(VLOOKUP($AO$17,Sheet1!AD7:AG7,3,0),0) -> 0 | AP19: =+IFERROR(VLOOKUP($AP$17,Sheet1!AD7:AG7,3,0),0) -> 0 | AQ19: =+IFERROR(VLOOKUP($AQ$17,Sheet1!AD7:AG7,3,0),0) -> 0 | AR19: 1577 | AS19: =+IFERROR(VLOOKUP($AS$17,Sheet1!AH7:AK7,3,0),0) -> 0 | AT19: =+IFERROR(VLOOKUP($AT$17,Sheet1!AH7:AK7,3,0),0) -> 0 | AU19: =+IFERROR(VLOOKUP($AU$17,Sheet1!AH7:AK7,3,0),0) -> 0 | AV19: =+IFERROR(VLOOKUP($AV$17,Sheet1!AH7:AK7,3,0),0) -> 0 | AW19: =+IFERROR(VLOOKUP($AW$17,Sheet1!AH7:AK7,3,0),0) -> 0 | AX19: =+IFERROR(VLOOKUP($AX$17,Sheet1!AH7:AK7,3,0),0) -> 0 | AY19: =+IFERROR(VLOOKUP($AY$17,Sheet1!AH7:AK7,3,0),0) -> 0 | AZ19: =+IFERROR(VLOOKUP($AZ$17,Sheet1!AH7:AK7,3,0),0) -> 0 | BA19: 7182 | BB19: =+IFERROR(VLOOKUP($BB$17,Sheet1!AH7:AK7,3,0),0) -> 0 | BC19: =+IFERROR(VLOOKUP($BC$17,Sheet1!AL7:AO7,3,0),0) -> 0 | BD19: =+IFERROR(VLOOKUP($BD$17,Sheet1!AL7:AO7,3,0),0) -> 0 | BE19: =+IFERROR(VLOOKUP($BE$17,Sheet1!AL7:AO7,3,0),0) -> 0 | BF19: 1724 | BG19: =+IFERROR(VLOOKUP($BG$17,Sheet1!AL7:AO7,3,0),0) -> 0 | BH19: =+IFERROR(VLOOKUP($BH$17,Sheet1!AL7:AO7,3,0),0) -> 0 | BI19: =+IFERROR(VLOOKUP($BI$17,Sheet1!AL7:AO7,3,0),0) -> 0 | BJ19: =+IFERROR(VLOOKUP($BJ$17,Sheet1!AL7:AO7,3,0),0) -> 0 | BK19: =+IFERROR(VLOOKUP($BK$17,Sheet1!AL7:AO7,3,0),0) -> 0 | BL19: 1768 | BN19: =+IFERROR(VLOOKUP($BN$17,Sheet1!AT7:AW7,3,0),0) -> 0 | BP19: 114 | BQ19: 58 | BS19: =+IFERROR(VLOOKUP($BS$17,Sheet1!BJ7:BM7,3,0),0) -> 0 | BT19: =+IFERROR(VLOOKUP($BT$17,Sheet1!BN7:BQ7,3,0),0) -> 0 | BU19: 76 | BV19: =+IFERROR(VLOOKUP($BV$17,Sheet1!BV7:BY7,3,0),0) -> 0 | BW19: =Sheet1!E7 -> STEEL | BX19: =Sheet1!CV7 -> SP0400137 | BY19: =Sheet1!CW7 -> CORRUGATED DISPATCH STEEL DRUM 2600 X 1600 X 1600 MM | BZ19: =Sheet1!CX7 -> 250 | CA19: =Sheet1!BZ7 -> 190000 | CB19: =SUMPRODUCT($N$18:$BV$18,N19:BV19)+CA19 -> 2725550 | CC19: =Sheet1!CB7 -> 0 | CD19: =CB19*CC19 -> 0 | CE19: 0.28 | CF19: =CB19*CE19 -> 763154 | CG19: 0 | CH19: =CB19*CG19 -> 0 | CI19: =CB19+CD19+CF19+CH19 -> 3488704 | CJ19: 0.02 | CK19: =CI19*CJ19 -> 69774.08 | CL19: 0.01 | CM19: =CI19*CL19 -> 34887.04
A20: =Sheet1!A6 -> ENQ-12006-22-23 | B20: =Sheet1!B6 -> 45261 | C20: =Sheet1!C6 -> FA1300202 | D20: =Sheet1!D6 -> 3 CORE X 240 SQ. MM. AL/ARM - WIRE (XLPE) - 22 KV | E20: =CI20+CK20+CM20 -> 2487463.5 | F20: =ROUNDUP(M29,0) -> 134400 | G20: =E20+F20 -> 2621863.5 | H20: =Sheet1!CP6 -> 0.18 | I20: =G20*H20 -> 471935.43 | J20: =G20+I20 -> 3093798.9 | K20: =Sheet1!CS6 -> 30 | L20: =Sheet1!CT6 -> KMS | M20: =J20*K20 -> 92813968 | N20: =+IFERROR(VLOOKUP($N$17,Sheet1!J6:L6,3,0),0) -> 1944 | O20: =+IFERROR(VLOOKUP($O$17,Sheet1!J6:L6,3,0),0) -> 0 | P20: =+IFERROR(VLOOKUP($P$17,Sheet1!J6:M6,3,0),0) -> 0 | Q20: =+IFERROR(VLOOKUP($Q$17,Sheet1!J6:M6,3,0),0) -> 0 | R20: =+IFERROR(VLOOKUP($R$17,Sheet1!J6:M6,3,0),0) -> 0 | S20: =+IFERROR(VLOOKUP($S$17,Sheet1!N6:Q6,3,0),0) -> 0 | T20: =+IFERROR(VLOOKUP($T$17,Sheet1!N6:Q6,3,0),0) -> 0 | U20: =+IFERROR(VLOOKUP($U$17,Sheet1!F6:I6,3,0),0) -> 0 | V20: =+IFERROR(VLOOKUP($V$17,Sheet1!F6:I6,3,0),0) -> 0 | W20: =+IFERROR(VLOOKUP($W$17,Sheet1!F6:I6,3,0),0) -> 0 | X20: =+IFERROR(VLOOKUP($X$17,Sheet1!F6:I6,3,0),0) -> 0 | Y20: 171 | Z20: =+IFERROR(VLOOKUP($Z$17,Sheet1!F6:I6,3,0),0) -> 0 | AA20: =+IFERROR(VLOOKUP($AA$17,Sheet1!F6:I6,3,0),0) -> 0 | AB20: =+IFERROR(VLOOKUP($AB$17,Sheet1!F6:I6,3,0),0) -> 0 | AC20: =+IFERROR(VLOOKUP($AC$17,Sheet1!R6:U6,3,0),0) -> 0 | AD20: 449 | AE20: 1394 | AF20: =+IFERROR(VLOOKUP($AF$17,Sheet1!V6:Y6,3,0),0) -> 0 | AG20: =+IFERROR(VLOOKUP($AG$17,Sheet1!V6:Y6,3,0),0) -> 0 | AH20: =+IFERROR(VLOOKUP($AH$17,Sheet1!V6:Y6,3,0),0) -> 0 | AI20: =+IFERROR(VLOOKUP($AI$17,Sheet1!V6:Y6,3,0),0) -> 0 | AJ20: =+IFERROR(VLOOKUP($AJ$17,Sheet1!V6:Y6,3,0),0) -> 0 | AK20: =+IFERROR(VLOOKUP($AK$17,Sheet1!Z6:AB6,3,0),0) -> 0 | AL20: =+IFERROR(VLOOKUP($AL$17,Sheet1!AD6:AG6,3,0),0) -> 0 | AM20: =+IFERROR(VLOOKUP($AM$17,Sheet1!AD6:AG6,3,0),0) -> 0 | AN20: =+IFERROR(VLOOKUP($AN$17,Sheet1!AD6:AG6,3,0),0) -> 0 | AO20: =+IFERROR(VLOOKUP($AO$17,Sheet1!AD6:AG6,3,0),0) -> 0 | AP20: =+IFERROR(VLOOKUP($AP$17,Sheet1!AD6:AG6,3,0),0) -> 0 | AQ20: =+IFERROR(VLOOKUP($AQ$17,Sheet1!AD6:AG6,3,0),0) -> 0 | AR20: 990 | AS20: =+IFERROR(VLOOKUP($AS$17,Sheet1!AH6:AK6,3,0),0) -> 0 | AT20: =+IFERROR(VLOOKUP($AT$17,Sheet1!AH6:AK6,3,0),0) -> 0 | AU20: =+IFERROR(VLOOKUP($AU$17,Sheet1!AH6:AK6,3,0),0) -> 0 | AV20: =+IFERROR(VLOOKUP($AV$17,Sheet1!AH6:AK6,3,0),0) -> 0 | AW20: =+IFERROR(VLOOKUP($AW$17,Sheet1!AH6:AK6,3,0),0) -> 0 | AX20: =+IFERROR(VLOOKUP($AX$17,Sheet1!AH6:AK6,3,0),0) -> 0 | AY20: =+IFERROR(VLOOKUP($AY$17,Sheet1!AH6:AK6,3,0),0) -> 0 | AZ20: =+IFERROR(VLOOKUP($AZ$17,Sheet1!AH6:AK6,3,0),0) -> 0 | BA20: 5540 | BB20: =+IFERROR(VLOOKUP($BB$17,Sheet1!AH6:AK6,3,0),0) -> 0 | BC20: =+IFERROR(VLOOKUP($BC$17,Sheet1!AL6:AO6,3,0),0) -> 0 | BD20: =+IFERROR(VLOOKUP($BD$17,Sheet1!AL6:AO6,3,0),0) -> 0 | BE20: =+IFERROR(VLOOKUP($BE$17,Sheet1!AL6:AO6,3,0),0) -> 0 | BF20: 1362 | BG20: =+IFERROR(VLOOKUP($BG$17,Sheet1!AL6:AO6,3,0),0) -> 0 | BH20: =+IFERROR(VLOOKUP($BH$17,Sheet1!AL6:AO6,3,0),0) -> 0 | BI20: =+IFERROR(VLOOKUP($BI$17,Sheet1!AL6:AO6,3,0),0) -> 0 | BK20: =+IFERROR(VLOOKUP($BK$17,Sheet1!AL6:AO6,3,0),0) -> 0 | BL20: 1028 | BN20: =+IFERROR(VLOOKUP($BN$17,Sheet1!AT6:AW6,3,0),0) -> 0 | BO20: =+IFERROR(VLOOKUP($BO$17,Sheet1!AX6:BA6,3,0),0) -> 0 | BP20: 87 | BQ20: 33 | BR20: =+IFERROR(VLOOKUP($BR$17,Sheet1!BF6:BI6,3,0),0) -> 0 | BS20: =+IFERROR(VLOOKUP($BS$17,Sheet1!BJ6:BM6,3,0),0) -> 0 | BT20: =+IFERROR(VLOOKUP($BT$17,Sheet1!BN6:BQ6,3,0),0) -> 0 | BU20: 60 | BV20: =+IFERROR(VLOOKUP($BV$17,Sheet1!BV6:BY6,3,0),0) -> 0 | BW20: =Sheet1!E6 -> STEEL | BX20: =Sheet1!CV6 -> SP0400081 | BY20: =Sheet1!CW6 -> CORRUGATED DISPATCH STEEL DRUM 2500 X 1400 X 1250 MM | BZ20: =Sheet1!CX6 -> 250 | CA20: =Sheet1!BZ6 -> 193800 | CB20: =SUMPRODUCT($N$18:$BV$18,N20:BV20)+CA20 -> 1886729 | CC20: =Sheet1!CB6 -> 0 | CD20: =CB20*CC20 -> 0 | CE20: 0.28 | CF20: =CB20*CE20 -> 528284.12 | CG20: 0 | CH20: =CB20*CG20 -> 0 | CI20: =CB20+CD20+CF20+CH20 -> 2415013.1 | CJ20: 0.02 | CK20: =CI20*CJ20 -> 48300.262 | CL20: 0.01 | CM20: =CI20*CL20 -> 24150.131
A21: =Sheet1!A8 -> ENQ-12006-22-23 | B21: =Sheet1!B8 -> 45261 | C21: =Sheet1!C8 -> FA1300091 | D21: =Sheet1!D8 -> 3 CORE X 300 SQ. MM. AL/ARM - WIRE (XLPE) - 11 KV | E21: =CI21+CK21+CM21 -> 2248076.4 | F21: =ROUNDUP(M30,0) -> 168000 | G21: =E21+F21 -> 2416076.4 | H21: =Sheet1!CP8 -> 0.18 | I21: =G21*H21 -> 434893.74 | J21: =G21+I21 -> 2850970.1 | K21: =Sheet1!CS8 -> 70 | L21: =Sheet1!CT8 -> KMS | M21: =J21*K21 -> 1.9956791e+08 | N21: =+IFERROR(VLOOKUP($N$17,Sheet1!J8:L8,3,0),0) -> 2430 | O21: =+IFERROR(VLOOKUP($O$17,Sheet1!J8:L8,3,0),0) -> 0 | P21: =+IFERROR(VLOOKUP($P$17,Sheet1!J8:M8,3,0),0) -> 0 | Q21: =+IFERROR(VLOOKUP($Q$17,Sheet1!J8:M8,3,0),0) -> 0 | R21: =+IFERROR(VLOOKUP($R$17,Sheet1!J8:M8,3,0),0) -> 0 | S21: =+IFERROR(VLOOKUP($S$17,Sheet1!N8:Q8,3,0),0) -> 0 | T21: =+IFERROR(VLOOKUP($T$17,Sheet1!N8:Q8,3,0),0) -> 0 | U21: =+IFERROR(VLOOKUP($U$17,Sheet1!F8:I8,3,0),0) -> 0 | V21: =+IFERROR(VLOOKUP($V$17,Sheet1!F8:I8,3,0),0) -> 0 | W21: =+IFERROR(VLOOKUP($W$17,Sheet1!F8:I8,3,0),0) -> 0 | X21: =+IFERROR(VLOOKUP($X$17,Sheet1!F8:I8,3,0),0) -> 0 | Y21: 158 | Z21: =+IFERROR(VLOOKUP($Z$17,Sheet1!F8:I8,3,0),0) -> 0 | AA21: =+IFERROR(VLOOKUP($AA$17,Sheet1!F8:I8,3,0),0) -> 0 | AB21: =+IFERROR(VLOOKUP($AB$17,Sheet1!F8:I8,3,0),0) -> 0 | AC21: =+IFERROR(VLOOKUP($AC$17,Sheet1!R8:U8,3,0),0) -> 0 | AD21: 450 | AE21: 838 | AF21: =+IFERROR(VLOOKUP($AF$17,Sheet1!V8:Y8,3,0),0) -> 0 | AG21: =+IFERROR(VLOOKUP($AG$17,Sheet1!V8:Y8,3,0),0) -> 0 | AH21: =+IFERROR(VLOOKUP($AH$17,Sheet1!V8:Y8,3,0),0) -> 0 | AI21: =+IFERROR(VLOOKUP($AI$17,Sheet1!V8:Y8,3,0),0) -> 0 | AJ21: =+IFERROR(VLOOKUP($AJ$17,Sheet1!V8:Y8,3,0),0) -> 0 | AK21: =+IFERROR(VLOOKUP($AK$17,Sheet1!Z8:AB8,3,0),0) -> 0 | AL21: =+IFERROR(VLOOKUP($AL$17,Sheet1!AD8:AG8,3,0),0) -> 0 | AM21: =+IFERROR(VLOOKUP($AM$17,Sheet1!AD8:AG8,3,0),0) -> 0 | AN21: =+IFERROR(VLOOKUP($AN$17,Sheet1!AD8:AG8,3,0),0) -> 0 | AO21: =+IFERROR(VLOOKUP($AO$17,Sheet1!AD8:AG8,3,0),0) -> 0 | AP21: =+IFERROR(VLOOKUP($AP$17,Sheet1!AD8:AG8,3,0),0) -> 0 | AQ21: =+IFERROR(VLOOKUP($AQ$17,Sheet1!AD8:AG8,3,0),0) -> 0 | AR21: 868 | AS21: =+IFERROR(VLOOKUP($AS$17,Sheet1!AH8:AK8,3,0),0) -> 0 | AT21: =+IFERROR(VLOOKUP($AT$17,Sheet1!AH8:AK8,3,0),0) -> 0 | AU21: =+IFERROR(VLOOKUP($AU$17,Sheet1!AH8:AK8,3,0),0) -> 0 | AV21: =+IFERROR(VLOOKUP($AV$17,Sheet1!AH8:AK8,3,0),0) -> 0 | AW21: =+IFERROR(VLOOKUP($AW$17,Sheet1!AH8:AK8,3,0),0) -> 0 | AX21: =+IFERROR(VLOOKUP($AX$17,Sheet1!AH8:AK8,3,0),0) -> 0 | AY21: =+IFERROR(VLOOKUP($AY$17,Sheet1!AH8:AK8,3,0),0) -> 0 | AZ21: =+IFERROR(VLOOKUP($AZ$17,Sheet1!AH8:AK8,3,0),0) -> 0 | BA21: 4008 | BB21: =+IFERROR(VLOOKUP($BB$17,Sheet1!AH8:AK8,3,0),0) -> 0 | BC21: =+IFERROR(VLOOKUP($BC$17,Sheet1!AL8:AO8,3,0),0) -> 0 | BD21: =+IFERROR(VLOOKUP($BD$17,Sheet1!AL8:AO8,3,0),0) -> 0 | BE21: =+IFERROR(VLOOKUP($BE$17,Sheet1!AL8:AO8,3,0),0) -> 0 | BF21: 1188 | BG21: =+IFERROR(VLOOKUP($BG$17,Sheet1!AL8:AO8,3,0),0) -> 0 | BH21: =+IFERROR(VLOOKUP($BH$17,Sheet1!AL8:AO8,3,0),0) -> 0 | BI21: =+IFERROR(VLOOKUP($BI$17,Sheet1!AL8:AO8,3,0),0) -> 0 | BJ21: =+IFERROR(VLOOKUP($BJ$17,Sheet1!AL8:AO8,3,0),0) -> 0 | BK21: =+IFERROR(VLOOKUP($BK$17,Sheet1!AL8:AO8,3,0),0) -> 0 | BL21: 881 | BM21: =+IFERROR(VLOOKUP($BM$17,Sheet1!AP8:AS8,3,0),0) -> 0 | BN21: =+IFERROR(VLOOKUP($BN$17,Sheet1!AT8:AW8,3,0),0) -> 0 | BO21: =+IFERROR(VLOOKUP($BO$17,Sheet1!AX8:BA8,3,0),0) -> 0 | BP21: 85 | BQ21: 38 | BS21: =+IFERROR(VLOOKUP($BS$17,Sheet1!BJ8:BM8,3,0),0) -> 0 | BT21: =+IFERROR(VLOOKUP($BT$17,Sheet1!BN8:BQ8,3,0),0) -> 0 | BU21: 54 | BV21: =+IFERROR(VLOOKUP($BV$17,Sheet1!BV8:BY8,3,0),0) -> 0 | BW21: =Sheet1!E8 -> STEEL | BX21: =Sheet1!CV8 -> SP0400136 | BY21: =Sheet1!CW8 -> CORRUGATED DISPATCH STEEL DRUM 2200 X 1300 X 1200 MM | BZ21: =Sheet1!CX8 -> 250 | CA21: =Sheet1!BZ8 -> 171000 | CB21: =SUMPRODUCT($N$18:$BV$18,N21:BV21)+CA21 -> 1705155 | CC21: =Sheet1!CB8 -> 0 | CD21: =CB21*CC21 -> 0 | CE21: 0.28 | CF21: =CB21*CE21 -> 477443.4 | CG21: 0 | CH21: =CB21*CG21 -> 0 | CI21: =CB21+CD21+CF21+CH21 -> 2182598.4 | CJ21: 0.02 | CK21: =CI21*CJ21 -> 43651.968 | CL21: 0.01 | CM21: =CI21*CL21 -> 21825.984
A22: =Sheet1!A2 -> ENQ-12006-22-23 | B22: =Sheet1!B2 -> 45261 | C22: =Sheet1!C2 -> FA1300027 | D22: =Sheet1!D2 -> 1 CORE X 630 SQ. MM. AL/ARM (XLPE) - 33 KV | E22: =CI22+CK22+CM22 -> 1341522.1 | F22: =ROUNDUP(M31,0) -> 168000 | G22: =E22+F22 -> 1509522.1 | H22: =Sheet1!CP2 -> 0.18 | I22: =G22*H22 -> 271713.98 | J22: =G22+I22 -> 1781236.1 | K22: =Sheet1!CS2 -> 1 | L22: =Sheet1!CT2 -> KMS | M22: =J22*K22 -> 1781236.1 | N22: =+IFERROR(VLOOKUP($N$17,Sheet1!J2:L2,3,0),0) -> 1701 | O22: =+IFERROR(VLOOKUP($O$17,Sheet1!J2:L2,3,0),0) -> 0 | P22: =+IFERROR(VLOOKUP($P$17,Sheet1!J2:M2,3,0),0) -> 0 | Q22: =+IFERROR(VLOOKUP($Q$17,Sheet1!J2:M2,3,0),0) -> 0 | R22: =+IFERROR(VLOOKUP($R$17,Sheet1!J2:M2,3,0),0) -> 0 | S22: =+IFERROR(VLOOKUP($S$17,Sheet1!N2:Q2,3,0),0) -> 0 | T22: =+IFERROR(VLOOKUP($T$17,Sheet1!N2:Q2,3,0),0) -> 0 | U22: =+IFERROR(VLOOKUP($U$17,Sheet1!F2:I2,3,0),0) -> 0 | V22: =+IFERROR(VLOOKUP($V$17,Sheet1!F2:I2,3,0),0) -> 0 | W22: =+IFERROR(VLOOKUP($W$17,Sheet1!F2:I2,3,0),0) -> 0 | X22: =+IFERROR(VLOOKUP($X$17,Sheet1!F2:I2,3,0),0) -> 0 | Y22: 85 | Z22: =+IFERROR(VLOOKUP($Z$17,Sheet1!F2:I2,3,0),0) -> 0 | AA22: =+IFERROR(VLOOKUP($AA$17,Sheet1!F2:I2,3,0),0) -> 0 | AB22: =+IFERROR(VLOOKUP($AB$17,Sheet1!F2:I2,3,0),0) -> 0 | AC22: =+IFERROR(VLOOKUP($AC$17,Sheet1!R2:U2,3,0),0) -> 0 | AD22: 237 | AE22: 1055 | AF22: =+IFERROR(VLOOKUP($AF$17,Sheet1!V2:Y2,3,0),0) -> 0 | AG22: =+IFERROR(VLOOKUP($AG$17,Sheet1!V2:Y2,3,0),0) -> 0 | AH22: =+IFERROR(VLOOKUP($AH$17,Sheet1!V2:Y2,3,0),0) -> 0 | AI22: =+IFERROR(VLOOKUP($AI$17,Sheet1!V2:Y2,3,0),0) -> 0 | AJ22: =+IFERROR(VLOOKUP($AJ$17,Sheet1!V2:Y2,3,0),0) -> 0 | AK22: 18 | AL22: =+IFERROR(VLOOKUP($AL$17,Sheet1!AD2:AG2,3,0),0) -> 0 | AM22: =+IFERROR(VLOOKUP($AM$17,Sheet1!AD2:AG2,3,0),0) -> 0 | AN22: =+IFERROR(VLOOKUP($AN$17,Sheet1!AD2:AG2,3,0),0) -> 0 | AO22: =+IFERROR(VLOOKUP($AO$17,Sheet1!AD2:AG2,3,0),0) -> 0 | AP22: =+IFERROR(VLOOKUP($AP$17,Sheet1!AD2:AG2,3,0),0) -> 0 | AQ22: =+IFERROR(VLOOKUP($AQ$17,Sheet1!AD2:AG2,3,0),0) -> 0 | AR22: 200 | AS22: =+IFERROR(VLOOKUP($AS$17,Sheet1!AH2:AK2,3,0),0) -> 0 | AT22: =+IFERROR(VLOOKUP($AT$17,Sheet1!AH2:AK2,3,0),0) -> 0 | AU22: =+IFERROR(VLOOKUP($AU$17,Sheet1!AH2:AK2,3,0),0) -> 0 | AV22: 842 | AW22: =+IFERROR(VLOOKUP($AW$17,Sheet1!AH2:AK2,3,0),0) -> 0 | AX22: =+IFERROR(VLOOKUP($AX$17,Sheet1!AH2:AK2,3,0),0) -> 0 | AY22: =+IFERROR(VLOOKUP($AY$17,Sheet1!AH2:AK2,3,0),0) -> 0 | AZ22: =+IFERROR(VLOOKUP($AZ$17,Sheet1!AH2:AK2,3,0),0) -> 0 | BA22: =+IFERROR(VLOOKUP($BA$17,Sheet1!AH2:AK2,3,0),0) -> 0 | BB22: =+IFERROR(VLOOKUP($BB$17,Sheet1!AH2:AK2,3,0),0) -> 0 | BC22: =+IFERROR(VLOOKUP($BC$17,Sheet1!AL2:AO2,3,0),0) -> 0 | BD22: =+IFERROR(VLOOKUP($BD$17,Sheet1!AL2:AO2,3,0),0) -> 0 | BE22: =+IFERROR(VLOOKUP($BE$17,Sheet1!AL2:AO2,3,0),0) -> 0 | BF22: 762 | BG22: =+IFERROR(VLOOKUP($BG$17,Sheet1!AL2:AO2,3,0),0) -> 0 | BH22: =+IFERROR(VLOOKUP($BH$17,Sheet1!AL2:AO2,3,0),0) -> 0 | BI22: =+IFERROR(VLOOKUP($BI$17,Sheet1!AL2:AO2,3,0),0) -> 0 | BK22: =+IFERROR(VLOOKUP($BK$17,Sheet1!AL2:AO2,3,0),0) -> 0 | BL22: =+IFERROR(VLOOKUP($BL$17,Sheet1!AL2:AO2,3,0),0) -> 0 | BM22: =+IFERROR(VLOOKUP($BM$17,Sheet1!AP2:AS2,3,0),0) -> 0 | BN22: =+IFERROR(VLOOKUP($BN$17,Sheet1!AT2:AW2,3,0),0) -> 0 | BO22: =+IFERROR(VLOOKUP($BO$17,Sheet1!AX2:BA2,3,0),0) -> 0 | BP22: 45 | BQ22: 26 | BR22: =+IFERROR(VLOOKUP($BR$17,Sheet1!BF2:BI2,3,0),0) -> 0 | BS22: =+IFERROR(VLOOKUP($BS$17,Sheet1!BJ2:BM2,3,0),0) -> 0 | BT22: =+IFERROR(VLOOKUP($BT$17,Sheet1!BN2:BQ2,3,0),0) -> 0 | BU22: 41 | BV22: =+IFERROR(VLOOKUP($BV$17,Sheet1!BV2:BY2,3,0),0) -> 0 | BW22: =Sheet1!E2 -> STEEL | BX22: =Sheet1!CV2 -> SP0400123 | BY22: =Sheet1!CW2 -> CORRUGATED DISPATCH STEEL DRUM 2000 X 1000 X 1200 MM | BZ22: =Sheet1!CX2 -> 500 | CA22: =Sheet1!BZ2 -> 53200 | CB22: =SUMPRODUCT($N$18:$BV$18,N22:BV22)+CA22 -> 1017538 | CC22: =Sheet1!CB2 -> 0 | CD22: =CB22*CC22 -> 0 | CE22: 0.28 | CF22: =CB22*CE22 -> 284910.64 | CG22: 0 | CH22: =CB22*CG22 -> 0 | CI22: =CB22+CD22+CF22+CH22 -> 1302448.6 | CJ22: 0.02 | CK22: =CI22*CJ22 -> 26048.973 | CL22: 0.01 | CM22: =CI22*CL22 -> 13024.486
A23: =Sheet1!A5 -> ENQ-12006-22-23 | B23: =Sheet1!B5 -> 45261 | C23: =Sheet1!C5 -> FA1300122 | D23: =Sheet1!D5 -> 1 CORE X 185 SQ. MM. AL/ARM - WIRE (XLPE) - 22 KV | E23: =CI23+CK23+CM23 -> 591984.01 | F23: =ROUNDUP(M32,0) -> 56000 | G23: =E23+F23 -> 647984.01 | H23: =Sheet1!CP5 -> 0.18 | I23: =G23*H23 -> 116637.12 | J23: =G23+I23 -> 764621.14 | K23: =Sheet1!CS5 -> 3 | L23: =Sheet1!CT5 -> KMS | M23: =J23*K23 -> 2293863.4 | N23: 499 | O23: =+IFERROR(VLOOKUP($O$17,Sheet1!J5:L5,3,0),0) -> 0 | P23: =+IFERROR(VLOOKUP($P$17,Sheet1!J5:M5,3,0),0) -> 0 | Q23: =+IFERROR(VLOOKUP($Q$17,Sheet1!J5:M5,3,0),0) -> 0 | R23: =+IFERROR(VLOOKUP($R$17,Sheet1!J5:M5,3,0),0) -> 0 | S23: =+IFERROR(VLOOKUP($S$17,Sheet1!N5:Q5,3,0),0) -> 0 | T23: =+IFERROR(VLOOKUP($T$17,Sheet1!N5:Q5,3,0),0) -> 0 | U23: =+IFERROR(VLOOKUP($U$17,Sheet1!F5:I5,3,0),0) -> 0 | V23: =+IFERROR(VLOOKUP($V$17,Sheet1!F5:I5,3,0),0) -> 0 | W23: =+IFERROR(VLOOKUP($W$17,Sheet1!F5:I5,3,0),0) -> 0 | X23: =+IFERROR(VLOOKUP($X$17,Sheet1!F5:I5,3,0),0) -> 0 | Y23: 53 | Z23: =+IFERROR(VLOOKUP($Z$17,Sheet1!F5:I5,3,0),0) -> 0 | AA23: =+IFERROR(VLOOKUP($AA$17,Sheet1!F5:I5,3,0),0) -> 0 | AB23: =+IFERROR(VLOOKUP($AB$17,Sheet1!F5:I5,3,0),0) -> 0 | AC23: =+IFERROR(VLOOKUP($AC$17,Sheet1!R5:U5,3,0),0) -> 0 | AD23: 139 | AE23: 428 | AF23: =+IFERROR(VLOOKUP($AF$17,Sheet1!V5:Y5,3,0),0) -> 0 | AG23: =+IFERROR(VLOOKUP($AG$17,Sheet1!V5:Y5,3,0),0) -> 0 | AH23: =+IFERROR(VLOOKUP($AH$17,Sheet1!V5:Y5,3,0),0) -> 0 | AI23: =+IFERROR(VLOOKUP($AI$17,Sheet1!V5:Y5,3,0),0) -> 0 | AJ23: =+IFERROR(VLOOKUP($AJ$17,Sheet1!V5:Y5,3,0),0) -> 0 | AK23: 12 | AL23: =+IFERROR(VLOOKUP($AL$17,Sheet1!AD5:AG5,3,0),0) -> 0 | AM23: =+IFERROR(VLOOKUP($AM$17,Sheet1!AD5:AG5,3,0),0) -> 0 | AN23: =+IFERROR(VLOOKUP($AN$17,Sheet1!AD5:AG5,3,0),0) -> 0 | AO23: =+IFERROR(VLOOKUP($AO$17,Sheet1!AD5:AG5,3,0),0) -> 0 | AP23: =+IFERROR(VLOOKUP($AP$17,Sheet1!AD5:AG5,3,0),0) -> 0 | AQ23: =+IFERROR(VLOOKUP($AQ$17,Sheet1!AD5:AG5,3,0),0) -> 0 | AR23: 93 | AS23: =+IFERROR(VLOOKUP($AS$17,Sheet1!AH5:AK5,3,0),0) -> 0 | AT23: =+IFERROR(VLOOKUP($AT$17,Sheet1!AH5:AK5,3,0),0) -> 0 | AU23: =+IFERROR(VLOOKUP($AU$17,Sheet1!AH5:AK5,3,0),0) -> 0 | AV23: 415 | AW23: =+IFERROR(VLOOKUP($AW$17,Sheet1!AH5:AK5,3,0),0) -> 0 | AX23: =+IFERROR(VLOOKUP($AX$17,Sheet1!AH5:AK5,3,0),0) -> 0 | AY23: =+IFERROR(VLOOKUP($AY$17,Sheet1!AH5:AK5,3,0),0) -> 0 | AZ23: =+IFERROR(VLOOKUP($AZ$17,Sheet1!AH5:AK5,3,0),0) -> 0 | BA23: =+IFERROR(VLOOKUP($BA$17,Sheet1!AH5:AK5,3,0),0) -> 0 | BB23: =+IFERROR(VLOOKUP($BB$17,Sheet1!AH5:AK5,3,0),0) -> 0 | BC23: =+IFERROR(VLOOKUP($BC$17,Sheet1!AL5:AO5,3,0),0) -> 0 | BD23: =+IFERROR(VLOOKUP($BD$17,Sheet1!AL5:AO5,3,0),0) -> 0 | BE23: =+IFERROR(VLOOKUP($BE$17,Sheet1!AL5:AO5,3,0),0) -> 0 | BF23: 371 | BG23: =+IFERROR(VLOOKUP($BG$17,Sheet1!AL5:AO5,3,0),0) -> 0 | BH23: =+IFERROR(VLOOKUP($BH$17,Sheet1!AL5:AO5,3,0),0) -> 0 | BI23: =+IFERROR(VLOOKUP($BI$17,Sheet1!AL5:AO5,3,0),0) -> 0 | BK23: =+IFERROR(VLOOKUP($BK$17,Sheet1!AL5:AO5,3,0),0) -> 0 | BL23: =+IFERROR(VLOOKUP($BL$17,Sheet1!AL5:AO5,3,0),0) -> 0 | BM23: =+IFERROR(VLOOKUP($BM$17,Sheet1!AP5:AS5,3,0),0) -> 0 | BN23: =+IFERROR(VLOOKUP($BN$17,Sheet1!AT5:AW5,3,0),0) -> 0 | BO23: =+IFERROR(VLOOKUP($BO$17,Sheet1!AX5:BA5,3,0),0) -> 0 | BP23: 27 | BQ23: 11 | BR23: =+IFERROR(VLOOKUP($BR$17,Sheet1!BF5:BI5,3,0),0) -> 0 | BS23: =+IFERROR(VLOOKUP($BS$17,Sheet1!BJ5:BM5,3,0),0) -> 0 | BT23: =+IFERROR(VLOOKUP($BT$17,Sheet1!BN5:BQ5,3,0),0) -> 0 | BU23: 27 | BV23: =+IFERROR(VLOOKUP($BV$17,Sheet1!BV5:BY5,3,0),0) -> 0 | BW23: =Sheet1!E5 -> STEEL | BX23: =Sheet1!CV5 -> SP0400125 | BY23: =Sheet1!CW5 -> CORRUGATED DISPATCH STEEL DRUM 1600 X 700 X 915 MM | BZ23: =Sheet1!CX5 -> 500 | CA23: =Sheet1!BZ5 -> 41800 | CB23: =SUMPRODUCT($N$18:$BV$18,N23:BV23)+CA23 -> 449017 | CC23: =Sheet1!CB5 -> 0 | CD23: =CB23*CC23 -> 0 | CE23: 0.28 | CF23: =CB23*CE23 -> 125724.76 | CG23: 0 | CH23: =CB23*CG23 -> 0 | CI23: =CB23+CD23+CF23+CH23 -> 574741.76 | CJ23: 0.02 | CK23: =CI23*CJ23 -> 11494.835 | CL23: 0.01 | CM23: =CI23*CL23 -> 5747.4176
A24: =Sheet1!A3 -> ENQ-12006-22-23 | B24: =Sheet1!B3 -> 45261 | C24: =Sheet1!C3 -> FA1300020 | D24: =Sheet1!D3 -> 1 CORE X 185 SQ. MM. AL./ARM (XLPE) - 11 KV | E24: =CI24+CK24+CM24 -> 510704.65 | F24: =ROUNDUP(M33,0) -> 56000 | G24: =E24+F24 -> 566704.65 | H24: =Sheet1!CP3 -> 0.18 | I24: =G24*H24 -> 102006.84 | J24: =G24+I24 -> 668711.49 | K24: =Sheet1!CS3 -> 3 | L24: =Sheet1!CT3 -> KMS | M24: =J24*K24 -> 2006134.5 | N24: 499 | O24: =+IFERROR(VLOOKUP($O$17,Sheet1!J3:L3,3,0),0) -> 0 | P24: =+IFERROR(VLOOKUP($P$17,Sheet1!J3:M3,3,0),0) -> 0 | Q24: =+IFERROR(VLOOKUP($Q$17,Sheet1!J3:M3,3,0),0) -> 0 | R24: =+IFERROR(VLOOKUP($R$17,Sheet1!J3:M3,3,0),0) -> 0 | S24: =+IFERROR(VLOOKUP($S$17,Sheet1!N3:Q3,3,0),0) -> 0 | T24: =+IFERROR(VLOOKUP($T$17,Sheet1!N3:Q3,3,0),0) -> 0 | U24: =+IFERROR(VLOOKUP($U$17,Sheet1!F3:I3,3,0),0) -> 0 | V24: =+IFERROR(VLOOKUP($V$17,Sheet1!F3:I3,3,0),0) -> 0 | W24: =+IFERROR(VLOOKUP($W$17,Sheet1!F3:I3,3,0),0) -> 0 | X24: =+IFERROR(VLOOKUP($X$17,Sheet1!F3:I3,3,0),0) -> 0 | Y24: 45 | Z24: =+IFERROR(VLOOKUP($Z$17,Sheet1!F3:I3,3,0),0) -> 0 | AA24: =+IFERROR(VLOOKUP($AA$17,Sheet1!F3:I3,3,0),0) -> 0 | AB24: =+IFERROR(VLOOKUP($AB$17,Sheet1!F3:I3,3,0),0) -> 0 | AC24: =+IFERROR(VLOOKUP($AC$17,Sheet1!R3:U3,3,0),0) -> 0 | AD24: 125 | AE24: 230 | AF24: =+IFERROR(VLOOKUP($AF$17,Sheet1!V3:Y3,3,0),0) -> 0 | AG24: =+IFERROR(VLOOKUP($AG$17,Sheet1!V3:Y3,3,0),0) -> 0 | AH24: =+IFERROR(VLOOKUP($AH$17,Sheet1!V3:Y3,3,0),0) -> 0 | AI24: =+IFERROR(VLOOKUP($AI$17,Sheet1!V3:Y3,3,0),0) -> 0 | AJ24: =+IFERROR(VLOOKUP($AJ$17,Sheet1!V3:Y3,3,0),0) -> 0 | AK24: 10 | AL24: =+IFERROR(VLOOKUP($AL$17,Sheet1!AD3:AG3,3,0),0) -> 0 | AM24: =+IFERROR(VLOOKUP($AM$17,Sheet1!AD3:AG3,3,0),0) -> 0 | AN24: =+IFERROR(VLOOKUP($AN$17,Sheet1!AD3:AG3,3,0),0) -> 0 | AO24: =+IFERROR(VLOOKUP($AO$17,Sheet1!AD3:AG3,3,0),0) -> 0 | AP24: =+IFERROR(VLOOKUP($AP$17,Sheet1!AD3:AG3,3,0),0) -> 0 | AQ24: =+IFERROR(VLOOKUP($AQ$17,Sheet1!AD3:AG3,3,0),0) -> 0 | AR24: 80 | AS24: =+IFERROR(VLOOKUP($AS$17,Sheet1!AH3:AK3,3,0),0) -> 0 | AT24: =+IFERROR(VLOOKUP($AT$17,Sheet1!AH3:AK3,3,0),0) -> 0 | AU24: =+IFERROR(VLOOKUP($AU$17,Sheet1!AH3:AK3,3,0),0) -> 0 | AV24: 362 | AW24: =+IFERROR(VLOOKUP($AW$17,Sheet1!AH3:AK3,3,0),0) -> 0 | AX24: =+IFERROR(VLOOKUP($AX$17,Sheet1!AH3:AK3,3,0),0) -> 0 | AY24: =+IFERROR(VLOOKUP($AY$17,Sheet1!AH3:AK3,3,0),0) -> 0 | AZ24: =+IFERROR(VLOOKUP($AZ$17,Sheet1!AH3:AK3,3,0),0) -> 0 | BA24: =+IFERROR(VLOOKUP($BA$17,Sheet1!AH3:AK3,3,0),0) -> 0 | BB24: =+IFERROR(VLOOKUP($BB$17,Sheet1!AH3:AK3,3,0),0) -> 0 | BC24: =+IFERROR(VLOOKUP($BC$17,Sheet1!AL3:AO3,3,0),0) -> 0 | BD24: =+IFERROR(VLOOKUP($BD$17,Sheet1!AL3:AO3,3,0),0) -> 0 | BE24: =+IFERROR(VLOOKUP($BE$17,Sheet1!AL3:AO3,3,0),0) -> 0 | BF24: 300 | BG24: =+IFERROR(VLOOKUP($BG$17,Sheet1!AL3:AO3,3,0),0) -> 0 | BH24: =+IFERROR(VLOOKUP($BH$17,Sheet1!AL3:AO3,3,0),0) -> 0 | BI24: =+IFERROR(VLOOKUP($BI$17,Sheet1!AL3:AO3,3,0),0) -> 0 | BK24: =+IFERROR(VLOOKUP($BK$17,Sheet1!AL3:AO3,3,0),0) -> 0 | BL24: =+IFERROR(VLOOKUP($BL$17,Sheet1!AL3:AO3,3,0),0) -> 0 | BM24: =+IFERROR(VLOOKUP($BM$17,Sheet1!AP3:AS3,3,0),0) -> 0 | BN24: =+IFERROR(VLOOKUP($BN$17,Sheet1!AT3:AW3,3,0),0) -> 0 | BO24: =+IFERROR(VLOOKUP($BO$17,Sheet1!AX3:BA3,3,0),0) -> 0 | BP24: 24 | BQ24: 11 | BR24: =+IFERROR(VLOOKUP($BR$17,Sheet1!BF3:BI3,3,0),0) -> 0 | BS24: =+IFERROR(VLOOKUP($BS$17,Sheet1!BJ3:BM3,3,0),0) -> 0 | BT24: =+IFERROR(VLOOKUP($BT$17,Sheet1!BN3:BQ3,3,0),0) -> 0 | BU24: 23 | BV24: =+IFERROR(VLOOKUP($BV$17,Sheet1!BV3:BY3,3,0),0) -> 0 | BW24: =Sheet1!E3 -> STEEL | BX24: =Sheet1!CV3 -> SP0400125 | BY24: =Sheet1!CW3 -> CORRUGATED DISPATCH STEEL DRUM 1600 X 700 X 915 MM | BZ24: =Sheet1!CX3 -> 500 | CA24: =Sheet1!BZ3 -> 41800 | CB24: =SUMPRODUCT($N$18:$BV$18,N24:BV24)+CA24 -> 387367 | CC24: =Sheet1!CB3 -> 0 | CD24: =CB24*CC24 -> 0 | CE24: 0.28 | CF24: =CB24*CE24 -> 108462.76 | CG24: 0 | CH24: =CB24*CG24 -> 0 | CI24: =CB24+CD24+CF24+CH24 -> 495829.76 | CJ24: 0.02 | CK24: =CI24*CJ24 -> 9916.5952 | CL24: 0.01 | CM24: =CI24*CL24 -> 4958.2976
A25: =Sheet1!A4 -> ENQ-12006-22-23 | B25: =Sheet1!B4 -> 45261 | C25: =Sheet1!C4 -> FA1300066 | D25: =Sheet1!D4 -> 1 CORE X 1000 SQ. MM. AL/ARM (XLPE) - 11 KV | E25: =CI25+CK25+CM25 -> 1804778.2 | F25: =ROUNDUP(M34,0) -> 67200 | G25: =E25+F25 -> 1871978.2 | H25: =Sheet1!CP4 -> 0.18 | I25: =G25*H25 -> 336956.08 | J25: =G25+I25 -> 2208934.3 | K25: =Sheet1!CS4 -> 3 | L25: =Sheet1!CT4 -> KMS | M25: =J25*K25 -> 6626803 | N25: 2770 | O25: =+IFERROR(VLOOKUP($O$17,Sheet1!J4:L4,3,0),0) -> 0 | P25: =+IFERROR(VLOOKUP($P$17,Sheet1!J4:M4,3,0),0) -> 0 | Q25: =+IFERROR(VLOOKUP($Q$17,Sheet1!J4:M4,3,0),0) -> 0 | R25: =+IFERROR(VLOOKUP($R$17,Sheet1!J4:M4,3,0),0) -> 0 | S25: =+IFERROR(VLOOKUP($S$17,Sheet1!N4:Q4,3,0),0) -> 0 | T25: =+IFERROR(VLOOKUP($T$17,Sheet1!N4:Q4,3,0),0) -> 0 | U25: =+IFERROR(VLOOKUP($U$17,Sheet1!F4:I4,3,0),0) -> 0 | V25: =+IFERROR(VLOOKUP($V$17,Sheet1!F4:I4,3,0),0) -> 0 | W25: =+IFERROR(VLOOKUP($W$17,Sheet1!F4:I4,3,0),0) -> 0 | X25: =+IFERROR(VLOOKUP($X$17,Sheet1!F4:I4,3,0),0) -> 0 | Y25: 87 | Z25: =+IFERROR(VLOOKUP($Z$17,Sheet1!F4:I4,3,0),0) -> 0 | AA25: =+IFERROR(VLOOKUP($AA$17,Sheet1!F4:I4,3,0),0) -> 0 | AB25: =+IFERROR(VLOOKUP($AB$17,Sheet1!F4:I4,3,0),0) -> 0 | AC25: =+IFERROR(VLOOKUP($AC$17,Sheet1!R4:U4,3,0),0) -> 0 | AD25: 290 | AE25: 495 | AF25: =+IFERROR(VLOOKUP($AF$17,Sheet1!V4:Y4,3,0),0) -> 0 | AG25: =+IFERROR(VLOOKUP($AG$17,Sheet1!V4:Y4,3,0),0) -> 0 | AH25: =+IFERROR(VLOOKUP($AH$17,Sheet1!V4:Y4,3,0),0) -> 0 | AI25: =+IFERROR(VLOOKUP($AI$17,Sheet1!V4:Y4,3,0),0) -> 0 | AJ25: =+IFERROR(VLOOKUP($AJ$17,Sheet1!V4:Y4,3,0),0) -> 0 | AK25: 18 | AL25: =+IFERROR(VLOOKUP($AL$17,Sheet1!AD4:AG4,3,0),0) -> 0 | AM25: =+IFERROR(VLOOKUP($AM$17,Sheet1!AD4:AG4,3,0),0) -> 0 | AN25: =+IFERROR(VLOOKUP($AN$17,Sheet1!AD4:AG4,3,0),0) -> 0 | AO25: =+IFERROR(VLOOKUP($AO$17,Sheet1!AD4:AG4,3,0),0) -> 0 | AP25: =+IFERROR(VLOOKUP($AP$17,Sheet1!AD4:AG4,3,0),0) -> 0 | AQ25: =+IFERROR(VLOOKUP($AQ$17,Sheet1!AD4:AG4,3,0),0) -> 0 | AR25: 205 | AS25: =+IFERROR(VLOOKUP($AS$17,Sheet1!AH4:AK4,3,0),0) -> 0 | AT25: =+IFERROR(VLOOKUP($AT$17,Sheet1!AH4:AK4,3,0),0) -> 0 | AU25: =+IFERROR(VLOOKUP($AU$17,Sheet1!AH4:AK4,3,0),0) -> 0 | AV25: 842 | AW25: =+IFERROR(VLOOKUP($AW$17,Sheet1!AH4:AK4,3,0),0) -> 0 | AX25: =+IFERROR(VLOOKUP($AX$17,Sheet1!AH4:AK4,3,0),0) -> 0 | AY25: =+IFERROR(VLOOKUP($AY$17,Sheet1!AH4:AK4,3,0),0) -> 0 | AZ25: =+IFERROR(VLOOKUP($AZ$17,Sheet1!AH4:AK4,3,0),0) -> 0 | BA25: =+IFERROR(VLOOKUP($BA$17,Sheet1!AH4:AK4,3,0),0) -> 0 | BB25: =+IFERROR(VLOOKUP($BB$17,Sheet1!AH4:AK4,3,0),0) -> 0 | BC25: =+IFERROR(VLOOKUP($BC$17,Sheet1!AL4:AO4,3,0),0) -> 0 | BD25: =+IFERROR(VLOOKUP($BD$17,Sheet1!AL4:AO4,3,0),0) -> 0 | BE25: =+IFERROR(VLOOKUP($BE$17,Sheet1!AL4:AO4,3,0),0) -> 0 | BF25: 724 | BG25: =+IFERROR(VLOOKUP($BG$17,Sheet1!AL4:AO4,3,0),0) -> 0 | BH25: =+IFERROR(VLOOKUP($BH$17,Sheet1!AL4:AO4,3,0),0) -> 0 | BI25: =+IFERROR(VLOOKUP($BI$17,Sheet1!AL4:AO4,3,0),0) -> 0 | BJ25: =+IFERROR(VLOOKUP($BJ$17,Sheet1!AL4:AO4,3,0),0) -> 0 | BK25: =+IFERROR(VLOOKUP($BK$17,Sheet1!AL4:AO4,3,0),0) -> 0 | BL25: =+IFERROR(VLOOKUP($BL$17,Sheet1!AL4:AO4,3,0),0) -> 0 | BM25: =+IFERROR(VLOOKUP($BM$17,Sheet1!AP4:AS4,3,0),0) -> 0 | BN25: =+IFERROR(VLOOKUP($BN$17,Sheet1!AT4:AW4,3,0),0) -> 0 | BO25: =+IFERROR(VLOOKUP($BO$17,Sheet1!AX4:BA4,3,0),0) -> 0 | BP25: 73 | BQ25: 75 | BS25: =+IFERROR(VLOOKUP($BS$17,Sheet1!BJ4:BM4,3,0),0) -> 0 | BT25: =+IFERROR(VLOOKUP($BT$17,Sheet1!BN4:BQ4,3,0),0) -> 0 | BU25: 42 | BV25: 45 | BW25: =Sheet1!E4 -> STEEL | BX25: =Sheet1!CV4 -> SP0400107 | BY25: =Sheet1!CW4 -> CORRUGATED DISPATCH STEEL DRUM 2150 X 1080 X 1240 MM | BZ25: =Sheet1!CX4 -> 500 | CA25: =Sheet1!BZ4 -> 66500 | CB25: =SUMPRODUCT($N$18:$BV$18,N25:BV25)+CA25 -> 1225323 | CC25: 0.15 | CD25: =CB25*CC25 -> 183798.45 | CE25: 0.28 | CF25: =CB25*CE25 -> 343090.44 | CG25: 0 | CH25: =CB25*CG25 -> 0 | CI25: =CB25+CD25+CF25+CH25 -> 1752211.9 | CJ25: 0.02 | CK25: =CI25*CJ25 -> 35044.238 | CL25: 0.01 | CM25: =CI25*CL25 -> 17522.119
E27: Order Quantity | F27: Stnd Length | G27: Truck type | H27: Fare of one truck | I27: No of Drum in one truck | J27: Total length in one Truck | K27: No of Truck | L27: Total Freight | M27: Freight per KM
D28: =D19 -> 3 CORE X 400 SQ. MM AL/ARM - WIRE (XLPE) - 33 KV | E28: =K19 -> 45 | F28: =BZ19/1000 -> 0.25 | G28: 28 MT TRAILER | H28: 168000 | I28: 3 | J28: =F28*I28 -> 0.75 | K28: =ROUNDUP((E28/J28),2) -> 60 | L28: =M28*E28 -> 10080000 | M28: =(H28*K28)/E28 -> 224000
D29: =D20 -> 3 CORE X 240 SQ. MM. AL/ARM - WIRE (XLPE) - 22 KV | E29: =K20 -> 30 | F29: =BZ20/1000 -> 0.25 | G29: 28 MT TRAILER | H29: 168000 | I29: 5 | J29: =F29*I29 -> 1.25 | K29: =ROUNDUP((E29/J29),2) -> 24 | L29: =M29*E29 -> 4032000 | M29: =(H29*K29)/E29 -> 134400
D30: =D21 -> 3 CORE X 300 SQ. MM. AL/ARM - WIRE (XLPE) - 11 KV | E30: =K21 -> 70 | F30: =BZ21/1000 -> 0.25 | G30: 28 MT TRAILER | H30: 168000 | I30: 4 | J30: =F30*I30 -> 1 | K30: =ROUNDUP((E30/J30),2) -> 70 | L30: =M30*E30 -> 11760000 | M30: =(H30*K30)/E30 -> 168000
D31: =D22 -> 1 CORE X 630 SQ. MM. AL/ARM (XLPE) - 33 KV | E31: =K22 -> 1 | F31: =BZ22/1000 -> 0.5 | G31: 28 MT TRAILER | H31: 168000 | I31: 5 | J31: =F31*I31 -> 2.5 | K31: =ROUNDUP((E31/J31),0) -> 1 | L31: =M31*E31 -> 168000 | M31: =(H31*K31)/E31 -> 168000
D32: =D23 -> 1 CORE X 185 SQ. MM. AL/ARM - WIRE (XLPE) - 22 KV | E32: =K23 -> 3 | F32: =BZ23/1000 -> 0.5 | G32: 28 MT TRAILER | H32: 168000 | I32: 10 | J32: =F32*I32 -> 5 | K32: =ROUNDUP((E32/J32),0) -> 1 | L32: =M32*E32 -> 168000 | M32: =(H32*K32)/E32 -> 56000
D33: =D24 -> 1 CORE X 185 SQ. MM. AL./ARM (XLPE) - 11 KV | E33: =K24 -> 3 | F33: =BZ24/1000 -> 0.5 | G33: 28 MT TRAILER | H33: 168000 | I33: 10 | J33: =F33*I33 -> 5 | K33: =ROUNDUP((E33/J33),0) -> 1 | L33: =M33*E33 -> 168000 | M33: =(H33*K33)/E33 -> 56000
D34: =D25 -> 1 CORE X 1000 SQ. MM. AL/ARM (XLPE) - 11 KV | E34: =K25 -> 3 | F34: =BZ25/1000 -> 0.5 | G34: 28 MT TRAILER | H34: 168000 | I34: 5 | J34: =F34*I34 -> 2.5 | K34: =ROUNDUP((E34/J34),2) -> 1.2 | L34: =M34*E34 -> 201600 | M34: =(H34*K34)/E34 -> 67200
I35: SOMBHU SIR CONFIRMED OVER PHONE
B37: AVG OF DEC'23
A38: DOCKET NO. | B38: Base Date | C38: ITEM CODE | D38: PROPOSE ERP ITEM NAME | E38: EX-WORKS (PER MTR) | F38: FREIGHT PER MTR | G38: PRICE INCLUDING FREIGHT (PER MTR) | H38: GST % | I38: GST VALUE | J38: PRICE INCLUDING GST & FREIGHT (PER MTR) | K38: QTY | L38: Unit | M38: TOTAL PRICE OF FULL QTY (INCLUDING FRIGHT & GST)
A40: =A19 -> ENQ-12006-22-23 | B40: =B19 -> 45261 | C40: =C19 -> FA1300080 | D40: =D19 -> 3 CORE X 400 SQ. MM AL/ARM - WIRE (XLPE) - 33 KV | E40: =ROUNDUP(E19/1000,2) -> 3593.37 | F40: =ROUNDUP(F19/1000,2) -> 224 | G40: =E40+F40 -> 3817.37 | H40: =Sheet1!CP28 -> 0 | I40: =G40*H40 -> 0 | J40: =G40+I40 -> 3817.37 | K40: =K19*1000 -> 45000 | L40: MTR | M40: =J40*K40 -> 1.7178165e+08
A41: =A20 -> ENQ-12006-22-23 | B41: =B20 -> 45261 | C41: =C20 -> FA1300202 | D41: =D20 -> 3 CORE X 240 SQ. MM. AL/ARM - WIRE (XLPE) - 22 KV | E41: =ROUNDUP(E20/1000,2) -> 2487.47 | F41: =ROUNDUP(F20/1000,2) -> 134.4 | G41: =E41+F41 -> 2621.87 | H41: =Sheet1!CP27 -> 0 | I41: =G41*H41 -> 0 | J41: =G41+I41 -> 2621.87 | K41: =K20*1000 -> 30000 | L41: MTR | M41: =J41*K41 -> 78656100
A42: =A21 -> ENQ-12006-22-23 | B42: =B21 -> 45261 | C42: =C21 -> FA1300091 | D42: =D21 -> 3 CORE X 300 SQ. MM. AL/ARM - WIRE (XLPE) - 11 KV | E42: =ROUNDUP(E21/1000,2) -> 2248.08 | F42: =ROUNDUP(F21/1000,2) -> 168 | G42: =E42+F42 -> 2416.08 | H42: =Sheet1!CP29 -> 0 | I42: =G42*H42 -> 0 | J42: =G42+I42 -> 2416.08 | K42: =K21*1000 -> 70000 | L42: MTR | M42: =J42*K42 -> 1.691256e+08
A43: =A22 -> ENQ-12006-22-23 | B43: =B22 -> 45261 | C43: =C22 -> FA1300027 | D43: =D22 -> 1 CORE X 630 SQ. MM. AL/ARM (XLPE) - 33 KV | E43: =ROUNDUP(E22/1000,2) -> 1341.53 | F43: =ROUNDUP(F22/1000,2) -> 168 | G43: =E43+F43 -> 1509.53 | H43: =Sheet1!CP23 -> 0 | I43: =G43*H43 -> 0 | J43: =G43+I43 -> 1509.53 | K43: =K22*1000 -> 1000 | L43: MTR | M43: =J43*K43 -> 1509530
A44: =A23 -> ENQ-12006-22-23 | B44: =B23 -> 45261 | C44: =C23 -> FA1300122 | D44: =D23 -> 1 CORE X 185 SQ. MM. AL/ARM - WIRE (XLPE) - 22 KV | E44: =ROUNDUP(E23/1000,2) -> 591.99 | F44: =ROUNDUP(F23/1000,2) -> 56 | G44: =E44+F44 -> 647.99 | H44: =Sheet1!CP26 -> 0 | I44: =G44*H44 -> 0 | J44: =G44+I44 -> 647.99 | K44: =K23*1000 -> 3000 | L44: MTR | M44: =J44*K44 -> 1943970
A45: =A24 -> ENQ-12006-22-23 | B45: =B24 -> 45261 | C45: =C24 -> FA1300020 | D45: =D24 -> 1 CORE X 185 SQ. MM. AL./ARM (XLPE) - 11 KV | E45: =ROUNDUP(E24/1000,2) -> 510.71 | F45: =ROUNDUP(F24/1000,2) -> 56 | G45: =E45+F45 -> 566.71 | H45: =Sheet1!CP24 -> 0 | I45: =G45*H45 -> 0 | J45: =G45+I45 -> 566.71 | K45: =K24*1000 -> 3000 | L45: MTR | M45: =J45*K45 -> 1700130
A46: =A25 -> ENQ-12006-22-23 | B46: =B25 -> 45261 | C46: =C25 -> FA1300066 | D46: =D25 -> 1 CORE X 1000 SQ. MM. AL/ARM (XLPE) - 11 KV | E46: =ROUNDUP(E25/1000,2) -> 1804.78 | F46: =ROUNDUP(F25/1000,2) -> 67.2 | G46: =E46+F46 -> 1871.98 | H46: =Sheet1!CP25 -> 0 | I46: =G46*H46 -> 0 | J46: =G46+I46 -> 1871.98 | K46: =K25*1000 -> 3000 | L46: MTR | M46: =J46*K46 -> 5615940
...

Sheet HT PV
A1: Base Date | B1: 44896
A2: PV FORMULA
AC4: VALUE ADDITION CALCULATION
A5: Item | B5: Calculation part | D5: Applicable Date | J5: BASE DATE | P5: FACTORS | U5: Ex-Work Po | V5: PVC of al | W5: PVC of Cu | X5: PVC of XLPE | Y5: PVC OF PVC | Z5: PVC OF FE | AA5: PV/PKM | AB5: Billing Price/PKM
D6: Date | E6: Al | F6: Cu | G6: Cc | H6: PVCc | I6: Fe | J6: Date | K6: Alo | L6: Cuo | M6: Cco | N6: PVCco | O6: Feo | AC6: ='AUTO CALCULATION SHEET (2)'!N17 -> Alumimium | AD6: ='AUTO CALCULATION SHEET (2)'!Y17 -> Copper Tape - 0.045 mm | AE6: ='AUTO CALCULATION SHEET (2)'!AD17 -> Extruded Semiconductive(Stripable) | AF6: ='AUTO CALCULATION SHEET (2)'!AE17 -> HT-XLPE | AG6: ='AUTO CALCULATION SHEET (2)'!AK17 -> POLY TAPE | AH6: ='AUTO CALCULATION SHEET (2)'!AR17 -> PVC Type ST-2-PRESSURE EXTRUDED | AI6: ='AUTO CALCULATION SHEET (2)'!AV17 -> Aluminium Round Wire | AJ6: ='AUTO CALCULATION SHEET (2)'!BA17 -> Galvanised Steel Round Wire | AK6: ='AUTO CALCULATION SHEET (2)'!BF17 -> FRLSH PVC Type ST-2 | AL6: ='AUTO CALCULATION SHEET (2)'!BL17 -> PP FILLER | AM6: ='AUTO CALCULATION SHEET (2)'!BP17 -> Semi conducting Water Swellable tape | AN6: ='AUTO CALCULATION SHEET (2)'!BQ17 -> NCWBT | AO6: ='AUTO CALCULATION SHEET (2)'!BU17 -> RUBBERIZED COTTON TAPE | AP6: ='AUTO CALCULATION SHEET (2)'!BV17 -> LDPE TAPE | AQ6: RMC | AR6: Drum | AS6: RMC+Drum | AT6: VA | AU6: Groos VA% | AV6: Mfg % | AW6: Int % | AX6: Ins% | AY6: Net VA
P7: Alf | Q7: Smif/CuF | R7: XLFAL | S7: CCFAI/ CCFCu | T7: FeF | AC7: 218 | AD7: 860 | AE7: 202 | AF7: 150 | AG7: 120 | AH7: 88 | AI7: 223 | AJ7: 82 | AK7: 104 | AL7: 65 | AM7: 460 | AN7: 348 | AO7: 450 | AP7: 190
AC8: Kg/Km | AD8: Kg/Km | AE8: Kg/Km | AF8: Kg/Km | AG8: Kg/Km | AH8: Kg/Km | AI8: Kg/Km | AJ8: Kg/Km | AK8: Kg/Km | AL8: Kg/Km | AM8: Kg/Km | AN8: Kg/Km | AO8: Kg/Km | AP8: Kg/Km
A9: ='AUTO CALCULATION SHEET (2)'!D19 -> 3 CORE X 400 SQ. MM AL/ARM - WIRE (XLPE) - 33 KV | D9: 44941 | E9: 211937.51 | F9: 753622.95 | G9: 169352 | H9: 152825 | I9: 70250 | J9: =$B$1 -> 44896 | K9: 209522 | L9: 758026 | M9: 169352 | N9: 152825 | O9: 70250 | P9: 3.374 | Q9: 0.1638 | R9: 3.229 | S9: 5.736 | T9: 8.76 | U9: ='AUTO CALCULATION SHEET (2)'!E19 -> 3593365.1 | V9: =(P9*(E9-K9)) -> 8149.9307 | W9: =Q9*(F9-L9) -> -721.21959 | X9: =(R9*(G9-M9)) -> 0 | Y9: =(S9*(H9-N9)) -> 0 | Z9: =(T9*(I9-O9)) -> 0 | AA9: =V9+W9+X9+Y9+Z9 -> 7428.7112 | AB9: =U9+AA9 -> 3600793.8 | AC9: ='AUTO CALCULATION SHEET (2)'!N19 -> 3243 | AD9: ='AUTO CALCULATION SHEET (2)'!Y19 -> 225 | AE9: ='AUTO CALCULATION SHEET (2)'!AD19 -> 588 | AF9: ='AUTO CALCULATION SHEET (2)'!AE19 -> 2670 | AG9: ='AUTO CALCULATION SHEET (2)'!AK19 -> 0 | AH9: ='AUTO CALCULATION SHEET (2)'!AR19 -> 1577 | AI9: ='AUTO CALCULATION SHEET (2)'!AV19 -> 0 | AJ9: ='AUTO CALCULATION SHEET (2)'!BA19 -> 7182 | AK9: ='AUTO CALCULATION SHEET (2)'!BF19 -> 1724 | AL9: ='AUTO CALCULATION SHEET (2)'!BL19 -> 1768 | AM9: ='AUTO CALCULATION SHEET (2)'!BP19 -> 114 | AN9: ='AUTO CALCULATION SHEET (2)'!BQ19 -> 58 | AO9: ='AUTO CALCULATION SHEET (2)'!BU19 -> 76 | AP9: ='AUTO CALCULATION SHEET (2)'!BV19 -> 0 | AQ9: =SUMPRODUCT(AC9:AP9,$AC$7:AP$7) -> 2548490 | AR9: ='AUTO CALCULATION SHEET (2)'!CA19 -> 190000 | AS9: =AQ9+AR9 -> 2738490 | AT9: =AB9-AS9 -> 862303.83 | AU9: =ROUND((AT9/AS9)*100,2) -> 31.49 | AW9: 2 | AX9: 1 | AY9: =AU9-AV9-AW9-AX9 -> 28.49
A10: ='AUTO CALCULATION SHEET (2)'!D20 -> 3 CORE X 240 SQ. MM. AL/ARM - WIRE (XLPE) - 22 KV | D10: 44941 | E10: 211937.51 | F10: 753622.95 | G10: 169352 | H10: 152825 | I10: 70250 | J10: =$B$1 -> 44896 | K10: 209522 | L10: 758026 | M10: 169352 | N10: 152825 | O10: 70250 | P10: 2.099 | Q10: 0.1209 | R10: 1.773 | S10: 3.58 | T10: 6.651 | U10: ='AUTO CALCULATION SHEET (2)'!E20 -> 2487463.5 | V10: =(P10*(E10-K10)) -> 5070.1555 | W10: =Q10*(F10-L10) -> -532.32875 | X10: =(R10*(G10-M10)) -> 0 | Y10: =(S10*(H10-N10)) -> 0 | Z10: =(T10*(I10-O10)) -> 0 | AA10: =V10+W10+X10+Y10+Z10 -> 4537.8267 | AB10: =U10+AA10 -> 2492001.3 | AC10: ='AUTO CALCULATION SHEET (2)'!N20 -> 1944 | AD10: ='AUTO CALCULATION SHEET (2)'!Y20 -> 171 | AE10: ='AUTO CALCULATION SHEET (2)'!AD20 -> 449 | AF10: ='AUTO CALCULATION SHEET (2)'!AE20 -> 1394 | AG10: ='AUTO CALCULATION SHEET (2)'!AK20 -> 0 | AH10: ='AUTO CALCULATION SHEET (2)'!AR20 -> 990 | AI10: ='AUTO CALCULATION SHEET (2)'!AV20 -> 0 | AJ10: ='AUTO CALCULATION SHEET (2)'!BA20 -> 5540 | AK10: ='AUTO CALCULATION SHEET (2)'!BF20 -> 1362 | AL10: ='AUTO CALCULATION SHEET (2)'!BL20 -> 1028 | AM10: ='AUTO CALCULATION SHEET (2)'!BP20 -> 87 | AN10: ='AUTO CALCULATION SHEET (2)'!BQ20 -> 33 | AO10: ='AUTO CALCULATION SHEET (2)'!BU20 -> 60 | AP10: ='AUTO CALCULATION SHEET (2)'!BV20 -> 0 | AQ10: =SUMPRODUCT(AC10:AP10,$AC$7:AP$7) -> 1699022 | AR10: ='AUTO CALCULATION SHEET (2)'!CA20 -> 193800 | AS10: =AQ10+AR10 -> 1892822 | AT10: =AB10-AS10 -> 599179.34 | AU10: =ROUND((AT10/AS10)*100,2) -> 31.66 | AW10: 2 | AX10: 1 | AY10: =AU10-AV10-AW10-AX10 -> 28.66
A11: ='AUTO CALCULATION SHEET (2)'!D21 -> 3 CORE X 300 SQ. MM. AL/ARM - WIRE (XLPE) - 11 KV | D11: 44941 | E11: 211937.51 | F11: 753622.95 | G11: 169352 | H11: 152825 | I11: 70250 | J11: =$B$1 -> 44896 | K11: 209522 | L11: 758026 | M11: 169352 | N11: 152825 | O11: 70250 | P11: 2.635 | Q11: 0.1102 | R11: 1.167 | S11: 3.161 | T11: 5.182 | U11: ='AUTO CALCULATION SHEET (2)'!E21 -> 2248076.4 | V11: =(P11*(E11-K11)) -> 6364.8689 | W11: =Q11*(F11-L11) -> -485.21611 | X11: =(R11*(G11-M11)) -> 0 | Y11: =(S11*(H11-N11)) -> 0 | Z11: =(T11*(I11-O11)) -> 0 | AA11: =V11+W11+X11+Y11+Z11 -> 5879.6527 | AB11: =U11+AA11 -> 2253956 | AC11: ='AUTO CALCULATION SHEET (2)'!N21 -> 2430 | AD11: ='AUTO CALCULATION SHEET (2)'!Y21 -> 158 | AE11: ='AUTO CALCULATION SHEET (2)'!AD21 -> 450 | AF11: ='AUTO CALCULATION SHEET (2)'!AE21 -> 838 | AG11: ='AUTO CALCULATION SHEET (2)'!AK21 -> 0 | AH11: ='AUTO CALCULATION SHEET (2)'!AR21 -> 868 | AI11: ='AUTO CALCULATION SHEET (2)'!AV21 -> 0 | AJ11: ='AUTO CALCULATION SHEET (2)'!BA21 -> 4008 | AK11: ='AUTO CALCULATION SHEET (2)'!BF21 -> 1188 | AL11: ='AUTO CALCULATION SHEET (2)'!BL21 -> 881 | AM11: ='AUTO CALCULATION SHEET (2)'!BP21 -> 85 | AN11: ='AUTO CALCULATION SHEET (2)'!BQ21 -> 38 | AO11: ='AUTO CALCULATION SHEET (2)'!BU21 -> 54 | AP11: ='AUTO CALCULATION SHEET (2)'!BV21 -> 0 | AQ11: =SUMPRODUCT(AC11:AP11,$AC$7:AP$7) -> 1544701 | AR11: ='AUTO CALCULATION SHEET (2)'!CA21 -> 171000 | AS11: =AQ11+AR11 -> 1715701 | AT11: =AB11-AS11 -> 538255 | AU11: =ROUND((AT11/AS11)*100,2) -> 31.37 | AW11: 2 | AX11: 1 | AY11: =AU11-AV11-AW11-AX11 -> 28.37
A12: ='AUTO CALCULATION SHEET (2)'!D22 -> 1 CORE X 630 SQ. MM. AL/ARM (XLPE) - 33 KV | D12: 44941 | E12: 211937.51 | F12: 753622.95 | G12: 169352 | H12: 152825 | J12: =$B$1 -> 44896 | K12: 209522 | L12: 758026 | M12: 169352 | N12: 152825 | P12: 2.978 | Q12: 0.063 | R12: 1.265 | S12: 1.168 | U12: ='AUTO CALCULATION SHEET (2)'!E22 -> 1341522.1 | V12: =(P12*(E12-K12)) -> 7193.3888 | W12: =Q12*(F12-L12) -> -277.39215 | X12: =(R12*(G12-M12)) -> 0 | Y12: =(S12*(H12-N12)) -> 0 | Z12: =(T12*(I12-O12)) -> 0 | AA12: =V12+W12+X12+Y12+Z12 -> 6915.9966 | AB12: =U12+AA12 -> 1348438.1 | AC12: ='AUTO CALCULATION SHEET (2)'!N22 -> 1701 | AD12: ='AUTO CALCULATION SHEET (2)'!Y22 -> 85 | AE12: ='AUTO CALCULATION SHEET (2)'!AD22 -> 237 | AF12: ='AUTO CALCULATION SHEET (2)'!AE22 -> 1055 | AG12: ='AUTO CALCULATION SHEET (2)'!AK22 -> 18 | AH12: ='AUTO CALCULATION SHEET (2)'!AR22 -> 200 | AI12: ='AUTO CALCULATION SHEET (2)'!AV22 -> 842 | AJ12: ='AUTO CALCULATION SHEET (2)'!BA22 -> 0 | AK12: ='AUTO CALCULATION SHEET (2)'!BF22 -> 762 | AL12: ='AUTO CALCULATION SHEET (2)'!BL22 -> 0 | AM12: ='AUTO CALCULATION SHEET (2)'!BP22 -> 45 | AN12: ='AUTO CALCULATION SHEET (2)'!BQ22 -> 26 | AO12: ='AUTO CALCULATION SHEET (2)'!BU22 -> 41 | AP12: ='AUTO CALCULATION SHEET (2)'!BV22 -> 0 | AQ12: =SUMPRODUCT(AC12:AP12,$AC$7:AP$7) -> 985014 | AR12: ='AUTO CALCULATION SHEET (2)'!CA22 -> 53200 | AS12: =AQ12+AR12 -> 1038214 | AT12: =AB12-AS12 -> 310224.1 | AU12: =ROUND((AT12/AS12)*100,2) -> 29.88 | AW12: 2 | AX12: 1 | AY12: =AU12-AV12-AW12-AX12 -> 26.88
A13: ='AUTO CALCULATION SHEET (2)'!D23 -> 1 CORE X 185 SQ. MM. AL/ARM - WIRE (XLPE) - 22 KV | D13: 44941 | E13: 211937.51 | F13: 753622.95 | G13: 169352 | H13: 152825 | J13: =$B$1 -> 44896 | K13: 209522 | L13: 758026 | M13: 169352 | N13: 152825 | P13: 0.965 | Q13: 0.0375 | R13: 0.518 | S13: 0.539 | U13: ='AUTO CALCULATION SHEET (2)'!E23 -> 591984.01 | V13: =(P13*(E13-K13)) -> 2330.9672 | W13: =Q13*(F13-L13) -> -165.11438 | X13: =(R13*(G13-M13)) -> 0 | Y13: =(S13*(H13-N13)) -> 0 | Z13: =(T13*(I13-O13)) -> 0 | AA13: =V13+W13+X13+Y13+Z13 -> 2165.8528 | AB13: =U13+AA13 -> 594149.87 | AC13: ='AUTO CALCULATION SHEET (2)'!N23 -> 499 | AD13: ='AUTO CALCULATION SHEET (2)'!Y23 -> 53 | AE13: ='AUTO CALCULATION SHEET (2)'!AD23 -> 139 | AF13: ='AUTO CALCULATION SHEET (2)'!AE23 -> 428 | AG13: ='AUTO CALCULATION SHEET (2)'!AK23 -> 12 | AH13: ='AUTO CALCULATION SHEET (2)'!AR23 -> 93 | AI13: ='AUTO CALCULATION SHEET (2)'!AV23 -> 415 | AJ13: ='AUTO CALCULATION SHEET (2)'!BA23 -> 0 | AK13: ='AUTO CALCULATION SHEET (2)'!BF23 -> 371 | AL13: ='AUTO CALCULATION SHEET (2)'!BL23 -> 0 | AM13: ='AUTO CALCULATION SHEET (2)'!BP23 -> 27 | AN13: ='AUTO CALCULATION SHEET (2)'!BQ23 -> 11 | AO13: ='AUTO CALCULATION SHEET (2)'!BU23 -> 27 | AP13: ='AUTO CALCULATION SHEET (2)'!BV23 -> 0 | AQ13: =SUMPRODUCT(AC13:AP13,$AC$7:AP$7) -> 415791 | AR13: ='AUTO CALCULATION SHEET (2)'!CA23 -> 41800 | AS13: =AQ13+AR13 -> 457591 | AT13: =AB13-AS13 -> 136558.87 | AU13: =ROUND((AT13/AS13)*100,2) -> 29.84 | AW13: 2 | AX13: 1 | AY13: =AU13-AV13-AW13-AX13 -> 26.84
