Workbook

Sheet Sheet1
A1: DOCKET NO. | B1: Base Date | C1: ITEM CODE | D1: PROPOSE ERP ITEM NAME | E1: Propose Drum Type | F1: Insulation Screening(Metallic) | G1: RM Rate(Insulation Screening(Metallic)) | H1: Weight (Insulation Screening (Metallic)) | I1: Cost Insulation Screening(Metallic) | J1: Conductor | K1: RM Rate(Conductor) | L1: Weight(Conductor) | M1: Cost(Conductor) | N1: AL ALLOY | O1: RM Rate(AL Alloy) | P1: Weight(Al Alloy) | Q1: Cost(AL Alloy) | R1: Insulation Screening(Non-Metallic) | S1: RM Rate(Insulation Screening(Non-Metallic)) | T1: Weight(Insulation Screening(Non-Metallic) | U1: Cost(Insulation Screening(Non-Metallic) | V1: Insulation | W1: RM Rate(Insulation) | X1: Weight(Insulation) | Y1: Cost(Insulation) | Z1: Poly Tape | AA1: RM Rate(Poly Tape) | AB1: Weight(Poly Tape) | AC1: Cost(Poly Tape) | AD1: Inner Sheath | AE1: RM Rate(Inner Sheath) | AF1: Weight(Inner Sheath) | AG1: Cost(Inner Sheath) | AH1: Armouring | AI1: RM Rate(Armouring) | AJ1: Weight(Armouring) | AK1: Cost(Armouring) | AL1: Outer Sheath | AM1: RM Rate(Outer Sheath) | AN1: Weight(Outer Sheath) | AO1: Cost(Outer Sheath) | AP1: Filler | AQ1: RM Rate(Filler) | AR1: Weight(Filler) | AS1: Cost(Filler) | AT1: Grease | AU1: RM Rate(Grease) | AV1: Weight(Grease) | AW1: Cost(Grease) | AX1: Water Swellable Tape | AY1: RM Rate(Water Swellable Tape) | AZ1: Weight(Water Swellable Tape) | BA1: Cost(Water Swellable Tape) | BB1: Semi Conducting Water Swellable Tape | BC1: RM Rate(Semi Conducting Water Swellable Tape) | BD1: Weight(Semi Conducting Water Swellable Tape) | BE1: Cost(Semi Conducting Water Swellable Tape) | BF1: Semicon Tape | BG1: RM Rate(Semicon Tape) | BH1: Weight(Semicon Tape) | BI1: Cost(Semicon Tape) | BJ1: Glass Fiber Tape | BK1: RM Rate(Glass Fiber Tape) | BL1: Weight(Glass Fiber Tape) | BM1: Cost(Glass Fiber Tape) | BN1: Copper Wire 0.8MM | BO1: RM Rate(Copper Wire 0.8MM) | BP1: Weight(Copper Wire 0.8MM) | BQ1: Cost(Copper Wire 0.8MM) | BR1: Rubberized Cotton Tape | BS1: RM Rate(Rubberized Cotton Tape) | BT1: Weight(Rubberized Cotton Tape) | BU1: Cost(Rubberized Cotton Tape) | BV1: Water Tight Compound | BW1: RM Rate(Water Tight Compound) | BX1: Weight(Water Tight Compound) | BY1: Cost(Water Tight Compound) | BZ1: Drum Cost Per KM | CA1: Total RM Cost | CB1: FIRM % | CC1: Firm Value | CD1: MFG% | CE1: MFG Value | CF1: PROF% | CG1: Profit Value | CH1: 1st EX-Works | CI1: Intt % | CJ1: Intt Value | CK1: insp% | CL1: Insp Value | CM1: TTR CHARGES% | CN1: TTR Value | CO1: EX-Works Per KM | CP1: Freight Per KM | CQ1: Price Including Freight Per KM | CR1: GST % | CS1: GST Value | CT1: Price Including GST & Freight Per KM | CU1: QTY | CV1: Unit | CW1: Total Price Of Full QTY(Including Freight&GST) | CX1: PARTY LENGTH (IF STANDER LENGTH NOT MATCH WITH PAR | CY1: DRUM CODE | CZ1: DRUM SIZE (FxbXtx Ft)
A2: ENQ-16887-25-26 | C2: FA0200008 | D2: 2 CORE X 2.5 SQ. MM. CU/ARD - WIRE (PVC) | E2: WOOD | H2: 0 | J2: Copper | L2: 44 | P2: 0 | T2: 0 | V2: Type A PVC | X2: 26 | Z2: POLY TAPE | AB2: 3 | AD2: FR PVC Type ST-1 | AF2: 39 | AH2: Galvanised Steel Round Wire | AJ2: 251 | AL2: FRLSH PVC Type ST-1 | AN2: 93 | AR2: 0 | AV2: 0 | AZ2: 0 | BD2: 0 | BH2: 0 | BL2: 16 | BP2: 0 | BT2: 0 | BX2: 0 | BZ2: 4260 | CA2: 4260 | CH2: 4260 | CO2: 4260 | CQ2: 4260 | CR2: 0.18 | CS2: 766.8 | CT2: 5026.8 | CU2: 2 | CV2: KMS | CW2: 10054 | CX2: 500 | CY2: MD0100003 | CZ2: DRUM - 28 X 14 X 23 X 2
A3: ENQ-16887-25-26 | C3: FA0200009 | D3: 3 CORE X 2.5 SQ. MM. CU/ARD - WIRE (PVC) | E3: WOOD | H3: 0 | J3: Copper | L3: 67 | P3: 0 | T3: 0 | V3: Type A PVC | X3: 39 | Z3: POLY TAPE | AB3: 3 | AD3: FR PVC Type ST-1 | AF3: 20 | AH3: Galvanised Steel Round Wire | AJ3: 264 | AL3: FRLSH PVC Type ST-1 | AN3: 97 | AR3: 0 | AV3: 0 | AZ3: 0 | BD3: 0 | BH3: 0 | BL3: 17 | BP3: 0 | BT3: 0 | BX3: 0 | BZ3: 4260 | CA3: 4260 | CH3: 4260 | CO3: 4260 | CQ3: 4260 | CR3: 0.18 | CS3: 766.8 | CT3: 5026.8 | CU3: 13 | CV3: KMS | CW3: 65348 | CX3: 500 | CY3: MD0100003 | CZ3: DRUM - 28 X 14 X 23 X 2
A4: ENQ-16887-25-26 | C4: FA0200016 | D4: 5 CORE X 2.5 SQ. MM. CU/ARD - WIRE (PVC) | E4: WOOD | H4: 0 | J4: Copper | L4: 111 | P4: 0 | T4: 0 | V4: Type A PVC | X4: 65 | Z4: POLY TAPE | AB4: 4 | AD4: FR PVC Type ST-1 | AF4: 28 | AH4: Galvanised Steel Round Wire | AJ4: 314 | AL4: FRLSH PVC Type ST-1 | AN4: 112 | AR4: 0 | AV4: 0 | AZ4: 0 | BD4: 0 | BH4: 0 | BL4: 0 | BP4: 0 | BT4: 0 | BX4: 0 | BZ4: 3946 | CA4: 3946 | CH4: 3946 | CO4: 3946 | CQ4: 3946 | CR4: 0.18 | CS4: 710.28 | CT4: 4656.28 | CU4: 11 | CV4: KMS | CW4: 51219 | CX4: 500 | CY4: MD0100004 | CZ4: DRUM - 28 X 10 X 23 X 2
A5: ENQ-16887-25-26 | C5: FA0200073 | D5: 19 CORE X 2.5 SQ. MM. CU/ARD - WIRE (PVC) | E5: WOOD | H5: 0 | J5: Copper | L5: 422 | P5: 0 | T5: 0 | V5: Type A PVC | X5: 247 | Z5: POLY TAPE | AB5: 7 | AD5: FR PVC Type ST-1 | AF5: 48 | AH5: Galvanised Steel Round Wire | AJ5: 607 | AL5: FRLSH PVC Type ST-1 | AN5: 195 | AR5: 0 | AV5: 0 | AZ5: 0 | BD5: 0 | BH5: 0 | BL5: 33 | BP5: 0 | BT5: 0 | BX5: 0 | BZ5: 8626 | CA5: 8626 | CH5: 8626 | CO5: 8626 | CQ5: 8626 | CR5: 0.18 | CS5: 1552.68 | CT5: 10178.68 | CU5: 14 | CV5: KMS | CW5: 142502 | CX5: 500 | CY5: MD0100075 | CZ5: DRUM - 42 X 15 X 23 X 2
A6: ENQ-16887-25-26 | C6: FA0700002 | D6: 1 CORE X 630 SQ. MM. AL/ARD (XLPE) | E6: WOOD | H6: 0 | J6: Alumimium | L6: 1701 | P6: 0 | T6: 0 | V6: LT-XLPE | X6: 295 | AB6: 0 | AF6: 0 | AH6: Aluminium Round Wire | AJ6: 431 | AL6: FRLSH PVC Type ST-2 | AN6: 443 | AR6: 0 | AV6: 0 | AZ6: 0 | BD6: 0 | BH6: 0 | BL6: 0 | BP6: 0 | BT6: 0 | BX6: 0 | BZ6: 18852 | CA6: 18852 | CH6: 18852 | CO6: 18852 | CQ6: 18852 | CR6: 0.18 | CS6: 3393.36 | CT6: 22245.36 | CU6: 7 | CV6: KMS | CW6: 155718 | CX6: 500 | CY6: MD0100076 | CZ6: DRUM - 62 X 25 X 32 X 3
A7: ENQ-16887-25-26 | C7: FA0700008 | D7: 1 CORE X 300 SQ. MM. AL/ARD. (XLPE) | E7: WOOD | H7: 0 | J7: Alumimium | L7: 810 | P7: 0 | T7: 0 | V7: LT-XLPE | X7: 154 | AB7: 0 | AF7: 0 | AH7: Aluminium Round Wire | AJ7: 238 | AL7: FRLSH PVC Type ST-2 | AN7: 259 | AR7: 0 | AV7: 0 | AZ7: 0 | BD7: 0 | BH7: 0 | BL7: 0 | BP7: 0 | BT7: 0 | BX7: 0 | BZ7: 13372 | CA7: 13372 | CH7: 13372 | CO7: 13372 | CQ7: 13372 | CR7: 0.18 | CS7: 2406.96 | CT7: 15778.96 | CU7: 7 | CV7: KMS | CW7: 110453 | CX7: 500 | CY7: MD0100017 | CZ7: DRUM - 52 X 18 X 36 X 2.5
A8: ENQ-16887-25-26 | C8: FA0700009 | D8: 1 CORE X 150 SQ. MM. ALU/ARD (XLPE) | E8: WOOD | H8: 0 | J8: Alumimium | L8: 405 | P8: 0 | T8: 0 | V8: LT-XLPE | X8: 93 | AB8: 0 | AF8: 0 | AH8: Aluminium Round Wire | AJ8: 175 | AL8: FRLSH PVC Type ST-2 | AN8: 180 | AR8: 0 | AV8: 0 | AZ8: 0 | BD8: 0 | BH8: 0 | BL8: 0 | BP8: 0 | BT8: 0 | BX8: 0 | BZ8: 9734 | CA8: 9734 | CH8: 9734 | CO8: 9734 | CQ8: 9734 | CR8: 0.18 | CS8: 1752.12 | CT8: 11486.12 | CU8: 10 | CV8: KMS | CW8: 114861 | CX8: 500 | CY8: MD0100014 | CZ8: DRUM - 48 X 21 X 32 X 2.25
A9: ENQ-16887-25-26 | C9: FA0900019 | D9: 2 CORE X 6 SQ. MM. AL/ARD - WIRE (PVC) | E9: WOOD | H9: 0 | J9: Alumimium | L9: 32 | P9: 0 | T9: 0 | V9: Type A PVC | X9: 44 | AB9: 0 | AD9: FR PVC Type ST-1 | AF9: 68 | AH9: Galvanised Steel Round Wire | AJ9: 314 | AL9: FRLSH PVC Type ST-1 | AN9: 118 | AR9: 0 | AV9: 0 | AZ9: 0 | BD9: 0 | BH9: 0 | BL9: 20 | BP9: 0 | BT9: 0 | BX9: 0 | BZ9: 3946 | CA9: 3946 | CH9: 3946 | CO9: 3946 | CQ9: 3946 | CR9: 0.18 | CS9: 710.28 | CT9: 4656.28 | CU9: 4 | CV9: KMS | CW9: 18625 | CX9: 500 | CY9: MD0100004 | CZ9: DRUM - 28 X 10 X 23 X 2
A10: ENQ-16887-25-26 | C10: FA1100007 | D10: 3.5 CORE X 70 SQ. MM. AL/ARD - STRIP (PVC) | E10: WOOD | H10: 0 | J10: Alumimium | L10: 662 | P10: 0 | T10: 0 | V10: Type A PVC | X10: 250 | AB10: 0 | AD10: FR PVC Type ST-1 | AF10: 76 | AH10: Galvanised Steel Flat Strip | AJ10: 476 | AL10: FRLSH PVC Type ST-1 | AN10: 262 | AR10: 0 | AV10: 0 | AZ10: 0 | BD10: 0 | BH10: 0 | BL10: 43 | BP10: 0 | BT10: 0 | BX10: 0 | BZ10: 15806 | CA10: 15806 | CH10: 15806 | CO10: 15806 | CQ10: 15806 | CR10: 0.18 | CS10: 2845.08 | CT10: 18651.08 | CU10: 17 | CV10: KMS | CW10: 317068 | CX10: 500 | CY10: MD0100018 | CZ10: DRUM - 54 X 24 X 35 X 3
A11: ENQ-16887-25-26 | C11: FA1100085 | D11: 3.5 CORE X 300 SQ. MM. AL/ARD - WIRE (XLPE) | E11: WOOD | H11: 0 | J11: Alumimium | L11: 2835 | P11: 0 | T11: 0 | V11: LT-XLPE | X11: 430 | AB11: 0 | AD11: FR PVC Type ST-2 | AF11: 245 | AH11: Galvanised Steel Round Wire | AJ11: 2852 | AL11: FRLSH PVC Type ST-2 | AN11: 754 | AR11: 0 | AV11: 0 | AZ11: 0 | BD11: 0 | BH11: 0 | BL11: 0 | BP11: 0 | BT11: 0 | BX11: 0 | BZ11: 50240 | CA11: 50240 | CH11: 50240 | CO11: 50240 | CQ11: 50240 | CR11: 0.18 | CS11: 9043.2 | CT11: 59283.2 | CU11: 17 | CV11: KMS | CW11: 1007814 | CX11: 500 | CY11: MD0100079 | CZ11: DRUM - 80 X 35 X 39 X 3
A12: ENQ-16887-25-26 | C12: FA1100106 | D12: 3.5 CORE X 150 SQ. MM. AL/ARD - WIRE (XLPE) | E12: WOOD | H12: 0 | J12: Alumimium | L12: 1404 | P12: 0 | T12: 0 | V12: LT-XLPE | X12: 244 | AB12: 0 | AD12: FR PVC Type ST-2 | AF12: 124 | AH12: Galvanised Steel Round Wire | AJ12: 1312 | AL12: FRLSH PVC Type ST-2 | AN12: 416 | AR12: 0 | AV12: 0 | AZ12: 0 | BD12: 0 | BH12: 0 | BL12: 0 | BP12: 0 | BT12: 0 | BX12: 0 | BZ12: 20094 | CA12: 20094 | CH12: 20094 | CO12: 20094 | CQ12: 20094 | CR12: 0.18 | CS12: 3616.92 | CT12: 23710.92 | CU12: 14 | CV12: KMS | CW12: 331953 | CX12: 500 | CY12: MD0100070 | CZ12: DRUM - 68 X 24 X 32 X 3
A13: ENQ-16887-25-26 | C13: FA1100107 | D13: 3.5 CORE X 95 SQ. MM. AL/ARD - WIRE (XLPE) | E13: WOOD | H13: 0 | J13: Alumimium | L13: 904 | P13: 0 | T13: 0 | V13: LT-XLPE | X13: 157 | AB13: 0 | AD13: FR PVC Type ST-2 | AF13: 86 | AH13: Galvanised Steel Round Wire | AJ13: 1060 | AL13: FRLSH PVC Type ST-2 | AN13: 328 | AR13: 0 | AV13: 0 | AZ13: 0 | BD13: 0 | BH13: 0 | BL13: 0 | BP13: 0 | BT13: 0 | BX13: 0 | BZ13: 14898 | CA13: 14898 | CH13: 14898 | CO13: 14898 | CQ13: 14898 | CR13: 0.18 | CS13: 2681.64 | CT13: 17579.64 | CU13: 13 | CV13: KMS | CW13: 228535 | CX13: 500 | CY13: MD0100019 | CZ13: DRUM - 54 X 24 X 32 X 3

Sheet AUTO CALCULATION SHEET (2)
N1: Conductor | V1: AL ALLOY | X1: Insulation Screening (Metallic) | AF1: Insulation Screening (Non-Metallic) | AH1: Insulation | AQ1: POLY TAPE | AR1: Inner Sheath | BA1: Armouring | BL1: Outer Sheath | BX1: FILLER | BY1: GREASE | BZ1: Water swellable Tape | CA1: Semi conducting Water Swellable tape | CB1: SEMICON TAPE | CC1: GLASS FIBER TAPE | CD1: COPPER WIRE 0.8 MM | CE1: RUBBERIZED COTTON TAPE | CF1: Water Tight Compound | CG1: DRUM TYPE | CK1: DRUM COST PER KM | CL1: TOTAL RM COST | CM1: EXTRA CONSUMPTION | CN1: EXTRA CONSUMPTION VALUE | CZ1: $A$1
A2: DOCKET NO. | B2: BASE DATE | C2: ITEM CODE | D2: PROPOSE ERP ITEM NAME | E2: EX-WORKS (PER KM) | F2: FREIGHT PER KM | G2: PRICE INCLUDING FREIGHT (PER KM) | H2: GST % | I2: GST VALUE | J2: PRICE INCLUDING GST & FREIGHT (PER KM) | K2: QTY | L2: Unit | M2: TOTAL PRICE OF FULL QTY (INCLUDING FRIGHT & GST) | N2: Alumimium | O2: Alumimium ALLOY | P2: Copper | Q2: AL-59 | R2: AL-4 | S2: AL-7 | T2: Flexible Copper | U2: Galvanized steel wire | V2: Alumimium | W2: Alumimium ALLOY | X2: Coper tape - 0.1 mm | Y2: Copper Tape - 0.03 mm | Z2: Copper Tape - 0.035 mm | AA2: Copper Tape - 0.04 mm | AB2: Copper Tape - 0.045 mm | AC2: Copper Tape - 0.050 mm | AD2: Copper Tape - 0.060 mm | AE2: Copper Tape - 0.075 mm(DOUBLE) | AF2: Extruded semiconductive | AG2: Extruded Semiconductive(Stripable) | AH2: HT-XLPE | AI2: LT-XLPE | AJ2: TR XLPE | AK2: Type A PVC | AL2: Type C PVC (HR) | AM2: Type A PVC-1.45 | AN2: Type A PVC-FR | AO2: Type A PVC-FRLS | AP2: Type A PVC-1.38 | AQ2: POLY TAPE | AR2: FR PVC Type ST-1 | AS2: FR PVC Type ST-2 | AT2: FRLSH PVC Type ST-1 | AU2: FRLSH PVC Type ST-2 | AV2: PVC Type ST-1 | AW2: PVC Type ST-1-PRESSURE EXTRUDED | AX2: PVC Type ST-2 | AY2: PVC COMPOUND 1.48 | AZ2: PVC Type ST-2-PRESSURE EXTRUDED | BA2: ACSR CORE WIRE | BB2: ACSR DOG STEEL WIRE | BC2: Aluminium Flat Strip | BD2: Aluminium Round Wire | BE2: Alumimium Tape | BF2: Double Steel Tape | BG2: Galvanised Steel Flat Strip | BH2: Galvanised Steel Flat Strip (Double) | BI2: Galvanised Steel Flat Strip-B | BJ2: Galvanised Steel Round Wire | BK2: Galvanised Steel Round Wire (Double) | BL2: FR PVC Type ST-1 | BM2: FR PVC Type ST-2 | BN2: FRLSH PVC Type ST-1 | BO2: FRLSH PVC Type ST-2 | BP2: ZHFR | BQ2: PE-ST-3 | BR2: PE-ST-7 | BS2: PVC Type ST-1 | BT2: PVC Type ST-2 | BU2: PVC COMPOUND 1.48 | BV2: PVC Type ST-2-PRESSURE EXTRUDED | BW2: UV & Track Resistant XLPE | BX2: FILLER | BY2: Grease | BZ2: Water swellable Tape | CA2: Semi conducting Water Swellable tape | CB2: SEMICON TAPE | CC2: GLASS FIBER TAPE | CD2: COPPER WIRE 0.8 MM | CE2: RUBBERIZED COTTON TAPE | CF2: Water Tight Compound | CG2: PROPOSE DRUM TYPE | CH2: DRUM CODE | CI2: DRUM SIZE (FxbXtx Ft) | CJ2: PARTY STANDARD LENGTH (MTR) | CO2: MFG% | CP2: MFG VALUE | CQ2: PROF% | CR2: PROFIT VALUE | CS2: 1ST EX-WORKS | CT2: Intt % | CU2: INTT VALUE | CV2: insp% | CW2: INSP VALUE | CX2: TTR Charges% | CY2: TTR Charges VALUE | DA2: LP JULY 25 | DB2: PVC | DC2: FRLS | DD2: WIRE ARM | DE2: TOTAL | DF2: DISC %
N3: 269 | O3: =+IFERROR(VLOOKUP($O$2,Sheet1!J:L,2,0),0) -> 0 | P3: 929 | Q3: =+IFERROR(VLOOKUP($Q$2,Sheet1!J:M,2,0),0) -> 0 | R3: =+IFERROR(VLOOKUP($R$2,Sheet1!J:M,2,0),0) -> 0 | S3: =+IFERROR(VLOOKUP($S$2,Sheet1!J:M,2,0),0) -> 0 | T3: =+IFERROR(VLOOKUP($T$2,Sheet1!J:M,2,0),0) -> 0 | U3: =+IFERROR(VLOOKUP($U$2,Sheet1!J:M,2,0),0) -> 0 | V3: =+IFERROR(VLOOKUP($V$2,Sheet1!N:Q,2,0),0) -> 0 | W3: =+IFERROR(VLOOKUP($W$2,Sheet1!N:O,2,0),0) -> 0 | X3: =+IFERROR(VLOOKUP($X$2,Sheet1!F:I,2,0),0) -> 0 | Y3: =+IFERROR(VLOOKUP($Y$2,Sheet1!F:I,2,0),0) -> 0 | Z3: =+IFERROR(VLOOKUP($Z$2,Sheet1!F:I,2,0),0) -> 0 | AA3: =+IFERROR(VLOOKUP($AA$2,Sheet1!F:I,2,0),0) -> 0 | AB3: =+IFERROR(VLOOKUP($AB$2,Sheet1!F:I,2,0),0) -> 0 | AC3: =+IFERROR(VLOOKUP($AC$2,Sheet1!F:I,2,0),0) -> 0 | AD3: =+IFERROR(VLOOKUP($AD$2,Sheet1!F:I,2,0),0) -> 0 | AE3: =+IFERROR(VLOOKUP($AE$2,Sheet1!F:I,2,0),0) -> 0 | AF3: =+IFERROR(VLOOKUP($AF$2,Sheet1!R:U,2,0),0) -> 0 | AG3: =+IFERROR(VLOOKUP($AG$2,Sheet1!R:U,2,0),0) -> 0 | AH3: =+IFERROR(VLOOKUP($AH$2,Sheet1!V:Y,2,0),0) -> 0 | AI3: 111 | AJ3: =+IFERROR(VLOOKUP($AJ$2,Sheet1!V:Y,2,0),0) -> 0 | AK3: 65 | AL3: =+IFERROR(VLOOKUP($AL$2,Sheet1!V:Y,2,0),0) -> 0 | AM3: =+IFERROR(VLOOKUP($AM$2,Sheet1!V:Y,2,0),0) -> 0 | AN3: =+IFERROR(VLOOKUP($AN$2,Sheet1!V:Y,2,0),0) -> 0 | AO3: =+IFERROR(VLOOKUP($AO$2,Sheet1!V:Y,2,0),0) -> 0 | AP3: =+IFERROR(VLOOKUP($AP$2,Sheet1!V:Y,2,0),0) -> 0 | AQ3: 108 | AR3: 79 | AS3: 79 | AT3: =+IFERROR(VLOOKUP($AT$2,Sheet1!AD2:AG840,2,0),0) -> 0 | AU3: =+IFERROR(VLOOKUP($AU$2,Sheet1!AD2:AG840,2,0),0) -> 0 | AV3: =+IFERROR(VLOOKUP($AV$2,Sheet1!AD2:AG840,2,0),0) -> 0 | AW3: =+IFERROR(VLOOKUP($AW$2,Sheet1!AD2:AG840,2,0),0) -> 0 | AX3: =+IFERROR(VLOOKUP($AX$2,Sheet1!AD2:AG840,2,0),0) -> 0 | AY3: =+IFERROR(VLOOKUP($AY$2,Sheet1!AD2:AG840,2,0),0) -> 0 | AZ3: =+IFERROR(VLOOKUP($AZ$2,Sheet1!AD2:AG840,2,0),0) -> 0 | BA3: =+IFERROR(VLOOKUP($BA$2,Sheet1!AH2:AK840,2,0),0) -> 0 | BB3: =+IFERROR(VLOOKUP($BB$2,Sheet1!AH2:AK840,2,0),0) -> 0 | BC3: =+IFERROR(VLOOKUP($BC$2,Sheet1!AH2:AK840,2,0),0) -> 0 | BD3: 274 | BE3: =+IFERROR(VLOOKUP($BE$2,Sheet1!AH2:AK840,2,0),0) -> 0 | BF3: =+IFERROR(VLOOKUP($BF$2,Sheet1!AH2:AK840,2,0),0) -> 0 | BG3: 75 | BH3: =+IFERROR(VLOOKUP($BH$2,Sheet1!AH2:AK840,2,0),0) -> 0 | BI3: =+IFERROR(VLOOKUP($BI$2,Sheet1!AH2:AK840,2,0),0) -> 0 | BJ3: 79 | BK3: =+IFERROR(VLOOKUP($BK$2,Sheet1!AH2:AK840,2,0),0) -> 0 | BL3: =+IFERROR(VLOOKUP($BL$2,Sheet1!AL2:AO840,2,0),0) -> 0 | BM3: =+IFERROR(VLOOKUP($BM$2,Sheet1!AL2:AO840,2,0),0) -> 0 | BN3: 123 | BO3: 123 | BP3: =+IFERROR(VLOOKUP($BP$2,Sheet1!AL2:AO840,2,0),0) -> 0 | BQ3: =+IFERROR(VLOOKUP($BQ$2,Sheet1!AL2:AO840,2,0),0) -> 0 | BR3: =+IFERROR(VLOOKUP($BR$2,Sheet1!AL2:AO840,2,0),0) -> 0 | BS3: =+IFERROR(VLOOKUP($BS$2,Sheet1!AL2:AO840,2,0),0) -> 0 | BT3: =+IFERROR(VLOOKUP($BT$2,Sheet1!AL2:AO840,2,0),0) -> 0 | BU3: =+IFERROR(VLOOKUP($BU$2,Sheet1!AL2:AO840,2,0),0) -> 0 | BV3: =+IFERROR(VLOOKUP($BV$2,Sheet1!AL2:AO840,2,0),0) -> 0 | BW3: =+IFERROR(VLOOKUP($BW$2,Sheet1!AL2:AO840,2,0),0) -> 0 | BX3: =+IFERROR(VLOOKUP($BX$2,Sheet1!AP2:AS840,2,0),0) -> 0 | BY3: =+IFERROR(VLOOKUP($BY$2,Sheet1!AT2:AW840,2,0),0) -> 0 | BZ3: =+IFERROR(VLOOKUP($BZ$2,Sheet1!AX2:BA840,2,0),0) -> 0 | CA3: =+IFERROR(VLOOKUP($CA$2,Sheet1!BB2:BE840,2,0),0) -> 0 | CB3: =+IFERROR(VLOOKUP($CB$2,Sheet1!BF2:BI840,2,0),0) -> 0 | CC3: =+IFERROR(VLOOKUP($CC$2,Sheet1!BJ2:BM840,2,0),0) -> 0 | CD3: =+IFERROR(VLOOKUP($CD$2,Sheet1!BN2:BQ840,2,0),0) -> 0 | CE3: =+IFERROR(VLOOKUP($CE$2,Sheet1!BR2:BU840,2,0),0) -> 0 | CF3: =+IFERROR(VLOOKUP($CF$2,Sheet1!BV2:BY840,2,0),0) -> 0
A4: =Sheet1!A2 -> ENQ-16887-25-26 | B4: 45902 | C4: =Sheet1!C2 -> FA0200008 | D4: =Sheet1!D2 -> 2 CORE X 2.5 SQ. MM. CU/ARD - WIRE (PVC) | E4: =CS4+CU4+CW4+CY4 -> 96370.59 | F4: =ROUNDUP(M22,0) -> 22500 | G4: =E4+F4 -> 118870.59 | H4: =Sheet1!CR2 -> 0.18 | I4: =G4*H4 -> 21396.706 | J4: =G4+I4 -> 140267.3 | K4: =Sheet1!CU2 -> 2 | L4: =Sheet1!CV2 -> KMS | M4: =J4*K4 -> 280534.59 | N4: =+IFERROR(VLOOKUP($N$2,Sheet1!J2:L2,3,0),0) -> 0 | O4: =+IFERROR(VLOOKUP($O$2,Sheet1!J2:L2,3,0),0) -> 0 | P4: =+IFERROR(VLOOKUP($P$2,Sheet1!J2:M2,3,0),0) -> 44 | Q4: =+IFERROR(VLOOKUP($Q$2,Sheet1!J2:M2,3,0),0) -> 0 | R4: =+IFERROR(VLOOKUP($R$2,Sheet1!J2:M2,3,0),0) -> 0 | S4: =+IFERROR(VLOOKUP($S$2,Sheet1!J2:M2,3,0),0) -> 0 | T4: =+IFERROR(VLOOKUP($T$2,Sheet1!J2:M2,3,0),0) -> 0 | U4: =+IFERROR(VLOOKUP($U$2,Sheet1!J2:M2,3,0),0) -> 0 | V4: =+IFERROR(VLOOKUP($V$2,Sheet1!N2:Q2,3,0),0) -> 0 | W4: =+IFERROR(VLOOKUP($W$2,Sheet1!N2:Q2,3,0),0) -> 0 | X4: =+IFERROR(VLOOKUP($X$2,Sheet1!F2:I2,3,0),0) -> 0 | Y4: =+IFERROR(VLOOKUP($Y$2,Sheet1!F2:I2,3,0),0) -> 0 | Z4: =+IFERROR(VLOOKUP($Z$2,Sheet1!F2:I2,3,0),0) -> 0 | AA4: =+IFERROR(VLOOKUP($AA$2,Sheet1!F2:I2,3,0),0) -> 0 | AB4: =+IFERROR(VLOOKUP($AB$2,Sheet1!F2:I2,3,0),0) -> 0 | AC4: =+IFERROR(VLOOKUP($AC$2,Sheet1!F2:I2,3,0),0) -> 0 | AD4: =+IFERROR(VLOOKUP($AD$2,Sheet1!F2:I2,3,0),0) -> 0 | AE4: =+IFERROR(VLOOKUP($AE$2,Sheet1!F2:I2,3,0),0) -> 0 | AF4: =+IFERROR(VLOOKUP($AF$2,Sheet1!R2:U2,3,0),0) -> 0 | AG4: =+IFERROR(VLOOKUP($AG$2,Sheet1!R2:U2,3,0),0) -> 0 | AH4: =+IFERROR(VLOOKUP($AH$2,Sheet1!V2:Y2,3,0),0) -> 0 | AI4: =+IFERROR(VLOOKUP($AI$2,Sheet1!V2:Y2,3,0),0) -> 0 | AJ4: =+IFERROR(VLOOKUP($AJ$2,Sheet1!V2:Y2,3,0),0) -> 0 | AK4: =+IFERROR(VLOOKUP($AK$2,Sheet1!V2:Y2,3,0),0) -> 26 | AL4: =+IFERROR(VLOOKUP($AL$2,Sheet1!V2:Y2,3,0),0) -> 0 | AM4: =+IFERROR(VLOOKUP($AM$2,Sheet1!V2:Y2,3,0),0) -> 0 | AN4: =+IFERROR(VLOOKUP($AN$2,Sheet1!V2:Y2,3,0),0) -> 0 | AO4: =+IFERROR(VLOOKUP($AO$2,Sheet1!V2:Y2,3,0),0) -> 0 | AP4: =+IFERROR(VLOOKUP($AP$2,Sheet1!V2:Y2,3,0),0) -> 0 | AQ4: =+IFERROR(VLOOKUP($AQ$2,Sheet1!Z2:AB2,3,0),0) -> 3 | AR4: =+IFERROR(VLOOKUP($AR$2,Sheet1!AD2:AG2,3,0),0) -> 39 | AS4: =+IFERROR(VLOOKUP($AS$2,Sheet1!AD2:AG2,3,0),0) -> 0 | AT4: =+IFERROR(VLOOKUP($AT$2,Sheet1!AD2:AG2,3,0),0) -> 0 | AU4: =+IFERROR(VLOOKUP($AU$2,Sheet1!AD2:AG2,3,0),0) -> 0 | AV4: =+IFERROR(VLOOKUP($AV$2,Sheet1!AD2:AG2,3,0),0) -> 0 | AW4: =+IFERROR(VLOOKUP($AW$2,Sheet1!AD2:AG2,3,0),0) -> 0 | AX4: =+IFERROR(VLOOKUP($AX$2,Sheet1!AD2:AG2,3,0),0) -> 0 | AY4: =+IFERROR(VLOOKUP($AY$2,Sheet1!AD2:AG2,3,0),0) -> 0 | AZ4: =+IFERROR(VLOOKUP($AZ$2,Sheet1!AD2:AG2,3,0),0) -> 0 | BA4: =+IFERROR(VLOOKUP($BA$2,Sheet1!AH2:AK2,3,0),0) -> 0 | BB4: =+IFERROR(VLOOKUP($BB$2,Sheet1!AH2:AK2,3,0),0) -> 0 | BC4: =+IFERROR(VLOOKUP($BC$2,Sheet1!AH2:AK2,3,0),0) -> 0 | BD4: =+IFERROR(VLOOKUP($BD$2,Sheet1!AH2:AK2,3,0),0) -> 0 | BE4: =+IFERROR(VLOOKUP($BE$2,Sheet1!AH2:AK2,3,0),0) -> 0 | BF4: =+IFERROR(VLOOKUP($BF$2,Sheet1!AH2:AK2,3,0),0) -> 0 | BG4: =+IFERROR(VLOOKUP($BG$2,Sheet1!AH2:AK2,3,0),0) -> 0 | BH4: =+IFERROR(VLOOKUP($BH$2,Sheet1!AH2:AK2,3,0),0) -> 0 | BI4: =+IFERROR(VLOOKUP($BI$2,Sheet1!AH2:AK2,3,0),0) -> 0 | BJ4: =+IFERROR(VLOOKUP($BJ$2,Sheet1!AH2:AK2,3,0),0) -> 251 | BK4: =+IFERROR(VLOOKUP($BK$2,Sheet1!AH2:AK2,3,0),0) -> 0 | BL4: =+IFERROR(VLOOKUP($BL$2,Sheet1!AL2:AO2,3,0),0) -> 0 | BM4: =+IFERROR(VLOOKUP($BM$2,Sheet1!AL2:AO2,3,0),0) -> 0 | BN4: =+IFERROR(VLOOKUP($BN$2,Sheet1!AL2:AO2,3,0),0) -> 93 | BO4: =+IFERROR(VLOOKUP($BO$2,Sheet1!AL2:AO2,3,0),0) -> 0 | BP4: =+IFERROR(VLOOKUP($BP$2,Sheet1!AL2:AO2,3,0),0) -> 0 | BQ4: =+IFERROR(VLOOKUP($BQ$2,Sheet1!AL2:AO2,3,0),0) -> 0 | BR4: =+IFERROR(VLOOKUP($BR$2,Sheet1!AL2:AO2,3,0),0) -> 0 | BS4: =+IFERROR(VLOOKUP($BS$2,Sheet1!AL2:AO2,3,0),0) -> 0 | BT4: =+IFERROR(VLOOKUP($BT$2,Sheet1!AL2:AO2,3,0),0) -> 0 | BU4: =+IFERROR(VLOOKUP($BU$2,Sheet1!AL2:AO2,3,0),0) -> 0 | BV4: =+IFERROR(VLOOKUP($BV$2,Sheet1!AL2:AO2,3,0),0) -> 0 | BW4: =+IFERROR(VLOOKUP($BW$2,Sheet1!AL2:AO2,3,0),0) -> 0 | BX4: =+IFERROR(VLOOKUP($BX$2,Sheet1!AP2:AS2,3,0),0) -> 0 | BY4: =+IFERROR(VLOOKUP($BY$2,Sheet1!AT2:AW2,3,0),0) -> 0 | BZ4: =+IFERROR(VLOOKUP($BZ$2,Sheet1!AX2:BA2,3,0),0) -> 0 | CA4: =+IFERROR(VLOOKUP($CA$2,Sheet1!BB2:BE2,3,0),0) -> 0 | CB4: =+IFERROR(VLOOKUP($CB$2,Sheet1!BF2:BI2,3,0),0) -> 0 | CC4: =+IFERROR(VLOOKUP($CC$2,Sheet1!BJ2:BM2,3,0),0) -> 0 | CD4: =+IFERROR(VLOOKUP($CD$2,Sheet1!BN2:BQ2,3,0),0) -> 0 | CE4: =+IFERROR(VLOOKUP($CE$2,Sheet1!BR2:BU2,3,0),0) -> 0 | CF4: =+IFERROR(VLOOKUP($CF$2,Sheet1!BV2:BY2,3,0),0) -> 0 | CG4: STEEL | CH4: MD0100004 | CI4: STEEL DRUM - 28 X 10 X 23 X 2 | CJ4: 500 | CK4: =3150/0.5 -> 6300 | CL4: =SUMPRODUCT($N$3:$CF$3,N4:CF4)+CK4 -> 83539 | CM4: =Sheet1!CB2 -> 0 | CN4: =CL4*CM4 -> 0 | CO4: 0.12 | CP4: =CL4*CO4 -> 10024.68 | CQ4: 0 | CR4: =CL4*CQ4 -> 0 | CS4: =CL4+CN4+CP4+CR4 -> 93563.68 | CT4: 0.02 | CU4: =CS4*CT4 -> 1871.2736 | CV4: 0.01 | CW4: =CS4*CV4 -> 935.6368 | CX4: =Sheet1!CM2 -> 0 | CY4: =CX4*CS4 -> 0 | DA4: =324*1000 -> 324000 | DB4: =DA4*15% -> 48600 | DC4: =DA4*9% -> 29160 | DE4: =DA4+DB4+DC4+DD4 -> 401760 | DF4: =((DE4-E4)/DE4)*100 -> 76.012896
A5: =Sheet1!A3 -> ENQ-16887-25-26 | B5: 45902 | C5: =Sheet1!C3 -> FA0200009 | D5: =Sheet1!D3 -> 3 CORE X 2.5 SQ. MM. CU/ARD - WIRE (PVC) | E5: =CS5+CU5+CW5+CY5 -> 122015.12 | F5: =ROUNDUP(M23,0) -> 3462 | G5: =E5+F5 -> 125477.12 | H5: =Sheet1!CR3 -> 0.18 | I5: =G5*H5 -> 22585.881 | J5: =G5+I5 -> 148063 | K5: =Sheet1!CU3 -> 13 | L5: =Sheet1!CV3 -> KMS | M5: =J5*K5 -> 1924819 | N5: =+IFERROR(VLOOKUP($N$2,Sheet1!J3:L3,3,0),0) -> 0 | O5: =+IFERROR(VLOOKUP($O$2,Sheet1!J3:L3,3,0),0) -> 0 | P5: =+IFERROR(VLOOKUP($P$2,Sheet1!J3:M3,3,0),0) -> 67 | Q5: =+IFERROR(VLOOKUP($Q$2,Sheet1!J3:M3,3,0),0) -> 0 | R5: =+IFERROR(VLOOKUP($R$2,Sheet1!J3:M3,3,0),0) -> 0 | S5: =+IFERROR(VLOOKUP($S$2,Sheet1!J3:M3,3,0),0) -> 0 | T5: =+IFERROR(VLOOKUP($T$2,Sheet1!J3:M3,3,0),0) -> 0 | U5: =+IFERROR(VLOOKUP($U$2,Sheet1!J3:M3,3,0),0) -> 0 | V5: =+IFERROR(VLOOKUP($V$2,Sheet1!N3:Q3,3,0),0) -> 0 | W5: =+IFERROR(VLOOKUP($W$2,Sheet1!N3:Q3,3,0),0) -> 0 | X5: =+IFERROR(VLOOKUP($X$2,Sheet1!F3:I3,3,0),0) -> 0 | Y5: =+IFERROR(VLOOKUP($Y$2,Sheet1!F3:I3,3,0),0) -> 0 | Z5: =+IFERROR(VLOOKUP($Z$2,Sheet1!F3:I3,3,0),0) -> 0 | AA5: =+IFERROR(VLOOKUP($AA$2,Sheet1!F3:I3,3,0),0) -> 0 | AB5: =+IFERROR(VLOOKUP($AB$2,Sheet1!F3:I3,3,0),0) -> 0 | AC5: =+IFERROR(VLOOKUP($AC$2,Sheet1!F3:I3,3,0),0) -> 0 | AD5: =+IFERROR(VLOOKUP($AD$2,Sheet1!F3:I3,3,0),0) -> 0 | AE5: =+IFERROR(VLOOKUP($AE$2,Sheet1!F3:I3,3,0),0) -> 0 | AF5: =+IFERROR(VLOOKUP($AF$2,Sheet1!R3:U3,3,0),0) -> 0 | AG5: =+IFERROR(VLOOKUP($AG$2,Sheet1!R3:U3,3,0),0) -> 0 | AH5: =+IFERROR(VLOOKUP($AH$2,Sheet1!V3:Y3,3,0),0) -> 0 | AI5: =+IFERROR(VLOOKUP($AI$2,Sheet1!V3:Y3,3,0),0) -> 0 | AJ5: =+IFERROR(VLOOKUP($AJ$2,Sheet1!V3:Y3,3,0),0) -> 0 | AK5: =+IFERROR(VLOOKUP($AK$2,Sheet1!V3:Y3,3,0),0) -> 39 | AL5: =+IFERROR(VLOOKUP($AL$2,Sheet1!V3:Y3,3,0),0) -> 0 | AM5: =+IFERROR(VLOOKUP($AM$2,Sheet1!V3:Y3,3,0),0) -> 0 | AN5: =+IFERROR(VLOOKUP($AN$2,Sheet1!V3:Y3,3,0),0) -> 0 | AO5: =+IFERROR(VLOOKUP($AO$2,Sheet1!V3:Y3,3,0),0) -> 0 | AP5: =+IFERROR(VLOOKUP($AP$2,Sheet1!V3:Y3,3,0),0) -> 0 | AQ5: =+IFERROR(VLOOKUP($AQ$2,Sheet1!Z3:AB3,3,0),0) -> 3 | AR5: =+IFERROR(VLOOKUP($AR$2,Sheet1!AD3:AG3,3,0),0) -> 20 | AS5: =+IFERROR(VLOOKUP($AS$2,Sheet1!AD3:AG3,3,0),0) -> 0 | AT5: =+IFERROR(VLOOKUP($AT$2,Sheet1!AD3:AG3,3,0),0) -> 0 | AU5: =+IFERROR(VLOOKUP($AU$2,Sheet1!AD3:AG3,3,0),0) -> 0 | AV5: =+IFERROR(VLOOKUP($AV$2,Sheet1!AD3:AG3,3,0),0) -> 0 | AW5: =+IFERROR(VLOOKUP($AW$2,Sheet1!AD3:AG3,3,0),0) -> 0 | AX5: =+IFERROR(VLOOKUP($AX$2,Sheet1!AD3:AG3,3,0),0) -> 0 | AY5: =+IFERROR(VLOOKUP($AY$2,Sheet1!AD3:AG3,3,0),0) -> 0 | AZ5: =+IFERROR(VLOOKUP($AZ$2,Sheet1!AD3:AG3,3,0),0) -> 0 | BA5: =+IFERROR(VLOOKUP($BA$2,Sheet1!AH3:AK3,3,0),0) -> 0 | BB5: =+IFERROR(VLOOKUP($BB$2,Sheet1!AH3:AK3,3,0),0) -> 0 | BC5: =+IFERROR(VLOOKUP($BC$2,Sheet1!AH3:AK3,3,0),0) -> 0 | BD5: =+IFERROR(VLOOKUP($BD$2,Sheet1!AH3:AK3,3,0),0) -> 0 | BE5: =+IFERROR(VLOOKUP($BE$2,Sheet1!AH3:AK3,3,0),0) -> 0 | BF5: =+IFERROR(VLOOKUP($BF$2,Sheet1!AH3:AK3,3,0),0) -> 0 | BG5: =+IFERROR(VLOOKUP($BG$2,Sheet1!AH3:AK3,3,0),0) -> 0 | BH5: =+IFERROR(VLOOKUP($BH$2,Sheet1!AH3:AK3,3,0),0) -> 0 | BI5: =+IFERROR(VLOOKUP($BI$2,Sheet1!AH3:AK3,3,0),0) -> 0 | BJ5: =+IFERROR(VLOOKUP($BJ$2,Sheet1!AH3:AK3,3,0),0) -> 264 | BK5: =+IFERROR(VLOOKUP($BK$2,Sheet1!AH3:AK3,3,0),0) -> 0 | BL5: =+IFERROR(VLOOKUP($BL$2,Sheet1!AL3:AO3,3,0),0) -> 0 | BM5: =+IFERROR(VLOOKUP($BM$2,Sheet1!AL3:AO3,3,0),0) -> 0 | BN5: =+IFERROR(VLOOKUP($BN$2,Sheet1!AL3:AO3,3,0),0) -> 97 | BO5: =+IFERROR(VLOOKUP($BO$2,Sheet1!AL3:AO3,3,0),0) -> 0 | BP5: =+IFERROR(VLOOKUP($BP$2,Sheet1!AL3:AO3,3,0),0) -> 0 | BQ5: =+IFERROR(VLOOKUP($BQ$2,Sheet1!AL3:AO3,3,0),0) -> 0 | BR5: =+IFERROR(VLOOKUP($BR$2,Sheet1!AL3:AO3,3,0),0) -> 0 | BS5: =+IFERROR(VLOOKUP($BS$2,Sheet1!AL3:AO3,3,0),0) -> 0 | BT5: =+IFERROR(VLOOKUP($BT$2,Sheet1!AL3:AO3,3,0),0) -> 0 | BU5: =+IFERROR(VLOOKUP($BU$2,Sheet1!AL3:AO3,3,0),0) -> 0 | BV5: =+IFERROR(VLOOKUP($BV$2,Sheet1!AL3:AO3,3,0),0) -> 0 | BW5: =+IFERROR(VLOOKUP($BW$2,Sheet1!AL3:AO3,3,0),0) -> 0 | BX5: =+IFERROR(VLOOKUP($BX$2,Sheet1!AP3:AS3,3,0),0) -> 0 | BY5: =+IFERROR(VLOOKUP($BY$2,Sheet1!AT3:AW3,3,0),0) -> 0 | BZ5: =+IFERROR(VLOOKUP($BZ$2,Sheet1!AX3:BA3,3,0),0) -> 0 | CA5: =+IFERROR(VLOOKUP($CA$2,Sheet1!BB3:BE3,3,0),0) -> 0 | CB5: =+IFERROR(VLOOKUP($CB$2,Sheet1!BF3:BI3,3,0),0) -> 0 | CC5: =+IFERROR(VLOOKUP($CC$2,Sheet1!BJ3:BM3,3,0),0) -> 0 | CD5: =+IFERROR(VLOOKUP($CD$2,Sheet1!BN3:BQ3,3,0),0) -> 0 | CE5: =+IFERROR(VLOOKUP($CE$2,Sheet1!BR3:BU3,3,0),0) -> 0 | CF5: =+IFERROR(VLOOKUP($CF$2,Sheet1!BV3:BY3,3,0),0) -> 0 | CG5: STEEL | CH5: MD0100004 | CI5: STEEL DRUM - 28 X 10 X 23 X 2 | CJ5: 500 | CK5: =3150/0.5 -> 6300 | CL5: =SUMPRODUCT($N$3:$CF$3,N5:CF5)+CK5 -> 105769 | CM5: =Sheet1!CB3 -> 0 | CN5: =CL5*CM5 -> 0 | CO5: 0.12 | CP5: =CL5*CO5 -> 12692.28 | CQ5: 0 | CR5: =CL5*CQ5 -> 0 | CS5: =CL5+CN5+CP5+CR5 -> 118461.28 | CT5: 0.02 | CU5: =CS5*CT5 -> 2369.2256 | CV5: 0.01 | CW5: =CS5*CV5 -> 1184.6128 | CX5: =Sheet1!CM3 -> 0 | CY5: =CX5*CS5 -> 0 | DA5: =418*1000 -> 418000 | DB5: =DA5*15% -> 62700 | DC5: =DA5*9% -> 37620 | DE5: =DA5+DB5+DC5+DD5 -> 518320 | DF5: =((DE5-E5)/DE5)*100 -> 76.4595
A6: =Sheet1!A4 -> ENQ-16887-25-26 | B6: 45902 | C6: =Sheet1!C4 -> FA0200016 | D6: =Sheet1!D4 -> 5 CORE X 2.5 SQ. MM. CU/ARD - WIRE (PVC) | E6: =CS6+CU6+CW6+CY6 -> 179696.27 | F6: =ROUNDUP(M24,0) -> 4091 | G6: =E6+F6 -> 183787.27 | H6: =Sheet1!CR4 -> 0.18 | I6: =G6*H6 -> 33081.709 | J6: =G6+I6 -> 216868.98 | K6: =Sheet1!CU4 -> 11 | L6: =Sheet1!CV4 -> KMS | M6: =J6*K6 -> 2385558.8 | N6: =+IFERROR(VLOOKUP($N$2,Sheet1!J4:L4,3,0),0) -> 0 | O6: =+IFERROR(VLOOKUP($O$2,Sheet1!J4:L4,3,0),0) -> 0 | P6: =+IFERROR(VLOOKUP($P$2,Sheet1!J4:M4,3,0),0) -> 111 | Q6: =+IFERROR(VLOOKUP($Q$2,Sheet1!J4:M4,3,0),0) -> 0 | R6: =+IFERROR(VLOOKUP($R$2,Sheet1!J4:M4,3,0),0) -> 0 | S6: =+IFERROR(VLOOKUP($S$2,Sheet1!J4:M4,3,0),0) -> 0 | T6: =+IFERROR(VLOOKUP($T$2,Sheet1!J4:M4,3,0),0) -> 0 | U6: =+IFERROR(VLOOKUP($U$2,Sheet1!J4:M4,3,0),0) -> 0 | V6: =+IFERROR(VLOOKUP($V$2,Sheet1!N4:Q4,3,0),0) -> 0 | W6: =+IFERROR(VLOOKUP($W$2,Sheet1!N4:Q4,3,0),0) -> 0 | X6: =+IFERROR(VLOOKUP($X$2,Sheet1!F4:I4,3,0),0) -> 0 | Y6: =+IFERROR(VLOOKUP($Y$2,Sheet1!F4:I4,3,0),0) -> 0 | Z6: =+IFERROR(VLOOKUP($Z$2,Sheet1!F4:I4,3,0),0) -> 0 | AA6: =+IFERROR(VLOOKUP($AA$2,Sheet1!F4:I4,3,0),0) -> 0 | AB6: =+IFERROR(VLOOKUP($AB$2,Sheet1!F4:I4,3,0),0) -> 0 | AC6: =+IFERROR(VLOOKUP($AC$2,Sheet1!F4:I4,3,0),0) -> 0 | AD6: =+IFERROR(VLOOKUP($AD$2,Sheet1!F4:I4,3,0),0) -> 0 | AE6: =+IFERROR(VLOOKUP($AE$2,Sheet1!F4:I4,3,0),0) -> 0 | AF6: =+IFERROR(VLOOKUP($AF$2,Sheet1!R4:U4,3,0),0) -> 0 | AG6: =+IFERROR(VLOOKUP($AG$2,Sheet1!R4:U4,3,0),0) -> 0 | AH6: =+IFERROR(VLOOKUP($AH$2,Sheet1!V4:Y4,3,0),0) -> 0 | AI6: =+IFERROR(VLOOKUP($AI$2,Sheet1!V4:Y4,3,0),0) -> 0 | AJ6: =+IFERROR(VLOOKUP($AJ$2,Sheet1!V4:Y4,3,0),0) -> 0 | AK6: =+IFERROR(VLOOKUP($AK$2,Sheet1!V4:Y4,3,0),0) -> 65 | AL6: =+IFERROR(VLOOKUP($AL$2,Sheet1!V4:Y4,3,0),0) -> 0 | AM6: =+IFERROR(VLOOKUP($AM$2,Sheet1!V4:Y4,3,0),0) -> 0 | AN6: =+IFERROR(VLOOKUP($AN$2,Sheet1!V4:Y4,3,0),0) -> 0 | AO6: =+IFERROR(VLOOKUP($AO$2,Sheet1!V4:Y4,3,0),0) -> 0 | AP6: =+IFERROR(VLOOKUP($AP$2,Sheet1!V4:Y4,3,0),0) -> 0 | AQ6: =+IFERROR(VLOOKUP($AQ$2,Sheet1!Z4:AB4,3,0),0) -> 4 | AR6: =+IFERROR(VLOOKUP($AR$2,Sheet1!AD4:AG4,3,0),0) -> 28 | AS6: =+IFERROR(VLOOKUP($AS$2,Sheet1!AD4:AG4,3,0),0) -> 0 | AT6: =+IFERROR(VLOOKUP($AT$2,Sheet1!AD4:AG4,3,0),0) -> 0 | AU6: =+IFERROR(VLOOKUP($AU$2,Sheet1!AD4:AG4,3,0),0) -> 0 | AV6: =+IFERROR(VLOOKUP($AV$2,Sheet1!AD4:AG4,3,0),0) -> 0 | AW6: =+IFERROR(VLOOKUP($AW$2,Sheet1!AD4:AG4,3,0),0) -> 0 | AX6: =+IFERROR(VLOOKUP($AX$2,Sheet1!AD4:AG4,3,0),0) -> 0 | AY6: =+IFERROR(VLOOKUP($AY$2,Sheet1!AD4:AG4,3,0),0) -> 0 | AZ6: =+IFERROR(VLOOKUP($AZ$2,Sheet1!AD4:AG4,3,0),0) -> 0 | BA6: =+IFERROR(VLOOKUP($BA$2,Sheet1!AH4:AK4,3,0),0) -> 0 | BB6: =+IFERROR(VLOOKUP($BB$2,Sheet1!AH4:AK4,3,0),0) -> 0 | BC6: =+IFERROR(VLOOKUP($BC$2,Sheet1!AH4:AK4,3,0),0) -> 0 | BD6: =+IFERROR(VLOOKUP($BD$2,Sheet1!AH4:AK4,3,0),0) -> 0 | BE6: =+IFERROR(VLOOKUP($BE$2,Sheet1!AH4:AK4,3,0),0) -> 0 | BF6: =+IFERROR(VLOOKUP($BF$2,Sheet1!AH4:AK4,3,0),0) -> 0 | BG6: =+IFERROR(VLOOKUP($BG$2,Sheet1!AH4:AK4,3,0),0) -> 0 | BH6: =+IFERROR(VLOOKUP($BH$2,Sheet1!AH4:AK4,3,0),0) -> 0 | BI6: =+IFERROR(VLOOKUP($BI$2,Sheet1!AH4:AK4,3,0),0) -> 0 | BJ6: =+IFERROR(VLOOKUP($BJ$2,Sheet1!AH4:AK4,3,0),0) -> 314 | BK6: =+IFERROR(VLOOKUP($BK$2,Sheet1!AH4:AK4,3,0),0) -> 0 | BL6: =+IFERROR(VLOOKUP($BL$2,Sheet1!AL4:AO4,3,0),0) -> 0 | BM6: =+IFERROR(VLOOKUP($BM$2,Sheet1!AL4:AO4,3,0),0) -> 0 | BN6: =+IFERROR(VLOOKUP($BN$2,Sheet1!AL4:AO4,3,0),0) -> 112 | BO6: =+IFERROR(VLOOKUP($BO$2,Sheet1!AL4:AO4,3,0),0) -> 0 | BP6: =+IFERROR(VLOOKUP($BP$2,Sheet1!AL4:AO4,3,0),0) -> 0 | BQ6: =+IFERROR(VLOOKUP($BQ$2,Sheet1!AL4:AO4,3,0),0) -> 0 | BR6: =+IFERROR(VLOOKUP($BR$2,Sheet1!AL4:AO4,3,0),0) -> 0 | BS6: =+IFERROR(VLOOKUP($BS$2,Sheet1!AL4:AO4,3,0),0) -> 0 | BT6: =+IFERROR(VLOOKUP($BT$2,Sheet1!AL4:AO4,3,0),0) -> 0 | BU6: =+IFERROR(VLOOKUP($BU$2,Sheet1!AL4:AO4,3,0),0) -> 0 | BV6: =+IFERROR(VLOOKUP($BV$2,Sheet1!AL4:AO4,3,0),0) -> 0 | BW6: =+IFERROR(VLOOKUP($BW$2,Sheet1!AL4:AO4,3,0),0) -> 0 | BX6: =+IFERROR(VLOOKUP($BX$2,Sheet1!AP4:AS4,3,0),0) -> 0 | BY6: =+IFERROR(VLOOKUP($BY$2,Sheet1!AT4:AW4,3,0),0) -> 0 | BZ6: =+IFERROR(VLOOKUP($BZ$2,Sheet1!AX4:BA4,3,0),0) -> 0 | CA6: =+IFERROR(VLOOKUP($CA$2,Sheet1!BB4:BE4,3,0),0) -> 0 | CB6: =+IFERROR(VLOOKUP($CB$2,Sheet1!BF4:BI4,3,0),0) -> 0 | CC6: =+IFERROR(VLOOKUP($CC$2,Sheet1!BJ4:BM4,3,0),0) -> 0 | CD6: =+IFERROR(VLOOKUP($CD$2,Sheet1!BN4:BQ4,3,0),0) -> 0 | CE6: =+IFERROR(VLOOKUP($CE$2,Sheet1!BR4:BU4,3,0),0) -> 0 | CF6: =+IFERROR(VLOOKUP($CF$2,Sheet1!BV4:BY4,3,0),0) -> 0 | CG6: STEEL | CH6: MD0200019 | CI6: STEEL DRUM - 35" X 16 X 22 | CJ6: 500 | CK6: =3600/0.5 -> 7200 | CL6: =SUMPRODUCT($N$3:$CF$3,N6:CF6)+CK6 -> 155770 | CM6: =Sheet1!CB4 -> 0 | CN6: =CL6*CM6 -> 0 | CO6: 0.12 | CP6: =CL6*CO6 -> 18692.4 | CQ6: 0 | CR6: =CL6*CQ6 -> 0 | CS6: =CL6+CN6+CP6+CR6 -> 174462.4 | CT6: 0.02 | CU6: =CS6*CT6 -> 3489.248 | CV6: 0.01 | CW6: =CS6*CV6 -> 1744.624 | CX6: =Sheet1!CM4 -> 0 | CY6: =CX6*CS6 -> 0 | DA6: =663*1000 -> 663000 | DB6: =DA6*15% -> 99450 | DC6: =DA6*6% -> 39780 | DE6: =DA6+DB6+DC6+DD6 -> 802230 | DF6: =((DE6-E6)/DE6)*100 -> 77.600405
A7: =Sheet1!A5 -> ENQ-16887-25-26 | B7: 45902 | C7: =Sheet1!C5 -> FA0200073 | D7: =Sheet1!D5 -> 19 CORE X 2.5 SQ. MM. CU/ARD - WIRE (PVC) | E7: =CS7+CU7+CW7+CY7 -> 579775.13 | F7: =ROUNDUP(M25,0) -> 6429 | G7: =E7+F7 -> 586204.13 | H7: =Sheet1!CR5 -> 0.18 | I7: =G7*H7 -> 105516.74 | J7: =G7+I7 -> 691720.88 | K7: =Sheet1!CU5 -> 14 | L7: =Sheet1!CV5 -> KMS | M7: =J7*K7 -> 9684092.3 | N7: =+IFERROR(VLOOKUP($N$2,Sheet1!J5:L5,3,0),0) -> 0 | O7: =+IFERROR(VLOOKUP($O$2,Sheet1!J5:L5,3,0),0) -> 0 | P7: =+IFERROR(VLOOKUP($P$2,Sheet1!J5:M5,3,0),0) -> 422 | Q7: =+IFERROR(VLOOKUP($Q$2,Sheet1!J5:M5,3,0),0) -> 0 | R7: =+IFERROR(VLOOKUP($R$2,Sheet1!J5:M5,3,0),0) -> 0 | S7: =+IFERROR(VLOOKUP($S$2,Sheet1!J5:M5,3,0),0) -> 0 | T7: =+IFERROR(VLOOKUP($T$2,Sheet1!J5:M5,3,0),0) -> 0 | U7: =+IFERROR(VLOOKUP($U$2,Sheet1!J5:M5,3,0),0) -> 0 | V7: =+IFERROR(VLOOKUP($V$2,Sheet1!N5:Q5,3,0),0) -> 0 | W7: =+IFERROR(VLOOKUP($W$2,Sheet1!N5:Q5,3,0),0) -> 0 | X7: =+IFERROR(VLOOKUP($X$2,Sheet1!F5:I5,3,0),0) -> 0 | Y7: =+IFERROR(VLOOKUP($Y$2,Sheet1!F5:I5,3,0),0) -> 0 | Z7: =+IFERROR(VLOOKUP($Z$2,Sheet1!F5:I5,3,0),0) -> 0 | AA7: =+IFERROR(VLOOKUP($AA$2,Sheet1!F5:I5,3,0),0) -> 0 | AB7: =+IFERROR(VLOOKUP($AB$2,Sheet1!F5:I5,3,0),0) -> 0 | AC7: =+IFERROR(VLOOKUP($AC$2,Sheet1!F5:I5,3,0),0) -> 0 | AD7: =+IFERROR(VLOOKUP($AD$2,Sheet1!F5:I5,3,0),0) -> 0 | AE7: =+IFERROR(VLOOKUP($AE$2,Sheet1!F5:I5,3,0),0) -> 0 | AF7: =+IFERROR(VLOOKUP($AF$2,Sheet1!R5:U5,3,0),0) -> 0 | AG7: =+IFERROR(VLOOKUP($AG$2,Sheet1!R5:U5,3,0),0) -> 0 | AH7: =+IFERROR(VLOOKUP($AH$2,Sheet1!V5:Y5,3,0),0) -> 0 | AI7: =+IFERROR(VLOOKUP($AI$2,Sheet1!V5:Y5,3,0),0) -> 0 | AJ7: =+IFERROR(VLOOKUP($AJ$2,Sheet1!V5:Y5,3,0),0) -> 0 | AK7: =+IFERROR(VLOOKUP($AK$2,Sheet1!V5:Y5,3,0),0) -> 247 | AL7: =+IFERROR(VLOOKUP($AL$2,Sheet1!V5:Y5,3,0),0) -> 0 | AM7: =+IFERROR(VLOOKUP($AM$2,Sheet1!V5:Y5,3,0),0) -> 0 | AN7: =+IFERROR(VLOOKUP($AN$2,Sheet1!V5:Y5,3,0),0) -> 0 | AO7: =+IFERROR(VLOOKUP($AO$2,Sheet1!V5:Y5,3,0),0) -> 0 | AP7: =+IFERROR(VLOOKUP($AP$2,Sheet1!V5:Y5,3,0),0) -> 0 | AQ7: =+IFERROR(VLOOKUP($AQ$2,Sheet1!Z5:AB5,3,0),0) -> 7 | AR7: =+IFERROR(VLOOKUP($AR$2,Sheet1!AD5:AG5,3,0),0) -> 48 | AS7: =+IFERROR(VLOOKUP($AS$2,Sheet1!AD5:AG5,3,0),0) -> 0 | AT7: =+IFERROR(VLOOKUP($AT$2,Sheet1!AD5:AG5,3,0),0) -> 0 | AU7: =+IFERROR(VLOOKUP($AU$2,Sheet1!AD5:AG5,3,0),0) -> 0 | AV7: =+IFERROR(VLOOKUP($AV$2,Sheet1!AD5:AG5,3,0),0) -> 0 | AW7: =+IFERROR(VLOOKUP($AW$2,Sheet1!AD5:AG5,3,0),0) -> 0 | AX7: =+IFERROR(VLOOKUP($AX$2,Sheet1!AD5:AG5,3,0),0) -> 0 | AY7: =+IFERROR(VLOOKUP($AY$2,Sheet1!AD5:AG5,3,0),0) -> 0 | AZ7: =+IFERROR(VLOOKUP($AZ$2,Sheet1!AD5:AG5,3,0),0) -> 0 | BA7: =+IFERROR(VLOOKUP($BA$2,Sheet1!AH5:AK5,3,0),0) -> 0 | BB7: =+IFERROR(VLOOKUP($BB$2,Sheet1!AH5:AK5,3,0),0) -> 0 | BC7: =+IFERROR(VLOOKUP($BC$2,Sheet1!AH5:AK5,3,0),0) -> 0 | BD7: =+IFERROR(VLOOKUP($BD$2,Sheet1!AH5:AK5,3,0),0) -> 0 | BE7: =+IFERROR(VLOOKUP($BE$2,Sheet1!AH5:AK5,3,0),0) -> 0 | BF7: =+IFERROR(VLOOKUP($BF$2,Sheet1!AH5:AK5,3,0),0) -> 0 | BG7: =+IFERROR(VLOOKUP($BG$2,Sheet1!AH5:AK5,3,0),0) -> 0 | BH7: =+IFERROR(VLOOKUP($BH$2,Sheet1!AH5:AK5,3,0),0) -> 0 | BI7: =+IFERROR(VLOOKUP($BI$2,Sheet1!AH5:AK5,3,0),0) -> 0 | BJ7: =+IFERROR(VLOOKUP($BJ$2,Sheet1!AH5:AK5,3,0),0) -> 607 | BK7: =+IFERROR(VLOOKUP($BK$2,Sheet1!AH5:AK5,3,0),0) -> 0 | BL7: =+IFERROR(VLOOKUP($BL$2,Sheet1!AL5:AO5,3,0),0) -> 0 | BM7: =+IFERROR(VLOOKUP($BM$2,Sheet1!AL5:AO5,3,0),0) -> 0 | BN7: =+IFERROR(VLOOKUP($BN$2,Sheet1!AL5:AO5,3,0),0) -> 195 | BO7: =+IFERROR(VLOOKUP($BO$2,Sheet1!AL5:AO5,3,0),0) -> 0 | BP7: =+IFERROR(VLOOKUP($BP$2,Sheet1!AL5:AO5,3,0),0) -> 0 | BQ7: =+IFERROR(VLOOKUP($BQ$2,Sheet1!AL5:AO5,3,0),0) -> 0 | BR7: =+IFERROR(VLOOKUP($BR$2,Sheet1!AL5:AO5,3,0),0) -> 0 | BS7: =+IFERROR(VLOOKUP($BS$2,Sheet1!AL5:AO5,3,0),0) -> 0 | BT7: =+IFERROR(VLOOKUP($BT$2,Sheet1!AL5:AO5,3,0),0) -> 0 | BU7: =+IFERROR(VLOOKUP($BU$2,Sheet1!AL5:AO5,3,0),0) -> 0 | BV7: =+IFERROR(VLOOKUP($BV$2,Sheet1!AL5:AO5,3,0),0) -> 0 | BW7: =+IFERROR(VLOOKUP($BW$2,Sheet1!AL5:AO5,3,0),0) -> 0 | BX7: =+IFERROR(VLOOKUP($BX$2,Sheet1!AP5:AS5,3,0),0) -> 0 | BY7: =+IFERROR(VLOOKUP($BY$2,Sheet1!AT5:AW5,3,0),0) -> 0 | BZ7: =+IFERROR(VLOOKUP($BZ$2,Sheet1!AX5:BA5,3,0),0) -> 0 | CA7: =+IFERROR(VLOOKUP($CA$2,Sheet1!BB5:BE5,3,0),0) -> 0 | CB7: =+IFERROR(VLOOKUP($CB$2,Sheet1!BF5:BI5,3,0),0) -> 0 | CC7: =+IFERROR(VLOOKUP($CC$2,Sheet1!BJ5:BM5,3,0),0) -> 0 | CD7: =+IFERROR(VLOOKUP($CD$2,Sheet1!BN5:BQ5,3,0),0) -> 0 | CE7: =+IFERROR(VLOOKUP($CE$2,Sheet1!BR5:BU5,3,0),0) -> 0 | CF7: =+IFERROR(VLOOKUP($CF$2,Sheet1!BV5:BY5,3,0),0) -> 0 | CG7: STEEL | CH7: SP0400144 | CI7: CORRUGATED DISPATCH STEEL DRUM 1060 X 600 X 965 MM | CJ7: 500 | CK7: =9000/0.5 -> 18000 | CL7: =SUMPRODUCT($N$3:$CF$3,N7:CF7)+CK7 -> 502579 | CM7: =Sheet1!CB5 -> 0 | CN7: =CL7*CM7 -> 0 | CO7: 0.12 | CP7: =CL7*CO7 -> 60309.48 | CQ7: 0 | CR7: =CL7*CQ7 -> 0 | CS7: =CL7+CN7+CP7+CR7 -> 562888.48 | CT7: 0.02 | CU7: =CS7*CT7 -> 11257.77 | CV7: 0.01 | CW7: =CS7*CV7 -> 5628.8848 | CX7: =Sheet1!CM5 -> 0 | CY7: =CX7*CS7 -> 0 | DA7: =2234*1000 -> 2234000 | DB7: =DA7*15% -> 335100 | DC7: =DA7*6% -> 134040 | DD7: =DA7*18% -> 402120 | DE7: =DA7+DB7+DC7+DD7 -> 3105260 | DF7: =((DE7-E7)/DE7)*100 -> 81.329256
A8: =Sheet1!A10 -> ENQ-16887-25-26 | B8: 45902 | C8: =Sheet1!C10 -> FA1100007 | D8: =Sheet1!D10 -> 3.5 CORE X 70 SQ. MM. AL/ARD - STRIP (PVC) | E8: =CS8+CU8+CW8+CY8 -> 339072.6 | F8: =ROUNDUP(M26,0) -> 10589 | G8: =E8+F8 -> 349661.6 | H8: =Sheet1!CR10 -> 0.18 | I8: =G8*H8 -> 62939.088 | J8: =G8+I8 -> 412600.69 | K8: =Sheet1!CU10 -> 17 | L8: =Sheet1!CV10 -> KMS | M8: =J8*K8 -> 7014211.7 | N8: =+IFERROR(VLOOKUP($N$2,Sheet1!J10:L10,3,0),0) -> 662 | O8: =+IFERROR(VLOOKUP($O$2,Sheet1!J10:L10,3,0),0) -> 0 | P8: =+IFERROR(VLOOKUP($P$2,Sheet1!J10:M10,3,0),0) -> 0 | Q8: =+IFERROR(VLOOKUP($Q$2,Sheet1!J10:M10,3,0),0) -> 0 | R8: =+IFERROR(VLOOKUP($R$2,Sheet1!J10:M10,3,0),0) -> 0 | S8: =+IFERROR(VLOOKUP($S$2,Sheet1!J10:M10,3,0),0) -> 0 | T8: =+IFERROR(VLOOKUP($T$2,Sheet1!J10:M10,3,0),0) -> 0 | U8: =+IFERROR(VLOOKUP($U$2,Sheet1!J10:M10,3,0),0) -> 0 | V8: =+IFERROR(VLOOKUP($V$2,Sheet1!N10:Q10,3,0),0) -> 0 | W8: =+IFERROR(VLOOKUP($W$2,Sheet1!N10:Q10,3,0),0) -> 0 | X8: =+IFERROR(VLOOKUP($X$2,Sheet1!F10:I10,3,0),0) -> 0 | Y8: =+IFERROR(VLOOKUP($Y$2,Sheet1!F10:I10,3,0),0) -> 0 | Z8: =+IFERROR(VLOOKUP($Z$2,Sheet1!F10:I10,3,0),0) -> 0 | AA8: =+IFERROR(VLOOKUP($AA$2,Sheet1!F10:I10,3,0),0) -> 0 | AB8: =+IFERROR(VLOOKUP($AB$2,Sheet1!F10:I10,3,0),0) -> 0 | AC8: =+IFERROR(VLOOKUP($AC$2,Sheet1!F10:I10,3,0),0) -> 0 | AD8: =+IFERROR(VLOOKUP($AD$2,Sheet1!F10:I10,3,0),0) -> 0 | AE8: =+IFERROR(VLOOKUP($AE$2,Sheet1!F10:I10,3,0),0) -> 0 | AF8: =+IFERROR(VLOOKUP($AF$2,Sheet1!R10:U10,3,0),0) -> 0 | AG8: =+IFERROR(VLOOKUP($AG$2,Sheet1!R10:U10,3,0),0) -> 0 | AH8: =+IFERROR(VLOOKUP($AH$2,Sheet1!V10:Y10,3,0),0) -> 0 | AI8: =+IFERROR(VLOOKUP($AI$2,Sheet1!V10:Y10,3,0),0) -> 0 | AJ8: =+IFERROR(VLOOKUP($AJ$2,Sheet1!V10:Y10,3,0),0) -> 0 | AK8: =+IFERROR(VLOOKUP($AK$2,Sheet1!V10:Y10,3,0),0) -> 250 | AL8: =+IFERROR(VLOOKUP($AL$2,Sheet1!V10:Y10,3,0),0) -> 0 | AM8: =+IFERROR(VLOOKUP($AM$2,Sheet1!V10:Y10,3,0),0) -> 0 | AN8: =+IFERROR(VLOOKUP($AN$2,Sheet1!V10:Y10,3,0),0) -> 0 | AO8: =+IFERROR(VLOOKUP($AO$2,Sheet1!V10:Y10,3,0),0) -> 0 | AP8: =+IFERROR(VLOOKUP($AP$2,Sheet1!V10:Y10,3,0),0) -> 0 | AQ8: =+IFERROR(VLOOKUP($AQ$2,Sheet1!Z10:AB10,3,0),0) -> 0 | AR8: =+IFERROR(VLOOKUP($AR$2,Sheet1!AD10:AG10,3,0),0) -> 76 | AS8: =+IFERROR(VLOOKUP($AS$2,Sheet1!AD10:AG10,3,0),0) -> 0 | AT8: =+IFERROR(VLOOKUP($AT$2,Sheet1!AD10:AG10,3,0),0) -> 0 | AU8: =+IFERROR(VLOOKUP($AU$2,Sheet1!AD10:AG10,3,0),0) -> 0 | AV8: =+IFERROR(VLOOKUP($AV$2,Sheet1!AD10:AG10,3,0),0) -> 0 | AW8: =+IFERROR(VLOOKUP($AW$2,Sheet1!AD10:AG10,3,0),0) -> 0 | AX8: =+IFERROR(VLOOKUP($AX$2,Sheet1!AD10:AG10,3,0),0) -> 0 | AY8: =+IFERROR(VLOOKUP($AY$2,Sheet1!AD10:AG10,3,0),0) -> 0 | AZ8: =+IFERROR(VLOOKUP($AZ$2,Sheet1!AD10:AG10,3,0),0) -> 0 | BA8: =+IFERROR(VLOOKUP($BA$2,Sheet1!AH10:AK10,3,0),0) -> 0 | BB8: =+IFERROR(VLOOKUP($BB$2,Sheet1!AH10:AK10,3,0),0) -> 0 | BC8: =+IFERROR(VLOOKUP($BC$2,Sheet1!AH10:AK10,3,0),0) -> 0 | BD8: =+IFERROR(VLOOKUP($BD$2,Sheet1!AH10:AK10,3,0),0) -> 0 | BE8: =+IFERROR(VLOOKUP($BE$2,Sheet1!AH10:AK10,3,0),0) -> 0 | BF8: =+IFERROR(VLOOKUP($BF$2,Sheet1!AH10:AK10,3,0),0) -> 0 | BG8: =+IFERROR(VLOOKUP($BG$2,Sheet1!AH10:AK10,3,0),0) -> 476 | BH8: =+IFERROR(VLOOKUP($BH$2,Sheet1!AH10:AK10,3,0),0) -> 0 | BI8: =+IFERROR(VLOOKUP($BI$2,Sheet1!AH10:AK10,3,0),0) -> 0 | BJ8: =+IFERROR(VLOOKUP($BJ$2,Sheet1!AH10:AK10,3,0),0) -> 0 | BK8: =+IFERROR(VLOOKUP($BK$2,Sheet1!AH10:AK10,3,0),0) -> 0 | BL8: =+IFERROR(VLOOKUP($BL$2,Sheet1!AL10:AO10,3,0),0) -> 0 | BM8: =+IFERROR(VLOOKUP($BM$2,Sheet1!AL10:AO10,3,0),0) -> 0 | BN8: =+IFERROR(VLOOKUP($BN$2,Sheet1!AL10:AO10,3,0),0) -> 262 | BO8: =+IFERROR(VLOOKUP($BO$2,Sheet1!AL10:AO10,3,0),0) -> 0 | BP8: =+IFERROR(VLOOKUP($BP$2,Sheet1!AL10:AO10,3,0),0) -> 0 | BQ8: =+IFERROR(VLOOKUP($BQ$2,Sheet1!AL10:AO10,3,0),0) -> 0 | BR8: =+IFERROR(VLOOKUP($BR$2,Sheet1!AL10:AO10,3,0),0) -> 0 | BS8: =+IFERROR(VLOOKUP($BS$2,Sheet1!AL10:AO10,3,0),0) -> 0 | BT8: =+IFERROR(VLOOKUP($BT$2,Sheet1!AL10:AO10,3,0),0) -> 0 | BU8: =+IFERROR(VLOOKUP($BU$2,Sheet1!AL10:AO10,3,0),0) -> 0 | BV8: =+IFERROR(VLOOKUP($BV$2,Sheet1!AL10:AO10,3,0),0) -> 0 | BW8: =+IFERROR(VLOOKUP($BW$2,Sheet1!AL10:AO10,3,0),0) -> 0 | BX8: =+IFERROR(VLOOKUP($BX$2,Sheet1!AP10:AS10,3,0),0) -> 0 | BY8: =+IFERROR(VLOOKUP($BY$2,Sheet1!AT10:AW10,3,0),0) -> 0 | BZ8: =+IFERROR(VLOOKUP($BZ$2,Sheet1!AX10:BA10,3,0),0) -> 0 | CA8: =+IFERROR(VLOOKUP($CA$2,Sheet1!BB10:BE10,3,0),0) -> 0 | CB8: =+IFERROR(VLOOKUP($CB$2,Sheet1!BF10:BI10,3,0),0) -> 0 | CC8: =+IFERROR(VLOOKUP($CC$2,Sheet1!BJ10:BM10,3,0),0) -> 0 | CD8: =+IFERROR(VLOOKUP($CD$2,Sheet1!BN10:BQ10,3,0),0) -> 0 | CE8: =+IFERROR(VLOOKUP($CE$2,Sheet1!BR10:BU10,3,0),0) -> 0 | CF8: =+IFERROR(VLOOKUP($CF$2,Sheet1!BV10:BY10,3,0),0) -> 0 | CG8: STEEL | CH8: SP0400145 | CI8: CORRUGATED DISPATCH STEEL DRUM 1320 X 850 X 965 MM | CJ8: 500 | CK8: =9000/0.5 -> 18000 | CL8: =SUMPRODUCT($N$3:$CF$3,N8:CF8)+CK8 -> 286258 | CM8: =Sheet1!CB10 -> 0 | CN8: =CL8*CM8 -> 0 | CO8: 0.15 | CP8: =CL8*CO8 -> 42938.7 | CQ8: 0 | CR8: =CL8*CQ8 -> 0 | CS8: =CL8+CN8+CP8+CR8 -> 329196.7 | CT8: 0.02 | CU8: =CS8*CT8 -> 6583.934 | CV8: 0.01 | CW8: =CS8*CV8 -> 3291.967 | CX8: =Sheet1!CM10 -> 0 | CY8: =CX8*CS8 -> 0 | DA8: =1369*1000 -> 1369000 | DB8: =DA8*15% -> 205350 | DC8: =DA8*7.5% -> 102675 | DE8: =DA8+DB8+DC8+DD8 -> 1677025 | DF8: =((DE8-E8)/DE8)*100 -> 79.781303
A9: =Sheet1!A9 -> ENQ-16887-25-26 | B9: 45902 | C9: =Sheet1!C9 -> FA0900019 | D9: =Sheet1!D9 -> 2 CORE X 6 SQ. MM. AL/ARD - WIRE (PVC) | E9: =CS9+CU9+CW9+CY9 -> 75049.92 | F9: =ROUNDUP(M27,0) -> 11250 | G9: =E9+F9 -> 86299.92 | H9: =Sheet1!CR9 -> 0.18 | I9: =G9*H9 -> 15533.986 | J9: =G9+I9 -> 101833.91 | K9: =Sheet1!CU9 -> 4 | L9: =Sheet1!CV9 -> KMS | M9: =J9*K9 -> 407335.62 | N9: =+IFERROR(VLOOKUP($N$2,Sheet1!J9:L9,3,0),0) -> 32 | O9: =+IFERROR(VLOOKUP($O$2,Sheet1!J9:L9,3,0),0) -> 0 | P9: =+IFERROR(VLOOKUP($P$2,Sheet1!J9:M9,3,0),0) -> 0 | Q9: =+IFERROR(VLOOKUP($Q$2,Sheet1!J9:M9,3,0),0) -> 0 | R9: =+IFERROR(VLOOKUP($R$2,Sheet1!J9:M9,3,0),0) -> 0 | S9: =+IFERROR(VLOOKUP($S$2,Sheet1!J9:M9,3,0),0) -> 0 | T9: =+IFERROR(VLOOKUP($T$2,Sheet1!J9:M9,3,0),0) -> 0 | U9: =+IFERROR(VLOOKUP($U$2,Sheet1!J9:M9,3,0),0) -> 0 | V9: =+IFERROR(VLOOKUP($V$2,Sheet1!N9:Q9,3,0),0) -> 0 | W9: =+IFERROR(VLOOKUP($W$2,Sheet1!N9:Q9,3,0),0) -> 0 | X9: =+IFERROR(VLOOKUP($X$2,Sheet1!F9:I9,3,0),0) -> 0 | Y9: =+IFERROR(VLOOKUP($Y$2,Sheet1!F9:I9,3,0),0) -> 0 | Z9: =+IFERROR(VLOOKUP($Z$2,Sheet1!F9:I9,3,0),0) -> 0 | AA9: =+IFERROR(VLOOKUP($AA$2,Sheet1!F9:I9,3,0),0) -> 0 | AB9: =+IFERROR(VLOOKUP($AB$2,Sheet1!F9:I9,3,0),0) -> 0 | AC9: =+IFERROR(VLOOKUP($AC$2,Sheet1!F9:I9,3,0),0) -> 0 | AD9: =+IFERROR(VLOOKUP($AD$2,Sheet1!F9:I9,3,0),0) -> 0 | AE9: =+IFERROR(VLOOKUP($AE$2,Sheet1!F9:I9,3,0),0) -> 0 | AF9: =+IFERROR(VLOOKUP($AF$2,Sheet1!R9:U9,3,0),0) -> 0 | AG9: =+IFERROR(VLOOKUP($AG$2,Sheet1!R9:U9,3,0),0) -> 0 | AH9: =+IFERROR(VLOOKUP($AH$2,Sheet1!V9:Y9,3,0),0) -> 0 | AI9: =+IFERROR(VLOOKUP($AI$2,Sheet1!V9:Y9,3,0),0) -> 0 | AJ9: =+IFERROR(VLOOKUP($AJ$2,Sheet1!V9:Y9,3,0),0) -> 0 | AK9: =+IFERROR(VLOOKUP($AK$2,Sheet1!V9:Y9,3,0),0) -> 44 | AL9: =+IFERROR(VLOOKUP($AL$2,Sheet1!V9:Y9,3,0),0) -> 0 | AM9: =+IFERROR(VLOOKUP($AM$2,Sheet1!V9:Y9,3,0),0) -> 0 | AN9: =+IFERROR(VLOOKUP($AN$2,Sheet1!V9:Y9,3,0),0) -> 0 | AO9: =+IFERROR(VLOOKUP($AO$2,Sheet1!V9:Y9,3,0),0) -> 0 | AP9: =+IFERROR(VLOOKUP($AP$2,Sheet1!V9:Y9,3,0),0) -> 0 | AQ9: =+IFERROR(VLOOKUP($AQ$2,Sheet1!Z9:AB9,3,0),0) -> 0 | AR9: =+IFERROR(VLOOKUP($AR$2,Sheet1!AD9:AG9,3,0),0) -> 68 | AS9: =+IFERROR(VLOOKUP($AS$2,Sheet1!AD9:AG9,3,0),0) -> 0 | AT9: =+IFERROR(VLOOKUP($AT$2,Sheet1!AD9:AG9,3,0),0) -> 0 | AU9: =+IFERROR(VLOOKUP($AU$2,Sheet1!AD9:AG9,3,0),0) -> 0 | AV9: =+IFERROR(VLOOKUP($AV$2,Sheet1!AD9:AG9,3,0),0) -> 0 | AW9: =+IFERROR(VLOOKUP($AW$2,Sheet1!AD9:AG9,3,0),0) -> 0 | AX9: =+IFERROR(VLOOKUP($AX$2,Sheet1!AD9:AG9,3,0),0) -> 0 | AY9: =+IFERROR(VLOOKUP($AY$2,Sheet1!AD9:AG9,3,0),0) -> 0 | AZ9: =+IFERROR(VLOOKUP($AZ$2,Sheet1!AD9:AG9,3,0),0) -> 0 | BA9: =+IFERROR(VLOOKUP($BA$2,Sheet1!AH9:AK9,3,0),0) -> 0 | BB9: =+IFERROR(VLOOKUP($BB$2,Sheet1!AH9:AK9,3,0),0) -> 0 | BC9: =+IFERROR(VLOOKUP($BC$2,Sheet1!AH9:AK9,3,0),0) -> 0 | BD9: =+IFERROR(VLOOKUP($BD$2,Sheet1!AH9:AK9,3,0),0) -> 0 | BE9: =+IFERROR(VLOOKUP($BE$2,Sheet1!AH9:AK9,3,0),0) -> 0 | BF9: =+IFERROR(VLOOKUP($BF$2,Sheet1!AH9:AK9,3,0),0) -> 0 | BG9: =+IFERROR(VLOOKUP($BG$2,Sheet1!AH9:AK9,3,0),0) -> 0 | BH9: =+IFERROR(VLOOKUP($BH$2,Sheet1!AH9:AK9,3,0),0) -> 0 | BI9: =+IFERROR(VLOOKUP($BI$2,Sheet1!AH9:AK9,3,0),0) -> 0 | BJ9: =+IFERROR(VLOOKUP($BJ$2,Sheet1!AH9:AK9,3,0),0) -> 314 | BK9: =+IFERROR(VLOOKUP($BK$2,Sheet1!AH9:AK9,3,0),0) -> 0 | BL9: =+IFERROR(VLOOKUP($BL$2,Sheet1!AL9:AO9,3,0),0) -> 0 | BM9: =+IFERROR(VLOOKUP($BM$2,Sheet1!AL9:AO9,3,0),0) -> 0 | BN9: =+IFERROR(VLOOKUP($BN$2,Sheet1!AL9:AO9,3,0),0) -> 118 | BO9: =+IFERROR(VLOOKUP($BO$2,Sheet1!AL9:AO9,3,0),0) -> 0 | BP9: =+IFERROR(VLOOKUP($BP$2,Sheet1!AL9:AO9,3,0),0) -> 0 | BQ9: =+IFERROR(VLOOKUP($BQ$2,Sheet1!AL9:AO9,3,0),0) -> 0 | BR9: =+IFERROR(VLOOKUP($BR$2,Sheet1!AL9:AO9,3,0),0) -> 0 | BS9: =+IFERROR(VLOOKUP($BS$2,Sheet1!AL9:AO9,3,0),0) -> 0 | BT9: =+IFERROR(VLOOKUP($BT$2,Sheet1!AL9:AO9,3,0),0) -> 0 | BU9: =+IFERROR(VLOOKUP($BU$2,Sheet1!AL9:AO9,3,0),0) -> 0 | BV9: =+IFERROR(VLOOKUP($BV$2,Sheet1!AL9:AO9,3,0),0) -> 0 | BW9: =+IFERROR(VLOOKUP($BW$2,Sheet1!AL9:AO9,3,0),0) -> 0 | BX9: =+IFERROR(VLOOKUP($BX$2,Sheet1!AP9:AS9,3,0),0) -> 0 | BY9: =+IFERROR(VLOOKUP($BY$2,Sheet1!AT9:AW9,3,0),0) -> 0 | BZ9: =+IFERROR(VLOOKUP($BZ$2,Sheet1!AX9:BA9,3,0),0) -> 0 | CA9: =+IFERROR(VLOOKUP($CA$2,Sheet1!BB9:BE9,3,0),0) -> 0 | CB9: =+IFERROR(VLOOKUP($CB$2,Sheet1!BF9:BI9,3,0),0) -> 0 | CC9: =+IFERROR(VLOOKUP($CC$2,Sheet1!BJ9:BM9,3,0),0) -> 0 | CD9: =+IFERROR(VLOOKUP($CD$2,Sheet1!BN9:BQ9,3,0),0) -> 0 | CE9: =+IFERROR(VLOOKUP($CE$2,Sheet1!BR9:BU9,3,0),0) -> 0 | CF9: =+IFERROR(VLOOKUP($CF$2,Sheet1!BV9:BY9,3,0),0) -> 0 | CG9: STEEL | CH9: MD0200019 | CI9: STEEL DRUM - 35" X 16 X 22 | CJ9: 500 | CK9: =3600/0.5 -> 7200 | CL9: =SUMPRODUCT($N$3:$CF$3,N9:CF9)+CK9 -> 63360 | CM9: =Sheet1!CB9 -> 0 | CN9: =CL9*CM9 -> 0 | CO9: 0.15 | CP9: =CL9*CO9 -> 9504 | CQ9: 0 | CR9: =CL9*CQ9 -> 0 | CS9: =CL9+CN9+CP9+CR9 -> 72864 | CT9: 0.02 | CU9: =CS9*CT9 -> 1457.28 | CV9: 0.01 | CW9: =CS9*CV9 -> 728.64 | CX9: =Sheet1!CM9 -> 0 | CY9: =CX9*CS9 -> 0 | DA9: =263*1000 -> 263000 | DB9: =DA9*15% -> 39450 | DC9: =DA9*11.5% -> 30245 | DE9: =DA9+DB9+DC9+DD9 -> 332695 | DF9: =((DE9-E9)/DE9)*100 -> 77.441825
A10: =Sheet1!A6 -> ENQ-16887-25-26 | B10: 45902 | C10: =Sheet1!C6 -> FA0700002 | D10: =Sheet1!D6 -> 1 CORE X 630 SQ. MM. AL/ARD (XLPE) | E10: =CS10+CU10+CW10+CY10 -> 847566.61 | F10: =ROUNDUP(M28,0) -> 12858 | G10: =E10+F10 -> 860424.61 | H10: =Sheet1!CR6 -> 0.18 | I10: =G10*H10 -> 154876.43 | J10: =G10+I10 -> 1015301 | K10: =Sheet1!CU6 -> 7 | L10: =Sheet1!CV6 -> KMS | M10: =J10*K10 -> 7107107.2 | N10: =+IFERROR(VLOOKUP($N$2,Sheet1!J6:L6,3,0),0) -> 1701 | O10: =+IFERROR(VLOOKUP($O$2,Sheet1!J6:L6,3,0),0) -> 0 | P10: =+IFERROR(VLOOKUP($P$2,Sheet1!J6:M6,3,0),0) -> 0 | Q10: =+IFERROR(VLOOKUP($Q$2,Sheet1!J6:M6,3,0),0) -> 0 | R10: =+IFERROR(VLOOKUP($R$2,Sheet1!J6:M6,3,0),0) -> 0 | S10: =+IFERROR(VLOOKUP($S$2,Sheet1!J6:M6,3,0),0) -> 0 | T10: =+IFERROR(VLOOKUP($T$2,Sheet1!J6:M6,3,0),0) -> 0 | U10: =+IFERROR(VLOOKUP($U$2,Sheet1!J6:M6,3,0),0) -> 0 | V10: =+IFERROR(VLOOKUP($V$2,Sheet1!N6:Q6,3,0),0) -> 0 | W10: =+IFERROR(VLOOKUP($W$2,Sheet1!N6:Q6,3,0),0) -> 0 | X10: =+IFERROR(VLOOKUP($X$2,Sheet1!F6:I6,3,0),0) -> 0 | Y10: =+IFERROR(VLOOKUP($Y$2,Sheet1!F6:I6,3,0),0) -> 0 | Z10: =+IFERROR(VLOOKUP($Z$2,Sheet1!F6:I6,3,0),0) -> 0 | AA10: =+IFERROR(VLOOKUP($AA$2,Sheet1!F6:I6,3,0),0) -> 0 | AB10: =+IFERROR(VLOOKUP($AB$2,Sheet1!F6:I6,3,0),0) -> 0 | AC10: =+IFERROR(VLOOKUP($AC$2,Sheet1!F6:I6,3,0),0) -> 0 | AD10: =+IFERROR(VLOOKUP($AD$2,Sheet1!F6:I6,3,0),0) -> 0 | AE10: =+IFERROR(VLOOKUP($AE$2,Sheet1!F6:I6,3,0),0) -> 0 | AF10: =+IFERROR(VLOOKUP($AF$2,Sheet1!R6:U6,3,0),0) -> 0 | AG10: =+IFERROR(VLOOKUP($AG$2,Sheet1!R6:U6,3,0),0) -> 0 | AH10: =+IFERROR(VLOOKUP($AH$2,Sheet1!V6:Y6,3,0),0) -> 0 | AI10: =+IFERROR(VLOOKUP($AI$2,Sheet1!V6:Y6,3,0),0) -> 295 | AJ10: =+IFERROR(VLOOKUP($AJ$2,Sheet1!V6:Y6,3,0),0) -> 0 | AK10: =+IFERROR(VLOOKUP($AK$2,Sheet1!V6:Y6,3,0),0) -> 0 | AL10: =+IFERROR(VLOOKUP($AL$2,Sheet1!V6:Y6,3,0),0) -> 0 | AM10: =+IFERROR(VLOOKUP($AM$2,Sheet1!V6:Y6,3,0),0) -> 0 | AN10: =+IFERROR(VLOOKUP($AN$2,Sheet1!V6:Y6,3,0),0) -> 0 | AO10: =+IFERROR(VLOOKUP($AO$2,Sheet1!V6:Y6,3,0),0) -> 0 | AP10: =+IFERROR(VLOOKUP($AP$2,Sheet1!V6:Y6,3,0),0) -> 0 | AQ10: =+IFERROR(VLOOKUP($AQ$2,Sheet1!Z6:AB6,3,0),0) -> 0 | AR10: =+IFERROR(VLOOKUP($AR$2,Sheet1!AD6:AG6,3,0),0) -> 0 | AS10: =+IFERROR(VLOOKUP($AS$2,Sheet1!AD6:AG6,3,0),0) -> 0 | AT10: =+IFERROR(VLOOKUP($AT$2,Sheet1!AD6:AG6,3,0),0) -> 0 | AU10: =+IFERROR(VLOOKUP($AU$2,Sheet1!AD6:AG6,3,0),0) -> 0 | AV10: =+IFERROR(VLOOKUP($AV$2,Sheet1!AD6:AG6,3,0),0) -> 0 | AW10: =+IFERROR(VLOOKUP($AW$2,Sheet1!AD6:AG6,3,0),0) -> 0 | AX10: =+IFERROR(VLOOKUP($AX$2,Sheet1!AD6:AG6,3,0),0) -> 0 | AY10: =+IFERROR(VLOOKUP($AY$2,Sheet1!AD6:AG6,3,0),0) -> 0 | AZ10: =+IFERROR(VLOOKUP($AZ$2,Sheet1!AD6:AG6,3,0),0) -> 0 | BA10: =+IFERROR(VLOOKUP($BA$2,Sheet1!AH6:AK6,3,0),0) -> 0 | BB10: =+IFERROR(VLOOKUP($BB$2,Sheet1!AH6:AK6,3,0),0) -> 0 | BC10: =+IFERROR(VLOOKUP($BC$2,Sheet1!AH6:AK6,3,0),0) -> 0 | BD10: 552 | BE10: =+IFERROR(VLOOKUP($BE$2,Sheet1!AH6:AK6,3,0),0) -> 0 | BF10: =+IFERROR(VLOOKUP($BF$2,Sheet1!AH6:AK6,3,0),0) -> 0 | BG10: =+IFERROR(VLOOKUP($BG$2,Sheet1!AH6:AK6,3,0),0) -> 0 | BH10: =+IFERROR(VLOOKUP($BH$2,Sheet1!AH6:AK6,3,0),0) -> 0 | BI10: =+IFERROR(VLOOKUP($BI$2,Sheet1!AH6:AK6,3,0),0) -> 0 | BJ10: =+IFERROR(VLOOKUP($BJ$2,Sheet1!AH6:AK6,3,0),0) -> 0 | BK10: =+IFERROR(VLOOKUP($BK$2,Sheet1!AH6:AK6,3,0),0) -> 0 | BL10: =+IFERROR(VLOOKUP($BL$2,Sheet1!AL6:AO6,3,0),0) -> 0 | BM10: =+IFERROR(VLOOKUP($BM$2,Sheet1!AL6:AO6,3,0),0) -> 0 | BN10: =+IFERROR(VLOOKUP($BN$2,Sheet1!AL6:AO6,3,0),0) -> 0 | BO10: 382 | BP10: =+IFERROR(VLOOKUP($BP$2,Sheet1!AL6:AO6,3,0),0) -> 0 | BQ10: =+IFERROR(VLOOKUP($BQ$2,Sheet1!AL6:AO6,3,0),0) -> 0 | BR10: =+IFERROR(VLOOKUP($BR$2,Sheet1!AL6:AO6,3,0),0) -> 0 | BS10: =+IFERROR(VLOOKUP($BS$2,Sheet1!AL6:AO6,3,0),0) -> 0 | BT10: =+IFERROR(VLOOKUP($BT$2,Sheet1!AL6:AO6,3,0),0) -> 0 | BU10: =+IFERROR(VLOOKUP($BU$2,Sheet1!AL6:AO6,3,0),0) -> 0 | BV10: =+IFERROR(VLOOKUP($BV$2,Sheet1!AL6:AO6,3,0),0) -> 0 | BW10: =+IFERROR(VLOOKUP($BW$2,Sheet1!AL6:AO6,3,0),0) -> 0 | BX10: =+IFERROR(VLOOKUP($BX$2,Sheet1!AP6:AS6,3,0),0) -> 0 | BY10: =+IFERROR(VLOOKUP($BY$2,Sheet1!AT6:AW6,3,0),0) -> 0 | BZ10: =+IFERROR(VLOOKUP($BZ$2,Sheet1!AX6:BA6,3,0),0) -> 0 | CA10: =+IFERROR(VLOOKUP($CA$2,Sheet1!BB6:BE6,3,0),0) -> 0 | CB10: =+IFERROR(VLOOKUP($CB$2,Sheet1!BF6:BI6,3,0),0) -> 0 | CC10: =+IFERROR(VLOOKUP($CC$2,Sheet1!BJ6:BM6,3,0),0) -> 0 | CD10: =+IFERROR(VLOOKUP($CD$2,Sheet1!BN6:BQ6,3,0),0) -> 0 | CE10: =+IFERROR(VLOOKUP($CE$2,Sheet1!BR6:BU6,3,0),0) -> 0 | CF10: =+IFERROR(VLOOKUP($CF$2,Sheet1!BV6:BY6,3,0),0) -> 0 | CG10: STEEL | CH10: SP0400125 | CI10: CORRUGATED DISPATCH STEEL DRUM 1600 X 700 X 915 MM | CJ10: 500 | CK10: =13500/0.5 -> 27000 | CL10: =SUMPRODUCT($N$3:$CF$3,N10:CF10)+CK10 -> 715548 | CM10: =Sheet1!CB6 -> 0 | CN10: =CL10*CM10 -> 0 | CO10: 0.15 | CP10: =CL10*CO10 -> 107332.2 | CQ10: 0 | CR10: =CL10*CQ10 -> 0 | CS10: =CL10+CN10+CP10+CR10 -> 822880.2 | CT10: 0.02 | CU10: =CS10*CT10 -> 16457.604 | CV10: 0.01 | CW10: =CS10*CV10 -> 8228.802 | CX10: =Sheet1!CM6 -> 0 | CY10: =CX10*CS10 -> 0 | DA10: =3233*1000 -> 3233000 | DC10: =DA10*7.5% -> 242475 | DD10: =DA10*30% -> 969900 | DE10: =DA10+DB10+DC10+DD10 -> 4445375 | DF10: =((DE10-E10)/DE10)*100 -> 80.933743
A11: =Sheet1!A11 -> ENQ-16887-25-26 | B11: 45902 | C11: =Sheet1!C11 -> FA1100085 | D11: =Sheet1!D11 -> 3.5 CORE X 300 SQ. MM. AL/ARD - WIRE (XLPE) | E11: =CS11+CU11+CW11+CY11 -> 1404799.2 | F11: =ROUNDUP(M29,0) -> 31765 | G11: =E11+F11 -> 1436564.2 | H11: =Sheet1!CR11 -> 0.18 | I11: =G11*H11 -> 258581.56 | J11: =G11+I11 -> 1695145.8 | K11: =Sheet1!CU11 -> 17 | L11: =Sheet1!CV11 -> KMS | M11: =J11*K11 -> 28817479 | N11: =+IFERROR(VLOOKUP($N$2,Sheet1!J11:L11,3,0),0) -> 2835 | O11: =+IFERROR(VLOOKUP($O$2,Sheet1!J11:L11,3,0),0) -> 0 | P11: =+IFERROR(VLOOKUP($P$2,Sheet1!J11:M11,3,0),0) -> 0 | Q11: =+IFERROR(VLOOKUP($Q$2,Sheet1!J11:M11,3,0),0) -> 0 | R11: =+IFERROR(VLOOKUP($R$2,Sheet1!J11:M11,3,0),0) -> 0 | S11: =+IFERROR(VLOOKUP($S$2,Sheet1!J11:M11,3,0),0) -> 0 | T11: =+IFERROR(VLOOKUP($T$2,Sheet1!J11:M11,3,0),0) -> 0 | U11: =+IFERROR(VLOOKUP($U$2,Sheet1!J11:M11,3,0),0) -> 0 | V11: =+IFERROR(VLOOKUP($V$2,Sheet1!N11:Q11,3,0),0) -> 0 | W11: =+IFERROR(VLOOKUP($W$2,Sheet1!N11:Q11,3,0),0) -> 0 | X11: =+IFERROR(VLOOKUP($X$2,Sheet1!F11:I11,3,0),0) -> 0 | Y11: =+IFERROR(VLOOKUP($Y$2,Sheet1!F11:I11,3,0),0) -> 0 | Z11: =+IFERROR(VLOOKUP($Z$2,Sheet1!F11:I11,3,0),0) -> 0 | AA11: =+IFERROR(VLOOKUP($AA$2,Sheet1!F11:I11,3,0),0) -> 0 | AB11: =+IFERROR(VLOOKUP($AB$2,Sheet1!F11:I11,3,0),0) -> 0 | AC11: =+IFERROR(VLOOKUP($AC$2,Sheet1!F11:I11,3,0),0) -> 0 | AD11: =+IFERROR(VLOOKUP($AD$2,Sheet1!F11:I11,3,0),0) -> 0 | AE11: =+IFERROR(VLOOKUP($AE$2,Sheet1!F11:I11,3,0),0) -> 0 | AF11: =+IFERROR(VLOOKUP($AF$2,Sheet1!R11:U11,3,0),0) -> 0 | AG11: =+IFERROR(VLOOKUP($AG$2,Sheet1!R11:U11,3,0),0) -> 0 | AH11: =+IFERROR(VLOOKUP($AH$2,Sheet1!V11:Y11,3,0),0) -> 0 | AI11: =+IFERROR(VLOOKUP($AI$2,Sheet1!V11:Y11,3,0),0) -> 430 | AJ11: =+IFERROR(VLOOKUP($AJ$2,Sheet1!V11:Y11,3,0),0) -> 0 | AK11: =+IFERROR(VLOOKUP($AK$2,Sheet1!V11:Y11,3,0),0) -> 0 | AL11: =+IFERROR(VLOOKUP($AL$2,Sheet1!V11:Y11,3,0),0) -> 0 | AM11: =+IFERROR(VLOOKUP($AM$2,Sheet1!V11:Y11,3,0),0) -> 0 | AN11: =+IFERROR(VLOOKUP($AN$2,Sheet1!V11:Y11,3,0),0) -> 0 | AO11: =+IFERROR(VLOOKUP($AO$2,Sheet1!V11:Y11,3,0),0) -> 0 | AP11: =+IFERROR(VLOOKUP($AP$2,Sheet1!V11:Y11,3,0),0) -> 0 | AQ11: =+IFERROR(VLOOKUP($AQ$2,Sheet1!Z11:AB11,3,0),0) -> 0 | AR11: =+IFERROR(VLOOKUP($AR$2,Sheet1!AD11:AG11,3,0),0) -> 0 | AS11: =+IFERROR(VLOOKUP($AS$2,Sheet1!AD11:AG11,3,0),0) -> 245 | AT11: =+IFERROR(VLOOKUP($AT$2,Sheet1!AD11:AG11,3,0),0) -> 0 | AU11: =+IFERROR(VLOOKUP($AU$2,Sheet1!AD11:AG11,3,0),0) -> 0 | AV11: =+IFERROR(VLOOKUP($AV$2,Sheet1!AD11:AG11,3,0),0) -> 0 | AW11: =+IFERROR(VLOOKUP($AW$2,Sheet1!AD11:AG11,3,0),0) -> 0 | AX11: =+IFERROR(VLOOKUP($AX$2,Sheet1!AD11:AG11,3,0),0) -> 0 | AY11: =+IFERROR(VLOOKUP($AY$2,Sheet1!AD11:AG11,3,0),0) -> 0 | AZ11: =+IFERROR(VLOOKUP($AZ$2,Sheet1!AD11:AG11,3,0),0) -> 0 | BA11: =+IFERROR(VLOOKUP($BA$2,Sheet1!AH11:AK11,3,0),0) -> 0 | BB11: =+IFERROR(VLOOKUP($BB$2,Sheet1!AH11:AK11,3,0),0) -> 0 | BC11: =+IFERROR(VLOOKUP($BC$2,Sheet1!AH11:AK11,3,0),0) -> 0 | BD11: =+IFERROR(VLOOKUP($BD$2,Sheet1!AH11:AK11,3,0),0) -> 0 | BE11: =+IFERROR(VLOOKUP($BE$2,Sheet1!AH11:AK11,3,0),0) -> 0 | BF11: =+IFERROR(VLOOKUP($BF$2,Sheet1!AH11:AK11,3,0),0) -> 0 | BG11: =+IFERROR(VLOOKUP($BG$2,Sheet1!AH11:AK11,3,0),0) -> 0 | BH11: =+IFERROR(VLOOKUP($BH$2,Sheet1!AH11:AK11,3,0),0) -> 0 | BI11: =+IFERROR(VLOOKUP($BI$2,Sheet1!AH11:AK11,3,0),0) -> 0 | BJ11: 2927 | BK11: =+IFERROR(VLOOKUP($BK$2,Sheet1!AH11:AK11,3,0),0) -> 0 | BL11: =+IFERROR(VLOOKUP($BL$2,Sheet1!AL11:AO11,3,0),0) -> 0 | BM11: =+IFERROR(VLOOKUP($BM$2,Sheet1!AL11:AO11,3,0),0) -> 0 | BN11: =+IFERROR(VLOOKUP($BN$2,Sheet1!AL11:AO11,3,0),0) -> 0 | BO11: 724 | BP11: =+IFERROR(VLOOKUP($BP$2,Sheet1!AL11:AO11,3,0),0) -> 0 | BQ11: =+IFERROR(VLOOKUP($BQ$2,Sheet1!AL11:AO11,3,0),0) -> 0 | BR11: =+IFERROR(VLOOKUP($BR$2,Sheet1!AL11:AO11,3,0),0) -> 0 | BS11: =+IFERROR(VLOOKUP($BS$2,Sheet1!AL11:AO11,3,0),0) -> 0 | BT11: =+IFERROR(VLOOKUP($BT$2,Sheet1!AL11:AO11,3,0),0) -> 0 | BU11: =+IFERROR(VLOOKUP($BU$2,Sheet1!AL11:AO11,3,0),0) -> 0 | BV11: =+IFERROR(VLOOKUP($BV$2,Sheet1!AL11:AO11,3,0),0) -> 0 | BW11: =+IFERROR(VLOOKUP($BW$2,Sheet1!AL11:AO11,3,0),0) -> 0 | BX11: =+IFERROR(VLOOKUP($BX$2,Sheet1!AP11:AS11,3,0),0) -> 0 | BY11: =+IFERROR(VLOOKUP($BY$2,Sheet1!AT11:AW11,3,0),0) -> 0 | BZ11: =+IFERROR(VLOOKUP($BZ$2,Sheet1!AX11:BA11,3,0),0) -> 0 | CA11: =+IFERROR(VLOOKUP($CA$2,Sheet1!BB11:BE11,3,0),0) -> 0 | CB11: =+IFERROR(VLOOKUP($CB$2,Sheet1!BF11:BI11,3,0),0) -> 0 | CC11: =+IFERROR(VLOOKUP($CC$2,Sheet1!BJ11:BM11,3,0),0) -> 0 | CD11: =+IFERROR(VLOOKUP($CD$2,Sheet1!BN11:BQ11,3,0),0) -> 0 | CE11: =+IFERROR(VLOOKUP($CE$2,Sheet1!BR11:BU11,3,0),0) -> 0 | CF11: =+IFERROR(VLOOKUP($CF$2,Sheet1!BV11:BY11,3,0),0) -> 0 | CG11: STEEL | CH11: SP0400112 | CI11: CORRUGATED DISPATCH STEEL DRUM 2000 X 1000 X 1000 MM | CJ11: 500 | CK11: =18000/0.5 -> 36000 | CL11: =SUMPRODUCT($N$3:$CF$3,N11:CF11)+CK11 -> 1185985 | CM11: =Sheet1!CB11 -> 0 | CN11: =CL11*CM11 -> 0 | CO11: 0.15 | CP11: =CL11*CO11 -> 177897.75 | CQ11: 0 | CR11: =CL11*CQ11 -> 0 | CS11: =CL11+CN11+CP11+CR11 -> 1363882.8 | CT11: 0.02 | CU11: =CS11*CT11 -> 27277.655 | CV11: 0.01 | CW11: =CS11*CV11 -> 13638.827 | CX11: =Sheet1!CM11 -> 0 | CY11: =CX11*CS11 -> 0 | DA11: =4986*1000 -> 4986000 | DC11: =DA11*7.5% -> 373950 | DD11: =DA11*30% -> 1495800 | DE11: =DA11+DB11+DC11+DD11 -> 6855750 | DF11: =((DE11-E11)/DE11)*100 -> 79.509182
