Workbook

Sheet Sheet1
A1: DOCKET NO. | B1: Base Date | C1: ITEM CODE | D1: PROPOSE ERP ITEM NAME | E1: Propose Drum Type | F1: Insulation Screening(Metallic) | G1: RM Rate(Insulation Screening(Metallic)) | H1: Weight (Insulation Screening (Metallic)) | I1: Cost Insulation Screening(Metallic) | J1: Conductor | K1: RM Rate(Conductor) | L1: Weight(Conductor) | M1: Cost(Conductor) | N1: AL ALLOY | O1: RM Rate(AL Alloy) | P1: Weight(Al Alloy) | Q1: Cost(AL Alloy) | R1: Insulation Screening(Non-Metallic) | S1: RM Rate(Insulation Screening(Non-Metallic)) | T1: Weight(Insulation Screening(Non-Metallic) | U1: Cost(Insulation Screening(Non-Metallic) | V1: Insulation | W1: RM Rate(Insulation) | X1: Weight(Insulation) | Y1: Cost(Insulation) | Z1: Poly Tape | AA1: RM Rate(Poly Tape) | AB1: Weight(Poly Tape) | AC1: Cost(Poly Tape) | AD1: Inner Sheath | AE1: RM Rate(Inner Sheath) | AF1: Weight(Inner Sheath) | AG1: Cost(Inner Sheath) | AH1: Armouring | AI1: RM Rate(Armouring) | AJ1: Weight(Armouring) | AK1: Cost(Armouring) | AL1: Outer Sheath | AM1: RM Rate(Outer Sheath) | AN1: Weight(Outer Sheath) | AO1: Cost(Outer Sheath) | AP1: Filler | AQ1: RM Rate(Filler) | AR1: Weight(Filler) | AS1: Cost(Filler) | AT1: Grease | AU1: RM Rate(Grease) | AV1: Weight(Grease) | AW1: Cost(Grease) | AX1: Water Swellable Tape | AY1: RM Rate(Water Swellable Tape) | AZ1: Weight(Water Swellable Tape) | BA1: Cost(Water Swellable Tape) | BB1: Semi Conducting Water Swellable Tape | BC1: RM Rate(Semi Conducting Water Swellable Tape) | BD1: Weight(Semi Conducting Water Swellable Tape) | BE1: Cost(Semi Conducting Water Swellable Tape) | BF1: Semicon Tape | BG1: RM Rate(Semicon Tape) | BH1: Weight(Semicon Tape) | BI1: Cost(Semicon Tape) | BJ1: Glass Fiber Tape | BK1: RM Rate(Glass Fiber Tape) | BL1: Weight(Glass Fiber Tape) | BM1: Cost(Glass Fiber Tape) | BN1: Copper Wire 0.8MM | BO1: RM Rate(Copper Wire 0.8MM) | BP1: Weight(Copper Wire 0.8MM) | BQ1: Cost(Copper Wire 0.8MM) | BR1: Rubberized Cotton Tape | BS1: RM Rate(Rubberized Cotton Tape) | BT1: Weight(Rubberized Cotton Tape) | BU1: Cost(Rubberized Cotton Tape) | BV1: Water Tight Compound | BW1: RM Rate(Water Tight Compound) | BX1: Weight(Water Tight Compound) | BY1: Cost(Water Tight Compound) | BZ1: Drum Cost Per KM | CA1: Total RM Cost | CB1: FIRM % | CC1: Firm Value | CD1: MFG% | CE1: MFG Value | CF1: PROF% | CG1: Profit Value | CH1: 1st EX-Works | CI1: Intt % | CJ1: Intt Value | CK1: insp% | CL1: Insp Value | CM1: TTR CHARGES% | CN1: TTR Value | CO1: EX-Works Per KM | CP1: Freight Per KM | CQ1: Price Including Freight Per KM | CR1: GST % | CS1: GST Value | CT1: Price Including GST & Freight Per KM | CU1: QTY | CV1: Unit | CW1: Total Price Of Full QTY(Including Freight&GST) | CX1: PARTY LENGTH (IF STANDER LENGTH NOT MATCH WITH PAR | CY1: DRUM CODE | CZ1: DRUM SIZE (FxbXtx Ft)
A2: ENQ-19953-25-26 | C2: FC3700003 | D2: ACSR : PANTHER CONDUCTOR - 200 SQ. MM. (30/7/3.00) | E2: WOOD | H2: 0 | J2: Alumimium | L2: 588 | P2: 0 | T2: 0 | X2: 0 | AB2: 0 | AF2: 0 | AH2: ACSR CORE WIRE | AJ2: 388 | AN2: 0 | AR2: 0 | AV2: 0 | AZ2: 0 | BD2: 0 | BH2: 0 | BL2: 0 | BP2: 0 | BT2: 0 | BX2: 0 | BZ2: 3956 | CA2: 3956 | CH2: 3956 | CO2: 3956 | CQ2: 3956 | CR2: 0.18 | CS2: 712.08 | CT2: 4668.08 | CU2: 80 | CV2: KMS | CW2: 373446 | CY2: MD0100061 | CZ2: DRUM - 56 X 24 X 32 X 3

Sheet BOQ1
P1: Conductor | X1: AL ALLOY | Z1: Insulation Screening (Metallic) | AH1: Insulation Screening (Non-Metallic) | AJ1: Insulation | AS1: POLY TAPE | AT1: Inner Sheath | BC1: Armouring | BN1: Outer Sheath | BZ1: FILLER | CA1: GREASE | CB1: Water swellable Tape | CC1: Semi conducting Water Swellable tape | CD1: SEMICON TAPE | CE1: GLASS FIBER TAPE | CF1: COPPER WIRE 0.8 MM | CG1: RUBBERIZED COTTON TAPE | CH1: Water Tight Compound | CI1: DRUM TYPE | CM1: DRUM COST PER KM | CN1: TOTAL RM COST | CO1: EXTRA CONSUMPTION | CP1: EXTRA CONSUMPTION VALUE | DB1: $A$1
A2: DOCKET NO. | B2: BASE DATE | C2: ITEM CODE | D2: PROPOSE ERP ITEM NAME | E2: EX-WORKS (PER KM) | F2: FREIGHT PER KM | G2: PRICE INCLUDING FREIGHT (PER KM) | H2: TOTAL PRICE WITHOUT TAX | I2: GST % | J2: GST VALUE | K2: PRICE INCLUDING GST & FREIGHT (PER KM) | L2: QTY | M2: Unit | N2: TOTAL PRICE OF FULL QTY (INCLUDING FRIGHT & GST) | O2: NON CHAIN BOM ID | P2: Alumimium | Q2: Alumimium ALLOY | R2: Copper | S2: AL-59 | T2: AL-4 | U2: AL-7 | V2: Flexible Copper | W2: Galvanized steel wire | X2: Alumimium | Y2: Alumimium ALLOY | Z2: Coper tape - 0.1 mm | AA2: Copper Tape - 0.03 mm | AB2: Copper Tape - 0.035 mm | AC2: Copper Tape - 0.04 mm | AD2: Copper Tape - 0.045 mm | AE2: Copper Tape - 0.050 mm | AF2: Copper Tape - 0.060 mm | AG2: Copper Tape - 0.075 mm(DOUBLE) | AH2: Extruded semiconductive | AI2: Extruded Semiconductive(Stripable) | AJ2: HT-XLPE | AK2: LT-XLPE | AL2: TR XLPE | AM2: Type A PVC | AN2: Type C PVC (HR) | AO2: Type A PVC-1.45 | AP2: Type A PVC-FR | AQ2: Type A PVC-FRLS | AR2: Type A PVC-1.38 | AS2: POLY TAPE | AT2: FR PVC Type ST-1 | AU2: FR PVC Type ST-2 | AV2: FRLSH PVC Type ST-1 | AW2: FRLSH PVC Type ST-2 | AX2: PVC Type ST-1 | AY2: PVC Type ST-1-PRESSURE EXTRUDED | AZ2: PVC Type ST-2 | BA2: PVC COMPOUND 1.48 | BB2: PVC Type ST-2-PRESSURE EXTRUDED | BC2: ACSR CORE WIRE | BD2: ACSR DOG STEEL WIRE | BE2: Aluminium Flat Strip | BF2: Aluminium Round Wire | BG2: Alumimium Tape | BH2: Double Steel Tape | BI2: Galvanised Steel Flat Strip | BJ2: Galvanised Steel Flat Strip (Double) | BK2: Galvanised Steel Flat Strip-B | BL2: Galvanised Steel Round Wire | BM2: Galvanised Steel Round Wire (Double) | BN2: FR PVC Type ST-1 | BO2: FR PVC Type ST-2 | BP2: FRLSH PVC Type ST-1 | BQ2: FRLSH PVC Type ST-2 | BR2: ZHFR | BS2: PE-ST-3 | BT2: PE-ST-7 | BU2: PVC Type ST-1 | BV2: PVC Type ST-2 | BW2: PVC COMPOUND 1.48 | BX2: PVC Type ST-2-PRESSURE EXTRUDED | BY2: UV & Track Resistant XLPE | BZ2: FILLER | CA2: Grease | CB2: Water swellable Tape | CC2: Semi conducting Water Swellable tape | CD2: SEMICON TAPE | CE2: GLASS FIBER TAPE | CF2: COPPER WIRE 0.8 MM | CG2: RUBBERIZED COTTON TAPE | CH2: Water Tight Compound | CI2: PROPOSE DRUM TYPE | CJ2: DRUM CODE | CK2: DRUM SIZE (FxbXtx Ft) | CL2: PARTY STANDARD LENGTH (MTR) | CO2: FREIGHT CHARGES FOR INSULATOR & ACCESSORIES | CQ2: MFG% | CR2: MFG VALUE | CS2: PROF% | CT2: PROFIT VALUE | CU2: 1ST EX-WORKS | CV2: Intt % | CW2: INTT VALUE | CX2: insp% | CY2: INSP VALUE | CZ2: TTR Charges% | DA2: TTR Charges VALUE
P3: 388 | Q3: =+IFERROR(VLOOKUP($Q$2,Sheet1!J:L,2,0),0) -> 0 | R3: =+IFERROR(VLOOKUP($R$2,Sheet1!J:M,2,0),0) -> 0 | S3: =+IFERROR(VLOOKUP($S$2,Sheet1!J:M,2,0),0) -> 0 | T3: =+IFERROR(VLOOKUP($T$2,Sheet1!J:M,2,0),0) -> 0 | U3: =+IFERROR(VLOOKUP($U$2,Sheet1!J:M,2,0),0) -> 0 | V3: =+IFERROR(VLOOKUP($V$2,Sheet1!J:M,2,0),0) -> 0 | W3: =+IFERROR(VLOOKUP($W$2,Sheet1!J:M,2,0),0) -> 0 | X3: =+IFERROR(VLOOKUP($X$2,Sheet1!N:Q,2,0),0) -> 0 | Y3: =+IFERROR(VLOOKUP($Y$2,Sheet1!N:O,2,0),0) -> 0 | Z3: =+IFERROR(VLOOKUP($Z$2,Sheet1!F:I,2,0),0) -> 0 | AA3: =+IFERROR(VLOOKUP($AA$2,Sheet1!F:I,2,0),0) -> 0 | AB3: =+IFERROR(VLOOKUP($AB$2,Sheet1!F:I,2,0),0) -> 0 | AC3: =+IFERROR(VLOOKUP($AC$2,Sheet1!F:I,2,0),0) -> 0 | AD3: =+IFERROR(VLOOKUP($AD$2,Sheet1!F:I,2,0),0) -> 0 | AE3: =+IFERROR(VLOOKUP($AE$2,Sheet1!F:I,2,0),0) -> 0 | AF3: =+IFERROR(VLOOKUP($AF$2,Sheet1!F:I,2,0),0) -> 0 | AG3: =+IFERROR(VLOOKUP($AG$2,Sheet1!F:I,2,0),0) -> 0 | AH3: =+IFERROR(VLOOKUP($AH$2,Sheet1!R:U,2,0),0) -> 0 | AI3: =+IFERROR(VLOOKUP($AI$2,Sheet1!R:U,2,0),0) -> 0 | AJ3: =+IFERROR(VLOOKUP($AJ$2,Sheet1!V:Y,2,0),0) -> 0 | AK3: =+IFERROR(VLOOKUP($AK$2,Sheet1!V:Y,2,0),0) -> 0 | AL3: =+IFERROR(VLOOKUP($AL$2,Sheet1!V:Y,2,0),0) -> 0 | AM3: =+IFERROR(VLOOKUP($AM$2,Sheet1!V:Y,2,0),0) -> 0 | AN3: =+IFERROR(VLOOKUP($AN$2,Sheet1!V:Y,2,0),0) -> 0 | AO3: =+IFERROR(VLOOKUP($AO$2,Sheet1!V:Y,2,0),0) -> 0 | AP3: =+IFERROR(VLOOKUP($AP$2,Sheet1!V:Y,2,0),0) -> 0 | AQ3: =+IFERROR(VLOOKUP($AQ$2,Sheet1!V:Y,2,0),0) -> 0 | AR3: =+IFERROR(VLOOKUP($AR$2,Sheet1!V:Y,2,0),0) -> 0 | AS3: =+IFERROR(VLOOKUP($AS$2,Sheet1!Z2:AA840,2,0),0) -> 0 | AT3: =+IFERROR(VLOOKUP($AT$2,Sheet1!AD2:AG840,2,0),0) -> 0 | AU3: =+IFERROR(VLOOKUP($AU$2,Sheet1!AD2:AG840,2,0),0) -> 0 | AV3: =+IFERROR(VLOOKUP($AV$2,Sheet1!AD2:AG840,2,0),0) -> 0 | AW3: =+IFERROR(VLOOKUP($AW$2,Sheet1!AD2:AG840,2,0),0) -> 0 | AX3: =+IFERROR(VLOOKUP($AX$2,Sheet1!AD2:AG840,2,0),0) -> 0 | AY3: =+IFERROR(VLOOKUP($AY$2,Sheet1!AD2:AG840,2,0),0) -> 0 | AZ3: =+IFERROR(VLOOKUP($AZ$2,Sheet1!AD2:AG840,2,0),0) -> 0 | BA3: =+IFERROR(VLOOKUP($BA$2,Sheet1!AD2:AG840,2,0),0) -> 0 | BB3: =+IFERROR(VLOOKUP($BB$2,Sheet1!AD2:AG840,2,0),0) -> 0 | BC3: 83 | BD3: =+IFERROR(VLOOKUP($BD$2,Sheet1!AH2:AK840,2,0),0) -> 0 | BE3: =+IFERROR(VLOOKUP($BE$2,Sheet1!AH2:AK840,2,0),0) -> 0 | BF3: =+IFERROR(VLOOKUP($BF$2,Sheet1!AH2:AK840,2,0),0) -> 0 | BG3: =+IFERROR(VLOOKUP($BG$2,Sheet1!AH2:AK840,2,0),0) -> 0 | BH3: =+IFERROR(VLOOKUP($BH$2,Sheet1!AH2:AK840,2,0),0) -> 0 | BI3: =+IFERROR(VLOOKUP($BI$2,Sheet1!AH2:AK840,2,0),0) -> 0 | BJ3: =+IFERROR(VLOOKUP($BJ$2,Sheet1!AH2:AK840,2,0),0) -> 0 | BK3: =+IFERROR(VLOOKUP($BK$2,Sheet1!AH2:AK840,2,0),0) -> 0 | BL3: =+IFERROR(VLOOKUP($BL$2,Sheet1!AH2:AK840,2,0),0) -> 0 | BM3: =+IFERROR(VLOOKUP($BM$2,Sheet1!AH2:AK840,2,0),0) -> 0 | BN3: =+IFERROR(VLOOKUP($BN$2,Sheet1!AL2:AO840,2,0),0) -> 0 | BO3: =+IFERROR(VLOOKUP($BO$2,Sheet1!AL2:AO840,2,0),0) -> 0 | BP3: =+IFERROR(VLOOKUP($BP$2,Sheet1!AL2:AO840,2,0),0) -> 0 | BQ3: =+IFERROR(VLOOKUP($BQ$2,Sheet1!AL2:AO840,2,0),0) -> 0 | BR3: =+IFERROR(VLOOKUP($BR$2,Sheet1!AL2:AO840,2,0),0) -> 0 | BS3: =+IFERROR(VLOOKUP($BS$2,Sheet1!AL2:AO840,2,0),0) -> 0 | BT3: =+IFERROR(VLOOKUP($BT$2,Sheet1!AL2:AO840,2,0),0) -> 0 | BU3: =+IFERROR(VLOOKUP($BU$2,Sheet1!AL2:AO840,2,0),0) -> 0 | BV3: =+IFERROR(VLOOKUP($BV$2,Sheet1!AL2:AO840,2,0),0) -> 0 | BW3: =+IFERROR(VLOOKUP($BW$2,Sheet1!AL2:AO840,2,0),0) -> 0 | BX3: =+IFERROR(VLOOKUP($BX$2,Sheet1!AL2:AO840,2,0),0) -> 0 | BY3: =+IFERROR(VLOOKUP($BY$2,Sheet1!AL2:AO840,2,0),0) -> 0 | BZ3: =+IFERROR(VLOOKUP($BZ$2,Sheet1!AP2:AS840,2,0),0) -> 0 | CA3: =+IFERROR(VLOOKUP($CA$2,Sheet1!AT2:AW840,2,0),0) -> 0 | CB3: =+IFERROR(VLOOKUP($CB$2,Sheet1!AX2:BA840,2,0),0) -> 0 | CC3: =+IFERROR(VLOOKUP($CC$2,Sheet1!BB2:BE840,2,0),0) -> 0 | CD3: =+IFERROR(VLOOKUP($CD$2,Sheet1!BF2:BI840,2,0),0) -> 0 | CE3: =+IFERROR(VLOOKUP($CE$2,Sheet1!BJ2:BM840,2,0),0) -> 0 | CF3: =+IFERROR(VLOOKUP($CF$2,Sheet1!BN2:BQ840,2,0),0) -> 0 | CG3: =+IFERROR(VLOOKUP($CG$2,Sheet1!BR2:BU840,2,0),0) -> 0 | CH3: =+IFERROR(VLOOKUP($CH$2,Sheet1!BV2:BY840,2,0),0) -> 0
A4: =Sheet1!A2 -> ENQ-19953-25-26 | B4: 46193 | C4: =Sheet1!C2 -> FC3700003 | D4: =Sheet1!D2 -> ACSR : PANTHER CONDUCTOR - 200 SQ. MM. (30/7/3.00) | E4: =CU4+CW4+CY4+DA4 -> 298756.8 | F4: =ROUNDUP(N28,0) -> 6000 | G4: =E4+F4 -> 304756.8 | H4: =G4*L4 -> 24380544 | I4: =Sheet1!CR2 -> 0.18 | J4: =G4*I4 -> 54856.225 | K4: =G4+J4 -> 359613.03 | L4: =Sheet1!CU2 -> 80 | M4: =Sheet1!CV2 -> KMS | N4: =K4*L4 -> 28769042 | O4: IS | P4: =+IFERROR(VLOOKUP($P$2,Sheet1!J2:L2,3,0),0) -> 588 | Q4: =+IFERROR(VLOOKUP($Q$2,Sheet1!J2:L2,3,0),0) -> 0 | R4: =+IFERROR(VLOOKUP($R$2,Sheet1!J2:M2,3,0),0) -> 0 | S4: =+IFERROR(VLOOKUP($S$2,Sheet1!J2:M2,3,0),0) -> 0 | T4: =+IFERROR(VLOOKUP($T$2,Sheet1!J2:M2,3,0),0) -> 0 | U4: =+IFERROR(VLOOKUP($U$2,Sheet1!J2:M2,3,0),0) -> 0 | V4: =+IFERROR(VLOOKUP($V$2,Sheet1!J2:M2,3,0),0) -> 0 | W4: =+IFERROR(VLOOKUP($W$2,Sheet1!J2:M2,3,0),0) -> 0 | X4: =+IFERROR(VLOOKUP($X$2,Sheet1!N2:Q2,3,0),0) -> 0 | Y4: =+IFERROR(VLOOKUP($Y$2,Sheet1!N2:Q2,3,0),0) -> 0 | Z4: =+IFERROR(VLOOKUP($Z$2,Sheet1!F2:I2,3,0),0) -> 0 | AA4: =+IFERROR(VLOOKUP($AA$2,Sheet1!F2:I2,3,0),0) -> 0 | AB4: =+IFERROR(VLOOKUP($AB$2,Sheet1!F2:I2,3,0),0) -> 0 | AC4: =+IFERROR(VLOOKUP($AC$2,Sheet1!F2:I2,3,0),0) -> 0 | AD4: =+IFERROR(VLOOKUP($AD$2,Sheet1!F2:I2,3,0),0) -> 0 | AE4: =+IFERROR(VLOOKUP($AE$2,Sheet1!F2:I2,3,0),0) -> 0 | AF4: =+IFERROR(VLOOKUP($AF$2,Sheet1!F2:I2,3,0),0) -> 0 | AG4: =+IFERROR(VLOOKUP($AG$2,Sheet1!F2:I2,3,0),0) -> 0 | AH4: =+IFERROR(VLOOKUP($AH$2,Sheet1!R2:U2,3,0),0) -> 0 | AI4: =+IFERROR(VLOOKUP($AI$2,Sheet1!R2:U2,3,0),0) -> 0 | AJ4: =+IFERROR(VLOOKUP($AJ$2,Sheet1!V2:Y2,3,0),0) -> 0 | AK4: =+IFERROR(VLOOKUP($AK$2,Sheet1!V2:Y2,3,0),0) -> 0 | AL4: =+IFERROR(VLOOKUP($AL$2,Sheet1!V2:Y2,3,0),0) -> 0 | AM4: =+IFERROR(VLOOKUP($AM$2,Sheet1!V2:Y2,3,0),0) -> 0 | AN4: =+IFERROR(VLOOKUP($AN$2,Sheet1!V2:Y2,3,0),0) -> 0 | AO4: =+IFERROR(VLOOKUP($AO$2,Sheet1!V2:Y2,3,0),0) -> 0 | AP4: =+IFERROR(VLOOKUP($AP$2,Sheet1!V2:Y2,3,0),0) -> 0 | AQ4: =+IFERROR(VLOOKUP($AQ$2,Sheet1!V2:Y2,3,0),0) -> 0 | AR4: =+IFERROR(VLOOKUP($AR$2,Sheet1!V2:Y2,3,0),0) -> 0 | AS4: =+IFERROR(VLOOKUP($AS$2,Sheet1!Z2:AB2,3,0),0) -> 0 | AT4: =+IFERROR(VLOOKUP($AT$2,Sheet1!AD2:AG2,3,0),0) -> 0 | AU4: =+IFERROR(VLOOKUP($AU$2,Sheet1!AD2:AG2,3,0),0) -> 0 | AV4: =+IFERROR(VLOOKUP($AV$2,Sheet1!AD2:AG2,3,0),0) -> 0 | AW4: =+IFERROR(VLOOKUP($AW$2,Sheet1!AD2:AG2,3,0),0) -> 0 | AX4: =+IFERROR(VLOOKUP($AX$2,Sheet1!AD2:AG2,3,0),0) -> 0 | AY4: =+IFERROR(VLOOKUP($AY$2,Sheet1!AD2:AG2,3,0),0) -> 0 | AZ4: =+IFERROR(VLOOKUP($AZ$2,Sheet1!AD2:AG2,3,0),0) -> 0 | BA4: =+IFERROR(VLOOKUP($BA$2,Sheet1!AD2:AG2,3,0),0) -> 0 | BB4: =+IFERROR(VLOOKUP($BB$2,Sheet1!AD2:AG2,3,0),0) -> 0 | BC4: =+IFERROR(VLOOKUP($BC$2,Sheet1!AH2:AK2,3,0),0) -> 388 | BD4: =+IFERROR(VLOOKUP($BD$2,Sheet1!AH2:AK2,3,0),0) -> 0 | BE4: =+IFERROR(VLOOKUP($BE$2,Sheet1!AH2:AK2,3,0),0) -> 0 | BF4: =+IFERROR(VLOOKUP($BF$2,Sheet1!AH2:AK2,3,0),0) -> 0 | BG4: =+IFERROR(VLOOKUP($BG$2,Sheet1!AH2:AK2,3,0),0) -> 0 | BH4: =+IFERROR(VLOOKUP($BH$2,Sheet1!AH2:AK2,3,0),0) -> 0 | BI4: =+IFERROR(VLOOKUP($BI$2,Sheet1!AH2:AK2,3,0),0) -> 0 | BJ4: =+IFERROR(VLOOKUP($BJ$2,Sheet1!AH2:AK2,3,0),0) -> 0 | BK4: =+IFERROR(VLOOKUP($BK$2,Sheet1!AH2:AK2,3,0),0) -> 0 | BL4: =+IFERROR(VLOOKUP($BL$2,Sheet1!AH2:AK2,3,0),0) -> 0 | BM4: =+IFERROR(VLOOKUP($BM$2,Sheet1!AH2:AK2,3,0),0) -> 0 | BN4: =+IFERROR(VLOOKUP($BN$2,Sheet1!AL2:AO2,3,0),0) -> 0 | BO4: =+IFERROR(VLOOKUP($BO$2,Sheet1!AL2:AO2,3,0),0) -> 0 | BP4: =+IFERROR(VLOOKUP($BP$2,Sheet1!AL2:AO2,3,0),0) -> 0 | BQ4: =+IFERROR(VLOOKUP($BQ$2,Sheet1!AL2:AO2,3,0),0) -> 0 | BR4: =+IFERROR(VLOOKUP($BR$2,Sheet1!AL2:AO2,3,0),0) -> 0 | BS4: =+IFERROR(VLOOKUP($BS$2,Sheet1!AL2:AO2,3,0),0) -> 0 | BT4: =+IFERROR(VLOOKUP($BT$2,Sheet1!AL2:AO2,3,0),0) -> 0 | BU4: =+IFERROR(VLOOKUP($BU$2,Sheet1!AL2:AO2,3,0),0) -> 0 | BV4: =+IFERROR(VLOOKUP($BV$2,Sheet1!AL2:AO2,3,0),0) -> 0 | BW4: =+IFERROR(VLOOKUP($BW$2,Sheet1!AL2:AO2,3,0),0) -> 0 | BX4: =+IFERROR(VLOOKUP($BX$2,Sheet1!AL2:AO2,3,0),0) -> 0 | BY4: =+IFERROR(VLOOKUP($BY$2,Sheet1!AL2:AO2,3,0),0) -> 0 | BZ4: =+IFERROR(VLOOKUP($BZ$2,Sheet1!AP2:AS2,3,0),0) -> 0 | CA4: =+IFERROR(VLOOKUP($CA$2,Sheet1!AT2:AW2,3,0),0) -> 0 | CB4: =+IFERROR(VLOOKUP($CB$2,Sheet1!AX2:BA2,3,0),0) -> 0 | CC4: =+IFERROR(VLOOKUP($CC$2,Sheet1!BB2:BE2,3,0),0) -> 0 | CD4: =+IFERROR(VLOOKUP($CD$2,Sheet1!BF2:BI2,3,0),0) -> 0 | CE4: =+IFERROR(VLOOKUP($CE$2,Sheet1!BJ2:BM2,3,0),0) -> 0 | CF4: =+IFERROR(VLOOKUP($CF$2,Sheet1!BN2:BQ2,3,0),0) -> 0 | CG4: =+IFERROR(VLOOKUP($CG$2,Sheet1!BR2:BU2,3,0),0) -> 0 | CH4: =+IFERROR(VLOOKUP($CH$2,Sheet1!BV2:BY2,3,0),0) -> 0 | CI4: =Sheet1!E2 -> WOOD | CJ4: =Sheet1!CY2 -> MD0100061 | CK4: =Sheet1!CZ2 -> DRUM - 56 X 24 X 32 X 3 | CL4: 2000 | CM4: =6677/2 -> 3338.5 | CN4: =SUMPRODUCT($P$3:$CH$3,P4:CH4)+CM4 -> 263686.5 | CO4: =Sheet1!CB2 -> 0 | CP4: =CN4*CO4 -> 0 | CQ4: 0.1 | CR4: =CN4*CQ4 -> 26368.65 | CS4: 0 | CT4: =CN4*CS4 -> 0 | CU4: =CN4+CP4+CR4+CT4 -> 290055.15 | CV4: 0.02 | CW4: =CU4*CV4 -> 5801.103 | CX4: 0.01 | CY4: =CU4*CX4 -> 2900.5515 | CZ4: =Sheet1!CM2 -> 0 | DA4: =CZ4*CU4 -> 0
A5: =Sheet1!A3 -> 0 | B5: =Sheet1!B3 -> 0 | C5: =Sheet1!C3 -> 0 | D5: Supply of Insulator | H5: =G5*L5 -> 0
A6: =Sheet1!A4 -> 0 | B6: =Sheet1!B4 -> 0 | C6: =Sheet1!C4 -> 0 | D6: 11KV Antifog Porcelain Insulator 70 KN Disc Insulator | E6: =CU6+CW6+CY6+DA6 -> 958.93 | G6: =E6+F6 -> 958.93 | H6: =G6*L6 -> 1701141.8 | I6: 0.18 | J6: =G6*I6 -> 172.6074 | K6: =G6+J6 -> 1131.5374 | L6: 1774 | M6: Nos | N6: =K6*L6 -> 2007347.3 | P6: =+IFERROR(VLOOKUP($P$2,Sheet1!J4:L4,3,0),0) -> 0 | Q6: =+IFERROR(VLOOKUP($Q$2,Sheet1!J4:L4,3,0),0) -> 0 | R6: =+IFERROR(VLOOKUP($R$2,Sheet1!J4:M4,3,0),0) -> 0 | S6: =+IFERROR(VLOOKUP($S$2,Sheet1!J4:M4,3,0),0) -> 0 | T6: =+IFERROR(VLOOKUP($T$2,Sheet1!J4:M4,3,0),0) -> 0 | U6: =+IFERROR(VLOOKUP($U$2,Sheet1!J4:M4,3,0),0) -> 0 | V6: =+IFERROR(VLOOKUP($V$2,Sheet1!J4:M4,3,0),0) -> 0 | W6: =+IFERROR(VLOOKUP($W$2,Sheet1!J4:M4,3,0),0) -> 0 | X6: =+IFERROR(VLOOKUP($X$2,Sheet1!N4:Q4,3,0),0) -> 0 | Y6: =+IFERROR(VLOOKUP($Y$2,Sheet1!N4:Q4,3,0),0) -> 0 | Z6: =+IFERROR(VLOOKUP($Z$2,Sheet1!F4:I4,3,0),0) -> 0 | AA6: =+IFERROR(VLOOKUP($AA$2,Sheet1!F4:I4,3,0),0) -> 0 | AB6: =+IFERROR(VLOOKUP($AB$2,Sheet1!F4:I4,3,0),0) -> 0 | AC6: =+IFERROR(VLOOKUP($AC$2,Sheet1!F4:I4,3,0),0) -> 0 | AD6: =+IFERROR(VLOOKUP($AD$2,Sheet1!F4:I4,3,0),0) -> 0 | AE6: =+IFERROR(VLOOKUP($AE$2,Sheet1!F4:I4,3,0),0) -> 0 | AF6: =+IFERROR(VLOOKUP($AF$2,Sheet1!F4:I4,3,0),0) -> 0 | AG6: =+IFERROR(VLOOKUP($AG$2,Sheet1!F4:I4,3,0),0) -> 0 | AH6: =+IFERROR(VLOOKUP($AH$2,Sheet1!R4:U4,3,0),0) -> 0 | AI6: =+IFERROR(VLOOKUP($AI$2,Sheet1!R4:U4,3,0),0) -> 0 | AJ6: =+IFERROR(VLOOKUP($AJ$2,Sheet1!V4:Y4,3,0),0) -> 0 | AK6: =+IFERROR(VLOOKUP($AK$2,Sheet1!V4:Y4,3,0),0) -> 0 | AL6: =+IFERROR(VLOOKUP($AL$2,Sheet1!V4:Y4,3,0),0) -> 0 | AM6: =+IFERROR(VLOOKUP($AM$2,Sheet1!V4:Y4,3,0),0) -> 0 | AN6: =+IFERROR(VLOOKUP($AN$2,Sheet1!V4:Y4,3,0),0) -> 0 | AO6: =+IFERROR(VLOOKUP($AO$2,Sheet1!V4:Y4,3,0),0) -> 0 | AP6: =+IFERROR(VLOOKUP($AP$2,Sheet1!V4:Y4,3,0),0) -> 0 | AQ6: =+IFERROR(VLOOKUP($AQ$2,Sheet1!V4:Y4,3,0),0) -> 0 | AR6: =+IFERROR(VLOOKUP($AR$2,Sheet1!V4:Y4,3,0),0) -> 0 | AS6: =+IFERROR(VLOOKUP($AS$2,Sheet1!Z4:AB4,3,0),0) -> 0 | AT6: =+IFERROR(VLOOKUP($AT$2,Sheet1!AD4:AG4,3,0),0) -> 0 | AU6: =+IFERROR(VLOOKUP($AU$2,Sheet1!AD4:AG4,3,0),0) -> 0 | AV6: =+IFERROR(VLOOKUP($AV$2,Sheet1!AD4:AG4,3,0),0) -> 0 | AW6: =+IFERROR(VLOOKUP($AW$2,Sheet1!AD4:AG4,3,0),0) -> 0 | AX6: =+IFERROR(VLOOKUP($AX$2,Sheet1!AD4:AG4,3,0),0) -> 0 | AY6: =+IFERROR(VLOOKUP($AY$2,Sheet1!AD4:AG4,3,0),0) -> 0 | AZ6: =+IFERROR(VLOOKUP($AZ$2,Sheet1!AD4:AG4,3,0),0) -> 0 | BA6: =+IFERROR(VLOOKUP($BA$2,Sheet1!AD4:AG4,3,0),0) -> 0 | BB6: =+IFERROR(VLOOKUP($BB$2,Sheet1!AD4:AG4,3,0),0) -> 0 | BC6: =+IFERROR(VLOOKUP($BC$2,Sheet1!AH4:AK4,3,0),0) -> 0 | BD6: =+IFERROR(VLOOKUP($BD$2,Sheet1!AH4:AK4,3,0),0) -> 0 | BE6: =+IFERROR(VLOOKUP($BE$2,Sheet1!AH4:AK4,3,0),0) -> 0 | BF6: =+IFERROR(VLOOKUP($BF$2,Sheet1!AH4:AK4,3,0),0) -> 0 | BG6: =+IFERROR(VLOOKUP($BG$2,Sheet1!AH4:AK4,3,0),0) -> 0 | BH6: =+IFERROR(VLOOKUP($BH$2,Sheet1!AH4:AK4,3,0),0) -> 0 | BI6: =+IFERROR(VLOOKUP($BI$2,Sheet1!AH4:AK4,3,0),0) -> 0 | BJ6: =+IFERROR(VLOOKUP($BJ$2,Sheet1!AH4:AK4,3,0),0) -> 0 | BK6: =+IFERROR(VLOOKUP($BK$2,Sheet1!AH4:AK4,3,0),0) -> 0 | BL6: =+IFERROR(VLOOKUP($BL$2,Sheet1!AH4:AK4,3,0),0) -> 0 | BM6: =+IFERROR(VLOOKUP($BM$2,Sheet1!AH4:AK4,3,0),0) -> 0 | BN6: =+IFERROR(VLOOKUP($BN$2,Sheet1!AL4:AO4,3,0),0) -> 0 | BO6: =+IFERROR(VLOOKUP($BO$2,Sheet1!AL4:AO4,3,0),0) -> 0 | BP6: =+IFERROR(VLOOKUP($BP$2,Sheet1!AL4:AO4,3,0),0) -> 0 | BQ6: =+IFERROR(VLOOKUP($BQ$2,Sheet1!AL4:AO4,3,0),0) -> 0 | BR6: =+IFERROR(VLOOKUP($BR$2,Sheet1!AL4:AO4,3,0),0) -> 0 | BS6: =+IFERROR(VLOOKUP($BS$2,Sheet1!AL4:AO4,3,0),0) -> 0 | BT6: =+IFERROR(VLOOKUP($BT$2,Sheet1!AL4:AO4,3,0),0) -> 0 | BU6: =+IFERROR(VLOOKUP($BU$2,Sheet1!AL4:AO4,3,0),0) -> 0 | BV6: =+IFERROR(VLOOKUP($BV$2,Sheet1!AL4:AO4,3,0),0) -> 0 | BW6: =+IFERROR(VLOOKUP($BW$2,Sheet1!AL4:AO4,3,0),0) -> 0 | BX6: =+IFERROR(VLOOKUP($BX$2,Sheet1!AL4:AO4,3,0),0) -> 0 | BY6: =+IFERROR(VLOOKUP($BY$2,Sheet1!AL4:AO4,3,0),0) -> 0 | BZ6: =+IFERROR(VLOOKUP($BZ$2,Sheet1!AP4:AS4,3,0),0) -> 0 | CA6: =+IFERROR(VLOOKUP($CA$2,Sheet1!AT4:AW4,3,0),0) -> 0 | CB6: =+IFERROR(VLOOKUP($CB$2,Sheet1!AX4:BA4,3,0),0) -> 0 | CC6: =+IFERROR(VLOOKUP($CC$2,Sheet1!BB4:BE4,3,0),0) -> 0 | CD6: =+IFERROR(VLOOKUP($CD$2,Sheet1!BF4:BI4,3,0),0) -> 0 | CE6: =+IFERROR(VLOOKUP($CE$2,Sheet1!BJ4:BM4,3,0),0) -> 0 | CF6: =+IFERROR(VLOOKUP($CF$2,Sheet1!BN4:BQ4,3,0),0) -> 0 | CG6: =+IFERROR(VLOOKUP($CG$2,Sheet1!BR4:BU4,3,0),0) -> 0 | CH6: =+IFERROR(VLOOKUP($CH$2,Sheet1!BV4:BY4,3,0),0) -> 0 | CI6: =Sheet1!E4 -> 0 | CJ6: =Sheet1!CY4 -> 0 | CK6: =Sheet1!CZ4 -> 0 | CL6: =Sheet1!CX4 -> 0 | CM6: =Sheet1!BZ4 -> 0 | CN6: 700 | CO6: 0.08 | CP6: =CN6*CO6 -> 56 | CQ6: 0.25 | CR6: =CN6*CQ6 -> 175 | CS6: =Sheet1!CF4 -> 0 | CT6: =CN6*CS6 -> 0 | CU6: =CN6+CP6+CR6+CT6 -> 931 | CV6: 0.02 | CW6: =CU6*CV6 -> 18.62 | CX6: 0.01 | CY6: =CU6*CX6 -> 9.31 | CZ6: =Sheet1!CM4 -> 0 | DA6: =CZ6*CU6 -> 0
A7: =Sheet1!A5 -> 0 | B7: =Sheet1!B5 -> 0 | C7: =Sheet1!C5 -> 0 | D7: 11KV Antifog Porcelain Insulator 90 KN Disc Insulator | E7: =CU7+CW7+CY7+DA7 -> 1027.425 | G7: =E7+F7 -> 1027.425 | H7: =G7*L7 -> 4434366.3 | I7: 0.18 | J7: =G7*I7 -> 184.9365 | K7: =G7+J7 -> 1212.3615 | L7: 4316 | M7: Nos | N7: =K7*L7 -> 5232552.2 | P7: =+IFERROR(VLOOKUP($P$2,Sheet1!J5:L5,3,0),0) -> 0 | Q7: =+IFERROR(VLOOKUP($Q$2,Sheet1!J5:L5,3,0),0) -> 0 | R7: =+IFERROR(VLOOKUP($R$2,Sheet1!J5:M5,3,0),0) -> 0 | S7: =+IFERROR(VLOOKUP($S$2,Sheet1!J5:M5,3,0),0) -> 0 | T7: =+IFERROR(VLOOKUP($T$2,Sheet1!J5:M5,3,0),0) -> 0 | U7: =+IFERROR(VLOOKUP($U$2,Sheet1!J5:M5,3,0),0) -> 0 | V7: =+IFERROR(VLOOKUP($V$2,Sheet1!J5:M5,3,0),0) -> 0 | W7: =+IFERROR(VLOOKUP($W$2,Sheet1!J5:M5,3,0),0) -> 0 | X7: =+IFERROR(VLOOKUP($X$2,Sheet1!N5:Q5,3,0),0) -> 0 | Y7: =+IFERROR(VLOOKUP($Y$2,Sheet1!N5:Q5,3,0),0) -> 0 | Z7: =+IFERROR(VLOOKUP($Z$2,Sheet1!F5:I5,3,0),0) -> 0 | AA7: =+IFERROR(VLOOKUP($AA$2,Sheet1!F5:I5,3,0),0) -> 0 | AB7: =+IFERROR(VLOOKUP($AB$2,Sheet1!F5:I5,3,0),0) -> 0 | AC7: =+IFERROR(VLOOKUP($AC$2,Sheet1!F5:I5,3,0),0) -> 0 | AD7: =+IFERROR(VLOOKUP($AD$2,Sheet1!F5:I5,3,0),0) -> 0 | AE7: =+IFERROR(VLOOKUP($AE$2,Sheet1!F5:I5,3,0),0) -> 0 | AF7: =+IFERROR(VLOOKUP($AF$2,Sheet1!F5:I5,3,0),0) -> 0 | AG7: =+IFERROR(VLOOKUP($AG$2,Sheet1!F5:I5,3,0),0) -> 0 | AH7: =+IFERROR(VLOOKUP($AH$2,Sheet1!R5:U5,3,0),0) -> 0 | AI7: =+IFERROR(VLOOKUP($AI$2,Sheet1!R5:U5,3,0),0) -> 0 | AJ7: =+IFERROR(VLOOKUP($AJ$2,Sheet1!V5:Y5,3,0),0) -> 0 | AK7: =+IFERROR(VLOOKUP($AK$2,Sheet1!V5:Y5,3,0),0) -> 0 | AL7: =+IFERROR(VLOOKUP($AL$2,Sheet1!V5:Y5,3,0),0) -> 0 | AM7: =+IFERROR(VLOOKUP($AM$2,Sheet1!V5:Y5,3,0),0) -> 0 | AN7: =+IFERROR(VLOOKUP($AN$2,Sheet1!V5:Y5,3,0),0) -> 0 | AO7: =+IFERROR(VLOOKUP($AO$2,Sheet1!V5:Y5,3,0),0) -> 0 | AP7: =+IFERROR(VLOOKUP($AP$2,Sheet1!V5:Y5,3,0),0) -> 0 | AQ7: =+IFERROR(VLOOKUP($AQ$2,Sheet1!V5:Y5,3,0),0) -> 0 | AR7: =+IFERROR(VLOOKUP($AR$2,Sheet1!V5:Y5,3,0),0) -> 0 | AS7: =+IFERROR(VLOOKUP($AS$2,Sheet1!Z5:AB5,3,0),0) -> 0 | AT7: =+IFERROR(VLOOKUP($AT$2,Sheet1!AD5:AG5,3,0),0) -> 0 | AU7: =+IFERROR(VLOOKUP($AU$2,Sheet1!AD5:AG5,3,0),0) -> 0 | AV7: =+IFERROR(VLOOKUP($AV$2,Sheet1!AD5:AG5,3,0),0) -> 0 | AW7: =+IFERROR(VLOOKUP($AW$2,Sheet1!AD5:AG5,3,0),0) -> 0 | AX7: =+IFERROR(VLOOKUP($AX$2,Sheet1!AD5:AG5,3,0),0) -> 0 | AY7: =+IFERROR(VLOOKUP($AY$2,Sheet1!AD5:AG5,3,0),0) -> 0 | AZ7: =+IFERROR(VLOOKUP($AZ$2,Sheet1!AD5:AG5,3,0),0) -> 0 | BA7: =+IFERROR(VLOOKUP($BA$2,Sheet1!AD5:AG5,3,0),0) -> 0 | BB7: =+IFERROR(VLOOKUP($BB$2,Sheet1!AD5:AG5,3,0),0) -> 0 | BC7: =+IFERROR(VLOOKUP($BC$2,Sheet1!AH5:AK5,3,0),0) -> 0 | BD7: =+IFERROR(VLOOKUP($BD$2,Sheet1!AH5:AK5,3,0),0) -> 0 | BE7: =+IFERROR(VLOOKUP($BE$2,Sheet1!AH5:AK5,3,0),0) -> 0 | BF7: =+IFERROR(VLOOKUP($BF$2,Sheet1!AH5:AK5,3,0),0) -> 0 | BG7: =+IFERROR(VLOOKUP($BG$2,Sheet1!AH5:AK5,3,0),0) -> 0 | BH7: =+IFERROR(VLOOKUP($BH$2,Sheet1!AH5:AK5,3,0),0) -> 0 | BI7: =+IFERROR(VLOOKUP($BI$2,Sheet1!AH5:AK5,3,0),0) -> 0 | BJ7: =+IFERROR(VLOOKUP($BJ$2,Sheet1!AH5:AK5,3,0),0) -> 0 | BK7: =+IFERROR(VLOOKUP($BK$2,Sheet1!AH5:AK5,3,0),0) -> 0 | BL7: =+IFERROR(VLOOKUP($BL$2,Sheet1!AH5:AK5,3,0),0) -> 0 | BM7: =+IFERROR(VLOOKUP($BM$2,Sheet1!AH5:AK5,3,0),0) -> 0 | BN7: =+IFERROR(VLOOKUP($BN$2,Sheet1!AL5:AO5,3,0),0) -> 0 | BO7: =+IFERROR(VLOOKUP($BO$2,Sheet1!AL5:AO5,3,0),0) -> 0 | BP7: =+IFERROR(VLOOKUP($BP$2,Sheet1!AL5:AO5,3,0),0) -> 0 | BQ7: =+IFERROR(VLOOKUP($BQ$2,Sheet1!AL5:AO5,3,0),0) -> 0 | BR7: =+IFERROR(VLOOKUP($BR$2,Sheet1!AL5:AO5,3,0),0) -> 0 | BS7: =+IFERROR(VLOOKUP($BS$2,Sheet1!AL5:AO5,3,0),0) -> 0 | BT7: =+IFERROR(VLOOKUP($BT$2,Sheet1!AL5:AO5,3,0),0) -> 0 | BU7: =+IFERROR(VLOOKUP($BU$2,Sheet1!AL5:AO5,3,0),0) -> 0 | BV7: =+IFERROR(VLOOKUP($BV$2,Sheet1!AL5:AO5,3,0),0) -> 0 | BW7: =+IFERROR(VLOOKUP($BW$2,Sheet1!AL5:AO5,3,0),0) -> 0 | BX7: =+IFERROR(VLOOKUP($BX$2,Sheet1!AL5:AO5,3,0),0) -> 0 | BY7: =+IFERROR(VLOOKUP($BY$2,Sheet1!AL5:AO5,3,0),0) -> 0 | BZ7: =+IFERROR(VLOOKUP($BZ$2,Sheet1!AP5:AS5,3,0),0) -> 0 | CA7: =+IFERROR(VLOOKUP($CA$2,Sheet1!AT5:AW5,3,0),0) -> 0 | CB7: =+IFERROR(VLOOKUP($CB$2,Sheet1!AX5:BA5,3,0),0) -> 0 | CC7: =+IFERROR(VLOOKUP($CC$2,Sheet1!BB5:BE5,3,0),0) -> 0 | CD7: =+IFERROR(VLOOKUP($CD$2,Sheet1!BF5:BI5,3,0),0) -> 0 | CE7: =+IFERROR(VLOOKUP($CE$2,Sheet1!BJ5:BM5,3,0),0) -> 0 | CF7: =+IFERROR(VLOOKUP($CF$2,Sheet1!BN5:BQ5,3,0),0) -> 0 | CG7: =+IFERROR(VLOOKUP($CG$2,Sheet1!BR5:BU5,3,0),0) -> 0 | CH7: =+IFERROR(VLOOKUP($CH$2,Sheet1!BV5:BY5,3,0),0) -> 0 | CI7: =Sheet1!E5 -> 0 | CJ7: =Sheet1!CY5 -> 0 | CK7: =Sheet1!CZ5 -> 0 | CL7: =Sheet1!CX5 -> 0 | CM7: =Sheet1!BZ5 -> 0 | CN7: 750 | CO7: 0.08 | CP7: =CN7*CO7 -> 60 | CQ7: 0.25 | CR7: =CN7*CQ7 -> 187.5 | CS7: =Sheet1!CF5 -> 0 | CT7: =CN7*CS7 -> 0 | CU7: =CN7+CP7+CR7+CT7 -> 997.5 | CV7: 0.02 | CW7: =CU7*CV7 -> 19.95 | CX7: 0.01 | CY7: =CU7*CX7 -> 9.975 | CZ7: =Sheet1!CM5 -> 0 | DA7: =CZ7*CU7 -> 0
A8: =Sheet1!A6 -> 0 | B8: =Sheet1!B6 -> 0 | C8: =Sheet1!C6 -> 0 | D8: Power Conductor Accessories suitable for ACSR Panther Conductor as per specification | H8: =G8*L8 -> 0
A9: =Sheet1!A7 -> 0 | B9: =Sheet1!B7 -> 0 | C9: =Sheet1!C7 -> 0 | D9: Single Tension Hardware Fittings for ACSR panther | E9: =CU9+CW9+CY9+DA9 -> 3219.265 | G9: =E9+F9 -> 3219.265 | H9: =G9*L9 -> 956121.71 | I9: 0.18 | J9: =G9*I9 -> 579.4677 | K9: =G9+J9 -> 3798.7327 | L9: 297 | M9: Nos | N9: =K9*L9 -> 1128223.6 | P9: =+IFERROR(VLOOKUP($P$2,Sheet1!J7:L7,3,0),0) -> 0 | Q9: =+IFERROR(VLOOKUP($Q$2,Sheet1!J7:L7,3,0),0) -> 0 | R9: =+IFERROR(VLOOKUP($R$2,Sheet1!J7:M7,3,0),0) -> 0 | S9: =+IFERROR(VLOOKUP($S$2,Sheet1!J7:M7,3,0),0) -> 0 | T9: =+IFERROR(VLOOKUP($T$2,Sheet1!J7:M7,3,0),0) -> 0 | U9: =+IFERROR(VLOOKUP($U$2,Sheet1!J7:M7,3,0),0) -> 0 | V9: =+IFERROR(VLOOKUP($V$2,Sheet1!J7:M7,3,0),0) -> 0 | W9: =+IFERROR(VLOOKUP($W$2,Sheet1!J7:M7,3,0),0) -> 0 | X9: =+IFERROR(VLOOKUP($X$2,Sheet1!N7:Q7,3,0),0) -> 0 | Y9: =+IFERROR(VLOOKUP($Y$2,Sheet1!N7:Q7,3,0),0) -> 0 | Z9: =+IFERROR(VLOOKUP($Z$2,Sheet1!F7:I7,3,0),0) -> 0 | AA9: =+IFERROR(VLOOKUP($AA$2,Sheet1!F7:I7,3,0),0) -> 0 | AB9: =+IFERROR(VLOOKUP($AB$2,Sheet1!F7:I7,3,0),0) -> 0 | AC9: =+IFERROR(VLOOKUP($AC$2,Sheet1!F7:I7,3,0),0) -> 0 | AD9: =+IFERROR(VLOOKUP($AD$2,Sheet1!F7:I7,3,0),0) -> 0 | AE9: =+IFERROR(VLOOKUP($AE$2,Sheet1!F7:I7,3,0),0) -> 0 | AF9: =+IFERROR(VLOOKUP($AF$2,Sheet1!F7:I7,3,0),0) -> 0 | AG9: =+IFERROR(VLOOKUP($AG$2,Sheet1!F7:I7,3,0),0) -> 0 | AH9: =+IFERROR(VLOOKUP($AH$2,Sheet1!R7:U7,3,0),0) -> 0 | AI9: =+IFERROR(VLOOKUP($AI$2,Sheet1!R7:U7,3,0),0) -> 0 | AJ9: =+IFERROR(VLOOKUP($AJ$2,Sheet1!V7:Y7,3,0),0) -> 0 | AK9: =+IFERROR(VLOOKUP($AK$2,Sheet1!V7:Y7,3,0),0) -> 0 | AL9: =+IFERROR(VLOOKUP($AL$2,Sheet1!V7:Y7,3,0),0) -> 0 | AM9: =+IFERROR(VLOOKUP($AM$2,Sheet1!V7:Y7,3,0),0) -> 0 | AN9: =+IFERROR(VLOOKUP($AN$2,Sheet1!V7:Y7,3,0),0) -> 0 | AO9: =+IFERROR(VLOOKUP($AO$2,Sheet1!V7:Y7,3,0),0) -> 0 | AP9: =+IFERROR(VLOOKUP($AP$2,Sheet1!V7:Y7,3,0),0) -> 0 | AQ9: =+IFERROR(VLOOKUP($AQ$2,Sheet1!V7:Y7,3,0),0) -> 0 | AR9: =+IFERROR(VLOOKUP($AR$2,Sheet1!V7:Y7,3,0),0) -> 0 | AS9: =+IFERROR(VLOOKUP($AS$2,Sheet1!Z7:AB7,3,0),0) -> 0 | AT9: =+IFERROR(VLOOKUP($AT$2,Sheet1!AD7:AG7,3,0),0) -> 0 | AU9: =+IFERROR(VLOOKUP($AU$2,Sheet1!AD7:AG7,3,0),0) -> 0 | AV9: =+IFERROR(VLOOKUP($AV$2,Sheet1!AD7:AG7,3,0),0) -> 0 | AW9: =+IFERROR(VLOOKUP($AW$2,Sheet1!AD7:AG7,3,0),0) -> 0 | AX9: =+IFERROR(VLOOKUP($AX$2,Sheet1!AD7:AG7,3,0),0) -> 0 | AY9: =+IFERROR(VLOOKUP($AY$2,Sheet1!AD7:AG7,3,0),0) -> 0 | AZ9: =+IFERROR(VLOOKUP($AZ$2,Sheet1!AD7:AG7,3,0),0) -> 0 | BA9: =+IFERROR(VLOOKUP($BA$2,Sheet1!AD7:AG7,3,0),0) -> 0 | BB9: =+IFERROR(VLOOKUP($BB$2,Sheet1!AD7:AG7,3,0),0) -> 0 | BC9: =+IFERROR(VLOOKUP($BC$2,Sheet1!AH7:AK7,3,0),0) -> 0 | BD9: =+IFERROR(VLOOKUP($BD$2,Sheet1!AH7:AK7,3,0),0) -> 0 | BE9: =+IFERROR(VLOOKUP($BE$2,Sheet1!AH7:AK7,3,0),0) -> 0 | BF9: =+IFERROR(VLOOKUP($BF$2,Sheet1!AH7:AK7,3,0),0) -> 0 | BG9: =+IFERROR(VLOOKUP($BG$2,Sheet1!AH7:AK7,3,0),0) -> 0 | BH9: =+IFERROR(VLOOKUP($BH$2,Sheet1!AH7:AK7,3,0),0) -> 0 | BI9: =+IFERROR(VLOOKUP($BI$2,Sheet1!AH7:AK7,3,0),0) -> 0 | BJ9: =+IFERROR(VLOOKUP($BJ$2,Sheet1!AH7:AK7,3,0),0) -> 0 | BK9: =+IFERROR(VLOOKUP($BK$2,Sheet1!AH7:AK7,3,0),0) -> 0 | BL9: =+IFERROR(VLOOKUP($BL$2,Sheet1!AH7:AK7,3,0),0) -> 0 | BM9: =+IFERROR(VLOOKUP($BM$2,Sheet1!AH7:AK7,3,0),0) -> 0 | BN9: =+IFERROR(VLOOKUP($BN$2,Sheet1!AL7:AO7,3,0),0) -> 0 | BO9: =+IFERROR(VLOOKUP($BO$2,Sheet1!AL7:AO7,3,0),0) -> 0 | BP9: =+IFERROR(VLOOKUP($BP$2,Sheet1!AL7:AO7,3,0),0) -> 0 | BQ9: =+IFERROR(VLOOKUP($BQ$2,Sheet1!AL7:AO7,3,0),0) -> 0 | BR9: =+IFERROR(VLOOKUP($BR$2,Sheet1!AL7:AO7,3,0),0) -> 0 | BS9: =+IFERROR(VLOOKUP($BS$2,Sheet1!AL7:AO7,3,0),0) -> 0 | BT9: =+IFERROR(VLOOKUP($BT$2,Sheet1!AL7:AO7,3,0),0) -> 0 | BU9: =+IFERROR(VLOOKUP($BU$2,Sheet1!AL7:AO7,3,0),0) -> 0 | BV9: =+IFERROR(VLOOKUP($BV$2,Sheet1!AL7:AO7,3,0),0) -> 0 | BW9: =+IFERROR(VLOOKUP($BW$2,Sheet1!AL7:AO7,3,0),0) -> 0 | BX9: =+IFERROR(VLOOKUP($BX$2,Sheet1!AL7:AO7,3,0),0) -> 0 | BY9: =+IFERROR(VLOOKUP($BY$2,Sheet1!AL7:AO7,3,0),0) -> 0 | BZ9: =+IFERROR(VLOOKUP($BZ$2,Sheet1!AP7:AS7,3,0),0) -> 0 | CA9: =+IFERROR(VLOOKUP($CA$2,Sheet1!AT7:AW7,3,0),0) -> 0 | CB9: =+IFERROR(VLOOKUP($CB$2,Sheet1!AX7:BA7,3,0),0) -> 0 | CC9: =+IFERROR(VLOOKUP($CC$2,Sheet1!BB7:BE7,3,0),0) -> 0 | CD9: =+IFERROR(VLOOKUP($CD$2,Sheet1!BF7:BI7,3,0),0) -> 0 | CE9: =+IFERROR(VLOOKUP($CE$2,Sheet1!BJ7:BM7,3,0),0) -> 0 | CF9: =+IFERROR(VLOOKUP($CF$2,Sheet1!BN7:BQ7,3,0),0) -> 0 | CG9: =+IFERROR(VLOOKUP($CG$2,Sheet1!BR7:BU7,3,0),0) -> 0 | CH9: =+IFERROR(VLOOKUP($CH$2,Sheet1!BV7:BY7,3,0),0) -> 0 | CI9: =Sheet1!E7 -> 0 | CJ9: =Sheet1!CY7 -> 0 | CK9: =Sheet1!CZ7 -> 0 | CL9: =Sheet1!CX7 -> 0 | CM9: =Sheet1!BZ7 -> 0 | CN9: 2350 | CO9: 0.08 | CP9: =CN9*CO9 -> 188 | CQ9: 0.25 | CR9: =CN9*CQ9 -> 587.5 | CS9: =Sheet1!CF7 -> 0 | CT9: =CN9*CS9 -> 0 | CU9: =CN9+CP9+CR9+CT9 -> 3125.5 | CV9: 0.02 | CW9: =CU9*CV9 -> 62.51 | CX9: 0.01 | CY9: =CU9*CX9 -> 31.255 | CZ9: =Sheet1!CM7 -> 0 | DA9: =CZ9*CU9 -> 0
A10: =Sheet1!A8 -> 0 | B10: =Sheet1!B8 -> 0 | C10: =Sheet1!C8 -> 0 | D10: Double Tension Hardware Fittings for ACSR panther | E10: =CU10+CW10+CY10+DA10 -> 6198.7975 | G10: =E10+F10 -> 6198.7975 | H10: =G10*L10 -> 353331.46 | I10: 0.18 | J10: =G10*I10 -> 1115.7835 | K10: =G10+J10 -> 7314.581 | L10: 57 | M10: Nos | N10: =K10*L10 -> 416931.12 | P10: =+IFERROR(VLOOKUP($P$2,Sheet1!J8:L8,3,0),0) -> 0 | Q10: =+IFERROR(VLOOKUP($Q$2,Sheet1!J8:L8,3,0),0) -> 0 | R10: =+IFERROR(VLOOKUP($R$2,Sheet1!J8:M8,3,0),0) -> 0 | S10: =+IFERROR(VLOOKUP($S$2,Sheet1!J8:M8,3,0),0) -> 0 | T10: =+IFERROR(VLOOKUP($T$2,Sheet1!J8:M8,3,0),0) -> 0 | U10: =+IFERROR(VLOOKUP($U$2,Sheet1!J8:M8,3,0),0) -> 0 | V10: =+IFERROR(VLOOKUP($V$2,Sheet1!J8:M8,3,0),0) -> 0 | W10: =+IFERROR(VLOOKUP($W$2,Sheet1!J8:M8,3,0),0) -> 0 | X10: =+IFERROR(VLOOKUP($X$2,Sheet1!N8:Q8,3,0),0) -> 0 | Y10: =+IFERROR(VLOOKUP($Y$2,Sheet1!N8:Q8,3,0),0) -> 0 | Z10: =+IFERROR(VLOOKUP($Z$2,Sheet1!F8:I8,3,0),0) -> 0 | AA10: =+IFERROR(VLOOKUP($AA$2,Sheet1!F8:I8,3,0),0) -> 0 | AB10: =+IFERROR(VLOOKUP($AB$2,Sheet1!F8:I8,3,0),0) -> 0 | AC10: =+IFERROR(VLOOKUP($AC$2,Sheet1!F8:I8,3,0),0) -> 0 | AD10: =+IFERROR(VLOOKUP($AD$2,Sheet1!F8:I8,3,0),0) -> 0 | AE10: =+IFERROR(VLOOKUP($AE$2,Sheet1!F8:I8,3,0),0) -> 0 | AF10: =+IFERROR(VLOOKUP($AF$2,Sheet1!F8:I8,3,0),0) -> 0 | AG10: =+IFERROR(VLOOKUP($AG$2,Sheet1!F8:I8,3,0),0) -> 0 | AH10: =+IFERROR(VLOOKUP($AH$2,Sheet1!R8:U8,3,0),0) -> 0 | AI10: =+IFERROR(VLOOKUP($AI$2,Sheet1!R8:U8,3,0),0) -> 0 | AJ10: =+IFERROR(VLOOKUP($AJ$2,Sheet1!V8:Y8,3,0),0) -> 0 | AK10: =+IFERROR(VLOOKUP($AK$2,Sheet1!V8:Y8,3,0),0) -> 0 | AL10: =+IFERROR(VLOOKUP($AL$2,Sheet1!V8:Y8,3,0),0) -> 0 | AM10: =+IFERROR(VLOOKUP($AM$2,Sheet1!V8:Y8,3,0),0) -> 0 | AN10: =+IFERROR(VLOOKUP($AN$2,Sheet1!V8:Y8,3,0),0) -> 0 | AO10: =+IFERROR(VLOOKUP($AO$2,Sheet1!V8:Y8,3,0),0) -> 0 | AP10: =+IFERROR(VLOOKUP($AP$2,Sheet1!V8:Y8,3,0),0) -> 0 | AQ10: =+IFERROR(VLOOKUP($AQ$2,Sheet1!V8:Y8,3,0),0) -> 0 | AR10: =+IFERROR(VLOOKUP($AR$2,Sheet1!V8:Y8,3,0),0) -> 0 | AS10: =+IFERROR(VLOOKUP($AS$2,Sheet1!Z8:AB8,3,0),0) -> 0 | AT10: =+IFERROR(VLOOKUP($AT$2,Sheet1!AD8:AG8,3,0),0) -> 0 | AU10: =+IFERROR(VLOOKUP($AU$2,Sheet1!AD8:AG8,3,0),0) -> 0 | AV10: =+IFERROR(VLOOKUP($AV$2,Sheet1!AD8:AG8,3,0),0) -> 0 | AW10: =+IFERROR(VLOOKUP($AW$2,Sheet1!AD8:AG8,3,0),0) -> 0 | AX10: =+IFERROR(VLOOKUP($AX$2,Sheet1!AD8:AG8,3,0),0) -> 0 | AY10: =+IFERROR(VLOOKUP($AY$2,Sheet1!AD8:AG8,3,0),0) -> 0 | AZ10: =+IFERROR(VLOOKUP($AZ$2,Sheet1!AD8:AG8,3,0),0) -> 0 | BA10: =+IFERROR(VLOOKUP($BA$2,Sheet1!AD8:AG8,3,0),0) -> 0 | BB10: =+IFERROR(VLOOKUP($BB$2,Sheet1!AD8:AG8,3,0),0) -> 0 | BC10: =+IFERROR(VLOOKUP($BC$2,Sheet1!AH8:AK8,3,0),0) -> 0 | BD10: =+IFERROR(VLOOKUP($BD$2,Sheet1!AH8:AK8,3,0),0) -> 0 | BE10: =+IFERROR(VLOOKUP($BE$2,Sheet1!AH8:AK8,3,0),0) -> 0 | BF10: =+IFERROR(VLOOKUP($BF$2,Sheet1!AH8:AK8,3,0),0) -> 0 | BG10: =+IFERROR(VLOOKUP($BG$2,Sheet1!AH8:AK8,3,0),0) -> 0 | BH10: =+IFERROR(VLOOKUP($BH$2,Sheet1!AH8:AK8,3,0),0) -> 0 | BI10: =+IFERROR(VLOOKUP($BI$2,Sheet1!AH8:AK8,3,0),0) -> 0 | BJ10: =+IFERROR(VLOOKUP($BJ$2,Sheet1!AH8:AK8,3,0),0) -> 0 | BK10: =+IFERROR(VLOOKUP($BK$2,Sheet1!AH8:AK8,3,0),0) -> 0 | BL10: =+IFERROR(VLOOKUP($BL$2,Sheet1!AH8:AK8,3,0),0) -> 0 | BM10: =+IFERROR(VLOOKUP($BM$2,Sheet1!AH8:AK8,3,0),0) -> 0 | BN10: =+IFERROR(VLOOKUP($BN$2,Sheet1!AL8:AO8,3,0),0) -> 0 | BO10: =+IFERROR(VLOOKUP($BO$2,Sheet1!AL8:AO8,3,0),0) -> 0 | BP10: =+IFERROR(VLOOKUP($BP$2,Sheet1!AL8:AO8,3,0),0) -> 0 | BQ10: =+IFERROR(VLOOKUP($BQ$2,Sheet1!AL8:AO8,3,0),0) -> 0 | BR10: =+IFERROR(VLOOKUP($BR$2,Sheet1!AL8:AO8,3,0),0) -> 0 | BS10: =+IFERROR(VLOOKUP($BS$2,Sheet1!AL8:AO8,3,0),0) -> 0 | BT10: =+IFERROR(VLOOKUP($BT$2,Sheet1!AL8:AO8,3,0),0) -> 0 | BU10: =+IFERROR(VLOOKUP($BU$2,Sheet1!AL8:AO8,3,0),0) -> 0 | BV10: =+IFERROR(VLOOKUP($BV$2,Sheet1!AL8:AO8,3,0),0) -> 0 | BW10: =+IFERROR(VLOOKUP($BW$2,Sheet1!AL8:AO8,3,0),0) -> 0 | BX10: =+IFERROR(VLOOKUP($BX$2,Sheet1!AL8:AO8,3,0),0) -> 0 | BY10: =+IFERROR(VLOOKUP($BY$2,Sheet1!AL8:AO8,3,0),0) -> 0 | BZ10: =+IFERROR(VLOOKUP($BZ$2,Sheet1!AP8:AS8,3,0),0) -> 0 | CA10: =+IFERROR(VLOOKUP($CA$2,Sheet1!AT8:AW8,3,0),0) -> 0 | CB10: =+IFERROR(VLOOKUP($CB$2,Sheet1!AX8:BA8,3,0),0) -> 0 | CC10: =+IFERROR(VLOOKUP($CC$2,Sheet1!BB8:BE8,3,0),0) -> 0 | CD10: =+IFERROR(VLOOKUP($CD$2,Sheet1!BF8:BI8,3,0),0) -> 0 | CE10: =+IFERROR(VLOOKUP($CE$2,Sheet1!BJ8:BM8,3,0),0) -> 0 | CF10: =+IFERROR(VLOOKUP($CF$2,Sheet1!BN8:BQ8,3,0),0) -> 0 | CG10: =+IFERROR(VLOOKUP($CG$2,Sheet1!BR8:BU8,3,0),0) -> 0 | CH10: =+IFERROR(VLOOKUP($CH$2,Sheet1!BV8:BY8,3,0),0) -> 0 | CI10: =Sheet1!E8 -> 0 | CJ10: =Sheet1!CY8 -> 0 | CK10: =Sheet1!CZ8 -> 0 | CL10: =Sheet1!CX8 -> 0 | CM10: =Sheet1!BZ8 -> 0 | CN10: 4525 | CO10: 0.08 | CP10: =CN10*CO10 -> 362 | CQ10: 0.25 | CR10: =CN10*CQ10 -> 1131.25 | CS10: =Sheet1!CF8 -> 0 | CT10: =CN10*CS10 -> 0 | CU10: =CN10+CP10+CR10+CT10 -> 6018.25 | CV10: 0.02 | CW10: =CU10*CV10 -> 120.365 | CX10: 0.01 | CY10: =CU10*CX10 -> 60.1825 | CZ10: =Sheet1!CM8 -> 0 | DA10: =CZ10*CU10 -> 0
A11: =Sheet1!A9 -> 0 | B11: =Sheet1!B9 -> 0 | C11: =Sheet1!C9 -> 0 | D11: Single Suspension Hardware Fitting for ACSR panther | E11: =CU11+CW11+CY11+DA11 -> 2328.83 | G11: =E11+F11 -> 2328.83 | H11: =G11*L11 -> 251513.64 | I11: 0.18 | J11: =G11*I11 -> 419.1894 | K11: =G11+J11 -> 2748.0194 | L11: 108 | M11: Nos | N11: =K11*L11 -> 296786.1 | P11: =+IFERROR(VLOOKUP($P$2,Sheet1!J9:L9,3,0),0) -> 0 | Q11: =+IFERROR(VLOOKUP($Q$2,Sheet1!J9:L9,3,0),0) -> 0 | R11: =+IFERROR(VLOOKUP($R$2,Sheet1!J9:M9,3,0),0) -> 0 | S11: =+IFERROR(VLOOKUP($S$2,Sheet1!J9:M9,3,0),0) -> 0 | T11: =+IFERROR(VLOOKUP($T$2,Sheet1!J9:M9,3,0),0) -> 0 | U11: =+IFERROR(VLOOKUP($U$2,Sheet1!J9:M9,3,0),0) -> 0 | V11: =+IFERROR(VLOOKUP($V$2,Sheet1!J9:M9,3,0),0) -> 0 | W11: =+IFERROR(VLOOKUP($W$2,Sheet1!J9:M9,3,0),0) -> 0 | X11: =+IFERROR(VLOOKUP($X$2,Sheet1!N9:Q9,3,0),0) -> 0 | Y11: =+IFERROR(VLOOKUP($Y$2,Sheet1!N9:Q9,3,0),0) -> 0 | Z11: =+IFERROR(VLOOKUP($Z$2,Sheet1!F9:I9,3,0),0) -> 0 | AA11: =+IFERROR(VLOOKUP($AA$2,Sheet1!F9:I9,3,0),0) -> 0 | AB11: =+IFERROR(VLOOKUP($AB$2,Sheet1!F9:I9,3,0),0) -> 0 | AC11: =+IFERROR(VLOOKUP($AC$2,Sheet1!F9:I9,3,0),0) -> 0 | AD11: =+IFERROR(VLOOKUP($AD$2,Sheet1!F9:I9,3,0),0) -> 0 | AE11: =+IFERROR(VLOOKUP($AE$2,Sheet1!F9:I9,3,0),0) -> 0 | AF11: =+IFERROR(VLOOKUP($AF$2,Sheet1!F9:I9,3,0),0) -> 0 | AG11: =+IFERROR(VLOOKUP($AG$2,Sheet1!F9:I9,3,0),0) -> 0 | AH11: =+IFERROR(VLOOKUP($AH$2,Sheet1!R9:U9,3,0),0) -> 0 | AI11: =+IFERROR(VLOOKUP($AI$2,Sheet1!R9:U9,3,0),0) -> 0 | AJ11: =+IFERROR(VLOOKUP($AJ$2,Sheet1!V9:Y9,3,0),0) -> 0 | AK11: =+IFERROR(VLOOKUP($AK$2,Sheet1!V9:Y9,3,0),0) -> 0 | AL11: =+IFERROR(VLOOKUP($AL$2,Sheet1!V9:Y9,3,0),0) -> 0 | AM11: =+IFERROR(VLOOKUP($AM$2,Sheet1!V9:Y9,3,0),0) -> 0 | AN11: =+IFERROR(VLOOKUP($AN$2,Sheet1!V9:Y9,3,0),0) -> 0 | AO11: =+IFERROR(VLOOKUP($AO$2,Sheet1!V9:Y9,3,0),0) -> 0 | AP11: =+IFERROR(VLOOKUP($AP$2,Sheet1!V9:Y9,3,0),0) -> 0 | AQ11: =+IFERROR(VLOOKUP($AQ$2,Sheet1!V9:Y9,3,0),0) -> 0 | AR11: =+IFERROR(VLOOKUP($AR$2,Sheet1!V9:Y9,3,0),0) -> 0 | AS11: =+IFERROR(VLOOKUP($AS$2,Sheet1!Z9:AB9,3,0),0) -> 0 | AT11: =+IFERROR(VLOOKUP($AT$2,Sheet1!AD9:AG9,3,0),0) -> 0 | AU11: =+IFERROR(VLOOKUP($AU$2,Sheet1!AD9:AG9,3,0),0) -> 0 | AV11: =+IFERROR(VLOOKUP($AV$2,Sheet1!AD9:AG9,3,0),0) -> 0 | AW11: =+IFERROR(VLOOKUP($AW$2,Sheet1!AD9:AG9,3,0),0) -> 0 | AX11: =+IFERROR(VLOOKUP($AX$2,Sheet1!AD9:AG9,3,0),0) -> 0 | AY11: =+IFERROR(VLOOKUP($AY$2,Sheet1!AD9:AG9,3,0),0) -> 0 | AZ11: =+IFERROR(VLOOKUP($AZ$2,Sheet1!AD9:AG9,3,0),0) -> 0 | BA11: =+IFERROR(VLOOKUP($BA$2,Sheet1!AD9:AG9,3,0),0) -> 0 | BB11: =+IFERROR(VLOOKUP($BB$2,Sheet1!AD9:AG9,3,0),0) -> 0 | BC11: =+IFERROR(VLOOKUP($BC$2,Sheet1!AH9:AK9,3,0),0) -> 0 | BD11: =+IFERROR(VLOOKUP($BD$2,Sheet1!AH9:AK9,3,0),0) -> 0 | BE11: =+IFERROR(VLOOKUP($BE$2,Sheet1!AH9:AK9,3,0),0) -> 0 | BF11: =+IFERROR(VLOOKUP($BF$2,Sheet1!AH9:AK9,3,0),0) -> 0 | BG11: =+IFERROR(VLOOKUP($BG$2,Sheet1!AH9:AK9,3,0),0) -> 0 | BH11: =+IFERROR(VLOOKUP($BH$2,Sheet1!AH9:AK9,3,0),0) -> 0 | BI11: =+IFERROR(VLOOKUP($BI$2,Sheet1!AH9:AK9,3,0),0) -> 0 | BJ11: =+IFERROR(VLOOKUP($BJ$2,Sheet1!AH9:AK9,3,0),0) -> 0 | BK11: =+IFERROR(VLOOKUP($BK$2,Sheet1!AH9:AK9,3,0),0) -> 0 | BL11: =+IFERROR(VLOOKUP($BL$2,Sheet1!AH9:AK9,3,0),0) -> 0 | BM11: =+IFERROR(VLOOKUP($BM$2,Sheet1!AH9:AK9,3,0),0) -> 0 | BN11: =+IFERROR(VLOOKUP($BN$2,Sheet1!AL9:AO9,3,0),0) -> 0 | BO11: =+IFERROR(VLOOKUP($BO$2,Sheet1!AL9:AO9,3,0),0) -> 0 | BP11: =+IFERROR(VLOOKUP($BP$2,Sheet1!AL9:AO9,3,0),0) -> 0 | BQ11: =+IFERROR(VLOOKUP($BQ$2,Sheet1!AL9:AO9,3,0),0) -> 0 | BR11: =+IFERROR(VLOOKUP($BR$2,Sheet1!AL9:AO9,3,0),0) -> 0 | BS11: =+IFERROR(VLOOKUP($BS$2,Sheet1!AL9:AO9,3,0),0) -> 0 | BT11: =+IFERROR(VLOOKUP($BT$2,Sheet1!AL9:AO9,3,0),0) -> 0 | BU11: =+IFERROR(VLOOKUP($BU$2,Sheet1!AL9:AO9,3,0),0) -> 0 | BV11: =+IFERROR(VLOOKUP($BV$2,Sheet1!AL9:AO9,3,0),0) -> 0 | BW11: =+IFERROR(VLOOKUP($BW$2,Sheet1!AL9:AO9,3,0),0) -> 0 | BX11: =+IFERROR(VLOOKUP($BX$2,Sheet1!AL9:AO9,3,0),0) -> 0 | BY11: =+IFERROR(VLOOKUP($BY$2,Sheet1!AL9:AO9,3,0),0) -> 0 | BZ11: =+IFERROR(VLOOKUP($BZ$2,Sheet1!AP9:AS9,3,0),0) -> 0 | CA11: =+IFERROR(VLOOKUP($CA$2,Sheet1!AT9:AW9,3,0),0) -> 0 | CB11: =+IFERROR(VLOOKUP($CB$2,Sheet1!AX9:BA9,3,0),0) -> 0 | CC11: =+IFERROR(VLOOKUP($CC$2,Sheet1!BB9:BE9,3,0),0) -> 0 | CD11: =+IFERROR(VLOOKUP($CD$2,Sheet1!BF9:BI9,3,0),0) -> 0 | CE11: =+IFERROR(VLOOKUP($CE$2,Sheet1!BJ9:BM9,3,0),0) -> 0 | CF11: =+IFERROR(VLOOKUP($CF$2,Sheet1!BN9:BQ9,3,0),0) -> 0 | CG11: =+IFERROR(VLOOKUP($CG$2,Sheet1!BR9:BU9,3,0),0) -> 0 | CH11: =+IFERROR(VLOOKUP($CH$2,Sheet1!BV9:BY9,3,0),0) -> 0 | CI11: =Sheet1!E9 -> 0 | CJ11: =Sheet1!CY9 -> 0 | CK11: =Sheet1!CZ9 -> 0 | CL11: =Sheet1!CX9 -> 0 | CM11: =Sheet1!BZ9 -> 0 | CN11: 1700 | CO11: 0.08 | CP11: =CN11*CO11 -> 136 | CQ11: 0.25 | CR11: =CN11*CQ11 -> 425 | CS11: =Sheet1!CF9 -> 0 | CT11: =CN11*CS11 -> 0 | CU11: =CN11+CP11+CR11+CT11 -> 2261 | CV11: 0.02 | CW11: =CU11*CV11 -> 45.22 | CX11: 0.01 | CY11: =CU11*CX11 -> 22.61 | CZ11: =Sheet1!CM9 -> 0 | DA11: =CZ11*CU11 -> 0
A12: =Sheet1!A10 -> 0 | B12: =Sheet1!B10 -> 0 | C12: =Sheet1!C10 -> 0 | D12: Double Suspension Hardware Fitting for ACSR panther | E12: =CU12+CW12+CY12+DA12 -> 5342.61 | G12: =E12+F12 -> 5342.61 | H12: =G12*L12 -> 208361.79 | I12: 0.18 | J12: =G12*I12 -> 961.6698 | K12: =G12+J12 -> 6304.2798 | L12: 39 | M12: Nos | N12: =K12*L12 -> 245866.91 | P12: =+IFERROR(VLOOKUP($P$2,Sheet1!J10:L10,3,0),0) -> 0 | Q12: =+IFERROR(VLOOKUP($Q$2,Sheet1!J10:L10,3,0),0) -> 0 | R12: =+IFERROR(VLOOKUP($R$2,Sheet1!J10:M10,3,0),0) -> 0 | S12: =+IFERROR(VLOOKUP($S$2,Sheet1!J10:M10,3,0),0) -> 0 | T12: =+IFERROR(VLOOKUP($T$2,Sheet1!J10:M10,3,0),0) -> 0 | U12: =+IFERROR(VLOOKUP($U$2,Sheet1!J10:M10,3,0),0) -> 0 | V12: =+IFERROR(VLOOKUP($V$2,Sheet1!J10:M10,3,0),0) -> 0 | W12: =+IFERROR(VLOOKUP($W$2,Sheet1!J10:M10,3,0),0) -> 0 | X12: =+IFERROR(VLOOKUP($X$2,Sheet1!N10:Q10,3,0),0) -> 0 | Y12: =+IFERROR(VLOOKUP($Y$2,Sheet1!N10:Q10,3,0),0) -> 0 | Z12: =+IFERROR(VLOOKUP($Z$2,Sheet1!F10:I10,3,0),0) -> 0 | AA12: =+IFERROR(VLOOKUP($AA$2,Sheet1!F10:I10,3,0),0) -> 0 | AB12: =+IFERROR(VLOOKUP($AB$2,Sheet1!F10:I10,3,0),0) -> 0 | AC12: =+IFERROR(VLOOKUP($AC$2,Sheet1!F10:I10,3,0),0) -> 0 | AD12: =+IFERROR(VLOOKUP($AD$2,Sheet1!F10:I10,3,0),0) -> 0 | AE12: =+IFERROR(VLOOKUP($AE$2,Sheet1!F10:I10,3,0),0) -> 0 | AF12: =+IFERROR(VLOOKUP($AF$2,Sheet1!F10:I10,3,0),0) -> 0 | AG12: =+IFERROR(VLOOKUP($AG$2,Sheet1!F10:I10,3,0),0) -> 0 | AH12: =+IFERROR(VLOOKUP($AH$2,Sheet1!R10:U10,3,0),0) -> 0 | AI12: =+IFERROR(VLOOKUP($AI$2,Sheet1!R10:U10,3,0),0) -> 0 | AJ12: =+IFERROR(VLOOKUP($AJ$2,Sheet1!V10:Y10,3,0),0) -> 0 | AK12: =+IFERROR(VLOOKUP($AK$2,Sheet1!V10:Y10,3,0),0) -> 0 | AL12: =+IFERROR(VLOOKUP($AL$2,Sheet1!V10:Y10,3,0),0) -> 0 | AM12: =+IFERROR(VLOOKUP($AM$2,Sheet1!V10:Y10,3,0),0) -> 0 | AN12: =+IFERROR(VLOOKUP($AN$2,Sheet1!V10:Y10,3,0),0) -> 0 | AO12: =+IFERROR(VLOOKUP($AO$2,Sheet1!V10:Y10,3,0),0) -> 0 | AP12: =+IFERROR(VLOOKUP($AP$2,Sheet1!V10:Y10,3,0),0) -> 0 | AQ12: =+IFERROR(VLOOKUP($AQ$2,Sheet1!V10:Y10,3,0),0) -> 0 | AR12: =+IFERROR(VLOOKUP($AR$2,Sheet1!V10:Y10,3,0),0) -> 0 | AS12: =+IFERROR(VLOOKUP($AS$2,Sheet1!Z10:AB10,3,0),0) -> 0 | AT12: =+IFERROR(VLOOKUP($AT$2,Sheet1!AD10:AG10,3,0),0) -> 0 | AU12: =+IFERROR(VLOOKUP($AU$2,Sheet1!AD10:AG10,3,0),0) -> 0 | AV12: =+IFERROR(VLOOKUP($AV$2,Sheet1!AD10:AG10,3,0),0) -> 0 | AW12: =+IFERROR(VLOOKUP($AW$2,Sheet1!AD10:AG10,3,0),0) -> 0 | AX12: =+IFERROR(VLOOKUP($AX$2,Sheet1!AD10:AG10,3,0),0) -> 0 | AY12: =+IFERROR(VLOOKUP($AY$2,Sheet1!AD10:AG10,3,0),0) -> 0 | AZ12: =+IFERROR(VLOOKUP($AZ$2,Sheet1!AD10:AG10,3,0),0) -> 0 | BA12: =+IFERROR(VLOOKUP($BA$2,Sheet1!AD10:AG10,3,0),0) -> 0 | BB12: =+IFERROR(VLOOKUP($BB$2,Sheet1!AD10:AG10,3,0),0) -> 0 | BC12: =+IFERROR(VLOOKUP($BC$2,Sheet1!AH10:AK10,3,0),0) -> 0 | BD12: =+IFERROR(VLOOKUP($BD$2,Sheet1!AH10:AK10,3,0),0) -> 0 | BE12: =+IFERROR(VLOOKUP($BE$2,Sheet1!AH10:AK10,3,0),0) -> 0 | BF12: =+IFERROR(VLOOKUP($BF$2,Sheet1!AH10:AK10,3,0),0) -> 0 | BG12: =+IFERROR(VLOOKUP($BG$2,Sheet1!AH10:AK10,3,0),0) -> 0 | BH12: =+IFERROR(VLOOKUP($BH$2,Sheet1!AH10:AK10,3,0),0) -> 0 | BI12: =+IFERROR(VLOOKUP($BI$2,Sheet1!AH10:AK10,3,0),0) -> 0 | BJ12: =+IFERROR(VLOOKUP($BJ$2,Sheet1!AH10:AK10,3,0),0) -> 0 | BK12: =+IFERROR(VLOOKUP($BK$2,Sheet1!AH10:AK10,3,0),0) -> 0 | BL12: =+IFERROR(VLOOKUP($BL$2,Sheet1!AH10:AK10,3,0),0) -> 0 | BM12: =+IFERROR(VLOOKUP($BM$2,Sheet1!AH10:AK10,3,0),0) -> 0 | BN12: =+IFERROR(VLOOKUP($BN$2,Sheet1!AL10:AO10,3,0),0) -> 0 | BO12: =+IFERROR(VLOOKUP($BO$2,Sheet1!AL10:AO10,3,0),0) -> 0 | BP12: =+IFERROR(VLOOKUP($BP$2,Sheet1!AL10:AO10,3,0),0) -> 0 | BQ12: =+IFERROR(VLOOKUP($BQ$2,Sheet1!AL10:AO10,3,0),0) -> 0 | BR12: =+IFERROR(VLOOKUP($BR$2,Sheet1!AL10:AO10,3,0),0) -> 0 | BS12: =+IFERROR(VLOOKUP($BS$2,Sheet1!AL10:AO10,3,0),0) -> 0 | BT12: =+IFERROR(VLOOKUP($BT$2,Sheet1!AL10:AO10,3,0),0) -> 0 | BU12: =+IFERROR(VLOOKUP($BU$2,Sheet1!AL10:AO10,3,0),0) -> 0 | BV12: =+IFERROR(VLOOKUP($BV$2,Sheet1!AL10:AO10,3,0),0) -> 0 | BW12: =+IFERROR(VLOOKUP($BW$2,Sheet1!AL10:AO10,3,0),0) -> 0 | BX12: =+IFERROR(VLOOKUP($BX$2,Sheet1!AL10:AO10,3,0),0) -> 0 | BY12: =+IFERROR(VLOOKUP($BY$2,Sheet1!AL10:AO10,3,0),0) -> 0 | BZ12: =+IFERROR(VLOOKUP($BZ$2,Sheet1!AP10:AS10,3,0),0) -> 0 | CA12: =+IFERROR(VLOOKUP($CA$2,Sheet1!AT10:AW10,3,0),0) -> 0 | CB12: =+IFERROR(VLOOKUP($CB$2,Sheet1!AX10:BA10,3,0),0) -> 0 | CC12: =+IFERROR(VLOOKUP($CC$2,Sheet1!BB10:BE10,3,0),0) -> 0 | CD12: =+IFERROR(VLOOKUP($CD$2,Sheet1!BF10:BI10,3,0),0) -> 0 | CE12: =+IFERROR(VLOOKUP($CE$2,Sheet1!BJ10:BM10,3,0),0) -> 0 | CF12: =+IFERROR(VLOOKUP($CF$2,Sheet1!BN10:BQ10,3,0),0) -> 0 | CG12: =+IFERROR(VLOOKUP($CG$2,Sheet1!BR10:BU10,3,0),0) -> 0 | CH12: =+IFERROR(VLOOKUP($CH$2,Sheet1!BV10:BY10,3,0),0) -> 0 | CI12: =Sheet1!E10 -> 0 | CJ12: =Sheet1!CY10 -> 0 | CK12: =Sheet1!CZ10 -> 0 | CL12: =Sheet1!CX10 -> 0 | CM12: =Sheet1!BZ10 -> 0 | CN12: 3900 | CO12: 0.08 | CP12: =CN12*CO12 -> 312 | CQ12: 0.25 | CR12: =CN12*CQ12 -> 975 | CS12: =Sheet1!CF10 -> 0 | CT12: =CN12*CS12 -> 0 | CU12: =CN12+CP12+CR12+CT12 -> 5187 | CV12: 0.02 | CW12: =CU12*CV12 -> 103.74 | CX12: 0.01 | CY12: =CU12*CX12 -> 51.87 | CZ12: =Sheet1!CM10 -> 0 | DA12: =CZ12*CU12 -> 0
A13: =Sheet1!A11 -> 0 | B13: =Sheet1!B11 -> 0 | C13: =Sheet1!C11 -> 0 | D13: Vibration Damper | E13: =CU13+CW13+CY13+DA13 -> 856.1875 | G13: =E13+F13 -> 856.1875 | H13: =G13*L13 -> 547103.81 | I13: 0.18 | J13: =G13*I13 -> 154.11375 | K13: =G13+J13 -> 1010.3012 | L13: 639 | M13: Nos | N13: =K13*L13 -> 645582.5 | P13: =+IFERROR(VLOOKUP($P$2,Sheet1!J11:L11,3,0),0) -> 0 | Q13: =+IFERROR(VLOOKUP($Q$2,Sheet1!J11:L11,3,0),0) -> 0 | R13: =+IFERROR(VLOOKUP($R$2,Sheet1!J11:M11,3,0),0) -> 0 | S13: =+IFERROR(VLOOKUP($S$2,Sheet1!J11:M11,3,0),0) -> 0 | T13: =+IFERROR(VLOOKUP($T$2,Sheet1!J11:M11,3,0),0) -> 0 | U13: =+IFERROR(VLOOKUP($U$2,Sheet1!J11:M11,3,0),0) -> 0 | V13: =+IFERROR(VLOOKUP($V$2,Sheet1!J11:M11,3,0),0) -> 0 | W13: =+IFERROR(VLOOKUP($W$2,Sheet1!J11:M11,3,0),0) -> 0 | X13: =+IFERROR(VLOOKUP($X$2,Sheet1!N11:Q11,3,0),0) -> 0 | Y13: =+IFERROR(VLOOKUP($Y$2,Sheet1!N11:Q11,3,0),0) -> 0 | Z13: =+IFERROR(VLOOKUP($Z$2,Sheet1!F11:I11,3,0),0) -> 0 | AA13: =+IFERROR(VLOOKUP($AA$2,Sheet1!F11:I11,3,0),0) -> 0 | AB13: =+IFERROR(VLOOKUP($AB$2,Sheet1!F11:I11,3,0),0) -> 0 | AC13: =+IFERROR(VLOOKUP($AC$2,Sheet1!F11:I11,3,0),0) -> 0 | AD13: =+IFERROR(VLOOKUP($AD$2,Sheet1!F11:I11,3,0),0) -> 0 | AE13: =+IFERROR(VLOOKUP($AE$2,Sheet1!F11:I11,3,0),0) -> 0 | AF13: =+IFERROR(VLOOKUP($AF$2,Sheet1!F11:I11,3,0),0) -> 0 | AG13: =+IFERROR(VLOOKUP($AG$2,Sheet1!F11:I11,3,0),0) -> 0 | AH13: =+IFERROR(VLOOKUP($AH$2,Sheet1!R11:U11,3,0),0) -> 0 | AI13: =+IFERROR(VLOOKUP($AI$2,Sheet1!R11:U11,3,0),0) -> 0 | AJ13: =+IFERROR(VLOOKUP($AJ$2,Sheet1!V11:Y11,3,0),0) -> 0 | AK13: =+IFERROR(VLOOKUP($AK$2,Sheet1!V11:Y11,3,0),0) -> 0 | AL13: =+IFERROR(VLOOKUP($AL$2,Sheet1!V11:Y11,3,0),0) -> 0 | AM13: =+IFERROR(VLOOKUP($AM$2,Sheet1!V11:Y11,3,0),0) -> 0 | AN13: =+IFERROR(VLOOKUP($AN$2,Sheet1!V11:Y11,3,0),0) -> 0 | AO13: =+IFERROR(VLOOKUP($AO$2,Sheet1!V11:Y11,3,0),0) -> 0 | AP13: =+IFERROR(VLOOKUP($AP$2,Sheet1!V11:Y11,3,0),0) -> 0 | AQ13: =+IFERROR(VLOOKUP($AQ$2,Sheet1!V11:Y11,3,0),0) -> 0 | AR13: =+IFERROR(VLOOKUP($AR$2,Sheet1!V11:Y11,3,0),0) -> 0 | AS13: =+IFERROR(VLOOKUP($AS$2,Sheet1!Z11:AB11,3,0),0) -> 0 | AT13: =+IFERROR(VLOOKUP($AT$2,Sheet1!AD11:AG11,3,0),0) -> 0 | AU13: =+IFERROR(VLOOKUP($AU$2,Sheet1!AD11:AG11,3,0),0) -> 0 | AV13: =+IFERROR(VLOOKUP($AV$2,Sheet1!AD11:AG11,3,0),0) -> 0 | AW13: =+IFERROR(VLOOKUP($AW$2,Sheet1!AD11:AG11,3,0),0) -> 0 | AX13: =+IFERROR(VLOOKUP($AX$2,Sheet1!AD11:AG11,3,0),0) -> 0 | AY13: =+IFERROR(VLOOKUP($AY$2,Sheet1!AD11:AG11,3,0),0) -> 0 | AZ13: =+IFERROR(VLOOKUP($AZ$2,Sheet1!AD11:AG11,3,0),0) -> 0 | BA13: =+IFERROR(VLOOKUP($BA$2,Sheet1!AD11:AG11,3,0),0) -> 0 | BB13: =+IFERROR(VLOOKUP($BB$2,Sheet1!AD11:AG11,3,0),0) -> 0 | BC13: =+IFERROR(VLOOKUP($BC$2,Sheet1!AH11:AK11,3,0),0) -> 0 | BD13: =+IFERROR(VLOOKUP($BD$2,Sheet1!AH11:AK11,3,0),0) -> 0 | BE13: =+IFERROR(VLOOKUP($BE$2,Sheet1!AH11:AK11,3,0),0) -> 0 | BF13: =+IFERROR(VLOOKUP($BF$2,Sheet1!AH11:AK11,3,0),0) -> 0 | BG13: =+IFERROR(VLOOKUP($BG$2,Sheet1!AH11:AK11,3,0),0) -> 0 | BH13: =+IFERROR(VLOOKUP($BH$2,Sheet1!AH11:AK11,3,0),0) -> 0 | BI13: =+IFERROR(VLOOKUP($BI$2,Sheet1!AH11:AK11,3,0),0) -> 0 | BJ13: =+IFERROR(VLOOKUP($BJ$2,Sheet1!AH11:AK11,3,0),0) -> 0 | BK13: =+IFERROR(VLOOKUP($BK$2,Sheet1!AH11:AK11,3,0),0) -> 0 | BL13: =+IFERROR(VLOOKUP($BL$2,Sheet1!AH11:AK11,3,0),0) -> 0 | BM13: =+IFERROR(VLOOKUP($BM$2,Sheet1!AH11:AK11,3,0),0) -> 0 | BN13: =+IFERROR(VLOOKUP($BN$2,Sheet1!AL11:AO11,3,0),0) -> 0 | BO13: =+IFERROR(VLOOKUP($BO$2,Sheet1!AL11:AO11,3,0),0) -> 0 | BP13: =+IFERROR(VLOOKUP($BP$2,Sheet1!AL11:AO11,3,0),0) -> 0 | BQ13: =+IFERROR(VLOOKUP($BQ$2,Sheet1!AL11:AO11,3,0),0) -> 0 | BR13: =+IFERROR(VLOOKUP($BR$2,Sheet1!AL11:AO11,3,0),0) -> 0 | BS13: =+IFERROR(VLOOKUP($BS$2,Sheet1!AL11:AO11,3,0),0) -> 0 | BT13: =+IFERROR(VLOOKUP($BT$2,Sheet1!AL11:AO11,3,0),0) -> 0 | BU13: =+IFERROR(VLOOKUP($BU$2,Sheet1!AL11:AO11,3,0),0) -> 0 | BV13: =+IFERROR(VLOOKUP($BV$2,Sheet1!AL11:AO11,3,0),0) -> 0 | BW13: =+IFERROR(VLOOKUP($BW$2,Sheet1!AL11:AO11,3,0),0) -> 0 | BX13: =+IFERROR(VLOOKUP($BX$2,Sheet1!AL11:AO11,3,0),0) -> 0 | BY13: =+IFERROR(VLOOKUP($BY$2,Sheet1!AL11:AO11,3,0),0) -> 0 | BZ13: =+IFERROR(VLOOKUP($BZ$2,Sheet1!AP11:AS11,3,0),0) -> 0 | CA13: =+IFERROR(VLOOKUP($CA$2,Sheet1!AT11:AW11,3,0),0) -> 0 | CB13: =+IFERROR(VLOOKUP($CB$2,Sheet1!AX11:BA11,3,0),0) -> 0 | CC13: =+IFERROR(VLOOKUP($CC$2,Sheet1!BB11:BE11,3,0),0) -> 0 | CD13: =+IFERROR(VLOOKUP($CD$2,Sheet1!BF11:BI11,3,0),0) -> 0 | CE13: =+IFERROR(VLOOKUP($CE$2,Sheet1!BJ11:BM11,3,0),0) -> 0 | CF13: =+IFERROR(VLOOKUP($CF$2,Sheet1!BN11:BQ11,3,0),0) -> 0 | CG13: =+IFERROR(VLOOKUP($CG$2,Sheet1!BR11:BU11,3,0),0) -> 0 | CH13: =+IFERROR(VLOOKUP($CH$2,Sheet1!BV11:BY11,3,0),0) -> 0 | CI13: =Sheet1!E11 -> 0 | CJ13: =Sheet1!CY11 -> 0 | CK13: =Sheet1!CZ11 -> 0 | CL13: =Sheet1!CX11 -> 0 | CM13: =Sheet1!BZ11 -> 0 | CN13: 625 | CO13: 0.08 | CP13: =CN13*CO13 -> 50 | CQ13: 0.25 | CR13: =CN13*CQ13 -> 156.25 | CS13: =Sheet1!CF11 -> 0 | CT13: =CN13*CS13 -> 0 | CU13: =CN13+CP13+CR13+CT13 -> 831.25 | CV13: 0.02 | CW13: =CU13*CV13 -> 16.625 | CX13: 0.01 | CY13: =CU13*CX13 -> 8.3125 | CZ13: =Sheet1!CM11 -> 0 | DA13: =CZ13*CU13 -> 0
A14: =Sheet1!A12 -> 0 | B14: =Sheet1!B12 -> 0 | C14: =Sheet1!C12 -> 0 | D14: Preformed Armour Rod | E14: =CU14+CW14+CY14+DA14 -> 1780.87 | G14: =E14+F14 -> 1780.87 | H14: =G14*L14 -> 261787.89 | I14: 0.18 | J14: =G14*I14 -> 320.5566 | K14: =G14+J14 -> 2101.4266 | L14: 147 | M14: Nos | N14: =K14*L14 -> 308909.71 | P14: =+IFERROR(VLOOKUP($P$2,Sheet1!J12:L12,3,0),0) -> 0 | Q14: =+IFERROR(VLOOKUP($Q$2,Sheet1!J12:L12,3,0),0) -> 0 | R14: =+IFERROR(VLOOKUP($R$2,Sheet1!J12:M12,3,0),0) -> 0 | S14: =+IFERROR(VLOOKUP($S$2,Sheet1!J12:M12,3,0),0) -> 0 | T14: =+IFERROR(VLOOKUP($T$2,Sheet1!J12:M12,3,0),0) -> 0 | U14: =+IFERROR(VLOOKUP($U$2,Sheet1!J12:M12,3,0),0) -> 0 | V14: =+IFERROR(VLOOKUP($V$2,Sheet1!J12:M12,3,0),0) -> 0 | W14: =+IFERROR(VLOOKUP($W$2,Sheet1!J12:M12,3,0),0) -> 0 | X14: =+IFERROR(VLOOKUP($X$2,Sheet1!N12:Q12,3,0),0) -> 0 | Y14: =+IFERROR(VLOOKUP($Y$2,Sheet1!N12:Q12,3,0),0) -> 0 | Z14: =+IFERROR(VLOOKUP($Z$2,Sheet1!F12:I12,3,0),0) -> 0 | AA14: =+IFERROR(VLOOKUP($AA$2,Sheet1!F12:I12,3,0),0) -> 0 | AB14: =+IFERROR(VLOOKUP($AB$2,Sheet1!F12:I12,3,0),0) -> 0 | AC14: =+IFERROR(VLOOKUP($AC$2,Sheet1!F12:I12,3,0),0) -> 0 | AD14: =+IFERROR(VLOOKUP($AD$2,Sheet1!F12:I12,3,0),0) -> 0 | AE14: =+IFERROR(VLOOKUP($AE$2,Sheet1!F12:I12,3,0),0) -> 0 | AF14: =+IFERROR(VLOOKUP($AF$2,Sheet1!F12:I12,3,0),0) -> 0 | AG14: =+IFERROR(VLOOKUP($AG$2,Sheet1!F12:I12,3,0),0) -> 0 | AH14: =+IFERROR(VLOOKUP($AH$2,Sheet1!R12:U12,3,0),0) -> 0 | AI14: =+IFERROR(VLOOKUP($AI$2,Sheet1!R12:U12,3,0),0) -> 0 | AJ14: =+IFERROR(VLOOKUP($AJ$2,Sheet1!V12:Y12,3,0),0) -> 0 | AK14: =+IFERROR(VLOOKUP($AK$2,Sheet1!V12:Y12,3,0),0) -> 0 | AL14: =+IFERROR(VLOOKUP($AL$2,Sheet1!V12:Y12,3,0),0) -> 0 | AM14: =+IFERROR(VLOOKUP($AM$2,Sheet1!V12:Y12,3,0),0) -> 0 | AN14: =+IFERROR(VLOOKUP($AN$2,Sheet1!V12:Y12,3,0),0) -> 0 | AO14: =+IFERROR(VLOOKUP($AO$2,Sheet1!V12:Y12,3,0),0) -> 0 | AP14: =+IFERROR(VLOOKUP($AP$2,Sheet1!V12:Y12,3,0),0) -> 0 | AQ14: =+IFERROR(VLOOKUP($AQ$2,Sheet1!V12:Y12,3,0),0) -> 0 | AR14: =+IFERROR(VLOOKUP($AR$2,Sheet1!V12:Y12,3,0),0) -> 0 | AS14: =+IFERROR(VLOOKUP($AS$2,Sheet1!Z12:AB12,3,0),0) -> 0 | AT14: =+IFERROR(VLOOKUP($AT$2,Sheet1!AD12:AG12,3,0),0) -> 0 | AU14: =+IFERROR(VLOOKUP($AU$2,Sheet1!AD12:AG12,3,0),0) -> 0 | AV14: =+IFERROR(VLOOKUP($AV$2,Sheet1!AD12:AG12,3,0),0) -> 0 | AW14: =+IFERROR(VLOOKUP($AW$2,Sheet1!AD12:AG12,3,0),0) -> 0 | AX14: =+IFERROR(VLOOKUP($AX$2,Sheet1!AD12:AG12,3,0),0) -> 0 | AY14: =+IFERROR(VLOOKUP($AY$2,Sheet1!AD12:AG12,3,0),0) -> 0 | AZ14: =+IFERROR(VLOOKUP($AZ$2,Sheet1!AD12:AG12,3,0),0) -> 0 | BA14: =+IFERROR(VLOOKUP($BA$2,Sheet1!AD12:AG12,3,0),0) -> 0 | BB14: =+IFERROR(VLOOKUP($BB$2,Sheet1!AD12:AG12,3,0),0) -> 0 | BC14: =+IFERROR(VLOOKUP($BC$2,Sheet1!AH12:AK12,3,0),0) -> 0 | BD14: =+IFERROR(VLOOKUP($BD$2,Sheet1!AH12:AK12,3,0),0) -> 0 | BE14: =+IFERROR(VLOOKUP($BE$2,Sheet1!AH12:AK12,3,0),0) -> 0 | BF14: =+IFERROR(VLOOKUP($BF$2,Sheet1!AH12:AK12,3,0),0) -> 0 | BG14: =+IFERROR(VLOOKUP($BG$2,Sheet1!AH12:AK12,3,0),0) -> 0 | BH14: =+IFERROR(VLOOKUP($BH$2,Sheet1!AH12:AK12,3,0),0) -> 0 | BI14: =+IFERROR(VLOOKUP($BI$2,Sheet1!AH12:AK12,3,0),0) -> 0 | BJ14: =+IFERROR(VLOOKUP($BJ$2,Sheet1!AH12:AK12,3,0),0) -> 0 | BK14: =+IFERROR(VLOOKUP($BK$2,Sheet1!AH12:AK12,3,0),0) -> 0 | BL14: =+IFERROR(VLOOKUP($BL$2,Sheet1!AH12:AK12,3,0),0) -> 0 | BM14: =+IFERROR(VLOOKUP($BM$2,Sheet1!AH12:AK12,3,0),0) -> 0 | BN14: =+IFERROR(VLOOKUP($BN$2,Sheet1!AL12:AO12,3,0),0) -> 0 | BO14: =+IFERROR(VLOOKUP($BO$2,Sheet1!AL12:AO12,3,0),0) -> 0 | BP14: =+IFERROR(VLOOKUP($BP$2,Sheet1!AL12:AO12,3,0),0) -> 0 | BQ14: =+IFERROR(VLOOKUP($BQ$2,Sheet1!AL12:AO12,3,0),0) -> 0 | BR14: =+IFERROR(VLOOKUP($BR$2,Sheet1!AL12:AO12,3,0),0) -> 0 | BS14: =+IFERROR(VLOOKUP($BS$2,Sheet1!AL12:AO12,3,0),0) -> 0 | BT14: =+IFERROR(VLOOKUP($BT$2,Sheet1!AL12:AO12,3,0),0) -> 0 | BU14: =+IFERROR(VLOOKUP($BU$2,Sheet1!AL12:AO12,3,0),0) -> 0 | BV14: =+IFERROR(VLOOKUP($BV$2,Sheet1!AL12:AO12,3,0),0) -> 0 | BW14: =+IFERROR(VLOOKUP($BW$2,Sheet1!AL12:AO12,3,0),0) -> 0 | BX14: =+IFERROR(VLOOKUP($BX$2,Sheet1!AL12:AO12,3,0),0) -> 0 | BY14: =+IFERROR(VLOOKUP($BY$2,Sheet1!AL12:AO12,3,0),0) -> 0 | BZ14: =+IFERROR(VLOOKUP($BZ$2,Sheet1!AP12:AS12,3,0),0) -> 0 | CA14: =+IFERROR(VLOOKUP($CA$2,Sheet1!AT12:AW12,3,0),0) -> 0 | CB14: =+IFERROR(VLOOKUP($CB$2,Sheet1!AX12:BA12,3,0),0) -> 0 | CC14: =+IFERROR(VLOOKUP($CC$2,Sheet1!BB12:BE12,3,0),0) -> 0 | CD14: =+IFERROR(VLOOKUP($CD$2,Sheet1!BF12:BI12,3,0),0) -> 0 | CE14: =+IFERROR(VLOOKUP($CE$2,Sheet1!BJ12:BM12,3,0),0) -> 0 | CF14: =+IFERROR(VLOOKUP($CF$2,Sheet1!BN12:BQ12,3,0),0) -> 0 | CG14: =+IFERROR(VLOOKUP($CG$2,Sheet1!BR12:BU12,3,0),0) -> 0 | CH14: =+IFERROR(VLOOKUP($CH$2,Sheet1!BV12:BY12,3,0),0) -> 0 | CI14: =Sheet1!E12 -> 0 | CJ14: =Sheet1!CY12 -> 0 | CK14: =Sheet1!CZ12 -> 0 | CL14: =Sheet1!CX12 -> 0 | CM14: =Sheet1!BZ12 -> 0 | CN14: 1300 | CO14: 0.08 | CP14: =CN14*CO14 -> 104 | CQ14: 0.25 | CR14: =CN14*CQ14 -> 325 | CS14: =Sheet1!CF12 -> 0 | CT14: =CN14*CS14 -> 0 | CU14: =CN14+CP14+CR14+CT14 -> 1729 | CV14: 0.02 | CW14: =CU14*CV14 -> 34.58 | CX14: 0.01 | CY14: =CU14*CX14 -> 17.29 | CZ14: =Sheet1!CM12 -> 0 | DA14: =CZ14*CU14 -> 0
