Workbook

Sheet Sheet1
A1: DOCKET NO. | B1: Base Date | C1: ITEM CODE | D1: PROPOSE ERP ITEM NAME | E1: PROPOSE DRUM TYPE | F1: Insulation Screening (Metallic) | G1: RM RATE (Insulation Screening (Metallic)) | H1: Weight (Insulation Screening (Metallic)) | I1: COST(Insulation Screening (Metallic)) | J1: Conductor | K1: RM RATE(Conductor) | L1: WEIGHT(Conductor) | M1: COST(Conductor) | N1: AL ALLOY | O1: RM RATE(Alu Alloy) | P1: WEIGHT(Alu Alloy) | Q1: COST(Alu Alloy) | R1: Insulation Screening (Non-Metallic) | S1: RM RATE(Insulation Screening (Non-Metallic)) | T1: WEIGHT(Insulation Screening (Non-Metallic)) | U1: COST(Insulation Screening (Non-Metallic)) | V1: Insulation | W1: RM RATE(Insulation) | X1: WEIGHT(Insulation) | Y1: COST(Insulation) | Z1: POLY TAPE | AA1: RM RATE (Poly Tape) | AB1: WEIGHT (Poly Tape) | AC1: COST(Poly Tape) | AD1: Inner Sheath | AE1: RM RATE(Inner Sheath) | AF1: WEIGHT(Inner Sheath) | AG1: COST(Inner Sheath) | AH1: Armouring | AI1: RM RATE(Armouring) | AJ1: WEIGHT(Armouring) | AK1: COST(Armouring) | AL1: Outer Sheath | AM1: RM RATE(Outer Sheath) | AN1: WEIGHT(Outer Sheath) | AO1: COST(Outer Sheath) | AP1: FILLER | AQ1: RM RATE(Filler) | AR1: WEIGHT(Filler) | AS1: COST(Filler) | AT1: GREASE | AU1: RM RATE(Grease) | AV1: WEIGHT(Grease) | AW1: COST(Grease) | AX1: Water swellable Tape | AY1: RM RATE(Water swellable Tape) | AZ1: WEIGHT(Water swellable Tape) | BA1: COST(Water swellable Tape) | BB1: Semi conducting Water Swellable tape | BC1: RM RATE(Semi conducting Water Swellable tape) | BD1: WEIGHT(Semi conducting Water Swellable tape) | BE1: COST(Semi conducting Water Swellable tape) | BF1: SEMICON TAPE | BG1: RM RATE(SEMICON TAPE) | BH1: WEIGHT(SEMICON TAPE) | BI1: COST(SEMICON TAPE) | BJ1: GLASS FIBER TAPE | BK1: RM RATE(GLASS FIBER TAPE) | BL1: WEIGHT(GLASS FIBER TAPE) | BM1: COST(GLASS FIBER TAPE) | BN1: COPPER WIRE 0.8 MM | BO1: RM RATE(COPPER WIRE 0.8 MM) | BP1: WEIGHT(COPPER WIRE 0.8 MM) | BQ1: COST(COPPER WIRE 0.8 MM) | BR1: RUBBERIZED COTTON TAPE | BS1: RM RATE(RUBBERIZED COTTON TAPE) | BT1: WEIGHT(RUBBERIZED COTTON TAPE) | BU1: COST(RUBBERIZED COTTON TAPE) | BV1: Water Tight Compound | BW1: RM RATE(Water Tight Compound) | BX1: WEIGHT(Water Tight Compound) | BY1: COST(Water Tight Compound) | BZ1: DRUM COST PER KM | CA1: TOTAL RM COST | CB1: FIRM % | CC1: FIRM VALUE | CD1: MFG% | CE1: MFG VALUE | CF1: PROF% | CG1: PROFIT VALUE | CH1: 1ST EX-WORKS | CI1: Intt % | CJ1: INTT VALUE | CK1: insp% | CL1: INSP VALUE | CM1: EX-WORKS (PER KM) | CN1: FREIGHT PER KM | CO1: PRICE INCLUDING FREIGHT (PER KM) | CP1: GST % | CQ1: GST VALUE | CR1: PRICE INCLUDING GST & FREIGHT (PER KM) | CS1: QTY | CT1: Unit | CU1: TOTAL PRICE OF FULL QTY (INCLUDING FRIGHT & GST) | CV1: DRUM CODE | CW1: DRUM SIZE (FxbXtx Ft) | CX1: PARTY STANDARD LENGTH (MTR)
A2: ENQ-11285-22-23 | B2: 45170 | C2: FA0600021 | D2: 1 CORE X 185 SQ. MM. AL/UNARD. (XLPE) | E2: Hybrid | J2: Alumimium | K2: 212 | L2: 499.5 | M2: 105894 | P2: 0 | T2: 0 | V2: LT-XLPE | W2: 116 | X2: 90 | Y2: 10440 | AB2: 0 | AF2: 0 | AJ2: 0 | AL2: FRLSH PVC Type ST-2 | AM2: 94 | AN2: 207 | AO2: 19458 | AR2: 0 | AV2: 0 | AX2: Water swellable Tape | AY2: 455 | AZ2: 0 | BA2: 0 | BD2: 0 | BH2: 0 | BL2: 0 | BP2: 0 | BT2: 0 | BX2: 0 | BZ2: 7976.12 | CA2: 143768.12 | CH2: 143768.12 | CM2: 143768.12 | CO2: 143768.12 | CR2: 143768.12 | CS2: 6.7 | CT2: KMS | CU2: 963246 | CV2: MD0100107 | CW2: DRUM - 42 X 15 X 38 X 2 (LOMBU-HYBRID) | CX2: 1000
A3: ENQ-11285-22-23 | B3: 45170 | C3: FA1000114 | D3: 1 CORE X 4 SQ. MM. AL/UNARD (XLPE) | E3: Hybrid | J3: Alumimium | K3: 212 | L3: 11 | M3: 2332 | P3: 0 | T3: 0 | V3: LT-XLPE | W3: 116 | X3: 11 | Y3: 1276 | AB3: 0 | AF3: 0 | AJ3: 0 | AL3: FRLSH PVC Type ST-2 | AM3: 94 | AN3: 56 | AO3: 5264 | AR3: 0 | AV3: 0 | AZ3: 0 | BD3: 0 | BH3: 0 | BL3: 0 | BP3: 0 | BT3: 0 | BX3: 0 | BZ3: 1875.84 | CA3: 10747.84 | CH3: 10747.84 | CM3: 10747.84 | CO3: 10747.84 | CR3: 10747.84 | CS3: 12.5 | CT3: KMS | CU3: 134348 | CV3: MD0100004 | CW3: DRUM - 28 X 10 X 23 X 2 | CX3: 1000
A4: ENQ-11285-22-23 | B4: 45170 | C4: FA0600032 | D4: 1 CORE X 630 SQ. MM. ALU/UNARD (XLPE) | E4: STEEL | J4: Alumimium | K4: 212 | L4: 1701 | M4: 360612 | P4: 0 | T4: 0 | V4: LT-XLPE | W4: 116 | X4: 253 | Y4: 29348 | AB4: 0 | AF4: 0 | AJ4: 0 | AL4: FRLSH PVC Type ST-2 | AM4: 94 | AN4: 429 | AO4: 40326 | AR4: 0 | AV4: 0 | AX4: Water swellable Tape | AY4: 455 | AZ4: 0 | BA4: 0 | BD4: 0 | BH4: 0 | BL4: 0 | BP4: 0 | BT4: 0 | BX4: 0 | BZ4: 26600 | CA4: 456886 | CH4: 456886 | CM4: 456886 | CO4: 456886 | CR4: 456886 | CS4: 18 | CT4: KMS | CU4: 8223948 | CV4: SP0400126 | CW4: CORRUGATED DISPATCH STEEL DRUM 1900 X 830 X 915 MM | CX4: 1000
A5: ENQ-11285-22-23 | B5: 45170 | C5: FA0600013 | D5: 1 CORE X 95 SQ. MM. AL/UNARD(XLPE ) | E5: Hybrid | J5: Alumimium | K5: 212 | L5: 256.5 | M5: 54378 | P5: 0 | T5: 0 | V5: LT-XLPE | W5: 116 | X5: 53 | Y5: 6148 | AB5: 0 | AF5: 0 | AJ5: 0 | AL5: FRLSH PVC Type ST-2 | AM5: 94 | AN5: 139 | AO5: 13066 | AR5: 0 | AV5: 0 | AZ5: 0 | BD5: 0 | BH5: 0 | BL5: 0 | BP5: 0 | BT5: 0 | BX5: 0 | BZ5: 7244.19 | CA5: 80836.19 | CH5: 80836.19 | CM5: 80836.19 | CO5: 80836.19 | CR5: 80836.19 | CS5: 18.5 | CT5: KMS | CU5: 1495470 | CV5: MD0100106 | CW5: DRUM - 42 X 15 X 23 X 2 (LOMBU-HYBRID) | CX5: 1000
A6: ENQ-11285-22-23 | B6: 45170 | C6: FA0600020 | D6: 1 CORE X 300 SQ. MM. AL/UNARD. (XLPE) | E6: STEEL | J6: Alumimium | K6: 212 | L6: 810 | M6: 171720 | P6: 0 | T6: 0 | V6: LT-XLPE | W6: 116 | X6: 132 | Y6: 15312 | AB6: 0 | AF6: 0 | AJ6: 0 | AL6: FRLSH PVC Type ST-2 | AM6: 94 | AN6: 251 | AO6: 23594 | AR6: 0 | AV6: 0 | AX6: Water swellable Tape | AY6: 455 | AZ6: 0 | BA6: 0 | BD6: 0 | BH6: 0 | BL6: 0 | BP6: 0 | BT6: 0 | BX6: 0 | CA6: 210626 | CH6: 210626 | CM6: 210626 | CO6: 210626 | CR6: 210626 | CS6: 20.7 | CT6: KMS | CU6: 4359958 | CX6: 1000
A7: ENQ-11285-22-23 | B7: 45170 | C7: FA0500020 | D7: 1 CORE X 25 SQ. MM. ALU/UNARD (XLPE ) | E7: Hybrid | J7: Alumimium | K7: 212 | L7: 67.5 | M7: 14310 | P7: 0 | T7: 0 | V7: LT-XLPE | W7: 116 | X7: 26 | Y7: 3016 | AB7: 0 | AF7: 0 | AJ7: 0 | AL7: FRLSH PVC Type ST-2 | AM7: 94 | AN7: 89 | AO7: 8366 | AR7: 0 | AV7: 0 | AZ7: 0 | BD7: 0 | BH7: 0 | BL7: 0 | BP7: 0 | BT7: 0 | BX7: 0 | BZ7: 1875.84 | CA7: 27567.84 | CH7: 27567.84 | CM7: 27567.84 | CO7: 27567.84 | CR7: 27567.84 | CS7: 39 | CT7: KMS | CU7: 1075146 | CV7: MD0100004 | CW7: DRUM - 28 X 10 X 23 X 2 | CX7: 1000
A8: ENQ-11285-22-23 | B8: 45170 | C8: FA1500045 | D8: 2 CORE X 25 SQ MM + 1 CORE X 25 SQ MM (AB CABLES) (BARE) | E8: STEEL | J8: Alumimium | K8: 212 | L8: 135 | M8: 28620 | N8: Alumimium Alloy | O8: 219 | P8: 67.5 | Q8: 14782.5 | T8: 0 | V8: LT-XLPE | W8: 116 | X8: 56 | Y8: 6496 | AB8: 0 | AF8: 0 | AJ8: 0 | AN8: 0 | AR8: 0 | AV8: 0 | AZ8: 0 | BD8: 0 | BH8: 0 | BL8: 0 | BP8: 0 | BT8: 0 | BX8: 0 | CA8: 49898.5 | CH8: 49898.5 | CM8: 49898.5 | CO8: 49898.5 | CR8: 49898.5 | CS8: 40 | CT8: KMS | CU8: 1995940 | CX8: 1000
A9: ENQ-11285-22-23 | B9: 45170 | C9: FA1100262 | D9: 4 CORE X 150 SQ. MM. AL/ARD - STRIP/TYPE - B (XLPE) | E9: STEEL | J9: Alumimium | K9: 212 | L9: 1620 | M9: 343440 | P9: 0 | T9: 0 | V9: LT-XLPE | W9: 116 | X9: 275 | Y9: 31900 | AB9: 0 | AD9: PVC Type ST-2 | AE9: 61.6 | AF9: 135 | AG9: 8316 | AH9: Galvanised Steel Flat Strip-B | AI9: 87.87 | AJ9: 1212 | AK9: 106498.44 | AL9: FRLSH PVC Type ST-2 | AM9: 94 | AN9: 445 | AO9: 41830 | AR9: 0 | AV9: 0 | AX9: Water swellable Tape | AY9: 455 | AZ9: 0 | BA9: 0 | BD9: 0 | BH9: 0 | BL9: 0 | BP9: 0 | BR9: RUBBERIZED COTTON TAPE | BS9: 450 | BT9: 0 | BU9: 0 | BX9: 0 | CA9: 531984.44 | CH9: 531984.44 | CM9: 531984.44 | CO9: 531984.44 | CR9: 531984.44 | CS9: 45 | CT9: KMS | CU9: 23939300 | CX9: 500
A10: ENQ-11285-22-23 | B10: 45170 | C10: FA0500035 | D10: 1 CORE X 2.5 SQ. MM. ALU/UNARD (XLPE) | E10: Hybrid | J10: Alumimium | K10: 212 | L10: 6.75 | M10: 1431 | P10: 0 | T10: 0 | V10: LT-XLPE | W10: 116 | X10: 10 | Y10: 1160 | AB10: 0 | AF10: 0 | AJ10: 0 | AL10: FRLSH PVC Type ST-2 | AM10: 94 | AN10: 53 | AO10: 4982 | AR10: 0 | AV10: 0 | AZ10: 0 | BD10: 0 | BH10: 0 | BL10: 0 | BP10: 0 | BT10: 0 | BX10: 0 | BZ10: 1875.84 | CA10: 9448.84 | CH10: 9448.84 | CM10: 9448.84 | CO10: 9448.84 | CR10: 9448.84 | CS10: 46 | CT10: KMS | CU10: 434647 | CV10: MD0100004 | CW10: DRUM - 28 X 10 X 23 X 2 | CX10: 1000
A11: ENQ-11285-22-23 | B11: 45170 | C11: FA1100176 | D11: 4 CORE X 300 SQ. MM. AL/ARD - WIRE (XLPE) | E11: STEEL | J11: Alumimium | K11: 212 | L11: 3240 | M11: 686880 | P11: 0 | T11: 0 | V11: LT-XLPE | W11: 116 | X11: 488 | Y11: 56608 | AB11: 0 | AD11: PVC Type ST-2 | AE11: 61.6 | AF11: 255 | AG11: 15708 | AH11: Galvanised Steel Round Wire | AI11: 86.13 | AJ11: 3436 | AK11: 295942.68 | AL11: FRLSH PVC Type ST-2 | AM11: 94 | AN11: 888 | AO11: 83472 | AR11: 0 | AV11: 0 | AX11: Water swellable Tape | AY11: 455 | AZ11: 0 | BA11: 0 | BD11: 90 | BH11: 0 | BL11: 0 | BP11: 0 | BR11: RUBBERIZED COTTON TAPE | BS11: 450 | BT11: 36 | BU11: 16200 | BX11: 0 | BZ11: 78780 | CA11: 1233590.7 | CH11: 1233590.7 | CM11: 1233590.7 | CO11: 1233590.7 | CR11: 1233590.7 | CS11: 72 | CT11: KMS | CU11: 88818529 | CV11: SP0400139 | CW11: CORRUGATED DISPATCH STEEL DRUM 2130 X 890 X 965 | CX11: 500
A12: ENQ-11285-22-23 | B12: 45170 | C12: FA1100012 | D12: 4 CORE X 95 SQ. MM. AL/ARD - STRIP (XLPE) | E12: STEEL | J12: Alumimium | K12: 212 | L12: 1026 | M12: 217512 | P12: 0 | T12: 0 | V12: LT-XLPE | W12: 116 | X12: 187 | Y12: 21692 | AB12: 0 | AD12: PVC Type ST-2 | AE12: 61.6 | AF12: 93 | AG12: 5728.8 | AH12: Galvanised Steel Flat Strip | AI12: 77.87 | AJ12: 611 | AK12: 47578.57 | AL12: FRLSH PVC Type ST-2 | AM12: 94 | AN12: 348 | AO12: 32712 | AR12: 0 | AV12: 0 | AZ12: 0 | BD12: 0 | BH12: 0 | BL12: 0 | BP12: 0 | BR12: RUBBERIZED COTTON TAPE | BS12: 450 | BT12: 0 | BU12: 0 | BX12: 0 | CA12: 325223.37 | CH12: 325223.37 | CM12: 325223.37 | CO12: 325223.37 | CR12: 325223.37 | CS12: 82 | CT12: KMS | CU12: 26668316 | CX12: 500
A13: ENQ-11285-22-23 | B13: 45170 | C13: FA0900036 | D13: 4 CORE X 50 SQ. MM. ALU/ARD - STRIP (XLPE) | E13: STEEL | J13: Alumimium | K13: 212 | L13: 540 | M13: 114480 | P13: 0 | T13: 0 | V13: LT-XLPE | W13: 116 | X13: 124 | Y13: 14384 | AB13: 0 | AD13: PVC Type ST-2 | AE13: 61.6 | AF13: 69 | AG13: 4250.4 | AH13: Galvanised Steel Flat Strip | AI13: 77.87 | AJ13: 457 | AK13: 35586.59 | AL13: FRLSH PVC Type ST-2 | AM13: 94 | AN13: 240 | AO13: 22560 | AR13: 0 | AV13: 0 | AZ13: 0 | BD13: 0 | BH13: 0 | BL13: 0 | BP13: 0 | BR13: RUBBERIZED COTTON TAPE | BS13: 450 | BT13: 0 | BU13: 0 | BX13: 0 | CA13: 191260.99 | CH13: 191260.99 | CM13: 191260.99 | CO13: 191260.99 | CR13: 191260.99 | CS13: 97 | CT13: KMS | CU13: 18552316 | CX13: 1000
A14: ENQ-11285-22-23 | B14: 45170 | C14: FA0900038 | D14: 2 CORE X 25 SQ. MM. AL/ARD - STRIP (XLPE) | E14: Hybrid | J14: Alumimium | K14: 212 | L14: 135 | M14: 28620 | P14: 0 | T14: 0 | V14: LT-XLPE | W14: 116 | X14: 38 | Y14: 4408 | AB14: 0 | AD14: PVC Type ST-2-PRESSURE EXTRUDED | AE14: 88 | AF14: 38 | AG14: 3344 | AH14: Galvanised Steel Flat Strip | AI14: 77.87 | AJ14: 256 | AK14: 19934.72 | AL14: FRLSH PVC Type ST-2 | AM14: 94 | AN14: 129 | AO14: 12126 | AR14: 0 | AV14: 0 | AZ14: 0 | BD14: 0 | BH14: 0 | BL14: 0 | BP14: 0 | BR14: RUBBERIZED COTTON TAPE | BS14: 450 | BT14: 0 | BU14: 0 | BX14: 0 | BZ14: 7976.12 | CA14: 76408.84 | CH14: 76408.84 | CM14: 76408.84 | CO14: 76408.84 | CR14: 76408.84 | CS14: 125 | CT14: KMS | CU14: 9551105 | CV14: MD0100105 | CW14: DRUM - 42 X 24 X 38 X 2 (LOMBU-HYBRID) | CX14: 1000
A15: ENQ-11285-22-23 | B15: 45170 | C15: FA0100086 | D15: 4 CORE X 150 SQ MM + 1 CORE X 16 SQ MM + 1 CORE X 150 SQ MM (AB CABLES) (BARE) | E15: WOOD | J15: Alumimium | K15: 212 | L15: 1664 | M15: 352768 | N15: Alumimium Alloy | O15: 219 | P15: 416 | Q15: 91104 | T15: 0 | V15: LT-XLPE | W15: 116 | X15: 360 | Y15: 41760 | AB15: 0 | AF15: 0 | AJ15: 0 | AN15: 0 | AR15: 0 | AV15: 0 | AZ15: 0 | BD15: 0 | BH15: 0 | BL15: 0 | BP15: 0 | BT15: 0 | BX15: 0 | BZ15: 17878.84 | CA15: 503510.84 | CH15: 503510.84 | CM15: 503510.84 | CO15: 503510.84 | CR15: 503510.84 | CS15: 170 | CT15: KMS | CU15: 85596843 | CV15: MD0100070 | CW15: DRUM - 68 X 24 X 32 X 3 | CX15: 500
A16: ENQ-11285-22-23 | B16: 45170 | C16: FA0900015 | D16: 4 CORE X 25 SQ. MM. ALU/ARD - STRIP (XLPE) | E16: Hybrid | J16: Alumimium | K16: 212 | L16: 270 | M16: 57240 | P16: 0 | T16: 0 | V16: LT-XLPE | W16: 116 | X16: 95 | Y16: 11020 | AB16: 0 | AD16: PVC Type ST-2 | AE16: 61.6 | AF16: 46 | AG16: 2833.6 | AH16: Galvanised Steel Flat Strip | AI16: 77.87 | AJ16: 364 | AK16: 28344.68 | AL16: FRLSH PVC Type ST-2 | AM16: 94 | AN16: 173 | AO16: 16262 | AR16: 0 | AV16: 0 | AZ16: 0 | BD16: 0 | BH16: 0 | BL16: 0 | BP16: 0 | BR16: RUBBERIZED COTTON TAPE | BS16: 450 | BT16: 0 | BU16: 0 | BX16: 0 | BZ16: 4493.28 | CA16: 120193.56 | CH16: 120193.56 | CM16: 120193.56 | CO16: 120193.56 | CR16: 120193.56 | CS16: 357 | CT16: KMS | CU16: 42909101 | CV16: MD0100092 | CW16: DRUM - 42 X 18 X 36 X 2 (LOMBU) | CX16: 1000
A17: ENQ-11285-22-23 | B17: 45170 | C17: FA0900133 | D17: 2 CORE X 16 SQ. MM. AL/ARD - WIRE (XLPE) | E17: Hybrid | J17: Alumimium | K17: 212 | L17: 86.4 | M17: 18316.8 | P17: 0 | T17: 0 | V17: LT-XLPE | W17: 116 | X17: 37 | Y17: 4292 | AB17: 0 | AD17: PVC Type ST-2-PRESSURE EXTRUDED | AE17: 88 | AF17: 33 | AG17: 2904 | AH17: Galvanised Steel Round Wire | AI17: 86.13 | AJ17: 416 | AK17: 35830.08 | AL17: FRLSH PVC Type ST-2 | AM17: 94 | AN17: 144 | AO17: 13536 | AR17: 0 | AV17: 0 | AZ17: 0 | BD17: 0 | BH17: 0 | BL17: 0 | BP17: 0 | BR17: RUBBERIZED COTTON TAPE | BS17: 450 | BT17: 0 | BU17: 0 | BX17: 0 | BZ17: 7244.19 | CA17: 82123.07 | CH17: 82123.07 | CM17: 82123.07 | CO17: 82123.07 | CR17: 82123.07 | CS17: 1511 | CT17: KMS | CU17: 124087959 | CV17: MD0100106 | CW17: DRUM - 42 X 15 X 23 X 2 (LOMBU-HYBRID) | CX17: 1000

Sheet AUTO CALCULATION SHEET (2)
A2: Tata Power Delhi Distribution Limited
A4: TENDER SPECIFICATION NO () | B4: TPDDL/ENGG/ENQ/200001584/23-24
A5: TENDER DESCRIPTION () | B5: Rate Contract for supply of LT XLPE Power and AB Cables at Tata Power-DDL Site/Store.
A6: Last Date & Time of Submission () | B6: 06.10.2023 up to 1500 Hours
A7: REVERSE AUCTION | B7: Tata Power-DDL reserves the right to conduct the reverse auction (instead of public opening of price bids) for the products/ services being asked for in the tender. The terms and conditions for such reverse auction events shall be as per the Acceptance Form attached as Annexure VI of this document. The bidders along with the tender document shall mandatorily submit a duly signed copy of the Acceptance Form attached as Annexure VI as a token of acceptance for the same.
A8: Price () | B8: LME Average Settlement Price in Kg including Premium for Ingot as per IEEMA. This price is applicable as of 1st working day of the month, 1 month prior to the due date of submission of tender.
A9: Validity () | B9: Bids shall remain valid for 180 days from the due date of submission of the bid. Notwithstanding clause above, the Tata Power-DDL may solicit the Bidder’s consent to an extension of the Period of Bid Validity. The request and responses thereto shall be made in writing.
A10: Delivery Period () | B10: The total time for completion of delivery at Tata Power-DDL Stores shall be within 60 days from the date of issue of RO to BA or manufacturing clearance whichever is later.
A11: Payment Terms () | B11: Tata Power-DDL will make 100% payment within 45 days (MSME) / 60 days (Non MSME) of submission of the Bill/Invoice complete in all respects and along with all the requisite documents at Bill Inward Receipt Desk (BIRD) located at Civil Lines II Office, Tata Power-DDL Near Delhi Vidhan Sabha; subject to condition that associate has furnished the requisite Security-cumPerformance Guarantee as stipulated in the contract.
A12: Technical Specification
BF13: Consider Rs. 1 extra for colour of o/sh for all cables
N14: =Sheet1!J1 -> Conductor | S14: AL ALLOY | U14: Insulation Screening (Metallic) | AC14: Insulation Screening (Non-Metallic) | AE14: Insulation | AK14: POLY TAPE | AL14: Inner Sheath | AS14: Armouring | BC14: Consider 5 rs/kg extra on outer sheath for UV protection for all cables | BM14: FILLER | BN14: GREASE | BO14: Water swellable Tape | BP14: Semi conducting Water Swellable tape | BQ14: SEMICON TAPE | BR14: GLASS FIBER TAPE | BS14: COPPER WIRE 0.8 MM | BT14: RUBBERIZED COTTON TAPE | BU14: Water Tight Compound | BZ14: DRUM COST PER KM | CA14: TOTAL RM COST | CB14: EXTRA CONSUMPTION | CC14: EXTRA CONSUMPTION VALUE
A15: DOCKET NO. | B15: =Sheet1!B1 -> Base Date | C15: ITEM CODE | D15: PROPOSE ERP ITEM NAME | E15: EX-WORKS (PER KM) | F15: FREIGHT PER KM | G15: PRICE INCLUDING FREIGHT (PER KM) | H15: GST % | I15: GST VALUE | J15: PRICE INCLUDING GST & FREIGHT (PER KM) | K15: QTY | L15: Unit | M15: TOTAL PRICE OF FULL QTY (INCLUDING FRIGHT & GST) | N15: Alumimium | O15: Alumimium ALLOY | P15: Copper | Q15: Flexible Copper | R15: Galvanized steel wire | S15: Alumimium | T15: Alumimium ALLOY | U15: Coper tape - 0.1 mm | V15: Copper Tape - 0.03 mm | W15: Copper Tape - 0.035 mm | X15: Copper Tape - 0.04 mm | Y15: Copper Tape - 0.045 mm | Z15: Copper Tape - 0.050 mm | AA15: Copper Tape - 0.060 mm | AB15: Copper Tape - 0.075 mm(DOUBLE) | AC15: Extruded semiconductive | AD15: Extruded Semiconductive(Stripable) | AE15: HT-XLPE | AF15: LT-XLPE | AG15: TR XLPE | AH15: Type A PVC | AI15: Type C PVC (HR) | AJ15: XLPE | AK15: POLY TAPE | AL15: FR PVC Type ST-1 | AM15: FR PVC Type ST-2 | AN15: FRLSH PVC Type ST-2 | AO15: PVC Type ST-1 | AP15: PVC Type ST-1-PRESSURE EXTRUDED | AQ15: PVC Type ST-2 | AR15: PVC Type ST-2-PRESSURE EXTRUDED | AS15: ACSR CORE WIRE | AT15: ACSR DOG STEEL WIRE | AU15: Aluminium Flat Strip | AV15: Aluminium Round Wire | AW15: Double Steel Tape | AX15: Galvanised Steel Flat Strip | AY15: Galvanised Steel Flat Strip (Double) | AZ15: Galvanised Steel Flat Strip-B | BA15: Galvanised Steel Round Wire | BB15: Galvanised Steel Round Wire (Double) | BC15: FR PVC Type ST-1 | BD15: FR PVC Type ST-2 | BE15: FRLSH PVC Type ST-1 | BF15: FRLSH PVC Type ST-2 | BG15: PE, ST-3 | BH15: PE, ST-7 | BI15: PVC Type ST-1 | BJ15: PVC Type ST-2 | BK15: PVC Type ST-2-PRESSURE EXTRUDED | BL15: UV & Track Resistant XLPE | BM15: FILLER | BN15: Grease | BO15: NCWBT | BP15: Semi conducting Water Swellable tape | BQ15: SEMICON TAPE | BR15: GLASS FIBER TAPE | BS15: COPPER WIRE 0.8 MM | BT15: RUBBERIZED COTTON TAPE | BU15: Water Tight Compound | BV15: =Sheet1!E1 -> PROPOSE DRUM TYPE | BW15: =Sheet1!CV1 -> DRUM CODE | BX15: =Sheet1!CW1 -> DRUM SIZE (FxbXtx Ft) | BY15: =Sheet1!CX1 -> PARTY STANDARD LENGTH (MTR) | CD15: MFG% | CE15: MFG VALUE | CF15: PROF% | CG15: PROFIT VALUE | CH15: 1ST EX-WORKS | CI15: Intt % | CJ15: INTT VALUE | CK15: insp% | CL15: INSP VALUE
N16: 213 | O16: =+IFERROR(VLOOKUP($O$15,Sheet1!J:L,2,0),0) -> 0 | P16: =+IFERROR(VLOOKUP($P$15,Sheet1!J:M,2,0),0) -> 0 | Q16: =+IFERROR(VLOOKUP($Q$15,Sheet1!J:M,2,0),0) -> 0 | R16: =+IFERROR(VLOOKUP($R$15,Sheet1!J:M,2,0),0) -> 0 | S16: =+IFERROR(VLOOKUP($S$15,Sheet1!N:Q,2,0),0) -> 0 | T16: =N16+7 -> 220 | U16: =+IFERROR(VLOOKUP($U$15,Sheet1!F:I,2,0),0) -> 0 | V16: =+IFERROR(VLOOKUP($V$15,Sheet1!F:I,2,0),0) -> 0 | W16: =+IFERROR(VLOOKUP($W$15,Sheet1!F:I,2,0),0) -> 0 | X16: =+IFERROR(VLOOKUP($X$15,Sheet1!F:I,2,0),0) -> 0 | Y16: =+IFERROR(VLOOKUP($Y$15,Sheet1!F:I,2,0),0) -> 0 | Z16: =+IFERROR(VLOOKUP($Z$15,Sheet1!F:I,2,0),0) -> 0 | AA16: =+IFERROR(VLOOKUP($AA$15,Sheet1!F:I,2,0),0) -> 0 | AB16: =+IFERROR(VLOOKUP($AB$15,Sheet1!F:I,2,0),0) -> 0 | AC16: =+IFERROR(VLOOKUP($AC$15,Sheet1!R:U,2,0),0) -> 0 | AD16: =+IFERROR(VLOOKUP($AD$15,Sheet1!R:U,2,0),0) -> 0 | AE16: =+IFERROR(VLOOKUP($AE$15,Sheet1!V:Y,2,0),0) -> 0 | AF16: =+IFERROR(VLOOKUP($AF$15,Sheet1!V:Y,2,0),0) -> 116 | AG16: =+IFERROR(VLOOKUP($AG$15,Sheet1!V:Y,2,0),0) -> 0 | AH16: =+IFERROR(VLOOKUP($AH$15,Sheet1!V:Y,2,0),0) -> 0 | AI16: =+IFERROR(VLOOKUP($AI$15,Sheet1!V:Y,2,0),0) -> 0 | AJ16: =+IFERROR(VLOOKUP($AJ$15,Sheet1!V:Y,2,0),0) -> 0 | AK16: =+IFERROR(VLOOKUP($AK$15,Sheet1!Z2:AA840,2,0),0) -> 0 | AL16: =+IFERROR(VLOOKUP($AL$15,Sheet1!AD2:AG840,2,0),0) -> 0 | AM16: =+IFERROR(VLOOKUP($AM$15,Sheet1!AD2:AG840,2,0),0) -> 0 | AN16: =+IFERROR(VLOOKUP($AN$15,Sheet1!AD2:AG840,2,0),0) -> 0 | AO16: =+IFERROR(VLOOKUP($AO$15,Sheet1!AD2:AG840,2,0),0) -> 0 | AP16: =+IFERROR(VLOOKUP($AP$15,Sheet1!AD2:AG840,2,0),0) -> 0 | AQ16: 62 | AR16: 88 | AX16: 76 | AZ16: 86 | BA16: 88 | BF16: =94+5+1 -> 100 | BO16: 420 | BT16: 450 | BU16: =+IFERROR(VLOOKUP($BU$15,Sheet1!BV2:BY840,2,0),0) -> 0
A17: =Sheet1!A10 -> ENQ-11285-22-23 | B17: =Sheet1!B10 -> 45170 | C17: =Sheet1!C10 -> FA0500035 | D17: =Sheet1!D10 -> 1 CORE X 2.5 SQ. MM. ALU/UNARD (XLPE) | E17: =CH17+CJ17+CL17 -> 16844.625 | F17: =ROUNDUP(M36,0) -> 1848 | G17: =E17+F17 -> 18692.625 | H17: 0.18 | I17: =G17*H17 -> 3364.6725 | J17: =G17+I17 -> 22057.298 | K17: =Sheet1!CS10 -> 46 | L17: =Sheet1!CT10 -> KMS | M17: =J17*K17 -> 1014635.7 | N17: 7 | O17: =+IFERROR(VLOOKUP($O$15,Sheet1!J10:L10,3,0),0) -> 0 | P17: =+IFERROR(VLOOKUP($P$15,Sheet1!J10:M10,3,0),0) -> 0 | Q17: =+IFERROR(VLOOKUP($Q$15,Sheet1!J10:M10,3,0),0) -> 0 | R17: =+IFERROR(VLOOKUP($R$15,Sheet1!J10:M10,3,0),0) -> 0 | S17: =+IFERROR(VLOOKUP($S$15,Sheet1!N10:Q10,3,0),0) -> 0 | T17: =+IFERROR(VLOOKUP($T$15,Sheet1!N10:Q10,3,0),0) -> 0 | U17: =+IFERROR(VLOOKUP($U$15,Sheet1!F10:I10,3,0),0) -> 0 | V17: =+IFERROR(VLOOKUP($V$15,Sheet1!F10:I10,3,0),0) -> 0 | W17: =+IFERROR(VLOOKUP($W$15,Sheet1!F10:I10,3,0),0) -> 0 | X17: =+IFERROR(VLOOKUP($X$15,Sheet1!F10:I10,3,0),0) -> 0 | Y17: =+IFERROR(VLOOKUP($Y$15,Sheet1!F10:I10,3,0),0) -> 0 | Z17: =+IFERROR(VLOOKUP($Z$15,Sheet1!F10:I10,3,0),0) -> 0 | AA17: =+IFERROR(VLOOKUP($AA$15,Sheet1!F10:I10,3,0),0) -> 0 | AB17: =+IFERROR(VLOOKUP($AB$15,Sheet1!F10:I10,3,0),0) -> 0 | AC17: =+IFERROR(VLOOKUP($AC$15,Sheet1!R10:U10,3,0),0) -> 0 | AD17: =+IFERROR(VLOOKUP($AD$15,Sheet1!R10:U10,2,0),0) -> 0 | AE17: =+IFERROR(VLOOKUP($AE$15,Sheet1!V10:Y10,3,0),0) -> 0 | AF17: 9 | AG17: =+IFERROR(VLOOKUP($AG$15,Sheet1!V10:Y10,3,0),0) -> 0 | AH17: =+IFERROR(VLOOKUP($AH$15,Sheet1!V10:Y10,3,0),0) -> 0 | AI17: =+IFERROR(VLOOKUP($AI$15,Sheet1!V10:Y10,3,0),0) -> 0 | AJ17: =+IFERROR(VLOOKUP($AJ$15,Sheet1!V10:Y10,3,0),0) -> 0 | AK17: =+IFERROR(VLOOKUP($AK$15,Sheet1!Z10:AB10,3,0),0) -> 0 | AL17: =+IFERROR(VLOOKUP($AL$15,Sheet1!AD10:AG10,3,0),0) -> 0 | AM17: =+IFERROR(VLOOKUP($AM$15,Sheet1!AD10:AG10,3,0),0) -> 0 | AN17: =+IFERROR(VLOOKUP($AN$15,Sheet1!AD10:AG10,3,0),0) -> 0 | AO17: =+IFERROR(VLOOKUP($AO$15,Sheet1!AD10:AG10,3,0),0) -> 0 | AP17: =+IFERROR(VLOOKUP($AP$15,Sheet1!AD10:AG10,3,0),0) -> 0 | AQ17: =+IFERROR(VLOOKUP($AQ$15,Sheet1!AD10:AG10,3,0),0) -> 0 | AR17: =+IFERROR(VLOOKUP($AR$15,Sheet1!AD10:AG10,3,0),0) -> 0 | AS17: =+IFERROR(VLOOKUP($AS$15,Sheet1!AH10:AK10,3,0),0) -> 0 | AT17: =+IFERROR(VLOOKUP($AT$15,Sheet1!AH10:AK10,3,0),0) -> 0 | AU17: =+IFERROR(VLOOKUP($AU$15,Sheet1!AH10:AK10,3,0),0) -> 0 | AV17: =+IFERROR(VLOOKUP($AV$15,Sheet1!AH10:AK10,3,0),0) -> 0 | AW17: =+IFERROR(VLOOKUP($AW$15,Sheet1!AH10:AK10,3,0),0) -> 0 | AX17: =+IFERROR(VLOOKUP($AX$15,Sheet1!AH10:AK10,3,0),0) -> 0 | AY17: =+IFERROR(VLOOKUP($AY$15,Sheet1!AH10:AK10,3,0),0) -> 0 | AZ17: =+IFERROR(VLOOKUP($AZ$15,Sheet1!AH10:AK10,3,0),0) -> 0 | BA17: =+IFERROR(VLOOKUP($BA$15,Sheet1!AH10:AK10,3,0),0) -> 0 | BB17: =+IFERROR(VLOOKUP($BB$15,Sheet1!AH10:AK10,3,0),0) -> 0 | BC17: =+IFERROR(VLOOKUP($BC$15,Sheet1!AL10:AO10,3,0),0) -> 0 | BD17: =+IFERROR(VLOOKUP($BD$15,Sheet1!AL10:AO10,3,0),0) -> 0 | BE17: =+IFERROR(VLOOKUP($BE$15,Sheet1!AL10:AO10,3,0),0) -> 0 | BF17: 52 | BG17: =+IFERROR(VLOOKUP($BG$15,Sheet1!AL10:AO10,3,0),0) -> 0 | BH17: =+IFERROR(VLOOKUP($BH$15,Sheet1!AL10:AO10,3,0),0) -> 0 | BI17: =+IFERROR(VLOOKUP($BI$15,Sheet1!AL10:AO10,3,0),0) -> 0 | BJ17: =+IFERROR(VLOOKUP($BJ$15,Sheet1!AL10:AO10,3,0),0) -> 0 | BK17: =+IFERROR(VLOOKUP($BK$15,Sheet1!AL10:AO10,3,0),0) -> 0 | BL17: =+IFERROR(VLOOKUP($BL$15,Sheet1!AL10:AO10,3,0),0) -> 0 | BM17: =+IFERROR(VLOOKUP($BM$15,Sheet1!AP10:AS10,3,0),0) -> 0 | BN17: =+IFERROR(VLOOKUP($BN$15,Sheet1!AT10:AW10,3,0),0) -> 0 | BO17: =+IFERROR(VLOOKUP($BO$15,Sheet1!AX10:BA10,3,0),0) -> 0 | BP17: =+IFERROR(VLOOKUP($BP$15,Sheet1!BB10:BE10,3,0),0) -> 0 | BQ17: =+IFERROR(VLOOKUP($BQ$15,Sheet1!BF10:BI10,3,0),0) -> 0 | BR17: =+IFERROR(VLOOKUP($BR$15,Sheet1!BJ10:BM10,3,0),0) -> 0 | BS17: =+IFERROR(VLOOKUP($BS$15,Sheet1!BN10:BQ10,3,0),0) -> 0 | BT17: =+IFERROR(VLOOKUP($BT$15,Sheet1!BR10:BU10,3,0),0) -> 0 | BU17: =+IFERROR(VLOOKUP($BU$15,Sheet1!BV10:BY10,3,0),0) -> 0 | BV17: =Sheet1!E10 -> Hybrid | BW17: =Sheet1!CV10 -> MD0100004 | BX17: =Sheet1!CW10 -> DRUM - 28 X 10 X 23 X 2 | BY17: =VLOOKUP(C17,Sheet1!$C$1:$CX$17,100,0) -> 1000 | BZ17: 2960 | CA17: =SUMPRODUCT($N$16:$BU$16,N17:BU17)+BZ17 -> 10695 | CB17: =Sheet1!CB10 -> 0 | CC17: =CA17*CB17 -> 0 | CD17: 0.5 | CE17: =CA17*CD17 -> 5347.5 | CF17: 0 | CG17: =CA17*CF17 -> 0 | CH17: =CA17+CC17+CE17+CG17 -> 16042.5 | CI17: 0.03 | CJ17: =CH17*CI17 -> 481.275 | CK17: 0.02 | CL17: =CH17*CK17 -> 320.85
A18: =Sheet1!A3 -> ENQ-11285-22-23 | B18: =Sheet1!B3 -> 45170 | C18: =Sheet1!C3 -> FA1000114 | D18: =Sheet1!D3 -> 1 CORE X 4 SQ. MM. AL/UNARD (XLPE) | E18: =CH18+CJ18+CL18 -> 19181.925 | F18: =ROUNDUP(M37,0) -> 6800 | G18: =E18+F18 -> 25981.925 | H18: 0.18 | I18: =G18*H18 -> 4676.7465 | J18: =G18+I18 -> 30658.671 | K18: =Sheet1!CS3 -> 12.5 | L18: =Sheet1!CT3 -> KMS | M18: =J18*K18 -> 383233.39 | N18: =+IFERROR(VLOOKUP($N$15,Sheet1!J3:L3,3,0),0) -> 11 | O18: =+IFERROR(VLOOKUP($O$15,Sheet1!J3:L3,3,0),0) -> 0 | P18: =+IFERROR(VLOOKUP($P$15,Sheet1!J3:M3,3,0),0) -> 0 | Q18: =+IFERROR(VLOOKUP($Q$15,Sheet1!J3:M3,3,0),0) -> 0 | R18: =+IFERROR(VLOOKUP($R$15,Sheet1!J3:M3,3,0),0) -> 0 | S18: =+IFERROR(VLOOKUP($S$15,Sheet1!N3:Q3,3,0),0) -> 0 | T18: =+IFERROR(VLOOKUP($T$15,Sheet1!N3:Q3,3,0),0) -> 0 | U18: =+IFERROR(VLOOKUP($U$15,Sheet1!F3:I3,3,0),0) -> 0 | V18: =+IFERROR(VLOOKUP($V$15,Sheet1!F3:I3,3,0),0) -> 0 | W18: =+IFERROR(VLOOKUP($W$15,Sheet1!F3:I3,3,0),0) -> 0 | X18: =+IFERROR(VLOOKUP($X$15,Sheet1!F3:I3,3,0),0) -> 0 | Y18: =+IFERROR(VLOOKUP($Y$15,Sheet1!F3:I3,3,0),0) -> 0 | Z18: =+IFERROR(VLOOKUP($Z$15,Sheet1!F3:I3,3,0),0) -> 0 | AA18: =+IFERROR(VLOOKUP($AA$15,Sheet1!F3:I3,3,0),0) -> 0 | AB18: =+IFERROR(VLOOKUP($AB$15,Sheet1!F3:I3,3,0),0) -> 0 | AC18: =+IFERROR(VLOOKUP($AC$15,Sheet1!R3:U3,3,0),0) -> 0 | AD18: =+IFERROR(VLOOKUP($AD$15,Sheet1!R3:U3,2,0),0) -> 0 | AE18: =+IFERROR(VLOOKUP($AE$15,Sheet1!V3:Y3,3,0),0) -> 0 | AF18: =+IFERROR(VLOOKUP($AF$15,Sheet1!V3:Y3,3,0),0) -> 11 | AG18: =+IFERROR(VLOOKUP($AG$15,Sheet1!V3:Y3,3,0),0) -> 0 | AH18: =+IFERROR(VLOOKUP($AH$15,Sheet1!V3:Y3,3,0),0) -> 0 | AI18: =+IFERROR(VLOOKUP($AI$15,Sheet1!V3:Y3,3,0),0) -> 0 | AJ18: =+IFERROR(VLOOKUP($AJ$15,Sheet1!V3:Y3,3,0),0) -> 0 | AK18: =+IFERROR(VLOOKUP($AK$15,Sheet1!Z3:AB3,3,0),0) -> 0 | AL18: =+IFERROR(VLOOKUP($AL$15,Sheet1!AD3:AG3,3,0),0) -> 0 | AM18: =+IFERROR(VLOOKUP($AM$15,Sheet1!AD3:AG3,3,0),0) -> 0 | AN18: =+IFERROR(VLOOKUP($AN$15,Sheet1!AD3:AG3,3,0),0) -> 0 | AO18: =+IFERROR(VLOOKUP($AO$15,Sheet1!AD3:AG3,3,0),0) -> 0 | AP18: =+IFERROR(VLOOKUP($AP$15,Sheet1!AD3:AG3,3,0),0) -> 0 | AQ18: =+IFERROR(VLOOKUP($AQ$15,Sheet1!AD3:AG3,3,0),0) -> 0 | AR18: =+IFERROR(VLOOKUP($AR$15,Sheet1!AD3:AG3,3,0),0) -> 0 | AS18: =+IFERROR(VLOOKUP($AS$15,Sheet1!AH3:AK3,3,0),0) -> 0 | AT18: =+IFERROR(VLOOKUP($AT$15,Sheet1!AH3:AK3,3,0),0) -> 0 | AU18: =+IFERROR(VLOOKUP($AU$15,Sheet1!AH3:AK3,3,0),0) -> 0 | AV18: =+IFERROR(VLOOKUP($AV$15,Sheet1!AH3:AK3,3,0),0) -> 0 | AW18: =+IFERROR(VLOOKUP($AW$15,Sheet1!AH3:AK3,3,0),0) -> 0 | AX18: =+IFERROR(VLOOKUP($AX$15,Sheet1!AH3:AK3,3,0),0) -> 0 | AY18: =+IFERROR(VLOOKUP($AY$15,Sheet1!AH3:AK3,3,0),0) -> 0 | AZ18: =+IFERROR(VLOOKUP($AZ$15,Sheet1!AH3:AK3,3,0),0) -> 0 | BA18: =+IFERROR(VLOOKUP($BA$15,Sheet1!AH3:AK3,3,0),0) -> 0 | BB18: =+IFERROR(VLOOKUP($BB$15,Sheet1!AH3:AK3,3,0),0) -> 0 | BC18: =+IFERROR(VLOOKUP($BC$15,Sheet1!AL3:AO3,3,0),0) -> 0 | BD18: =+IFERROR(VLOOKUP($BD$15,Sheet1!AL3:AO3,3,0),0) -> 0 | BE18: =+IFERROR(VLOOKUP($BE$15,Sheet1!AL3:AO3,3,0),0) -> 0 | BF18: =+IFERROR(VLOOKUP($BF$15,Sheet1!AL3:AO3,3,0),0) -> 56 | BG18: =+IFERROR(VLOOKUP($BG$15,Sheet1!AL3:AO3,3,0),0) -> 0 | BH18: =+IFERROR(VLOOKUP($BH$15,Sheet1!AL3:AO3,3,0),0) -> 0 | BI18: =+IFERROR(VLOOKUP($BI$15,Sheet1!AL3:AO3,3,0),0) -> 0 | BJ18: =+IFERROR(VLOOKUP($BJ$15,Sheet1!AL3:AO3,3,0),0) -> 0 | BK18: =+IFERROR(VLOOKUP($BK$15,Sheet1!AL3:AO3,3,0),0) -> 0 | BL18: =+IFERROR(VLOOKUP($BL$15,Sheet1!AL3:AO3,3,0),0) -> 0 | BM18: =+IFERROR(VLOOKUP($BM$15,Sheet1!AP3:AS3,3,0),0) -> 0 | BN18: =+IFERROR(VLOOKUP($BN$15,Sheet1!AT3:AW3,3,0),0) -> 0 | BO18: =+IFERROR(VLOOKUP($BO$15,Sheet1!AX3:BA3,3,0),0) -> 0 | BP18: =+IFERROR(VLOOKUP($BP$15,Sheet1!BB3:BE3,3,0),0) -> 0 | BQ18: =+IFERROR(VLOOKUP($BQ$15,Sheet1!BF3:BI3,3,0),0) -> 0 | BR18: =+IFERROR(VLOOKUP($BR$15,Sheet1!BJ3:BM3,3,0),0) -> 0 | BS18: =+IFERROR(VLOOKUP($BS$15,Sheet1!BN3:BQ3,3,0),0) -> 0 | BT18: =+IFERROR(VLOOKUP($BT$15,Sheet1!BR3:BU3,3,0),0) -> 0 | BU18: =+IFERROR(VLOOKUP($BU$15,Sheet1!BV3:BY3,3,0),0) -> 0 | BV18: =Sheet1!E3 -> Hybrid | BW18: =Sheet1!CV3 -> MD0100004 | BX18: =Sheet1!CW3 -> DRUM - 28 X 10 X 23 X 2 | BY18: =VLOOKUP(C18,Sheet1!$C$1:$CX$17,100,0) -> 1000 | BZ18: 2960 | CA18: =SUMPRODUCT($N$16:$BU$16,N18:BU18)+BZ18 -> 12179 | CB18: =Sheet1!CB3 -> 0 | CC18: =CA18*CB18 -> 0 | CD18: 0.5 | CE18: =CA18*CD18 -> 6089.5 | CF18: =Sheet1!CF3 -> 0 | CG18: =CA18*CF18 -> 0 | CH18: =CA18+CC18+CE18+CG18 -> 18268.5 | CI18: 0.03 | CJ18: =CH18*CI18 -> 548.055 | CK18: 0.02 | CL18: =CH18*CK18 -> 365.37
A19: =Sheet1!A7 -> ENQ-11285-22-23 | B19: =Sheet1!B7 -> 45170 | C19: =Sheet1!C7 -> FA0500020 | D19: =Sheet1!D7 -> 1 CORE X 25 SQ. MM. ALU/UNARD (XLPE ) | E19: =CH19+CJ19+CL19 -> 46242 | F19: =ROUNDUP(M38,0) -> 2180 | G19: =E19+F19 -> 48422 | H19: 0.18 | I19: =G19*H19 -> 8715.96 | J19: =G19+I19 -> 57137.96 | K19: =Sheet1!CS7 -> 39 | L19: =Sheet1!CT7 -> KMS | M19: =J19*K19 -> 2228380.4 | N19: 68 | O19: =+IFERROR(VLOOKUP($O$15,Sheet1!J7:L7,3,0),0) -> 0 | P19: =+IFERROR(VLOOKUP($P$15,Sheet1!J7:M7,3,0),0) -> 0 | Q19: =+IFERROR(VLOOKUP($Q$15,Sheet1!J7:M7,3,0),0) -> 0 | R19: =+IFERROR(VLOOKUP($R$15,Sheet1!J7:M7,3,0),0) -> 0 | S19: =+IFERROR(VLOOKUP($S$15,Sheet1!N7:Q7,3,0),0) -> 0 | T19: =+IFERROR(VLOOKUP($T$15,Sheet1!N7:Q7,3,0),0) -> 0 | U19: =+IFERROR(VLOOKUP($U$15,Sheet1!F7:I7,3,0),0) -> 0 | V19: =+IFERROR(VLOOKUP($V$15,Sheet1!F7:I7,3,0),0) -> 0 | W19: =+IFERROR(VLOOKUP($W$15,Sheet1!F7:I7,3,0),0) -> 0 | X19: =+IFERROR(VLOOKUP($X$15,Sheet1!F7:I7,3,0),0) -> 0 | Y19: =+IFERROR(VLOOKUP($Y$15,Sheet1!F7:I7,3,0),0) -> 0 | Z19: =+IFERROR(VLOOKUP($Z$15,Sheet1!F7:I7,3,0),0) -> 0 | AA19: =+IFERROR(VLOOKUP($AA$15,Sheet1!F7:I7,3,0),0) -> 0 | AB19: =+IFERROR(VLOOKUP($AB$15,Sheet1!F7:I7,3,0),0) -> 0 | AC19: =+IFERROR(VLOOKUP($AC$15,Sheet1!R7:U7,3,0),0) -> 0 | AD19: =+IFERROR(VLOOKUP($AD$15,Sheet1!R7:U7,2,0),0) -> 0 | AE19: =+IFERROR(VLOOKUP($AE$15,Sheet1!V7:Y7,3,0),0) -> 0 | AF19: =+IFERROR(VLOOKUP($AF$15,Sheet1!V7:Y7,3,0),0) -> 26 | AG19: =+IFERROR(VLOOKUP($AG$15,Sheet1!V7:Y7,3,0),0) -> 0 | AH19: =+IFERROR(VLOOKUP($AH$15,Sheet1!V7:Y7,3,0),0) -> 0 | AI19: =+IFERROR(VLOOKUP($AI$15,Sheet1!V7:Y7,3,0),0) -> 0 | AJ19: =+IFERROR(VLOOKUP($AJ$15,Sheet1!V7:Y7,3,0),0) -> 0 | AK19: =+IFERROR(VLOOKUP($AK$15,Sheet1!Z7:AB7,3,0),0) -> 0 | AL19: =+IFERROR(VLOOKUP($AL$15,Sheet1!AD7:AG7,3,0),0) -> 0 | AM19: =+IFERROR(VLOOKUP($AM$15,Sheet1!AD7:AG7,3,0),0) -> 0 | AN19: =+IFERROR(VLOOKUP($AN$15,Sheet1!AD7:AG7,3,0),0) -> 0 | AO19: =+IFERROR(VLOOKUP($AO$15,Sheet1!AD7:AG7,3,0),0) -> 0 | AP19: =+IFERROR(VLOOKUP($AP$15,Sheet1!AD7:AG7,3,0),0) -> 0 | AQ19: =+IFERROR(VLOOKUP($AQ$15,Sheet1!AD7:AG7,3,0),0) -> 0 | AR19: =+IFERROR(VLOOKUP($AR$15,Sheet1!AD7:AG7,3,0),0) -> 0 | AS19: =+IFERROR(VLOOKUP($AS$15,Sheet1!AH7:AK7,3,0),0) -> 0 | AT19: =+IFERROR(VLOOKUP($AT$15,Sheet1!AH7:AK7,3,0),0) -> 0 | AU19: =+IFERROR(VLOOKUP($AU$15,Sheet1!AH7:AK7,3,0),0) -> 0 | AV19: =+IFERROR(VLOOKUP($AV$15,Sheet1!AH7:AK7,3,0),0) -> 0 | AW19: =+IFERROR(VLOOKUP($AW$15,Sheet1!AH7:AK7,3,0),0) -> 0 | AX19: =+IFERROR(VLOOKUP($AX$15,Sheet1!AH7:AK7,3,0),0) -> 0 | AY19: =+IFERROR(VLOOKUP($AY$15,Sheet1!AH7:AK7,3,0),0) -> 0 | AZ19: =+IFERROR(VLOOKUP($AZ$15,Sheet1!AH7:AK7,3,0),0) -> 0 | BA19: =+IFERROR(VLOOKUP($BA$15,Sheet1!AH7:AK7,3,0),0) -> 0 | BB19: =+IFERROR(VLOOKUP($BB$15,Sheet1!AH7:AK7,3,0),0) -> 0 | BC19: =+IFERROR(VLOOKUP($BC$15,Sheet1!AL7:AO7,3,0),0) -> 0 | BD19: =+IFERROR(VLOOKUP($BD$15,Sheet1!AL7:AO7,3,0),0) -> 0 | BE19: =+IFERROR(VLOOKUP($BE$15,Sheet1!AL7:AO7,3,0),0) -> 0 | BF19: =+IFERROR(VLOOKUP($BF$15,Sheet1!AL7:AO7,3,0),0) -> 89 | BG19: =+IFERROR(VLOOKUP($BG$15,Sheet1!AL7:AO7,3,0),0) -> 0 | BH19: =+IFERROR(VLOOKUP($BH$15,Sheet1!AL7:AO7,3,0),0) -> 0 | BI19: =+IFERROR(VLOOKUP($BI$15,Sheet1!AL7:AO7,3,0),0) -> 0 | BJ19: =+IFERROR(VLOOKUP($BJ$15,Sheet1!AL7:AO7,3,0),0) -> 0 | BK19: =+IFERROR(VLOOKUP($BK$15,Sheet1!AL7:AO7,3,0),0) -> 0 | BL19: =+IFERROR(VLOOKUP($BL$15,Sheet1!AL7:AO7,3,0),0) -> 0 | BM19: =+IFERROR(VLOOKUP($BM$15,Sheet1!AP7:AS7,3,0),0) -> 0 | BN19: =+IFERROR(VLOOKUP($BN$15,Sheet1!AT7:AW7,3,0),0) -> 0 | BO19: =+IFERROR(VLOOKUP($BO$15,Sheet1!AX7:BA7,3,0),0) -> 0 | BP19: =+IFERROR(VLOOKUP($BP$15,Sheet1!BB7:BE7,3,0),0) -> 0 | BQ19: =+IFERROR(VLOOKUP($BQ$15,Sheet1!BF7:BI7,3,0),0) -> 0 | BR19: =+IFERROR(VLOOKUP($BR$15,Sheet1!BJ7:BM7,3,0),0) -> 0 | BS19: =+IFERROR(VLOOKUP($BS$15,Sheet1!BN7:BQ7,3,0),0) -> 0 | BT19: =+IFERROR(VLOOKUP($BT$15,Sheet1!BR7:BU7,3,0),0) -> 0 | BU19: =+IFERROR(VLOOKUP($BU$15,Sheet1!BV7:BY7,3,0),0) -> 0 | BV19: =Sheet1!E7 -> Hybrid | BW19: =Sheet1!CV7 -> MD0100004 | BX19: =Sheet1!CW7 -> DRUM - 28 X 10 X 23 X 2 | BY19: =VLOOKUP(C19,Sheet1!$C$1:$CX$17,100,0) -> 1000 | BZ19: 2960 | CA19: =SUMPRODUCT($N$16:$BU$16,N19:BU19)+BZ19 -> 29360 | CB19: =Sheet1!CB7 -> 0 | CC19: =CA19*CB19 -> 0 | CD19: 0.5 | CE19: =CA19*CD19 -> 14680 | CF19: =Sheet1!CF7 -> 0 | CG19: =CA19*CF19 -> 0 | CH19: =CA19+CC19+CE19+CG19 -> 44040 | CI19: 0.03 | CJ19: =CH19*CI19 -> 1321.2 | CK19: 0.02 | CL19: =CH19*CK19 -> 880.8
A20: =Sheet1!A5 -> ENQ-11285-22-23 | B20: =Sheet1!B5 -> 45170 | C20: =Sheet1!C5 -> FA0600013 | D20: =Sheet1!D5 -> 1 CORE X 95 SQ. MM. AL/UNARD(XLPE ) | E20: =CH20+CJ20+CL20 -> 128866.8 | F20: =ROUNDUP(M39,0) -> 4595 | G20: =E20+F20 -> 133461.8 | H20: 0.18 | I20: =G20*H20 -> 24023.124 | J20: =G20+I20 -> 157484.92 | K20: =Sheet1!CS5 -> 18.5 | L20: =Sheet1!CT5 -> KMS | M20: =J20*K20 -> 2913471.1 | N20: 256 | O20: =+IFERROR(VLOOKUP($O$15,Sheet1!J5:L5,3,0),0) -> 0 | P20: =+IFERROR(VLOOKUP($P$15,Sheet1!J5:M5,3,0),0) -> 0 | Q20: =+IFERROR(VLOOKUP($Q$15,Sheet1!J5:M5,3,0),0) -> 0 | R20: =+IFERROR(VLOOKUP($R$15,Sheet1!J5:M5,3,0),0) -> 0 | S20: =+IFERROR(VLOOKUP($S$15,Sheet1!N5:Q5,3,0),0) -> 0 | T20: =+IFERROR(VLOOKUP($T$15,Sheet1!N5:Q5,3,0),0) -> 0 | U20: =+IFERROR(VLOOKUP($U$15,Sheet1!F5:I5,3,0),0) -> 0 | V20: =+IFERROR(VLOOKUP($V$15,Sheet1!F5:I5,3,0),0) -> 0 | W20: =+IFERROR(VLOOKUP($W$15,Sheet1!F5:I5,3,0),0) -> 0 | X20: =+IFERROR(VLOOKUP($X$15,Sheet1!F5:I5,3,0),0) -> 0 | Y20: =+IFERROR(VLOOKUP($Y$15,Sheet1!F5:I5,3,0),0) -> 0 | Z20: =+IFERROR(VLOOKUP($Z$15,Sheet1!F5:I5,3,0),0) -> 0 | AA20: =+IFERROR(VLOOKUP($AA$15,Sheet1!F5:I5,3,0),0) -> 0 | AB20: =+IFERROR(VLOOKUP($AB$15,Sheet1!F5:I5,3,0),0) -> 0 | AC20: =+IFERROR(VLOOKUP($AC$15,Sheet1!R5:U5,3,0),0) -> 0 | AD20: =+IFERROR(VLOOKUP($AD$15,Sheet1!R5:U5,2,0),0) -> 0 | AE20: =+IFERROR(VLOOKUP($AE$15,Sheet1!V5:Y5,3,0),0) -> 0 | AF20: =+IFERROR(VLOOKUP($AF$15,Sheet1!V5:Y5,3,0),0) -> 53 | AG20: =+IFERROR(VLOOKUP($AG$15,Sheet1!V5:Y5,3,0),0) -> 0 | AH20: =+IFERROR(VLOOKUP($AH$15,Sheet1!V5:Y5,3,0),0) -> 0 | AI20: =+IFERROR(VLOOKUP($AI$15,Sheet1!V5:Y5,3,0),0) -> 0 | AJ20: =+IFERROR(VLOOKUP($AJ$15,Sheet1!V5:Y5,3,0),0) -> 0 | AK20: =+IFERROR(VLOOKUP($AK$15,Sheet1!Z5:AB5,3,0),0) -> 0 | AL20: =+IFERROR(VLOOKUP($AL$15,Sheet1!AD5:AG5,3,0),0) -> 0 | AM20: =+IFERROR(VLOOKUP($AM$15,Sheet1!AD5:AG5,3,0),0) -> 0 | AN20: =+IFERROR(VLOOKUP($AN$15,Sheet1!AD5:AG5,3,0),0) -> 0 | AO20: =+IFERROR(VLOOKUP($AO$15,Sheet1!AD5:AG5,3,0),0) -> 0 | AP20: =+IFERROR(VLOOKUP($AP$15,Sheet1!AD5:AG5,3,0),0) -> 0 | AQ20: =+IFERROR(VLOOKUP($AQ$15,Sheet1!AD5:AG5,3,0),0) -> 0 | AR20: =+IFERROR(VLOOKUP($AR$15,Sheet1!AD5:AG5,3,0),0) -> 0 | AS20: =+IFERROR(VLOOKUP($AS$15,Sheet1!AH5:AK5,3,0),0) -> 0 | AT20: =+IFERROR(VLOOKUP($AT$15,Sheet1!AH5:AK5,3,0),0) -> 0 | AU20: =+IFERROR(VLOOKUP($AU$15,Sheet1!AH5:AK5,3,0),0) -> 0 | AV20: =+IFERROR(VLOOKUP($AV$15,Sheet1!AH5:AK5,3,0),0) -> 0 | AW20: =+IFERROR(VLOOKUP($AW$15,Sheet1!AH5:AK5,3,0),0) -> 0 | AX20: =+IFERROR(VLOOKUP($AX$15,Sheet1!AH5:AK5,3,0),0) -> 0 | AY20: =+IFERROR(VLOOKUP($AY$15,Sheet1!AH5:AK5,3,0),0) -> 0 | AZ20: =+IFERROR(VLOOKUP($AZ$15,Sheet1!AH5:AK5,3,0),0) -> 0 | BA20: =+IFERROR(VLOOKUP($BA$15,Sheet1!AH5:AK5,3,0),0) -> 0 | BB20: =+IFERROR(VLOOKUP($BB$15,Sheet1!AH5:AK5,3,0),0) -> 0 | BC20: =+IFERROR(VLOOKUP($BC$15,Sheet1!AL5:AO5,3,0),0) -> 0 | BD20: =+IFERROR(VLOOKUP($BD$15,Sheet1!AL5:AO5,3,0),0) -> 0 | BE20: =+IFERROR(VLOOKUP($BE$15,Sheet1!AL5:AO5,3,0),0) -> 0 | BF20: =+IFERROR(VLOOKUP($BF$15,Sheet1!AL5:AO5,3,0),0) -> 139 | BG20: =+IFERROR(VLOOKUP($BG$15,Sheet1!AL5:AO5,3,0),0) -> 0 | BH20: =+IFERROR(VLOOKUP($BH$15,Sheet1!AL5:AO5,3,0),0) -> 0 | BI20: =+IFERROR(VLOOKUP($BI$15,Sheet1!AL5:AO5,3,0),0) -> 0 | BJ20: =+IFERROR(VLOOKUP($BJ$15,Sheet1!AL5:AO5,3,0),0) -> 0 | BK20: =+IFERROR(VLOOKUP($BK$15,Sheet1!AL5:AO5,3,0),0) -> 0 | BL20: =+IFERROR(VLOOKUP($BL$15,Sheet1!AL5:AO5,3,0),0) -> 0 | BM20: =+IFERROR(VLOOKUP($BM$15,Sheet1!AP5:AS5,3,0),0) -> 0 | BN20: =+IFERROR(VLOOKUP($BN$15,Sheet1!AT5:AW5,3,0),0) -> 0 | BO20: =+IFERROR(VLOOKUP($BO$15,Sheet1!AX5:BA5,3,0),0) -> 0 | BP20: =+IFERROR(VLOOKUP($BP$15,Sheet1!BB5:BE5,3,0),0) -> 0 | BQ20: =+IFERROR(VLOOKUP($BQ$15,Sheet1!BF5:BI5,3,0),0) -> 0 | BR20: =+IFERROR(VLOOKUP($BR$15,Sheet1!BJ5:BM5,3,0),0) -> 0 | BS20: =+IFERROR(VLOOKUP($BS$15,Sheet1!BN5:BQ5,3,0),0) -> 0 | BT20: =+IFERROR(VLOOKUP($BT$15,Sheet1!BR5:BU5,3,0),0) -> 0 | BU20: =+IFERROR(VLOOKUP($BU$15,Sheet1!BV5:BY5,3,0),0) -> 0 | BV20: =Sheet1!E5 -> Hybrid | BW20: =Sheet1!CV5 -> MD0100106 | BX20: =Sheet1!CW5 -> DRUM - 42 X 15 X 23 X 2 (LOMBU-HYBRID) | BY20: =VLOOKUP(C20,Sheet1!$C$1:$CX$17,100,0) -> 1000 | BZ20: =Sheet1!BZ5 -> 7244.19 | CA20: =SUMPRODUCT($N$16:$BU$16,N20:BU20)+BZ20 -> 81820.19 | CB20: =Sheet1!CB5 -> 0 | CC20: =CA20*CB20 -> 0 | CD20: 0.5 | CE20: =CA20*CD20 -> 40910.095 | CF20: =Sheet1!CF5 -> 0 | CG20: =CA20*CF20 -> 0 | CH20: =CA20+CC20+CE20+CG20 -> 122730.29 | CI20: 0.03 | CJ20: =CH20*CI20 -> 3681.9086 | CK20: 0.02 | CL20: =CH20*CK20 -> 2454.6057
A21: =Sheet1!A2 -> ENQ-11285-22-23 | B21: =Sheet1!B2 -> 45170 | C21: =Sheet1!C2 -> FA0600021 | D21: =Sheet1!D2 -> 1 CORE X 185 SQ. MM. AL/UNARD. (XLPE) | E21: =CH21+CJ21+CL21 -> 244370.89 | F21: =ROUNDUP(M40,0) -> 12687 | G21: =E21+F21 -> 257057.89 | H21: 0.18 | I21: =G21*H21 -> 46270.42 | J21: =G21+I21 -> 303328.31 | K21: =Sheet1!CS2 -> 6.7 | L21: =Sheet1!CT2 -> KMS | M21: =J21*K21 -> 2032299.7 | N21: 500 | O21: =+IFERROR(VLOOKUP($O$15,Sheet1!J2:L2,3,0),0) -> 0 | P21: =+IFERROR(VLOOKUP($P$15,Sheet1!J2:M2,3,0),0) -> 0 | Q21: =+IFERROR(VLOOKUP($Q$15,Sheet1!J2:M2,3,0),0) -> 0 | R21: =+IFERROR(VLOOKUP($R$15,Sheet1!J2:M2,3,0),0) -> 0 | S21: =+IFERROR(VLOOKUP($S$15,Sheet1!N2:Q2,3,0),0) -> 0 | T21: =+IFERROR(VLOOKUP($T$15,Sheet1!N2:Q2,3,0),0) -> 0 | U21: =+IFERROR(VLOOKUP($U$15,Sheet1!F2:I2,3,0),0) -> 0 | V21: =+IFERROR(VLOOKUP($V$15,Sheet1!F2:I2,3,0),0) -> 0 | W21: =+IFERROR(VLOOKUP($W$15,Sheet1!F2:I2,3,0),0) -> 0 | X21: =+IFERROR(VLOOKUP($X$15,Sheet1!F2:I2,3,0),0) -> 0 | Y21: =+IFERROR(VLOOKUP($Y$15,Sheet1!F2:I2,3,0),0) -> 0 | Z21: =+IFERROR(VLOOKUP($Z$15,Sheet1!F2:I2,3,0),0) -> 0 | AA21: =+IFERROR(VLOOKUP($AA$15,Sheet1!F2:I2,3,0),0) -> 0 | AB21: =+IFERROR(VLOOKUP($AB$15,Sheet1!F2:I2,3,0),0) -> 0 | AC21: =+IFERROR(VLOOKUP($AC$15,Sheet1!R2:U2,3,0),0) -> 0 | AD21: =+IFERROR(VLOOKUP($AD$15,Sheet1!R2:U2,2,0),0) -> 0 | AE21: =+IFERROR(VLOOKUP($AE$15,Sheet1!V2:Y2,3,0),0) -> 0 | AF21: =+IFERROR(VLOOKUP($AF$15,Sheet1!V2:Y2,3,0),0) -> 90 | AG21: =+IFERROR(VLOOKUP($AG$15,Sheet1!V2:Y2,3,0),0) -> 0 | AH21: =+IFERROR(VLOOKUP($AH$15,Sheet1!V2:Y2,3,0),0) -> 0 | AI21: =+IFERROR(VLOOKUP($AI$15,Sheet1!V2:Y2,3,0),0) -> 0 | AJ21: =+IFERROR(VLOOKUP($AJ$15,Sheet1!V2:Y2,3,0),0) -> 0 | AK21: =+IFERROR(VLOOKUP($AK$15,Sheet1!Z2:AB2,3,0),0) -> 0 | AL21: =+IFERROR(VLOOKUP($AL$15,Sheet1!AD2:AG2,3,0),0) -> 0 | AM21: =+IFERROR(VLOOKUP($AM$15,Sheet1!AD2:AG2,3,0),0) -> 0 | AN21: =+IFERROR(VLOOKUP($AN$15,Sheet1!AD2:AG2,3,0),0) -> 0 | AO21: =+IFERROR(VLOOKUP($AO$15,Sheet1!AD2:AG2,3,0),0) -> 0 | AP21: =+IFERROR(VLOOKUP($AP$15,Sheet1!AD2:AG2,3,0),0) -> 0 | AQ21: =+IFERROR(VLOOKUP($AQ$15,Sheet1!AD2:AG2,3,0),0) -> 0 | AR21: =+IFERROR(VLOOKUP($AR$15,Sheet1!AD2:AG2,3,0),0) -> 0 | AS21: =+IFERROR(VLOOKUP($AS$15,Sheet1!AH2:AK2,3,0),0) -> 0 | AT21: =+IFERROR(VLOOKUP($AT$15,Sheet1!AH2:AK2,3,0),0) -> 0 | AU21: =+IFERROR(VLOOKUP($AU$15,Sheet1!AH2:AK2,3,0),0) -> 0 | AV21: =+IFERROR(VLOOKUP($AV$15,Sheet1!AH2:AK2,3,0),0) -> 0 | AW21: =+IFERROR(VLOOKUP($AW$15,Sheet1!AH2:AK2,3,0),0) -> 0 | AX21: =+IFERROR(VLOOKUP($AX$15,Sheet1!AH2:AK2,3,0),0) -> 0 | AY21: =+IFERROR(VLOOKUP($AY$15,Sheet1!AH2:AK2,3,0),0) -> 0 | AZ21: =+IFERROR(VLOOKUP($AZ$15,Sheet1!AH2:AK2,3,0),0) -> 0 | BA21: =+IFERROR(VLOOKUP($BA$15,Sheet1!AH2:AK2,3,0),0) -> 0 | BB21: =+IFERROR(VLOOKUP($BB$15,Sheet1!AH2:AK2,3,0),0) -> 0 | BC21: =+IFERROR(VLOOKUP($BC$15,Sheet1!AL2:AO2,3,0),0) -> 0 | BD21: =+IFERROR(VLOOKUP($BD$15,Sheet1!AL2:AO2,3,0),0) -> 0 | BE21: =+IFERROR(VLOOKUP($BE$15,Sheet1!AL2:AO2,3,0),0) -> 0 | BF21: 210 | BG21: =+IFERROR(VLOOKUP($BG$15,Sheet1!AL2:AO2,3,0),0) -> 0 | BH21: =+IFERROR(VLOOKUP($BH$15,Sheet1!AL2:AO2,3,0),0) -> 0 | BI21: =+IFERROR(VLOOKUP($BI$15,Sheet1!AL2:AO2,3,0),0) -> 0 | BJ21: =+IFERROR(VLOOKUP($BJ$15,Sheet1!AL2:AO2,3,0),0) -> 0 | BK21: =+IFERROR(VLOOKUP($BK$15,Sheet1!AL2:AO2,3,0),0) -> 0 | BL21: =+IFERROR(VLOOKUP($BL$15,Sheet1!AL2:AO2,3,0),0) -> 0 | BM21: =+IFERROR(VLOOKUP($BM$15,Sheet1!AP2:AS2,3,0),0) -> 0 | BN21: =+IFERROR(VLOOKUP($BN$15,Sheet1!AT2:AW2,3,0),0) -> 0 | BO21: 22 | BP21: =+IFERROR(VLOOKUP($BP$15,Sheet1!BB2:BE2,3,0),0) -> 0 | BQ21: =+IFERROR(VLOOKUP($BQ$15,Sheet1!BF2:BI2,3,0),0) -> 0 | BR21: =+IFERROR(VLOOKUP($BR$15,Sheet1!BJ2:BM2,3,0),0) -> 0 | BS21: =+IFERROR(VLOOKUP($BS$15,Sheet1!BN2:BQ2,3,0),0) -> 0 | BU21: =+IFERROR(VLOOKUP($BU$15,Sheet1!BV2:BY2,3,0),0) -> 0 | BV21: =Sheet1!E2 -> Hybrid | BW21: =Sheet1!CV2 -> MD0100107 | BX21: =Sheet1!CW2 -> DRUM - 42 X 15 X 38 X 2 (LOMBU-HYBRID) | BY21: =VLOOKUP(C21,Sheet1!$C$1:$CX$17,100,0) -> 1000 | BZ21: =Sheet1!BZ2 -> 7976.12 | CA21: =SUMPRODUCT($N$16:$BU$16,N21:BU21)+BZ21 -> 155156.12 | CB21: =Sheet1!CB2 -> 0 | CC21: =CA21*CB21 -> 0 | CD21: 0.5 | CE21: =CA21*CD21 -> 77578.06 | CF21: =Sheet1!CF2 -> 0 | CG21: =CA21*CF21 -> 0 | CH21: =CA21+CC21+CE21+CG21 -> 232734.18 | CI21: 0.03 | CJ21: =CH21*CI21 -> 6982.0254 | CK21: 0.02 | CL21: =CH21*CK21 -> 4654.6836
A22: =Sheet1!A6 -> ENQ-11285-22-23 | B22: =Sheet1!B6 -> 45170 | C22: =Sheet1!C6 -> FA0600020 | D22: =Sheet1!D6 -> 1 CORE X 300 SQ. MM. AL/UNARD. (XLPE) | E22: =CH22+CJ22+CL22 -> 387453.15 | F22: =ROUNDUP(M41,0) -> 12319 | G22: =E22+F22 -> 399772.15 | H22: 0.18 | I22: =G22*H22 -> 71958.987 | J22: =G22+I22 -> 471731.14 | K22: =Sheet1!CS6 -> 20.7 | L22: =Sheet1!CT6 -> KMS | M22: =J22*K22 -> 9764834.5 | N22: =+IFERROR(VLOOKUP($N$15,Sheet1!J6:L6,3,0),0) -> 810 | O22: =+IFERROR(VLOOKUP($O$15,Sheet1!J6:L6,3,0),0) -> 0 | P22: =+IFERROR(VLOOKUP($P$15,Sheet1!J6:M6,3,0),0) -> 0 | Q22: =+IFERROR(VLOOKUP($Q$15,Sheet1!J6:M6,3,0),0) -> 0 | R22: =+IFERROR(VLOOKUP($R$15,Sheet1!J6:M6,3,0),0) -> 0 | S22: =+IFERROR(VLOOKUP($S$15,Sheet1!N6:Q6,3,0),0) -> 0 | T22: =+IFERROR(VLOOKUP($T$15,Sheet1!N6:Q6,3,0),0) -> 0 | U22: =+IFERROR(VLOOKUP($U$15,Sheet1!F6:I6,3,0),0) -> 0 | V22: =+IFERROR(VLOOKUP($V$15,Sheet1!F6:I6,3,0),0) -> 0 | W22: =+IFERROR(VLOOKUP($W$15,Sheet1!F6:I6,3,0),0) -> 0 | X22: =+IFERROR(VLOOKUP($X$15,Sheet1!F6:I6,3,0),0) -> 0 | Y22: =+IFERROR(VLOOKUP($Y$15,Sheet1!F6:I6,3,0),0) -> 0 | Z22: =+IFERROR(VLOOKUP($Z$15,Sheet1!F6:I6,3,0),0) -> 0 | AA22: =+IFERROR(VLOOKUP($AA$15,Sheet1!F6:I6,3,0),0) -> 0 | AB22: =+IFERROR(VLOOKUP($AB$15,Sheet1!F6:I6,3,0),0) -> 0 | AC22: =+IFERROR(VLOOKUP($AC$15,Sheet1!R6:U6,3,0),0) -> 0 | AD22: =+IFERROR(VLOOKUP($AD$15,Sheet1!R6:U6,2,0),0) -> 0 | AE22: =+IFERROR(VLOOKUP($AE$15,Sheet1!V6:Y6,3,0),0) -> 0 | AF22: =+IFERROR(VLOOKUP($AF$15,Sheet1!V6:Y6,3,0),0) -> 132 | AG22: =+IFERROR(VLOOKUP($AG$15,Sheet1!V6:Y6,3,0),0) -> 0 | AH22: =+IFERROR(VLOOKUP($AH$15,Sheet1!V6:Y6,3,0),0) -> 0 | AI22: =+IFERROR(VLOOKUP($AI$15,Sheet1!V6:Y6,3,0),0) -> 0 | AJ22: =+IFERROR(VLOOKUP($AJ$15,Sheet1!V6:Y6,3,0),0) -> 0 | AK22: =+IFERROR(VLOOKUP($AK$15,Sheet1!Z6:AB6,3,0),0) -> 0 | AL22: =+IFERROR(VLOOKUP($AL$15,Sheet1!AD6:AG6,3,0),0) -> 0 | AM22: =+IFERROR(VLOOKUP($AM$15,Sheet1!AD6:AG6,3,0),0) -> 0 | AN22: =+IFERROR(VLOOKUP($AN$15,Sheet1!AD6:AG6,3,0),0) -> 0 | AO22: =+IFERROR(VLOOKUP($AO$15,Sheet1!AD6:AG6,3,0),0) -> 0 | AP22: =+IFERROR(VLOOKUP($AP$15,Sheet1!AD6:AG6,3,0),0) -> 0 | AQ22: =+IFERROR(VLOOKUP($AQ$15,Sheet1!AD6:AG6,3,0),0) -> 0 | AR22: =+IFERROR(VLOOKUP($AR$15,Sheet1!AD6:AG6,3,0),0) -> 0 | AS22: =+IFERROR(VLOOKUP($AS$15,Sheet1!AH6:AK6,3,0),0) -> 0 | AT22: =+IFERROR(VLOOKUP($AT$15,Sheet1!AH6:AK6,3,0),0) -> 0 | AU22: =+IFERROR(VLOOKUP($AU$15,Sheet1!AH6:AK6,3,0),0) -> 0 | AV22: =+IFERROR(VLOOKUP($AV$15,Sheet1!AH6:AK6,3,0),0) -> 0 | AW22: =+IFERROR(VLOOKUP($AW$15,Sheet1!AH6:AK6,3,0),0) -> 0 | AX22: =+IFERROR(VLOOKUP($AX$15,Sheet1!AH6:AK6,3,0),0) -> 0 | AY22: =+IFERROR(VLOOKUP($AY$15,Sheet1!AH6:AK6,3,0),0) -> 0 | AZ22: =+IFERROR(VLOOKUP($AZ$15,Sheet1!AH6:AK6,3,0),0) -> 0 | BA22: =+IFERROR(VLOOKUP($BA$15,Sheet1!AH6:AK6,3,0),0) -> 0 | BB22: =+IFERROR(VLOOKUP($BB$15,Sheet1!AH6:AK6,3,0),0) -> 0 | BC22: =+IFERROR(VLOOKUP($BC$15,Sheet1!AL6:AO6,3,0),0) -> 0 | BD22: =+IFERROR(VLOOKUP($BD$15,Sheet1!AL6:AO6,3,0),0) -> 0 | BE22: =+IFERROR(VLOOKUP($BE$15,Sheet1!AL6:AO6,3,0),0) -> 0 | BF22: 255 | BG22: =+IFERROR(VLOOKUP($BG$15,Sheet1!AL6:AO6,3,0),0) -> 0 | BH22: =+IFERROR(VLOOKUP($BH$15,Sheet1!AL6:AO6,3,0),0) -> 0 | BI22: =+IFERROR(VLOOKUP($BI$15,Sheet1!AL6:AO6,3,0),0) -> 0 | BJ22: =+IFERROR(VLOOKUP($BJ$15,Sheet1!AL6:AO6,3,0),0) -> 0 | BK22: =+IFERROR(VLOOKUP($BK$15,Sheet1!AL6:AO6,3,0),0) -> 0 | BL22: =+IFERROR(VLOOKUP($BL$15,Sheet1!AL6:AO6,3,0),0) -> 0 | BM22: =+IFERROR(VLOOKUP($BM$15,Sheet1!AP6:AS6,3,0),0) -> 0 | BN22: =+IFERROR(VLOOKUP($BN$15,Sheet1!AT6:AW6,3,0),0) -> 0 | BO22: 28 | BP22: =+IFERROR(VLOOKUP($BP$15,Sheet1!BB6:BE6,3,0),0) -> 0 | BQ22: =+IFERROR(VLOOKUP($BQ$15,Sheet1!BF6:BI6,3,0),0) -> 0 | BR22: =+IFERROR(VLOOKUP($BR$15,Sheet1!BJ6:BM6,3,0),0) -> 0 | BS22: =+IFERROR(VLOOKUP($BS$15,Sheet1!BN6:BQ6,3,0),0) -> 0 | BT22: =+IFERROR(VLOOKUP($BT$15,Sheet1!BR6:BU6,3,0),0) -> 0 | BU22: =+IFERROR(VLOOKUP($BU$15,Sheet1!BV6:BY6,3,0),0) -> 0 | BV22: =Sheet1!E6 -> STEEL | BW22: SP0400125 | BX22: CORRUGATED DISPATCH STEEL DRUM 1600 X 700 X 915 MM | BY22: =VLOOKUP(C22,Sheet1!$C$1:$CX$17,100,0) -> 1000 | BZ22: 20900 | CA22: =SUMPRODUCT($N$16:$BU$16,N22:BU22)+BZ22 -> 246002 | CB22: =Sheet1!CB6 -> 0 | CC22: =CA22*CB22 -> 0 | CD22: 0.5 | CE22: =CA22*CD22 -> 123001 | CF22: =Sheet1!CF6 -> 0 | CG22: =CA22*CF22 -> 0 | CH22: =CA22+CC22+CE22+CG22 -> 369003 | CI22: 0.03 | CJ22: =CH22*CI22 -> 11070.09 | CK22: 0.02 | CL22: =CH22*CK22 -> 7380.06
A23: =Sheet1!A4 -> ENQ-11285-22-23 | B23: =Sheet1!B4 -> 45170 | C23: =Sheet1!C4 -> FA0600032 | D23: =Sheet1!D4 -> 1 CORE X 630 SQ. MM. ALU/UNARD (XLPE) | E23: =CH23+CJ23+CL23 -> 747471.38 | F23: =ROUNDUP(M42,0) -> 28334 | G23: =E23+F23 -> 775805.38 | H23: 0.18 | I23: =G23*H23 -> 139644.97 | J23: =G23+I23 -> 915450.34 | K23: =Sheet1!CS4 -> 18 | L23: =Sheet1!CT4 -> KMS | M23: =J23*K23 -> 16478106 | N23: =+IFERROR(VLOOKUP($N$15,Sheet1!J4:L4,3,0),0) -> 1701 | O23: =+IFERROR(VLOOKUP($O$15,Sheet1!J4:L4,3,0),0) -> 0 | P23: =+IFERROR(VLOOKUP($P$15,Sheet1!J4:M4,3,0),0) -> 0 | Q23: =+IFERROR(VLOOKUP($Q$15,Sheet1!J4:M4,3,0),0) -> 0 | R23: =+IFERROR(VLOOKUP($R$15,Sheet1!J4:M4,3,0),0) -> 0 | S23: =+IFERROR(VLOOKUP($S$15,Sheet1!N4:Q4,3,0),0) -> 0 | T23: =+IFERROR(VLOOKUP($T$15,Sheet1!N4:Q4,3,0),0) -> 0 | U23: =+IFERROR(VLOOKUP($U$15,Sheet1!F4:I4,3,0),0) -> 0 | V23: =+IFERROR(VLOOKUP($V$15,Sheet1!F4:I4,3,0),0) -> 0 | W23: =+IFERROR(VLOOKUP($W$15,Sheet1!F4:I4,3,0),0) -> 0 | X23: =+IFERROR(VLOOKUP($X$15,Sheet1!F4:I4,3,0),0) -> 0 | Y23: =+IFERROR(VLOOKUP($Y$15,Sheet1!F4:I4,3,0),0) -> 0 | Z23: =+IFERROR(VLOOKUP($Z$15,Sheet1!F4:I4,3,0),0) -> 0 | AA23: =+IFERROR(VLOOKUP($AA$15,Sheet1!F4:I4,3,0),0) -> 0 | AB23: =+IFERROR(VLOOKUP($AB$15,Sheet1!F4:I4,3,0),0) -> 0 | AC23: =+IFERROR(VLOOKUP($AC$15,Sheet1!R4:U4,3,0),0) -> 0 | AD23: =+IFERROR(VLOOKUP($AD$15,Sheet1!R4:U4,2,0),0) -> 0 | AE23: =+IFERROR(VLOOKUP($AE$15,Sheet1!V4:Y4,3,0),0) -> 0 | AF23: 242 | AG23: =+IFERROR(VLOOKUP($AG$15,Sheet1!V4:Y4,3,0),0) -> 0 | AH23: =+IFERROR(VLOOKUP($AH$15,Sheet1!V4:Y4,3,0),0) -> 0 | AI23: =+IFERROR(VLOOKUP($AI$15,Sheet1!V4:Y4,3,0),0) -> 0 | AJ23: =+IFERROR(VLOOKUP($AJ$15,Sheet1!V4:Y4,3,0),0) -> 0 | AK23: =+IFERROR(VLOOKUP($AK$15,Sheet1!Z4:AB4,3,0),0) -> 0 | AL23: =+IFERROR(VLOOKUP($AL$15,Sheet1!AD4:AG4,3,0),0) -> 0 | AM23: =+IFERROR(VLOOKUP($AM$15,Sheet1!AD4:AG4,3,0),0) -> 0 | AN23: =+IFERROR(VLOOKUP($AN$15,Sheet1!AD4:AG4,3,0),0) -> 0 | AO23: =+IFERROR(VLOOKUP($AO$15,Sheet1!AD4:AG4,3,0),0) -> 0 | AP23: =+IFERROR(VLOOKUP($AP$15,Sheet1!AD4:AG4,3,0),0) -> 0 | AQ23: =+IFERROR(VLOOKUP($AQ$15,Sheet1!AD4:AG4,3,0),0) -> 0 | AR23: =+IFERROR(VLOOKUP($AR$15,Sheet1!AD4:AG4,3,0),0) -> 0 | AS23: =+IFERROR(VLOOKUP($AS$15,Sheet1!AH4:AK4,3,0),0) -> 0 | AT23: =+IFERROR(VLOOKUP($AT$15,Sheet1!AH4:AK4,3,0),0) -> 0 | AU23: =+IFERROR(VLOOKUP($AU$15,Sheet1!AH4:AK4,3,0),0) -> 0 | AV23: =+IFERROR(VLOOKUP($AV$15,Sheet1!AH4:AK4,3,0),0) -> 0 | AW23: =+IFERROR(VLOOKUP($AW$15,Sheet1!AH4:AK4,3,0),0) -> 0 | AX23: =+IFERROR(VLOOKUP($AX$15,Sheet1!AH4:AK4,3,0),0) -> 0 | AY23: =+IFERROR(VLOOKUP($AY$15,Sheet1!AH4:AK4,3,0),0) -> 0 | AZ23: =+IFERROR(VLOOKUP($AZ$15,Sheet1!AH4:AK4,3,0),0) -> 0 | BA23: =+IFERROR(VLOOKUP($BA$15,Sheet1!AH4:AK4,3,0),0) -> 0 | BB23: =+IFERROR(VLOOKUP($BB$15,Sheet1!AH4:AK4,3,0),0) -> 0 | BC23: =+IFERROR(VLOOKUP($BC$15,Sheet1!AL4:AO4,3,0),0) -> 0 | BD23: =+IFERROR(VLOOKUP($BD$15,Sheet1!AL4:AO4,3,0),0) -> 0 | BE23: =+IFERROR(VLOOKUP($BE$15,Sheet1!AL4:AO4,3,0),0) -> 0 | BF23: 408 | BG23: =+IFERROR(VLOOKUP($BG$15,Sheet1!AL4:AO4,3,0),0) -> 0 | BH23: =+IFERROR(VLOOKUP($BH$15,Sheet1!AL4:AO4,3,0),0) -> 0 | BI23: =+IFERROR(VLOOKUP($BI$15,Sheet1!AL4:AO4,3,0),0) -> 0 | BJ23: =+IFERROR(VLOOKUP($BJ$15,Sheet1!AL4:AO4,3,0),0) -> 0 | BK23: =+IFERROR(VLOOKUP($BK$15,Sheet1!AL4:AO4,3,0),0) -> 0 | BL23: =+IFERROR(VLOOKUP($BL$15,Sheet1!AL4:AO4,3,0),0) -> 0 | BM23: =+IFERROR(VLOOKUP($BM$15,Sheet1!AP4:AS4,3,0),0) -> 0 | BN23: =+IFERROR(VLOOKUP($BN$15,Sheet1!AT4:AW4,3,0),0) -> 0 | BO23: 40 | BP23: =+IFERROR(VLOOKUP($BP$15,Sheet1!BB4:BE4,3,0),0) -> 0 | BQ23: =+IFERROR(VLOOKUP($BQ$15,Sheet1!BF4:BI4,3,0),0) -> 0 | BR23: =+IFERROR(VLOOKUP($BR$15,Sheet1!BJ4:BM4,3,0),0) -> 0 | BS23: =+IFERROR(VLOOKUP($BS$15,Sheet1!BN4:BQ4,3,0),0) -> 0 | BT23: =+IFERROR(VLOOKUP($BT$15,Sheet1!BR4:BU4,3,0),0) -> 0 | BU23: =+IFERROR(VLOOKUP($BU$15,Sheet1!BV4:BY4,3,0),0) -> 0 | BV23: =Sheet1!E4 -> STEEL | BW23: =Sheet1!CV4 -> SP0400126 | BX23: =Sheet1!CW4 -> CORRUGATED DISPATCH STEEL DRUM 1900 X 830 X 915 MM | BY23: =VLOOKUP(C23,Sheet1!$C$1:$CX$17,100,0) -> 1000 | BZ23: =Sheet1!BZ4 -> 26600 | CA23: =SUMPRODUCT($N$16:$BU$16,N23:BU23)+BZ23 -> 474585 | CB23: =Sheet1!CB4 -> 0 | CC23: =CA23*CB23 -> 0 | CD23: 0.5 | CE23: =CA23*CD23 -> 237292.5 | CF23: =Sheet1!CF4 -> 0 | CG23: =CA23*CF23 -> 0 | CH23: =CA23+CC23+CE23+CG23 -> 711877.5 | CI23: 0.03 | CJ23: =CH23*CI23 -> 21356.325 | CK23: 0.02 | CL23: =CH23*CK23 -> 14237.55
A24: =Sheet1!A17 -> ENQ-11285-22-23 | B24: =Sheet1!B17 -> 45170 | C24: =Sheet1!C17 -> FA0900133 | D24: =Sheet1!D17 -> 2 CORE X 16 SQ. MM. AL/ARD - WIRE (XLPE) | E24: =CH24+CJ24+CL24 -> 114603.6 | F24: =ROUNDUP(M43,0) -> 4276 | G24: =E24+F24 -> 118879.6 | H24: 0.18 | I24: =G24*H24 -> 21398.328 | J24: =G24+I24 -> 140277.93 | K24: =Sheet1!CS17 -> 1511 | L24: =Sheet1!CT17 -> KMS | M24: =J24*K24 -> 2.1195995e+08 | N24: 86 | O24: =+IFERROR(VLOOKUP($O$15,Sheet1!J17:L17,3,0),0) -> 0 | P24: =+IFERROR(VLOOKUP($P$15,Sheet1!J17:M17,3,0),0) -> 0 | Q24: =+IFERROR(VLOOKUP($Q$15,Sheet1!J17:M17,3,0),0) -> 0 | R24: =+IFERROR(VLOOKUP($R$15,Sheet1!J17:M17,3,0),0) -> 0 | S24: =+IFERROR(VLOOKUP($S$15,Sheet1!N17:Q17,3,0),0) -> 0 | T24: =+IFERROR(VLOOKUP($T$15,Sheet1!N17:Q17,3,0),0) -> 0 | U24: =+IFERROR(VLOOKUP($U$15,Sheet1!F17:I17,3,0),0) -> 0 | V24: =+IFERROR(VLOOKUP($V$15,Sheet1!F17:I17,3,0),0) -> 0 | W24: =+IFERROR(VLOOKUP($W$15,Sheet1!F17:I17,3,0),0) -> 0 | X24: =+IFERROR(VLOOKUP($X$15,Sheet1!F17:I17,3,0),0) -> 0 | Y24: =+IFERROR(VLOOKUP($Y$15,Sheet1!F17:I17,3,0),0) -> 0 | Z24: =+IFERROR(VLOOKUP($Z$15,Sheet1!F17:I17,3,0),0) -> 0 | AA24: =+IFERROR(VLOOKUP($AA$15,Sheet1!F17:I17,3,0),0) -> 0 | AB24: =+IFERROR(VLOOKUP($AB$15,Sheet1!F17:I17,3,0),0) -> 0 | AC24: =+IFERROR(VLOOKUP($AC$15,Sheet1!R17:U17,3,0),0) -> 0 | AD24: =+IFERROR(VLOOKUP($AD$15,Sheet1!R17:U17,2,0),0) -> 0 | AE24: =+IFERROR(VLOOKUP($AE$15,Sheet1!V17:Y17,3,0),0) -> 0 | AF24: =+IFERROR(VLOOKUP($AF$15,Sheet1!V17:Y17,3,0),0) -> 37 | AG24: =+IFERROR(VLOOKUP($AG$15,Sheet1!V17:Y17,3,0),0) -> 0 | AH24: =+IFERROR(VLOOKUP($AH$15,Sheet1!V17:Y17,3,0),0) -> 0 | AI24: =+IFERROR(VLOOKUP($AI$15,Sheet1!V17:Y17,3,0),0) -> 0 | AJ24: =+IFERROR(VLOOKUP($AJ$15,Sheet1!V17:Y17,3,0),0) -> 0 | AK24: =+IFERROR(VLOOKUP($AK$15,Sheet1!Z17:AB17,3,0),0) -> 0 | AL24: =+IFERROR(VLOOKUP($AL$15,Sheet1!AD17:AG17,3,0),0) -> 0 | AM24: =+IFERROR(VLOOKUP($AM$15,Sheet1!AD17:AG17,3,0),0) -> 0 | AN24: =+IFERROR(VLOOKUP($AN$15,Sheet1!AD17:AG17,3,0),0) -> 0 | AO24: =+IFERROR(VLOOKUP($AO$15,Sheet1!AD17:AG17,3,0),0) -> 0 | AP24: =+IFERROR(VLOOKUP($AP$15,Sheet1!AD17:AG17,3,0),0) -> 0 | AQ24: =+IFERROR(VLOOKUP($AQ$15,Sheet1!AD17:AG17,3,0),0) -> 0 | AR24: 45 | AS24: =+IFERROR(VLOOKUP($AS$15,Sheet1!AH17:AK17,3,0),0) -> 0 | AT24: =+IFERROR(VLOOKUP($AT$15,Sheet1!AH17:AK17,3,0),0) -> 0 | AU24: =+IFERROR(VLOOKUP($AU$15,Sheet1!AH17:AK17,3,0),0) -> 0 | AV24: =+IFERROR(VLOOKUP($AV$15,Sheet1!AH17:AK17,3,0),0) -> 0 | AW24: =+IFERROR(VLOOKUP($AW$15,Sheet1!AH17:AK17,3,0),0) -> 0 | AX24: =+IFERROR(VLOOKUP($AX$15,Sheet1!AH17:AK17,3,0),0) -> 0 | AY24: =+IFERROR(VLOOKUP($AY$15,Sheet1!AH17:AK17,3,0),0) -> 0 | AZ24: =+IFERROR(VLOOKUP($AZ$15,Sheet1!AH17:AK17,3,0),0) -> 0 | BA24: 250 | BB24: =+IFERROR(VLOOKUP($BB$15,Sheet1!AH17:AK17,3,0),0) -> 0 | BC24: =+IFERROR(VLOOKUP($BC$15,Sheet1!AL17:AO17,3,0),0) -> 0 | BD24: =+IFERROR(VLOOKUP($BD$15,Sheet1!AL17:AO17,3,0),0) -> 0 | BE24: =+IFERROR(VLOOKUP($BE$15,Sheet1!AL17:AO17,3,0),0) -> 0 | BF24: 120 | BG24: =+IFERROR(VLOOKUP($BG$15,Sheet1!AL17:AO17,3,0),0) -> 0 | BH24: =+IFERROR(VLOOKUP($BH$15,Sheet1!AL17:AO17,3,0),0) -> 0 | BI24: =+IFERROR(VLOOKUP($BI$15,Sheet1!AL17:AO17,3,0),0) -> 0 | BJ24: =+IFERROR(VLOOKUP($BJ$15,Sheet1!AL17:AO17,3,0),0) -> 0 | BK24: =+IFERROR(VLOOKUP($BK$15,Sheet1!AL17:AO17,3,0),0) -> 0 | BL24: =+IFERROR(VLOOKUP($BL$15,Sheet1!AL17:AO17,3,0),0) -> 0 | BM24: =+IFERROR(VLOOKUP($BM$15,Sheet1!AP17:AS17,3,0),0) -> 0 | BN24: =+IFERROR(VLOOKUP($BN$15,Sheet1!AT17:AW17,3,0),0) -> 0 | BO24: =+IFERROR(VLOOKUP($BO$15,Sheet1!AX17:BA17,3,0),0) -> 0 | BP24: =+IFERROR(VLOOKUP($BP$15,Sheet1!BB17:BE17,3,0),0) -> 0 | BQ24: =+IFERROR(VLOOKUP($BQ$15,Sheet1!BF17:BI17,3,0),0) -> 0 | BR24: =+IFERROR(VLOOKUP($BR$15,Sheet1!BJ17:BM17,3,0),0) -> 0 | BS24: =+IFERROR(VLOOKUP($BS$15,Sheet1!BN17:BQ17,3,0),0) -> 0 | BT24: 11 | BU24: =+IFERROR(VLOOKUP($BU$15,Sheet1!BV17:BY17,3,0),0) -> 0 | BV24: =Sheet1!E17 -> Hybrid | BW24: =Sheet1!CV17 -> MD0100106 | BX24: =Sheet1!CW17 -> DRUM - 42 X 15 X 23 X 2 (LOMBU-HYBRID) | BY24: =VLOOKUP(C24,Sheet1!$C$1:$CX$17,100,0) -> 1000 | BZ24: =Sheet1!BZ17 -> 7244.19 | CA24: =SUMPRODUCT($N$16:$BU$16,N24:BU24)+BZ24 -> 72764.19 | CB24: =Sheet1!CB17 -> 0 | CC24: =CA24*CB24 -> 0 | CD24: 0.5 | CE24: =CA24*CD24 -> 36382.095 | CF24: =Sheet1!CF17 -> 0 | CG24: =CA24*CF24 -> 0 | CH24: =CA24+CC24+CE24+CG24 -> 109146.29 | CI24: 0.03 | CJ24: =CH24*CI24 -> 3274.3886 | CK24: 0.02 | CL24: =CH24*CK24 -> 2182.9257
