Workbook

Sheet Sheet1
A1: DOCKET NO. | B1: Base Date | C1: ITEM CODE | D1: PROPOSE ERP ITEM NAME | E1: Propose Drum Type | F1: Insulation Screening(Metallic) | G1: RM Rate(Insulation Screening(Metallic)) | H1: Weight (Insulation Screening (Metallic)) | I1: Cost Insulation Screening(Metallic) | J1: Conductor | K1: RM Rate(Conductor) | L1: Weight(Conductor) | M1: Cost(Conductor) | N1: AL ALLOY | O1: RM Rate(AL Alloy) | P1: Weight(Al Alloy) | Q1: Cost(AL Alloy) | R1: Insulation Screening(Non-Metallic) | S1: RM Rate(Insulation Screening(Non-Metallic)) | T1: Weight(Insulation Screening(Non-Metallic) | U1: Cost(Insulation Screening(Non-Metallic) | V1: Insulation | W1: RM Rate(Insulation) | X1: Weight(Insulation) | Y1: Cost(Insulation) | Z1: Poly Tape | AA1: RM Rate(Poly Tape) | AB1: Weight(Poly Tape) | AC1: Cost(Poly Tape) | AD1: Inner Sheath | AE1: RM Rate(Inner Sheath) | AF1: Weight(Inner Sheath) | AG1: Cost(Inner Sheath) | AH1: Armouring | AI1: RM Rate(Armouring) | AJ1: Weight(Armouring) | AK1: Cost(Armouring) | AL1: Outer Sheath | AM1: RM Rate(Outer Sheath) | AN1: Weight(Outer Sheath) | AO1: Cost(Outer Sheath) | AP1: Filler | AQ1: RM Rate(Filler) | AR1: Weight(Filler) | AS1: Cost(Filler) | AT1: Grease | AU1: RM Rate(Grease) | AV1: Weight(Grease) | AW1: Cost(Grease) | AX1: Water Swellable Tape | AY1: RM Rate(Water Swellable Tape) | AZ1: Weight(Water Swellable Tape) | BA1: Cost(Water Swellable Tape) | BB1: Semi Conducting Water Swellable Tape | BC1: RM Rate(Semi Conducting Water Swellable Tape) | BD1: Weight(Semi Conducting Water Swellable Tape) | BE1: Cost(Semi Conducting Water Swellable Tape) | BF1: Semicon Tape | BG1: RM Rate(Semicon Tape) | BH1: Weight(Semicon Tape) | BI1: Cost(Semicon Tape) | BJ1: Glass Fiber Tape | BK1: RM Rate(Glass Fiber Tape) | BL1: Weight(Glass Fiber Tape) | BM1: Cost(Glass Fiber Tape) | BN1: Copper Wire 0.8MM | BO1: RM Rate(Copper Wire 0.8MM) | BP1: Weight(Copper Wire 0.8MM) | BQ1: Cost(Copper Wire 0.8MM) | BR1: Rubberized Cotton Tape | BS1: RM Rate(Rubberized Cotton Tape) | BT1: Weight(Rubberized Cotton Tape) | BU1: Cost(Rubberized Cotton Tape) | BV1: Water Tight Compound | BW1: RM Rate(Water Tight Compound) | BX1: Weight(Water Tight Compound) | BY1: Cost(Water Tight Compound) | BZ1: Drum Cost Per KM | CA1: Total RM Cost | CB1: FIRM % | CC1: Firm Value | CD1: MFG% | CE1: MFG Value | CF1: PROF% | CG1: Profit Value | CH1: 1st EX-Works | CI1: Intt % | CJ1: Intt Value | CK1: insp% | CL1: Insp Value | CM1: TTR CHARGES% | CN1: TTR Value | CO1: EX-Works Per KM | CP1: Freight Per KM | CQ1: Price Including Freight Per KM | CR1: GST % | CS1: GST Value | CT1: Price Including GST & Freight Per KM | CU1: QTY | CV1: Unit | CW1: Total Price Of Full QTY(Including Freight&GST) | CX1: PARTY LENGTH (IF STANDER LENGTH NOT MATCH WITH PAR | CY1: DRUM CODE | CZ1: DRUM SIZE (FxbXtx Ft)
A2: ENQ-17670-25-26 | C2: FA1300010 | D2: 3 CORE X 400 SQ. MM. AL/ARM - STRIP (XLPE) - 33 KV | E2: STEEL | F2: Copper Tape -50X0.10 | H2: 399 | J2: Alumimium | L2: 3240 | P2: 0 | R2: Extruded Semiconductive(Stripable) | T2: 427 | V2: TR XLPE | X2: 2621 | AB2: 0 | AD2: PVC Type ST-2 | AF2: 405 | AH2: Galvanised Steel Flat Strip | AJ2: 1600 | AL2: PE-ST-7 | AN2: 1560 | AP2: Polypropylene Filler | AR2: 2672 | AV2: 0 | AX2: Water swellable Tape | AZ2: 162 | BB2: Semi conducting Water Swellable tape | BD2: 0 | BH2: 52 | BL2: 129 | BP2: 0 | BR2: RUBBERIZED COTTON TAPE | BT2: 0 | BX2: 0 | BZ2: 182400 | CA2: 182400 | CH2: 182400 | CO2: 182400 | CQ2: 182400 | CR2: 0.18 | CS2: 32832 | CT2: 215232 | CU2: 78 | CV2: KMS | CW2: 16788096 | CX2: 250 | CY2: SP0400105 | CZ2: CORRUGATED DISPATCH STEEL DRUM 2500 X 1500 X 1400
A3: ENQ-17670-25-26 | C3: FA1300017 | D3: 3 CORE X 400 SQ. MM. AL/ARM - STRIP (XLPE) - 11 KV | E3: STEEL | F3: Copper Tape -50X0.10 | H3: 303 | J3: Alumimium | L3: 3240 | P3: 0 | R3: Extruded Semiconductive(Stripable) | T3: 366 | V3: TR XLPE | X3: 908 | AB3: 0 | AD3: PVC Type ST-2 | AF3: 305 | AH3: Galvanised Steel Flat Strip | AJ3: 1225 | AL3: PE-ST-7 | AN3: 1146 | AP3: Polypropylene Filler | AR3: 1535 | AV3: 0 | AX3: Water swellable Tape | AZ3: 0 | BB3: Semi conducting Water Swellable tape | BD3: 0 | BH3: 0 | BL3: 0 | BP3: 0 | BR3: RUBBERIZED COTTON TAPE | BT3: 0 | BX3: 0 | BZ3: 100100 | CA3: 100100 | CH3: 100100 | CO3: 100100 | CQ3: 100100 | CR3: 0.18 | CS3: 18018 | CT3: 118118 | CU3: 398.5 | CV3: KMS | CW3: 47070023 | CX3: 300 | CY3: SP0400136 | CZ3: CORRUGATED DISPATCH STEEL DRUM 2200 X 1300 X 1200 MM
A4: ENQ-17670-25-26 | C4: FA1300027 | D4: 1 CORE X 630 SQ. MM. AL/ARM (XLPE) - 33 KV | H4: 0 | L4: 1701 | P4: 0 | T4: 172 | X4: 1040 | AB4: 0 | AF4: 193 | AJ4: 800 | AN4: 738 | AR4: 0 | AV4: 0 | AZ4: 0 | BD4: 0 | BH4: 0 | BL4: 0 | BP4: 0 | BT4: 0 | BX4: 0 | CR4: 0.18 | CU4: 7.6 | CV4: KMS | CX4: 500
A5: ENQ-17670-25-26 | C5: FA1300052 | D5: 3 CORE X 150 SQ. MM. AL/ARM - STRIP (XLPE) - 11 KV | E5: WOOD | F5: Copper Tape -50X0.10 | H5: 220 | J5: Alumimium | L5: 1215 | P5: 0 | R5: Extruded Semiconductive(Stripable) | T5: 246 | V5: TR XLPE | X5: 620 | AB5: 0 | AD5: PVC Type ST-2 | AF5: 200 | AH5: Galvanised Steel Flat Strip | AJ5: 900 | AL5: PVC Type ST-2 | AN5: 672 | AP5: Polypropylene Filler | AR5: 809 | AV5: 0 | AX5: Water swellable Tape | AZ5: 0 | BB5: Semi conducting Water Swellable tape | BD5: 0 | BH5: 0 | BL5: 0 | BP5: 0 | BR5: RUBBERIZED COTTON TAPE | BT5: 0 | BX5: 0 | BZ5: 33260 | CA5: 33260 | CH5: 33260 | CO5: 33260 | CQ5: 33260 | CR5: 0.18 | CS5: 5986.8 | CT5: 39246.8 | CU5: 8.5 | CV5: KMS | CW5: 333598 | CX5: 300 | CY5: MD0100022 | CZ5: DRUM - 64 X 23 X 36 X 3
A6: ENQ-17670-25-26 | C6: FA1300066 | D6: 1 CORE X 1000 SQ. MM. AL/ARM (XLPE) - 11 KV | E6: STEEL | F6: Copper Tape -50X0.10 | H6: 148 | J6: Alumimium | L6: 2732 | P6: 0 | R6: Extruded Semiconductive(Stripable) | T6: 200 | V6: TR XLPE | X6: 465 | AB6: 0 | AD6: PVC Type ST-2 | AF6: 185 | AH6: Aluminium Round Wire | AJ6: 773 | AL6: PVC Type ST-2 | AN6: 655 | AR6: 0 | AV6: 0 | AX6: Water swellable Tape | AZ6: 0 | BB6: Semi conducting Water Swellable tape | BD6: 99 | BH6: 59 | BL6: 0 | BP6: 0 | BR6: RUBBERIZED COTTON TAPE | BT6: 52 | BX6: 0 | BZ6: 66500 | CA6: 66500 | CH6: 66500 | CO6: 66500 | CQ6: 66500 | CR6: 0.18 | CS6: 11970 | CT6: 78470 | CU6: 14.2 | CV6: KMS | CW6: 1114274 | CX6: 500 | CY6: SP0400107 | CZ6: CORRUGATED DISPATCH STEEL DRUM 2150 X 1080 X 1240 MM

Sheet AUTO CALCULATION SHEET (2)
A2: Adani Electricity Mumbai Ltd
A4: TENDER SPECIFICATION NO () | B4: NIT No: AEML/MDB/2025-26/44
A5: TENDER DESCRIPTION () | B5: Tender Notification for Supply of assorted sizes of HT Cables
A6: Last Date & Time of Submission () | B6: 24/Nov/2025 (Up to 16:00 Hours IST)
A7: REVERSE AUCTION | B7: Purchaser reserves the right to use the reverse auction as a part of the tendering process. All the bidders which are techno-commercially qualified on the basis of tender requirements shall participate in reverse auction. The prices quoted by bidder in reverse auction event shall be on FOR Landed cost AEML Store/site basis inclusive of all relevant taxes, duties, levies, transportation charges
A8: Price () | B8: Prices will be Variable as per IEEMA Price Variation Formula considering below LME Index Base. 1) Copper: …………. USD/MT (LME Closing day offer price of 28.10.2025) 2) Aluminum: …………. USD/MT (LME Closing day offer price of 28.10.2025) 3) USD to INR: ……… (USD to INR for 28.10.2025 - As per RBI website - Closing of day) 4) HDPE Polyethylene PE ST7: Rs. 1,47,250/MT (IEEMA - Sept 2025 i.e. Circular issued in Oct 2025) 5) PVC: Rs. 1,59,825/MT (IEEMA - Sept 2025 i.e. Circular issued in Oct 2025) 6) XLPE: Rs. 1,91,538/MT (IEEMA - Sept 2025 i.e. Circular issued in Oct 2025) 7) Steel: Rs. 81,250/MT (IEEMA - Sept 2025 i.e. Circular issued in Oct 2025) Price variance approved for a Lot shall be FIRM & applicable till delivery completion of entire Lot.
A9: Validity () | B9: 180 days from the date of opening of technocommercial bid.
A10: Delivery Period () | B10: All the Goods covered under the PO Documents shall be Delivered on or before 30.06.2027 from the Effective Date as per the delivery schedule / manufacturing clearance provided by AEML.
A11: Payment Terms () | B11: Hundred percent (100%) of the Basic Price (along with hundred percent (100%) of the applicable GST payable on the total Basic Price) shall be paid on a pro rata basis within Ninety (90) days after receipt of Goods at the Delivery Point upon submission of the invoice and the documents as specified in Clause 9 of this document.
A12: Standard length () | B12: Cable length per drum b) 11 KV, Three core = 300 mtr +/- 5 % c) 33 KV, Three core [R5] = 250 mtr +/- 5 % d) 11 KV, Single core = 500 mtr +/- 5 % e) 33 KV, Single core = 500 mtr +/- 5 %
A13: Packing () | B13: Steel / wooden drums, as per relevant IS / IEC. (Wooden drums shall be with M.S. spindle plate with nut-bolts)
A14: Technical Specification
N16: Conductor | V16: AL ALLOY | X16: Insulation Screening (Metallic) | AF16: Insulation Screening (Non-Metallic) | AH16: Insulation | AQ16: POLY TAPE | AR16: Inner Sheath | BA16: Armouring | BL16: Outer Sheath | BX16: FILLER | BY16: GREASE | BZ16: Water swellable Tape | CA16: Semi conducting Water Swellable tape | CB16: SEMICON TAPE | CC16: GLASS FIBER TAPE | CD16: COPPER WIRE 0.8 MM | CE16: RUBBERIZED COTTON TAPE | CF16: Water Tight Compound | CG16: DRUM TYPE | CK16: DRUM COST PER KM | CL16: TOTAL RM COST | CM16: EXTRA CONSUMPTION | CN16: EXTRA CONSUMPTION VALUE | CZ16: $A$1
A17: DOCKET NO. | B17: BASE DATE | C17: ITEM CODE | D17: PROPOSE ERP ITEM NAME | E17: EX-WORKS (PER KM) | F17: FREIGHT PER KM | G17: PRICE INCLUDING FREIGHT (PER KM) | H17: GST % | I17: GST VALUE | J17: PRICE INCLUDING GST & FREIGHT (PER KM) | K17: QTY | L17: Unit | M17: TOTAL PRICE OF FULL QTY (INCLUDING FRIGHT & GST) | N17: Alumimium | O17: Alumimium ALLOY | P17: Copper | Q17: AL-59 | R17: AL-4 | S17: AL-7 | T17: Flexible Copper | U17: Galvanized steel wire | V17: Alumimium | W17: Alumimium ALLOY | X17: Coper tape -50X 0.1 mm | Y17: Copper Tape - 0.03 mm | Z17: Copper Tape - 0.035 mm | AA17: Copper Tape - 0.04 mm | AB17: Copper Tape - 0.045 mm | AC17: Copper Tape - 0.050 mm | AD17: Copper Tape - 0.060 mm | AE17: Copper Tape - 0.075 mm(DOUBLE) | AF17: Extruded semiconductive | AG17: Extruded Semiconductive(Stripable) | AH17: HT-XLPE | AI17: LT-XLPE | AJ17: TR XLPE | AK17: Type A PVC | AL17: Type C PVC (HR) | AM17: Type A PVC-1.45 | AN17: Type A PVC-FR | AO17: Type A PVC-FRLS | AP17: Type A PVC-1.38 | AQ17: POLY TAPE | AR17: FR PVC Type ST-1 | AS17: FR PVC Type ST-2 | AT17: FRLSH PVC Type ST-1 | AU17: FRLSH PVC Type ST-2 | AV17: PVC Type ST-1 | AW17: PVC Type ST-1-PRESSURE EXTRUDED | AX17: PVC Type ST-2 | AY17: PVC COMPOUND 1.48 | AZ17: PVC Type ST-2-PRESSURE EXTRUDED | BA17: ACSR CORE WIRE | BB17: ACSR DOG STEEL WIRE | BC17: Aluminium Flat Strip | BD17: Aluminium Round Wire | BE17: Alumimium Tape | BF17: Double Steel Tape | BG17: Galvanised Steel Flat Strip | BH17: Galvanised Steel Flat Strip (Double) | BI17: Galvanised Steel Flat Strip-B | BJ17: Galvanised Steel Round Wire | BK17: Galvanised Steel Round Wire (Double) | BL17: FR PVC Type ST-1 | BM17: FR PVC Type ST-2 | BN17: FRLSH PVC Type ST-1 | BO17: FRLSH PVC Type ST-2 | BP17: ZHFR | BQ17: PE-ST-3 | BR17: PE-ST-7 | BS17: PVC Type ST-1 | BT17: PVC Type ST-2 WITH ATR | BU17: PVC COMPOUND 1.48 | BV17: PVC Type ST-2-PRESSURE EXTRUDED | BW17: UV & Track Resistant XLPE | BX17: PP FILLER | BY17: Grease | BZ17: NCWBT | CA17: Semi conducting Water Swellable tape (min 0.3) | CB17: SEMICON TAPE | CC17: GLASS FIBER TAPE | CD17: COPPER WIRE 0.8 MM | CE17: RUBBERIZED COTTON TAPE | CF17: Water Tight Compound | CG17: PROPOSE DRUM TYPE | CH17: DRUM CODE | CI17: DRUM SIZE (FxbXtx Ft) | CJ17: PARTY STANDARD LENGTH (MTR) | CO17: MFG% | CP17: MFG VALUE | CQ17: PROF% | CR17: PROFIT VALUE | CS17: 1ST EX-WORKS | CT17: Intt % | CU17: INTT VALUE | CV17: insp% | CW17: INSP VALUE | CX17: TTR Charges% | CY17: TTR Charges VALUE
N18: 287 | O18: =+IFERROR(VLOOKUP($O$17,Sheet1!J:L,2,0),0) -> 0 | P18: =+IFERROR(VLOOKUP($P$17,Sheet1!J:M,2,0),0) -> 0 | Q18: =+IFERROR(VLOOKUP($Q$17,Sheet1!J:M,2,0),0) -> 0 | R18: =+IFERROR(VLOOKUP($R$17,Sheet1!J:M,2,0),0) -> 0 | S18: =+IFERROR(VLOOKUP($S$17,Sheet1!J:M,2,0),0) -> 0 | T18: =+IFERROR(VLOOKUP($T$17,Sheet1!J:M,2,0),0) -> 0 | U18: =+IFERROR(VLOOKUP($U$17,Sheet1!J:M,2,0),0) -> 0 | V18: =+IFERROR(VLOOKUP($V$17,Sheet1!N:Q,2,0),0) -> 0 | W18: =+IFERROR(VLOOKUP($W$17,Sheet1!N:O,2,0),0) -> 0 | X18: 1135 | Y18: =+IFERROR(VLOOKUP($Y$17,Sheet1!F:I,2,0),0) -> 0 | Z18: =+IFERROR(VLOOKUP($Z$17,Sheet1!F:I,2,0),0) -> 0 | AA18: =+IFERROR(VLOOKUP($AA$17,Sheet1!F:I,2,0),0) -> 0 | AB18: =+IFERROR(VLOOKUP($AB$17,Sheet1!F:I,2,0),0) -> 0 | AC18: =+IFERROR(VLOOKUP($AC$17,Sheet1!F:I,2,0),0) -> 0 | AD18: =+IFERROR(VLOOKUP($AD$17,Sheet1!F:I,2,0),0) -> 0 | AE18: =+IFERROR(VLOOKUP($AE$17,Sheet1!F:I,2,0),0) -> 0 | AF18: =+IFERROR(VLOOKUP($AF$17,Sheet1!R:U,2,0),0) -> 0 | AG18: 178 | AH18: =+IFERROR(VLOOKUP($AH$17,Sheet1!V:Y,2,0),0) -> 0 | AI18: =+IFERROR(VLOOKUP($AI$17,Sheet1!V:Y,2,0),0) -> 0 | AJ18: 215 | AK18: =+IFERROR(VLOOKUP($AK$17,Sheet1!V:Y,2,0),0) -> 0 | AL18: =+IFERROR(VLOOKUP($AL$17,Sheet1!V:Y,2,0),0) -> 0 | AM18: =+IFERROR(VLOOKUP($AM$17,Sheet1!V:Y,2,0),0) -> 0 | AN18: =+IFERROR(VLOOKUP($AN$17,Sheet1!V:Y,2,0),0) -> 0 | AO18: =+IFERROR(VLOOKUP($AO$17,Sheet1!V:Y,2,0),0) -> 0 | AP18: =+IFERROR(VLOOKUP($AP$17,Sheet1!V:Y,2,0),0) -> 0 | AQ18: 108 | AR18: =+IFERROR(VLOOKUP($AR$17,Sheet1!AD2:AG840,2,0),0) -> 0 | AS18: =+IFERROR(VLOOKUP($AS$17,Sheet1!AD2:AG840,2,0),0) -> 0 | AT18: =+IFERROR(VLOOKUP($AT$17,Sheet1!AD2:AG840,2,0),0) -> 0 | AU18: =+IFERROR(VLOOKUP($AU$17,Sheet1!AD2:AG840,2,0),0) -> 0 | AV18: =+IFERROR(VLOOKUP($AV$17,Sheet1!AD2:AG840,2,0),0) -> 0 | AW18: =+IFERROR(VLOOKUP($AW$17,Sheet1!AD2:AG840,2,0),0) -> 0 | AX18: 62 | AY18: =+IFERROR(VLOOKUP($AY$17,Sheet1!AD2:AG840,2,0),0) -> 0 | AZ18: =+IFERROR(VLOOKUP($AZ$17,Sheet1!AD2:AG840,2,0),0) -> 0 | BA18: =+IFERROR(VLOOKUP($BA$17,Sheet1!AH2:AK840,2,0),0) -> 0 | BB18: =+IFERROR(VLOOKUP($BB$17,Sheet1!AH2:AK840,2,0),0) -> 0 | BC18: =+IFERROR(VLOOKUP($BC$17,Sheet1!AH2:AK840,2,0),0) -> 0 | BD18: 292 | BE18: =+IFERROR(VLOOKUP($BE$17,Sheet1!AH2:AK840,2,0),0) -> 0 | BF18: =+IFERROR(VLOOKUP($BF$17,Sheet1!AH2:AK840,2,0),0) -> 0 | BG18: 75 | BH18: =+IFERROR(VLOOKUP($BH$17,Sheet1!AH2:AK840,2,0),0) -> 0 | BI18: =+IFERROR(VLOOKUP($BI$17,Sheet1!AH2:AK840,2,0),0) -> 0 | BJ18: =+IFERROR(VLOOKUP($BJ$17,Sheet1!AH2:AK840,2,0),0) -> 0 | BK18: =+IFERROR(VLOOKUP($BK$17,Sheet1!AH2:AK840,2,0),0) -> 0 | BL18: =+IFERROR(VLOOKUP($BL$17,Sheet1!AL2:AO840,2,0),0) -> 0 | BM18: =+IFERROR(VLOOKUP($BM$17,Sheet1!AL2:AO840,2,0),0) -> 0 | BN18: =+IFERROR(VLOOKUP($BN$17,Sheet1!AL2:AO840,2,0),0) -> 0 | BO18: =+IFERROR(VLOOKUP($BO$17,Sheet1!AL2:AO840,2,0),0) -> 0 | BP18: =+IFERROR(VLOOKUP($BP$17,Sheet1!AL2:AO840,2,0),0) -> 0 | BQ18: =+IFERROR(VLOOKUP($BQ$17,Sheet1!AL2:AO840,2,0),0) -> 0 | BR18: 105 | BS18: =+IFERROR(VLOOKUP($BS$17,Sheet1!AL2:AO840,2,0),0) -> 0 | BT18: =AX18+7 -> 69 | BU18: =+IFERROR(VLOOKUP($BU$17,Sheet1!AL2:AO840,2,0),0) -> 0 | BV18: =+IFERROR(VLOOKUP($BV$17,Sheet1!AL2:AO840,2,0),0) -> 0 | BW18: =+IFERROR(VLOOKUP($BW$17,Sheet1!AL2:AO840,2,0),0) -> 0 | BX18: 78 | BY18: =+IFERROR(VLOOKUP($BY$17,Sheet1!AT2:AW840,2,0),0) -> 0 | BZ18: 300 | CA18: 415 | CB18: =+IFERROR(VLOOKUP($CB$17,Sheet1!BF2:BI840,2,0),0) -> 0 | CC18: =+IFERROR(VLOOKUP($CC$17,Sheet1!BJ2:BM840,2,0),0) -> 0 | CD18: =+IFERROR(VLOOKUP($CD$17,Sheet1!BN2:BQ840,2,0),0) -> 0 | CE18: 285 | CF18: =+IFERROR(VLOOKUP($CF$17,Sheet1!BV2:BY840,2,0),0) -> 0
A19: =Sheet1!A2 -> ENQ-17670-25-26 | B19: 45958 | C19: =Sheet1!C2 -> FA1300010 | D19: =Sheet1!D2 -> 3 CORE X 400 SQ. MM. AL/ARM - STRIP (XLPE) - 33 KV | E19: =CS19+CU19+CW19+CY19 -> 4233504.9 | F19: =ROUNDUP(M28,2) -> 118730.77 | G19: =E19+F19 -> 4352235.7 | H19: =Sheet1!CR2 -> 0.18 | I19: =G19*H19 -> 783402.42 | J19: =G19+I19 -> 5135638.1 | K19: =Sheet1!CU2 -> 78 | L19: =Sheet1!CV2 -> KMS | M19: =J19*K19 -> 4.0057977e+08 | N19: =+IFERROR(VLOOKUP($N$17,Sheet1!J2:L2,3,0),0) -> 3240 | O19: =+IFERROR(VLOOKUP($O$17,Sheet1!J2:L2,3,0),0) -> 0 | P19: =+IFERROR(VLOOKUP($P$17,Sheet1!J2:M2,3,0),0) -> 0 | Q19: =+IFERROR(VLOOKUP($Q$17,Sheet1!J2:M2,3,0),0) -> 0 | R19: =+IFERROR(VLOOKUP($R$17,Sheet1!J2:M2,3,0),0) -> 0 | S19: =+IFERROR(VLOOKUP($S$17,Sheet1!J2:M2,3,0),0) -> 0 | T19: =+IFERROR(VLOOKUP($T$17,Sheet1!J2:M2,3,0),0) -> 0 | U19: =+IFERROR(VLOOKUP($U$17,Sheet1!J2:M2,3,0),0) -> 0 | V19: =+IFERROR(VLOOKUP($V$17,Sheet1!N2:Q2,3,0),0) -> 0 | W19: =+IFERROR(VLOOKUP($W$17,Sheet1!N2:Q2,3,0),0) -> 0 | X19: 536 | Y19: =+IFERROR(VLOOKUP($Y$17,Sheet1!F2:I2,3,0),0) -> 0 | Z19: =+IFERROR(VLOOKUP($Z$17,Sheet1!F2:I2,3,0),0) -> 0 | AA19: =+IFERROR(VLOOKUP($AA$17,Sheet1!F2:I2,3,0),0) -> 0 | AB19: =+IFERROR(VLOOKUP($AB$17,Sheet1!F2:I2,3,0),0) -> 0 | AC19: =+IFERROR(VLOOKUP($AC$17,Sheet1!F2:I2,3,0),0) -> 0 | AD19: =+IFERROR(VLOOKUP($AD$17,Sheet1!F2:I2,3,0),0) -> 0 | AE19: =+IFERROR(VLOOKUP($AE$17,Sheet1!F2:I2,3,0),0) -> 0 | AF19: =+IFERROR(VLOOKUP($AF$17,Sheet1!R2:U2,3,0),0) -> 0 | AG19: 506 | AH19: =+IFERROR(VLOOKUP($AH$17,Sheet1!V2:Y2,3,0),0) -> 0 | AI19: =+IFERROR(VLOOKUP($AI$17,Sheet1!V2:Y2,3,0),0) -> 0 | AJ19: 2675 | AK19: =+IFERROR(VLOOKUP($AK$17,Sheet1!V2:Y2,3,0),0) -> 0 | AL19: =+IFERROR(VLOOKUP($AL$17,Sheet1!V2:Y2,3,0),0) -> 0 | AM19: =+IFERROR(VLOOKUP($AM$17,Sheet1!V2:Y2,3,0),0) -> 0 | AN19: =+IFERROR(VLOOKUP($AN$17,Sheet1!V2:Y2,3,0),0) -> 0 | AO19: =+IFERROR(VLOOKUP($AO$17,Sheet1!V2:Y2,3,0),0) -> 0 | AP19: =+IFERROR(VLOOKUP($AP$17,Sheet1!V2:Y2,3,0),0) -> 0 | AQ19: =+IFERROR(VLOOKUP($AQ$17,Sheet1!Z2:AB2,3,0),0) -> 0 | AR19: =+IFERROR(VLOOKUP($AR$17,Sheet1!AD2:AG2,3,0),0) -> 0 | AS19: =+IFERROR(VLOOKUP($AS$17,Sheet1!AD2:AG2,3,0),0) -> 0 | AT19: =+IFERROR(VLOOKUP($AT$17,Sheet1!AD2:AG2,3,0),0) -> 0 | AU19: =+IFERROR(VLOOKUP($AU$17,Sheet1!AD2:AG2,3,0),0) -> 0 | AV19: =+IFERROR(VLOOKUP($AV$17,Sheet1!AD2:AG2,3,0),0) -> 0 | AW19: =+IFERROR(VLOOKUP($AW$17,Sheet1!AD2:AG2,3,0),0) -> 0 | AX19: 1547 | AY19: =+IFERROR(VLOOKUP($AY$17,Sheet1!AD2:AG2,3,0),0) -> 0 | AZ19: =+IFERROR(VLOOKUP($AZ$17,Sheet1!AD2:AG2,3,0),0) -> 0 | BA19: =+IFERROR(VLOOKUP($BA$17,Sheet1!AH2:AK2,3,0),0) -> 0 | BB19: =+IFERROR(VLOOKUP($BB$17,Sheet1!AH2:AK2,3,0),0) -> 0 | BC19: =+IFERROR(VLOOKUP($BC$17,Sheet1!AH2:AK2,3,0),0) -> 0 | BD19: =+IFERROR(VLOOKUP($BD$17,Sheet1!AH2:AK2,3,0),0) -> 0 | BE19: =+IFERROR(VLOOKUP($BE$17,Sheet1!AH2:AK2,3,0),0) -> 0 | BF19: =+IFERROR(VLOOKUP($BF$17,Sheet1!AH2:AK2,3,0),0) -> 0 | BG19: 1675 | BH19: =+IFERROR(VLOOKUP($BH$17,Sheet1!AH2:AK2,3,0),0) -> 0 | BI19: =+IFERROR(VLOOKUP($BI$17,Sheet1!AH2:AK2,3,0),0) -> 0 | BJ19: =+IFERROR(VLOOKUP($BJ$17,Sheet1!AH2:AK2,3,0),0) -> 0 | BK19: =+IFERROR(VLOOKUP($BK$17,Sheet1!AH2:AK2,3,0),0) -> 0 | BL19: =+IFERROR(VLOOKUP($BL$17,Sheet1!AL2:AO2,3,0),0) -> 0 | BM19: =+IFERROR(VLOOKUP($BM$17,Sheet1!AL2:AO2,3,0),0) -> 0 | BN19: =+IFERROR(VLOOKUP($BN$17,Sheet1!AL2:AO2,3,0),0) -> 0 | BO19: =+IFERROR(VLOOKUP($BO$17,Sheet1!AL2:AO2,3,0),0) -> 0 | BP19: =+IFERROR(VLOOKUP($BP$17,Sheet1!AL2:AO2,3,0),0) -> 0 | BQ19: =+IFERROR(VLOOKUP($BQ$17,Sheet1!AL2:AO2,3,0),0) -> 0 | BR19: 1063 | BS19: =+IFERROR(VLOOKUP($BS$17,Sheet1!AL2:AO2,3,0),0) -> 0 | BT19: =+IFERROR(VLOOKUP($BT$17,Sheet1!AL2:AO2,3,0),0) -> 0 | BU19: =+IFERROR(VLOOKUP($BU$17,Sheet1!AL2:AO2,3,0),0) -> 0 | BV19: =+IFERROR(VLOOKUP($BV$17,Sheet1!AL2:AO2,3,0),0) -> 0 | BW19: =+IFERROR(VLOOKUP($BW$17,Sheet1!AL2:AO2,3,0),0) -> 0 | BX19: 1660 | BY19: =+IFERROR(VLOOKUP($BY$17,Sheet1!AT2:AW2,3,0),0) -> 0 | BZ19: 58 | CA19: 108 | CB19: =+IFERROR(VLOOKUP($CB$17,Sheet1!BF2:BI2,3,0),0) -> 0 | CC19: =+IFERROR(VLOOKUP($CC$17,Sheet1!BJ2:BM2,3,0),0) -> 0 | CD19: =+IFERROR(VLOOKUP($CD$17,Sheet1!BN2:BQ2,3,0),0) -> 0 | CE19: 164 | CF19: =+IFERROR(VLOOKUP($CF$17,Sheet1!BV2:BY2,3,0),0) -> 0 | CG19: =Sheet1!E2 -> STEEL | CH19: SP0400105 | CI19: CORRUGATED DISPATCH STEEL DRUM 2500 X 1500 X 1400 | CJ19: 250 | CK19: =33150/0.25 -> 132600 | CL19: =SUMPRODUCT($N$18:$CF$18,N19:CF19)+CK19 -> 2907627 | CM19: =Sheet1!CB2 -> 0 | CN19: =CL19*CM19 -> 0 | CO19: 0.4 | CP19: =CL19*CO19 -> 1163050.8 | CQ19: 0 | CR19: =CL19*CQ19 -> 0 | CS19: =CL19+CN19+CP19+CR19 -> 4070677.8 | CT19: 0.03 | CU19: =CS19*CT19 -> 122120.33 | CV19: 0.01 | CW19: =CS19*CV19 -> 40706.778 | CX19: =Sheet1!CM2 -> 0 | CY19: =CX19*CS19 -> 0
A20: =Sheet1!A4 -> ENQ-17670-25-26 | B20: 45958 | C20: =Sheet1!C4 -> FA1300027 | D20: =Sheet1!D4 -> 1 CORE X 630 SQ. MM. AL/ARM (XLPE) - 33 KV | E20: =CS20+CU20+CW20+CY20 -> 1999438.9 | F20: =ROUNDUP(M29,2) -> 58026.32 | G20: =E20+F20 -> 2057465.2 | H20: =Sheet1!CR4 -> 0.18 | I20: =G20*H20 -> 370343.74 | J20: =G20+I20 -> 2427809 | K20: =Sheet1!CU4 -> 7.6 | L20: =Sheet1!CV4 -> KMS | M20: =J20*K20 -> 18451348 | N20: 1701 | O20: =+IFERROR(VLOOKUP($O$17,Sheet1!J4:L4,3,0),0) -> 0 | P20: =+IFERROR(VLOOKUP($P$17,Sheet1!J4:M4,3,0),0) -> 0 | Q20: =+IFERROR(VLOOKUP($Q$17,Sheet1!J4:M4,3,0),0) -> 0 | R20: =+IFERROR(VLOOKUP($R$17,Sheet1!J4:M4,3,0),0) -> 0 | S20: =+IFERROR(VLOOKUP($S$17,Sheet1!J4:M4,3,0),0) -> 0 | T20: =+IFERROR(VLOOKUP($T$17,Sheet1!J4:M4,3,0),0) -> 0 | U20: =+IFERROR(VLOOKUP($U$17,Sheet1!J4:M4,3,0),0) -> 0 | V20: =+IFERROR(VLOOKUP($V$17,Sheet1!N4:Q4,3,0),0) -> 0 | W20: =+IFERROR(VLOOKUP($W$17,Sheet1!N4:Q4,3,0),0) -> 0 | X20: 204 | Y20: =+IFERROR(VLOOKUP($Y$17,Sheet1!F4:I4,3,0),0) -> 0 | Z20: =+IFERROR(VLOOKUP($Z$17,Sheet1!F4:I4,3,0),0) -> 0 | AA20: =+IFERROR(VLOOKUP($AA$17,Sheet1!F4:I4,3,0),0) -> 0 | AB20: =+IFERROR(VLOOKUP($AB$17,Sheet1!F4:I4,3,0),0) -> 0 | AC20: =+IFERROR(VLOOKUP($AC$17,Sheet1!F4:I4,3,0),0) -> 0 | AD20: =+IFERROR(VLOOKUP($AD$17,Sheet1!F4:I4,3,0),0) -> 0 | AE20: =+IFERROR(VLOOKUP($AE$17,Sheet1!F4:I4,3,0),0) -> 0 | AF20: =+IFERROR(VLOOKUP($AF$17,Sheet1!R4:U4,3,0),0) -> 0 | AG20: 200 | AH20: =+IFERROR(VLOOKUP($AH$17,Sheet1!V4:Y4,3,0),0) -> 0 | AI20: =+IFERROR(VLOOKUP($AI$17,Sheet1!V4:Y4,3,0),0) -> 0 | AJ20: 1056 | AK20: =+IFERROR(VLOOKUP($AK$17,Sheet1!V4:Y4,3,0),0) -> 0 | AL20: =+IFERROR(VLOOKUP($AL$17,Sheet1!V4:Y4,3,0),0) -> 0 | AM20: =+IFERROR(VLOOKUP($AM$17,Sheet1!V4:Y4,3,0),0) -> 0 | AN20: =+IFERROR(VLOOKUP($AN$17,Sheet1!V4:Y4,3,0),0) -> 0 | AO20: =+IFERROR(VLOOKUP($AO$17,Sheet1!V4:Y4,3,0),0) -> 0 | AP20: =+IFERROR(VLOOKUP($AP$17,Sheet1!V4:Y4,3,0),0) -> 0 | AQ20: =+IFERROR(VLOOKUP($AQ$17,Sheet1!Z4:AB4,3,0),0) -> 0 | AR20: =+IFERROR(VLOOKUP($AR$17,Sheet1!AD4:AG4,3,0),0) -> 0 | AS20: =+IFERROR(VLOOKUP($AS$17,Sheet1!AD4:AG4,3,0),0) -> 0 | AT20: =+IFERROR(VLOOKUP($AT$17,Sheet1!AD4:AG4,3,0),0) -> 0 | AU20: =+IFERROR(VLOOKUP($AU$17,Sheet1!AD4:AG4,3,0),0) -> 0 | AV20: =+IFERROR(VLOOKUP($AV$17,Sheet1!AD4:AG4,3,0),0) -> 0 | AW20: =+IFERROR(VLOOKUP($AW$17,Sheet1!AD4:AG4,3,0),0) -> 0 | AX20: 215 | AY20: =+IFERROR(VLOOKUP($AY$17,Sheet1!AD4:AG4,3,0),0) -> 0 | AZ20: =+IFERROR(VLOOKUP($AZ$17,Sheet1!AD4:AG4,3,0),0) -> 0 | BA20: =+IFERROR(VLOOKUP($BA$17,Sheet1!AH4:AK4,3,0),0) -> 0 | BB20: =+IFERROR(VLOOKUP($BB$17,Sheet1!AH4:AK4,3,0),0) -> 0 | BC20: =+IFERROR(VLOOKUP($BC$17,Sheet1!AH4:AK4,3,0),0) -> 0 | BD20: 842 | BE20: =+IFERROR(VLOOKUP($BE$17,Sheet1!AH4:AK4,3,0),0) -> 0 | BF20: =+IFERROR(VLOOKUP($BF$17,Sheet1!AH4:AK4,3,0),0) -> 0 | BG20: =+IFERROR(VLOOKUP($BG$17,Sheet1!AH4:AK4,3,0),0) -> 0 | BH20: =+IFERROR(VLOOKUP($BH$17,Sheet1!AH4:AK4,3,0),0) -> 0 | BI20: =+IFERROR(VLOOKUP($BI$17,Sheet1!AH4:AK4,3,0),0) -> 0 | BJ20: =+IFERROR(VLOOKUP($BJ$17,Sheet1!AH4:AK4,3,0),0) -> 0 | BK20: =+IFERROR(VLOOKUP($BK$17,Sheet1!AH4:AK4,3,0),0) -> 0 | BL20: =+IFERROR(VLOOKUP($BL$17,Sheet1!AL4:AO4,3,0),0) -> 0 | BM20: =+IFERROR(VLOOKUP($BM$17,Sheet1!AL4:AO4,3,0),0) -> 0 | BN20: =+IFERROR(VLOOKUP($BN$17,Sheet1!AL4:AO4,3,0),0) -> 0 | BO20: =+IFERROR(VLOOKUP($BO$17,Sheet1!AL4:AO4,3,0),0) -> 0 | BP20: =+IFERROR(VLOOKUP($BP$17,Sheet1!AL4:AO4,3,0),0) -> 0 | BQ20: =+IFERROR(VLOOKUP($BQ$17,Sheet1!AL4:AO4,3,0),0) -> 0 | BR20: =+IFERROR(VLOOKUP($BR$17,Sheet1!AL4:AO4,3,0),0) -> 0 | BS20: =+IFERROR(VLOOKUP($BS$17,Sheet1!AL4:AO4,3,0),0) -> 0 | BT20: 765 | BU20: =+IFERROR(VLOOKUP($BU$17,Sheet1!AL4:AO4,3,0),0) -> 0 | BV20: =+IFERROR(VLOOKUP($BV$17,Sheet1!AL4:AO4,3,0),0) -> 0 | BW20: =+IFERROR(VLOOKUP($BW$17,Sheet1!AL4:AO4,3,0),0) -> 0 | BX20: =+IFERROR(VLOOKUP($BX$17,Sheet1!AP4:AS4,3,0),0) -> 0 | BY20: =+IFERROR(VLOOKUP($BY$17,Sheet1!AT4:AW4,3,0),0) -> 0 | BZ20: 26 | CA20: 43 | CB20: =+IFERROR(VLOOKUP($CB$17,Sheet1!BF4:BI4,3,0),0) -> 0 | CC20: =+IFERROR(VLOOKUP($CC$17,Sheet1!BJ4:BM4,3,0),0) -> 0 | CD20: =+IFERROR(VLOOKUP($CD$17,Sheet1!BN4:BQ4,3,0),0) -> 0 | CE20: 50 | CF20: =+IFERROR(VLOOKUP($CF$17,Sheet1!BV4:BY4,3,0),0) -> 0 | CG20: STEEL | CH20: SP0400123 | CI20: CORRUGATED DISPATCH STEEL DRUM 2000 X 1000 X 1200 MM | CJ20: 500 | CK20: =19500/0.5 -> 39000 | CL20: =SUMPRODUCT($N$18:$CF$18,N20:CF20)+CK20 -> 1373241 | CM20: =Sheet1!CB4 -> 0 | CN20: =CL20*CM20 -> 0 | CO20: 0.4 | CP20: =CL20*CO20 -> 549296.4 | CQ20: 0 | CR20: =CL20*CQ20 -> 0 | CS20: =CL20+CN20+CP20+CR20 -> 1922537.4 | CT20: 0.03 | CU20: =CS20*CT20 -> 57676.122 | CV20: 0.01 | CW20: =CS20*CV20 -> 19225.374 | CX20: =Sheet1!CM4 -> 0 | CY20: =CX20*CS20 -> 0
A21: =Sheet1!A3 -> ENQ-17670-25-26 | B21: 45958 | C21: =Sheet1!C3 -> FA1300017 | D21: =Sheet1!D3 -> 3 CORE X 400 SQ. MM. AL/ARM - STRIP (XLPE) - 11 KV | E21: =CS21+CU21+CW21+CY21 -> 3158423.1 | F21: =ROUNDUP(M30,2) -> 81892.1 | G21: =E21+F21 -> 3240315.2 | H21: =Sheet1!CR3 -> 0.18 | I21: =G21*H21 -> 583256.74 | J21: =G21+I21 -> 3823572 | K21: =Sheet1!CU3 -> 398.5 | L21: =Sheet1!CV3 -> KMS | M21: =J21*K21 -> 1.5236934e+09 | N21: =+IFERROR(VLOOKUP($N$17,Sheet1!J3:L3,3,0),0) -> 3240 | O21: =+IFERROR(VLOOKUP($O$17,Sheet1!J3:L3,3,0),0) -> 0 | P21: =+IFERROR(VLOOKUP($P$17,Sheet1!J3:M3,3,0),0) -> 0 | Q21: =+IFERROR(VLOOKUP($Q$17,Sheet1!J3:M3,3,0),0) -> 0 | R21: =+IFERROR(VLOOKUP($R$17,Sheet1!J3:M3,3,0),0) -> 0 | S21: =+IFERROR(VLOOKUP($S$17,Sheet1!J3:M3,3,0),0) -> 0 | T21: =+IFERROR(VLOOKUP($T$17,Sheet1!J3:M3,3,0),0) -> 0 | U21: =+IFERROR(VLOOKUP($U$17,Sheet1!J3:M3,3,0),0) -> 0 | V21: =+IFERROR(VLOOKUP($V$17,Sheet1!N3:Q3,3,0),0) -> 0 | W21: =+IFERROR(VLOOKUP($W$17,Sheet1!N3:Q3,3,0),0) -> 0 | X21: 410 | Y21: =+IFERROR(VLOOKUP($Y$17,Sheet1!F3:I3,3,0),0) -> 0 | Z21: =+IFERROR(VLOOKUP($Z$17,Sheet1!F3:I3,3,0),0) -> 0 | AA21: =+IFERROR(VLOOKUP($AA$17,Sheet1!F3:I3,3,0),0) -> 0 | AB21: =+IFERROR(VLOOKUP($AB$17,Sheet1!F3:I3,3,0),0) -> 0 | AC21: =+IFERROR(VLOOKUP($AC$17,Sheet1!F3:I3,3,0),0) -> 0 | AD21: =+IFERROR(VLOOKUP($AD$17,Sheet1!F3:I3,3,0),0) -> 0 | AE21: =+IFERROR(VLOOKUP($AE$17,Sheet1!F3:I3,3,0),0) -> 0 | AF21: =+IFERROR(VLOOKUP($AF$17,Sheet1!R3:U3,3,0),0) -> 0 | AG21: 430 | AH21: =+IFERROR(VLOOKUP($AH$17,Sheet1!V3:Y3,3,0),0) -> 0 | AI21: =+IFERROR(VLOOKUP($AI$17,Sheet1!V3:Y3,3,0),0) -> 0 | AJ21: 930 | AK21: =+IFERROR(VLOOKUP($AK$17,Sheet1!V3:Y3,3,0),0) -> 0 | AL21: =+IFERROR(VLOOKUP($AL$17,Sheet1!V3:Y3,3,0),0) -> 0 | AM21: =+IFERROR(VLOOKUP($AM$17,Sheet1!V3:Y3,3,0),0) -> 0 | AN21: =+IFERROR(VLOOKUP($AN$17,Sheet1!V3:Y3,3,0),0) -> 0 | AO21: =+IFERROR(VLOOKUP($AO$17,Sheet1!V3:Y3,3,0),0) -> 0 | AP21: =+IFERROR(VLOOKUP($AP$17,Sheet1!V3:Y3,3,0),0) -> 0 | AQ21: =+IFERROR(VLOOKUP($AQ$17,Sheet1!Z3:AB3,3,0),0) -> 0 | AR21: =+IFERROR(VLOOKUP($AR$17,Sheet1!AD3:AG3,3,0),0) -> 0 | AS21: =+IFERROR(VLOOKUP($AS$17,Sheet1!AD3:AG3,3,0),0) -> 0 | AT21: =+IFERROR(VLOOKUP($AT$17,Sheet1!AD3:AG3,3,0),0) -> 0 | AU21: =+IFERROR(VLOOKUP($AU$17,Sheet1!AD3:AG3,3,0),0) -> 0 | AV21: =+IFERROR(VLOOKUP($AV$17,Sheet1!AD3:AG3,3,0),0) -> 0 | AW21: =+IFERROR(VLOOKUP($AW$17,Sheet1!AD3:AG3,3,0),0) -> 0 | AX21: 975 | AY21: =+IFERROR(VLOOKUP($AY$17,Sheet1!AD3:AG3,3,0),0) -> 0 | AZ21: =+IFERROR(VLOOKUP($AZ$17,Sheet1!AD3:AG3,3,0),0) -> 0 | BA21: =+IFERROR(VLOOKUP($BA$17,Sheet1!AH3:AK3,3,0),0) -> 0 | BB21: =+IFERROR(VLOOKUP($BB$17,Sheet1!AH3:AK3,3,0),0) -> 0 | BC21: =+IFERROR(VLOOKUP($BC$17,Sheet1!AH3:AK3,3,0),0) -> 0 | BD21: =+IFERROR(VLOOKUP($BD$17,Sheet1!AH3:AK3,3,0),0) -> 0 | BE21: =+IFERROR(VLOOKUP($BE$17,Sheet1!AH3:AK3,3,0),0) -> 0 | BF21: =+IFERROR(VLOOKUP($BF$17,Sheet1!AH3:AK3,3,0),0) -> 0 | BG21: 1325 | BH21: =+IFERROR(VLOOKUP($BH$17,Sheet1!AH3:AK3,3,0),0) -> 0 | BI21: =+IFERROR(VLOOKUP($BI$17,Sheet1!AH3:AK3,3,0),0) -> 0 | BJ21: =+IFERROR(VLOOKUP($BJ$17,Sheet1!AH3:AK3,3,0),0) -> 0 | BK21: =+IFERROR(VLOOKUP($BK$17,Sheet1!AH3:AK3,3,0),0) -> 0 | BL21: =+IFERROR(VLOOKUP($BL$17,Sheet1!AL3:AO3,3,0),0) -> 0 | BM21: =+IFERROR(VLOOKUP($BM$17,Sheet1!AL3:AO3,3,0),0) -> 0 | BN21: =+IFERROR(VLOOKUP($BN$17,Sheet1!AL3:AO3,3,0),0) -> 0 | BO21: =+IFERROR(VLOOKUP($BO$17,Sheet1!AL3:AO3,3,0),0) -> 0 | BP21: =+IFERROR(VLOOKUP($BP$17,Sheet1!AL3:AO3,3,0),0) -> 0 | BQ21: =+IFERROR(VLOOKUP($BQ$17,Sheet1!AL3:AO3,3,0),0) -> 0 | BR21: 790 | BS21: =+IFERROR(VLOOKUP($BS$17,Sheet1!AL3:AO3,3,0),0) -> 0 | BT21: =+IFERROR(VLOOKUP($BT$17,Sheet1!AL3:AO3,3,0),0) -> 0 | BU21: =+IFERROR(VLOOKUP($BU$17,Sheet1!AL3:AO3,3,0),0) -> 0 | BV21: =+IFERROR(VLOOKUP($BV$17,Sheet1!AL3:AO3,3,0),0) -> 0 | BW21: =+IFERROR(VLOOKUP($BW$17,Sheet1!AL3:AO3,3,0),0) -> 0 | BX21: 980 | BY21: =+IFERROR(VLOOKUP($BY$17,Sheet1!AT3:AW3,3,0),0) -> 0 | BZ21: 58 | CA21: 91 | CB21: =+IFERROR(VLOOKUP($CB$17,Sheet1!BF3:BI3,3,0),0) -> 0 | CC21: =+IFERROR(VLOOKUP($CC$17,Sheet1!BJ3:BM3,3,0),0) -> 0 | CD21: =+IFERROR(VLOOKUP($CD$17,Sheet1!BN3:BQ3,3,0),0) -> 0 | CE21: 128 | CF21: =+IFERROR(VLOOKUP($CF$17,Sheet1!BV3:BY3,3,0),0) -> 0 | CG21: =Sheet1!E3 -> STEEL | CH21: SP0400136 | CI21: CORRUGATED DISPATCH STEEL DRUM 2200 X 1300 X 1200 MM | CJ21: 300 | CK21: =26000/0.3 -> 86666.667 | CL21: =SUMPRODUCT($N$18:$CF$18,N21:CF21)+CK21 -> 2169246.7 | CM21: =Sheet1!CB3 -> 0 | CN21: =CL21*CM21 -> 0 | CO21: 0.4 | CP21: =CL21*CO21 -> 867698.67 | CQ21: 0 | CR21: =CL21*CQ21 -> 0 | CS21: =CL21+CN21+CP21+CR21 -> 3036945.3 | CT21: 0.03 | CU21: =CS21*CT21 -> 91108.36 | CV21: 0.01 | CW21: =CS21*CV21 -> 30369.453 | CX21: =Sheet1!CM3 -> 0 | CY21: =CX21*CS21 -> 0
A22: =Sheet1!A6 -> ENQ-17670-25-26 | B22: 45958 | C22: =Sheet1!C6 -> FA1300066 | D22: =Sheet1!D6 -> 1 CORE X 1000 SQ. MM. AL/ARM (XLPE) - 11 KV | E22: =CS22+CU22+CW22+CY22 -> 2262251.3 | F22: =ROUNDUP(M31,2) -> 51760.57 | G22: =E22+F22 -> 2314011.8 | H22: =Sheet1!CR6 -> 0.18 | I22: =G22*H22 -> 416522.13 | J22: =G22+I22 -> 2730534 | K22: =Sheet1!CU6 -> 14.2 | L22: =Sheet1!CV6 -> KMS | M22: =J22*K22 -> 38773582 | N22: =+IFERROR(VLOOKUP($N$17,Sheet1!J6:L6,3,0),0) -> 2732 | O22: =+IFERROR(VLOOKUP($O$17,Sheet1!J6:L6,3,0),0) -> 0 | P22: =+IFERROR(VLOOKUP($P$17,Sheet1!J6:M6,3,0),0) -> 0 | Q22: =+IFERROR(VLOOKUP($Q$17,Sheet1!J6:M6,3,0),0) -> 0 | R22: =+IFERROR(VLOOKUP($R$17,Sheet1!J6:M6,3,0),0) -> 0 | S22: =+IFERROR(VLOOKUP($S$17,Sheet1!J6:M6,3,0),0) -> 0 | T22: =+IFERROR(VLOOKUP($T$17,Sheet1!J6:M6,3,0),0) -> 0 | U22: =+IFERROR(VLOOKUP($U$17,Sheet1!J6:M6,3,0),0) -> 0 | V22: =+IFERROR(VLOOKUP($V$17,Sheet1!N6:Q6,3,0),0) -> 0 | W22: =+IFERROR(VLOOKUP($W$17,Sheet1!N6:Q6,3,0),0) -> 0 | X22: 199 | Y22: =+IFERROR(VLOOKUP($Y$17,Sheet1!F6:I6,3,0),0) -> 0 | Z22: =+IFERROR(VLOOKUP($Z$17,Sheet1!F6:I6,3,0),0) -> 0 | AA22: =+IFERROR(VLOOKUP($AA$17,Sheet1!F6:I6,3,0),0) -> 0 | AB22: =+IFERROR(VLOOKUP($AB$17,Sheet1!F6:I6,3,0),0) -> 0 | AC22: =+IFERROR(VLOOKUP($AC$17,Sheet1!F6:I6,3,0),0) -> 0 | AD22: =+IFERROR(VLOOKUP($AD$17,Sheet1!F6:I6,3,0),0) -> 0 | AE22: =+IFERROR(VLOOKUP($AE$17,Sheet1!F6:I6,3,0),0) -> 0 | AF22: =+IFERROR(VLOOKUP($AF$17,Sheet1!R6:U6,3,0),0) -> 0 | AG22: 236 | AH22: =+IFERROR(VLOOKUP($AH$17,Sheet1!V6:Y6,3,0),0) -> 0 | AI22: =+IFERROR(VLOOKUP($AI$17,Sheet1!V6:Y6,3,0),0) -> 0 | AJ22: 480 | AK22: =+IFERROR(VLOOKUP($AK$17,Sheet1!V6:Y6,3,0),0) -> 0 | AL22: =+IFERROR(VLOOKUP($AL$17,Sheet1!V6:Y6,3,0),0) -> 0 | AM22: =+IFERROR(VLOOKUP($AM$17,Sheet1!V6:Y6,3,0),0) -> 0 | AN22: =+IFERROR(VLOOKUP($AN$17,Sheet1!V6:Y6,3,0),0) -> 0 | AO22: =+IFERROR(VLOOKUP($AO$17,Sheet1!V6:Y6,3,0),0) -> 0 | AP22: =+IFERROR(VLOOKUP($AP$17,Sheet1!V6:Y6,3,0),0) -> 0 | AQ22: 15 | AR22: =+IFERROR(VLOOKUP($AR$17,Sheet1!AD6:AG6,3,0),0) -> 0 | AS22: =+IFERROR(VLOOKUP($AS$17,Sheet1!AD6:AG6,3,0),0) -> 0 | AT22: =+IFERROR(VLOOKUP($AT$17,Sheet1!AD6:AG6,3,0),0) -> 0 | AU22: =+IFERROR(VLOOKUP($AU$17,Sheet1!AD6:AG6,3,0),0) -> 0 | AV22: =+IFERROR(VLOOKUP($AV$17,Sheet1!AD6:AG6,3,0),0) -> 0 | AW22: =+IFERROR(VLOOKUP($AW$17,Sheet1!AD6:AG6,3,0),0) -> 0 | AX22: 205 | AY22: =+IFERROR(VLOOKUP($AY$17,Sheet1!AD6:AG6,3,0),0) -> 0 | AZ22: =+IFERROR(VLOOKUP($AZ$17,Sheet1!AD6:AG6,3,0),0) -> 0 | BA22: =+IFERROR(VLOOKUP($BA$17,Sheet1!AH6:AK6,3,0),0) -> 0 | BB22: =+IFERROR(VLOOKUP($BB$17,Sheet1!AH6:AK6,3,0),0) -> 0 | BC22: =+IFERROR(VLOOKUP($BC$17,Sheet1!AH6:AK6,3,0),0) -> 0 | BD22: 814 | BE22: =+IFERROR(VLOOKUP($BE$17,Sheet1!AH6:AK6,3,0),0) -> 0 | BF22: =+IFERROR(VLOOKUP($BF$17,Sheet1!AH6:AK6,3,0),0) -> 0 | BG22: =+IFERROR(VLOOKUP($BG$17,Sheet1!AH6:AK6,3,0),0) -> 0 | BH22: =+IFERROR(VLOOKUP($BH$17,Sheet1!AH6:AK6,3,0),0) -> 0 | BI22: =+IFERROR(VLOOKUP($BI$17,Sheet1!AH6:AK6,3,0),0) -> 0 | BJ22: =+IFERROR(VLOOKUP($BJ$17,Sheet1!AH6:AK6,3,0),0) -> 0 | BK22: =+IFERROR(VLOOKUP($BK$17,Sheet1!AH6:AK6,3,0),0) -> 0 | BL22: =+IFERROR(VLOOKUP($BL$17,Sheet1!AL6:AO6,3,0),0) -> 0 | BM22: =+IFERROR(VLOOKUP($BM$17,Sheet1!AL6:AO6,3,0),0) -> 0 | BN22: =+IFERROR(VLOOKUP($BN$17,Sheet1!AL6:AO6,3,0),0) -> 0 | BO22: =+IFERROR(VLOOKUP($BO$17,Sheet1!AL6:AO6,3,0),0) -> 0 | BP22: =+IFERROR(VLOOKUP($BP$17,Sheet1!AL6:AO6,3,0),0) -> 0 | BQ22: =+IFERROR(VLOOKUP($BQ$17,Sheet1!AL6:AO6,3,0),0) -> 0 | BR22: =+IFERROR(VLOOKUP($BR$17,Sheet1!AL6:AO6,3,0),0) -> 0 | BS22: =+IFERROR(VLOOKUP($BS$17,Sheet1!AL6:AO6,3,0),0) -> 0 | BT22: 706 | BU22: =+IFERROR(VLOOKUP($BU$17,Sheet1!AL6:AO6,3,0),0) -> 0 | BV22: =+IFERROR(VLOOKUP($BV$17,Sheet1!AL6:AO6,3,0),0) -> 0 | BW22: =+IFERROR(VLOOKUP($BW$17,Sheet1!AL6:AO6,3,0),0) -> 0 | BX22: =+IFERROR(VLOOKUP($BX$17,Sheet1!AP6:AS6,3,0),0) -> 0 | BY22: =+IFERROR(VLOOKUP($BY$17,Sheet1!AT6:AW6,3,0),0) -> 0 | BZ22: 39 | CA22: 65 | CB22: =+IFERROR(VLOOKUP($CB$17,Sheet1!BF6:BI6,3,0),0) -> 0 | CC22: =+IFERROR(VLOOKUP($CC$17,Sheet1!BJ6:BM6,3,0),0) -> 0 | CD22: =+IFERROR(VLOOKUP($CD$17,Sheet1!BN6:BQ6,3,0),0) -> 0 | CE22: 48 | CF22: =+IFERROR(VLOOKUP($CF$17,Sheet1!BV6:BY6,3,0),0) -> 0 | CG22: =Sheet1!E6 -> STEEL | CH22: SP0400107 | CI22: CORRUGATED DISPATCH STEEL DRUM 2150 X 1080 X 1240 MM | CJ22: 500 | CK22: =22750/0.5 -> 45500 | CL22: =SUMPRODUCT($N$18:$CF$18,N22:CF22)+CK22 -> 1553744 | CM22: =Sheet1!CB6 -> 0 | CN22: =CL22*CM22 -> 0 | CO22: 0.4 | CP22: =CL22*CO22 -> 621497.6 | CQ22: 0 | CR22: =CL22*CQ22 -> 0 | CS22: =CL22+CN22+CP22+CR22 -> 2175241.6 | CT22: 0.03 | CU22: =CS22*CT22 -> 65257.248 | CV22: 0.01 | CW22: =CS22*CV22 -> 21752.416 | CX22: =Sheet1!CM6 -> 0 | CY22: =CX22*CS22 -> 0
A23: =Sheet1!A5 -> ENQ-17670-25-26 | B23: 45958 | C23: =Sheet1!C5 -> FA1300052 | D23: =Sheet1!D5 -> 3 CORE X 150 SQ. MM. AL/ARM - STRIP (XLPE) - 11 KV | E23: =CS23+CU23+CW23+CY23 -> 1743169.3 | F23: =ROUNDUP(M32,2) -> 51882.36 | G23: =E23+F23 -> 1795051.7 | H23: =Sheet1!CR5 -> 0.18 | I23: =G23*H23 -> 323109.3 | J23: =G23+I23 -> 2118161 | K23: =Sheet1!CU5 -> 8.5 | L23: =Sheet1!CV5 -> KMS | M23: =J23*K23 -> 18004368 | N23: =+IFERROR(VLOOKUP($N$17,Sheet1!J5:L5,3,0),0) -> 1215 | O23: =+IFERROR(VLOOKUP($O$17,Sheet1!J5:L5,3,0),0) -> 0 | P23: =+IFERROR(VLOOKUP($P$17,Sheet1!J5:M5,3,0),0) -> 0 | Q23: =+IFERROR(VLOOKUP($Q$17,Sheet1!J5:M5,3,0),0) -> 0 | R23: =+IFERROR(VLOOKUP($R$17,Sheet1!J5:M5,3,0),0) -> 0 | S23: =+IFERROR(VLOOKUP($S$17,Sheet1!J5:M5,3,0),0) -> 0 | T23: =+IFERROR(VLOOKUP($T$17,Sheet1!J5:M5,3,0),0) -> 0 | U23: =+IFERROR(VLOOKUP($U$17,Sheet1!J5:M5,3,0),0) -> 0 | V23: =+IFERROR(VLOOKUP($V$17,Sheet1!N5:Q5,3,0),0) -> 0 | W23: =+IFERROR(VLOOKUP($W$17,Sheet1!N5:Q5,3,0),0) -> 0 | X23: 303 | Y23: =+IFERROR(VLOOKUP($Y$17,Sheet1!F5:I5,3,0),0) -> 0 | Z23: =+IFERROR(VLOOKUP($Z$17,Sheet1!F5:I5,3,0),0) -> 0 | AA23: =+IFERROR(VLOOKUP($AA$17,Sheet1!F5:I5,3,0),0) -> 0 | AB23: =+IFERROR(VLOOKUP($AB$17,Sheet1!F5:I5,3,0),0) -> 0 | AC23: =+IFERROR(VLOOKUP($AC$17,Sheet1!F5:I5,3,0),0) -> 0 | AD23: =+IFERROR(VLOOKUP($AD$17,Sheet1!F5:I5,3,0),0) -> 0 | AE23: =+IFERROR(VLOOKUP($AE$17,Sheet1!F5:I5,3,0),0) -> 0 | AF23: =+IFERROR(VLOOKUP($AF$17,Sheet1!R5:U5,3,0),0) -> 0 | AG23: 296 | AH23: =+IFERROR(VLOOKUP($AH$17,Sheet1!V5:Y5,3,0),0) -> 0 | AI23: =+IFERROR(VLOOKUP($AI$17,Sheet1!V5:Y5,3,0),0) -> 0 | AJ23: 642 | AK23: =+IFERROR(VLOOKUP($AK$17,Sheet1!V5:Y5,3,0),0) -> 0 | AL23: =+IFERROR(VLOOKUP($AL$17,Sheet1!V5:Y5,3,0),0) -> 0 | AM23: =+IFERROR(VLOOKUP($AM$17,Sheet1!V5:Y5,3,0),0) -> 0 | AN23: =+IFERROR(VLOOKUP($AN$17,Sheet1!V5:Y5,3,0),0) -> 0 | AO23: =+IFERROR(VLOOKUP($AO$17,Sheet1!V5:Y5,3,0),0) -> 0 | AP23: =+IFERROR(VLOOKUP($AP$17,Sheet1!V5:Y5,3,0),0) -> 0 | AQ23: =+IFERROR(VLOOKUP($AQ$17,Sheet1!Z5:AB5,3,0),0) -> 0 | AR23: =+IFERROR(VLOOKUP($AR$17,Sheet1!AD5:AG5,3,0),0) -> 0 | AS23: =+IFERROR(VLOOKUP($AS$17,Sheet1!AD5:AG5,3,0),0) -> 0 | AT23: =+IFERROR(VLOOKUP($AT$17,Sheet1!AD5:AG5,3,0),0) -> 0 | AU23: =+IFERROR(VLOOKUP($AU$17,Sheet1!AD5:AG5,3,0),0) -> 0 | AV23: =+IFERROR(VLOOKUP($AV$17,Sheet1!AD5:AG5,3,0),0) -> 0 | AW23: =+IFERROR(VLOOKUP($AW$17,Sheet1!AD5:AG5,3,0),0) -> 0 | AX23: 574 | AY23: =+IFERROR(VLOOKUP($AY$17,Sheet1!AD5:AG5,3,0),0) -> 0 | AZ23: =+IFERROR(VLOOKUP($AZ$17,Sheet1!AD5:AG5,3,0),0) -> 0 | BA23: =+IFERROR(VLOOKUP($BA$17,Sheet1!AH5:AK5,3,0),0) -> 0 | BB23: =+IFERROR(VLOOKUP($BB$17,Sheet1!AH5:AK5,3,0),0) -> 0 | BC23: =+IFERROR(VLOOKUP($BC$17,Sheet1!AH5:AK5,3,0),0) -> 0 | BD23: =+IFERROR(VLOOKUP($BD$17,Sheet1!AH5:AK5,3,0),0) -> 0 | BE23: =+IFERROR(VLOOKUP($BE$17,Sheet1!AH5:AK5,3,0),0) -> 0 | BF23: =+IFERROR(VLOOKUP($BF$17,Sheet1!AH5:AK5,3,0),0) -> 0 | BG23: 975 | BH23: =+IFERROR(VLOOKUP($BH$17,Sheet1!AH5:AK5,3,0),0) -> 0 | BI23: =+IFERROR(VLOOKUP($BI$17,Sheet1!AH5:AK5,3,0),0) -> 0 | BJ23: =+IFERROR(VLOOKUP($BJ$17,Sheet1!AH5:AK5,3,0),0) -> 0 | BK23: =+IFERROR(VLOOKUP($BK$17,Sheet1!AH5:AK5,3,0),0) -> 0 | BL23: =+IFERROR(VLOOKUP($BL$17,Sheet1!AL5:AO5,3,0),0) -> 0 | BM23: =+IFERROR(VLOOKUP($BM$17,Sheet1!AL5:AO5,3,0),0) -> 0 | BN23: =+IFERROR(VLOOKUP($BN$17,Sheet1!AL5:AO5,3,0),0) -> 0 | BO23: =+IFERROR(VLOOKUP($BO$17,Sheet1!AL5:AO5,3,0),0) -> 0 | BP23: =+IFERROR(VLOOKUP($BP$17,Sheet1!AL5:AO5,3,0),0) -> 0 | BQ23: =+IFERROR(VLOOKUP($BQ$17,Sheet1!AL5:AO5,3,0),0) -> 0 | BR23: =+IFERROR(VLOOKUP($BR$17,Sheet1!AL5:AO5,3,0),0) -> 0 | BS23: =+IFERROR(VLOOKUP($BS$17,Sheet1!AL5:AO5,3,0),0) -> 0 | BT23: 725 | BU23: =+IFERROR(VLOOKUP($BU$17,Sheet1!AL5:AO5,3,0),0) -> 0 | BV23: =+IFERROR(VLOOKUP($BV$17,Sheet1!AL5:AO5,3,0),0) -> 0 | BW23: =+IFERROR(VLOOKUP($BW$17,Sheet1!AL5:AO5,3,0),0) -> 0 | BX23: 538 | BY23: =+IFERROR(VLOOKUP($BY$17,Sheet1!AT5:AW5,3,0),0) -> 0 | BZ23: 18 | CA23: 64 | CB23: =+IFERROR(VLOOKUP($CB$17,Sheet1!BF5:BI5,3,0),0) -> 0 | CC23: =+IFERROR(VLOOKUP($CC$17,Sheet1!BJ5:BM5,3,0),0) -> 0 | CD23: =+IFERROR(VLOOKUP($CD$17,Sheet1!BN5:BQ5,3,0),0) -> 0 | CE23: 95 | CF23: =+IFERROR(VLOOKUP($CF$17,Sheet1!BV5:BY5,3,0),0) -> 0 | CG23: STEEL | CH23: SP0400091 | CI23: CORRUGATED DISPATCH STEEL DRUM 1800 X 900 X 1000 | CJ23: 300 | CK23: =16250/0.3 -> 54166.667 | CL23: =SUMPRODUCT($N$18:$CF$18,N23:CF23)+CK23 -> 1197231.7 | CM23: =Sheet1!CB5 -> 0 | CN23: =CL23*CM23 -> 0 | CO23: 0.4 | CP23: =CL23*CO23 -> 478892.67 | CQ23: 0 | CR23: =CL23*CQ23 -> 0 | CS23: =CL23+CN23+CP23+CR23 -> 1676124.3 | CT23: 0.03 | CU23: =CS23*CT23 -> 50283.73 | CV23: 0.01 | CW23: =CS23*CV23 -> 16761.243 | CX23: =Sheet1!CM5 -> 0 | CY23: =CX23*CS23 -> 0
B24: Al & Cu price is from 28-10-2025 and rest are average of September 2025 as per tender | M24: =SUM(M19:M23) -> 1.9995025e+09 | CQ24: 0
E27: Order Quantity | F27: Stnd Length | G27: Truck type | H27: Fare of one truck | I27: No of Drum in one truck | J27: Total length in one Truck | K27: No of Truck | L27: Total Freight | M27: Freight per KM | X27: CABLE WEIGHT KG/KM | AG27: DRUM WEIGHT | AJ27: CABLE+DRUM WEIGHT | AQ27: TRAILOR WEIGHT
D28: =D19 -> 3 CORE X 400 SQ. MM. AL/ARM - STRIP (XLPE) - 33 KV | E28: =K19 -> 78 | F28: =CJ19/1000 -> 0.25 | G28: 25 MT TRAILOR | H28: 147000 | I28: 5 | J28: =F28*I28 -> 1.25 | K28: =ROUNDUP((E28/J28),0) -> 63 | L28: =H28*K28 -> 9261000 | M28: =L28/E28 -> 118730.77 | N28: =CH19 -> SP0400105 | X28: =SUM(N19:CE19) -> 13232 | AG28: 510 | AJ28: =((X28*F28)+AG28) -> 3818 | AQ28: =AJ28*I28 -> 19090
D29: =D20 -> 1 CORE X 630 SQ. MM. AL/ARM (XLPE) - 33 KV | E29: =K20 -> 7.6 | F29: =CJ20/1000 -> 0.5 | G29: 25 MT TRAILOR | H29: 147000 | I29: 6 | J29: =F29*I29 -> 3 | K29: =ROUNDUP((E29/J29),0) -> 3 | L29: =H29*K29 -> 441000 | M29: =L29/E29 -> 58026.316 | N29: =CH20 -> SP0400123 | X29: =SUM(N20:CE20) -> 5102 | AG29: 300 | AJ29: =((X29*F29)+AG29) -> 2851 | AQ29: =AJ29*I29 -> 17106
D30: =D21 -> 3 CORE X 400 SQ. MM. AL/ARM - STRIP (XLPE) - 11 KV | E30: =K21 -> 398.5 | F30: =CJ21/1000 -> 0.3 | G30: 25 MT TRAILOR | H30: 147000 | I30: 6 | J30: =F30*I30 -> 1.8 | K30: =ROUNDUP((E30/J30),0) -> 222 | L30: =H30*K30 -> 32634000 | M30: =L30/E30 -> 81892.095 | N30: =CH21 -> SP0400136 | X30: =SUM(N21:CE21) -> 9357 | AG30: 400 | AJ30: =((X30*F30)+AG30) -> 3207.1 | AQ30: =AJ30*I30 -> 19242.6
D31: =D22 -> 1 CORE X 1000 SQ. MM. AL/ARM (XLPE) - 11 KV | E31: =K22 -> 14.2 | F31: =CJ22/1000 -> 0.5 | G31: 25 MT TRAILOR | H31: 147000 | I31: 6 | J31: =F31*I31 -> 3 | K31: =ROUNDUP((E31/J31),0) -> 5 | L31: =H31*K31 -> 735000 | M31: =L31/E31 -> 51760.563 | N31: =CH22 -> SP0400107 | X31: =SUM(N22:CE22) -> 5539 | AG31: 350 | AJ31: =((X31*F31)+AG31) -> 3119.5 | AQ31: =AJ31*I31 -> 18717
D32: =D23 -> 3 CORE X 150 SQ. MM. AL/ARM - STRIP (XLPE) - 11 KV | E32: =K23 -> 8.5 | F32: =CJ23/1000 -> 0.3 | G32: 25 MT TRAILOR | H32: 147000 | I32: 10 | J32: =F32*I32 -> 3 | K32: =ROUNDUP((E32/J32),0) -> 3 | L32: =H32*K32 -> 441000 | M32: =L32/E32 -> 51882.353 | N32: =CH23 -> SP0400091 | X32: =SUM(N23:CE23) -> 5445 | AG32: 250 | AJ32: =((X32*F32)+AG32) -> 1883.5 | AQ32: =AJ32*I32 -> 18835
C35: NOTE: | D35: Consider Aluminium rate from BALCO/NALCO/HINDALCO.
D36: Consider TR-XLPE rate from DOW/BOREALIS/HANWA.
D37: Consider Semiconducting compound rate from DOW/BOREALIS/HANWA.
D38: Consider Water-swellable tape rate from LANTOR/GECA/ FREUDENBERG/SCAPA/MIRACLE/TEKSTILNA(SLOVENIA)/SNEHAM/SHENYANG/CHENGU CENTRAN /TOP TAPES
D39: Consider Conductor water blocking tape rate from LANTOR/GECA/ FREUDENBERG/SNEHAM
D40: Consider HDPE compound rate from KALPANA /KLJ/DOW/BOREALIS/HANWA.
A43: DOCKET NO. | B43: BASE DATE | C43: ITEM CODE | D43: PROPOSE ERP ITEM NAME | E43: EX-WORKS (PER MTR) | F43: FREIGHT PER MTR | G43: PRICE INCLUDING FREIGHT (PER MTR) | H43: GST % | I43: GST VALUE | J43: PRICE INCLUDING GST & FREIGHT (PER MTR) | K43: QTY | L43: Unit | M43: TOTAL PRICE OF FULL QTY (INCLUDING FRIGHT & GST)
A45: =A19 -> ENQ-17670-25-26 | B45: =B19 -> 45958 | C45: =C19 -> FA1300010 | D45: =D19 -> 3 CORE X 400 SQ. MM. AL/ARM - STRIP (XLPE) - 33 KV | E45: =ROUNDUP(E19/1000,2) -> 4233.51 | F45: =ROUNDUP(F19/1000,2) -> 118.74 | G45: =E45+F45 -> 4352.25 | H45: =H19 -> 0.18 | I45: =G45*H45 -> 783.405 | J45: =G45+I45 -> 5135.655 | K45: =K19*1000 -> 78000 | L45: MTR | M45: =J45*K45 -> 400581090 | X45: =G45*K45 -> 339475500
A46: =A20 -> ENQ-17670-25-26 | B46: =B20 -> 45958 | C46: =C20 -> FA1300027 | D46: =D20 -> 1 CORE X 630 SQ. MM. AL/ARM (XLPE) - 33 KV | E46: =ROUNDUP(E20/1000,2) -> 1999.44 | F46: =ROUNDUP(F20/1000,2) -> 58.03 | G46: =E46+F46 -> 2057.47 | H46: =H20 -> 0.18 | I46: =G46*H46 -> 370.3446 | J46: =G46+I46 -> 2427.8146 | K46: =K20*1000 -> 7600 | L46: MTR | M46: =J46*K46 -> 18451391 | X46: =G46*K46 -> 15636772
A47: =A21 -> ENQ-17670-25-26 | B47: =B21 -> 45958 | C47: =C21 -> FA1300017 | D47: =D21 -> 3 CORE X 400 SQ. MM. AL/ARM - STRIP (XLPE) - 11 KV | E47: =ROUNDUP(E21/1000,2) -> 3158.43 | F47: =ROUNDUP(F21/1000,2) -> 81.9 | G47: =E47+F47 -> 3240.33 | H47: =H21 -> 0.18 | I47: =G47*H47 -> 583.2594 | J47: =G47+I47 -> 3823.5894 | K47: =K21*1000 -> 398500 | L47: MTR | M47: =J47*K47 -> 1.5237004e+09 | X47: =G47*K47 -> 1.2912715e+09
A48: =A22 -> ENQ-17670-25-26 | B48: =B22 -> 45958 | C48: =C22 -> FA1300066 | D48: =D22 -> 1 CORE X 1000 SQ. MM. AL/ARM (XLPE) - 11 KV | E48: =ROUNDUP(E22/1000,2) -> 2262.26 | F48: =ROUNDUP(F22/1000,2) -> 51.77 | G48: =E48+F48 -> 2314.03 | H48: =H22 -> 0.18 | I48: =G48*H48 -> 416.5254 | J48: =G48+I48 -> 2730.5554 | K48: =K22*1000 -> 14200 | L48: MTR | M48: =J48*K48 -> 38773887 | X48: =G48*K48 -> 32859226
A49: =A23 -> ENQ-17670-25-26 | B49: =B23 -> 45958 | C49: =C23 -> FA1300052 | D49: =D23 -> 3 CORE X 150 SQ. MM. AL/ARM - STRIP (XLPE) - 11 KV | E49: =ROUNDUP(E23/1000,2) -> 1743.17 | F49: =ROUNDUP(F23/1000,2) -> 51.89 | G49: =E49+F49 -> 1795.06 | H49: =H23 -> 0.18 | I49: =G49*H49 -> 323.1108 | J49: =G49+I49 -> 2118.1708 | K49: =K23*1000 -> 8500 | L49: MTR | M49: =J49*K49 -> 18004452 | X49: =G49*K49 -> 15258010
B50: Al & Cu price is from 28-10-2025 and rest are average of September 2025 as per tender | M50: =SUM(M45:M49) -> 1.9995112e+09 | X50: =SUM(X45:X49) -> 1.694501e+09
...

Sheet PV AUTO CALCULATION
A1: Base Date | B1: Prices will be Variable as per IEEMA Price Variation Formula considering below LME Index Base. 1) Copper: …………. USD/MT (LME Closing day offer price of 28.10.2025) 2) Aluminum: …………. USD/MT (LME Closing day offer price of 28.10.2025) 3) USD to INR: ……… (USD to INR for 28.10.2025 - As per RBI website - Closing of day) 4) HDPE Polyethylene PE ST7: Rs. 1,47,250/MT (IEEMA - Sept 2025 i.e. Circular issued in Oct 2025) 5) PVC: Rs. 1,59,825/MT (IEEMA - Sept 2025 i.e. Circular issued in Oct 2025) 6) XLPE: Rs. 1,91,538/MT (IEEMA - Sept 2025 i.e. Circular issued in Oct 2025) 7) Steel: Rs. 81,250/MT (IEEMA - Sept 2025 i.e. Circular issued in Oct 2025)
A2: PV FORMULA
A3: P = Po + AIF (Al–Alo) + XLFAL (CC–Cco) + SMIF (SMIF1–SMIF0) + FeF (FeF1–FeF0) + CCFAI (PVCc–PVCco)
S6: for PE factor = factor x 0.63 as per IEEMA Circular
K7: ieema-conductor | L7: balco declared | AF7: VALUE ADDITION CALCULATION
A8: Item | B8: Calculation part | C8: Date of Inspection | D8: Applicable Date | J8: BASE DATE | P8: FACTORS | W8: Ex-Work Po | X8: PVC of al | Y8: PVC of Cu | Z8: PVC of XLPE | AA8: PVC OF PVC | AB8: PVC OF FE | AC8: PVC OF CU TAPE | AD8: PV/PKM | AE8: Billing Price/PKM
D9: Date | E9: Al | F9: Cu | G9: Cc | H9: PVCc | I9: Fe | J9: Date | K9: Alo | L9: Cuo | M9: Cco | N9: PVCco | O9: Feo | AF9: ='AUTO CALCULATION SHEET (2)'!N17 -> Alumimium | AG9: ='AUTO CALCULATION SHEET (2)'!X17 -> Coper tape -50X 0.1 mm | AH9: ='AUTO CALCULATION SHEET (2)'!AG17 -> Extruded Semiconductive(Stripable) | AI9: ='AUTO CALCULATION SHEET (2)'!AJ17 -> TR XLPE | AJ9: ='AUTO CALCULATION SHEET (2)'!AQ17 -> POLY TAPE | AK9: ='AUTO CALCULATION SHEET (2)'!AX17 -> PVC Type ST-2 | AL9: ='AUTO CALCULATION SHEET (2)'!BD17 -> Aluminium Round Wire | AM9: ='AUTO CALCULATION SHEET (2)'!BG17 -> Galvanised Steel Flat Strip | AN9: ='AUTO CALCULATION SHEET (2)'!BR17 -> PE-ST-7 | AO9: ='AUTO CALCULATION SHEET (2)'!BT17 -> PVC Type ST-2 WITH ATR | AP9: ='AUTO CALCULATION SHEET (2)'!BX17 -> PP FILLER | AQ9: ='AUTO CALCULATION SHEET (2)'!BZ17 -> NCWBT | AR9: ='AUTO CALCULATION SHEET (2)'!CA17 -> Semi conducting Water Swellable tape (min 0.3) | AS9: ='AUTO CALCULATION SHEET (2)'!CE17 -> RUBBERIZED COTTON TAPE | AT9: RMC | AU9: Drum | AV9: RMC+Drum | AW9: VA | AX9: Groos VA% | AY9: Mfg % | AZ9: Int % | BA9: Ins% | BB9: Net VA
P10: Alf | Q10: Cu | R10: XLFAL | S10: CCFAI | T10: CCFCu | U10: FeF | V10: Smif | AF10: 284 | AG10: 1145 | AH10: 175 | AI10: 215 | AJ10: 110 | AK10: 61 | AL10: 289 | AM10: 75 | AN10: 96 | AO10: =AK10+7 -> 68 | AP10: 75 | AQ10: 300 | AR10: 415 | AS10: 285
K11: 45958 | L11: 45958 | M11: average Sept'25 | N11: average Sept'25 | O11: average Sept'25 | AF11: Kg/Km | AG11: Kg/Km | AH11: Kg/Km | AI11: Kg/Km | AJ11: Kg/Km | AK11: Kg/Km | AL11: Kg/Km | AM11: Kg/Km | AN11: Kg/Km | AO11: Kg/Km | AP11: Kg/Km | AQ11: Kg/Km | AR11: Kg/Km | AS11: Kg/Km
A12: ='AUTO CALCULATION SHEET (2)'!D19 -> 3 CORE X 400 SQ. MM. AL/ARM - STRIP (XLPE) - 33 KV | C12: PROVISIONAL | D12: 45982 | E12: 288466.81 | F12: 1032675.2 | G12: 192963 | H12: 157825 | I12: 81250 | J12: 45958 | K12: 286282 | L12: 1039488 | M12: 191538 | N12: 159825 | O12: 81250 | P12: 3.374 | R12: 3.229 | S12: =5.736*0.63 -> 3.61368 | U12: 1.876 | V12: 0.164 | W12: ='AUTO CALCULATION SHEET (2)'!E45*1000 -> 4233510 | X12: =(P12*(E12-K12)) -> 7371.5489 | Y12: =(Q12*(F12-L12)) -> 0 | Z12: =(R12*(G12-M12)) -> 4601.325 | AA12: =(S12*(H12-N12)) -> -7227.36 | AB12: =(U12*(I12-O12)) -> 0 | AC12: =V12*(F12-L12) -> -1117.291 | AD12: =X12+Y12+Z12+AA12+AB12+AC12 -> 3628.2229 | AE12: =+W12+AD12 -> 4237138.2 | AF12: ='AUTO CALCULATION SHEET (2)'!N19 -> 3240 | AG12: ='AUTO CALCULATION SHEET (2)'!X19 -> 536 | AH12: ='AUTO CALCULATION SHEET (2)'!AG19 -> 506 | AI12: ='AUTO CALCULATION SHEET (2)'!AJ19 -> 2675 | AJ12: ='AUTO CALCULATION SHEET (2)'!AQ19 -> 0 | AK12: ='AUTO CALCULATION SHEET (2)'!AX19 -> 1547 | AL12: ='AUTO CALCULATION SHEET (2)'!BD19 -> 0 | AM12: ='AUTO CALCULATION SHEET (2)'!BG19 -> 1675 | AN12: ='AUTO CALCULATION SHEET (2)'!BR19 -> 1063 | AO12: ='AUTO CALCULATION SHEET (2)'!BT19 -> 0 | AP12: ='AUTO CALCULATION SHEET (2)'!BX19 -> 1660 | AQ12: ='AUTO CALCULATION SHEET (2)'!BZ19 -> 58 | AR12: ='AUTO CALCULATION SHEET (2)'!CA19 -> 108 | AS12: ='AUTO CALCULATION SHEET (2)'!CE19 -> 164 | AT12: =SUMPRODUCT(AF12:AS12,$AF$10:$AS$10) -> 2753055 | AU12: ='AUTO CALCULATION SHEET (2)'!CK19 -> 132600 | AV12: =AT12+AU12 -> 2885655 | AW12: =AE12-AV12 -> 1351483.2 | AX12: =ROUND((AW12/AV12)*100,2) -> 46.83 | AY12: 0 | AZ12: 3 | BA12: 1 | BB12: =AX12-AY12-AZ12-BA12 -> 42.83
A13: ='AUTO CALCULATION SHEET (2)'!D20 -> 1 CORE X 630 SQ. MM. AL/ARM (XLPE) - 33 KV | B13: 2.5 | C13: PROVISIONAL | D13: 45982 | E13: 288466.81 | F13: 1032675.2 | G13: 192963 | H13: 157825 | J13: 45958 | K13: 286282 | L13: 1039488 | M13: 191538 | N13: 159825 | P13: 2.978 | R13: 1.265 | S13: 1.168 | V13: 0.063 | W13: ='AUTO CALCULATION SHEET (2)'!E46*1000 -> 1999440 | X13: =(P13*(E13-K13)) -> 6506.3642 | Y13: =(Q13*(F13-L13)) -> 0 | Z13: =(R13*(G13-M13)) -> 1802.625 | AA13: =(S13*(H13-N13)) -> -2336 | AB13: =(U13*(I13-O13)) -> 0 | AC13: =V13*(F13-L13) -> -429.20325 | AD13: =X13+Y13+Z13+AA13+AB13+AC13 -> 5543.7859 | AE13: =+W13+AD13 -> 2004983.8 | AF13: ='AUTO CALCULATION SHEET (2)'!N20 -> 1701 | AG13: ='AUTO CALCULATION SHEET (2)'!X20 -> 204 | AH13: ='AUTO CALCULATION SHEET (2)'!AG20 -> 200 | AI13: ='AUTO CALCULATION SHEET (2)'!AJ20 -> 1056 | AJ13: ='AUTO CALCULATION SHEET (2)'!AQ20 -> 0 | AK13: ='AUTO CALCULATION SHEET (2)'!AX20 -> 215 | AL13: ='AUTO CALCULATION SHEET (2)'!BD20 -> 842 | AM13: ='AUTO CALCULATION SHEET (2)'!BG20 -> 0 | AN13: ='AUTO CALCULATION SHEET (2)'!BR20 -> 0 | AO13: ='AUTO CALCULATION SHEET (2)'!BT20 -> 765 | AP13: ='AUTO CALCULATION SHEET (2)'!BX20 -> 0 | AQ13: ='AUTO CALCULATION SHEET (2)'!BZ20 -> 26 | AR13: ='AUTO CALCULATION SHEET (2)'!CA20 -> 43 | AS13: ='AUTO CALCULATION SHEET (2)'!CE20 -> 50 | AT13: =SUMPRODUCT(AF13:AS13,$AF$10:$AS$10) -> 1327072 | AU13: ='AUTO CALCULATION SHEET (2)'!CK20 -> 39000 | AV13: =AT13+AU13 -> 1366072 | AW13: =AE13-AV13 -> 638911.79 | AX13: =ROUND((AW13/AV13)*100,2) -> 46.77 | AY13: 0 | AZ13: 3 | BA13: 1 | BB13: =AX13-AY13-AZ13-BA13 -> 42.77
A14: ='AUTO CALCULATION SHEET (2)'!D21 -> 3 CORE X 400 SQ. MM. AL/ARM - STRIP (XLPE) - 11 KV | C14: PROVISIONAL | D14: 45982 | E14: 288466.81 | F14: 1032675.2 | G14: 192963 | H14: 157825 | I14: 81250 | J14: 45958 | K14: 286282 | L14: 1039488 | M14: 191538 | N14: 159825 | O14: 81250 | P14: 3.374 | R14: 1.314 | S14: =3.664*0.63 -> 2.30832 | U14: 1.435 | V14: 0.124 | W14: ='AUTO CALCULATION SHEET (2)'!E47*1000 -> 3158430 | X14: =(P14*(E14-K14)) -> 7371.5489 | Y14: =(Q14*(F14-L14)) -> 0 | Z14: =(R14*(G14-M14)) -> 1872.45 | AA14: =(S14*(H14-N14)) -> -4616.64 | AB14: =(U14*(I14-O14)) -> 0 | AC14: =V14*(F14-L14) -> -844.781 | AD14: =X14+Y14+Z14+AA14+AB14+AC14 -> 3782.5779 | AE14: =+W14+AD14 -> 3162212.6 | AF14: ='AUTO CALCULATION SHEET (2)'!N21 -> 3240 | AG14: ='AUTO CALCULATION SHEET (2)'!X21 -> 410 | AH14: ='AUTO CALCULATION SHEET (2)'!AG21 -> 430 | AI14: ='AUTO CALCULATION SHEET (2)'!AJ21 -> 930 | AJ14: ='AUTO CALCULATION SHEET (2)'!AQ21 -> 0 | AK14: ='AUTO CALCULATION SHEET (2)'!AX21 -> 975 | AL14: ='AUTO CALCULATION SHEET (2)'!BD21 -> 0 | AM14: ='AUTO CALCULATION SHEET (2)'!BG21 -> 1325 | AN14: ='AUTO CALCULATION SHEET (2)'!BR21 -> 790 | AO14: ='AUTO CALCULATION SHEET (2)'!BT21 -> 0 | AP14: ='AUTO CALCULATION SHEET (2)'!BX21 -> 980 | AQ14: ='AUTO CALCULATION SHEET (2)'!BZ21 -> 58 | AR14: ='AUTO CALCULATION SHEET (2)'!CA21 -> 91 | AS14: ='AUTO CALCULATION SHEET (2)'!CE21 -> 128 | AT14: =SUMPRODUCT(AF14:AS14,$AF$10:$AS$10) -> 2064645 | AU14: ='AUTO CALCULATION SHEET (2)'!CK21 -> 86666.667 | AV14: =AT14+AU14 -> 2151311.7 | AW14: =AE14-AV14 -> 1010900.9 | AX14: =ROUND((AW14/AV14)*100,2) -> 46.99 | AY14: 0 | AZ14: 3 | BA14: 1 | BB14: =AX14-AY14-AZ14-BA14 -> 42.99
A15: ='AUTO CALCULATION SHEET (2)'!D22 -> 1 CORE X 1000 SQ. MM. AL/ARM (XLPE) - 11 KV | B15: 2.5 | C15: PROVISIONAL | D15: 45982 | E15: 288466.81 | F15: 1032675.2 | G15: 192963 | H15: 157825 | J15: 45958 | K15: 286282 | L15: 1039488 | M15: 191538 | N15: 159825 | P15: 3.749 | R15: 0.66 | S15: 1.035 | V15: 0.058 | W15: ='AUTO CALCULATION SHEET (2)'!E48*1000 -> 2262260 | X15: =(P15*(E15-K15)) -> 8190.8527 | Y15: =(Q15*(F15-L15)) -> 0 | Z15: =(R15*(G15-M15)) -> 940.5 | AA15: =(S15*(H15-N15)) -> -2070 | AB15: =(U15*(I15-O15)) -> 0 | AC15: =V15*(F15-L15) -> -395.1395 | AD15: =X15+Y15+Z15+AA15+AB15+AC15 -> 6666.2132 | AE15: =+W15+AD15 -> 2268926.2 | AF15: ='AUTO CALCULATION SHEET (2)'!N22 -> 2732 | AG15: ='AUTO CALCULATION SHEET (2)'!X22 -> 199 | AH15: ='AUTO CALCULATION SHEET (2)'!AG22 -> 236 | AI15: ='AUTO CALCULATION SHEET (2)'!AJ22 -> 480 | AJ15: ='AUTO CALCULATION SHEET (2)'!AQ22 -> 15 | AK15: ='AUTO CALCULATION SHEET (2)'!AX22 -> 205 | AL15: ='AUTO CALCULATION SHEET (2)'!BD22 -> 814 | AM15: ='AUTO CALCULATION SHEET (2)'!BG22 -> 0 | AN15: ='AUTO CALCULATION SHEET (2)'!BR22 -> 0 | AO15: ='AUTO CALCULATION SHEET (2)'!BT22 -> 706 | AP15: ='AUTO CALCULATION SHEET (2)'!BX22 -> 0 | AQ15: ='AUTO CALCULATION SHEET (2)'!BZ22 -> 39 | AR15: ='AUTO CALCULATION SHEET (2)'!CA22 -> 65 | AS15: ='AUTO CALCULATION SHEET (2)'!CE22 -> 48 | AT15: =SUMPRODUCT(AF15:AS15,$AF$10:$AS$10) -> 1498007 | AU15: ='AUTO CALCULATION SHEET (2)'!CK22 -> 45500 | AV15: =AT15+AU15 -> 1543507 | AW15: =AE15-AV15 -> 725419.21 | AX15: =ROUND((AW15/AV15)*100,2) -> 47 | AY15: 0 | AZ15: 3 | BA15: 1 | BB15: =AX15-AY15-AZ15-BA15 -> 43
A16: ='AUTO CALCULATION SHEET (2)'!D23 -> 3 CORE X 150 SQ. MM. AL/ARM - STRIP (XLPE) - 11 KV | C16: PROVISIONAL | D16: 45982 | E16: 288466.81 | F16: 1032675.2 | G16: 192963 | H16: 157825 | I16: 81250 | J16: 45958 | K16: 286282 | L16: 1039488 | M16: 191538 | N16: 159825 | O16: 81250 | P16: 1.279 | R16: 0.89 | S16: 2.061 | U16: 1.055 | V16: 0.088 | W16: ='AUTO CALCULATION SHEET (2)'!E49*1000 -> 1743170 | X16: =(P16*(E16-K16)) -> 2794.372 | Y16: =(Q16*(F16-L16)) -> 0 | Z16: =(R16*(G16-M16)) -> 1268.25 | AA16: =(S16*(H16-N16)) -> -4122 | AB16: =(U16*(I16-O16)) -> 0 | AC16: =V16*(F16-L16) -> -599.522 | AD16: =X16+Y16+Z16+AA16+AB16+AC16 -> -658.90001 | AE16: =+W16+AD16 -> 1742511.1 | AF16: ='AUTO CALCULATION SHEET (2)'!N23 -> 1215 | AG16: ='AUTO CALCULATION SHEET (2)'!X23 -> 303 | AH16: ='AUTO CALCULATION SHEET (2)'!AG23 -> 296 | AI16: ='AUTO CALCULATION SHEET (2)'!AJ23 -> 642 | AJ16: ='AUTO CALCULATION SHEET (2)'!AQ23 -> 0 | AK16: ='AUTO CALCULATION SHEET (2)'!AX23 -> 574 | AL16: ='AUTO CALCULATION SHEET (2)'!BD23 -> 0 | AM16: ='AUTO CALCULATION SHEET (2)'!BG23 -> 975 | AN16: ='AUTO CALCULATION SHEET (2)'!BR23 -> 0 | AO16: ='AUTO CALCULATION SHEET (2)'!BT23 -> 725 | AP16: ='AUTO CALCULATION SHEET (2)'!BX23 -> 538 | AQ16: ='AUTO CALCULATION SHEET (2)'!BZ23 -> 18 | AR16: ='AUTO CALCULATION SHEET (2)'!CA23 -> 64 | AS16: ='AUTO CALCULATION SHEET (2)'!CE23 -> 95 | AT16: =SUMPRODUCT(AF16:AS16,$AF$10:$AS$10) -> 1138649 | AU16: ='AUTO CALCULATION SHEET (2)'!CK23 -> 54166.667 | AV16: =AT16+AU16 -> 1192815.7 | AW16: =AE16-AV16 -> 549695.43 | AX16: =ROUND((AW16/AV16)*100,2) -> 46.08 | AY16: 0 | AZ16: 3 | BA16: 1 | BB16: =AX16-AY16-AZ16-BA16 -> 42.08

Sheet terms
A1: The quoted prices are on Firm inclusive of packing and forwading but exclusive of GST Statutory levies.
A2: The quoted prices are on VARIABLE basis with PV base Date: DD/MM/YYYY as per "IEEMA", inclusive of packing and forwading but exclusive of GST Statutory levies.
A4: The above prices are quoted on Ex-works basis, where freight will be charged extra.
A5: The above prices are quoted on FOR Destination basis, where freight is included, refer Price offer.
A6: The above prices are quoted on Ex-works+Freight basis.
A8: 20% Advance and Balance against PI (Proforma Invoice) prior to dispatch
A9: 100% against "90 days" LC, where 90 days usance interest will be borne by LPIPL
A10: 100% against "120 days" LC, where 120 days usance interest will be borne by LPIPL
A11: 100% against "45 days" LC, where 45 days usance interest will be borne by LPIPL
A12: 100% against "60 days" LC, where 60 days usance interest will be borne by LPIPL
A13: 100% against "30 days" LC, where 30 days usance interest will be borne by LPIPL
A14: 100% against 60 days PDC from the date of MRC/MRN
... A27: Negotiable
