Workbook

Sheet Sheet1
A1: DOCKET NO. | B1: Base Date | C1: ITEM CODE | D1: PROPOSE ERP ITEM NAME | E1: Propose Drum Type | F1: Insulation Screening(Metallic) | G1: RM Rate(Insulation Screening(Metallic)) | H1: Weight (Insulation Screening (Metallic)) | I1: Cost Insulation Screening(Metallic) | J1: Conductor | K1: RM Rate(Conductor) | L1: Weight(Conductor) | M1: Cost(Conductor) | N1: AL ALLOY | O1: RM Rate(AL Alloy) | P1: Weight(Al Alloy) | Q1: Cost(AL Alloy) | R1: Insulation Screening(Non-Metallic) | S1: RM Rate(Insulation Screening(Non-Metallic)) | T1: Weight(Insulation Screening(Non-Metallic) | U1: Cost(Insulation Screening(Non-Metallic) | V1: Insulation | W1: RM Rate(Insulation) | X1: Weight(Insulation) | Y1: Cost(Insulation) | Z1: Poly Tape | AA1: RM Rate(Poly Tape) | AB1: Weight(Poly Tape) | AC1: Cost(Poly Tape) | AD1: Inner Sheath | AE1: RM Rate(Inner Sheath) | AF1: Weight(Inner Sheath) | AG1: Cost(Inner Sheath) | AH1: Armouring | AI1: RM Rate(Armouring) | AJ1: Weight(Armouring) | AK1: Cost(Armouring) | AL1: Outer Sheath | AM1: RM Rate(Outer Sheath) | AN1: Weight(Outer Sheath) | AO1: Cost(Outer Sheath) | AP1: Filler | AQ1: RM Rate(Filler) | AR1: Weight(Filler) | AS1: Cost(Filler) | AT1: Grease | AU1: RM Rate(Grease) | AV1: Weight(Grease) | AW1: Cost(Grease) | AX1: Water Swellable Tape | AY1: RM Rate(Water Swellable Tape) | AZ1: Weight(Water Swellable Tape) | BA1: Cost(Water Swellable Tape) | BB1: Semi Conducting Water Swellable Tape | BC1: RM Rate(Semi Conducting Water Swellable Tape) | BD1: Weight(Semi Conducting Water Swellable Tape) | BE1: Cost(Semi Conducting Water Swellable Tape) | BF1: Semicon Tape | BG1: RM Rate(Semicon Tape) | BH1: Weight(Semicon Tape) | BI1: Cost(Semicon Tape) | BJ1: Glass Fiber Tape | BK1: RM Rate(Glass Fiber Tape) | BL1: Weight(Glass Fiber Tape) | BM1: Cost(Glass Fiber Tape) | BN1: Copper Wire 0.8MM | BO1: RM Rate(Copper Wire 0.8MM) | BP1: Weight(Copper Wire 0.8MM) | BQ1: Cost(Copper Wire 0.8MM) | BR1: Rubberized Cotton Tape | BS1: RM Rate(Rubberized Cotton Tape) | BT1: Weight(Rubberized Cotton Tape) | BU1: Cost(Rubberized Cotton Tape) | BV1: Water Tight Compound | BW1: RM Rate(Water Tight Compound) | BX1: Weight(Water Tight Compound) | BY1: Cost(Water Tight Compound) | BZ1: Drum Cost Per KM | CA1: Total RM Cost | CB1: FIRM % | CC1: Firm Value | CD1: MFG% | CE1: MFG Value | CF1: PROF% | CG1: Profit Value | CH1: 1st EX-Works | CI1: Intt % | CJ1: Intt Value | CK1: insp% | CL1: Insp Value | CM1: EX-Works Per KM | CN1: Freight Per KM | CO1: Price Including Freight Per KM | CP1: GST % | CQ1: GST Value | CR1: Price Including GST & Freight Per KM | CS1: QTY | CT1: Unit | CU1: Total Price Of Full QTY(Including Freight&GST) | CV1: DRUM CODE | CW1: DRUM SIZE (FxbXtx Ft) | CX1: Party Standard Length(MTR)
A2: ENQ-14722-22-23 | B2: 45637 | C2: FA1300080 | D2: 3 CORE X 400 SQ. MM AL/ARM - WIRE (XLPE) - 33 KV | E2: STEEL | F2: Copper Tape - 0.045 mm | G2: 927.72 | H2: 179 | I2: 166061.88 | J2: Alumimium | K2: 257 | L2: 3240 | M2: 832680 | P2: 0 | R2: Extruded Semiconductive | S2: 180 | T2: 427 | U2: 76860 | V2: HT-XLPE | W2: 140 | X2: 2621 | Y2: 366940 | AB2: 0 | AD2: PVC Type ST-2-PRESSURE EXTRUDED | AE2: 88 | AF2: 405 | AG2: 35640 | AH2: Galvanised Steel Round Wire | AI2: 90.7 | AJ2: 6975 | AK2: 632632.5 | AL2: FRLSH PVC Type ST-2 | AM2: 90 | AN2: 1660 | AO2: 149400 | AP2: Polypropylene Filler | AR2: 2672 | AV2: 0 | AX2: Water swellable Tape | AY2: 420 | AZ2: 120 | BA2: 50400 | BB2: Semi conducting Water Swellable tape | BC2: 400 | BD2: 0 | BE2: 0 | BH2: 144 | BL2: 0 | BP2: 0 | BR2: RUBBERIZED COTTON TAPE | BS2: 375 | BT2: 0 | BU2: 0 | BX2: 0 | BZ2: 190000 | CA2: 2500614.4 | CH2: 2500614.4 | CM2: 2500614.4 | CO2: 2500614.4 | CP2: 0.18 | CQ2: 450110.59 | CR2: 2950725 | CS2: 17 | CT2: KMS | CU2: 50162324 | CV2: SP0400137 | CW2: CORRUGATED DISPATCH STEEL DRUM 2600 X 1600 X 1600 MM | CX2: 250
A3: ENQ-14722-22-23 | B3: 45637 | C3: FA1300083 | D3: 3 CORE X 400 SQ. MM. AL/ARM - WIRE (XLPE) - 11 KV | E3: STEEL | F3: Copper Tape - 0.045 mm | G3: 927.72 | H3: 136 | I3: 126169.92 | J3: Alumimium | K3: 257 | L3: 3240 | M3: 832680 | P3: 0 | R3: Extruded Semiconductive | S3: 180 | T3: 366 | U3: 65880 | V3: HT-XLPE | W3: 140 | X3: 908 | Y3: 127120 | AB3: 0 | AD3: PVC Type ST-2-PRESSURE EXTRUDED | AE3: 88 | AF3: 305 | AG3: 26840 | AH3: Galvanised Steel Round Wire | AI3: 90.7 | AJ3: 5335 | AK3: 483884.5 | AL3: FRLSH PVC Type ST-2 | AM3: 90 | AN3: 1308 | AO3: 117720 | AP3: Polypropylene Filler | AR3: 1535 | AV3: 0 | AX3: Water swellable Tape | AY3: 420 | AZ3: 0 | BA3: 0 | BB3: Semi conducting Water Swellable tape | BC3: 400 | BD3: 64 | BE3: 25600 | BH3: 0 | BL3: 0 | BP3: 0 | BR3: RUBBERIZED COTTON TAPE | BS3: 375 | BT3: 0 | BU3: 0 | BX3: 0 | BZ3: 182400 | CA3: 1988294.4 | CH3: 1988294.4 | CM3: 1988294.4 | CO3: 1988294.4 | CP3: 0.18 | CQ3: 357893 | CR3: 2346187.4 | CS3: 12 | CT3: KMS | CU3: 28154249 | CV3: SP0400105 | CW3: CORRUGATED DISPATCH STEEL DRUM 2500 X 1500 X 1400 | CX3: 250
A4: ENQ-14722-22-23 | B4: 45637 | C4: FA1300200 | D4: 3 CORE X 95 SQ. MM. AL/ARM WIRE (XLPE) - 33 KV | E4: STEEL | F4: Copper Tape - 0.045 mm | G4: 927.72 | H4: 129 | I4: 119675.88 | J4: Alumimium | K4: 257 | L4: 770 | M4: 197890 | P4: 0 | R4: Extruded Semiconductive | S4: 180 | T4: 265 | U4: 47700 | V4: HT-XLPE | W4: 140 | X4: 1670 | Y4: 233800 | AB4: 0 | AD4: PVC Type ST-2-PRESSURE EXTRUDED | AE4: 88 | AF4: 292 | AG4: 25696 | AH4: Galvanised Steel Round Wire | AI4: 90.7 | AJ4: 3945 | AK4: 357811.5 | AL4: FRLSH PVC Type ST-2 | AM4: 90 | AN4: 1228 | AO4: 110520 | AP4: Polypropylene Filler | AR4: 1389 | AV4: 0 | AX4: Water swellable Tape | AY4: 420 | AZ4: 0 | BA4: 0 | BB4: Semi conducting Water Swellable tape | BC4: 400 | BD4: 0 | BE4: 0 | BH4: 0 | BL4: 0 | BP4: 0 | BR4: RUBBERIZED COTTON TAPE | BS4: 375 | BT4: 0 | BU4: 0 | BX4: 0 | BZ4: 147200 | CA4: 1240293.4 | CH4: 1240293.4 | CM4: 1240293.4 | CO4: 1240293.4 | CP4: 0.18 | CQ4: 223252.81 | CR4: 1463546.2 | CS4: 2.5 | CT4: KMS | CU4: 3658865 | CV4: SP0400136 | CW4: CORRUGATED DISPATCH STEEL DRUM 2200 X 1300 X 1200 MM | CX4: 250
A5: ENQ-14722-22-23 | B5: 45637 | C5: FA1300027 | D5: 1 CORE X 630 SQ. MM. AL/ARM (XLPE) - 33 KV | E5: STEEL | F5: Copper Tape - 0.045 mm | G5: 927.72 | H5: 69 | I5: 64012.68 | J5: Alumimium | K5: 257 | L5: 1701 | M5: 437157 | P5: 0 | R5: Extruded Semiconductive | S5: 180 | T5: 172 | U5: 30960 | V5: HT-XLPE | W5: 140 | X5: 1040 | Y5: 145600 | Z5: POLY TAPE | AA5: 124 | AB5: 0 | AC5: 0 | AD5: PVC Type ST-2 | AE5: 69.29 | AF5: 193 | AG5: 13372.97 | AH5: Aluminium Round Wire | AI5: 262 | AJ5: 800 | AK5: 209600 | AL5: FRLSH PVC Type ST-2 | AM5: 90 | AN5: 738 | AO5: 66420 | AR5: 0 | AV5: 0 | AX5: Water swellable Tape | AY5: 420 | AZ5: 0 | BA5: 0 | BB5: Semi conducting Water Swellable tape | BC5: 400 | BD5: 0 | BE5: 0 | BH5: 0 | BL5: 0 | BP5: 0 | BR5: RUBBERIZED COTTON TAPE | BS5: 375 | BT5: 0 | BU5: 0 | BX5: 0 | BZ5: 53200 | CA5: 1020322.7 | CH5: 1020322.7 | CM5: 1020322.7 | CO5: 1020322.7 | CP5: 0.18 | CQ5: 183658.08 | CR5: 1203980.7 | CS5: 238.5 | CT5: KMS | CU5: 287149403 | CV5: SP0400123 | CW5: CORRUGATED DISPATCH STEEL DRUM 2000 X 1000 X 1200 MM | CX5: 500
A6: ENQ-14722-22-23 | B6: 45637 | C6: FA1300018 | D6: 1 CORE X 400 SQ. MM. AL/ARM (XLPE) - 33 KV | E6: STEEL | F6: Copper Tape - 0.045 mm | G6: 927.72 | H6: 60 | I6: 55663.2 | J6: Alumimium | K6: 257 | L6: 1080 | M6: 277560 | P6: 0 | R6: Extruded Semiconductive | S6: 180 | T6: 141 | U6: 25380 | V6: HT-XLPE | W6: 140 | X6: 870 | Y6: 121800 | Z6: POLY TAPE | AA6: 124 | AB6: 0 | AC6: 0 | AD6: PVC Type ST-2 | AE6: 69.29 | AF6: 147 | AG6: 10185.63 | AH6: Aluminium Round Wire | AI6: 262 | AJ6: 702 | AK6: 183924 | AL6: FRLSH PVC Type ST-2 | AM6: 90 | AN6: 575 | AO6: 51750 | AR6: 0 | AV6: 0 | AX6: Water swellable Tape | AY6: 420 | AZ6: 54 | BA6: 22680 | BB6: Semi conducting Water Swellable tape | BC6: 400 | BD6: 0 | BE6: 0 | BH6: 52 | BL6: 0 | BP6: 0 | BR6: RUBBERIZED COTTON TAPE | BS6: 375 | BT6: 0 | BU6: 0 | BX6: 0 | BZ6: 53200 | CA6: 802142.83 | CH6: 802142.83 | CM6: 802142.83 | CO6: 802142.83 | CP6: 0.18 | CQ6: 144385.71 | CR6: 946528.54 | CS6: 5.22 | CT6: KMS | CU6: 4940879 | CV6: SP0400112 | CW6: CORRUGATED DISPATCH STEEL DRUM 2000 X 1000 X 1000 MM | CX6: 500

Sheet AUTO CALCULATION SHEET (2)
A2: TPCODL TPNODL TPSODL TPWODL (TATA Power and Odisha Government Joint Venture)
A4: TENDER SPECIFICATION NO () | B4: TPCODL/CCG/FY24-25/1000001519
A5: TENDER DESCRIPTION () | B5: Open Tender Notification For Purchase Order for supply of HT Cables at TPCODL
A6: Last Date & Time of Submission () | B6: 16.12.2024 [16:00 hrs]
A7: REVERSE AUCTION | B7: No of bidders allowed to participate in RA process shall be: Total No of bidders on whom tender would be split PLUS 2 more bidders Illustrative example: Total no of qualified bidders is 10 & tender needs to split amongst 4 bidders. PLUS 2 means (04 + 02 = 06) means lowest 6 bidders i.e., L1 to L6 bidders would be allowed in the RA process. Balance, H1 to H4 bidders would not be allowed in the RA process.
A8: Price () | B8: Prices shall be FIRM till completion of entire supplies.
A9: Validity () | B9: Bids shall remain valid for 180 days from the due date of submission of the bid.
A10: Delivery Period () | B10: Delivery shall be completed within 60 days from date of receipt of Purchase Order / CAT-A issuance, whichever is later. Considering the urgencies of prestigious Govt. project, best efforts is to be made by supplier to start staggered deliveries as per mutual agreement between BA & TPCODL, at the earliest post order/CAT A issuance.
A11: Payment Terms () | B11: 100% payment shall be released as per GCC within 30 days of submission of certified error-free Invoice complete in all respects.
A12: Standard length () | B12: The cable shall be supplied in continuous standard length of 250 (3 cores) & 500 (Single core) running meters with +/- 5% tolerance.
A13: Packing () | B13: Steel drums shall be provided. Drum shall be free from sharp edges and visual defect. Stencil plate on one flange side of the drum and laminated paper sheet on other side flange of drum.
A14: Technical Specification
N16: =Sheet1!J1 -> Conductor | S16: AL ALLOY | U16: Insulation Screening (Metallic) | AC16: Insulation Screening (Non-Metallic) | AE16: Insulation | AK16: POLY TAPE | AL16: Inner Sheath | AS16: Armouring | BC16: Consider Rs. 1 extra for colour of o/sh | BM16: FILLER | BN16: GREASE | BO16: Water swellable Tape | BP16: Semi conducting Water Swellable tape | BQ16: SEMICON TAPE | BR16: GLASS FIBER TAPE | BS16: COPPER WIRE 0.8 MM | BT16: RUBBERIZED COTTON TAPE | BU16: Water Tight Compound | BZ16: DRUM COST PER KM | CA16: TOTAL RM COST | CB16: EXTRA CONSUMPTION | CC16: EXTRA CONSUMPTION VALUE
A17: DOCKET NO. | B17: =Sheet1!B1 -> Base Date | C17: ITEM CODE | D17: PROPOSE ERP ITEM NAME | E17: EX-WORKS (PER KM) | F17: FREIGHT PER KM | G17: PRICE INCLUDING FREIGHT (PER KM) | H17: GST % | I17: GST VALUE | J17: PRICE INCLUDING GST & FREIGHT (PER KM) | K17: QTY | L17: Unit | M17: TOTAL PRICE OF FULL QTY (INCLUDING FRIGHT & GST) | N17: Alumimium | O17: Alumimium ALLOY | P17: Copper | Q17: Flexible Copper | R17: Galvanized steel wire | S17: Alumimium | T17: Alumimium ALLOY | U17: Coper tape - 0.1 mm | V17: Copper Tape - 0.03 mm | W17: Copper Tape - 0.035 mm | X17: Copper Tape - 0.04 mm | Y17: Copper Tape - 0.045 mm | Z17: Copper Tape - 0.050 mm | AA17: Copper Tape - 0.060 mm | AB17: Copper Tape - 0.075 mm(DOUBLE) | AC17: Extruded semiconductive | AD17: Extruded Semiconductive(Stripable) | AE17: HT-XLPE | AF17: LT-XLPE | AG17: TR XLPE | AH17: Type A PVC | AI17: Type C PVC (HR) | AJ17: XLPE | AK17: POLY TAPE | AL17: FR PVC Type ST-1 | AM17: FR PVC Type ST-2 | AN17: FRLSH PVC Type ST-2 | AO17: PVC Type ST-1 | AP17: PVC Type ST-1-PRESSURE EXTRUDED | AQ17: PVC Type ST-2 | AR17: PVC Type ST-2-PRESSURE EXTRUDED | AS17: ACSR CORE WIRE | AT17: ACSR DOG STEEL WIRE | AU17: Aluminium Flat Strip | AV17: Aluminium Round Wire | AW17: Double Steel Tape | AX17: Galvanised Steel Flat Strip | AY17: Galvanised Steel Flat Strip (Double) | AZ17: Galvanised Steel Flat Strip-B | BA17: Galvanised Steel Round Wire | BB17: Galvanised Steel Round Wire (Double) | BC17: FR PVC Type ST-1 | BD17: FR PVC Type ST-2 | BE17: FRLSH PVC Type ST-1 | BF17: FRLSH PVC Type ST-2 | BG17: PE, ST-3 | BH17: PE, ST-7 | BI17: PVC Type ST-1 | BJ17: PVC Type ST-2 | BK17: PVC Type ST-2-PRESSURE EXTRUDED | BL17: UV & Track Resistant XLPE | BM17: PP FILLER | BN17: Grease | BO17: Water swellable Tape | BP17: Semi conducting Water Swellable tape | BQ17: NCWBT | BR17: GLASS FIBER TAPE | BS17: COPPER WIRE 0.8 MM | BT17: RUBBERIZED COTTON TAPE | BU17: Water Tight Compound | BV17: =Sheet1!E1 -> Propose Drum Type | BW17: =Sheet1!CV1 -> DRUM CODE | BX17: =Sheet1!CW1 -> DRUM SIZE (FxbXtx Ft) | BY17: =Sheet1!CX1 -> Party Standard Length(MTR) | CB17: Consider 1% extra for complete cable . | CD17: MFG% | CE17: MFG VALUE | CF17: PROF% | CG17: PROFIT VALUE | CH17: 1ST EX-WORKS | CI17: Intt % | CJ17: INTT VALUE | CK17: insp% | CL17: INSP VALUE
N18: =+IFERROR(VLOOKUP($N$17,Sheet1!J:L,2,0),0) -> 257 | O18: =+IFERROR(VLOOKUP($O$17,Sheet1!J:L,2,0),0) -> 0 | P18: =+IFERROR(VLOOKUP($P$17,Sheet1!J:M,2,0),0) -> 0 | Q18: =+IFERROR(VLOOKUP($Q$17,Sheet1!J:M,2,0),0) -> 0 | R18: =+IFERROR(VLOOKUP($R$17,Sheet1!J:M,2,0),0) -> 0 | S18: =+IFERROR(VLOOKUP($S$17,Sheet1!N:Q,2,0),0) -> 0 | T18: =+IFERROR(VLOOKUP($T$17,Sheet1!N:O,2,0),0) -> 0 | U18: =+IFERROR(VLOOKUP($U$17,Sheet1!F:I,2,0),0) -> 0 | V18: =+IFERROR(VLOOKUP($V$17,Sheet1!F:I,2,0),0) -> 0 | W18: =+IFERROR(VLOOKUP($W$17,Sheet1!F:I,2,0),0) -> 0 | X18: =+IFERROR(VLOOKUP($X$17,Sheet1!F:I,2,0),0) -> 0 | Y18: =+IFERROR(VLOOKUP($Y$17,Sheet1!F:I,2,0),0) -> 927.72 | Z18: =+IFERROR(VLOOKUP($Z$17,Sheet1!F:I,2,0),0) -> 0 | AA18: =+IFERROR(VLOOKUP($AA$17,Sheet1!F:I,2,0),0) -> 0 | AB18: =+IFERROR(VLOOKUP($AB$17,Sheet1!F:I,2,0),0) -> 0 | AC18: =+IFERROR(VLOOKUP($AC$17,Sheet1!R:U,2,0),0) -> 180 | AD18: =+IFERROR(VLOOKUP($AD$17,Sheet1!R:U,2,0),0) -> 0 | AE18: =+IFERROR(VLOOKUP($AE$17,Sheet1!V:Y,2,0),0) -> 140 | AF18: =+IFERROR(VLOOKUP($AF$17,Sheet1!V:Y,2,0),0) -> 0 | AG18: =+IFERROR(VLOOKUP($AG$17,Sheet1!V:Y,2,0),0) -> 0 | AH18: =+IFERROR(VLOOKUP($AH$17,Sheet1!V:Y,2,0),0) -> 0 | AI18: =+IFERROR(VLOOKUP($AI$17,Sheet1!V:Y,2,0),0) -> 0 | AJ18: =+IFERROR(VLOOKUP($AJ$17,Sheet1!V:Y,2,0),0) -> 0 | AK18: =+IFERROR(VLOOKUP($AK$17,Sheet1!Z2:AA840,2,0),0) -> 124 | AL18: =+IFERROR(VLOOKUP($AL$17,Sheet1!AD2:AG840,2,0),0) -> 0 | AM18: =+IFERROR(VLOOKUP($AM$17,Sheet1!AD2:AG840,2,0),0) -> 0 | AN18: =+IFERROR(VLOOKUP($AN$17,Sheet1!AD2:AG840,2,0),0) -> 0 | AO18: =+IFERROR(VLOOKUP($AO$17,Sheet1!AD2:AG840,2,0),0) -> 0 | AP18: =+IFERROR(VLOOKUP($AP$17,Sheet1!AD2:AG840,2,0),0) -> 0 | AQ18: =+IFERROR(VLOOKUP($AQ$17,Sheet1!AD2:AG840,2,0),0) -> 69.29 | AR18: =+IFERROR(VLOOKUP($AR$17,Sheet1!AD2:AG840,2,0),0) -> 88 | AS18: =+IFERROR(VLOOKUP($AS$17,Sheet1!AH2:AK840,2,0),0) -> 0 | AT18: =+IFERROR(VLOOKUP($AT$17,Sheet1!AH2:AK840,2,0),0) -> 0 | AU18: =+IFERROR(VLOOKUP($AU$17,Sheet1!AH2:AK840,2,0),0) -> 0 | AV18: =+IFERROR(VLOOKUP($AV$17,Sheet1!AH2:AK840,2,0),0) -> 262 | AW18: =+IFERROR(VLOOKUP($AW$17,Sheet1!AH2:AK840,2,0),0) -> 0 | AX18: =+IFERROR(VLOOKUP($AX$17,Sheet1!AH2:AK840,2,0),0) -> 0 | AY18: =+IFERROR(VLOOKUP($AY$17,Sheet1!AH2:AK840,2,0),0) -> 0 | AZ18: =+IFERROR(VLOOKUP($AZ$17,Sheet1!AH2:AK840,2,0),0) -> 0 | BA18: =+IFERROR(VLOOKUP($BA$17,Sheet1!AH2:AK840,2,0),0) -> 90.7 | BB18: =+IFERROR(VLOOKUP($BB$17,Sheet1!AH2:AK840,2,0),0) -> 0 | BC18: =+IFERROR(VLOOKUP($BC$17,Sheet1!AL2:AO840,2,0),0) -> 0 | BD18: =+IFERROR(VLOOKUP($BD$17,Sheet1!AL2:AO840,2,0),0) -> 0 | BE18: =+IFERROR(VLOOKUP($BE$17,Sheet1!AL2:AO840,2,0),0) -> 0 | BF18: =+IFERROR(VLOOKUP($BF$17,Sheet1!AL2:AO840,2,0),0)+1 -> 91 | BG18: =+IFERROR(VLOOKUP($BG$17,Sheet1!AL2:AO840,2,0),0) -> 0 | BH18: =+IFERROR(VLOOKUP($BH$17,Sheet1!AL2:AO840,2,0),0) -> 0 | BI18: =+IFERROR(VLOOKUP($BI$17,Sheet1!AL2:AO840,2,0),0) -> 0 | BJ18: =+IFERROR(VLOOKUP($BJ$17,Sheet1!AL2:AO840,2,0),0) -> 0 | BK18: =+IFERROR(VLOOKUP($BK$17,Sheet1!AL2:AO840,2,0),0) -> 0 | BL18: =+IFERROR(VLOOKUP($BL$17,Sheet1!AL2:AO840,2,0),0) -> 0 | BM18: 85 | BN18: =+IFERROR(VLOOKUP($BN$17,Sheet1!AT2:AW840,2,0),0) -> 0 | BP18: =+IFERROR(VLOOKUP($BP$17,Sheet1!BB2:BE840,2,0),0) -> 400 | BQ18: 340 | BR18: =+IFERROR(VLOOKUP($BR$17,Sheet1!BJ2:BM840,2,0),0) -> 0 | BS18: =+IFERROR(VLOOKUP($BS$17,Sheet1!BN2:BQ840,2,0),0) -> 0 | BT18: =+IFERROR(VLOOKUP($BT$17,Sheet1!BR2:BU840,2,0),0) -> 375 | BU18: =+IFERROR(VLOOKUP($BU$17,Sheet1!BV2:BY840,2,0),0) -> 0
A19: =Sheet1!A3 -> ENQ-14722-22-23 | B19: 45638 | C19: =Sheet1!C3 -> FA1300083 | D19: =Sheet1!D3 -> 3 CORE X 400 SQ. MM. AL/ARM - WIRE (XLPE) - 11 KV | E19: =CH19+CJ19+CL19 -> 3040974 | F19: =ROUNDUP(M27,0) -> 52500 | G19: =E19+F19 -> 3093474 | H19: =Sheet1!CP3 -> 0.18 | I19: =G19*H19 -> 556825.31 | J19: =G19+I19 -> 3650299.3 | K19: =Sheet1!CS3 -> 12 | L19: =Sheet1!CT3 -> KMS | M19: =J19*K19 -> 43803591 | N19: 3243 | O19: =+IFERROR(VLOOKUP($O$17,Sheet1!J3:L3,3,0),0) -> 0 | P19: =+IFERROR(VLOOKUP($P$17,Sheet1!J3:M3,3,0),0) -> 0 | Q19: =+IFERROR(VLOOKUP($Q$17,Sheet1!J3:M3,3,0),0) -> 0 | R19: =+IFERROR(VLOOKUP($R$17,Sheet1!J3:M3,3,0),0) -> 0 | S19: =+IFERROR(VLOOKUP($S$17,Sheet1!N3:Q3,3,0),0) -> 0 | T19: =+IFERROR(VLOOKUP($T$17,Sheet1!N3:Q3,3,0),0) -> 0 | U19: =+IFERROR(VLOOKUP($U$17,Sheet1!F3:I3,3,0),0) -> 0 | V19: =+IFERROR(VLOOKUP($V$17,Sheet1!F3:I3,3,0),0) -> 0 | W19: =+IFERROR(VLOOKUP($W$17,Sheet1!F3:I3,3,0),0) -> 0 | X19: =+IFERROR(VLOOKUP($X$17,Sheet1!F3:I3,3,0),0) -> 0 | Y19: 158 | Z19: =+IFERROR(VLOOKUP($Z$17,Sheet1!F3:I3,3,0),0) -> 0 | AA19: =+IFERROR(VLOOKUP($AA$17,Sheet1!F3:I3,3,0),0) -> 0 | AB19: =+IFERROR(VLOOKUP($AB$17,Sheet1!F3:I3,3,0),0) -> 0 | AC19: 414 | AD19: =+IFERROR(VLOOKUP($AD$17,Sheet1!R3:U3,2,0),0) -> 0 | AE19: 938 | AF19: =+IFERROR(VLOOKUP($AF$17,Sheet1!V3:Y3,3,0),0) -> 0 | AG19: =+IFERROR(VLOOKUP($AG$17,Sheet1!V3:Y3,3,0),0) -> 0 | AH19: =+IFERROR(VLOOKUP($AH$17,Sheet1!V3:Y3,3,0),0) -> 0 | AI19: =+IFERROR(VLOOKUP($AI$17,Sheet1!V3:Y3,3,0),0) -> 0 | AJ19: =+IFERROR(VLOOKUP($AJ$17,Sheet1!V3:Y3,3,0),0) -> 0 | AK19: =+IFERROR(VLOOKUP($AK$17,Sheet1!Z3:AB3,3,0),0) -> 0 | AL19: =+IFERROR(VLOOKUP($AL$17,Sheet1!AD3:AG3,3,0),0) -> 0 | AM19: =+IFERROR(VLOOKUP($AM$17,Sheet1!AD3:AG3,3,0),0) -> 0 | AN19: =+IFERROR(VLOOKUP($AN$17,Sheet1!AD3:AG3,3,0),0) -> 0 | AO19: =+IFERROR(VLOOKUP($AO$17,Sheet1!AD3:AG3,3,0),0) -> 0 | AP19: =+IFERROR(VLOOKUP($AP$17,Sheet1!AD3:AG3,3,0),0) -> 0 | AQ19: =+IFERROR(VLOOKUP($AQ$17,Sheet1!AD3:AG3,3,0),0) -> 0 | AR19: 980 | AS19: =+IFERROR(VLOOKUP($AS$17,Sheet1!AH3:AK3,3,0),0) -> 0 | AT19: =+IFERROR(VLOOKUP($AT$17,Sheet1!AH3:AK3,3,0),0) -> 0 | AU19: =+IFERROR(VLOOKUP($AU$17,Sheet1!AH3:AK3,3,0),0) -> 0 | AV19: =+IFERROR(VLOOKUP($AV$17,Sheet1!AH3:AK3,3,0),0) -> 0 | AW19: =+IFERROR(VLOOKUP($AW$17,Sheet1!AH3:AK3,3,0),0) -> 0 | AX19: =+IFERROR(VLOOKUP($AX$17,Sheet1!AH3:AK3,3,0),0) -> 0 | AY19: =+IFERROR(VLOOKUP($AY$17,Sheet1!AH3:AK3,3,0),0) -> 0 | AZ19: =+IFERROR(VLOOKUP($AZ$17,Sheet1!AH3:AK3,3,0),0) -> 0 | BA19: 5540 | BB19: =+IFERROR(VLOOKUP($BB$17,Sheet1!AH3:AK3,3,0),0) -> 0 | BC19: =+IFERROR(VLOOKUP($BC$17,Sheet1!AL3:AO3,3,0),0) -> 0 | BD19: =+IFERROR(VLOOKUP($BD$17,Sheet1!AL3:AO3,3,0),0) -> 0 | BE19: =+IFERROR(VLOOKUP($BE$17,Sheet1!AL3:AO3,3,0),0) -> 0 | BF19: 1355 | BG19: =+IFERROR(VLOOKUP($BG$17,Sheet1!AL3:AO3,3,0),0) -> 0 | BH19: =+IFERROR(VLOOKUP($BH$17,Sheet1!AL3:AO3,3,0),0) -> 0 | BI19: =+IFERROR(VLOOKUP($BI$17,Sheet1!AL3:AO3,3,0),0) -> 0 | BJ19: =+IFERROR(VLOOKUP($BJ$17,Sheet1!AL3:AO3,3,0),0) -> 0 | BK19: =+IFERROR(VLOOKUP($BK$17,Sheet1!AL3:AO3,3,0),0) -> 0 | BL19: =+IFERROR(VLOOKUP($BL$17,Sheet1!AL3:AO3,3,0),0) -> 0 | BM19: 997 | BN19: =+IFERROR(VLOOKUP($BN$17,Sheet1!AT3:AW3,3,0),0) -> 0 | BO19: =+IFERROR(VLOOKUP($BO$17,Sheet1!AX3:BA3,3,0),0) -> 0 | BP19: 86 | BQ19: 58 | BR19: =+IFERROR(VLOOKUP($BR$17,Sheet1!BJ3:BM3,3,0),0) -> 0 | BS19: =+IFERROR(VLOOKUP($BS$17,Sheet1!BN3:BQ3,3,0),0) -> 0 | BT19: 59 | BU19: =+IFERROR(VLOOKUP($BU$17,Sheet1!BV3:BY3,3,0),0) -> 0 | BV19: =Sheet1!E3 -> STEEL | BW19: SP0400136 | BX19: CORRUGATED DISPATCH STEEL DRUM 2200 X 1300 X 1200 MM | BY19: =Sheet1!CX3 -> 250 | BZ19: =28000/0.25 -> 112000 | CA19: =SUMPRODUCT($N$18:$BU$18,N19:BU19)+BZ19 -> 2170883.8 | CB19: 0.01 | CC19: =CA19*CB19 -> 21708.838 | CD19: 0.35 | CE19: =CA19*CD19 -> 759809.32 | CF19: 0 | CG19: =CA19*CF19 -> 0 | CH19: =CA19+CC19+CE19+CG19 -> 2952401.9 | CI19: 0.02 | CJ19: =CH19*CI19 -> 59048.038 | CK19: 0.01 | CL19: =CH19*CK19 -> 29524.019
A20: =Sheet1!A4 -> ENQ-14722-22-23 | B20: 45638 | C20: =Sheet1!C4 -> FA1300200 | D20: =Sheet1!D4 -> 3 CORE X 95 SQ. MM. AL/ARM WIRE (XLPE) - 33 KV | E20: =CH20+CJ20+CL20 -> 2062200.6 | F20: =ROUNDUP(M28,0) -> 50400 | G20: =E20+F20 -> 2112600.6 | H20: =Sheet1!CP4 -> 0.18 | I20: =G20*H20 -> 380268.11 | J20: =G20+I20 -> 2492868.7 | K20: =Sheet1!CS4 -> 2.5 | L20: =Sheet1!CT4 -> KMS | M20: =J20*K20 -> 6232171.9 | N20: =+IFERROR(VLOOKUP($N$17,Sheet1!J4:L4,3,0),0) -> 770 | O20: =+IFERROR(VLOOKUP($O$17,Sheet1!J4:L4,3,0),0) -> 0 | P20: =+IFERROR(VLOOKUP($P$17,Sheet1!J4:M4,3,0),0) -> 0 | Q20: =+IFERROR(VLOOKUP($Q$17,Sheet1!J4:M4,3,0),0) -> 0 | R20: =+IFERROR(VLOOKUP($R$17,Sheet1!J4:M4,3,0),0) -> 0 | S20: =+IFERROR(VLOOKUP($S$17,Sheet1!N4:Q4,3,0),0) -> 0 | T20: =+IFERROR(VLOOKUP($T$17,Sheet1!N4:Q4,3,0),0) -> 0 | U20: =+IFERROR(VLOOKUP($U$17,Sheet1!F4:I4,3,0),0) -> 0 | V20: =+IFERROR(VLOOKUP($V$17,Sheet1!F4:I4,3,0),0) -> 0 | W20: =+IFERROR(VLOOKUP($W$17,Sheet1!F4:I4,3,0),0) -> 0 | X20: =+IFERROR(VLOOKUP($X$17,Sheet1!F4:I4,3,0),0) -> 0 | Y20: 151 | Z20: =+IFERROR(VLOOKUP($Z$17,Sheet1!F4:I4,3,0),0) -> 0 | AA20: =+IFERROR(VLOOKUP($AA$17,Sheet1!F4:I4,3,0),0) -> 0 | AB20: =+IFERROR(VLOOKUP($AB$17,Sheet1!F4:I4,3,0),0) -> 0 | AC20: 345 | AD20: =+IFERROR(VLOOKUP($AD$17,Sheet1!R4:U4,2,0),0) -> 0 | AE20: 1725 | AF20: =+IFERROR(VLOOKUP($AF$17,Sheet1!V4:Y4,3,0),0) -> 0 | AG20: =+IFERROR(VLOOKUP($AG$17,Sheet1!V4:Y4,3,0),0) -> 0 | AH20: =+IFERROR(VLOOKUP($AH$17,Sheet1!V4:Y4,3,0),0) -> 0 | AI20: =+IFERROR(VLOOKUP($AI$17,Sheet1!V4:Y4,3,0),0) -> 0 | AJ20: =+IFERROR(VLOOKUP($AJ$17,Sheet1!V4:Y4,3,0),0) -> 0 | AK20: =+IFERROR(VLOOKUP($AK$17,Sheet1!Z4:AB4,3,0),0) -> 0 | AL20: =+IFERROR(VLOOKUP($AL$17,Sheet1!AD4:AG4,3,0),0) -> 0 | AM20: =+IFERROR(VLOOKUP($AM$17,Sheet1!AD4:AG4,3,0),0) -> 0 | AN20: =+IFERROR(VLOOKUP($AN$17,Sheet1!AD4:AG4,3,0),0) -> 0 | AO20: =+IFERROR(VLOOKUP($AO$17,Sheet1!AD4:AG4,3,0),0) -> 0 | AP20: =+IFERROR(VLOOKUP($AP$17,Sheet1!AD4:AG4,3,0),0) -> 0 | AQ20: =+IFERROR(VLOOKUP($AQ$17,Sheet1!AD4:AG4,3,0),0) -> 0 | AR20: 914 | AS20: =+IFERROR(VLOOKUP($AS$17,Sheet1!AH4:AK4,3,0),0) -> 0 | AT20: =+IFERROR(VLOOKUP($AT$17,Sheet1!AH4:AK4,3,0),0) -> 0 | AU20: =+IFERROR(VLOOKUP($AU$17,Sheet1!AH4:AK4,3,0),0) -> 0 | AV20: =+IFERROR(VLOOKUP($AV$17,Sheet1!AH4:AK4,3,0),0) -> 0 | AW20: =+IFERROR(VLOOKUP($AW$17,Sheet1!AH4:AK4,3,0),0) -> 0 | AX20: =+IFERROR(VLOOKUP($AX$17,Sheet1!AH4:AK4,3,0),0) -> 0 | AY20: =+IFERROR(VLOOKUP($AY$17,Sheet1!AH4:AK4,3,0),0) -> 0 | AZ20: =+IFERROR(VLOOKUP($AZ$17,Sheet1!AH4:AK4,3,0),0) -> 0 | BA20: 4135 | BB20: =+IFERROR(VLOOKUP($BB$17,Sheet1!AH4:AK4,3,0),0) -> 0 | BC20: =+IFERROR(VLOOKUP($BC$17,Sheet1!AL4:AO4,3,0),0) -> 0 | BD20: =+IFERROR(VLOOKUP($BD$17,Sheet1!AL4:AO4,3,0),0) -> 0 | BE20: =+IFERROR(VLOOKUP($BE$17,Sheet1!AL4:AO4,3,0),0) -> 0 | BF20: 1282 | BG20: =+IFERROR(VLOOKUP($BG$17,Sheet1!AL4:AO4,3,0),0) -> 0 | BH20: =+IFERROR(VLOOKUP($BH$17,Sheet1!AL4:AO4,3,0),0) -> 0 | BI20: =+IFERROR(VLOOKUP($BI$17,Sheet1!AL4:AO4,3,0),0) -> 0 | BJ20: =+IFERROR(VLOOKUP($BJ$17,Sheet1!AL4:AO4,3,0),0) -> 0 | BK20: =+IFERROR(VLOOKUP($BK$17,Sheet1!AL4:AO4,3,0),0) -> 0 | BL20: =+IFERROR(VLOOKUP($BL$17,Sheet1!AL4:AO4,3,0),0) -> 0 | BM20: 917 | BN20: =+IFERROR(VLOOKUP($BN$17,Sheet1!AT4:AW4,3,0),0) -> 0 | BO20: =+IFERROR(VLOOKUP($BO$17,Sheet1!AX4:BA4,3,0),0) -> 0 | BP20: 66 | BQ20: 15 | BR20: =+IFERROR(VLOOKUP($BR$17,Sheet1!BJ4:BM4,3,0),0) -> 0 | BS20: =+IFERROR(VLOOKUP($BS$17,Sheet1!BN4:BQ4,3,0),0) -> 0 | BT20: 56 | BU20: =+IFERROR(VLOOKUP($BU$17,Sheet1!BV4:BY4,3,0),0) -> 0 | BV20: =Sheet1!E4 -> STEEL | BW20: =Sheet1!CV4 -> SP0400136 | BX20: =Sheet1!CW4 -> CORRUGATED DISPATCH STEEL DRUM 2200 X 1300 X 1200 MM | BY20: =Sheet1!CX4 -> 250 | BZ20: =32000/0.25 -> 128000 | CA20: =SUMPRODUCT($N$18:$BU$18,N20:BU20)+BZ20 -> 1472159.2 | CB20: 0.01 | CC20: =CA20*CB20 -> 14721.592 | CD20: 0.35 | CE20: =CA20*CD20 -> 515255.73 | CF20: 0 | CG20: =CA20*CF20 -> 0 | CH20: =CA20+CC20+CE20+CG20 -> 2002136.5 | CI20: 0.02 | CJ20: =CH20*CI20 -> 40042.731 | CK20: 0.01 | CL20: =CH20*CK20 -> 20021.365
A21: =Sheet1!A2 -> ENQ-14722-22-23 | B21: 45638 | C21: =Sheet1!C2 -> FA1300080 | D21: =Sheet1!D2 -> 3 CORE X 400 SQ. MM AL/ARM - WIRE (XLPE) - 33 KV | E21: =CH21+CJ21+CL21 -> 3996402.6 | F21: =ROUNDUP(M29,0) -> 63000 | G21: =E21+F21 -> 4059402.6 | H21: =Sheet1!CP2 -> 0.18 | I21: =G21*H21 -> 730692.47 | J21: =G21+I21 -> 4790095.1 | K21: =Sheet1!CS2 -> 17 | L21: =Sheet1!CT2 -> KMS | M21: =J21*K21 -> 81431616 | N21: 3243 | O21: =+IFERROR(VLOOKUP($O$17,Sheet1!J2:L2,3,0),0) -> 0 | P21: =+IFERROR(VLOOKUP($P$17,Sheet1!J2:M2,3,0),0) -> 0 | Q21: =+IFERROR(VLOOKUP($Q$17,Sheet1!J2:M2,3,0),0) -> 0 | R21: =+IFERROR(VLOOKUP($R$17,Sheet1!J2:M2,3,0),0) -> 0 | S21: =+IFERROR(VLOOKUP($S$17,Sheet1!N2:Q2,3,0),0) -> 0 | T21: =+IFERROR(VLOOKUP($T$17,Sheet1!N2:Q2,3,0),0) -> 0 | U21: =+IFERROR(VLOOKUP($U$17,Sheet1!F2:I2,3,0),0) -> 0 | V21: =+IFERROR(VLOOKUP($V$17,Sheet1!F2:I2,3,0),0) -> 0 | W21: =+IFERROR(VLOOKUP($W$17,Sheet1!F2:I2,3,0),0) -> 0 | X21: =+IFERROR(VLOOKUP($X$17,Sheet1!F2:I2,3,0),0) -> 0 | Y21: 212 | Z21: =+IFERROR(VLOOKUP($Z$17,Sheet1!F2:I2,3,0),0) -> 0 | AA21: =+IFERROR(VLOOKUP($AA$17,Sheet1!F2:I2,3,0),0) -> 0 | AB21: =+IFERROR(VLOOKUP($AB$17,Sheet1!F2:I2,3,0),0) -> 0 | AC21: 515 | AD21: =+IFERROR(VLOOKUP($AD$17,Sheet1!R2:U2,2,0),0) -> 0 | AE21: 2670 | AF21: =+IFERROR(VLOOKUP($AF$17,Sheet1!V2:Y2,3,0),0) -> 0 | AG21: =+IFERROR(VLOOKUP($AG$17,Sheet1!V2:Y2,3,0),0) -> 0 | AH21: =+IFERROR(VLOOKUP($AH$17,Sheet1!V2:Y2,3,0),0) -> 0 | AI21: =+IFERROR(VLOOKUP($AI$17,Sheet1!V2:Y2,3,0),0) -> 0 | AJ21: =+IFERROR(VLOOKUP($AJ$17,Sheet1!V2:Y2,3,0),0) -> 0 | AK21: =+IFERROR(VLOOKUP($AK$17,Sheet1!Z2:AB2,3,0),0) -> 0 | AL21: =+IFERROR(VLOOKUP($AL$17,Sheet1!AD2:AG2,3,0),0) -> 0 | AM21: =+IFERROR(VLOOKUP($AM$17,Sheet1!AD2:AG2,3,0),0) -> 0 | AN21: =+IFERROR(VLOOKUP($AN$17,Sheet1!AD2:AG2,3,0),0) -> 0 | AO21: =+IFERROR(VLOOKUP($AO$17,Sheet1!AD2:AG2,3,0),0) -> 0 | AP21: =+IFERROR(VLOOKUP($AP$17,Sheet1!AD2:AG2,3,0),0) -> 0 | AQ21: =+IFERROR(VLOOKUP($AQ$17,Sheet1!AD2:AG2,3,0),0) -> 0 | AR21: 1561 | AS21: =+IFERROR(VLOOKUP($AS$17,Sheet1!AH2:AK2,3,0),0) -> 0 | AT21: =+IFERROR(VLOOKUP($AT$17,Sheet1!AH2:AK2,3,0),0) -> 0 | AU21: =+IFERROR(VLOOKUP($AU$17,Sheet1!AH2:AK2,3,0),0) -> 0 | AV21: =+IFERROR(VLOOKUP($AV$17,Sheet1!AH2:AK2,3,0),0) -> 0 | AW21: =+IFERROR(VLOOKUP($AW$17,Sheet1!AH2:AK2,3,0),0) -> 0 | AX21: =+IFERROR(VLOOKUP($AX$17,Sheet1!AH2:AK2,3,0),0) -> 0 | AY21: =+IFERROR(VLOOKUP($AY$17,Sheet1!AH2:AK2,3,0),0) -> 0 | AZ21: =+IFERROR(VLOOKUP($AZ$17,Sheet1!AH2:AK2,3,0),0) -> 0 | BA21: 7182 | BB21: =+IFERROR(VLOOKUP($BB$17,Sheet1!AH2:AK2,3,0),0) -> 0 | BC21: =+IFERROR(VLOOKUP($BC$17,Sheet1!AL2:AO2,3,0),0) -> 0 | BD21: =+IFERROR(VLOOKUP($BD$17,Sheet1!AL2:AO2,3,0),0) -> 0 | BE21: =+IFERROR(VLOOKUP($BE$17,Sheet1!AL2:AO2,3,0),0) -> 0 | BF21: 1715 | BG21: =+IFERROR(VLOOKUP($BG$17,Sheet1!AL2:AO2,3,0),0) -> 0 | BH21: =+IFERROR(VLOOKUP($BH$17,Sheet1!AL2:AO2,3,0),0) -> 0 | BI21: =+IFERROR(VLOOKUP($BI$17,Sheet1!AL2:AO2,3,0),0) -> 0 | BJ21: =+IFERROR(VLOOKUP($BJ$17,Sheet1!AL2:AO2,3,0),0) -> 0 | BK21: =+IFERROR(VLOOKUP($BK$17,Sheet1!AL2:AO2,3,0),0) -> 0 | BL21: =+IFERROR(VLOOKUP($BL$17,Sheet1!AL2:AO2,3,0),0) -> 0 | BM21: 1718 | BN21: =+IFERROR(VLOOKUP($BN$17,Sheet1!AT2:AW2,3,0),0) -> 0 | BO21: 0 | BP21: 104 | BQ21: 58 | BR21: =+IFERROR(VLOOKUP($BR$17,Sheet1!BJ2:BM2,3,0),0) -> 0 | BS21: =+IFERROR(VLOOKUP($BS$17,Sheet1!BN2:BQ2,3,0),0) -> 0 | BT21: 75 | BU21: =+IFERROR(VLOOKUP($BU$17,Sheet1!BV2:BY2,3,0),0) -> 0 | BV21: =Sheet1!E2 -> STEEL | BW21: =Sheet1!CV2 -> SP0400137 | BX21: =Sheet1!CW2 -> CORRUGATED DISPATCH STEEL DRUM 2600 X 1600 X 1600 MM | BY21: =Sheet1!CX2 -> 250 | BZ21: =44000/0.25 -> 176000 | CA21: =SUMPRODUCT($N$18:$BU$18,N21:BU21)+BZ21 -> 2852943 | CB21: 0.01 | CC21: =CA21*CB21 -> 28529.43 | CD21: 0.35 | CE21: =CA21*CD21 -> 998530.06 | CF21: 0 | CG21: =CA21*CF21 -> 0 | CH21: =CA21+CC21+CE21+CG21 -> 3880002.5 | CI21: 0.02 | CJ21: =CH21*CI21 -> 77600.051 | CK21: 0.01 | CL21: =CH21*CK21 -> 38800.025
A22: =Sheet1!A6 -> ENQ-14722-22-23 | B22: 45638 | C22: =Sheet1!C6 -> FA1300018 | D22: =Sheet1!D6 -> 1 CORE X 400 SQ. MM. AL/ARM (XLPE) - 33 KV | E22: =CH22+CJ22+CL22 -> 1148860.8 | F22: =ROUNDUP(M30,0) -> 24138 | G22: =E22+F22 -> 1172998.8 | H22: =Sheet1!CP6 -> 0.18 | I22: =G22*H22 -> 211139.78 | J22: =G22+I22 -> 1384138.6 | K22: =Sheet1!CS6 -> 5.22 | L22: =Sheet1!CT6 -> KMS | M22: =J22*K22 -> 7225203.3 | N22: 1081 | O22: =+IFERROR(VLOOKUP($O$17,Sheet1!J6:L6,3,0),0) -> 0 | P22: =+IFERROR(VLOOKUP($P$17,Sheet1!J6:M6,3,0),0) -> 0 | Q22: =+IFERROR(VLOOKUP($Q$17,Sheet1!J6:M6,3,0),0) -> 0 | R22: =+IFERROR(VLOOKUP($R$17,Sheet1!J6:M6,3,0),0) -> 0 | S22: =+IFERROR(VLOOKUP($S$17,Sheet1!N6:Q6,3,0),0) -> 0 | T22: =+IFERROR(VLOOKUP($T$17,Sheet1!N6:Q6,3,0),0) -> 0 | U22: =+IFERROR(VLOOKUP($U$17,Sheet1!F6:I6,3,0),0) -> 0 | V22: =+IFERROR(VLOOKUP($V$17,Sheet1!F6:I6,3,0),0) -> 0 | W22: =+IFERROR(VLOOKUP($W$17,Sheet1!F6:I6,3,0),0) -> 0 | X22: =+IFERROR(VLOOKUP($X$17,Sheet1!F6:I6,3,0),0) -> 0 | Y22: 70 | Z22: =+IFERROR(VLOOKUP($Z$17,Sheet1!F6:I6,3,0),0) -> 0 | AA22: =+IFERROR(VLOOKUP($AA$17,Sheet1!F6:I6,3,0),0) -> 0 | AB22: =+IFERROR(VLOOKUP($AB$17,Sheet1!F6:I6,3,0),0) -> 0 | AC22: 171 | AD22: =+IFERROR(VLOOKUP($AD$17,Sheet1!R6:U6,2,0),0) -> 0 | AE22: 885 | AF22: =+IFERROR(VLOOKUP($AF$17,Sheet1!V6:Y6,3,0),0) -> 0 | AG22: =+IFERROR(VLOOKUP($AG$17,Sheet1!V6:Y6,3,0),0) -> 0 | AH22: =+IFERROR(VLOOKUP($AH$17,Sheet1!V6:Y6,3,0),0) -> 0 | AI22: =+IFERROR(VLOOKUP($AI$17,Sheet1!V6:Y6,3,0),0) -> 0 | AJ22: =+IFERROR(VLOOKUP($AJ$17,Sheet1!V6:Y6,3,0),0) -> 0 | AK22: 16 | AL22: =+IFERROR(VLOOKUP($AL$17,Sheet1!AD6:AG6,3,0),0) -> 0 | AM22: =+IFERROR(VLOOKUP($AM$17,Sheet1!AD6:AG6,3,0),0) -> 0 | AN22: =+IFERROR(VLOOKUP($AN$17,Sheet1!AD6:AG6,3,0),0) -> 0 | AO22: =+IFERROR(VLOOKUP($AO$17,Sheet1!AD6:AG6,3,0),0) -> 0 | AP22: =+IFERROR(VLOOKUP($AP$17,Sheet1!AD6:AG6,3,0),0) -> 0 | AQ22: 151 | AR22: =+IFERROR(VLOOKUP($AR$17,Sheet1!AD6:AG6,3,0),0) -> 0 | AS22: =+IFERROR(VLOOKUP($AS$17,Sheet1!AH6:AK6,3,0),0) -> 0 | AT22: =+IFERROR(VLOOKUP($AT$17,Sheet1!AH6:AK6,3,0),0) -> 0 | AU22: =+IFERROR(VLOOKUP($AU$17,Sheet1!AH6:AK6,3,0),0) -> 0 | AV22: 731 | AW22: =+IFERROR(VLOOKUP($AW$17,Sheet1!AH6:AK6,3,0),0) -> 0 | AX22: =+IFERROR(VLOOKUP($AX$17,Sheet1!AH6:AK6,3,0),0) -> 0 | AY22: =+IFERROR(VLOOKUP($AY$17,Sheet1!AH6:AK6,3,0),0) -> 0 | AZ22: =+IFERROR(VLOOKUP($AZ$17,Sheet1!AH6:AK6,3,0),0) -> 0 | BA22: =+IFERROR(VLOOKUP($BA$17,Sheet1!AH6:AK6,3,0),0) -> 0 | BB22: =+IFERROR(VLOOKUP($BB$17,Sheet1!AH6:AK6,3,0),0) -> 0 | BC22: =+IFERROR(VLOOKUP($BC$17,Sheet1!AL6:AO6,3,0),0) -> 0 | BD22: =+IFERROR(VLOOKUP($BD$17,Sheet1!AL6:AO6,3,0),0) -> 0 | BE22: =+IFERROR(VLOOKUP($BE$17,Sheet1!AL6:AO6,3,0),0) -> 0 | BF22: 580 | BG22: =+IFERROR(VLOOKUP($BG$17,Sheet1!AL6:AO6,3,0),0) -> 0 | BH22: =+IFERROR(VLOOKUP($BH$17,Sheet1!AL6:AO6,3,0),0) -> 0 | BI22: =+IFERROR(VLOOKUP($BI$17,Sheet1!AL6:AO6,3,0),0) -> 0 | BJ22: =+IFERROR(VLOOKUP($BJ$17,Sheet1!AL6:AO6,3,0),0) -> 0 | BK22: =+IFERROR(VLOOKUP($BK$17,Sheet1!AL6:AO6,3,0),0) -> 0 | BL22: =+IFERROR(VLOOKUP($BL$17,Sheet1!AL6:AO6,3,0),0) -> 0 | BM22: =+IFERROR(VLOOKUP($BM$17,Sheet1!AP6:AS6,3,0),0) -> 0 | BN22: =+IFERROR(VLOOKUP($BN$17,Sheet1!AT6:AW6,3,0),0) -> 0 | BP22: 35 | BQ22: 19 | BR22: =+IFERROR(VLOOKUP($BR$17,Sheet1!BJ6:BM6,3,0),0) -> 0 | BS22: =+IFERROR(VLOOKUP($BS$17,Sheet1!BN6:BQ6,3,0),0) -> 0 | BT22: 36 | BU22: =+IFERROR(VLOOKUP($BU$17,Sheet1!BV6:BY6,3,0),0) -> 0 | BV22: =Sheet1!E6 -> STEEL | BW22: SP0400126 | BX22: CORRUGATED DISPATCH STEEL DRUM 1900 X 830 X 915 MM | BY22: =Sheet1!CX6 -> 500 | BZ22: =16000/0.5 -> 32000 | CA22: =SUMPRODUCT($N$18:$BU$18,N22:BU22)+BZ22 -> 820146.19 | CB22: 0.01 | CC22: =CA22*CB22 -> 8201.4619 | CD22: 0.35 | CE22: =CA22*CD22 -> 287051.17 | CF22: 0 | CG22: =CA22*CF22 -> 0 | CH22: =CA22+CC22+CE22+CG22 -> 1115398.8 | CI22: 0.02 | CJ22: =CH22*CI22 -> 22307.976 | CK22: 0.01 | CL22: =CH22*CK22 -> 11153.988
A23: =Sheet1!A5 -> ENQ-14722-22-23 | B23: 45638 | C23: =Sheet1!C5 -> FA1300027 | D23: =Sheet1!D5 -> 1 CORE X 630 SQ. MM. AL/ARM (XLPE) - 33 KV | E23: =CH23+CJ23+CL23 -> 1513652.5 | F23: =ROUNDUP(M31,0) -> 15850 | G23: =E23+F23 -> 1529502.5 | H23: =Sheet1!CP5 -> 0.18 | I23: =G23*H23 -> 275310.45 | J23: =G23+I23 -> 1804812.9 | K23: =Sheet1!CS5 -> 238.5 | L23: =Sheet1!CT5 -> KMS | M23: =J23*K23 -> 4.3044788e+08 | N23: =+IFERROR(VLOOKUP($N$17,Sheet1!J5:L5,3,0),0) -> 1701 | O23: =+IFERROR(VLOOKUP($O$17,Sheet1!J5:L5,3,0),0) -> 0 | P23: =+IFERROR(VLOOKUP($P$17,Sheet1!J5:M5,3,0),0) -> 0 | Q23: =+IFERROR(VLOOKUP($Q$17,Sheet1!J5:M5,3,0),0) -> 0 | R23: =+IFERROR(VLOOKUP($R$17,Sheet1!J5:M5,3,0),0) -> 0 | S23: =+IFERROR(VLOOKUP($S$17,Sheet1!N5:Q5,3,0),0) -> 0 | T23: =+IFERROR(VLOOKUP($T$17,Sheet1!N5:Q5,3,0),0) -> 0 | U23: =+IFERROR(VLOOKUP($U$17,Sheet1!F5:I5,3,0),0) -> 0 | V23: =+IFERROR(VLOOKUP($V$17,Sheet1!F5:I5,3,0),0) -> 0 | W23: =+IFERROR(VLOOKUP($W$17,Sheet1!F5:I5,3,0),0) -> 0 | X23: =+IFERROR(VLOOKUP($X$17,Sheet1!F5:I5,3,0),0) -> 0 | Y23: 79 | Z23: =+IFERROR(VLOOKUP($Z$17,Sheet1!F5:I5,3,0),0) -> 0 | AA23: =+IFERROR(VLOOKUP($AA$17,Sheet1!F5:I5,3,0),0) -> 0 | AB23: =+IFERROR(VLOOKUP($AB$17,Sheet1!F5:I5,3,0),0) -> 0 | AC23: 218 | AD23: =+IFERROR(VLOOKUP($AD$17,Sheet1!R5:U5,2,0),0) -> 0 | AE23: 1055 | AF23: =+IFERROR(VLOOKUP($AF$17,Sheet1!V5:Y5,3,0),0) -> 0 | AG23: =+IFERROR(VLOOKUP($AG$17,Sheet1!V5:Y5,3,0),0) -> 0 | AH23: =+IFERROR(VLOOKUP($AH$17,Sheet1!V5:Y5,3,0),0) -> 0 | AI23: =+IFERROR(VLOOKUP($AI$17,Sheet1!V5:Y5,3,0),0) -> 0 | AJ23: =+IFERROR(VLOOKUP($AJ$17,Sheet1!V5:Y5,3,0),0) -> 0 | AK23: 18 | AL23: =+IFERROR(VLOOKUP($AL$17,Sheet1!AD5:AG5,3,0),0) -> 0 | AM23: =+IFERROR(VLOOKUP($AM$17,Sheet1!AD5:AG5,3,0),0) -> 0 | AN23: =+IFERROR(VLOOKUP($AN$17,Sheet1!AD5:AG5,3,0),0) -> 0 | AO23: =+IFERROR(VLOOKUP($AO$17,Sheet1!AD5:AG5,3,0),0) -> 0 | AP23: =+IFERROR(VLOOKUP($AP$17,Sheet1!AD5:AG5,3,0),0) -> 0 | AQ23: 200 | AR23: =+IFERROR(VLOOKUP($AR$17,Sheet1!AD5:AG5,3,0),0) -> 0 | AS23: =+IFERROR(VLOOKUP($AS$17,Sheet1!AH5:AK5,3,0),0) -> 0 | AT23: =+IFERROR(VLOOKUP($AT$17,Sheet1!AH5:AK5,3,0),0) -> 0 | AU23: =+IFERROR(VLOOKUP($AU$17,Sheet1!AH5:AK5,3,0),0) -> 0 | AV23: 828 | AW23: =+IFERROR(VLOOKUP($AW$17,Sheet1!AH5:AK5,3,0),0) -> 0 | AX23: =+IFERROR(VLOOKUP($AX$17,Sheet1!AH5:AK5,3,0),0) -> 0 | AY23: =+IFERROR(VLOOKUP($AY$17,Sheet1!AH5:AK5,3,0),0) -> 0 | AZ23: =+IFERROR(VLOOKUP($AZ$17,Sheet1!AH5:AK5,3,0),0) -> 0 | BA23: =+IFERROR(VLOOKUP($BA$17,Sheet1!AH5:AK5,3,0),0) -> 0 | BB23: =+IFERROR(VLOOKUP($BB$17,Sheet1!AH5:AK5,3,0),0) -> 0 | BC23: =+IFERROR(VLOOKUP($BC$17,Sheet1!AL5:AO5,3,0),0) -> 0 | BD23: =+IFERROR(VLOOKUP($BD$17,Sheet1!AL5:AO5,3,0),0) -> 0 | BE23: =+IFERROR(VLOOKUP($BE$17,Sheet1!AL5:AO5,3,0),0) -> 0 | BF23: 760 | BG23: =+IFERROR(VLOOKUP($BG$17,Sheet1!AL5:AO5,3,0),0) -> 0 | BH23: =+IFERROR(VLOOKUP($BH$17,Sheet1!AL5:AO5,3,0),0) -> 0 | BI23: =+IFERROR(VLOOKUP($BI$17,Sheet1!AL5:AO5,3,0),0) -> 0 | BJ23: =+IFERROR(VLOOKUP($BJ$17,Sheet1!AL5:AO5,3,0),0) -> 0 | BK23: =+IFERROR(VLOOKUP($BK$17,Sheet1!AL5:AO5,3,0),0) -> 0 | BL23: =+IFERROR(VLOOKUP($BL$17,Sheet1!AL5:AO5,3,0),0) -> 0 | BM23: =+IFERROR(VLOOKUP($BM$17,Sheet1!AP5:AS5,3,0),0) -> 0 | BN23: =+IFERROR(VLOOKUP($BN$17,Sheet1!AT5:AW5,3,0),0) -> 0 | BO23: =+IFERROR(VLOOKUP($BO$17,Sheet1!AX5:BA5,3,0),0) -> 0 | BP23: 41 | BQ23: 26 | BR23: =+IFERROR(VLOOKUP($BR$17,Sheet1!BJ5:BM5,3,0),0) -> 0 | BS23: =+IFERROR(VLOOKUP($BS$17,Sheet1!BN5:BQ5,3,0),0) -> 0 | BT23: 42 | BU23: =+IFERROR(VLOOKUP($BU$17,Sheet1!BV5:BY5,3,0),0) -> 0 | BV23: =Sheet1!E5 -> STEEL | BW23: SP0400118 | BX23: CORRUGATED DISPATCH STEEL DRUM 1700 X 1000 X 1200 | BY23: =Sheet1!CX5 -> 500 | BZ23: =20000/0.5 -> 40000 | CA23: =SUMPRODUCT($N$18:$BU$18,N23:BU23)+BZ23 -> 1080562.9 | CB23: 0.01 | CC23: =CA23*CB23 -> 10805.629 | CD23: 0.35 | CE23: =CA23*CD23 -> 378197.01 | CF23: 0 | CG23: =CA23*CF23 -> 0 | CH23: =CA23+CC23+CE23+CG23 -> 1469565.5 | CI23: 0.02 | CJ23: =CH23*CI23 -> 29391.31 | CK23: 0.01 | CL23: =CH23*CK23 -> 14695.655
M24: =SUM(M19:M23) -> 5.6914047e+08
E26: Order Quantity | F26: Stnd Length | G26: Truck type | H26: Fare of one truck | I26: No of Drum in one truck | J26: Total length in one Truck | K26: No of Truck | L26: Total Freight | M26: Freight per KM | Y26: CABLE WEIGHT KG/KM | AC26: DRUM WEIGHT | AE26: CABLE+DRUM WEIGHT | AK26: TRAILOR WEIGHT
C27: =C19 -> FA1300083 | D27: =D19 -> 3 CORE X 400 SQ. MM. AL/ARM - WIRE (XLPE) - 11 KV | E27: =K19 -> 12 | F27: =BY19/1000 -> 0.25 | G27: 25 MT TRAILER | H27: 63000 | I27: 5 | J27: =F27*I27 -> 1.25 | K27: =ROUNDUP((E27/J27),0) -> 10 | L27: =M27*E27 -> 630000 | M27: =(H27*K27)/E27 -> 52500 | N27: =BW19 -> SP0400136 | Y27: =SUM(N19:BT19) -> 13828 | AC27: 470 | AE27: =((Y27*F27)+AC27) -> 3927 | AK27: =I27*AE27 -> 19635
C28: =C20 -> FA1300200 | D28: =D20 -> 3 CORE X 95 SQ. MM. AL/ARM WIRE (XLPE) - 33 KV | E28: =K20 -> 2.5 | F28: =BY20/1000 -> 0.25 | G28: 25 MT TRAILER | H28: 63000 | I28: 7 | J28: =F28*I28 -> 1.75 | K28: =ROUNDUP((E28/J28),0) -> 2 | L28: =M28*E28 -> 126000 | M28: =(H28*K28)/E28 -> 50400 | N28: =BW20 -> SP0400136 | Y28: =SUM(N20:BT20) -> 10376 | AC28: 400 | AE28: =((Y28*F28)+AC28) -> 2994 | AK28: =I28*AE28 -> 20958
C29: =C21 -> FA1300080 | D29: =D21 -> 3 CORE X 400 SQ. MM AL/ARM - WIRE (XLPE) - 33 KV | E29: =K21 -> 17 | F29: =BY21/1000 -> 0.25 | G29: 25 MT TRAILER | H29: 63000 | I29: 4 | J29: =F29*I29 -> 1 | K29: =ROUNDUP((E29/J29),0) -> 17 | L29: =M29*E29 -> 1071000 | M29: =(H29*K29)/E29 -> 63000 | N29: =BW21 -> SP0400137 | Y29: =SUM(N21:BT21) -> 19053 | AC29: 500 | AE29: =((Y29*F29)+AC29) -> 5263.25 | AK29: =I29*AE29 -> 21053
C30: =C22 -> FA1300018 | D30: =D22 -> 1 CORE X 400 SQ. MM. AL/ARM (XLPE) - 33 KV | E30: =K22 -> 5.22 | F30: =BY22/1000 -> 0.5 | G30: 25 MT TRAILER | H30: 63000 | I30: 8 | J30: =F30*I30 -> 4 | K30: =ROUNDUP((E30/J30),0) -> 2 | L30: =M30*E30 -> 126000 | M30: =(H30*K30)/E30 -> 24137.931 | N30: =BW22 -> SP0400126 | Y30: =SUM(N22:BT22) -> 3775 | AC30: 220 | AE30: =((Y30*F30)+AC30) -> 2107.5 | AK30: =I30*AE30 -> 16860
C31: =C23 -> FA1300027 | D31: =D23 -> 1 CORE X 630 SQ. MM. AL/ARM (XLPE) - 33 KV | E31: =K23 -> 238.5 | F31: =BY23/1000 -> 0.5 | G31: 25 MT TRAILER | H31: 63000 | I31: 8 | J31: =F31*I31 -> 4 | K31: =ROUNDUP((E31/J31),0) -> 60 | L31: =M31*E31 -> 3780000 | M31: =(H31*K31)/E31 -> 15849.057 | N31: =BW23 -> SP0400118 | Y31: =SUM(N23:BT23) -> 4968 | AC31: 280 | AE31: =((Y31*F31)+AC31) -> 2764 | AK31: =I31*AE31 -> 22112
C33: 1 | D33: Consider Al rate from- BALCO/ HINDALCO/ NALCO/ Vedanta only.
C34: 2 | D34: Consider mass of zinc coating 290 gm/m2 for each size galvanized steel wire
C35: 3 | D35: Consider Rs. 1 extra for colour of o/sh-FRLSH
C36: 4 | D36: Consider PVC compound rate from- Shakun/Kalpana/KLJ/ DCM ShriRam only
C37: 5 | D37: Consider Steel armour rate from- TATA Steel/Jindal Steel/ SAIL only
C38: 6 | D38: Consider al armour rate from- TATA/BALCO/HINDALCO/NALCO/Vedanta Only
C39: 7 | D39: Consider XLPE compound rate from- Dow/Borealis/Hanwa only.
C40: 8 | D40: Consider Semiconducting compound rate from- Dow/Borealis/Hanwa only.
C41: 9 | D41: Consider 1% extra for complete cable .
A44: DOCKET NO. | B44: Base Date | C44: ITEM CODE | D44: PROPOSE ERP ITEM NAME | E44: EX-WORKS (PER MTR) | F44: FREIGHT PER MTR | G44: PRICE INCLUDING FREIGHT (PER MTR) | H44: GST % | I44: GST VALUE | J44: PRICE INCLUDING GST & FREIGHT (PER MTR) | K44: QTY | L44: Unit | M44: TOTAL PRICE OF FULL QTY (INCLUDING FRIGHT & GST)
A46: =A19 -> ENQ-14722-22-23 | B46: =B19 -> 45638 | C46: =C19 -> FA1300083 | D46: =D19 -> 3 CORE X 400 SQ. MM. AL/ARM - WIRE (XLPE) - 11 KV | E46: =ROUNDUP(E19/1000,2) -> 3040.98 | F46: =ROUNDUP(F19/1000,2) -> 52.5 | G46: =E46+F46 -> 3093.48 | H46: =H19 -> 0.18 | I46: =G46*H46 -> 556.8264 | J46: =G46+I46 -> 3650.3064 | K46: =K19*1000 -> 12000 | L46: MTR | M46: =J46*K46 -> 43803677
A47: =A20 -> ENQ-14722-22-23 | B47: =B20 -> 45638 | C47: =C20 -> FA1300200 | D47: =D20 -> 3 CORE X 95 SQ. MM. AL/ARM WIRE (XLPE) - 33 KV | E47: =ROUNDUP(E20/1000,2) -> 2062.21 | F47: =ROUNDUP(F20/1000,2) -> 50.4 | G47: =E47+F47 -> 2112.61 | H47: =H20 -> 0.18 | I47: =G47*H47 -> 380.2698 | J47: =G47+I47 -> 2492.8798 | K47: =K20*1000 -> 2500 | L47: MTR | M47: =J47*K47 -> 6232199.5
A48: =A21 -> ENQ-14722-22-23 | B48: =B21 -> 45638 | C48: =C21 -> FA1300080 | D48: =D21 -> 3 CORE X 400 SQ. MM AL/ARM - WIRE (XLPE) - 33 KV | E48: =ROUNDUP(E21/1000,2) -> 3996.41 | F48: =ROUNDUP(F21/1000,2) -> 63 | G48: =E48+F48 -> 4059.41 | H48: =H21 -> 0.18 | I48: =G48*H48 -> 730.6938 | J48: =G48+I48 -> 4790.1038 | K48: =K21*1000 -> 17000 | L48: MTR | M48: =J48*K48 -> 81431765
...
