Workbook

Sheet Sheet1
A1: DOCKET NO. | B1: Base Date | C1: ITEM CODE | D1: PROPOSE ERP ITEM NAME | E1: PROPOSE DRUM TYPE | F1: Insulation Screening (Metallic) | G1: RM RATE (Insulation Screening (Metallic)) | H1: Weight (Insulation Screening (Metallic)) | I1: COST(Insulation Screening (Metallic)) | J1: Conductor | K1: RM RATE(Conductor) | L1: WEIGHT(Conductor) | M1: COST(Conductor) | N1: AL ALLOY | O1: RM RATE(Alu Alloy) | P1: WEIGHT(Alu Alloy) | Q1: COST(Alu Alloy) | R1: Insulation Screening (Non-Metallic) | S1: RM RATE(Insulation Screening (Non-Metallic)) | T1: WEIGHT(Insulation Screening (Non-Metallic)) | U1: COST(Insulation Screening (Non-Metallic)) | V1: Insulation | W1: RM RATE(Insulation) | X1: WEIGHT(Insulation) | Y1: COST(Insulation) | Z1: POLY TAPE | AA1: RM RATE (Poly Tape) | AB1: WEIGHT (Poly Tape) | AC1: COST(Poly Tape) | AD1: Inner Sheath | AE1: RM RATE(Inner Sheath) | AF1: WEIGHT(Inner Sheath) | AG1: COST(Inner Sheath) | AH1: Armouring | AI1: RM RATE(Armouring) | AJ1: WEIGHT(Armouring) | AK1: COST(Armouring) | AL1: Outer Sheath | AM1: RM RATE(Outer Sheath) | AN1: WEIGHT(Outer Sheath) | AO1: COST(Outer Sheath) | AP1: FILLER | AQ1: RM RATE(Filler) | AR1: WEIGHT(Filler) | AS1: COST(Filler) | AT1: GREASE | AU1: RM RATE(Grease) | AV1: WEIGHT(Grease) | AW1: COST(Grease) | AX1: Water swellable Tape | AY1: RM RATE(Water swellable Tape) | AZ1: WEIGHT(Water swellable Tape) | BA1: COST(Water swellable Tape) | BB1: Semi conducting Water Swellable tape | BC1: RM RATE(Semi conducting Water Swellable tape) | BD1: WEIGHT(Semi conducting Water Swellable tape) | BE1: COST(Semi conducting Water Swellable tape) | BF1: SEMICON TAPE | BG1: RM RATE(SEMICON TAPE) | BH1: WEIGHT(SEMICON TAPE) | BI1: COST(SEMICON TAPE) | BJ1: GLASS FIBER TAPE | BK1: RM RATE(GLASS FIBER TAPE) | BL1: WEIGHT(GLASS FIBER TAPE) | BM1: COST(GLASS FIBER TAPE) | BN1: COPPER WIRE 0.8 MM | BO1: RM RATE(COPPER WIRE 0.8 MM) | BP1: WEIGHT(COPPER WIRE 0.8 MM) | BQ1: COST(COPPER WIRE 0.8 MM) | BR1: RUBBERIZED COTTON TAPE | BS1: RM RATE(RUBBERIZED COTTON TAPE) | BT1: WEIGHT(RUBBERIZED COTTON TAPE) | BU1: COST(RUBBERIZED COTTON TAPE) | BV1: Water Tight Compound | BW1: RM RATE(Water Tight Compound) | BX1: WEIGHT(Water Tight Compound) | BY1: COST(Water Tight Compound) | BZ1: DRUM COST PER KM | CA1: TOTAL RM COST | CB1: FIRM % | CC1: FIRM VALUE | CD1: MFG% | CE1: MFG VALUE | CF1: PROF% | CG1: PROFIT VALUE | CH1: 1ST EX-WORKS | CI1: Intt % | CJ1: INTT VALUE | CK1: insp% | CL1: INSP VALUE | CM1: EX-WORKS (PER KM) | CN1: FREIGHT PER KM | CO1: PRICE INCLUDING FREIGHT (PER KM) | CP1: GST % | CQ1: GST VALUE | CR1: PRICE INCLUDING GST & FREIGHT (PER KM) | CS1: QTY | CT1: Unit | CU1: TOTAL PRICE OF FULL QTY (INCLUDING FRIGHT & GST) | CV1: DRUM CODE | CW1: DRUM SIZE (FxbXtx Ft) | CX1: PARTY STANDARD LENGTH (MTR)
A2: ENQ-12232-22-23 | B2: 45334 | C2: FA0800011 | D2: 1 CORE X 16 SQ. MM. CU/ARD (PVC) | E2: WOOD | J2: Copper | K2: 740 | L2: 142.24 | M2: 105257.6 | P2: 0 | T2: 0 | V2: Type C PVC (HR) | W2: 103.07 | X2: 40 | Y2: 4122.8 | AB2: 0 | AF2: 0 | AH2: Aluminium Round Wire | AI2: 221 | AJ2: 65 | AK2: 14365 | AL2: FRLSH PVC Type ST-2 | AM2: 92 | AN2: 88 | AO2: 8096 | AR2: 0 | AV2: 0 | AZ2: 0 | BD2: 0 | BH2: 0 | BL2: 15 | BP2: 0 | BT2: 0 | BX2: 0 | BZ2: 3751.68 | CA2: 135593.08 | CH2: 135593.08 | CM2: 135593.08 | CO2: 135593.08 | CP2: 0.18 | CQ2: 24406.75 | CR2: 159999.83 | CS2: 0.12 | CT2: KMS | CU2: 19200 | CV2: MD0100004 | CW2: DRUM - 28 X 10 X 23 X 2 | CX2: 500
A3: ENQ-12232-22-23 | B3: 45334 | C3: FA1100091 | D3: 4 CORE X 240 SQ. MM. AL/ARD - WIRE (XLPE) | E3: WOOD | J3: Alumimium | K3: 216 | L3: 2594.88 | M3: 560494.08 | P3: 0 | T3: 0 | V3: LT-XLPE | W3: 107 | X3: 438 | Y3: 46866 | AB3: 0 | AD3: PVC Type ST-2 | AE3: 60.05 | AF3: 244 | AG3: 14652.2 | AH3: Galvanised Steel Round Wire | AI3: 83.9 | AJ3: 2364 | AK3: 198339.6 | AL3: FRLSH PVC Type ST-2 | AM3: 92 | AN3: 735 | AO3: 67620 | AR3: 0 | AV3: 0 | AX3: Water swellable Tape | AY3: 445 | AZ3: 0 | BA3: 0 | BD3: 0 | BH3: 0 | BL3: 0 | BP3: 0 | BR3: RUBBERIZED COTTON TAPE | BS3: 445 | BT3: 0 | BU3: 0 | BX3: 0 | BZ3: 27302 | CA3: 915273.88 | CH3: 915273.88 | CM3: 915273.88 | CO3: 915273.88 | CP3: 0.18 | CQ3: 164749.3 | CR3: 1080023.2 | CS3: 1 | CT3: KMS | CU3: 1080023 | CV3: MD0100048 | CW3: DRUM - 74 X 35 X 39 X 3 | CX3: 500
A4: ENQ-12232-22-23 | B4: 45334 | C4: FA0900125 | D4: 4 CORE X 16 SQ. MM. CU/ARD - WIRE (PVC) | E4: WOOD | J4: Copper | K4: 740 | L4: 568.96 | M4: 421030.4 | P4: 0 | T4: 0 | V4: Type C PVC (HR) | W4: 103.07 | X4: 114 | Y4: 11749.98 | AB4: 0 | AD4: PVC Type ST-2 | AE4: 60.05 | AF4: 40 | AG4: 2402 | AH4: Galvanised Steel Round Wire | AI4: 83.9 | AJ4: 498 | AK4: 41782.2 | AL4: FRLSH PVC Type ST-2 | AM4: 92 | AN4: 166 | AO4: 15272 | AR4: 0 | AV4: 0 | AZ4: 0 | BD4: 0 | BH4: 0 | BL4: 0 | BP4: 0 | BT4: 0 | BX4: 0 | BZ4: 5151.48 | CA4: 497388.06 | CH4: 497388.06 | CM4: 497388.06 | CO4: 497388.06 | CP4: 0.18 | CQ4: 89529.85 | CR4: 586917.91 | CS4: 1.5 | CT4: KMS | CU4: 880377 | CV4: MD0100066 | CW4: DRUM - 40 X 15 X 23 X 2 | CX4: 500
A5: ENQ-12232-22-23 | B5: 45334 | C5: FA0900024 | D5: 4 CORE X 4 SQ. MM. CU/ARD - WIRE (PVC) | E5: WOOD | J5: Copper | K5: 740 | L5: 144 | M5: 106560 | P5: 0 | T5: 0 | V5: Type C PVC (HR) | W5: 103.07 | X5: 76 | Y5: 7833.32 | Z5: POLY TAPE | AA5: 119.6 | AB5: 4 | AC5: 478.4 | AD5: PVC Type ST-2 | AE5: 60.05 | AF5: 34 | AG5: 2041.7 | AH5: Galvanised Steel Round Wire | AI5: 83.9 | AJ5: 352 | AK5: 29532.8 | AL5: FRLSH PVC Type ST-2 | AM5: 92 | AN5: 119 | AO5: 10948 | AR5: 0 | AV5: 0 | AZ5: 0 | BD5: 0 | BH5: 0 | BL5: 0 | BP5: 0 | BT5: 0 | BX5: 0 | BZ5: 4610.79 | CA5: 162005.01 | CH5: 162005.01 | CM5: 162005.01 | CO5: 162005.01 | CP5: 0.18 | CQ5: 29160.9 | CR5: 191165.91 | CS5: 2 | CT5: KMS | CU5: 382332 | CV5: MD0100005 | CW5: DRUM - 36 X 14 X 23 X 2 | CX5: 500
A6: ENQ-12232-22-23 | B6: 45334 | C6: FA0900148 | D6: 2 CORE X 16 SQ. MM. CU/ARD - WIRE (PVC) | E6: WOOD | J6: Copper | K6: 740 | L6: 284.48 | M6: 210515.2 | P6: 0 | T6: 0 | V6: Type C PVC (HR) | W6: 103.07 | X6: 57 | Y6: 5874.99 | AB6: 0 | AD6: PVC Type ST-2 | AE6: 60.05 | AF6: 33 | AG6: 1981.65 | AH6: Galvanised Steel Round Wire | AI6: 83.9 | AJ6: 416 | AK6: 34902.4 | AL6: FRLSH PVC Type ST-2 | AM6: 92 | AN6: 144 | AO6: 13248 | AR6: 0 | AV6: 0 | AZ6: 0 | BD6: 0 | BH6: 0 | BL6: 0 | BP6: 0 | BT6: 0 | BX6: 0 | BZ6: 4610.79 | CA6: 271133.03 | CH6: 271133.03 | CM6: 271133.03 | CO6: 271133.03 | CP6: 0.18 | CQ6: 48803.95 | CR6: 319936.98 | CS6: 2.12 | CT6: KMS | CU6: 678266 | CV6: MD0100005 | CW6: DRUM - 36 X 14 X 23 X 2 | CX6: 500
A7: ENQ-12232-22-23 | B7: 45334 | C7: FA0900022 | D7: 4 CORE X 10 SQ. MM. CU/ARD - WIRE (PVC) | E7: WOOD | J7: Copper | K7: 740 | L7: 355.6 | M7: 263144 | P7: 0 | T7: 0 | V7: Type A PVC-1.45 | W7: 73.07 | X7: 98 | Y7: 7160.86 | AB7: 0 | AD7: PVC Type ST-1 | AE7: 58.05 | AF7: 35 | AG7: 2031.75 | AH7: Galvanised Steel Round Wire | AI7: 83.9 | AJ7: 441 | AK7: 36999.9 | AL7: PVC Type ST-1 | AM7: 58.05 | AN7: 151 | AO7: 8765.55 | AR7: 0 | AV7: 0 | AZ7: 0 | BD7: 0 | BH7: 0 | BL7: 0 | BP7: 0 | BT7: 0 | BX7: 0 | BZ7: 5151.48 | CA7: 323253.54 | CH7: 323253.54 | CM7: 323253.54 | CO7: 323253.54 | CP7: 0.18 | CQ7: 58185.64 | CR7: 381439.18 | CS7: 3 | CT7: KMS | CU7: 1144318 | CV7: MD0100066 | CW7: DRUM - 40 X 15 X 23 X 2 | CX7: 500
A8: ENQ-12232-22-23 | B8: 45334 | C8: FA0900165 | D8: 2 CORE X 50 SQ. MM. CU/ARD - WIRE (PVC) | E8: WOOD | J8: Copper | K8: 740 | L8: 860 | M8: 636400 | P8: 0 | T8: 0 | V8: Type C PVC (HR) | W8: 103.07 | X8: 132 | Y8: 13605.24 | AB8: 0 | AD8: PVC Type ST-2 | AE8: 60.05 | AF8: 50 | AG8: 3002.5 | AH8: Galvanised Steel Round Wire | AI8: 83.9 | AJ8: 575 | AK8: 48242.5 | AL8: FRLSH PVC Type ST-2 | AM8: 92 | AN8: 204 | AO8: 18768 | AR8: 0 | AV8: 0 | AZ8: 0 | BD8: 0 | BH8: 0 | BL8: 0 | BP8: 0 | BT8: 0 | BX8: 0 | BZ8: 7084.06 | CA8: 727102.3 | CH8: 727102.3 | CM8: 727102.3 | CO8: 727102.3 | CP8: 0.18 | CQ8: 130878.41 | CR8: 857980.71 | CS8: 3.65 | CT8: KMS | CU8: 3131630 | CV8: MD0100075 | CW8: DRUM - 42 X 15 X 23 X 2 | CX8: 500
A9: ENQ-12232-22-23 | B9: 45334 | C9: FA0500017 | D9: 1 CORE X 50 SQ. MM. AL/UNARD. (XLPE) | E9: WOOD | J9: Alumimium | K9: 216 | L9: 135 | M9: 29160 | P9: 0 | T9: 0 | V9: LT-XLPE | W9: 107 | X9: 37 | Y9: 3959 | AB9: 0 | AF9: 0 | AJ9: 0 | AL9: FRLSH PVC Type ST-2 | AM9: 92 | AN9: 110 | AO9: 10120 | AR9: 0 | AV9: 0 | AZ9: 0 | BD9: 0 | BH9: 0 | BL9: 0 | BP9: 0 | BT9: 0 | BX9: 0 | BZ9: 2305.4 | CA9: 45544.4 | CH9: 45544.4 | CM9: 45544.4 | CO9: 45544.4 | CP9: 0.18 | CQ9: 8197.99 | CR9: 53742.39 | CS9: 6.5 | CT9: KMS | CU9: 349326 | CV9: MD0100005 | CW9: DRUM - 36 X 14 X 23 X 2 | CX9: 1000
A10: ENQ-12232-22-23 | B10: 45334 | C10: FA1200026 | D10: 4 CORE X 150 SQ. MM. AL/UNARD (XLPE) | E10: WOOD | J10: Alumimium | K10: 216 | L10: 1620 | M10: 349920 | P10: 0 | T10: 0 | V10: LT-XLPE | W10: 107 | X10: 297 | Y10: 31779 | AB10: 0 | AD10: PVC Type ST-2 | AE10: 60.05 | AF10: 138 | AG10: 8286.9 | AJ10: 0 | AL10: FRLSH PVC Type ST-2 | AM10: 92 | AN10: 552 | AO10: 50784 | AR10: 0 | AV10: 0 | AX10: Water swellable Tape | AY10: 445 | AZ10: 0 | BA10: 0 | BD10: 0 | BH10: 0 | BL10: 0 | BP10: 0 | BT10: 0 | BX10: 0 | BZ10: 17878.84 | CA10: 458648.74 | CH10: 458648.74 | CM10: 458648.74 | CO10: 458648.74 | CP10: 0.18 | CQ10: 82556.77 | CR10: 541205.51 | CS10: 7.925 | CT10: KMS | CU10: 4289054 | CV10: MD0100070 | CW10: DRUM - 68 X 24 X 32 X 3 | CX10: 500
A11: ENQ-12232-22-23 | B11: 45334 | C11: FA0900117 | D11: 4 CORE X 35 SQ. MM. AL/ARD - WIRE (XLPE) | E11: WOOD | J11: Alumimium | K11: 216 | L11: 378.42 | M11: 81738.72 | P11: 0 | T11: 0 | V11: LT-XLPE | W11: 107 | X11: 109 | Y11: 11663 | AB11: 0 | AD11: PVC Type ST-2 | AE11: 60.05 | AF11: 51 | AG11: 3062.55 | AH11: Galvanised Steel Round Wire | AI11: 83.9 | AJ11: 639 | AK11: 53612.1 | AL11: FRLSH PVC Type ST-2 | AM11: 92 | AN11: 230 | AO11: 21160 | AR11: 0 | AV11: 0 | AZ11: 0 | BD11: 0 | BH11: 0 | BL11: 0 | BP11: 0 | BR11: RUBBERIZED COTTON TAPE | BS11: 445 | BT11: 0 | BU11: 0 | BX11: 0 | BZ11: 3743.02 | CA11: 174979.39 | CH11: 174979.39 | CM11: 174979.39 | CO11: 174979.39 | CP11: 0.18 | CQ11: 31496.29 | CR11: 206475.68 | CS11: 10.2 | CT11: KMS | CU11: 2106052 | CV11: MD0100013 | CW11: DRUM - 48 X 14 X 36 X 2.25 | CX11: 1000
A12: ENQ-12232-22-23 | B12: 45334 | C12: FA0900116 | D12: 4 CORE X 50 SQ. MM. AL/ARD - WIRE (XLPE) | E12: WOOD | J12: Alumimium | K12: 216 | L12: 540.6 | M12: 116769.6 | P12: 0 | T12: 0 | V12: LT-XLPE | W12: 107 | X12: 124 | Y12: 13268 | AB12: 0 | AD12: PVC Type ST-2 | AE12: 60.05 | AF12: 69 | AG12: 4143.45 | AH12: Galvanised Steel Round Wire | AI12: 83.9 | AJ12: 898 | AK12: 75342.2 | AL12: FRLSH PVC Type ST-2 | AM12: 92 | AN12: 260 | AO12: 23920 | AR12: 0 | AV12: 0 | AZ12: 0 | BD12: 0 | BH12: 0 | BL12: 0 | BP12: 0 | BR12: RUBBERIZED COTTON TAPE | BS12: 445 | BT12: 0 | BU12: 0 | BX12: 0 | BZ12: 5708.97 | CA12: 239152.22 | CH12: 239152.22 | CM12: 239152.22 | CO12: 239152.22 | CP12: 0.18 | CQ12: 43047.4 | CR12: 282199.62 | CS12: 13.67 | CT12: KMS | CU12: 3857669 | CV12: MD0100068 | CW12: DRUM - 54 X 20 X 36 X 2.5 | CX12: 1000
A13: ENQ-12232-22-23 | B13: 45334 | C13: FA0300006 | D13: 4 CORE X 2.5 SQ. MM. CU/UNARD.(PVC) | E13: WOOD | J13: Copper | K13: 740 | L13: 88.8 | M13: 65712 | P13: 0 | T13: 0 | V13: Type C PVC (HR) | W13: 103.07 | X13: 52 | Y13: 5359.64 | Z13: POLY TAPE | AA13: 119.6 | AB13: 4 | AC13: 478.4 | AD13: PVC Type ST-2 | AE13: 60.05 | AF13: 27 | AG13: 1621.35 | AJ13: 0 | AL13: FRLSH PVC Type ST-2 | AM13: 92 | AN13: 109 | AO13: 10028 | AR13: 0 | AV13: 0 | AZ13: 0 | BD13: 0 | BH13: 0 | BL13: 15 | BP13: 0 | BT13: 0 | BX13: 0 | BZ13: 3850.93 | CA13: 87050.32 | CH13: 87050.32 | CM13: 87050.32 | CO13: 87050.32 | CP13: 0.18 | CQ13: 15669.06 | CR13: 102719.38 | CS13: 16.3 | CT13: KMS | CU13: 1674326 | CV13: MD0100003 | CW13: DRUM - 28 X 14 X 23 X 2 | CX13: 500
A14: ENQ-12232-22-23 | B14: 45334 | C14: FA0300017 | D14: 16 CORE X 2.5 SQ. MM. CU/UNARD.(PVC) | E14: WOOD | J14: Copper | K14: 740 | L14: 355.2 | M14: 262848 | P14: 0 | T14: 0 | V14: Type C PVC (HR) | W14: 103.07 | X14: 208 | Y14: 21438.56 | Z14: POLY TAPE | AA14: 119.6 | AB14: 5 | AC14: 598 | AD14: PVC Type ST-2 | AE14: 60.05 | AF14: 42 | AG14: 2522.1 | AJ14: 0 | AL14: FRLSH PVC Type ST-2 | AM14: 92 | AN14: 191 | AO14: 17572 | AR14: 0 | AV14: 0 | AZ14: 0 | BD14: 0 | BH14: 0 | BL14: 0 | BP14: 0 | BT14: 0 | BX14: 0 | BZ14: 7084.06 | CA14: 312062.72 | CH14: 312062.72 | CM14: 312062.72 | CO14: 312062.72 | CP14: 0.18 | CQ14: 56171.29 | CR14: 368234.01 | CS14: 18.5 | CT14: KMS | CU14: 6812329 | CV14: MD0100075 | CW14: DRUM - 42 X 15 X 23 X 2 | CX14: 500
A15: ENQ-12232-22-23 | B15: 45334 | C15: FA0600021 | D15: 1 CORE X 185 SQ. MM. AL/UNARD. (XLPE) | E15: WOOD | J15: Alumimium | K15: 216 | L15: 499.5 | M15: 107892 | P15: 0 | T15: 0 | V15: LT-XLPE | W15: 107 | X15: 90 | Y15: 9630 | AB15: 0 | AF15: 0 | AJ15: 0 | AL15: FRLSH PVC Type ST-2 | AM15: 92 | AN15: 207 | AO15: 19044 | AR15: 0 | AV15: 0 | AX15: Water swellable Tape | AY15: 445 | AZ15: 0 | BA15: 0 | BD15: 0 | BH15: 0 | BL15: 0 | BP15: 0 | BT15: 0 | BX15: 0 | BZ15: 3505.61 | CA15: 140071.61 | CH15: 140071.61 | CM15: 140071.61 | CO15: 140071.61 | CP15: 0.18 | CQ15: 25212.89 | CR15: 165284.5 | CS15: 20 | CT15: KMS | CU15: 3305690 | CV15: MD0100090 | CW15: DRUM - 43 X 15 X 36 X 2.5 | CX15: 1000
A16: ENQ-12232-22-23 | B16: 45334 | C16: FA1100177 | D16: 4 CORE X 150 SQ. MM. AL/ARD - WIRE (XLPE) | E16: WOOD | J16: Alumimium | K16: 216 | L16: 1620 | M16: 349920 | P16: 0 | T16: 0 | V16: LT-XLPE | W16: 107 | X16: 276 | Y16: 29532 | AB16: 0 | AD16: PVC Type ST-2 | AE16: 60.05 | AF16: 148 | AG16: 8887.4 | AH16: Galvanised Steel Round Wire | AI16: 83.9 | AJ16: 1965 | AK16: 164863.5 | AL16: FRLSH PVC Type ST-2 | AM16: 92 | AN16: 543 | AO16: 49956 | AR16: 0 | AV16: 0 | AX16: Water swellable Tape | AY16: 445 | AZ16: 0 | BA16: 0 | BD16: 48 | BH16: 0 | BL16: 0 | BP16: 0 | BR16: RUBBERIZED COTTON TAPE | BS16: 445 | BT16: 26 | BU16: 11570 | BX16: 0 | BZ16: 18867.25 | CA16: 633596.15 | CH16: 633596.15 | CM16: 633596.15 | CO16: 633596.15 | CP16: 0.18 | CQ16: 114047.31 | CR16: 747643.46 | CS16: 22.17 | CT16: KMS | CU16: 16575255 | CV16: MD0100024 | CW16: DRUM - 70 X 30 X 36 X 3 | CX16: 500
A17: ENQ-12232-22-23 | B17: 45334 | C17: FA0300011 | D17: 10 CORE X 2.5 SQ. MM. CU/UNARD. (PVC) | E17: WOOD | J17: Copper | K17: 740 | L17: 222 | M17: 164280 | P17: 0 | T17: 0 | V17: Type C PVC (HR) | W17: 103.07 | X17: 130 | Y17: 13399.1 | Z17: POLY TAPE | AA17: 119.6 | AB17: 5 | AC17: 598 | AD17: PVC Type ST-2 | AE17: 60.05 | AF17: 36 | AG17: 2161.8 | AJ17: 0 | AL17: FRLSH PVC Type ST-2 | AM17: 92 | AN17: 165 | AO17: 15180 | AR17: 0 | AV17: 0 | AZ17: 0 | BD17: 0 | BH17: 0 | BL17: 0 | BP17: 0 | BT17: 0 | BX17: 0 | BZ17: 5151.48 | CA17: 200770.38 | CH17: 200770.38 | CM17: 200770.38 | CO17: 200770.38 | CP17: 0.18 | CQ17: 36138.67 | CR17: 236909.05 | CS17: 22.3 | CT17: KMS | CU17: 5283072 | CV17: MD0100066 | CW17: DRUM - 40 X 15 X 23 X 2 | CX17: 500
A18: ENQ-12232-22-23 | B18: 45334 | C18: FA1100176 | D18: 4 CORE X 300 SQ. MM. AL/ARD - WIRE (XLPE) | E18: WOOD | J18: Alumimium | K18: 216 | L18: 3240 | M18: 699840 | P18: 0 | T18: 0 | V18: LT-XLPE | W18: 107 | X18: 488 | Y18: 52216 | AB18: 0 | AD18: PVC Type ST-2 | AE18: 60.05 | AF18: 255 | AG18: 15312.75 | AH18: Galvanised Steel Round Wire | AI18: 83.9 | AJ18: 3436 | AK18: 288280.4 | AL18: FRLSH PVC Type ST-2 | AM18: 92 | AN18: 888 | AO18: 81696 | AR18: 0 | AV18: 0 | AX18: Water swellable Tape | AY18: 445 | AZ18: 0 | BA18: 0 | BD18: 90 | BH18: 0 | BL18: 0 | BP18: 0 | BR18: RUBBERIZED COTTON TAPE | BS18: 445 | BT18: 36 | BU18: 16020 | BX18: 0 | BZ18: 47086 | CA18: 1200451.1 | CH18: 1200451.1 | CM18: 1200451.1 | CO18: 1200451.1 | CP18: 0.18 | CQ18: 216081.21 | CR18: 1416532.4 | CS18: 34.32 | CT18: KMS | CU18: 48615390 | CV18: MD0100040 | CW18: DRUM - 86 X 38 X 46 X 4 | CX18: 500
A19: ENQ-12232-22-23 | B19: 45334 | C19: FA0600019 | D19: 1 CORE X 150 SQ. MM. AL/UNARD. (XLPE) | E19: WOOD | J19: Alumimium | K19: 216 | L19: 405 | M19: 87480 | P19: 0 | T19: 0 | V19: LT-XLPE | W19: 107 | X19: 72 | Y19: 7704 | AB19: 0 | AF19: 0 | AJ19: 0 | AL19: FRLSH PVC Type ST-2 | AM19: 92 | AN19: 187 | AO19: 17204 | AR19: 0 | AV19: 0 | AX19: Water swellable Tape | AY19: 445 | AZ19: 0 | BA19: 0 | BD19: 0 | BH19: 0 | BL19: 0 | BP19: 0 | BT19: 0 | BX19: 0 | BZ19: 3257.88 | CA19: 115645.88 | CH19: 115645.88 | CM19: 115645.88 | CO19: 115645.88 | CP19: 0.18 | CQ19: 20816.26 | CR19: 136462.14 | CS19: 47.838 | CT19: KMS | CU19: 6528076 | CV19: MD0100085 | CW19: DRUM - 43 X 15 X 28 X 2.25 | CX19: 1000
A20: ENQ-12232-22-23 | B20: 45334 | C20: FA0200003 | D20: 12 CORE X 2.5 SQ. MM. CU/ARD - WIRE (PVC) | E20: WOOD | J20: Copper | K20: 740 | L20: 266.4 | M20: 197136 | P20: 0 | T20: 0 | V20: Type C PVC (HR) | W20: 103.07 | X20: 156 | Y20: 16078.92 | Z20: POLY TAPE | AA20: 119.6 | AB20: 6 | AC20: 717.6 | AD20: PVC Type ST-2 | AE20: 60.05 | AF20: 40 | AG20: 2402 | AH20: Galvanised Steel Round Wire | AI20: 83.9 | AJ20: 508 | AK20: 42621.2 | AL20: FRLSH PVC Type ST-2 | AM20: 92 | AN20: 170 | AO20: 15640 | AR20: 0 | AV20: 0 | AZ20: 0 | BD20: 0 | BH20: 0 | BL20: 28 | BP20: 0 | BT20: 0 | BX20: 0 | BZ20: 5151.48 | CA20: 279747.2 | CH20: 279747.2 | CM20: 279747.2 | CO20: 279747.2 | CP20: 0.18 | CQ20: 50354.5 | CR20: 330101.7 | CS20: 62.667 | CT20: KMS | CU20: 20686483 | CV20: MD0100066 | CW20: DRUM - 40 X 15 X 23 X 2 | CX20: 500
A21: ENQ-12232-22-23 | B21: 45334 | C21: FA0600020 | D21: 1 CORE X 300 SQ. MM. AL/UNARD. (XLPE) | E21: WOOD | J21: Alumimium | K21: 216 | L21: 810 | M21: 174960 | P21: 0 | T21: 0 | V21: LT-XLPE | W21: 107 | X21: 132 | Y21: 14124 | AB21: 0 | AF21: 0 | AJ21: 0 | AL21: FRLSH PVC Type ST-2 | AM21: 92 | AN21: 251 | AO21: 23092 | AR21: 0 | AV21: 0 | AX21: Water swellable Tape | AY21: 445 | AZ21: 0 | BA21: 0 | BD21: 0 | BH21: 0 | BL21: 0 | BP21: 0 | BT21: 0 | BX21: 0 | BZ21: 4956.84 | CA21: 217132.84 | CH21: 217132.84 | CM21: 217132.84 | CO21: 217132.84 | CP21: 0.18 | CQ21: 39083.91 | CR21: 256216.75 | CS21: 63.368 | CT21: KMS | CU21: 16235943 | CV21: MD0100017 | CW21: DRUM - 52 X 18 X 36 X 2.5 | CX21: 1000
A22: ENQ-12232-22-23 | B22: 45334 | C22: FA0600032 | D22: 1 CORE X 630 SQ. MM. ALU/UNARD (XLPE) | E22: WOOD | J22: Alumimium | K22: 216 | L22: 1701 | M22: 367416 | P22: 0 | T22: 0 | V22: LT-XLPE | W22: 107 | X22: 253 | Y22: 27071 | AB22: 0 | AF22: 0 | AJ22: 0 | AL22: FRLSH PVC Type ST-2 | AM22: 92 | AN22: 429 | AO22: 39468 | AR22: 0 | AV22: 0 | AX22: Water swellable Tape | AY22: 445 | AZ22: 0 | BA22: 0 | BD22: 0 | BH22: 0 | BL22: 0 | BP22: 0 | BT22: 0 | BX22: 0 | BZ22: 17290 | CA22: 451245 | CH22: 451245 | CM22: 451245 | CO22: 451245 | CP22: 0.18 | CQ22: 81224.1 | CR22: 532469.1 | CS22: 81.688 | CT22: KMS | CU22: 43496336 | CV22: MD0100062 | CW22: DRUM - 74 X 24 X 32 X 3 | CX22: 1000
A23: ENQ-12232-22-23 | B23: 45334 | C23: FA0600013 | D23: 1 CORE X 95 SQ. MM. AL/UNARD(XLPE ) | E23: WOOD | J23: Alumimium | K23: 216 | L23: 256.5 | M23: 55404 | P23: 0 | T23: 0 | V23: LT-XLPE | W23: 107 | X23: 53 | Y23: 5671 | AB23: 0 | AF23: 0 | AJ23: 0 | AL23: FRLSH PVC Type ST-2 | AM23: 92 | AN23: 139 | AO23: 12788 | AR23: 0 | AV23: 0 | AZ23: 0 | BD23: 0 | BH23: 0 | BL23: 0 | BP23: 0 | BT23: 0 | BX23: 0 | BZ23: 2575.74 | CA23: 76438.74 | CH23: 76438.74 | CM23: 76438.74 | CO23: 76438.74 | CP23: 0.18 | CQ23: 13758.97 | CR23: 90197.71 | CS23: 82.208 | CT23: KMS | CU23: 7414974 | CV23: MD0100066 | CW23: DRUM - 40 X 15 X 23 X 2 | CX23: 1000
A24: ENQ-12232-22-23 | B24: 45334 | C24: FA0200002 | D24: 10 CORE X 2.5 SQ. MM. CU/ARD - WIRE (PVC) | E24: WOOD | J24: Copper | K24: 740 | L24: 222 | M24: 164280 | P24: 0 | T24: 0 | V24: Type C PVC (HR) | W24: 103.07 | X24: 130 | Y24: 13399.1 | Z24: POLY TAPE | AA24: 119.6 | AB24: 5 | AC24: 598 | AD24: PVC Type ST-2 | AE24: 60.05 | AF24: 38 | AG24: 2281.9 | AH24: Galvanised Steel Round Wire | AI24: 83.9 | AJ24: 492 | AK24: 41278.8 | AL24: FRLSH PVC Type ST-2 | AM24: 92 | AN24: 166 | AO24: 15272 | AR24: 0 | AV24: 0 | AZ24: 0 | BD24: 0 | BH24: 0 | BL24: 28 | BP24: 0 | BT24: 0 | BX24: 0 | BZ24: 5151.48 | CA24: 242261.28 | CH24: 242261.28 | CM24: 242261.28 | CO24: 242261.28 | CP24: 0.18 | CQ24: 43607.03 | CR24: 285868.31 | CS24: 83.006 | CT24: KMS | CU24: 23728785 | CV24: MD0100066 | CW24: DRUM - 40 X 15 X 23 X 2 | CX24: 500
A25: ENQ-12232-22-23 | B25: 45334 | C25: FA0200018 | D25: 7 CORE X 2.5 SQ. MM. CU/ARD - WIRE (PVC) | E25: WOOD | J25: Copper | K25: 740 | L25: 155.4 | M25: 114996 | P25: 0 | T25: 0 | V25: Type C PVC (HR) | W25: 103.07 | X25: 91 | Y25: 9379.37 | Z25: POLY TAPE | AA25: 119.6 | AB25: 4 | AC25: 478.4 | AD25: PVC Type ST-2 | AE25: 60.05 | AF25: 30 | AG25: 1801.5 | AH25: Galvanised Steel Round Wire | AI25: 83.9 | AJ25: 339 | AK25: 28442.1 | AL25: FRLSH PVC Type ST-2 | AM25: 92 | AN25: 120 | AO25: 11040 | AR25: 0 | AV25: 0 | AZ25: 0 | BD25: 0 | BH25: 0 | BL25: 22 | BP25: 0 | BT25: 0 | BX25: 0 | BZ25: 4610.79 | CA25: 170748.16 | CH25: 170748.16 | CM25: 170748.16 | CO25: 170748.16 | CP25: 0.18 | CQ25: 30734.67 | CR25: 201482.83 | CS25: 86.355 | CT25: KMS | CU25: 17399050 | CV25: MD0100005 | CW25: DRUM - 36 X 14 X 23 X 2 | CX25: 500
A26: ENQ-12232-22-23 | B26: 45334 | C26: FA0900042 | D26: 2 CORE X 10 SQ. MM. ALU/ARD - WIRE (XLPE) | E26: WOOD | J26: Alumimium | K26: 216 | L26: 54 | M26: 11664 | P26: 0 | T26: 0 | V26: LT-XLPE | W26: 107 | X26: 31 | Y26: 3317 | AB26: 0 | AD26: PVC Type ST-2-PRESSURE EXTRUDED | AE26: 88 | AF26: 112 | AG26: 9856 | AH26: Galvanised Steel Round Wire | AI26: 83.9 | AJ26: 360 | AK26: 30204 | AL26: FRLSH PVC Type ST-2 | AM26: 92 | AN26: 130 | AO26: 11960 | AR26: 0 | AV26: 0 | AZ26: 0 | BD26: 0 | BH26: 0 | BL26: 0 | BP26: 0 | BR26: RUBBERIZED COTTON TAPE | BS26: 445 | BT26: 0 | BU26: 0 | BX26: 0 | BZ26: 3542.03 | CA26: 70543.03 | CH26: 70543.03 | CM26: 70543.03 | CO26: 70543.03 | CP26: 0.18 | CQ26: 12697.75 | CR26: 83240.78 | CS26: 88.713 | CT26: KMS | CU26: 7384539 | CV26: MD0100075 | CW26: DRUM - 42 X 15 X 23 X 2 | CX26: 1000
A27: ENQ-12232-22-23 | B27: 45334 | C27: FA0200011 | D27: 4 CORE X 2.5 SQ. MM. CU/ARD - WIRE (PVC) | E27: WOOD | J27: Copper | K27: 740 | L27: 88.8 | M27: 65712 | P27: 0 | T27: 0 | V27: Type C PVC (HR) | W27: 103.07 | X27: 52 | Y27: 5359.64 | Z27: POLY TAPE | AA27: 119.6 | AB27: 3 | AC27: 358.8 | AD27: PVC Type ST-2 | AE27: 60.05 | AF27: 27 | AG27: 1621.35 | AH27: Galvanised Steel Round Wire | AI27: 83.9 | AJ27: 289 | AK27: 24247.1 | AL27: FRLSH PVC Type ST-2 | AM27: 92 | AN27: 104 | AO27: 9568 | AR27: 0 | AV27: 0 | AZ27: 0 | BD27: 0 | BH27: 0 | BL27: 19 | BP27: 0 | BT27: 0 | BX27: 0 | BZ27: 4610.79 | CA27: 111477.68 | CH27: 111477.68 | CM27: 111477.68 | CO27: 111477.68 | CP27: 0.18 | CQ27: 20065.98 | CR27: 131543.66 | CS27: 167.188 | CT27: KMS | CU27: 21992522 | CV27: MD0100005 | CW27: DRUM - 36 X 14 X 23 X 2 | CX27: 500
A28: ENQ-12232-22-23 | B28: 45334 | C28: FA0900111 | D28: 4 CORE X 25 SQ. MM. ALU/ARD - WIRE (XLPE) | E28: WOOD | J28: Alumimium | K28: 216 | L28: 270.3 | M28: 58384.8 | P28: 0 | T28: 0 | V28: LT-XLPE | W28: 107 | X28: 95 | Y28: 10165 | AB28: 0 | AD28: PVC Type ST-2 | AE28: 60.05 | AF28: 46 | AG28: 2762.3 | AH28: Galvanised Steel Round Wire | AI28: 83.9 | AJ28: 572 | AK28: 47990.8 | AL28: FRLSH PVC Type ST-2 | AM28: 92 | AN28: 185 | AO28: 17020 | AR28: 0 | AV28: 0 | AZ28: 0 | BD28: 0 | BH28: 0 | BL28: 0 | BP28: 0 | BT28: 0 | BX28: 0 | BZ28: 3505.61 | CA28: 139828.51 | CH28: 139828.51 | CM28: 139828.51 | CO28: 139828.51 | CP28: 0.18 | CQ28: 25169.13 | CR28: 164997.64 | CS28: 172.516 | CT28: KMS | CU28: 28464733 | CV28: MD0100090 | CW28: DRUM - 43 X 15 X 36 X 2.5 | CX28: 1000
A29: ENQ-12232-22-23 | B29: 45334 | C29: FA0900112 | D29: 4 CORE X 10 SQ. MM. AL/ARD - WIRE (XLPE) | E29: WOOD | J29: Alumimium | K29: 216 | L29: 108.12 | M29: 23353.92 | P29: 0 | T29: 0 | V29: LT-XLPE | W29: 107 | X29: 64 | Y29: 6848 | AB29: 0 | AD29: PVC Type ST-2 | AE29: 60.05 | AF29: 35 | AG29: 2101.75 | AH29: Galvanised Steel Round Wire | AI29: 83.9 | AJ29: 441 | AK29: 36999.9 | AL29: FRLSH PVC Type ST-2 | AM29: 92 | AN29: 151 | AO29: 13892 | AR29: 0 | AV29: 0 | AZ29: 0 | BD29: 0 | BH29: 0 | BL29: 0 | BP29: 0 | BT29: 0 | BX29: 0 | BZ29: 4155.88 | CA29: 87351.45 | CH29: 87351.45 | CM29: 87351.45 | CO29: 87351.45 | CP29: 0.18 | CQ29: 15723.26 | CR29: 103074.71 | CS29: 223.526 | CT29: KMS | CU29: 23039878 | CV29: MD0100064 | CW29: DRUM - 42 X 15 X 32 X 2 | CX29: 1000
A30: ENQ-12232-22-23 | B30: 45334 | C30: FA1100094 | D30: 4 CORE X 95 SQ. MM. ALU/ARD - WIRE (XLPE) | E30: WOOD | J30: Alumimium | K30: 216 | L30: 1027.14 | M30: 221862.24 | P30: 0 | T30: 0 | V30: LT-XLPE | W30: 107 | X30: 187 | Y30: 20009 | AB30: 0 | AD30: PVC Type ST-2 | AE30: 60.05 | AF30: 93 | AG30: 5584.65 | AH30: Galvanised Steel Round Wire | AI30: 83.9 | AJ30: 1200 | AK30: 100680 | AL30: FRLSH PVC Type ST-2 | AM30: 92 | AN30: 370 | AO30: 34040 | AR30: 0 | AV30: 0 | AZ30: 0 | BD30: 0 | BH30: 0 | BL30: 0 | BP30: 0 | BR30: RUBBERIZED COTTON TAPE | BS30: 445 | BT30: 0 | BU30: 0 | BX30: 0 | BZ30: 13713.74 | CA30: 395889.63 | CH30: 395889.63 | CM30: 395889.63 | CO30: 395889.63 | CP30: 0.18 | CQ30: 71260.13 | CR30: 467149.76 | CS30: 249.27 | CT30: KMS | CU30: 116446422 | CV30: MD0100061 | CW30: DRUM - 56 X 24 X 32 X 3 | CX30: 500
A31: ENQ-12232-22-23 | B31: 45334 | C31: FA0900020 | D31: 2 CORE X 6 SQ. MM. AL/ARD - WIRE (XLPE) | E31: WOOD | J31: Alumimium | K31: 216 | L31: 33.1 | M31: 7149.6 | P31: 0 | T31: 0 | V31: LT-XLPE | W31: 107 | X31: 26 | Y31: 2782 | AB31: 0 | AD31: PVC Type ST-2-PRESSURE EXTRUDED | AE31: 88 | AF31: 57 | AG31: 5016 | AH31: Galvanised Steel Round Wire | AI31: 83.9 | AJ31: 302 | AK31: 25337.8 | AL31: FRLSH PVC Type ST-2 | AM31: 92 | AN31: 108 | AO31: 9936 | AR31: 0 | AV31: 0 | AZ31: 0 | BD31: 0 | BH31: 0 | BL31: 0 | BP31: 0 | BR31: RUBBERIZED COTTON TAPE | BS31: 445 | BT31: 0 | BU31: 0 | BX31: 0 | BZ31: 2575.74 | CA31: 52797.14 | CH31: 52797.14 | CM31: 52797.14 | CO31: 52797.14 | CP31: 0.18 | CQ31: 9503.49 | CR31: 62300.63 | CS31: 900 | CT31: KMS | CU31: 56070563 | CV31: MD0100066 | CW31: DRUM - 40 X 15 X 23 X 2 | CX31: 1000
A32: ENQ-12232-22-23 | B32: 45334 | C32: FA0900041 | D32: 2 CORE X 4 SQ. MM. AL/ARD - WIRE (XLPE) | E32: WOOD | J32: Alumimium | K32: 216 | L32: 21.6 | M32: 4665.6 | P32: 0 | T32: 0 | V32: LT-XLPE | W32: 107 | X32: 23 | Y32: 2461 | AB32: 0 | AD32: PVC Type ST-2 | AE32: 60.05 | AF32: 47 | AG32: 2822.35 | AH32: Galvanised Steel Round Wire | AI32: 83.9 | AJ32: 250 | AK32: 20975 | AL32: FRLSH PVC Type ST-2 | AM32: 92 | AN32: 92 | AO32: 8464 | AR32: 0 | AV32: 0 | AZ32: 0 | BD32: 0 | BH32: 0 | BL32: 0 | BP32: 0 | BT32: 0 | BX32: 0 | BZ32: 2575.74 | CA32: 41963.69 | CH32: 41963.69 | CM32: 41963.69 | CO32: 41963.69 | CP32: 0.18 | CQ32: 7553.46 | CR32: 49517.15 | CS32: 3493.688 | CT32: KMS | CU32: 172997487 | CV32: MD0100066 | CW32: DRUM - 40 X 15 X 23 X 2 | CX32: 1000

Sheet AUTO CALCULATION SHEET (2)
A2: Tata Power Odisha DISCOMs
A4: TENDER SPECIFICATION NO () | B4: TPCODL / CCG / 23-24 / 1000000538
A5: TENDER DESCRIPTION () | B5: One Year Rate Contract for Supply of 1.1 kV Power and Control Cables at TPNODL, TPCODL & TPSODL.
A6: Last Date & Time of Submission () | B6: 20/Feb/2024 [17:00 Hrs.]
A7: REVERSE AUCTION | B7: Bidders shall be allowed to participate in Reverse auction as per following criteria hence bidders are advised to quote their most competitive rates while submitting the bids to avoid disqualification from participation in Reverse Auction. Reverse Auction shall be as per the below approach: No of bidders allowed to participate in RA process shall be: Total No of bidders on whom tender would be split PLUS 2 more bidders.
A8: Price () | B8: Price shall be fixed and firm during the contractual period.
A9: Validity () | B9: Bids shall remain valid for 180 days from the due date of submission of the bid. Notwithstanding clause above, CCG may solicit the Bidder’s consent to an extension of the Period of Bid Validity. The request and responses thereto shall be made in writing.
A10: Delivery Period () | B10: Delivery Period shall be 60 + 7 days (considering the approval of CAT-A / drawing / GTP) from date of receipt of release order for the first lot however for remaining lots the delivery period will be 60 days from RO date.
A11: Payment Terms () | B11: Payment Terms: On delivery of the materials in good condition and certification of acceptance by certified official, Associate shall submit the Bills/ Invoices in original in the name of respective Odisha discom to Invoice Desk. The payment shall be released within 30 days from the date of submission of error free certified bills/ invoices. Any change in statutory taxes, duties and levies during the contract period shall be borne by respective Odisha DISCOMs. However, in case of delay in work execution owing to reasons not attributable to Odisha Disom, any increase in total liability shall be passed on the Bidder, whereas any benefits arising owing to such statutory variation in taxes and duties shall be passed on TP Discom.
A12: Standard length () | B12: Cable length on one drum shall be: (a) 4 Core Cable – 95 sq.mm. to 300 sq.mm. – 500 meters with + 5% tolerance (b) 4 Core Cable – 16 sq.mm. to 50 sq.mm. – 1000 meters with + 5% tolerance (c) 2 Core & 1 Core Cables – 1000 meters with + 5% tolerance (as per PO terms and conditions)
A13: Packing () | B13: Wooden drums shall be free from sharp edges and visual defects.
A14: Technical Specification
N16: =Sheet1!J1 -> Conductor | S16: AL ALLOY | U16: Insulation Screening (Metallic) | AC16: Insulation Screening (Non-Metallic) | AE16: Insulation | AK16: POLY TAPE | AL16: Inner Sheath | AS16: Armouring | BC16: Outer Sheath | BF16: UV resistance RS-5/kg | BM16: FILLER | BN16: GREASE | BO16: Water swellable Tape | BP16: Semi conducting Water Swellable tape | BQ16: SEMICON TAPE | BR16: GLASS FIBER TAPE | BS16: COPPER WIRE 0.8 MM | BT16: RUBBERIZED COTTON TAPE | BU16: Water Tight Compound | BZ16: DRUM COST PER KM | CA16: TOTAL RM COST | CB16: EXTRA CONSUMPTION | CC16: EXTRA CONSUMPTION VALUE
A17: DOCKET NO. | B17: =Sheet1!B1 -> Base Date | C17: ITEM CODE | D17: PROPOSE ERP ITEM NAME | E17: EX-WORKS (PER KM) | F17: FREIGHT PER KM | G17: PRICE INCLUDING FREIGHT (PER KM) | H17: GST % | I17: GST VALUE | J17: PRICE INCLUDING GST & FREIGHT (PER KM) | K17: QTY | L17: Unit | M17: TOTAL PRICE OF FULL QTY (INCLUDING FRIGHT & GST) | N17: Alumimium | O17: Alumimium ALLOY | P17: Copper | Q17: Flexible Copper | R17: Galvanized steel wire | S17: Alumimium | T17: Alumimium ALLOY | U17: Coper tape - 0.1 mm | V17: Copper Tape - 0.03 mm | W17: Copper Tape - 0.035 mm | X17: Copper Tape - 0.04 mm | Y17: Copper Tape - 0.045 mm | Z17: Copper Tape - 0.050 mm | AA17: Copper Tape - 0.060 mm | AB17: Copper Tape - 0.075 mm(DOUBLE) | AC17: Extruded semiconductive | AD17: Extruded Semiconductive(Stripable) | AE17: HT-XLPE | AF17: LT-XLPE | AG17: TR XLPE | AH17: Type A PVC-1.45 | AI17: Type C PVC (HR) | AJ17: XLPE | AK17: POLY TAPE | AL17: FR PVC Type ST-1 | AM17: FR PVC Type ST-2 | AN17: FRLSH PVC Type ST-2 | AO17: PVC Type ST-1 | AP17: PVC Type ST-1-PRESSURE EXTRUDED | AQ17: PVC Type ST-2 | AR17: PVC Type ST-2-PRESSURE EXTRUDED | AS17: ACSR CORE WIRE | AT17: ACSR DOG STEEL WIRE | AU17: Aluminium Flat Strip | AV17: Aluminium Round Wire | AW17: Double Steel Tape | AX17: Galvanised Steel Flat Strip | AY17: Galvanised Steel Flat Strip (Double) | AZ17: Galvanised Steel Flat Strip-B | BA17: Galvanised Steel Round Wire | BB17: Galvanised Steel Round Wire (Double) | BC17: FR PVC Type ST-1 | BD17: FR PVC Type ST-2 | BE17: FRLSH PVC Type ST-1 | BF17: FRLSH PVC Type ST-2 | BG17: PE, ST-3 | BH17: PE, ST-7 | BI17: PVC Type ST-1 | BJ17: PVC Type ST-2 | BK17: PVC Type ST-2-PRESSURE EXTRUDED | BL17: UV & Track Resistant XLPE | BM17: FILLER | BN17: NCWBT | BO17: Water swellable Tape | BP17: Semi conducting Water Swellable tape | BQ17: SEMICON TAPE | BR17: GLASS FIBER TAPE | BS17: COPPER WIRE 0.8 MM | BT17: RUBBERIZED COTTON TAPE | BU17: Water Tight Compound | BV17: =Sheet1!E1 -> PROPOSE DRUM TYPE | BW17: =Sheet1!CV1 -> DRUM CODE | BX17: =Sheet1!CW1 -> DRUM SIZE (FxbXtx Ft) | BY17: =Sheet1!CX1 -> PARTY STANDARD LENGTH (MTR) | CD17: MFG% | CE17: MFG VALUE | CF17: PROF% | CG17: PROFIT VALUE | CH17: 1ST EX-WORKS | CI17: Intt % | CJ17: INTT VALUE | CK17: insp% | CL17: INSP VALUE
N18: 228 | O18: =+IFERROR(VLOOKUP($O$17,Sheet1!J:L,2,0),0) -> 0 | P18: 782 | Q18: =+IFERROR(VLOOKUP($Q$17,Sheet1!J:M,2,0),0) -> 0 | R18: =+IFERROR(VLOOKUP($R$17,Sheet1!J:M,2,0),0) -> 0 | S18: =+IFERROR(VLOOKUP($S$17,Sheet1!N:Q,2,0),0) -> 0 | T18: =+IFERROR(VLOOKUP($T$17,Sheet1!N:O,2,0),0) -> 0 | U18: =+IFERROR(VLOOKUP($U$17,Sheet1!F:I,2,0),0) -> 0 | V18: =+IFERROR(VLOOKUP($V$17,Sheet1!F:I,2,0),0) -> 0 | W18: =+IFERROR(VLOOKUP($W$17,Sheet1!F:I,2,0),0) -> 0 | X18: =+IFERROR(VLOOKUP($X$17,Sheet1!F:I,2,0),0) -> 0 | Y18: =+IFERROR(VLOOKUP($Y$17,Sheet1!F:I,2,0),0) -> 0 | Z18: =+IFERROR(VLOOKUP($Z$17,Sheet1!F:I,2,0),0) -> 0 | AA18: =+IFERROR(VLOOKUP($AA$17,Sheet1!F:I,2,0),0) -> 0 | AB18: =+IFERROR(VLOOKUP($AB$17,Sheet1!F:I,2,0),0) -> 0 | AC18: =+IFERROR(VLOOKUP($AC$17,Sheet1!R:U,2,0),0) -> 0 | AD18: =+IFERROR(VLOOKUP($AD$17,Sheet1!R:U,2,0),0) -> 0 | AE18: =+IFERROR(VLOOKUP($AE$17,Sheet1!V:Y,2,0),0) -> 0 | AF18: 100 | AG18: =+IFERROR(VLOOKUP($AG$17,Sheet1!V:Y,2,0),0) -> 0 | AH18: 75 | AI18: 105 | AJ18: =+IFERROR(VLOOKUP($AJ$17,Sheet1!V:Y,2,0),0) -> 0 | AK18: 114 | AL18: =+IFERROR(VLOOKUP($AL$17,Sheet1!AD2:AG840,2,0),0) -> 0 | AM18: =+IFERROR(VLOOKUP($AM$17,Sheet1!AD2:AG840,2,0),0) -> 0 | AN18: =+IFERROR(VLOOKUP($AN$17,Sheet1!AD2:AG840,2,0),0) -> 0 | AO18: 59 | AP18: =+IFERROR(VLOOKUP($AP$17,Sheet1!AD2:AG840,2,0),0) -> 0 | AQ18: 61 | AR18: 89 | AS18: =+IFERROR(VLOOKUP($AS$17,Sheet1!AH2:AK840,2,0),0) -> 0 | AT18: =+IFERROR(VLOOKUP($AT$17,Sheet1!AH2:AK840,2,0),0) -> 0 | AU18: =+IFERROR(VLOOKUP($AU$17,Sheet1!AH2:AK840,2,0),0) -> 0 | AV18: 233 | AW18: =+IFERROR(VLOOKUP($AW$17,Sheet1!AH2:AK840,2,0),0) -> 0 | AX18: =+IFERROR(VLOOKUP($AX$17,Sheet1!AH2:AK840,2,0),0) -> 0 | AY18: =+IFERROR(VLOOKUP($AY$17,Sheet1!AH2:AK840,2,0),0) -> 0 | AZ18: =+IFERROR(VLOOKUP($AZ$17,Sheet1!AH2:AK840,2,0),0) -> 0 | BA18: 82 | BB18: =+IFERROR(VLOOKUP($BB$17,Sheet1!AH2:AK840,2,0),0) -> 0 | BC18: =+IFERROR(VLOOKUP($BC$17,Sheet1!AL2:AO840,2,0),0) -> 0 | BD18: =+IFERROR(VLOOKUP($BD$17,Sheet1!AL2:AO840,2,0),0) -> 0 | BE18: =+IFERROR(VLOOKUP($BE$17,Sheet1!AL2:AO840,2,0),0) -> 0 | BF18: 105 | BG18: =+IFERROR(VLOOKUP($BG$17,Sheet1!AL2:AO840,2,0),0) -> 0 | BH18: =+IFERROR(VLOOKUP($BH$17,Sheet1!AL2:AO840,2,0),0) -> 0 | BI18: 59 | BJ18: =+IFERROR(VLOOKUP($BJ$17,Sheet1!AL2:AO840,2,0),0) -> 0 | BK18: =+IFERROR(VLOOKUP($BK$17,Sheet1!AL2:AO840,2,0),0) -> 0 | BL18: =+IFERROR(VLOOKUP($BL$17,Sheet1!AL2:AO840,2,0),0) -> 0 | BM18: =+IFERROR(VLOOKUP($BM$17,Sheet1!AP2:AS840,2,0),0) -> 0 | BN18: 340 | BP18: =+IFERROR(VLOOKUP($BP$17,Sheet1!BB2:BE840,2,0),0) -> 0 | BQ18: =+IFERROR(VLOOKUP($BQ$17,Sheet1!BF2:BI840,2,0),0) -> 0 | BR18: =+IFERROR(VLOOKUP($BR$17,Sheet1!BJ2:BM840,2,0),0) -> 0 | BS18: =+IFERROR(VLOOKUP($BS$17,Sheet1!BN2:BQ840,2,0),0) -> 0 | BT18: 450 | BU18: =+IFERROR(VLOOKUP($BU$17,Sheet1!BV2:BY840,2,0),0) -> 0
A19: =Sheet1!A23 -> ENQ-12232-22-23 | B19: 45380 | C19: =Sheet1!C23 -> FA0600013 | D19: =Sheet1!D23 -> 1 CORE X 95 SQ. MM. AL/UNARD(XLPE ) | E19: =CH19+CJ19+CL19 -> 97423.717 | F19: =ROUNDUP(M52,0) -> 986 | G19: =E19+F19 -> 98409.717 | H19: =Sheet1!CP23 -> 0.18 | I19: =G19*H19 -> 17713.749 | J19: =G19+I19 -> 116123.47 | K19: =Sheet1!CS23 -> 82.208 | L19: =Sheet1!CT23 -> KMS | M19: =J19*K19 -> 9546277.9 | N19: =+IFERROR(VLOOKUP($N$17,Sheet1!J23:L23,3,0),0) -> 256.5 | O19: =+IFERROR(VLOOKUP($O$17,Sheet1!J23:L23,3,0),0) -> 0 | P19: =+IFERROR(VLOOKUP($P$17,Sheet1!J23:M23,3,0),0) -> 0 | Q19: =+IFERROR(VLOOKUP($Q$17,Sheet1!J23:M23,3,0),0) -> 0 | R19: =+IFERROR(VLOOKUP($R$17,Sheet1!J23:M23,3,0),0) -> 0 | S19: =+IFERROR(VLOOKUP($S$17,Sheet1!N23:Q23,3,0),0) -> 0 | T19: =+IFERROR(VLOOKUP($T$17,Sheet1!N23:Q23,3,0),0) -> 0 | U19: =+IFERROR(VLOOKUP($U$17,Sheet1!F23:I23,3,0),0) -> 0 | V19: =+IFERROR(VLOOKUP($V$17,Sheet1!F23:I23,3,0),0) -> 0 | W19: =+IFERROR(VLOOKUP($W$17,Sheet1!F23:I23,3,0),0) -> 0 | X19: =+IFERROR(VLOOKUP($X$17,Sheet1!F23:I23,3,0),0) -> 0 | Y19: =+IFERROR(VLOOKUP($Y$17,Sheet1!F23:I23,3,0),0) -> 0 | Z19: =+IFERROR(VLOOKUP($Z$17,Sheet1!F23:I23,3,0),0) -> 0 | AA19: =+IFERROR(VLOOKUP($AA$17,Sheet1!F23:I23,3,0),0) -> 0 | AB19: =+IFERROR(VLOOKUP($AB$17,Sheet1!F23:I23,3,0),0) -> 0 | AC19: =+IFERROR(VLOOKUP($AC$17,Sheet1!R23:U23,3,0),0) -> 0 | AD19: =+IFERROR(VLOOKUP($AD$17,Sheet1!R23:U23,2,0),0) -> 0 | AE19: =+IFERROR(VLOOKUP($AE$17,Sheet1!V23:Y23,3,0),0) -> 0 | AF19: 44 | AG19: =+IFERROR(VLOOKUP($AG$17,Sheet1!V23:Y23,3,0),0) -> 0 | AH19: =+IFERROR(VLOOKUP($AH$17,Sheet1!V23:Y23,3,0),0) -> 0 | AI19: =+IFERROR(VLOOKUP($AI$17,Sheet1!V23:Y23,3,0),0) -> 0 | AJ19: =+IFERROR(VLOOKUP($AJ$17,Sheet1!V23:Y23,3,0),0) -> 0 | AK19: =+IFERROR(VLOOKUP($AK$17,Sheet1!Z23:AB23,3,0),0) -> 0 | AL19: =+IFERROR(VLOOKUP($AL$17,Sheet1!AD23:AG23,3,0),0) -> 0 | AM19: =+IFERROR(VLOOKUP($AM$17,Sheet1!AD23:AG23,3,0),0) -> 0 | AN19: =+IFERROR(VLOOKUP($AN$17,Sheet1!AD23:AG23,3,0),0) -> 0 | AO19: =+IFERROR(VLOOKUP($AO$17,Sheet1!AD23:AG23,3,0),0) -> 0 | AP19: =+IFERROR(VLOOKUP($AP$17,Sheet1!AD23:AG23,3,0),0) -> 0 | AQ19: =+IFERROR(VLOOKUP($AQ$17,Sheet1!AD23:AG23,3,0),0) -> 0 | AR19: =+IFERROR(VLOOKUP($AR$17,Sheet1!AD23:AG23,3,0),0) -> 0 | AS19: =+IFERROR(VLOOKUP($AS$17,Sheet1!AH23:AK23,3,0),0) -> 0 | AT19: =+IFERROR(VLOOKUP($AT$17,Sheet1!AH23:AK23,3,0),0) -> 0 | AU19: =+IFERROR(VLOOKUP($AU$17,Sheet1!AH23:AK23,3,0),0) -> 0 | AV19: =+IFERROR(VLOOKUP($AV$17,Sheet1!AH23:AK23,3,0),0) -> 0 | AW19: =+IFERROR(VLOOKUP($AW$17,Sheet1!AH23:AK23,3,0),0) -> 0 | AX19: =+IFERROR(VLOOKUP($AX$17,Sheet1!AH23:AK23,3,0),0) -> 0 | AY19: =+IFERROR(VLOOKUP($AY$17,Sheet1!AH23:AK23,3,0),0) -> 0 | AZ19: =+IFERROR(VLOOKUP($AZ$17,Sheet1!AH23:AK23,3,0),0) -> 0 | BA19: =+IFERROR(VLOOKUP($BA$17,Sheet1!AH23:AK23,3,0),0) -> 0 | BB19: =+IFERROR(VLOOKUP($BB$17,Sheet1!AH23:AK23,3,0),0) -> 0 | BC19: =+IFERROR(VLOOKUP($BC$17,Sheet1!AL23:AO23,3,0),0) -> 0 | BD19: =+IFERROR(VLOOKUP($BD$17,Sheet1!AL23:AO23,3,0),0) -> 0 | BE19: =+IFERROR(VLOOKUP($BE$17,Sheet1!AL23:AO23,3,0),0) -> 0 | BF19: 140 | BG19: =+IFERROR(VLOOKUP($BG$17,Sheet1!AL23:AO23,3,0),0) -> 0 | BH19: =+IFERROR(VLOOKUP($BH$17,Sheet1!AL23:AO23,3,0),0) -> 0 | BI19: =+IFERROR(VLOOKUP($BI$17,Sheet1!AL23:AO23,3,0),0) -> 0 | BJ19: =+IFERROR(VLOOKUP($BJ$17,Sheet1!AL23:AO23,3,0),0) -> 0 | BK19: =+IFERROR(VLOOKUP($BK$17,Sheet1!AL23:AO23,3,0),0) -> 0 | BL19: =+IFERROR(VLOOKUP($BL$17,Sheet1!AL23:AO23,3,0),0) -> 0 | BM19: =+IFERROR(VLOOKUP($BM$17,Sheet1!AP23:AS23,3,0),0) -> 0 | BN19: =+IFERROR(VLOOKUP($BN$17,Sheet1!AT23:AW23,3,0),0) -> 0 | BO19: =+IFERROR(VLOOKUP($BO$17,Sheet1!AX23:BA23,3,0),0) -> 0 | BP19: =+IFERROR(VLOOKUP($BP$17,Sheet1!BB23:BE23,3,0),0) -> 0 | BQ19: =+IFERROR(VLOOKUP($BQ$17,Sheet1!BF23:BI23,3,0),0) -> 0 | BR19: =+IFERROR(VLOOKUP($BR$17,Sheet1!BJ23:BM23,3,0),0) -> 0 | BS19: =+IFERROR(VLOOKUP($BS$17,Sheet1!BN23:BQ23,3,0),0) -> 0 | BT19: =+IFERROR(VLOOKUP($BT$17,Sheet1!BR23:BU23,3,0),0) -> 0 | BU19: =+IFERROR(VLOOKUP($BU$17,Sheet1!BV23:BY23,3,0),0) -> 0 | BV19: =Sheet1!E23 -> WOOD | BW19: =Sheet1!CV23 -> MD0100066 | BX19: =Sheet1!CW23 -> DRUM - 40 X 15 X 23 X 2 | BY19: =Sheet1!CX23 -> 1000 | BZ19: =Sheet1!BZ23 -> 2575.74 | CA19: =SUMPRODUCT($N$18:$BU$18,N19:BU19)+BZ19 -> 80157.74 | CB19: =Sheet1!CB23 -> 0 | CC19: =CA19*CB19 -> 0 | CD19: 0.18 | CE19: =CA19*CD19 -> 14428.393 | CF19: 0 | CG19: =CA19*CF19 -> 0 | CH19: =CA19+CC19+CE19+CG19 -> 94586.133 | CI19: 0.02 | CJ19: =CH19*CI19 -> 1891.7227 | CK19: 0.01 | CL19: =CH19*CK19 -> 945.86133 | CM19: 55 | CN19: 20
A20: =Sheet1!A19 -> ENQ-12232-22-23 | B20: 45380 | C20: =Sheet1!C19 -> FA0600019 | D20: =Sheet1!D19 -> 1 CORE X 150 SQ. MM. AL/UNARD. (XLPE) | E20: =CH20+CJ20+CL20 -> 155611.16 | F20: =ROUNDUP(M53,0) -> 1694 | G20: =E20+F20 -> 157305.16 | H20: =Sheet1!CP19 -> 0.18 | I20: =G20*H20 -> 28314.929 | J20: =G20+I20 -> 185620.09 | K20: =Sheet1!CS19 -> 47.838 | L20: =Sheet1!CT19 -> KMS | M20: =J20*K20 -> 8879693.9 | N20: =+IFERROR(VLOOKUP($N$17,Sheet1!J19:L19,3,0),0) -> 405 | O20: =+IFERROR(VLOOKUP($O$17,Sheet1!J19:L19,3,0),0) -> 0 | P20: =+IFERROR(VLOOKUP($P$17,Sheet1!J19:M19,3,0),0) -> 0 | Q20: =+IFERROR(VLOOKUP($Q$17,Sheet1!J19:M19,3,0),0) -> 0 | R20: =+IFERROR(VLOOKUP($R$17,Sheet1!J19:M19,3,0),0) -> 0 | S20: =+IFERROR(VLOOKUP($S$17,Sheet1!N19:Q19,3,0),0) -> 0 | T20: =+IFERROR(VLOOKUP($T$17,Sheet1!N19:Q19,3,0),0) -> 0 | U20: =+IFERROR(VLOOKUP($U$17,Sheet1!F19:I19,3,0),0) -> 0 | V20: =+IFERROR(VLOOKUP($V$17,Sheet1!F19:I19,3,0),0) -> 0 | W20: =+IFERROR(VLOOKUP($W$17,Sheet1!F19:I19,3,0),0) -> 0 | X20: =+IFERROR(VLOOKUP($X$17,Sheet1!F19:I19,3,0),0) -> 0 | Y20: =+IFERROR(VLOOKUP($Y$17,Sheet1!F19:I19,3,0),0) -> 0 | Z20: =+IFERROR(VLOOKUP($Z$17,Sheet1!F19:I19,3,0),0) -> 0 | AA20: =+IFERROR(VLOOKUP($AA$17,Sheet1!F19:I19,3,0),0) -> 0 | AB20: =+IFERROR(VLOOKUP($AB$17,Sheet1!F19:I19,3,0),0) -> 0 | AC20: =+IFERROR(VLOOKUP($AC$17,Sheet1!R19:U19,3,0),0) -> 0 | AD20: =+IFERROR(VLOOKUP($AD$17,Sheet1!R19:U19,2,0),0) -> 0 | AE20: =+IFERROR(VLOOKUP($AE$17,Sheet1!V19:Y19,3,0),0) -> 0 | AF20: =+IFERROR(VLOOKUP($AF$17,Sheet1!V19:Y19,3,0),0) -> 72 | AG20: =+IFERROR(VLOOKUP($AG$17,Sheet1!V19:Y19,3,0),0) -> 0 | AH20: =+IFERROR(VLOOKUP($AH$17,Sheet1!V19:Y19,3,0),0) -> 0 | AI20: =+IFERROR(VLOOKUP($AI$17,Sheet1!V19:Y19,3,0),0) -> 0 | AJ20: =+IFERROR(VLOOKUP($AJ$17,Sheet1!V19:Y19,3,0),0) -> 0 | AK20: =+IFERROR(VLOOKUP($AK$17,Sheet1!Z19:AB19,3,0),0) -> 0 | AL20: =+IFERROR(VLOOKUP($AL$17,Sheet1!AD19:AG19,3,0),0) -> 0 | AM20: =+IFERROR(VLOOKUP($AM$17,Sheet1!AD19:AG19,3,0),0) -> 0 | AN20: =+IFERROR(VLOOKUP($AN$17,Sheet1!AD19:AG19,3,0),0) -> 0 | AO20: =+IFERROR(VLOOKUP($AO$17,Sheet1!AD19:AG19,3,0),0) -> 0 | AP20: =+IFERROR(VLOOKUP($AP$17,Sheet1!AD19:AG19,3,0),0) -> 0 | AQ20: =+IFERROR(VLOOKUP($AQ$17,Sheet1!AD19:AG19,3,0),0) -> 0 | AR20: =+IFERROR(VLOOKUP($AR$17,Sheet1!AD19:AG19,3,0),0) -> 0 | AS20: =+IFERROR(VLOOKUP($AS$17,Sheet1!AH19:AK19,3,0),0) -> 0 | AT20: =+IFERROR(VLOOKUP($AT$17,Sheet1!AH19:AK19,3,0),0) -> 0 | AU20: =+IFERROR(VLOOKUP($AU$17,Sheet1!AH19:AK19,3,0),0) -> 0 | AV20: =+IFERROR(VLOOKUP($AV$17,Sheet1!AH19:AK19,3,0),0) -> 0 | AW20: =+IFERROR(VLOOKUP($AW$17,Sheet1!AH19:AK19,3,0),0) -> 0 | AX20: =+IFERROR(VLOOKUP($AX$17,Sheet1!AH19:AK19,3,0),0) -> 0 | AY20: =+IFERROR(VLOOKUP($AY$17,Sheet1!AH19:AK19,3,0),0) -> 0 | AZ20: =+IFERROR(VLOOKUP($AZ$17,Sheet1!AH19:AK19,3,0),0) -> 0 | BA20: =+IFERROR(VLOOKUP($BA$17,Sheet1!AH19:AK19,3,0),0) -> 0 | BB20: =+IFERROR(VLOOKUP($BB$17,Sheet1!AH19:AK19,3,0),0) -> 0 | BC20: =+IFERROR(VLOOKUP($BC$17,Sheet1!AL19:AO19,3,0),0) -> 0 | BD20: =+IFERROR(VLOOKUP($BD$17,Sheet1!AL19:AO19,3,0),0) -> 0 | BE20: =+IFERROR(VLOOKUP($BE$17,Sheet1!AL19:AO19,3,0),0) -> 0 | BF20: 195 | BG20: =+IFERROR(VLOOKUP($BG$17,Sheet1!AL19:AO19,3,0),0) -> 0 | BH20: =+IFERROR(VLOOKUP($BH$17,Sheet1!AL19:AO19,3,0),0) -> 0 | BI20: =+IFERROR(VLOOKUP($BI$17,Sheet1!AL19:AO19,3,0),0) -> 0 | BJ20: =+IFERROR(VLOOKUP($BJ$17,Sheet1!AL19:AO19,3,0),0) -> 0 | BK20: =+IFERROR(VLOOKUP($BK$17,Sheet1!AL19:AO19,3,0),0) -> 0 | BL20: =+IFERROR(VLOOKUP($BL$17,Sheet1!AL19:AO19,3,0),0) -> 0 | BM20: =+IFERROR(VLOOKUP($BM$17,Sheet1!AP19:AS19,3,0),0) -> 0 | BN20: 14 | BO20: =+IFERROR(VLOOKUP($BO$17,Sheet1!AX19:BA19,3,0),0) -> 0 | BP20: =+IFERROR(VLOOKUP($BP$17,Sheet1!BB19:BE19,3,0),0) -> 0 | BQ20: =+IFERROR(VLOOKUP($BQ$17,Sheet1!BF19:BI19,3,0),0) -> 0 | BR20: =+IFERROR(VLOOKUP($BR$17,Sheet1!BJ19:BM19,3,0),0) -> 0 | BS20: =+IFERROR(VLOOKUP($BS$17,Sheet1!BN19:BQ19,3,0),0) -> 0 | BT20: =+IFERROR(VLOOKUP($BT$17,Sheet1!BR19:BU19,3,0),0) -> 0 | BU20: =+IFERROR(VLOOKUP($BU$17,Sheet1!BV19:BY19,3,0),0) -> 0 | BV20: =Sheet1!E19 -> WOOD | BW20: =Sheet1!CV19 -> MD0100085 | BX20: =Sheet1!CW19 -> DRUM - 43 X 15 X 28 X 2.25 | BY20: =Sheet1!CX19 -> 1000 | BZ20: =Sheet1!BZ19 -> 3257.88 | CA20: =SUMPRODUCT($N$18:$BU$18,N20:BU20)+BZ20 -> 128032.88 | CB20: =Sheet1!CB19 -> 0 | CC20: =CA20*CB20 -> 0 | CD20: 0.18 | CE20: =CA20*CD20 -> 23045.918 | CF20: 0 | CG20: =CA20*CF20 -> 0 | CH20: =CA20+CC20+CE20+CG20 -> 151078.8 | CI20: 0.02 | CJ20: =CH20*CI20 -> 3021.576 | CK20: 0.01 | CL20: =CH20*CK20 -> 1510.788 | CM20: 75 | CN20: 25
A21: =Sheet1!A15 -> ENQ-12232-22-23 | B21: 45380 | C21: =Sheet1!C15 -> FA0600021 | D21: =Sheet1!D15 -> 1 CORE X 185 SQ. MM. AL/UNARD. (XLPE) | E21: =CH21+CJ21+CL21 -> 190411.38 | F21: =ROUNDUP(M54,0) -> 2700 | G21: =E21+F21 -> 193111.38 | H21: =Sheet1!CP15 -> 0.18 | I21: =G21*H21 -> 34760.049 | J21: =G21+I21 -> 227871.43 | K21: =Sheet1!CS15 -> 20 | L21: =Sheet1!CT15 -> KMS | M21: =J21*K21 -> 4557428.6 | N21: 500 | O21: =+IFERROR(VLOOKUP($O$17,Sheet1!J15:L15,3,0),0) -> 0 | P21: =+IFERROR(VLOOKUP($P$17,Sheet1!J15:M15,3,0),0) -> 0 | Q21: =+IFERROR(VLOOKUP($Q$17,Sheet1!J15:M15,3,0),0) -> 0 | R21: =+IFERROR(VLOOKUP($R$17,Sheet1!J15:M15,3,0),0) -> 0 | S21: =+IFERROR(VLOOKUP($S$17,Sheet1!N15:Q15,3,0),0) -> 0 | T21: =+IFERROR(VLOOKUP($T$17,Sheet1!N15:Q15,3,0),0) -> 0 | U21: =+IFERROR(VLOOKUP($U$17,Sheet1!F15:I15,3,0),0) -> 0 | V21: =+IFERROR(VLOOKUP($V$17,Sheet1!F15:I15,3,0),0) -> 0 | W21: =+IFERROR(VLOOKUP($W$17,Sheet1!F15:I15,3,0),0) -> 0 | X21: =+IFERROR(VLOOKUP($X$17,Sheet1!F15:I15,3,0),0) -> 0 | Y21: =+IFERROR(VLOOKUP($Y$17,Sheet1!F15:I15,3,0),0) -> 0 | Z21: =+IFERROR(VLOOKUP($Z$17,Sheet1!F15:I15,3,0),0) -> 0 | AA21: =+IFERROR(VLOOKUP($AA$17,Sheet1!F15:I15,3,0),0) -> 0 | AB21: =+IFERROR(VLOOKUP($AB$17,Sheet1!F15:I15,3,0),0) -> 0 | AC21: =+IFERROR(VLOOKUP($AC$17,Sheet1!R15:U15,3,0),0) -> 0 | AD21: =+IFERROR(VLOOKUP($AD$17,Sheet1!R15:U15,2,0),0) -> 0 | AE21: =+IFERROR(VLOOKUP($AE$17,Sheet1!V15:Y15,3,0),0) -> 0 | AF21: =+IFERROR(VLOOKUP($AF$17,Sheet1!V15:Y15,3,0),0) -> 90 | AG21: =+IFERROR(VLOOKUP($AG$17,Sheet1!V15:Y15,3,0),0) -> 0 | AH21: =+IFERROR(VLOOKUP($AH$17,Sheet1!V15:Y15,3,0),0) -> 0 | AI21: =+IFERROR(VLOOKUP($AI$17,Sheet1!V15:Y15,3,0),0) -> 0 | AJ21: =+IFERROR(VLOOKUP($AJ$17,Sheet1!V15:Y15,3,0),0) -> 0 | AK21: =+IFERROR(VLOOKUP($AK$17,Sheet1!Z15:AB15,3,0),0) -> 0 | AL21: =+IFERROR(VLOOKUP($AL$17,Sheet1!AD15:AG15,3,0),0) -> 0 | AM21: =+IFERROR(VLOOKUP($AM$17,Sheet1!AD15:AG15,3,0),0) -> 0 | AN21: =+IFERROR(VLOOKUP($AN$17,Sheet1!AD15:AG15,3,0),0) -> 0 | AO21: =+IFERROR(VLOOKUP($AO$17,Sheet1!AD15:AG15,3,0),0) -> 0 | AP21: =+IFERROR(VLOOKUP($AP$17,Sheet1!AD15:AG15,3,0),0) -> 0 | AQ21: =+IFERROR(VLOOKUP($AQ$17,Sheet1!AD15:AG15,3,0),0) -> 0 | AR21: =+IFERROR(VLOOKUP($AR$17,Sheet1!AD15:AG15,3,0),0) -> 0 | AS21: =+IFERROR(VLOOKUP($AS$17,Sheet1!AH15:AK15,3,0),0) -> 0 | AT21: =+IFERROR(VLOOKUP($AT$17,Sheet1!AH15:AK15,3,0),0) -> 0 | AU21: =+IFERROR(VLOOKUP($AU$17,Sheet1!AH15:AK15,3,0),0) -> 0 | AV21: =+IFERROR(VLOOKUP($AV$17,Sheet1!AH15:AK15,3,0),0) -> 0 | AW21: =+IFERROR(VLOOKUP($AW$17,Sheet1!AH15:AK15,3,0),0) -> 0 | AX21: =+IFERROR(VLOOKUP($AX$17,Sheet1!AH15:AK15,3,0),0) -> 0 | AY21: =+IFERROR(VLOOKUP($AY$17,Sheet1!AH15:AK15,3,0),0) -> 0 | AZ21: =+IFERROR(VLOOKUP($AZ$17,Sheet1!AH15:AK15,3,0),0) -> 0 | BA21: =+IFERROR(VLOOKUP($BA$17,Sheet1!AH15:AK15,3,0),0) -> 0 | BB21: =+IFERROR(VLOOKUP($BB$17,Sheet1!AH15:AK15,3,0),0) -> 0 | BC21: =+IFERROR(VLOOKUP($BC$17,Sheet1!AL15:AO15,3,0),0) -> 0 | BD21: =+IFERROR(VLOOKUP($BD$17,Sheet1!AL15:AO15,3,0),0) -> 0 | BE21: =+IFERROR(VLOOKUP($BE$17,Sheet1!AL15:AO15,3,0),0) -> 0 | BF21: 216 | BG21: =+IFERROR(VLOOKUP($BG$17,Sheet1!AL15:AO15,3,0),0) -> 0 | BH21: =+IFERROR(VLOOKUP($BH$17,Sheet1!AL15:AO15,3,0),0) -> 0 | BI21: =+IFERROR(VLOOKUP($BI$17,Sheet1!AL15:AO15,3,0),0) -> 0 | BJ21: =+IFERROR(VLOOKUP($BJ$17,Sheet1!AL15:AO15,3,0),0) -> 0 | BK21: =+IFERROR(VLOOKUP($BK$17,Sheet1!AL15:AO15,3,0),0) -> 0 | BL21: =+IFERROR(VLOOKUP($BL$17,Sheet1!AL15:AO15,3,0),0) -> 0 | BM21: =+IFERROR(VLOOKUP($BM$17,Sheet1!AP15:AS15,3,0),0) -> 0 | BN21: 22 | BO21: =+IFERROR(VLOOKUP($BO$17,Sheet1!AX15:BA15,3,0),0) -> 0 | BP21: =+IFERROR(VLOOKUP($BP$17,Sheet1!BB15:BE15,3,0),0) -> 0 | BQ21: =+IFERROR(VLOOKUP($BQ$17,Sheet1!BF15:BI15,3,0),0) -> 0 | BR21: =+IFERROR(VLOOKUP($BR$17,Sheet1!BJ15:BM15,3,0),0) -> 0 | BS21: =+IFERROR(VLOOKUP($BS$17,Sheet1!BN15:BQ15,3,0),0) -> 0 | BT21: =+IFERROR(VLOOKUP($BT$17,Sheet1!BR15:BU15,3,0),0) -> 0 | BU21: =+IFERROR(VLOOKUP($BU$17,Sheet1!BV15:BY15,3,0),0) -> 0 | BV21: =Sheet1!E15 -> WOOD | BW21: =Sheet1!CV15 -> MD0100090 | BX21: =Sheet1!CW15 -> DRUM - 43 X 15 X 36 X 2.5 | BY21: =Sheet1!CX15 -> 1000 | BZ21: =Sheet1!BZ15 -> 3505.61 | CA21: =SUMPRODUCT($N$18:$BU$18,N21:BU21)+BZ21 -> 156665.61 | CB21: =Sheet1!CB15 -> 0 | CC21: =CA21*CB21 -> 0 | CD21: 0.18 | CE21: =CA21*CD21 -> 28199.81 | CF21: 0 | CG21: =CA21*CF21 -> 0 | CH21: =CA21+CC21+CE21+CG21 -> 184865.42 | CI21: 0.02 | CJ21: =CH21*CI21 -> 3697.3084 | CK21: 0.01 | CL21: =CH21*CK21 -> 1848.6542 | CM21: 75 | CN21: 25
A22: =Sheet1!A21 -> ENQ-12232-22-23 | B22: 45380 | C22: =Sheet1!C21 -> FA0600020 | D22: =Sheet1!D21 -> 1 CORE X 300 SQ. MM. AL/UNARD. (XLPE) | E22: =CH22+CJ22+CL22 -> 290640.84 | F22: =ROUNDUP(M55,0) -> 2983 | G22: =E22+F22 -> 293623.84 | H22: =Sheet1!CP21 -> 0.18 | I22: =G22*H22 -> 52852.291 | J22: =G22+I22 -> 346476.13 | K22: =Sheet1!CS21 -> 63.368 | L22: =Sheet1!CT21 -> KMS | M22: =J22*K22 -> 21955499 | N22: =+IFERROR(VLOOKUP($N$17,Sheet1!J21:L21,3,0),0) -> 810 | O22: =+IFERROR(VLOOKUP($O$17,Sheet1!J21:L21,3,0),0) -> 0 | P22: =+IFERROR(VLOOKUP($P$17,Sheet1!J21:M21,3,0),0) -> 0 | Q22: =+IFERROR(VLOOKUP($Q$17,Sheet1!J21:M21,3,0),0) -> 0 | R22: =+IFERROR(VLOOKUP($R$17,Sheet1!J21:M21,3,0),0) -> 0 | S22: =+IFERROR(VLOOKUP($S$17,Sheet1!N21:Q21,3,0),0) -> 0 | T22: =+IFERROR(VLOOKUP($T$17,Sheet1!N21:Q21,3,0),0) -> 0 | U22: =+IFERROR(VLOOKUP($U$17,Sheet1!F21:I21,3,0),0) -> 0 | V22: =+IFERROR(VLOOKUP($V$17,Sheet1!F21:I21,3,0),0) -> 0 | W22: =+IFERROR(VLOOKUP($W$17,Sheet1!F21:I21,3,0),0) -> 0 | X22: =+IFERROR(VLOOKUP($X$17,Sheet1!F21:I21,3,0),0) -> 0 | Y22: =+IFERROR(VLOOKUP($Y$17,Sheet1!F21:I21,3,0),0) -> 0 | Z22: =+IFERROR(VLOOKUP($Z$17,Sheet1!F21:I21,3,0),0) -> 0 | AA22: =+IFERROR(VLOOKUP($AA$17,Sheet1!F21:I21,3,0),0) -> 0 | AB22: =+IFERROR(VLOOKUP($AB$17,Sheet1!F21:I21,3,0),0) -> 0 | AC22: =+IFERROR(VLOOKUP($AC$17,Sheet1!R21:U21,3,0),0) -> 0 | AD22: =+IFERROR(VLOOKUP($AD$17,Sheet1!R21:U21,2,0),0) -> 0 | AE22: =+IFERROR(VLOOKUP($AE$17,Sheet1!V21:Y21,3,0),0) -> 0 | AF22: =+IFERROR(VLOOKUP($AF$17,Sheet1!V21:Y21,3,0),0) -> 132 | AG22: =+IFERROR(VLOOKUP($AG$17,Sheet1!V21:Y21,3,0),0) -> 0 | AH22: =+IFERROR(VLOOKUP($AH$17,Sheet1!V21:Y21,3,0),0) -> 0 | AI22: =+IFERROR(VLOOKUP($AI$17,Sheet1!V21:Y21,3,0),0) -> 0 | AJ22: =+IFERROR(VLOOKUP($AJ$17,Sheet1!V21:Y21,3,0),0) -> 0 | AK22: =+IFERROR(VLOOKUP($AK$17,Sheet1!Z21:AB21,3,0),0) -> 0 | AL22: =+IFERROR(VLOOKUP($AL$17,Sheet1!AD21:AG21,3,0),0) -> 0 | AM22: =+IFERROR(VLOOKUP($AM$17,Sheet1!AD21:AG21,3,0),0) -> 0 | AN22: =+IFERROR(VLOOKUP($AN$17,Sheet1!AD21:AG21,3,0),0) -> 0 | AO22: =+IFERROR(VLOOKUP($AO$17,Sheet1!AD21:AG21,3,0),0) -> 0 | AP22: =+IFERROR(VLOOKUP($AP$17,Sheet1!AD21:AG21,3,0),0) -> 0 | AQ22: =+IFERROR(VLOOKUP($AQ$17,Sheet1!AD21:AG21,3,0),0) -> 0 | AR22: =+IFERROR(VLOOKUP($AR$17,Sheet1!AD21:AG21,3,0),0) -> 0 | AS22: =+IFERROR(VLOOKUP($AS$17,Sheet1!AH21:AK21,3,0),0) -> 0 | AT22: =+IFERROR(VLOOKUP($AT$17,Sheet1!AH21:AK21,3,0),0) -> 0 | AU22: =+IFERROR(VLOOKUP($AU$17,Sheet1!AH21:AK21,3,0),0) -> 0 | AV22: =+IFERROR(VLOOKUP($AV$17,Sheet1!AH21:AK21,3,0),0) -> 0 | AW22: =+IFERROR(VLOOKUP($AW$17,Sheet1!AH21:AK21,3,0),0) -> 0 | AX22: =+IFERROR(VLOOKUP($AX$17,Sheet1!AH21:AK21,3,0),0) -> 0 | AY22: =+IFERROR(VLOOKUP($AY$17,Sheet1!AH21:AK21,3,0),0) -> 0 | AZ22: =+IFERROR(VLOOKUP($AZ$17,Sheet1!AH21:AK21,3,0),0) -> 0 | BA22: =+IFERROR(VLOOKUP($BA$17,Sheet1!AH21:AK21,3,0),0) -> 0 | BB22: =+IFERROR(VLOOKUP($BB$17,Sheet1!AH21:AK21,3,0),0) -> 0 | BC22: =+IFERROR(VLOOKUP($BC$17,Sheet1!AL21:AO21,3,0),0) -> 0 | BD22: =+IFERROR(VLOOKUP($BD$17,Sheet1!AL21:AO21,3,0),0) -> 0 | BE22: =+IFERROR(VLOOKUP($BE$17,Sheet1!AL21:AO21,3,0),0) -> 0 | BF22: 255 | BG22: =+IFERROR(VLOOKUP($BG$17,Sheet1!AL21:AO21,3,0),0) -> 0 | BH22: =+IFERROR(VLOOKUP($BH$17,Sheet1!AL21:AO21,3,0),0) -> 0 | BI22: =+IFERROR(VLOOKUP($BI$17,Sheet1!AL21:AO21,3,0),0) -> 0 | BJ22: =+IFERROR(VLOOKUP($BJ$17,Sheet1!AL21:AO21,3,0),0) -> 0 | BK22: =+IFERROR(VLOOKUP($BK$17,Sheet1!AL21:AO21,3,0),0) -> 0 | BL22: =+IFERROR(VLOOKUP($BL$17,Sheet1!AL21:AO21,3,0),0) -> 0 | BM22: =+IFERROR(VLOOKUP($BM$17,Sheet1!AP21:AS21,3,0),0) -> 0 | BN22: 28 | BO22: =+IFERROR(VLOOKUP($BO$17,Sheet1!AX21:BA21,3,0),0) -> 0 | BP22: =+IFERROR(VLOOKUP($BP$17,Sheet1!BB21:BE21,3,0),0) -> 0 | BQ22: =+IFERROR(VLOOKUP($BQ$17,Sheet1!BF21:BI21,3,0),0) -> 0 | BR22: =+IFERROR(VLOOKUP($BR$17,Sheet1!BJ21:BM21,3,0),0) -> 0 | BS22: =+IFERROR(VLOOKUP($BS$17,Sheet1!BN21:BQ21,3,0),0) -> 0 | BT22: =+IFERROR(VLOOKUP($BT$17,Sheet1!BR21:BU21,3,0),0) -> 0 | BU22: =+IFERROR(VLOOKUP($BU$17,Sheet1!BV21:BY21,3,0),0) -> 0 | BV22: =Sheet1!E21 -> WOOD | BW22: =Sheet1!CV21 -> MD0100017 | BX22: =Sheet1!CW21 -> DRUM - 52 X 18 X 36 X 2.5 | BY22: =Sheet1!CX21 -> 1000 | BZ22: =Sheet1!BZ21 -> 4956.84 | CA22: =SUMPRODUCT($N$18:$BU$18,N22:BU22)+BZ22 -> 239131.84 | CB22: =Sheet1!CB21 -> 0 | CC22: =CA22*CB22 -> 0 | CD22: 0.18 | CE22: =CA22*CD22 -> 43043.731 | CF22: 0 | CG22: =CA22*CF22 -> 0 | CH22: =CA22+CC22+CE22+CG22 -> 282175.57 | CI22: 0.02 | CJ22: =CH22*CI22 -> 5643.5114 | CK22: 0.01 | CL22: =CH22*CK22 -> 2821.7557 | CM22: 120 | CN22: 30
A23: =Sheet1!A22 -> ENQ-12232-22-23 | B23: 45380 | C23: =Sheet1!C22 -> FA0600032 | D23: =Sheet1!D22 -> 1 CORE X 630 SQ. MM. ALU/UNARD (XLPE) | E23: =CH23+CJ23+CL23 -> 590390.27 | F23: =ROUNDUP(M56,0) -> 5619 | G23: =E23+F23 -> 596009.27 | H23: =Sheet1!CP22 -> 0.18 | I23: =G23*H23 -> 107281.67 | J23: =G23+I23 -> 703290.94 | K23: =Sheet1!CS22 -> 81.688 | L23: =Sheet1!CT22 -> KMS | M23: =J23*K23 -> 57450431 | N23: =+IFERROR(VLOOKUP($N$17,Sheet1!J22:L22,3,0),0) -> 1701 | O23: =+IFERROR(VLOOKUP($O$17,Sheet1!J22:L22,3,0),0) -> 0 | P23: =+IFERROR(VLOOKUP($P$17,Sheet1!J22:M22,3,0),0) -> 0 | Q23: =+IFERROR(VLOOKUP($Q$17,Sheet1!J22:M22,3,0),0) -> 0 | R23: =+IFERROR(VLOOKUP($R$17,Sheet1!J22:M22,3,0),0) -> 0 | S23: =+IFERROR(VLOOKUP($S$17,Sheet1!N22:Q22,3,0),0) -> 0 | T23: =+IFERROR(VLOOKUP($T$17,Sheet1!N22:Q22,3,0),0) -> 0 | U23: =+IFERROR(VLOOKUP($U$17,Sheet1!F22:I22,3,0),0) -> 0 | V23: =+IFERROR(VLOOKUP($V$17,Sheet1!F22:I22,3,0),0) -> 0 | W23: =+IFERROR(VLOOKUP($W$17,Sheet1!F22:I22,3,0),0) -> 0 | X23: =+IFERROR(VLOOKUP($X$17,Sheet1!F22:I22,3,0),0) -> 0 | Y23: =+IFERROR(VLOOKUP($Y$17,Sheet1!F22:I22,3,0),0) -> 0 | Z23: =+IFERROR(VLOOKUP($Z$17,Sheet1!F22:I22,3,0),0) -> 0 | AA23: =+IFERROR(VLOOKUP($AA$17,Sheet1!F22:I22,3,0),0) -> 0 | AB23: =+IFERROR(VLOOKUP($AB$17,Sheet1!F22:I22,3,0),0) -> 0 | AC23: =+IFERROR(VLOOKUP($AC$17,Sheet1!R22:U22,3,0),0) -> 0 | AD23: =+IFERROR(VLOOKUP($AD$17,Sheet1!R22:U22,2,0),0) -> 0 | AE23: =+IFERROR(VLOOKUP($AE$17,Sheet1!V22:Y22,3,0),0) -> 0 | AF23: 242 | AG23: =+IFERROR(VLOOKUP($AG$17,Sheet1!V22:Y22,3,0),0) -> 0 | AH23: =+IFERROR(VLOOKUP($AH$17,Sheet1!V22:Y22,3,0),0) -> 0 | AI23: =+IFERROR(VLOOKUP($AI$17,Sheet1!V22:Y22,3,0),0) -> 0 | AJ23: =+IFERROR(VLOOKUP($AJ$17,Sheet1!V22:Y22,3,0),0) -> 0 | AK23: =+IFERROR(VLOOKUP($AK$17,Sheet1!Z22:AB22,3,0),0) -> 0 | AL23: =+IFERROR(VLOOKUP($AL$17,Sheet1!AD22:AG22,3,0),0) -> 0 | AM23: =+IFERROR(VLOOKUP($AM$17,Sheet1!AD22:AG22,3,0),0) -> 0 | AN23: =+IFERROR(VLOOKUP($AN$17,Sheet1!AD22:AG22,3,0),0) -> 0 | AO23: =+IFERROR(VLOOKUP($AO$17,Sheet1!AD22:AG22,3,0),0) -> 0 | AP23: =+IFERROR(VLOOKUP($AP$17,Sheet1!AD22:AG22,3,0),0) -> 0 | AQ23: =+IFERROR(VLOOKUP($AQ$17,Sheet1!AD22:AG22,3,0),0) -> 0 | AR23: =+IFERROR(VLOOKUP($AR$17,Sheet1!AD22:AG22,3,0),0) -> 0 | AS23: =+IFERROR(VLOOKUP($AS$17,Sheet1!AH22:AK22,3,0),0) -> 0 | AT23: =+IFERROR(VLOOKUP($AT$17,Sheet1!AH22:AK22,3,0),0) -> 0 | AU23: =+IFERROR(VLOOKUP($AU$17,Sheet1!AH22:AK22,3,0),0) -> 0 | AV23: =+IFERROR(VLOOKUP($AV$17,Sheet1!AH22:AK22,3,0),0) -> 0 | AW23: =+IFERROR(VLOOKUP($AW$17,Sheet1!AH22:AK22,3,0),0) -> 0 | AX23: =+IFERROR(VLOOKUP($AX$17,Sheet1!AH22:AK22,3,0),0) -> 0 | AY23: =+IFERROR(VLOOKUP($AY$17,Sheet1!AH22:AK22,3,0),0) -> 0 | AZ23: =+IFERROR(VLOOKUP($AZ$17,Sheet1!AH22:AK22,3,0),0) -> 0 | BA23: =+IFERROR(VLOOKUP($BA$17,Sheet1!AH22:AK22,3,0),0) -> 0 | BB23: =+IFERROR(VLOOKUP($BB$17,Sheet1!AH22:AK22,3,0),0) -> 0 | BC23: =+IFERROR(VLOOKUP($BC$17,Sheet1!AL22:AO22,3,0),0) -> 0 | BD23: =+IFERROR(VLOOKUP($BD$17,Sheet1!AL22:AO22,3,0),0) -> 0 | BE23: =+IFERROR(VLOOKUP($BE$17,Sheet1!AL22:AO22,3,0),0) -> 0 | BF23: 408 | BG23: =+IFERROR(VLOOKUP($BG$17,Sheet1!AL22:AO22,3,0),0) -> 0 | BH23: =+IFERROR(VLOOKUP($BH$17,Sheet1!AL22:AO22,3,0),0) -> 0 | BI23: =+IFERROR(VLOOKUP($BI$17,Sheet1!AL22:AO22,3,0),0) -> 0 | BJ23: =+IFERROR(VLOOKUP($BJ$17,Sheet1!AL22:AO22,3,0),0) -> 0 | BK23: =+IFERROR(VLOOKUP($BK$17,Sheet1!AL22:AO22,3,0),0) -> 0 | BL23: =+IFERROR(VLOOKUP($BL$17,Sheet1!AL22:AO22,3,0),0) -> 0 | BM23: =+IFERROR(VLOOKUP($BM$17,Sheet1!AP22:AS22,3,0),0) -> 0 | BN23: 40 | BO23: =+IFERROR(VLOOKUP($BO$17,Sheet1!AX22:BA22,3,0),0) -> 0 | BP23: =+IFERROR(VLOOKUP($BP$17,Sheet1!BB22:BE22,3,0),0) -> 0 | BQ23: =+IFERROR(VLOOKUP($BQ$17,Sheet1!BF22:BI22,3,0),0) -> 0 | BR23: =+IFERROR(VLOOKUP($BR$17,Sheet1!BJ22:BM22,3,0),0) -> 0 | BS23: =+IFERROR(VLOOKUP($BS$17,Sheet1!BN22:BQ22,3,0),0) -> 0 | BT23: =+IFERROR(VLOOKUP($BT$17,Sheet1!BR22:BU22,3,0),0) -> 0 | BU23: =+IFERROR(VLOOKUP($BU$17,Sheet1!BV22:BY22,3,0),0) -> 0 | BV23: =Sheet1!E22 -> WOOD | BW23: =Sheet1!CV22 -> MD0100062 | BX23: =Sheet1!CW22 -> DRUM - 74 X 24 X 32 X 3 | BY23: =Sheet1!CX22 -> 1000 | BZ23: =Sheet1!BZ22 -> 17290 | CA23: =SUMPRODUCT($N$18:$BU$18,N23:BU23)+BZ23 -> 485758 | CB23: =Sheet1!CB22 -> 0 | CC23: =CA23*CB23 -> 0 | CD23: 0.18 | CE23: =CA23*CD23 -> 87436.44 | CF23: 0 | CG23: =CA23*CF23 -> 0 | CH23: =CA23+CC23+CE23+CG23 -> 573194.44 | CI23: 0.02 | CJ23: =CH23*CI23 -> 11463.889 | CK23: 0.01 | CL23: =CH23*CK23 -> 5731.9444 | CM23: 300 | CN23: 65
