Workbook

Sheet Sheet1
A1: DOCKET NO. | B1: Base Date | C1: ITEM CODE | D1: PROPOSE ERP ITEM NAME | E1: Propose Drum Type | F1: Insulation Screening(Metallic) | G1: RM Rate(Insulation Screening(Metallic)) | H1: Weight (Insulation Screening (Metallic)) | I1: Cost Insulation Screening(Metallic) | J1: Conductor | K1: RM Rate(Conductor) | L1: Weight(Conductor) | M1: Cost(Conductor) | N1: AL ALLOY | O1: RM Rate(AL Alloy) | P1: Weight(Al Alloy) | Q1: Cost(AL Alloy) | R1: Insulation Screening(Non-Metallic) | S1: RM Rate(Insulation Screening(Non-Metallic)) | T1: Weight(Insulation Screening(Non-Metallic) | U1: Cost(Insulation Screening(Non-Metallic) | V1: Insulation | W1: RM Rate(Insulation) | X1: Weight(Insulation) | Y1: Cost(Insulation) | Z1: Poly Tape | AA1: RM Rate(Poly Tape) | AB1: Weight(Poly Tape) | AC1: Cost(Poly Tape) | AD1: Inner Sheath | AE1: RM Rate(Inner Sheath) | AF1: Weight(Inner Sheath) | AG1: Cost(Inner Sheath) | AH1: Armouring | AI1: RM Rate(Armouring) | AJ1: Weight(Armouring) | AK1: Cost(Armouring) | AL1: Outer Sheath | AM1: RM Rate(Outer Sheath) | AN1: Weight(Outer Sheath) | AO1: Cost(Outer Sheath) | AP1: Filler | AQ1: RM Rate(Filler) | AR1: Weight(Filler) | AS1: Cost(Filler) | AT1: Grease | AU1: RM Rate(Grease) | AV1: Weight(Grease) | AW1: Cost(Grease) | AX1: Water Swellable Tape | AY1: RM Rate(Water Swellable Tape) | AZ1: Weight(Water Swellable Tape) | BA1: Cost(Water Swellable Tape) | BB1: Semi Conducting Water Swellable Tape | BC1: RM Rate(Semi Conducting Water Swellable Tape) | BD1: Weight(Semi Conducting Water Swellable Tape) | BE1: Cost(Semi Conducting Water Swellable Tape) | BF1: Semicon Tape | BG1: RM Rate(Semicon Tape) | BH1: Weight(Semicon Tape) | BI1: Cost(Semicon Tape) | BJ1: Glass Fiber Tape | BK1: RM Rate(Glass Fiber Tape) | BL1: Weight(Glass Fiber Tape) | BM1: Cost(Glass Fiber Tape) | BN1: Copper Wire 0.8MM | BO1: RM Rate(Copper Wire 0.8MM) | BP1: Weight(Copper Wire 0.8MM) | BQ1: Cost(Copper Wire 0.8MM) | BR1: Rubberized Cotton Tape | BS1: RM Rate(Rubberized Cotton Tape) | BT1: Weight(Rubberized Cotton Tape) | BU1: Cost(Rubberized Cotton Tape) | BV1: Water Tight Compound | BW1: RM Rate(Water Tight Compound) | BX1: Weight(Water Tight Compound) | BY1: Cost(Water Tight Compound) | BZ1: Drum Cost Per KM | CA1: Total RM Cost | CB1: FIRM % | CC1: Firm Value | CD1: MFG% | CE1: MFG Value | CF1: PROF% | CG1: Profit Value | CH1: 1st EX-Works | CI1: Intt % | CJ1: Intt Value | CK1: insp% | CL1: Insp Value | CM1: TTR CHARGES% | CN1: TTR Value | CO1: EX-Works Per KM | CP1: Freight Per KM | CQ1: Price Including Freight Per KM | CR1: GST % | CS1: GST Value | CT1: Price Including GST & Freight Per KM | CU1: QTY | CV1: Unit | CW1: Total Price Of Full QTY(Including Freight&GST) | CX1: PARTY LENGTH (IF STANDER LENGTH NOT MATCH WITH PAR | CY1: DRUM CODE | CZ1: DRUM SIZE (FxbXtx Ft)
A2: ENQ-18775-25-26 | C2: FA0400106 | D2: 3 CORE X 120 SQ MM + 1 CORE X 125 SQ MM (AB CABLES) (INSULATED) - 11 KV | E2: STEEL | F2: Copper Tape - 0.060 mm | H2: 136 | J2: Alumimium | L2: 972 | N2: Alumimium Alloy | P2: 348 | R2: Extruded Semiconductive | T2: 300 | V2: HT-XLPE | X2: 584 | AB2: 0 | AF2: 0 | AJ2: 0 | AL2: PVC Type ST-2 | AN2: 901 | AR2: 0 | AV2: 0 | AZ2: 0 | BD2: 0 | BH2: 0 | BL2: 0 | BP2: 0 | BT2: 0 | BX2: 0 | BZ2: 56560 | CA2: 56560 | CH2: 56560 | CO2: 56560 | CQ2: 56560 | CR2: 0.18 | CS2: 10180.8 | CT2: 66740.8 | CU2: 45 | CV2: KMS | CW2: 3003336 | CY2: SP0400123 | CZ2: DRUM - 2000 X 1000 X 1200
A3: ENQ-18775-25-26 | C3: FA1300004 | D3: 3 CORE X 300 SQ. MM. AL/ARM - STRIP (XLPE) - 11 KV | E3: STEEL | F3: Copper Tape - 0.04 mm | H3: 108 | J3: Alumimium | L3: 2430 | P3: 0 | R3: Extruded Semiconductive | T3: 337 | V3: HT-XLPE | X3: 802 | AB3: 0 | AD3: PVC Type ST-2 | AF3: 277 | AH3: Galvanised Steel Flat Strip | AJ3: 1125 | AL3: PVC Type ST-2 | AN3: 995 | AP3: FILLER | AR3: 1258 | AV3: 0 | AZ3: 0 | BD3: 0 | BH3: 0 | BL3: 88 | BP3: 0 | BR3: RUBBERIZED COTTON TAPE | BT3: 0 | BX3: 0 | BZ3: 60800 | CA3: 60800 | CH3: 60800 | CO3: 60800 | CQ3: 60800 | CR3: 0.18 | CS3: 10944 | CT3: 71744 | CU3: 270 | CV3: KMS | CW3: 19370880 | CY3: SP0400141 | CZ3: CORRUGATED DISPATCH STEEL DRUM 2080 X 1000 X 1400 MM
A4: ENQ-18775-25-26 | C4: FA1300006 | D4: 3 CORE X 70 SQ. MM. AL/ARM - STRIP (XLPE) - 11 KV | E4: STEEL | F4: Copper Tape - 0.04 mm | H4: 71 | J4: Alumimium | L4: 567 | P4: 0 | R4: Extruded Semiconductive | T4: 188 | V4: HT-XLPE | X4: 474 | AB4: 0 | AD4: PVC Type ST-2 | AF4: 142 | AH4: Galvanised Steel Flat Strip | AJ4: 750 | AL4: PVC Type ST-2 | AN4: 474 | AP4: FILLER | AR4: 533 | AV4: 0 | AZ4: 0 | BD4: 0 | BH4: 0 | BL4: 0 | BP4: 0 | BR4: RUBBERIZED COTTON TAPE | BT4: 0 | BX4: 0 | CR4: 0.18 | CU4: 15 | CV4: KMS | CY4: SP0400118 | CZ4: CORRUGATED DISPATCH STEEL DRUM 1700 X 1000 X 1200
A5: ENQ-18775-25-26 | C5: FA1300010 | D5: 3 CORE X 400 SQ. MM. AL/ARM - STRIP (XLPE) - 33 KV | E5: STEEL | F5: Copper Tape - 0.04 mm | H5: 159 | J5: Alumimium | L5: 3240 | P5: 0 | R5: Extruded Semiconductive | T5: 427 | V5: HT-XLPE | X5: 2621 | AB5: 0 | AD5: PVC Type ST-2 | AF5: 405 | AH5: Galvanised Steel Flat Strip | AJ5: 1600 | AL5: PVC Type ST-2 | AN5: 1560 | AP5: FILLER | AR5: 2672 | AV5: 0 | AZ5: 162 | BD5: 0 | BH5: 52 | BL5: 129 | BP5: 0 | BR5: RUBBERIZED COTTON TAPE | BT5: 0 | BX5: 0 | BZ5: 182400 | CA5: 182400 | CH5: 182400 | CO5: 182400 | CQ5: 182400 | CR5: 0.18 | CS5: 32832 | CT5: 215232 | CU5: 195 | CV5: KMS | CW5: 41970240 | CY5: SP0400105 | CZ5: CORRUGATED DISPATCH STEEL DRUM 2500 X 1500 X 1400
A6: ENQ-18775-25-26 | C6: FA1300015 | D6: 3 CORE X 300 SQ. MM. AL/ARM - STRIP (XLPE) - 33 KV | E6: STEEL | F6: Copper Tape - 0.04 mm | H6: 146 | J6: Alumimium | L6: 2430 | P6: 0 | R6: Extruded Semiconductive(Stripable) | T6: 386 | V6: TR XLPE | X6: 2385 | Z6: POLY TAPE | AB6: 0 | AD6: PVC Type ST-2 | AF6: 378 | AH6: Galvanised Steel Flat Strip | AJ6: 1500 | AL6: FRLSH PVC Type ST-2 | AN6: 1460 | AP6: Polypropylene Filler | AR6: 2315 | AV6: 0 | AX6: Water swellable Tape | AZ6: 0 | BB6: Semi conducting Water Swellable tape | BD6: 0 | BH6: 0 | BL6: 0 | BP6: 0 | BR6: RUBBERIZED COTTON TAPE | BT6: 0 | BX6: 0 | BZ6: 182400 | CA6: 182400 | CH6: 182400 | CO6: 182400 | CQ6: 182400 | CR6: 0.18 | CS6: 32832 | CT6: 215232 | CU6: 3 | CV6: KMS | CW6: 645696 | CY6: SP0400105 | CZ6: CORRUGATED DISPATCH STEEL DRUM 2500 X 1500 X 1400
A7: ENQ-18775-25-26 | C7: FA1300052 | D7: 3 CORE X 150 SQ. MM. AL/ARM - STRIP (XLPE) - 11 KV | E7: STEEL | F7: Copper Tape - 0.04 mm | H7: 88 | J7: Alumimium | L7: 1215 | P7: 0 | R7: Extruded Semiconductive | T7: 246 | V7: HT-XLPE | X7: 620 | AB7: 0 | AD7: PVC Type ST-2 | AF7: 200 | AH7: Galvanised Steel Flat Strip | AJ7: 900 | AL7: PVC Type ST-2 | AN7: 672 | AP7: FILLER | AR7: 809 | AV7: 0 | AZ7: 0 | BD7: 0 | BH7: 0 | BL7: 0 | BP7: 0 | BR7: RUBBERIZED COTTON TAPE | BT7: 0 | BX7: 0 | BZ7: 53200 | CA7: 53200 | CH7: 53200 | CO7: 53200 | CQ7: 53200 | CR7: 0.18 | CS7: 9576 | CT7: 62776 | CU7: 15 | CV7: KMS | CW7: 941640 | CY7: SP0400112 | CZ7: CORRUGATED DISPATCH STEEL DRUM 2000 X 1000 X 1000 MM

Sheet AUTO CALCULATION SHEET (2)
A2: Noida Power Company Ltd.
A4: TENDER SPECIFICATION NO () | B4: NPCL/FY25-26/HTCAB/061
A5: TENDER DESCRIPTION () | B5: TENDER NOTIFICATION FOR 18 MONTHS RATE CONTRACT OF SUPPLY OF HT ABC CABLE & HT CABLES (LOT 3)
A6: Last Date & Time of Submission () | B6: 19.03.2026 up to 15:00 Hours OPENING ON 19.03.2026 up to 15:00 Hours
A7: REVERSE AUCTION | B7: Purchaser reserves the right to use Reverse Auction through SAP-SRM as an optional tool as an integral part of the entire tendering process. All techno-commercially qualified bidders shall participate in this event.
A8: Price () | B8: Prices are as per latest IEEMA PV Formula The prices shall variable be as per Latest IEEMA Price Variation formula as mentioned below; P = Po + AIF (AI – Alo) + XLFAL(CC-Cco)+ SMIF (SMIF-SMIF0) + FeF(FeF-FeF0) + CCFAI (PVCc - PVCco) All #0# denoted input prices in the formula (Al0, CC0, SMIF0, PVCc0, Fe0, etc.) shall be as per IEEMA Circulars of January 2026 (Published in February 2026). P = P₀ + Alph × n × (Al - Al₀) + Alm × (Al - Al₀) + CUFtph × n × (Cu - Cu₀)+ CCF1Alph × n × (CC - CC₀) + CCF2Alph × n × (PVCc - PVCc₀) + CCFAlm × (CC - CC₀) This price shall be as per IEEMA Circulars of January 2026 (Published in February 2026).
A9: Validity () | B9: Bids shall remain valid for 120 days from the due date of submission of the Bid & subsequent corrigendum / amendment / extension of due date of submission.
A10: Delivery Period () | B10: 90 Days from the date of issuance of LOI / Order; however, firm delivery dates will be mentioned in the LOI / Order.
A11: Payment Terms () | B11: 15% Basic value of Release Order payment shall be paid as interest free advance against submission of Advance Bank Guarantee (ABG) of a nationalized/scheduled bank(s) located at State Capital/Delhi NCR, payable at Delhi/Noida / Corporate Guarantee as may be acceptable to the NPCL, for the equal amount valid up to the PO supply completion period plus 3 months claim period. In case of delay, the BG shall be extended suitably by the bidder. Bidder can request to submit Corporate guarantee in place of ABG, Same request can be considered with discretion of NPCL management only. 80% Payment shall be released on pro-rata basic within 45 days from the receipt of material at NPCL site with complete set of documents as mentioned in order. Your invoices complete in all respect along with all required documents should reach our office within 3 days. Any delay in submission of any of these documents will be to your account. It may please be noted that for payment purposes the date of receipt of documents will be considered on the basis of the date of receipt of last document, in case partial documents were received earlier. Balance 5% payment shall be released against submission of the Performance Bank Guarantee (PBG) of 5% of PO/Contract value valid up to defect liability period Plus 3 months towards the Claim Period.
A12: Standard length () | B12: 33kv 3 core = 500 meters ±2% 11kv 3 core = 500 meters ±2% 11kv 3cx120+150 = 500 meter +/-5%
A13: Packing () | B13: 33kv 3 core = Non-returnable MS steel drum 11kv 3 core = Non-returnable MS steel drum 11kv 3cx120+150 = Cable shall be supplied in wooden drum conforming to IS:10418
A14: Technical Specification
N17: Conductor | V17: AL ALLOY | X17: Insulation Screening (Metallic) | AF17: Insulation Screening (Non-Metallic) | AH17: Insulation | AQ17: POLY TAPE | AR17: Inner Sheath | BA17: Armouring | BL17: Outer Sheath | BX17: FILLER | BY17: GREASE | BZ17: Water swellable Tape | CA17: Semi conducting Water Swellable tape | CB17: SEMICON TAPE | CC17: GLASS FIBER TAPE | CD17: COPPER WIRE 0.8 MM | CE17: RUBBERIZED COTTON TAPE | CF17: Water Tight Compound | CG17: DRUM TYPE | CK17: DRUM COST PER KM | CL17: TOTAL RM COST | CM17: EXTRA CONSUMPTION | CN17: EXTRA CONSUMPTION VALUE | CZ17: $A$1
A18: DOCKET NO. | B18: BASE DATE | C18: ITEM CODE | D18: PROPOSE ERP ITEM NAME | E18: EX-WORKS (PER KM) | F18: FREIGHT PER KM | G18: PRICE INCLUDING FREIGHT (PER KM) | H18: GST % | I18: GST VALUE | J18: PRICE INCLUDING GST & FREIGHT (PER KM) | K18: QTY | L18: Unit | M18: TOTAL PRICE OF FULL QTY (INCLUDING FRIGHT & GST) | N18: Alumimium | O18: Alumimium ALLOY | P18: Copper | Q18: AL-59 | R18: AL-4 | S18: AL-7 | T18: Flexible Copper | U18: Galvanized steel wire | V18: Alumimium | W18: Alumimium ALLOY | X18: Coper tape - 0.1 mm | Y18: Copper Tape - 0.03 mm | Z18: Copper Tape - 0.035 mm | AA18: Copper Tape - 0.04 mm | AB18: Copper Tape - 0.045 mm | AC18: Copper Tape - 0.050 mm | AD18: Copper Tape - 0.060 mm | AE18: Copper Tape - 0.075 mm(DOUBLE) | AF18: Extruded semiconductive | AG18: Extruded Semiconductive(Stripable) | AH18: HT-XLPE | AI18: LT-XLPE | AJ18: TR XLPE | AK18: Type A PVC | AL18: Type C PVC (HR) | AM18: Type A PVC-1.45 | AN18: Type A PVC-FR | AO18: Type A PVC-FRLS | AP18: Type A PVC-1.38 | AQ18: POLY TAPE | AR18: FR PVC Type ST-1 | AS18: FR PVC Type ST-2 | AT18: FRLSH PVC Type ST-1 | AU18: FRLSH PVC Type ST-2 | AV18: PVC Type ST-1 | AW18: PVC Type ST-1-PRESSURE EXTRUDED | AX18: PVC Type ST-2 | AY18: PVC COMPOUND 1.48 | AZ18: PVC Type ST-2-PRESSURE EXTRUDED | BA18: ACSR CORE WIRE | BB18: ACSR DOG STEEL WIRE | BC18: Aluminium Flat Strip | BD18: Aluminium Round Wire | BE18: Alumimium Tape | BF18: Double Steel Tape | BG18: Galvanised Steel Flat Strip | BH18: Galvanised Steel Flat Strip (Double) | BI18: Galvanised Steel Flat Strip-B | BJ18: Galvanised Steel Round Wire | BK18: Galvanised Steel Round Wire (Double) | BL18: FR PVC Type ST-1 | BM18: FR PVC Type ST-2 | BN18: FRLSH PVC Type ST-1 | BO18: FRLSH PVC Type ST-2 | BP18: ZHFR | BQ18: PE-ST-3 | BR18: PE-ST-7 | BS18: PVC Type ST-1 | BT18: PVC Type ST-2 | BU18: PVC COMPOUND 1.48 | BV18: PVC Type ST-2-PRESSURE EXTRUDED | BW18: UV & Track Resistant XLPE | BX18: FILLER | BY18: PP FILLER | BZ18: Al Tape (15x0.10) | CA18: Semi conducting Water Swellable tape | CB18: NCWT | CC18: GLASS FIBER TAPE | CD18: COPPER WIRE 0.8 MM | CE18: RUBBERIZED COTTON TAPE | CF18: Al Wire Screen | CG18: PROPOSE DRUM TYPE | CH18: DRUM CODE | CI18: DRUM SIZE (FxbXtx Ft) | CJ18: PARTY STANDARD LENGTH (MTR) | CO18: MFG% | CP18: MFG VALUE | CQ18: PROF% | CR18: PROFIT VALUE | CS18: 1ST EX-WORKS | CT18: Intt % | CU18: INTT VALUE | CV18: insp% | CW18: INSP VALUE | CX18: TTR Charges% | CY18: TTR Charges VALUE
N19: 335 | O19: =+IFERROR(VLOOKUP($O$18,Sheet1!J:L,2,0),0) -> 0 | P19: =+IFERROR(VLOOKUP($P$18,Sheet1!J:M,2,0),0) -> 0 | Q19: =+IFERROR(VLOOKUP($Q$18,Sheet1!J:M,2,0),0) -> 0 | R19: =+IFERROR(VLOOKUP($R$18,Sheet1!J:M,2,0),0) -> 0 | S19: =+IFERROR(VLOOKUP($S$18,Sheet1!J:M,2,0),0) -> 0 | T19: =+IFERROR(VLOOKUP($T$18,Sheet1!J:M,2,0),0) -> 0 | U19: =+IFERROR(VLOOKUP($U$18,Sheet1!J:M,2,0),0) -> 0 | V19: =+IFERROR(VLOOKUP($V$18,Sheet1!N:Q,2,0),0) -> 0 | W19: =N19+5 -> 340 | X19: =+IFERROR(VLOOKUP($X$18,Sheet1!F:I,2,0),0) -> 0 | Y19: =+IFERROR(VLOOKUP($Y$18,Sheet1!F:I,2,0),0) -> 0 | Z19: =+IFERROR(VLOOKUP($Z$18,Sheet1!F:I,2,0),0) -> 0 | AA19: 1276 | AB19: =+IFERROR(VLOOKUP($AB$18,Sheet1!F:I,2,0),0) -> 0 | AC19: =+IFERROR(VLOOKUP($AC$18,Sheet1!F:I,2,0),0) -> 0 | AD19: =+IFERROR(VLOOKUP($AD$18,Sheet1!F:I,2,0),0) -> 0 | AE19: =+IFERROR(VLOOKUP($AE$18,Sheet1!F:I,2,0),0) -> 0 | AF19: =+IFERROR(VLOOKUP($AF$18,Sheet1!R:U,2,0),0) -> 0 | AG19: 170 | AH19: 125 | AI19: =+IFERROR(VLOOKUP($AI$18,Sheet1!V:Y,2,0),0) -> 0 | AJ19: 200 | AK19: =+IFERROR(VLOOKUP($AK$18,Sheet1!V:Y,2,0),0) -> 0 | AL19: =+IFERROR(VLOOKUP($AL$18,Sheet1!V:Y,2,0),0) -> 0 | AM19: =+IFERROR(VLOOKUP($AM$18,Sheet1!V:Y,2,0),0) -> 0 | AN19: =+IFERROR(VLOOKUP($AN$18,Sheet1!V:Y,2,0),0) -> 0 | AO19: =+IFERROR(VLOOKUP($AO$18,Sheet1!V:Y,2,0),0) -> 0 | AP19: =+IFERROR(VLOOKUP($AP$18,Sheet1!V:Y,2,0),0) -> 0 | AQ19: 110 | AR19: =+IFERROR(VLOOKUP($AR$18,Sheet1!AD2:AG840,2,0),0) -> 0 | AS19: =+IFERROR(VLOOKUP($AS$18,Sheet1!AD2:AG840,2,0),0) -> 0 | AT19: =+IFERROR(VLOOKUP($AT$18,Sheet1!AD2:AG840,2,0),0) -> 0 | AU19: =+IFERROR(VLOOKUP($AU$18,Sheet1!AD2:AG840,2,0),0) -> 0 | AV19: =+IFERROR(VLOOKUP($AV$18,Sheet1!AD2:AG840,2,0),0) -> 0 | AW19: =+IFERROR(VLOOKUP($AW$18,Sheet1!AD2:AG840,2,0),0) -> 0 | AX19: 59 | AY19: =+IFERROR(VLOOKUP($AY$18,Sheet1!AD2:AG840,2,0),0) -> 0 | AZ19: =+IFERROR(VLOOKUP($AZ$18,Sheet1!AD2:AG840,2,0),0) -> 0 | BA19: =+IFERROR(VLOOKUP($BA$18,Sheet1!AH2:AK840,2,0),0) -> 0 | BB19: =+IFERROR(VLOOKUP($BB$18,Sheet1!AH2:AK840,2,0),0) -> 0 | BC19: =+IFERROR(VLOOKUP($BC$18,Sheet1!AH2:AK840,2,0),0) -> 0 | BD19: =+IFERROR(VLOOKUP($BD$18,Sheet1!AH2:AK840,2,0),0) -> 0 | BE19: =+IFERROR(VLOOKUP($BE$18,Sheet1!AH2:AK840,2,0),0) -> 0 | BF19: =+IFERROR(VLOOKUP($BF$18,Sheet1!AH2:AK840,2,0),0) -> 0 | BG19: 74 | BH19: =+IFERROR(VLOOKUP($BH$18,Sheet1!AH2:AK840,2,0),0) -> 0 | BI19: =+IFERROR(VLOOKUP($BI$18,Sheet1!AH2:AK840,2,0),0) -> 0 | BJ19: =+IFERROR(VLOOKUP($BJ$18,Sheet1!AH2:AK840,2,0),0) -> 0 | BK19: =+IFERROR(VLOOKUP($BK$18,Sheet1!AH2:AK840,2,0),0) -> 0 | BL19: =+IFERROR(VLOOKUP($BL$18,Sheet1!AL2:AO840,2,0),0) -> 0 | BM19: =+IFERROR(VLOOKUP($BM$18,Sheet1!AL2:AO840,2,0),0) -> 0 | BN19: =+IFERROR(VLOOKUP($BN$18,Sheet1!AL2:AO840,2,0),0) -> 0 | BO19: 76 | BP19: =+IFERROR(VLOOKUP($BP$18,Sheet1!AL2:AO840,2,0),0) -> 0 | BQ19: =+IFERROR(VLOOKUP($BQ$18,Sheet1!AL2:AO840,2,0),0) -> 0 | BR19: 96 | BS19: =+IFERROR(VLOOKUP($BS$18,Sheet1!AL2:AO840,2,0),0) -> 0 | BT19: =+IFERROR(VLOOKUP($BT$18,Sheet1!AL2:AO840,2,0),0) -> 0 | BU19: =+IFERROR(VLOOKUP($BU$18,Sheet1!AL2:AO840,2,0),0) -> 0 | BV19: =+IFERROR(VLOOKUP($BV$18,Sheet1!AL2:AO840,2,0),0) -> 0 | BW19: =+IFERROR(VLOOKUP($BW$18,Sheet1!AL2:AO840,2,0),0) -> 0 | BX19: 27 | BY19: 76 | BZ19: 491 | CA19: 369 | CB19: 310 | CC19: =+IFERROR(VLOOKUP($CC$18,Sheet1!BJ2:BM840,2,0),0) -> 0 | CD19: =+IFERROR(VLOOKUP($CD$18,Sheet1!BN2:BQ840,2,0),0) -> 0 | CE19: 282 | CF19: =N19+5 -> 340
A20: =Sheet1!A7 -> ENQ-18775-25-26 | B20: 46023 | C20: =Sheet1!C7 -> FA1300052 | D20: =Sheet1!D7 -> 3 CORE X 150 SQ. MM. AL/ARM - STRIP (XLPE) - 11 KV | E20: =CS20+CU20+CW20+CY20 -> 1207624.9 | F20: =ROUNDUP(M30,0) -> 36000 | G20: =E20+F20 -> 1243624.9 | H20: =Sheet1!CR7 -> 0.18 | I20: =G20*H20 -> 223852.48 | J20: =G20+I20 -> 1467477.3 | K20: =Sheet1!CU7 -> 15 | L20: =Sheet1!CV7 -> KMS | M20: =J20*K20 -> 22012160 | N20: =+IFERROR(VLOOKUP($N$18,Sheet1!J7:L7,3,0),0) -> 1215 | O20: =+IFERROR(VLOOKUP($O$18,Sheet1!J7:L7,3,0),0) -> 0 | P20: =+IFERROR(VLOOKUP($P$18,Sheet1!J7:M7,3,0),0) -> 0 | Q20: =+IFERROR(VLOOKUP($Q$18,Sheet1!J7:M7,3,0),0) -> 0 | R20: =+IFERROR(VLOOKUP($R$18,Sheet1!J7:M7,3,0),0) -> 0 | S20: =+IFERROR(VLOOKUP($S$18,Sheet1!J7:M7,3,0),0) -> 0 | T20: =+IFERROR(VLOOKUP($T$18,Sheet1!J7:M7,3,0),0) -> 0 | U20: =+IFERROR(VLOOKUP($U$18,Sheet1!J7:M7,3,0),0) -> 0 | V20: =+IFERROR(VLOOKUP($V$18,Sheet1!N7:Q7,3,0),0) -> 0 | W20: =+IFERROR(VLOOKUP($W$18,Sheet1!N7:Q7,3,0),0) -> 0 | X20: =+IFERROR(VLOOKUP($X$18,Sheet1!F7:I7,3,0),0) -> 0 | Y20: =+IFERROR(VLOOKUP($Y$18,Sheet1!F7:I7,3,0),0) -> 0 | Z20: =+IFERROR(VLOOKUP($Z$18,Sheet1!F7:I7,3,0),0) -> 0 | AA20: 99 | AB20: =+IFERROR(VLOOKUP($AB$18,Sheet1!F7:I7,3,0),0) -> 0 | AC20: =+IFERROR(VLOOKUP($AC$18,Sheet1!F7:I7,3,0),0) -> 0 | AD20: =+IFERROR(VLOOKUP($AD$18,Sheet1!F7:I7,3,0),0) -> 0 | AE20: =+IFERROR(VLOOKUP($AE$18,Sheet1!F7:I7,3,0),0) -> 0 | AG20: 246 | AH20: =+IFERROR(VLOOKUP($AH$18,Sheet1!V7:Y7,3,0),0) -> 620 | AI20: =+IFERROR(VLOOKUP($AI$18,Sheet1!V7:Y7,3,0),0) -> 0 | AJ20: =+IFERROR(VLOOKUP($AJ$18,Sheet1!V7:Y7,3,0),0) -> 0 | AK20: =+IFERROR(VLOOKUP($AK$18,Sheet1!V7:Y7,3,0),0) -> 0 | AL20: =+IFERROR(VLOOKUP($AL$18,Sheet1!V7:Y7,3,0),0) -> 0 | AM20: =+IFERROR(VLOOKUP($AM$18,Sheet1!V7:Y7,3,0),0) -> 0 | AN20: =+IFERROR(VLOOKUP($AN$18,Sheet1!V7:Y7,3,0),0) -> 0 | AO20: =+IFERROR(VLOOKUP($AO$18,Sheet1!V7:Y7,3,0),0) -> 0 | AP20: =+IFERROR(VLOOKUP($AP$18,Sheet1!V7:Y7,3,0),0) -> 0 | AQ20: 37 | AR20: =+IFERROR(VLOOKUP($AR$18,Sheet1!AD7:AG7,3,0),0) -> 0 | AS20: =+IFERROR(VLOOKUP($AS$18,Sheet1!AD7:AG7,3,0),0) -> 0 | AT20: =+IFERROR(VLOOKUP($AT$18,Sheet1!AD7:AG7,3,0),0) -> 0 | AU20: =+IFERROR(VLOOKUP($AU$18,Sheet1!AD7:AG7,3,0),0) -> 0 | AV20: =+IFERROR(VLOOKUP($AV$18,Sheet1!AD7:AG7,3,0),0) -> 0 | AW20: =+IFERROR(VLOOKUP($AW$18,Sheet1!AD7:AG7,3,0),0) -> 0 | AX20: 210 | AY20: =+IFERROR(VLOOKUP($AY$18,Sheet1!AD7:AG7,3,0),0) -> 0 | AZ20: =+IFERROR(VLOOKUP($AZ$18,Sheet1!AD7:AG7,3,0),0) -> 0 | BA20: =+IFERROR(VLOOKUP($BA$18,Sheet1!AH7:AK7,3,0),0) -> 0 | BB20: =+IFERROR(VLOOKUP($BB$18,Sheet1!AH7:AK7,3,0),0) -> 0 | BC20: =+IFERROR(VLOOKUP($BC$18,Sheet1!AH7:AK7,3,0),0) -> 0 | BD20: =+IFERROR(VLOOKUP($BD$18,Sheet1!AH7:AK7,3,0),0) -> 0 | BE20: =+IFERROR(VLOOKUP($BE$18,Sheet1!AH7:AK7,3,0),0) -> 0 | BF20: =+IFERROR(VLOOKUP($BF$18,Sheet1!AH7:AK7,3,0),0) -> 0 | BG20: 972 | BH20: =+IFERROR(VLOOKUP($BH$18,Sheet1!AH7:AK7,3,0),0) -> 0 | BI20: =+IFERROR(VLOOKUP($BI$18,Sheet1!AH7:AK7,3,0),0) -> 0 | BJ20: =+IFERROR(VLOOKUP($BJ$18,Sheet1!AH7:AK7,3,0),0) -> 0 | BK20: =+IFERROR(VLOOKUP($BK$18,Sheet1!AH7:AK7,3,0),0) -> 0 | BL20: =+IFERROR(VLOOKUP($BL$18,Sheet1!AL7:AO7,3,0),0) -> 0 | BM20: =+IFERROR(VLOOKUP($BM$18,Sheet1!AL7:AO7,3,0),0) -> 0 | BN20: =+IFERROR(VLOOKUP($BN$18,Sheet1!AL7:AO7,3,0),0) -> 0 | BO20: 739 | BP20: =+IFERROR(VLOOKUP($BP$18,Sheet1!AL7:AO7,3,0),0) -> 0 | BQ20: =+IFERROR(VLOOKUP($BQ$18,Sheet1!AL7:AO7,3,0),0) -> 0 | BR20: =+IFERROR(VLOOKUP($BR$18,Sheet1!AL7:AO7,3,0),0) -> 0 | BS20: =+IFERROR(VLOOKUP($BS$18,Sheet1!AL7:AO7,3,0),0) -> 0 | BU20: =+IFERROR(VLOOKUP($BU$18,Sheet1!AL7:AO7,3,0),0) -> 0 | BV20: =+IFERROR(VLOOKUP($BV$18,Sheet1!AL7:AO7,3,0),0) -> 0 | BW20: =+IFERROR(VLOOKUP($BW$18,Sheet1!AL7:AO7,3,0),0) -> 0 | BX20: =+IFERROR(VLOOKUP($BX$18,Sheet1!AP7:AS7,3,0),0) -> 809 | BY20: =+IFERROR(VLOOKUP($BY$18,Sheet1!AT7:AW7,3,0),0) -> 0 | BZ20: =+IFERROR(VLOOKUP($BZ$18,Sheet1!AX7:BA7,3,0),0) -> 0 | CA20: 37 | CB20: =+IFERROR(VLOOKUP($CB$18,Sheet1!BF7:BI7,3,0),0) -> 0 | CC20: =+IFERROR(VLOOKUP($CC$18,Sheet1!BJ7:BM7,3,0),0) -> 0 | CD20: =+IFERROR(VLOOKUP($CD$18,Sheet1!BN7:BQ7,3,0),0) -> 0 | CE20: 40 | CF20: =+IFERROR(VLOOKUP($CF$18,Sheet1!BV7:BY7,3,0),0) -> 0 | CG20: =Sheet1!E7 -> STEEL | CH20: =Sheet1!CY7 -> SP0400112 | CI20: =Sheet1!CZ7 -> CORRUGATED DISPATCH STEEL DRUM 2000 X 1000 X 1000 MM | CJ20: 500 | CK20: =16500/0.5 -> 33000 | CL20: =SUMPRODUCT($N$19:$CF$19,N20:CF20)+CK20 -> 876997 | CM20: =Sheet1!CB7 -> 0 | CN20: =CL20*CM20 -> 0 | CO20: 0.35 | CP20: =CL20*CO20 -> 306948.95 | CQ20: 0 | CR20: =CL20*CQ20 -> 0 | CS20: =CL20+CN20+CP20+CR20 -> 1183945.9 | CT20: 0.02 | CU20: =CS20*CT20 -> 23678.919 | CV20: 0 | CW20: =CS20*CV20 -> 0 | CX20: =Sheet1!CM7 -> 0 | CY20: =CX20*CS20 -> 0
A21: =Sheet1!A3 -> ENQ-18775-25-26 | B21: 46023 | C21: =Sheet1!C3 -> FA1300004 | D21: =Sheet1!D3 -> 3 CORE X 300 SQ. MM. AL/ARM - STRIP (XLPE) - 11 KV | E21: =CS21+CU21+CW21+CY21 -> 1958018.3 | F21: =ROUNDUP(M31,0) -> 54000 | G21: =E21+F21 -> 2012018.3 | H21: =Sheet1!CR3 -> 0.18 | I21: =G21*H21 -> 362163.29 | J21: =G21+I21 -> 2374181.6 | K21: =Sheet1!CU3 -> 270 | L21: =Sheet1!CV3 -> KMS | M21: =J21*K21 -> 6.4102902e+08 | N21: =+IFERROR(VLOOKUP($N$18,Sheet1!J3:L3,3,0),0) -> 2430 | O21: =+IFERROR(VLOOKUP($O$18,Sheet1!J3:L3,3,0),0) -> 0 | P21: =+IFERROR(VLOOKUP($P$18,Sheet1!J3:M3,3,0),0) -> 0 | Q21: =+IFERROR(VLOOKUP($Q$18,Sheet1!J3:M3,3,0),0) -> 0 | R21: =+IFERROR(VLOOKUP($R$18,Sheet1!J3:M3,3,0),0) -> 0 | S21: =+IFERROR(VLOOKUP($S$18,Sheet1!J3:M3,3,0),0) -> 0 | T21: =+IFERROR(VLOOKUP($T$18,Sheet1!J3:M3,3,0),0) -> 0 | U21: =+IFERROR(VLOOKUP($U$18,Sheet1!J3:M3,3,0),0) -> 0 | V21: =+IFERROR(VLOOKUP($V$18,Sheet1!N3:Q3,3,0),0) -> 0 | W21: =+IFERROR(VLOOKUP($W$18,Sheet1!N3:Q3,3,0),0) -> 0 | X21: =+IFERROR(VLOOKUP($X$18,Sheet1!F3:I3,3,0),0) -> 0 | Y21: =+IFERROR(VLOOKUP($Y$18,Sheet1!F3:I3,3,0),0) -> 0 | Z21: =+IFERROR(VLOOKUP($Z$18,Sheet1!F3:I3,3,0),0) -> 0 | AA21: 123 | AB21: =+IFERROR(VLOOKUP($AB$18,Sheet1!F3:I3,3,0),0) -> 0 | AC21: =+IFERROR(VLOOKUP($AC$18,Sheet1!F3:I3,3,0),0) -> 0 | AD21: =+IFERROR(VLOOKUP($AD$18,Sheet1!F3:I3,3,0),0) -> 0 | AE21: =+IFERROR(VLOOKUP($AE$18,Sheet1!F3:I3,3,0),0) -> 0 | AG21: 337 | AH21: =+IFERROR(VLOOKUP($AH$18,Sheet1!V3:Y3,3,0),0) -> 802 | AI21: =+IFERROR(VLOOKUP($AI$18,Sheet1!V3:Y3,3,0),0) -> 0 | AJ21: =+IFERROR(VLOOKUP($AJ$18,Sheet1!V3:Y3,3,0),0) -> 0 | AK21: =+IFERROR(VLOOKUP($AK$18,Sheet1!V3:Y3,3,0),0) -> 0 | AL21: =+IFERROR(VLOOKUP($AL$18,Sheet1!V3:Y3,3,0),0) -> 0 | AM21: =+IFERROR(VLOOKUP($AM$18,Sheet1!V3:Y3,3,0),0) -> 0 | AN21: =+IFERROR(VLOOKUP($AN$18,Sheet1!V3:Y3,3,0),0) -> 0 | AO21: =+IFERROR(VLOOKUP($AO$18,Sheet1!V3:Y3,3,0),0) -> 0 | AP21: =+IFERROR(VLOOKUP($AP$18,Sheet1!V3:Y3,3,0),0) -> 0 | AQ21: 46 | AR21: =+IFERROR(VLOOKUP($AR$18,Sheet1!AD3:AG3,3,0),0) -> 0 | AS21: =+IFERROR(VLOOKUP($AS$18,Sheet1!AD3:AG3,3,0),0) -> 0 | AT21: =+IFERROR(VLOOKUP($AT$18,Sheet1!AD3:AG3,3,0),0) -> 0 | AU21: =+IFERROR(VLOOKUP($AU$18,Sheet1!AD3:AG3,3,0),0) -> 0 | AV21: =+IFERROR(VLOOKUP($AV$18,Sheet1!AD3:AG3,3,0),0) -> 0 | AW21: =+IFERROR(VLOOKUP($AW$18,Sheet1!AD3:AG3,3,0),0) -> 0 | AX21: 291 | AY21: =+IFERROR(VLOOKUP($AY$18,Sheet1!AD3:AG3,3,0),0) -> 0 | AZ21: =+IFERROR(VLOOKUP($AZ$18,Sheet1!AD3:AG3,3,0),0) -> 0 | BA21: =+IFERROR(VLOOKUP($BA$18,Sheet1!AH3:AK3,3,0),0) -> 0 | BB21: =+IFERROR(VLOOKUP($BB$18,Sheet1!AH3:AK3,3,0),0) -> 0 | BC21: =+IFERROR(VLOOKUP($BC$18,Sheet1!AH3:AK3,3,0),0) -> 0 | BD21: =+IFERROR(VLOOKUP($BD$18,Sheet1!AH3:AK3,3,0),0) -> 0 | BE21: =+IFERROR(VLOOKUP($BE$18,Sheet1!AH3:AK3,3,0),0) -> 0 | BF21: =+IFERROR(VLOOKUP($BF$18,Sheet1!AH3:AK3,3,0),0) -> 0 | BG21: 1215 | BH21: =+IFERROR(VLOOKUP($BH$18,Sheet1!AH3:AK3,3,0),0) -> 0 | BI21: =+IFERROR(VLOOKUP($BI$18,Sheet1!AH3:AK3,3,0),0) -> 0 | BJ21: =+IFERROR(VLOOKUP($BJ$18,Sheet1!AH3:AK3,3,0),0) -> 0 | BK21: =+IFERROR(VLOOKUP($BK$18,Sheet1!AH3:AK3,3,0),0) -> 0 | BL21: =+IFERROR(VLOOKUP($BL$18,Sheet1!AL3:AO3,3,0),0) -> 0 | BM21: =+IFERROR(VLOOKUP($BM$18,Sheet1!AL3:AO3,3,0),0) -> 0 | BN21: =+IFERROR(VLOOKUP($BN$18,Sheet1!AL3:AO3,3,0),0) -> 0 | BO21: 1045 | BP21: =+IFERROR(VLOOKUP($BP$18,Sheet1!AL3:AO3,3,0),0) -> 0 | BQ21: =+IFERROR(VLOOKUP($BQ$18,Sheet1!AL3:AO3,3,0),0) -> 0 | BR21: =+IFERROR(VLOOKUP($BR$18,Sheet1!AL3:AO3,3,0),0) -> 0 | BS21: =+IFERROR(VLOOKUP($BS$18,Sheet1!AL3:AO3,3,0),0) -> 0 | BU21: =+IFERROR(VLOOKUP($BU$18,Sheet1!AL3:AO3,3,0),0) -> 0 | BV21: =+IFERROR(VLOOKUP($BV$18,Sheet1!AL3:AO3,3,0),0) -> 0 | BW21: =+IFERROR(VLOOKUP($BW$18,Sheet1!AL3:AO3,3,0),0) -> 0 | BX21: =+IFERROR(VLOOKUP($BX$18,Sheet1!AP3:AS3,3,0),0) -> 1258 | BY21: =+IFERROR(VLOOKUP($BY$18,Sheet1!AT3:AW3,3,0),0) -> 0 | BZ21: =+IFERROR(VLOOKUP($BZ$18,Sheet1!AX3:BA3,3,0),0) -> 0 | CA21: 46 | CB21: =+IFERROR(VLOOKUP($CB$18,Sheet1!BF3:BI3,3,0),0) -> 0 | CC21: =+IFERROR(VLOOKUP($CC$18,Sheet1!BJ3:BM3,3,0),0) -> 0 | CD21: =+IFERROR(VLOOKUP($CD$18,Sheet1!BN3:BQ3,3,0),0) -> 0 | CE21: 44 | CF21: =+IFERROR(VLOOKUP($CF$18,Sheet1!BV3:BY3,3,0),0) -> 0 | CG21: =Sheet1!E3 -> STEEL | CH21: =Sheet1!CY3 -> SP0400141 | CI21: =Sheet1!CZ3 -> CORRUGATED DISPATCH STEEL DRUM 2080 X 1000 X 1400 MM | CJ21: 500 | CK21: =19250/0.5 -> 38500 | CL21: =SUMPRODUCT($N$19:$CF$19,N21:CF21)+CK21 -> 1421945 | CM21: =Sheet1!CB3 -> 0 | CN21: =CL21*CM21 -> 0 | CO21: 0.35 | CP21: =CL21*CO21 -> 497680.75 | CQ21: 0 | CR21: =CL21*CQ21 -> 0 | CS21: =CL21+CN21+CP21+CR21 -> 1919625.8 | CT21: 0.02 | CU21: =CS21*CT21 -> 38392.515 | CV21: 0 | CW21: =CS21*CV21 -> 0 | CX21: =Sheet1!CM3 -> 0 | CY21: =CX21*CS21 -> 0
A22: =Sheet1!A4 -> ENQ-18775-25-26 | B22: 46023 | C22: =Sheet1!C4 -> FA1300006 | D22: =Sheet1!D4 -> 3 CORE X 70 SQ. MM. AL/ARM - STRIP (XLPE) - 11 KV | E22: =CS22+CU22+CW22+CY22 -> 785528.93 | F22: =ROUNDUP(M32,0) -> 27000 | G22: =E22+F22 -> 812528.93 | H22: =Sheet1!CR4 -> 0.18 | I22: =G22*H22 -> 146255.21 | J22: =G22+I22 -> 958784.14 | K22: =Sheet1!CU4 -> 15 | L22: =Sheet1!CV4 -> KMS | M22: =J22*K22 -> 14381762 | N22: =+IFERROR(VLOOKUP($N$18,Sheet1!J4:L4,3,0),0) -> 567 | O22: =+IFERROR(VLOOKUP($O$18,Sheet1!J4:L4,3,0),0) -> 0 | P22: =+IFERROR(VLOOKUP($P$18,Sheet1!J4:M4,3,0),0) -> 0 | Q22: =+IFERROR(VLOOKUP($Q$18,Sheet1!J4:M4,3,0),0) -> 0 | R22: =+IFERROR(VLOOKUP($R$18,Sheet1!J4:M4,3,0),0) -> 0 | S22: =+IFERROR(VLOOKUP($S$18,Sheet1!J4:M4,3,0),0) -> 0 | T22: =+IFERROR(VLOOKUP($T$18,Sheet1!J4:M4,3,0),0) -> 0 | U22: =+IFERROR(VLOOKUP($U$18,Sheet1!J4:M4,3,0),0) -> 0 | V22: =+IFERROR(VLOOKUP($V$18,Sheet1!N4:Q4,3,0),0) -> 0 | W22: =+IFERROR(VLOOKUP($W$18,Sheet1!N4:Q4,3,0),0) -> 0 | X22: =+IFERROR(VLOOKUP($X$18,Sheet1!F4:I4,3,0),0) -> 0 | Y22: =+IFERROR(VLOOKUP($Y$18,Sheet1!F4:I4,3,0),0) -> 0 | Z22: =+IFERROR(VLOOKUP($Z$18,Sheet1!F4:I4,3,0),0) -> 0 | AA22: 81 | AB22: =+IFERROR(VLOOKUP($AB$18,Sheet1!F4:I4,3,0),0) -> 0 | AC22: =+IFERROR(VLOOKUP($AC$18,Sheet1!F4:I4,3,0),0) -> 0 | AD22: =+IFERROR(VLOOKUP($AD$18,Sheet1!F4:I4,3,0),0) -> 0 | AE22: =+IFERROR(VLOOKUP($AE$18,Sheet1!F4:I4,3,0),0) -> 0 | AG22: 188 | AH22: =+IFERROR(VLOOKUP($AH$18,Sheet1!V4:Y4,3,0),0) -> 474 | AI22: =+IFERROR(VLOOKUP($AI$18,Sheet1!V4:Y4,3,0),0) -> 0 | AJ22: =+IFERROR(VLOOKUP($AJ$18,Sheet1!V4:Y4,3,0),0) -> 0 | AK22: =+IFERROR(VLOOKUP($AK$18,Sheet1!V4:Y4,3,0),0) -> 0 | AL22: =+IFERROR(VLOOKUP($AL$18,Sheet1!V4:Y4,3,0),0) -> 0 | AM22: =+IFERROR(VLOOKUP($AM$18,Sheet1!V4:Y4,3,0),0) -> 0 | AN22: =+IFERROR(VLOOKUP($AN$18,Sheet1!V4:Y4,3,0),0) -> 0 | AO22: =+IFERROR(VLOOKUP($AO$18,Sheet1!V4:Y4,3,0),0) -> 0 | AP22: =+IFERROR(VLOOKUP($AP$18,Sheet1!V4:Y4,3,0),0) -> 0 | AQ22: 30 | AR22: =+IFERROR(VLOOKUP($AR$18,Sheet1!AD4:AG4,3,0),0) -> 0 | AS22: =+IFERROR(VLOOKUP($AS$18,Sheet1!AD4:AG4,3,0),0) -> 0 | AT22: =+IFERROR(VLOOKUP($AT$18,Sheet1!AD4:AG4,3,0),0) -> 0 | AU22: =+IFERROR(VLOOKUP($AU$18,Sheet1!AD4:AG4,3,0),0) -> 0 | AV22: =+IFERROR(VLOOKUP($AV$18,Sheet1!AD4:AG4,3,0),0) -> 0 | AW22: =+IFERROR(VLOOKUP($AW$18,Sheet1!AD4:AG4,3,0),0) -> 0 | AX22: 167 | AY22: =+IFERROR(VLOOKUP($AY$18,Sheet1!AD4:AG4,3,0),0) -> 0 | AZ22: =+IFERROR(VLOOKUP($AZ$18,Sheet1!AD4:AG4,3,0),0) -> 0 | BA22: =+IFERROR(VLOOKUP($BA$18,Sheet1!AH4:AK4,3,0),0) -> 0 | BB22: =+IFERROR(VLOOKUP($BB$18,Sheet1!AH4:AK4,3,0),0) -> 0 | BC22: =+IFERROR(VLOOKUP($BC$18,Sheet1!AH4:AK4,3,0),0) -> 0 | BD22: =+IFERROR(VLOOKUP($BD$18,Sheet1!AH4:AK4,3,0),0) -> 0 | BE22: =+IFERROR(VLOOKUP($BE$18,Sheet1!AH4:AK4,3,0),0) -> 0 | BF22: =+IFERROR(VLOOKUP($BF$18,Sheet1!AH4:AK4,3,0),0) -> 0 | BG22: 858 | BH22: =+IFERROR(VLOOKUP($BH$18,Sheet1!AH4:AK4,3,0),0) -> 0 | BI22: =+IFERROR(VLOOKUP($BI$18,Sheet1!AH4:AK4,3,0),0) -> 0 | BJ22: =+IFERROR(VLOOKUP($BJ$18,Sheet1!AH4:AK4,3,0),0) -> 0 | BK22: =+IFERROR(VLOOKUP($BK$18,Sheet1!AH4:AK4,3,0),0) -> 0 | BL22: =+IFERROR(VLOOKUP($BL$18,Sheet1!AL4:AO4,3,0),0) -> 0 | BM22: =+IFERROR(VLOOKUP($BM$18,Sheet1!AL4:AO4,3,0),0) -> 0 | BN22: =+IFERROR(VLOOKUP($BN$18,Sheet1!AL4:AO4,3,0),0) -> 0 | BO22: 708 | BP22: =+IFERROR(VLOOKUP($BP$18,Sheet1!AL4:AO4,3,0),0) -> 0 | BQ22: =+IFERROR(VLOOKUP($BQ$18,Sheet1!AL4:AO4,3,0),0) -> 0 | BR22: =+IFERROR(VLOOKUP($BR$18,Sheet1!AL4:AO4,3,0),0) -> 0 | BS22: =+IFERROR(VLOOKUP($BS$18,Sheet1!AL4:AO4,3,0),0) -> 0 | BU22: =+IFERROR(VLOOKUP($BU$18,Sheet1!AL4:AO4,3,0),0) -> 0 | BV22: =+IFERROR(VLOOKUP($BV$18,Sheet1!AL4:AO4,3,0),0) -> 0 | BW22: =+IFERROR(VLOOKUP($BW$18,Sheet1!AL4:AO4,3,0),0) -> 0 | BX22: =+IFERROR(VLOOKUP($BX$18,Sheet1!AP4:AS4,3,0),0) -> 533 | BY22: =+IFERROR(VLOOKUP($BY$18,Sheet1!AT4:AW4,3,0),0) -> 0 | BZ22: =+IFERROR(VLOOKUP($BZ$18,Sheet1!AX4:BA4,3,0),0) -> 0 | CA22: 31 | CB22: =+IFERROR(VLOOKUP($CB$18,Sheet1!BF4:BI4,3,0),0) -> 0 | CC22: =+IFERROR(VLOOKUP($CC$18,Sheet1!BJ4:BM4,3,0),0) -> 0 | CD22: =+IFERROR(VLOOKUP($CD$18,Sheet1!BN4:BQ4,3,0),0) -> 0 | CE22: 35 | CF22: =+IFERROR(VLOOKUP($CF$18,Sheet1!BV4:BY4,3,0),0) -> 0 | CG22: =Sheet1!E4 -> STEEL | CH22: =Sheet1!CY4 -> SP0400118 | CI22: =Sheet1!CZ4 -> CORRUGATED DISPATCH STEEL DRUM 1700 X 1000 X 1200 | CJ22: 500 | CK22: =9900/0.5 -> 19800 | CL22: =SUMPRODUCT($N$19:$CF$19,N22:CF22)+CK22 -> 570464 | CM22: =Sheet1!CB4 -> 0 | CN22: =CL22*CM22 -> 0 | CO22: 0.35 | CP22: =CL22*CO22 -> 199662.4 | CQ22: 0 | CR22: =CL22*CQ22 -> 0 | CS22: =CL22+CN22+CP22+CR22 -> 770126.4 | CT22: 0.02 | CU22: =CS22*CT22 -> 15402.528 | CV22: 0 | CW22: =CS22*CV22 -> 0 | CX22: =Sheet1!CM4 -> 0 | CY22: =CX22*CS22 -> 0
A23: =Sheet1!A5 -> ENQ-18775-25-26 | B23: 46023 | C23: =Sheet1!C5 -> FA1300010 | D23: =Sheet1!D5 -> 3 CORE X 400 SQ. MM. AL/ARM - STRIP (XLPE) - 33 KV | E23: =CS23+CU23+CW23+CY23 -> 3371284.3 | F23: =ROUNDUP(M33,0) -> 90000 | G23: =E23+F23 -> 3461284.3 | H23: =Sheet1!CR5 -> 0.18 | I23: =G23*H23 -> 623031.18 | J23: =G23+I23 -> 4084315.5 | K23: =Sheet1!CU5 -> 195 | L23: =Sheet1!CV5 -> KMS | M23: =J23*K23 -> 7.9644152e+08 | N23: =+IFERROR(VLOOKUP($N$18,Sheet1!J5:L5,3,0),0) -> 3240 | O23: =+IFERROR(VLOOKUP($O$18,Sheet1!J5:L5,3,0),0) -> 0 | P23: =+IFERROR(VLOOKUP($P$18,Sheet1!J5:M5,3,0),0) -> 0 | Q23: =+IFERROR(VLOOKUP($Q$18,Sheet1!J5:M5,3,0),0) -> 0 | R23: =+IFERROR(VLOOKUP($R$18,Sheet1!J5:M5,3,0),0) -> 0 | S23: =+IFERROR(VLOOKUP($S$18,Sheet1!J5:M5,3,0),0) -> 0 | T23: =+IFERROR(VLOOKUP($T$18,Sheet1!J5:M5,3,0),0) -> 0 | U23: =+IFERROR(VLOOKUP($U$18,Sheet1!J5:M5,3,0),0) -> 0 | V23: =+IFERROR(VLOOKUP($V$18,Sheet1!N5:Q5,3,0),0) -> 0 | W23: =+IFERROR(VLOOKUP($W$18,Sheet1!N5:Q5,3,0),0) -> 0 | X23: =+IFERROR(VLOOKUP($X$18,Sheet1!F5:I5,3,0),0) -> 0 | Y23: =+IFERROR(VLOOKUP($Y$18,Sheet1!F5:I5,3,0),0) -> 0 | Z23: =+IFERROR(VLOOKUP($Z$18,Sheet1!F5:I5,3,0),0) -> 0 | AA23: 181 | AB23: =+IFERROR(VLOOKUP($AB$18,Sheet1!F5:I5,3,0),0) -> 0 | AC23: =+IFERROR(VLOOKUP($AC$18,Sheet1!F5:I5,3,0),0) -> 0 | AD23: =+IFERROR(VLOOKUP($AD$18,Sheet1!F5:I5,3,0),0) -> 0 | AE23: =+IFERROR(VLOOKUP($AE$18,Sheet1!F5:I5,3,0),0) -> 0 | AG23: 427 | AI23: =+IFERROR(VLOOKUP($AI$18,Sheet1!V5:Y5,3,0),0) -> 0 | AJ23: 2621 | AK23: =+IFERROR(VLOOKUP($AK$18,Sheet1!V5:Y5,3,0),0) -> 0 | AL23: =+IFERROR(VLOOKUP($AL$18,Sheet1!V5:Y5,3,0),0) -> 0 | AM23: =+IFERROR(VLOOKUP($AM$18,Sheet1!V5:Y5,3,0),0) -> 0 | AN23: =+IFERROR(VLOOKUP($AN$18,Sheet1!V5:Y5,3,0),0) -> 0 | AO23: =+IFERROR(VLOOKUP($AO$18,Sheet1!V5:Y5,3,0),0) -> 0 | AP23: =+IFERROR(VLOOKUP($AP$18,Sheet1!V5:Y5,3,0),0) -> 0 | AQ23: 66 | AR23: =+IFERROR(VLOOKUP($AR$18,Sheet1!AD5:AG5,3,0),0) -> 0 | AS23: =+IFERROR(VLOOKUP($AS$18,Sheet1!AD5:AG5,3,0),0) -> 0 | AT23: =+IFERROR(VLOOKUP($AT$18,Sheet1!AD5:AG5,3,0),0) -> 0 | AU23: =+IFERROR(VLOOKUP($AU$18,Sheet1!AD5:AG5,3,0),0) -> 0 | AV23: =+IFERROR(VLOOKUP($AV$18,Sheet1!AD5:AG5,3,0),0) -> 0 | AW23: =+IFERROR(VLOOKUP($AW$18,Sheet1!AD5:AG5,3,0),0) -> 0 | AX23: 426 | AY23: =+IFERROR(VLOOKUP($AY$18,Sheet1!AD5:AG5,3,0),0) -> 0 | AZ23: =+IFERROR(VLOOKUP($AZ$18,Sheet1!AD5:AG5,3,0),0) -> 0 | BA23: =+IFERROR(VLOOKUP($BA$18,Sheet1!AH5:AK5,3,0),0) -> 0 | BB23: =+IFERROR(VLOOKUP($BB$18,Sheet1!AH5:AK5,3,0),0) -> 0 | BC23: =+IFERROR(VLOOKUP($BC$18,Sheet1!AH5:AK5,3,0),0) -> 0 | BD23: =+IFERROR(VLOOKUP($BD$18,Sheet1!AH5:AK5,3,0),0) -> 0 | BE23: =+IFERROR(VLOOKUP($BE$18,Sheet1!AH5:AK5,3,0),0) -> 0 | BF23: =+IFERROR(VLOOKUP($BF$18,Sheet1!AH5:AK5,3,0),0) -> 0 | BG23: 1728 | BH23: =+IFERROR(VLOOKUP($BH$18,Sheet1!AH5:AK5,3,0),0) -> 0 | BI23: =+IFERROR(VLOOKUP($BI$18,Sheet1!AH5:AK5,3,0),0) -> 0 | BJ23: =+IFERROR(VLOOKUP($BJ$18,Sheet1!AH5:AK5,3,0),0) -> 0 | BK23: =+IFERROR(VLOOKUP($BK$18,Sheet1!AH5:AK5,3,0),0) -> 0 | BL23: =+IFERROR(VLOOKUP($BL$18,Sheet1!AL5:AO5,3,0),0) -> 0 | BM23: =+IFERROR(VLOOKUP($BM$18,Sheet1!AL5:AO5,3,0),0) -> 0 | BN23: =+IFERROR(VLOOKUP($BN$18,Sheet1!AL5:AO5,3,0),0) -> 0 | BO23: 1638 | BP23: =+IFERROR(VLOOKUP($BP$18,Sheet1!AL5:AO5,3,0),0) -> 0 | BQ23: =+IFERROR(VLOOKUP($BQ$18,Sheet1!AL5:AO5,3,0),0) -> 0 | BR23: =+IFERROR(VLOOKUP($BR$18,Sheet1!AL5:AO5,3,0),0) -> 0 | BS23: =+IFERROR(VLOOKUP($BS$18,Sheet1!AL5:AO5,3,0),0) -> 0 | BU23: =+IFERROR(VLOOKUP($BU$18,Sheet1!AL5:AO5,3,0),0) -> 0 | BV23: =+IFERROR(VLOOKUP($BV$18,Sheet1!AL5:AO5,3,0),0) -> 0 | BW23: =+IFERROR(VLOOKUP($BW$18,Sheet1!AL5:AO5,3,0),0) -> 0 | BY23: 1718 | BZ23: =+IFERROR(VLOOKUP($BZ$18,Sheet1!AX5:BA5,3,0),0) -> 0 | CA23: 104 | CB23: 58 | CC23: =+IFERROR(VLOOKUP($CC$18,Sheet1!BJ5:BM5,3,0),0) -> 0 | CD23: =+IFERROR(VLOOKUP($CD$18,Sheet1!BN5:BQ5,3,0),0) -> 0 | CE23: 69 | CF23: =+IFERROR(VLOOKUP($CF$18,Sheet1!BV5:BY5,3,0),0) -> 0 | CG23: =Sheet1!E5 -> STEEL | CH23: =Sheet1!CY5 -> SP0400105 | CI23: =Sheet1!CZ5 -> CORRUGATED DISPATCH STEEL DRUM 2500 X 1500 X 1400 | CJ23: 500 | CK23: =22000/0.5 -> 44000 | CL23: =SUMPRODUCT($N$19:$CF$19,N23:CF23)+CK23 -> 2448282 | CM23: =Sheet1!CB5 -> 0 | CN23: =CL23*CM23 -> 0 | CO23: 0.35 | CP23: =CL23*CO23 -> 856898.7 | CQ23: 0 | CR23: =CL23*CQ23 -> 0 | CS23: =CL23+CN23+CP23+CR23 -> 3305180.7 | CT23: 0.02 | CU23: =CS23*CT23 -> 66103.614 | CV23: 0 | CW23: =CS23*CV23 -> 0 | CX23: =Sheet1!CM5 -> 0 | CY23: =CX23*CS23 -> 0
A24: =Sheet1!A6 -> ENQ-18775-25-26 | B24: 46023 | C24: =Sheet1!C6 -> FA1300015 | D24: =Sheet1!D6 -> 3 CORE X 300 SQ. MM. AL/ARM - STRIP (XLPE) - 33 KV | E24: =CS24+CU24+CW24+CY24 -> 2833568.6 | F24: =ROUNDUP(M34,0) -> 90000 | G24: =E24+F24 -> 2923568.6 | H24: =Sheet1!CR6 -> 0.18 | I24: =G24*H24 -> 526242.34 | J24: =G24+I24 -> 3449810.9 | K24: =Sheet1!CU6 -> 3 | L24: =Sheet1!CV6 -> KMS | M24: =J24*K24 -> 10349433 | N24: =+IFERROR(VLOOKUP($N$18,Sheet1!J6:L6,3,0),0) -> 2430 | O24: =+IFERROR(VLOOKUP($O$18,Sheet1!J6:L6,3,0),0) -> 0 | P24: =+IFERROR(VLOOKUP($P$18,Sheet1!J6:M6,3,0),0) -> 0 | Q24: =+IFERROR(VLOOKUP($Q$18,Sheet1!J6:M6,3,0),0) -> 0 | R24: =+IFERROR(VLOOKUP($R$18,Sheet1!J6:M6,3,0),0) -> 0 | S24: =+IFERROR(VLOOKUP($S$18,Sheet1!J6:M6,3,0),0) -> 0 | T24: =+IFERROR(VLOOKUP($T$18,Sheet1!J6:M6,3,0),0) -> 0 | U24: =+IFERROR(VLOOKUP($U$18,Sheet1!J6:M6,3,0),0) -> 0 | V24: =+IFERROR(VLOOKUP($V$18,Sheet1!N6:Q6,3,0),0) -> 0 | W24: =+IFERROR(VLOOKUP($W$18,Sheet1!N6:Q6,3,0),0) -> 0 | X24: =+IFERROR(VLOOKUP($X$18,Sheet1!F6:I6,3,0),0) -> 0 | Y24: =+IFERROR(VLOOKUP($Y$18,Sheet1!F6:I6,3,0),0) -> 0 | Z24: =+IFERROR(VLOOKUP($Z$18,Sheet1!F6:I6,3,0),0) -> 0 | AA24: 168 | AB24: =+IFERROR(VLOOKUP($AB$18,Sheet1!F6:I6,3,0),0) -> 0 | AC24: =+IFERROR(VLOOKUP($AC$18,Sheet1!F6:I6,3,0),0) -> 0 | AD24: =+IFERROR(VLOOKUP($AD$18,Sheet1!F6:I6,3,0),0) -> 0 | AE24: =+IFERROR(VLOOKUP($AE$18,Sheet1!F6:I6,3,0),0) -> 0 | AF24: =+IFERROR(VLOOKUP($AF$18,Sheet1!R6:U6,3,0),0) -> 0 | AG24: =+IFERROR(VLOOKUP($AG$18,Sheet1!R6:U6,3,0),0) -> 386 | AH24: =+IFERROR(VLOOKUP($AH$18,Sheet1!V6:Y6,3,0),0) -> 0 | AI24: =+IFERROR(VLOOKUP($AI$18,Sheet1!V6:Y6,3,0),0) -> 0 | AJ24: =+IFERROR(VLOOKUP($AJ$18,Sheet1!V6:Y6,3,0),0) -> 2385 | AK24: =+IFERROR(VLOOKUP($AK$18,Sheet1!V6:Y6,3,0),0) -> 0 | AL24: =+IFERROR(VLOOKUP($AL$18,Sheet1!V6:Y6,3,0),0) -> 0 | AM24: =+IFERROR(VLOOKUP($AM$18,Sheet1!V6:Y6,3,0),0) -> 0 | AN24: =+IFERROR(VLOOKUP($AN$18,Sheet1!V6:Y6,3,0),0) -> 0 | AO24: =+IFERROR(VLOOKUP($AO$18,Sheet1!V6:Y6,3,0),0) -> 0 | AP24: =+IFERROR(VLOOKUP($AP$18,Sheet1!V6:Y6,3,0),0) -> 0 | AQ24: 61 | AR24: =+IFERROR(VLOOKUP($AR$18,Sheet1!AD6:AG6,3,0),0) -> 0 | AS24: =+IFERROR(VLOOKUP($AS$18,Sheet1!AD6:AG6,3,0),0) -> 0 | AT24: =+IFERROR(VLOOKUP($AT$18,Sheet1!AD6:AG6,3,0),0) -> 0 | AU24: =+IFERROR(VLOOKUP($AU$18,Sheet1!AD6:AG6,3,0),0) -> 0 | AV24: =+IFERROR(VLOOKUP($AV$18,Sheet1!AD6:AG6,3,0),0) -> 0 | AW24: =+IFERROR(VLOOKUP($AW$18,Sheet1!AD6:AG6,3,0),0) -> 0 | AX24: 397 | AY24: =+IFERROR(VLOOKUP($AY$18,Sheet1!AD6:AG6,3,0),0) -> 0 | AZ24: =+IFERROR(VLOOKUP($AZ$18,Sheet1!AD6:AG6,3,0),0) -> 0 | BA24: =+IFERROR(VLOOKUP($BA$18,Sheet1!AH6:AK6,3,0),0) -> 0 | BB24: =+IFERROR(VLOOKUP($BB$18,Sheet1!AH6:AK6,3,0),0) -> 0 | BC24: =+IFERROR(VLOOKUP($BC$18,Sheet1!AH6:AK6,3,0),0) -> 0 | BD24: =+IFERROR(VLOOKUP($BD$18,Sheet1!AH6:AK6,3,0),0) -> 0 | BE24: =+IFERROR(VLOOKUP($BE$18,Sheet1!AH6:AK6,3,0),0) -> 0 | BF24: =+IFERROR(VLOOKUP($BF$18,Sheet1!AH6:AK6,3,0),0) -> 0 | BG24: 1620 | BH24: =+IFERROR(VLOOKUP($BH$18,Sheet1!AH6:AK6,3,0),0) -> 0 | BI24: =+IFERROR(VLOOKUP($BI$18,Sheet1!AH6:AK6,3,0),0) -> 0 | BJ24: =+IFERROR(VLOOKUP($BJ$18,Sheet1!AH6:AK6,3,0),0) -> 0 | BK24: =+IFERROR(VLOOKUP($BK$18,Sheet1!AH6:AK6,3,0),0) -> 0 | BL24: =+IFERROR(VLOOKUP($BL$18,Sheet1!AL6:AO6,3,0),0) -> 0 | BM24: =+IFERROR(VLOOKUP($BM$18,Sheet1!AL6:AO6,3,0),0) -> 0 | BN24: =+IFERROR(VLOOKUP($BN$18,Sheet1!AL6:AO6,3,0),0) -> 0 | BO24: 1533 | BP24: =+IFERROR(VLOOKUP($BP$18,Sheet1!AL6:AO6,3,0),0) -> 0 | BQ24: =+IFERROR(VLOOKUP($BQ$18,Sheet1!AL6:AO6,3,0),0) -> 0 | BR24: =+IFERROR(VLOOKUP($BR$18,Sheet1!AL6:AO6,3,0),0) -> 0 | BS24: =+IFERROR(VLOOKUP($BS$18,Sheet1!AL6:AO6,3,0),0) -> 0 | BT24: =+IFERROR(VLOOKUP($BT$18,Sheet1!AL6:AO6,3,0),0) -> 0 | BU24: =+IFERROR(VLOOKUP($BU$18,Sheet1!AL6:AO6,3,0),0) -> 0 | BV24: =+IFERROR(VLOOKUP($BV$18,Sheet1!AL6:AO6,3,0),0) -> 0 | BW24: =+IFERROR(VLOOKUP($BW$18,Sheet1!AL6:AO6,3,0),0) -> 0 | BX24: =+IFERROR(VLOOKUP($BX$18,Sheet1!AP6:AS6,3,0),0) -> 0 | BY24: 1497 | BZ24: =+IFERROR(VLOOKUP($BZ$18,Sheet1!AX6:BA6,3,0),0) -> 0 | CA24: 93 | CB24: 38 | CC24: =+IFERROR(VLOOKUP($CC$18,Sheet1!BJ6:BM6,3,0),0) -> 0 | CD24: =+IFERROR(VLOOKUP($CD$18,Sheet1!BN6:BQ6,3,0),0) -> 0 | CE24: 58 | CF24: =+IFERROR(VLOOKUP($CF$18,Sheet1!BV6:BY6,3,0),0) -> 0 | CG24: =Sheet1!E6 -> STEEL | CH24: =Sheet1!CY6 -> SP0400105 | CI24: =Sheet1!CZ6 -> CORRUGATED DISPATCH STEEL DRUM 2500 X 1500 X 1400 | CJ24: 500 | CK24: =22000/0.5 -> 44000 | CL24: =SUMPRODUCT($N$19:$CF$19,N24:CF24)+CK24 -> 2057784 | CM24: =Sheet1!CB6 -> 0 | CN24: =CL24*CM24 -> 0 | CO24: 0.35 | CP24: =CL24*CO24 -> 720224.4 | CQ24: 0 | CR24: =CL24*CQ24 -> 0 | CS24: =CL24+CN24+CP24+CR24 -> 2778008.4 | CT24: 0.02 | CU24: =CS24*CT24 -> 55560.168 | CV24: 0 | CW24: =CS24*CV24 -> 0 | CX24: =Sheet1!CM6 -> 0 | CY24: =CX24*CS24 -> 0
A25: =Sheet1!A2 -> ENQ-18775-25-26 | B25: 46023 | C25: =Sheet1!C2 -> FA0400106 | D25: =Sheet1!D2 -> 3 CORE X 120 SQ MM + 1 CORE X 125 SQ MM (AB CABLES) (INSULATED) - 11 KV | E25: =CS25+CU25+CW25+CY25 -> 1439767.8 | F25: =ROUNDUP(M35,0) -> 36000 | G25: =E25+F25 -> 1475767.8 | H25: =Sheet1!CR2 -> 0.18 | I25: =G25*H25 -> 265638.2 | J25: =G25+I25 -> 1741406 | K25: =Sheet1!CU2 -> 45 | L25: =Sheet1!CV2 -> KMS | M25: =J25*K25 -> 78363270 | N25: 975 | O25: =+IFERROR(VLOOKUP($O$18,Sheet1!J2:L2,3,0),0) -> 0 | P25: =+IFERROR(VLOOKUP($P$18,Sheet1!J2:M2,3,0),0) -> 0 | Q25: =+IFERROR(VLOOKUP($Q$18,Sheet1!J2:M2,3,0),0) -> 0 | R25: =+IFERROR(VLOOKUP($R$18,Sheet1!J2:M2,3,0),0) -> 0 | S25: =+IFERROR(VLOOKUP($S$18,Sheet1!J2:M2,3,0),0) -> 0 | T25: =+IFERROR(VLOOKUP($T$18,Sheet1!J2:M2,3,0),0) -> 0 | U25: =+IFERROR(VLOOKUP($U$18,Sheet1!J2:M2,3,0),0) -> 0 | V25: =+IFERROR(VLOOKUP($V$18,Sheet1!N2:Q2,3,0),0) -> 0 | W25: 350 | X25: =+IFERROR(VLOOKUP($X$18,Sheet1!F2:I2,3,0),0) -> 0 | Y25: =+IFERROR(VLOOKUP($Y$18,Sheet1!F2:I2,3,0),0) -> 0 | Z25: =+IFERROR(VLOOKUP($Z$18,Sheet1!F2:I2,3,0),0) -> 0 | AA25: =+IFERROR(VLOOKUP($AA$18,Sheet1!F2:I2,3,0),0) -> 0 | AB25: =+IFERROR(VLOOKUP($AB$18,Sheet1!F2:I2,3,0),0) -> 0 | AC25: =+IFERROR(VLOOKUP($AC$18,Sheet1!F2:I2,3,0),0) -> 0 | AE25: =+IFERROR(VLOOKUP($AE$18,Sheet1!F2:I2,3,0),0) -> 0 | AG25: 276 | AH25: 584 | AI25: =+IFERROR(VLOOKUP($AI$18,Sheet1!V2:Y2,3,0),0) -> 0 | AJ25: =+IFERROR(VLOOKUP($AJ$18,Sheet1!V2:Y2,3,0),0) -> 0 | AK25: =+IFERROR(VLOOKUP($AK$18,Sheet1!V2:Y2,3,0),0) -> 0 | AL25: =+IFERROR(VLOOKUP($AL$18,Sheet1!V2:Y2,3,0),0) -> 0 | AM25: =+IFERROR(VLOOKUP($AM$18,Sheet1!V2:Y2,3,0),0) -> 0 | AN25: =+IFERROR(VLOOKUP($AN$18,Sheet1!V2:Y2,3,0),0) -> 0 | AO25: =+IFERROR(VLOOKUP($AO$18,Sheet1!V2:Y2,3,0),0) -> 0 | AP25: =+IFERROR(VLOOKUP($AP$18,Sheet1!V2:Y2,3,0),0) -> 0 | AQ25: =+IFERROR(VLOOKUP($AQ$18,Sheet1!Z2:AB2,3,0),0) -> 0 | AR25: =+IFERROR(VLOOKUP($AR$18,Sheet1!AD2:AG2,3,0),0) -> 0 | AS25: =+IFERROR(VLOOKUP($AS$18,Sheet1!AD2:AG2,3,0),0) -> 0 | AT25: =+IFERROR(VLOOKUP($AT$18,Sheet1!AD2:AG2,3,0),0) -> 0 | AU25: =+IFERROR(VLOOKUP($AU$18,Sheet1!AD2:AG2,3,0),0) -> 0 | AV25: =+IFERROR(VLOOKUP($AV$18,Sheet1!AD2:AG2,3,0),0) -> 0 | AW25: =+IFERROR(VLOOKUP($AW$18,Sheet1!AD2:AG2,3,0),0) -> 0 | AX25: 135 | AY25: =+IFERROR(VLOOKUP($AY$18,Sheet1!AD2:AG2,3,0),0) -> 0 | AZ25: =+IFERROR(VLOOKUP($AZ$18,Sheet1!AD2:AG2,3,0),0) -> 0 | BA25: =+IFERROR(VLOOKUP($BA$18,Sheet1!AH2:AK2,3,0),0) -> 0 | BB25: =+IFERROR(VLOOKUP($BB$18,Sheet1!AH2:AK2,3,0),0) -> 0 | BC25: =+IFERROR(VLOOKUP($BC$18,Sheet1!AH2:AK2,3,0),0) -> 0 | BD25: =+IFERROR(VLOOKUP($BD$18,Sheet1!AH2:AK2,3,0),0) -> 0 | BE25: =+IFERROR(VLOOKUP($BE$18,Sheet1!AH2:AK2,3,0),0) -> 0 | BF25: =+IFERROR(VLOOKUP($BF$18,Sheet1!AH2:AK2,3,0),0) -> 0 | BG25: =+IFERROR(VLOOKUP($BG$18,Sheet1!AH2:AK2,3,0),0) -> 0 | BH25: =+IFERROR(VLOOKUP($BH$18,Sheet1!AH2:AK2,3,0),0) -> 0 | BI25: =+IFERROR(VLOOKUP($BI$18,Sheet1!AH2:AK2,3,0),0) -> 0 | BJ25: =+IFERROR(VLOOKUP($BJ$18,Sheet1!AH2:AK2,3,0),0) -> 0 | BK25: =+IFERROR(VLOOKUP($BK$18,Sheet1!AH2:AK2,3,0),0) -> 0 | BL25: =+IFERROR(VLOOKUP($BL$18,Sheet1!AL2:AO2,3,0),0) -> 0 | BM25: =+IFERROR(VLOOKUP($BM$18,Sheet1!AL2:AO2,3,0),0) -> 0 | BN25: =+IFERROR(VLOOKUP($BN$18,Sheet1!AL2:AO2,3,0),0) -> 0 | BO25: =+IFERROR(VLOOKUP($BO$18,Sheet1!AL2:AO2,3,0),0) -> 0 | BP25: =+IFERROR(VLOOKUP($BP$18,Sheet1!AL2:AO2,3,0),0) -> 0 | BQ25: =+IFERROR(VLOOKUP($BQ$18,Sheet1!AL2:AO2,3,0),0) -> 0 | BR25: 680 | BS25: =+IFERROR(VLOOKUP($BS$18,Sheet1!AL2:AO2,3,0),0) -> 0 | BU25: =+IFERROR(VLOOKUP($BU$18,Sheet1!AL2:AO2,3,0),0) -> 0 | BV25: =+IFERROR(VLOOKUP($BV$18,Sheet1!AL2:AO2,3,0),0) -> 0 | BW25: =+IFERROR(VLOOKUP($BW$18,Sheet1!AL2:AO2,3,0),0) -> 0 | BX25: =+IFERROR(VLOOKUP($BX$18,Sheet1!AP2:AS2,3,0),0) -> 0 | BY25: =+IFERROR(VLOOKUP($BY$18,Sheet1!AT2:AW2,3,0),0) -> 0 | BZ25: 18 | CA25: 75 | CB25: =+IFERROR(VLOOKUP($CB$18,Sheet1!BF2:BI2,3,0),0) -> 0 | CC25: =+IFERROR(VLOOKUP($CC$18,Sheet1!BJ2:BM2,3,0),0) -> 0 | CD25: =+IFERROR(VLOOKUP($CD$18,Sheet1!BN2:BQ2,3,0),0) -> 0 | CE25: =+IFERROR(VLOOKUP($CE$18,Sheet1!BR2:BU2,3,0),0) -> 0 | CF25: 992 | CG25: =Sheet1!E2 -> STEEL | CH25: =Sheet1!CY2 -> SP0400123 | CI25: =Sheet1!CZ2 -> DRUM - 2000 X 1000 X 1200 | CJ25: 500 | CK25: =16500/0.5 -> 33000 | CL25: =SUMPRODUCT($N$19:$CF$19,N25:CF25)+CK25 -> 1045583 | CM25: =Sheet1!CB2 -> 0 | CN25: =CL25*CM25 -> 0 | CO25: 0.35 | CP25: =CL25*CO25 -> 365954.05 | CQ25: 0 | CR25: =CL25*CQ25 -> 0 | CS25: =CL25+CN25+CP25+CR25 -> 1411537.1 | CT25: 0.02 | CU25: =CS25*CT25 -> 28230.741 | CV25: 0 | CW25: =CS25*CV25 -> 0 | CX25: =Sheet1!CM2 -> 0 | CY25: =CX25*CS25 -> 0
M26: =SUM(M20:M25) -> 1.5625772e+09
E29: Order Quantity | F29: Stnd Length | G29: Truck type | H29: Fare of one truck | I29: No of Drum in one truck | J29: Total length in one Truck | K29: No of Truck | L29: Total Freight | M29: Freight per KM | W29: CABLE WEIGHT KG/KM | AA29: DRUM WEIGHT | AG29: CABLE+DRUM WEIGHT | AH29: TRAILOR
D30: =D20 -> 3 CORE X 150 SQ. MM. AL/ARM - STRIP (XLPE) - 11 KV | E30: =K20 -> 15 | F30: =CJ20/1000 -> 0.5 | G30: 25 MT TRAILOR | H30: 135000 | I30: 8 | J30: =F30*I30 -> 4 | K30: =ROUNDUP((E30/J30),0) -> 4 | L30: =H30*K30 -> 540000 | M30: =L30/E30 -> 36000 | N30: =CH20 -> SP0400112 | W30: =SUM(N20:CF20) -> 5024 | AA30: 220 | AG30: =((W30*F30)+AA30) -> 2732 | AH30: =AG30*I30 -> 21856
D31: =D21 -> 3 CORE X 300 SQ. MM. AL/ARM - STRIP (XLPE) - 11 KV | E31: =K21 -> 270 | F31: =CJ21/1000 -> 0.5 | G31: 25 MT TRAILOR | H31: 135000 | I31: 5 | J31: =F31*I31 -> 2.5 | K31: =ROUNDUP((E31/J31),0) -> 108 | L31: =H31*K31 -> 14580000 | M31: =L31/E31 -> 54000 | N31: =CH21 -> SP0400141 | W31: =SUM(N21:CF21) -> 7637 | AA31: 350 | AG31: =((W31*F31)+AA31) -> 4168.5 | AH31: =AG31*I31 -> 20842.5
D32: =D22 -> 3 CORE X 70 SQ. MM. AL/ARM - STRIP (XLPE) - 11 KV | E32: =K22 -> 15 | F32: =CJ22/1000 -> 0.5 | G32: 25 MT TRAILOR | H32: 135000 | I32: 10 | J32: =F32*I32 -> 5 | K32: =ROUNDUP((E32/J32),0) -> 3 | L32: =H32*K32 -> 405000 | M32: =L32/E32 -> 27000 | N32: =CH22 -> SP0400118 | W32: =SUM(N22:CF22) -> 3672 | AA32: 200 | AG32: =((W32*F32)+AA32) -> 2036 | AH32: =AG32*I32 -> 20360
D33: =D23 -> 3 CORE X 400 SQ. MM. AL/ARM - STRIP (XLPE) - 33 KV | E33: =K23 -> 195 | F33: =CJ23/1000 -> 0.5 | G33: 25 MT TRAILOR | H33: 135000 | I33: 3 | J33: =F33*I33 -> 1.5 | K33: =ROUNDUP((E33/J33),0) -> 130 | L33: =H33*K33 -> 17550000 | M33: =L33/E33 -> 90000 | N33: =CH23 -> SP0400105 | W33: =SUM(N23:CF23) -> 12276 | AA33: 470 | AG33: =((W33*F33)+AA33) -> 6608 | AH33: =AG33*I33 -> 19824
D34: =D24 -> 3 CORE X 300 SQ. MM. AL/ARM - STRIP (XLPE) - 33 KV | E34: =K24 -> 3 | F34: =CJ24/1000 -> 0.5 | G34: 25 MT TRAILOR | H34: 135000 | I34: 3 | J34: =F34*I34 -> 1.5 | K34: =ROUNDUP((E34/J34),0) -> 2 | L34: =H34*K34 -> 270000 | M34: =L34/E34 -> 90000 | N34: =CH24 -> SP0400105 | W34: =SUM(N24:CF24) -> 10666 | AA34: 470 | AG34: =((W34*F34)+AA34) -> 5803 | AH34: =AG34*I34 -> 17409
D35: =D25 -> 3 CORE X 120 SQ MM + 1 CORE X 125 SQ MM (AB CABLES) (INSULATED) - 11 KV | E35: =K25 -> 45 | F35: =CJ25/1000 -> 0.5 | G35: 25 MT TRAILOR | H35: 135000 | I35: 8 | J35: =F35*I35 -> 4 | K35: =ROUNDUP((E35/J35),0) -> 12 | L35: =H35*K35 -> 1620000 | M35: =L35/E35 -> 36000 | N35: =CH25 -> SP0400123 | W35: =SUM(N25:CF25) -> 4085 | AA35: 280 | AG35: =((W35*F35)+AA35) -> 2322.5 | AH35: =AG35*I35 -> 18580
B37: NOTE:- | C37: Please consider the rate of compounds from below mentioned makes :
C38: Aluminium conductor - BALCO / HINDALCO / NALCO / VEDANTA
C39: Semiconducting compound - DOW / BOREALIS / HANWHA
C40: XLPE compound- DOW / BOREALIS / HANWHA
C41: Water-swellable semiconducting tape - LANTOR / GECA / MIRACLE / SCAPA / SNEHAM INTERNATIONAL
C42: Core identification strips - AVSL INDUSTRIES / YASH POLYMERS / VIJOY POLYMERS
C43: PVC fillers- VIJOY POLYMERS / YASH POLYMERS / AVSL INDUSTRIES
C44: Copper Tape - AGGARWAL METAL/INDIAN SMELTING
C45: PVC compound - SHAKUN / KALPANA / KLJ / DCM SHRIRAM
C46: Galvanized steel armour - TATA STEEL / JINDAL STEEL / SAIL / JSW/BALAJI
A49: DOCKET NO. | B49: BASE DATE | C49: ITEM CODE | D49: PROPOSE ERP ITEM NAME | E49: EX-WORKS (PER MTR | F49: FREIGHT PER MTR | G49: PRICE INCLUDING FREIGHT (PER MTR) | H49: GST % | I49: GST VALUE | J49: PRICE INCLUDING GST & FREIGHT (PER MTR) | K49: QTY | L49: Unit | M49: TOTAL PRICE OF FULL QTY (INCLUDING FRIGHT & GST)
...

Sheet PV AUTO CALCULATION-HTPC
A1: Base Date | B1: 46023
A2: PV FORMULA
A3: The prices shall variable be as per Latest IEEMA Price Variation formula as mentioned below; P = Po + AIF (AI – Alo) + XLFAL(CC-Cco)+ SMIF (SMIF-SMIF0) + FeF(FeF-FeF0) + CCFAI (PVCc - PVCco) All #0# denoted input prices in the formula (Al0, CC0, SMIF0, PVCc0, Fe0, etc.) shall be as per IEEMA Circulars of January 2026 (Published in February 2026).
AF7: VALUE ADDITION CALCULATION
A8: Item | B8: Calculation part | C8: Date of Inspection | D8: Applicable Date | J8: BASE DATE | P8: FACTORS | W8: Ex-Work Po | X8: PVC of al | Y8: PVC of Cu | Z8: PVC of XLPE | AA8: PVC OF PVC | AB8: PVC OF FE | AC8: PVC OF CU TAPE | AD8: PV/PKM | AE8: Billing Price/PKM
D9: Date | E9: Al | F9: Cu | G9: Cc | H9: PVCc | I9: Fe | J9: Date | K9: Alo | L9: Cuo | M9: Cco | N9: PVCco | O9: Feo | AF9: ='AUTO CALCULATION SHEET (2)'!N18 -> Alumimium | AG9: ='AUTO CALCULATION SHEET (2)'!W18 -> Alumimium ALLOY | AH9: ='AUTO CALCULATION SHEET (2)'!AA18 -> Copper Tape - 0.04 mm | AI9: ='AUTO CALCULATION SHEET (2)'!AG18 -> Extruded Semiconductive(Stripable) | AJ9: ='AUTO CALCULATION SHEET (2)'!AH18 -> HT-XLPE | AK9: ='AUTO CALCULATION SHEET (2)'!AJ18 -> TR XLPE | AL9: ='AUTO CALCULATION SHEET (2)'!AQ18 -> POLY TAPE | AM9: ='AUTO CALCULATION SHEET (2)'!AX18 -> PVC Type ST-2 | AN9: ='AUTO CALCULATION SHEET (2)'!BG18 -> Galvanised Steel Flat Strip | AO9: ='AUTO CALCULATION SHEET (2)'!BO18 -> FRLSH PVC Type ST-2 | AP9: ='AUTO CALCULATION SHEET (2)'!BR18 -> PE-ST-7 | AQ9: ='AUTO CALCULATION SHEET (2)'!BX18 -> FILLER | AR9: ='AUTO CALCULATION SHEET (2)'!BY18 -> PP FILLER | AS9: ='AUTO CALCULATION SHEET (2)'!BZ18 -> Al Tape (15x0.10) | AT9: ='AUTO CALCULATION SHEET (2)'!CA18 -> Semi conducting Water Swellable tape | AU9: ='AUTO CALCULATION SHEET (2)'!CB18 -> NCWT | AV9: ='AUTO CALCULATION SHEET (2)'!CE18 -> RUBBERIZED COTTON TAPE | AW9: ='AUTO CALCULATION SHEET (2)'!CF18 -> Al Wire Screen | AX9: RMC | AY9: Drum | AZ9: RMC+Drum | BA9: VA | BB9: Groos VA% | BC9: Mfg % | BD9: Int % | BE9: Ins% | BF9: Net VA
P10: Alf | Q10: Cu | R10: XLFAL | S10: CCFAI | T10: CCFCu | U10: FeF | V10: Smif | AF10: 361 | AG10: =AF10+5 -> 366 | AH10: 1394 | AI10: 210 | AJ10: 158 | AK10: 240 | AL10: 130 | AM10: 83 | AN10: 76 | AO10: 98 | AP10: 132 | AQ10: 30 | AR10: 76 | AS10: 559 | AT10: 370 | AU10: 300 | AV10: 280 | AW10: =AF10+5 -> 366
AF11: Kg/Km | AG11: Kg/Km | AH11: Kg/Km | AI11: Kg/Km | AJ11: Kg/Km | AK11: Kg/Km | AL11: Kg/Km | AM11: Kg/Km | AN11: Kg/Km | AO11: Kg/Km | AP11: Kg/Km | AQ11: Kg/Km | AR11: Kg/Km | AS11: Kg/Km | AT11: Kg/Km | AU11: Kg/Km | AV11: Kg/Km | AW11: Kg/Km
A12: ='AUTO CALCULATION SHEET (2)'!D20 -> 3 CORE X 150 SQ. MM. AL/ARM - STRIP (XLPE) - 11 KV | C12: PROVISIONAL | D12: 46098 | E12: 352322.32 | F12: 1273267.1 | G12: 198367 | H12: 158825 | I12: 82250 | J12: =$B$1 -> 46023 | K12: 334622 | L12: 1275895 | M12: 194965 | N12: 153825 | O12: 80250 | P12: 1.279 | R12: 0.89 | S12: 2.061 | U12: 1.055 | V12: 0.088 | W12: ='AUTO CALCULATION SHEET (2)'!E51*1000 -> 1207630 | X12: =(P12*(E12-K12)) -> 22638.709 | Y12: =(Q12*(F12-L12)) -> 0 | Z12: =(R12*(G12-M12)) -> 3027.78 | AA12: =(S12*(H12-N12)) -> 10305 | AB12: =(U12*(I12-O12)) -> 2110 | AC12: =V12*(F12-L12) -> -231.25784 | AD12: =X12+Y12+Z12+AA12+AB12+AC12 -> 37850.231 | AE12: =+W12+AD12 -> 1245480.2 | AF12: ='AUTO CALCULATION SHEET (2)'!N20 -> 1215 | AG12: ='AUTO CALCULATION SHEET (2)'!W20 -> 0 | AH12: ='AUTO CALCULATION SHEET (2)'!AA20 -> 99 | AI12: ='AUTO CALCULATION SHEET (2)'!AG20 -> 246 | AJ12: ='AUTO CALCULATION SHEET (2)'!AH20 -> 620 | AK12: ='AUTO CALCULATION SHEET (2)'!AJ20 -> 0 | AL12: ='AUTO CALCULATION SHEET (2)'!AQ20 -> 37 | AM12: ='AUTO CALCULATION SHEET (2)'!AX20 -> 210 | AN12: ='AUTO CALCULATION SHEET (2)'!BG20 -> 972 | AO12: ='AUTO CALCULATION SHEET (2)'!BO20 -> 739 | AP12: ='AUTO CALCULATION SHEET (2)'!BR20 -> 0 | AQ12: ='AUTO CALCULATION SHEET (2)'!BX20 -> 809 | AR12: ='AUTO CALCULATION SHEET (2)'!BY20 -> 0 | AS12: ='AUTO CALCULATION SHEET (2)'!BZ20 -> 0 | AT12: ='AUTO CALCULATION SHEET (2)'!CA20 -> 37 | AU12: ='AUTO CALCULATION SHEET (2)'!CB20 -> 0 | AV12: ='AUTO CALCULATION SHEET (2)'!CE20 -> 40 | AW12: ='AUTO CALCULATION SHEET (2)'!CF20 -> 0 | AX12: =SUMPRODUCT(AF12:AW12,$AF$10:$AW$10) -> 943935 | AY12: ='AUTO CALCULATION SHEET (2)'!CK20 -> 33000 | AZ12: =AX12+AY12 -> 976935 | BA12: =AE12-AZ12 -> 268545.23 | BB12: =ROUND((BA12/AZ12)*100,2) -> 27.49 | BC12: 0 | BD12: 2 | BE12: 0 | BF12: =BB12-BC12-BD12-BE12 -> 25.49
A13: ='AUTO CALCULATION SHEET (2)'!D21 -> 3 CORE X 300 SQ. MM. AL/ARM - STRIP (XLPE) - 11 KV | C13: PROVISIONAL | D13: 46098 | E13: 352322.32 | F13: 1273267.1 | G13: 198367 | H13: 158825 | I13: 82250 | J13: =$B$1 -> 46023 | K13: 334622 | L13: 1275895 | M13: 194965 | N13: 153825 | O13: 80250 | P13: 2.635 | R13: 1.167 | S13: 3.161 | U13: 1.318 | V13: 0.11 | W13: ='AUTO CALCULATION SHEET (2)'!E52*1000 -> 1958020 | X13: =(P13*(E13-K13)) -> 46640.343 | Y13: =(Q13*(F13-L13)) -> 0 | Z13: =(R13*(G13-M13)) -> 3970.134 | AA13: =(S13*(H13-N13)) -> 15805 | AB13: =(U13*(I13-O13)) -> 2636 | AC13: =V13*(F13-L13) -> -289.0723 | AD13: =X13+Y13+Z13+AA13+AB13+AC13 -> 68762.405 | AE13: =+W13+AD13 -> 2026782.4 | AF13: ='AUTO CALCULATION SHEET (2)'!N21 -> 2430 | AG13: ='AUTO CALCULATION SHEET (2)'!W21 -> 0 | AH13: ='AUTO CALCULATION SHEET (2)'!AA21 -> 123 | AI13: ='AUTO CALCULATION SHEET (2)'!AG21 -> 337 | AJ13: ='AUTO CALCULATION SHEET (2)'!AH21 -> 802 | AK13: ='AUTO CALCULATION SHEET (2)'!AJ21 -> 0 | AL13: ='AUTO CALCULATION SHEET (2)'!AQ21 -> 46 | AM13: ='AUTO CALCULATION SHEET (2)'!AX21 -> 291 | AN13: ='AUTO CALCULATION SHEET (2)'!BG21 -> 1215 | AO13: ='AUTO CALCULATION SHEET (2)'!BO21 -> 1045 | AP13: ='AUTO CALCULATION SHEET (2)'!BR21 -> 0 | AQ13: ='AUTO CALCULATION SHEET (2)'!BX21 -> 1258 | AR13: ='AUTO CALCULATION SHEET (2)'!BY21 -> 0 | AS13: ='AUTO CALCULATION SHEET (2)'!BZ21 -> 0 | AT13: ='AUTO CALCULATION SHEET (2)'!CA21 -> 46 | AU13: ='AUTO CALCULATION SHEET (2)'!CB21 -> 0 | AV13: ='AUTO CALCULATION SHEET (2)'!CE21 -> 44 | AW13: ='AUTO CALCULATION SHEET (2)'!CF21 -> 0 | AX13: =SUMPRODUCT(AF13:AW13,$AF$10:$AW$10) -> 1538141 | AY13: ='AUTO CALCULATION SHEET (2)'!CK21 -> 38500 | AZ13: =AX13+AY13 -> 1576641 | BA13: =AE13-AZ13 -> 450141.4 | BB13: =ROUND((BA13/AZ13)*100,2) -> 28.55 | BC13: 0 | BD13: 2 | BE13: 0 | BF13: =BB13-BC13-BD13-BE13 -> 26.55
A14: ='AUTO CALCULATION SHEET (2)'!D22 -> 3 CORE X 70 SQ. MM. AL/ARM - STRIP (XLPE) - 11 KV | C14: PROVISIONAL | D14: 46098 | E14: 352322.32 | F14: 1273267.1 | G14: 198367 | H14: 158825 | I14: 82250 | J14: =$B$1 -> 46023 | K14: 334622 | L14: 1275895 | M14: 194965 | N14: 153825 | O14: 80250 | P14: 0.593 | R14: 0.679 | S14: 1.396 | U14: 0.849 | V14: 0.071 | W14: ='AUTO CALCULATION SHEET (2)'!E53*1000 -> 785530 | X14: =(P14*(E14-K14)) -> 10496.29 | Y14: =(Q14*(F14-L14)) -> 0 | Z14: =(R14*(G14-M14)) -> 2309.958 | AA14: =(S14*(H14-N14)) -> 6980 | AB14: =(U14*(I14-O14)) -> 1698 | AC14: =V14*(F14-L14) -> -186.58303 | AD14: =X14+Y14+Z14+AA14+AB14+AC14 -> 21297.665 | AE14: =+W14+AD14 -> 806827.66 | AF14: ='AUTO CALCULATION SHEET (2)'!N22 -> 567 | AG14: ='AUTO CALCULATION SHEET (2)'!W22 -> 0 | AH14: ='AUTO CALCULATION SHEET (2)'!AA22 -> 81 | AI14: ='AUTO CALCULATION SHEET (2)'!AG22 -> 188 | AJ14: ='AUTO CALCULATION SHEET (2)'!AH22 -> 474 | AK14: ='AUTO CALCULATION SHEET (2)'!AJ22 -> 0 | AL14: ='AUTO CALCULATION SHEET (2)'!AQ22 -> 30 | AM14: ='AUTO CALCULATION SHEET (2)'!AX22 -> 167 | AN14: ='AUTO CALCULATION SHEET (2)'!BG22 -> 858 | AO14: ='AUTO CALCULATION SHEET (2)'!BO22 -> 708 | AP14: ='AUTO CALCULATION SHEET (2)'!BR22 -> 0 | AQ14: ='AUTO CALCULATION SHEET (2)'!BX22 -> 533 | AR14: ='AUTO CALCULATION SHEET (2)'!BY22 -> 0 | AS14: ='AUTO CALCULATION SHEET (2)'!BZ22 -> 0 | AT14: ='AUTO CALCULATION SHEET (2)'!CA22 -> 31 | AU14: ='AUTO CALCULATION SHEET (2)'!CB22 -> 0 | AV14: ='AUTO CALCULATION SHEET (2)'!CE22 -> 35 | AW14: ='AUTO CALCULATION SHEET (2)'!CF22 -> 0 | AX14: =SUMPRODUCT(AF14:AW14,$AF$10:$AW$10) -> 621586 | AY14: ='AUTO CALCULATION SHEET (2)'!CK22 -> 19800 | AZ14: =AX14+AY14 -> 641386 | BA14: =AE14-AZ14 -> 165441.66 | BB14: =ROUND((BA14/AZ14)*100,2) -> 25.79 | BC14: 0 | BD14: 2 | BE14: 0 | BF14: =BB14-BC14-BD14-BE14 -> 23.79
A15: ='AUTO CALCULATION SHEET (2)'!D23 -> 3 CORE X 400 SQ. MM. AL/ARM - STRIP (XLPE) - 33 KV | C15: PROVISIONAL | D15: 46098 | E15: 352322.32 | F15: 1273267.1 | G15: 198367 | H15: 158825 | I15: 82250 | J15: =$B$1 -> 46023 | K15: 334622 | L15: 1275895 | M15: 194965 | N15: 153825 | O15: 80250 | P15: 3.374 | R15: 3.229 | S15: 5.736 | U15: 1.876 | V15: 0.164 | W15: ='AUTO CALCULATION SHEET (2)'!E54*1000 -> 3371290 | X15: =(P15*(E15-K15)) -> 59720.88 | Y15: =(Q15*(F15-L15)) -> 0 | Z15: =(R15*(G15-M15)) -> 10985.058 | AA15: =(S15*(H15-N15)) -> 28680 | AB15: =(U15*(I15-O15)) -> 3752 | AC15: =V15*(F15-L15) -> -430.98052 | AD15: =X15+Y15+Z15+AA15+AB15+AC15 -> 102706.96 | AE15: =+W15+AD15 -> 3473997 | AF15: ='AUTO CALCULATION SHEET (2)'!N23 -> 3240 | AG15: ='AUTO CALCULATION SHEET (2)'!W23 -> 0 | AH15: ='AUTO CALCULATION SHEET (2)'!AA23 -> 181 | AI15: ='AUTO CALCULATION SHEET (2)'!AG23 -> 427 | AJ15: ='AUTO CALCULATION SHEET (2)'!AH23 -> 0 | AK15: ='AUTO CALCULATION SHEET (2)'!AJ23 -> 2621 | AL15: ='AUTO CALCULATION SHEET (2)'!AQ23 -> 66 | AM15: ='AUTO CALCULATION SHEET (2)'!AX23 -> 426 | AN15: ='AUTO CALCULATION SHEET (2)'!BG23 -> 1728 | AO15: ='AUTO CALCULATION SHEET (2)'!BO23 -> 1638 | AP15: ='AUTO CALCULATION SHEET (2)'!BR23 -> 0 | AQ15: ='AUTO CALCULATION SHEET (2)'!BX23 -> 0 | AR15: ='AUTO CALCULATION SHEET (2)'!BY23 -> 1718 | AS15: ='AUTO CALCULATION SHEET (2)'!BZ23 -> 0 | AT15: ='AUTO CALCULATION SHEET (2)'!CA23 -> 104 | AU15: ='AUTO CALCULATION SHEET (2)'!CB23 -> 58 | AV15: ='AUTO CALCULATION SHEET (2)'!CE23 -> 69 | AW15: ='AUTO CALCULATION SHEET (2)'!CF23 -> 0 | AX15: =SUMPRODUCT(AF15:AW15,$AF$10:$AW$10) -> 2682222 | AY15: ='AUTO CALCULATION SHEET (2)'!CK23 -> 44000 | AZ15: =AX15+AY15 -> 2726222 | BA15: =AE15-AZ15 -> 747774.96 | BB15: =ROUND((BA15/AZ15)*100,2) -> 27.43 | BC15: 0 | BD15: 2 | BE15: 0 | BF15: =BB15-BC15-BD15-BE15 -> 25.43
