Workbook

Sheet Sheet1
A1: DOCKET NO. | B1: Base Date | C1: ITEM CODE | D1: PROPOSE ERP ITEM NAME | E1: Propose Drum Type | F1: Insulation Screening(Metallic) | G1: RM Rate(Insulation Screening(Metallic)) | H1: Weight (Insulation Screening (Metallic)) | I1: Cost Insulation Screening(Metallic) | J1: Conductor | K1: RM Rate(Conductor) | L1: Weight(Conductor) | M1: Cost(Conductor) | N1: AL ALLOY | O1: RM Rate(AL Alloy) | P1: Weight(Al Alloy) | Q1: Cost(AL Alloy) | R1: Insulation Screening(Non-Metallic) | S1: RM Rate(Insulation Screening(Non-Metallic)) | T1: Weight(Insulation Screening(Non-Metallic) | U1: Cost(Insulation Screening(Non-Metallic) | V1: Insulation | W1: RM Rate(Insulation) | X1: Weight(Insulation) | Y1: Cost(Insulation) | Z1: Poly Tape | AA1: RM Rate(Poly Tape) | AB1: Weight(Poly Tape) | AC1: Cost(Poly Tape) | AD1: Inner Sheath | AE1: RM Rate(Inner Sheath) | AF1: Weight(Inner Sheath) | AG1: Cost(Inner Sheath) | AH1: Armouring | AI1: RM Rate(Armouring) | AJ1: Weight(Armouring) | AK1: Cost(Armouring) | AL1: Outer Sheath | AM1: RM Rate(Outer Sheath) | AN1: Weight(Outer Sheath) | AO1: Cost(Outer Sheath) | AP1: Filler | AQ1: RM Rate(Filler) | AR1: Weight(Filler) | AS1: Cost(Filler) | AT1: Grease | AU1: RM Rate(Grease) | AV1: Weight(Grease) | AW1: Cost(Grease) | AX1: Water Swellable Tape | AY1: RM Rate(Water Swellable Tape) | AZ1: Weight(Water Swellable Tape) | BA1: Cost(Water Swellable Tape) | BB1: Semi Conducting Water Swellable Tape | BC1: RM Rate(Semi Conducting Water Swellable Tape) | BD1: Weight(Semi Conducting Water Swellable Tape) | BE1: Cost(Semi Conducting Water Swellable Tape) | BF1: Semicon Tape | BG1: RM Rate(Semicon Tape) | BH1: Weight(Semicon Tape) | BI1: Cost(Semicon Tape) | BJ1: Glass Fiber Tape | BK1: RM Rate(Glass Fiber Tape) | BL1: Weight(Glass Fiber Tape) | BM1: Cost(Glass Fiber Tape) | BN1: Copper Wire 0.8MM | BO1: RM Rate(Copper Wire 0.8MM) | BP1: Weight(Copper Wire 0.8MM) | BQ1: Cost(Copper Wire 0.8MM) | BR1: Rubberized Cotton Tape | BS1: RM Rate(Rubberized Cotton Tape) | BT1: Weight(Rubberized Cotton Tape) | BU1: Cost(Rubberized Cotton Tape) | BV1: Water Tight Compound | BW1: RM Rate(Water Tight Compound) | BX1: Weight(Water Tight Compound) | BY1: Cost(Water Tight Compound) | BZ1: Drum Cost Per KM | CA1: Total RM Cost | CB1: FIRM % | CC1: Firm Value | CD1: MFG% | CE1: MFG Value | CF1: PROF% | CG1: Profit Value | CH1: 1st EX-Works | CI1: Intt % | CJ1: Intt Value | CK1: insp% | CL1: Insp Value | CM1: TTR CHARGES% | CN1: TTR Value | CO1: EX-Works Per KM | CP1: Freight Per KM | CQ1: Price Including Freight Per KM | CR1: GST % | CS1: GST Value | CT1: Price Including GST & Freight Per KM | CU1: QTY | CV1: Unit | CW1: Total Price Of Full QTY(Including Freight&GST) | CX1: DRUM CODE | CY1: DRUM SIZE (FxbXtx Ft) | CZ1: Party Standard Length(MTR)
A2: ENQ-16531-25-26 | C2: FA0200002 | D2: 10 CORE X 2.5 SQ. MM. CU/ARD - WIRE (PVC) | E2: WOOD | H2: 0 | J2: Tinned Copper | L2: 222 | P2: 0 | T2: 0 | V2: Type C PVC (HR) | X2: 130 | Z2: POLY TAPE | AB2: 5 | AD2: FR PVC Type ST-2 | AF2: 38 | AH2: Galvanised Steel Round Wire | AJ2: 492 | AL2: FRLSH PVC Type ST-2 | AN2: 166 | AR2: 0 | AV2: 0 | AZ2: 0 | BD2: 0 | BH2: 0 | BL2: 28 | BP2: 0 | BT2: 0 | BX2: 0 | BZ2: 5448 | CA2: 5448 | CH2: 5448 | CO2: 5448 | CQ2: 5448 | CR2: 0.18 | CS2: 980.64 | CT2: 6428.64 | CU2: 35 | CV2: KMS | CW2: 225002 | CX2: MD0100066 | CY2: DRUM - 40 X 15 X 23 X 2 | CZ2: 500
A3: ENQ-16531-25-26 | C3: FA0200003 | D3: 12 CORE X 2.5 SQ. MM. CU/ARD - WIRE (PVC) | E3: WOOD | H3: 0 | J3: Tinned Copper | L3: 266 | P3: 0 | T3: 0 | V3: Type C PVC (HR) | X3: 156 | Z3: POLY TAPE | AB3: 6 | AD3: FR PVC Type ST-2 | AF3: 40 | AH3: Galvanised Steel Round Wire | AJ3: 508 | AL3: FRLSH PVC Type ST-2 | AN3: 170 | AR3: 0 | AV3: 0 | AZ3: 0 | BD3: 0 | BH3: 0 | BL3: 28 | BP3: 0 | BT3: 0 | BX3: 0 | BZ3: 5448 | CA3: 5448 | CH3: 5448 | CO3: 5448 | CQ3: 5448 | CR3: 0.18 | CS3: 980.64 | CT3: 6428.64 | CU3: 35 | CV3: KMS | CW3: 225002 | CX3: MD0100066 | CY3: DRUM - 40 X 15 X 23 X 2 | CZ3: 500
A4: ENQ-16531-25-26 | C4: FA0200008 | D4: 2 CORE X 2.5 SQ. MM. CU/ARD - WIRE (PVC) | E4: WOOD | H4: 0 | J4: Tinned Copper | L4: 44 | P4: 0 | T4: 0 | V4: Type C PVC (HR) | X4: 26 | Z4: POLY TAPE | AB4: 3 | AD4: FR PVC Type ST-2 | AF4: 39 | AH4: Galvanised Steel Round Wire | AJ4: 251 | AL4: FRLSH PVC Type ST-2 | AN4: 93 | AR4: 0 | AV4: 0 | AZ4: 0 | BD4: 0 | BH4: 0 | BL4: 16 | BP4: 0 | BT4: 0 | BX4: 0 | BZ4: 4260 | CA4: 4260 | CH4: 4260 | CO4: 4260 | CQ4: 4260 | CR4: 0.18 | CS4: 766.8 | CT4: 5026.8 | CU4: 15 | CV4: KMS | CW4: 75402 | CX4: MD0100003 | CY4: DRUM - 28 X 14 X 23 X 2 | CZ4: 500
A5: ENQ-16531-25-26 | C5: FA0200011 | D5: 4 CORE X 2.5 SQ. MM. CU/ARD - WIRE (PVC) | E5: WOOD | H5: 0 | J5: Tinned Copper | L5: 89 | P5: 0 | T5: 0 | V5: Type C PVC (HR) | X5: 52 | Z5: POLY TAPE | AB5: 3 | AD5: FR PVC Type ST-2 | AF5: 27 | AH5: Galvanised Steel Round Wire | AJ5: 289 | AL5: FRLSH PVC Type ST-2 | AN5: 104 | AR5: 0 | AV5: 0 | AZ5: 0 | BD5: 0 | BH5: 0 | BL5: 19 | BP5: 0 | BT5: 0 | BX5: 0 | BZ5: 5170 | CA5: 5170 | CH5: 5170 | CO5: 5170 | CQ5: 5170 | CR5: 0.18 | CS5: 930.6 | CT5: 6100.6 | CU5: 25 | CV5: KMS | CW5: 152515 | CX5: MD0100005 | CY5: DRUM - 36 X 14 X 23 X 2 | CZ5: 500

Sheet AUTO CALCULATION SHEET (2)
A2: NORTH BIHAR POWER DISTRIBUTION CO. LTD, PATNA
A4: TENDER SPECIFICATION NO () | B4: 72/PR/NBPDCL/2025 (System Tender No.104083)
A5: TENDER DESCRIPTION () | B5: LT Copper control cable of different size for NBPDCL and SBPDCL
A6: Last Date & Time of Submission () | B6: 04-08-2025 06:00 PM
A7: REVERSE AUCTION | B7: Not Mention
A8: Price () | B8: Price Variation for Control Cable shall be applicable as per current IEEMA as applicable on the final date of submission of bid. Base date will be one month prior to the last date of submission of bid against the NIT.
A9: Validity () | B9: 1.11.1. Bidders should specify the validity period of their offer/bid which should be valid for a minimum period of 180 days from the last date of submission of bid.
A10: Payment Terms () | B10: 90% payment along with full amount of taxes, duties and freight keeping 10% retention money , on submission of triplicate copy of bills with all relevant documents (Sample check list) enclosed in annexure by the vendor after receipt of the material / equipment in good condition. After successful completion of delivery of entire order or modified quantity as decided during its delivery schedule, 10 % retention money may be released after deduction of penalty. ii. Payment will be released normally within 15 working days from the date of submission of bill along with all required relevant document(s) to Sr. Manager (Finance), NBPDCL/SBPDCL.
A11: Standard length () | B11: Standard lengths for each size of power and control cables shall be 500/1000 meters. The cable length per drum shall be subject to a tolerance of plus or minus 5% of the standard drum length.
A12: Packing () | B12: Cables shall be supplied on returnable wooden or steel drums of heavy construction. Wooden drum shall be properly seasoned sound and free from defects. Wood preservative shall be applied to the entire drum.
A13: Technical Specification
N15: Conductor | V15: AL ALLOY | X15: Insulation Screening (Metallic) | AF15: Insulation Screening (Non-Metallic) | AH15: Insulation | AQ15: POLY TAPE | AR15: Inner Sheath | BA15: Armouring | BL15: Outer Sheath | BX15: FILLER | BY15: GREASE | BZ15: Water swellable Tape | CA15: Semi conducting Water Swellable tape | CB15: SEMICON TAPE | CC15: GLASS FIBER TAPE | CD15: COPPER WIRE 0.8 MM | CE15: RUBBERIZED COTTON TAPE | CF15: Water Tight Compound | CG15: DRUM TYPE | CK15: DRUM COST PER KM | CL15: TOTAL RM COST | CM15: EXTRA CONSUMPTION | CN15: EXTRA CONSUMPTION VALUE | CZ15: $A$1
A16: DOCKET NO. | B16: BASE DATE | C16: ITEM CODE | D16: PROPOSE ERP ITEM NAME | E16: EX-WORKS (PER KM) | F16: FREIGHT PER KM | G16: PRICE INCLUDING FREIGHT (PER KM) | H16: GST % | I16: GST VALUE | J16: PRICE INCLUDING GST & FREIGHT (PER KM) | K16: QTY | L16: Unit | M16: TOTAL PRICE OF FULL QTY (INCLUDING FRIGHT & GST) | N16: Alumimium | O16: Alumimium ALLOY | P16: Tinned Copper | Q16: AL-59 | R16: AL-4 | S16: AL-7 | T16: Flexible Copper | U16: Galvanized steel wire | V16: Alumimium | W16: Alumimium ALLOY | X16: Coper tape - 0.1 mm | Y16: Copper Tape - 0.03 mm | Z16: Copper Tape - 0.035 mm | AA16: Copper Tape - 0.04 mm | AB16: Copper Tape - 0.045 mm | AC16: Copper Tape - 0.050 mm | AD16: Copper Tape - 0.060 mm | AE16: Copper Tape - 0.075 mm(DOUBLE) | AF16: Extruded semiconductive | AG16: Extruded Semiconductive(Stripable) | AH16: HT-XLPE | AI16: LT-XLPE | AJ16: TR XLPE | AK16: Type A PVC | AL16: Type C PVC (HR) | AM16: Type A PVC-1.45 | AN16: Type A PVC-FR | AO16: Type A PVC-FRLS | AP16: Type A PVC-1.38 | AQ16: POLY TAPE | AR16: FR PVC Type ST-1 | AS16: FR PVC Type ST-2 | AT16: FRLSH PVC Type ST-1 | AU16: FRLSH PVC Type ST-2 | AV16: PVC Type ST-1 | AW16: PVC Type ST-1-PRESSURE EXTRUDED | AX16: PVC Type ST-2 | AY16: PVC COMPOUND 1.48 | AZ16: PVC Type ST-2-PRESSURE EXTRUDED | BA16: ACSR CORE WIRE | BB16: ACSR DOG STEEL WIRE | BC16: Aluminium Flat Strip | BD16: Aluminium Round Wire | BE16: Alumimium Tape | BF16: Double Steel Tape | BG16: Galvanised Steel Flat Strip | BH16: Galvanised Steel Flat Strip (Double) | BI16: Galvanised Steel Flat Strip-B | BJ16: Galvanised Steel Round Wire | BK16: Galvanised Steel Round Wire (Double) | BL16: FR PVC Type ST-1 | BM16: FR PVC Type ST-2 | BN16: FRLSH PVC Type ST-1 | BO16: FRLSH PVC Type ST-2 | BP16: ZHFR | BQ16: PE-ST-3 | BR16: PE-ST-7 | BS16: PVC Type ST-1 | BT16: PVC Type ST-2 | BU16: PVC COMPOUND 1.48 | BV16: PVC Type ST-2-PRESSURE EXTRUDED | BW16: UV & Track Resistant XLPE | BX16: FILLER | BY16: Grease | BZ16: Water swellable Tape | CA16: Semi conducting Water Swellable tape | CB16: SEMICON TAPE | CC16: GLASS FIBER TAPE | CD16: COPPER WIRE 0.8 MM | CE16: RUBBERIZED COTTON TAPE | CF16: Water Tight Compound | CG16: PROPOSE DRUM TYPE | CH16: DRUM CODE | CI16: DRUM SIZE (FxbXtx Ft) | CJ16: PARTY STANDARD LENGTH (MTR) | CO16: MFG% | CP16: MFG VALUE | CQ16: PROF% | CR16: PROFIT VALUE | CS16: 1ST EX-WORKS | CT16: Intt % | CU16: INTT VALUE | CV16: insp% | CW16: INSP VALUE | CX16: TTR Charges% | CY16: TTR Charges VALUE
N17: =+IFERROR(VLOOKUP($N$16,Sheet1!J:L,2,0),0) -> 0 | O17: =+IFERROR(VLOOKUP($O$16,Sheet1!J:L,2,0),0) -> 0 | P17: 964 | Q17: =+IFERROR(VLOOKUP($Q$16,Sheet1!J:M,2,0),0) -> 0 | R17: =+IFERROR(VLOOKUP($R$16,Sheet1!J:M,2,0),0) -> 0 | S17: =+IFERROR(VLOOKUP($S$16,Sheet1!J:M,2,0),0) -> 0 | T17: =+IFERROR(VLOOKUP($T$16,Sheet1!J:M,2,0),0) -> 0 | U17: =+IFERROR(VLOOKUP($U$16,Sheet1!J:M,2,0),0) -> 0 | V17: =+IFERROR(VLOOKUP($V$16,Sheet1!N:Q,2,0),0) -> 0 | W17: =+IFERROR(VLOOKUP($W$16,Sheet1!N:O,2,0),0) -> 0 | X17: =+IFERROR(VLOOKUP($X$16,Sheet1!F:I,2,0),0) -> 0 | Y17: =+IFERROR(VLOOKUP($Y$16,Sheet1!F:I,2,0),0) -> 0 | Z17: =+IFERROR(VLOOKUP($Z$16,Sheet1!F:I,2,0),0) -> 0 | AA17: =+IFERROR(VLOOKUP($AA$16,Sheet1!F:I,2,0),0) -> 0 | AB17: =+IFERROR(VLOOKUP($AB$16,Sheet1!F:I,2,0),0) -> 0 | AC17: =+IFERROR(VLOOKUP($AC$16,Sheet1!F:I,2,0),0) -> 0 | AD17: =+IFERROR(VLOOKUP($AD$16,Sheet1!F:I,2,0),0) -> 0 | AE17: =+IFERROR(VLOOKUP($AE$16,Sheet1!F:I,2,0),0) -> 0 | AF17: =+IFERROR(VLOOKUP($AF$16,Sheet1!R:U,2,0),0) -> 0 | AG17: =+IFERROR(VLOOKUP($AG$16,Sheet1!R:U,2,0),0) -> 0 | AH17: =+IFERROR(VLOOKUP($AH$16,Sheet1!V:Y,2,0),0) -> 0 | AI17: =+IFERROR(VLOOKUP($AI$16,Sheet1!V:Y,2,0),0) -> 0 | AJ17: =+IFERROR(VLOOKUP($AJ$16,Sheet1!V:Y,2,0),0) -> 0 | AK17: =+IFERROR(VLOOKUP($AK$16,Sheet1!V:Y,2,0),0) -> 0 | AL17: 97 | AM17: =+IFERROR(VLOOKUP($AM$16,Sheet1!V:Y,2,0),0) -> 0 | AN17: =+IFERROR(VLOOKUP($AN$16,Sheet1!V:Y,2,0),0) -> 0 | AO17: =+IFERROR(VLOOKUP($AO$16,Sheet1!V:Y,2,0),0) -> 0 | AP17: =+IFERROR(VLOOKUP($AP$16,Sheet1!V:Y,2,0),0) -> 0 | AQ17: 111 | AR17: =+IFERROR(VLOOKUP($AR$16,Sheet1!AD2:AG840,2,0),0) -> 0 | AS17: 81 | AT17: =+IFERROR(VLOOKUP($AT$16,Sheet1!AD2:AG840,2,0),0) -> 0 | AU17: =+IFERROR(VLOOKUP($AU$16,Sheet1!AD2:AG840,2,0),0) -> 0 | AV17: =+IFERROR(VLOOKUP($AV$16,Sheet1!AD2:AG840,2,0),0) -> 0 | AW17: =+IFERROR(VLOOKUP($AW$16,Sheet1!AD2:AG840,2,0),0) -> 0 | AX17: =+IFERROR(VLOOKUP($AX$16,Sheet1!AD2:AG840,2,0),0) -> 0 | AY17: =+IFERROR(VLOOKUP($AY$16,Sheet1!AD2:AG840,2,0),0) -> 0 | AZ17: =+IFERROR(VLOOKUP($AZ$16,Sheet1!AD2:AG840,2,0),0) -> 0 | BA17: =+IFERROR(VLOOKUP($BA$16,Sheet1!AH2:AK840,2,0),0) -> 0 | BB17: =+IFERROR(VLOOKUP($BB$16,Sheet1!AH2:AK840,2,0),0) -> 0 | BC17: =+IFERROR(VLOOKUP($BC$16,Sheet1!AH2:AK840,2,0),0) -> 0 | BD17: =+IFERROR(VLOOKUP($BD$16,Sheet1!AH2:AK840,2,0),0) -> 0 | BE17: =+IFERROR(VLOOKUP($BE$16,Sheet1!AH2:AK840,2,0),0) -> 0 | BF17: =+IFERROR(VLOOKUP($BF$16,Sheet1!AH2:AK840,2,0),0) -> 0 | BG17: =+IFERROR(VLOOKUP($BG$16,Sheet1!AH2:AK840,2,0),0) -> 0 | BH17: =+IFERROR(VLOOKUP($BH$16,Sheet1!AH2:AK840,2,0),0) -> 0 | BI17: =+IFERROR(VLOOKUP($BI$16,Sheet1!AH2:AK840,2,0),0) -> 0 | BJ17: 79 | BK17: =+IFERROR(VLOOKUP($BK$16,Sheet1!AH2:AK840,2,0),0) -> 0 | BL17: =+IFERROR(VLOOKUP($BL$16,Sheet1!AL2:AO840,2,0),0) -> 0 | BM17: =+IFERROR(VLOOKUP($BM$16,Sheet1!AL2:AO840,2,0),0) -> 0 | BN17: =+IFERROR(VLOOKUP($BN$16,Sheet1!AL2:AO840,2,0),0) -> 0 | BO17: 81 | BP17: =+IFERROR(VLOOKUP($BP$16,Sheet1!AL2:AO840,2,0),0) -> 0 | BQ17: =+IFERROR(VLOOKUP($BQ$16,Sheet1!AL2:AO840,2,0),0) -> 0 | BR17: =+IFERROR(VLOOKUP($BR$16,Sheet1!AL2:AO840,2,0),0) -> 0 | BS17: =+IFERROR(VLOOKUP($BS$16,Sheet1!AL2:AO840,2,0),0) -> 0 | BT17: =+IFERROR(VLOOKUP($BT$16,Sheet1!AL2:AO840,2,0),0) -> 0 | BU17: =+IFERROR(VLOOKUP($BU$16,Sheet1!AL2:AO840,2,0),0) -> 0 | BV17: =+IFERROR(VLOOKUP($BV$16,Sheet1!AL2:AO840,2,0),0) -> 0 | BW17: =+IFERROR(VLOOKUP($BW$16,Sheet1!AL2:AO840,2,0),0) -> 0 | BX17: =+IFERROR(VLOOKUP($BX$16,Sheet1!AP2:AS840,2,0),0) -> 0 | BY17: =+IFERROR(VLOOKUP($BY$16,Sheet1!AT2:AW840,2,0),0) -> 0 | BZ17: =+IFERROR(VLOOKUP($BZ$16,Sheet1!AX2:BA840,2,0),0) -> 0 | CA17: =+IFERROR(VLOOKUP($CA$16,Sheet1!BB2:BE840,2,0),0) -> 0 | CB17: =+IFERROR(VLOOKUP($CB$16,Sheet1!BF2:BI840,2,0),0) -> 0 | CC17: =+IFERROR(VLOOKUP($CC$16,Sheet1!BJ2:BM840,2,0),0) -> 0 | CD17: =+IFERROR(VLOOKUP($CD$16,Sheet1!BN2:BQ840,2,0),0) -> 0 | CE17: =+IFERROR(VLOOKUP($CE$16,Sheet1!BR2:BU840,2,0),0) -> 0 | CF17: =+IFERROR(VLOOKUP($CF$16,Sheet1!BV2:BY840,2,0),0) -> 0
A18: =Sheet1!A4 -> ENQ-16531-25-26 | B18: 45839 | C18: =Sheet1!C4 -> FA0200008 | D18: =Sheet1!D4 -> 2 CORE X 2.5 SQ. MM. CU/ARD - WIRE (PVC) | E18: =CS18+CU18+CW18+CY18 -> 88225.309 | F18: =ROUNDUP(M34,0) -> 2967 | G18: =E18+F18 -> 91192.309 | H18: =Sheet1!CR4 -> 0.18 | I18: =G18*H18 -> 16414.616 | J18: =G18+I18 -> 107606.92 | K18: =Sheet1!CU4 -> 15 | L18: =Sheet1!CV4 -> KMS | M18: =J18*K18 -> 1614103.9 | N18: =+IFERROR(VLOOKUP($N$16,Sheet1!J4:L4,3,0),0) -> 0 | O18: =+IFERROR(VLOOKUP($O$16,Sheet1!J4:L4,3,0),0) -> 0 | P18: =+IFERROR(VLOOKUP($P$16,Sheet1!J4:M4,3,0),0) -> 44 | Q18: =+IFERROR(VLOOKUP($Q$16,Sheet1!J4:M4,3,0),0) -> 0 | R18: =+IFERROR(VLOOKUP($R$16,Sheet1!J4:M4,3,0),0) -> 0 | S18: =+IFERROR(VLOOKUP($S$16,Sheet1!J4:M4,3,0),0) -> 0 | T18: =+IFERROR(VLOOKUP($T$16,Sheet1!J4:M4,3,0),0) -> 0 | U18: =+IFERROR(VLOOKUP($U$16,Sheet1!J4:M4,3,0),0) -> 0 | V18: =+IFERROR(VLOOKUP($V$16,Sheet1!N4:Q4,3,0),0) -> 0 | W18: =+IFERROR(VLOOKUP($W$16,Sheet1!N4:Q4,3,0),0) -> 0 | X18: =+IFERROR(VLOOKUP($X$16,Sheet1!F4:I4,3,0),0) -> 0 | Y18: =+IFERROR(VLOOKUP($Y$16,Sheet1!F4:I4,3,0),0) -> 0 | Z18: =+IFERROR(VLOOKUP($Z$16,Sheet1!F4:I4,3,0),0) -> 0 | AA18: =+IFERROR(VLOOKUP($AA$16,Sheet1!F4:I4,3,0),0) -> 0 | AB18: =+IFERROR(VLOOKUP($AB$16,Sheet1!F4:I4,3,0),0) -> 0 | AC18: =+IFERROR(VLOOKUP($AC$16,Sheet1!F4:I4,3,0),0) -> 0 | AD18: =+IFERROR(VLOOKUP($AD$16,Sheet1!F4:I4,3,0),0) -> 0 | AE18: =+IFERROR(VLOOKUP($AE$16,Sheet1!F4:I4,3,0),0) -> 0 | AF18: =+IFERROR(VLOOKUP($AF$16,Sheet1!R4:U4,3,0),0) -> 0 | AG18: =+IFERROR(VLOOKUP($AG$16,Sheet1!R4:U4,3,0),0) -> 0 | AH18: =+IFERROR(VLOOKUP($AH$16,Sheet1!V4:Y4,3,0),0) -> 0 | AI18: =+IFERROR(VLOOKUP($AI$16,Sheet1!V4:Y4,3,0),0) -> 0 | AJ18: =+IFERROR(VLOOKUP($AJ$16,Sheet1!V4:Y4,3,0),0) -> 0 | AK18: =+IFERROR(VLOOKUP($AK$16,Sheet1!V4:Y4,3,0),0) -> 0 | AL18: =+IFERROR(VLOOKUP($AL$16,Sheet1!V4:Y4,3,0),0) -> 26 | AM18: =+IFERROR(VLOOKUP($AM$16,Sheet1!V4:Y4,3,0),0) -> 0 | AN18: =+IFERROR(VLOOKUP($AN$16,Sheet1!V4:Y4,3,0),0) -> 0 | AO18: =+IFERROR(VLOOKUP($AO$16,Sheet1!V4:Y4,3,0),0) -> 0 | AP18: =+IFERROR(VLOOKUP($AP$16,Sheet1!V4:Y4,3,0),0) -> 0 | AQ18: =+IFERROR(VLOOKUP($AQ$16,Sheet1!Z4:AB4,3,0),0) -> 3 | AR18: =+IFERROR(VLOOKUP($AR$16,Sheet1!AD4:AG4,3,0),0) -> 0 | AS18: =+IFERROR(VLOOKUP($AS$16,Sheet1!AD4:AG4,3,0),0) -> 39 | AT18: =+IFERROR(VLOOKUP($AT$16,Sheet1!AD4:AG4,3,0),0) -> 0 | AU18: =+IFERROR(VLOOKUP($AU$16,Sheet1!AD4:AG4,3,0),0) -> 0 | AV18: =+IFERROR(VLOOKUP($AV$16,Sheet1!AD4:AG4,3,0),0) -> 0 | AW18: =+IFERROR(VLOOKUP($AW$16,Sheet1!AD4:AG4,3,0),0) -> 0 | AX18: =+IFERROR(VLOOKUP($AX$16,Sheet1!AD4:AG4,3,0),0) -> 0 | AY18: =+IFERROR(VLOOKUP($AY$16,Sheet1!AD4:AG4,3,0),0) -> 0 | AZ18: =+IFERROR(VLOOKUP($AZ$16,Sheet1!AD4:AG4,3,0),0) -> 0 | BA18: =+IFERROR(VLOOKUP($BA$16,Sheet1!AH4:AK4,3,0),0) -> 0 | BB18: =+IFERROR(VLOOKUP($BB$16,Sheet1!AH4:AK4,3,0),0) -> 0 | BC18: =+IFERROR(VLOOKUP($BC$16,Sheet1!AH4:AK4,3,0),0) -> 0 | BD18: =+IFERROR(VLOOKUP($BD$16,Sheet1!AH4:AK4,3,0),0) -> 0 | BE18: =+IFERROR(VLOOKUP($BE$16,Sheet1!AH4:AK4,3,0),0) -> 0 | BF18: =+IFERROR(VLOOKUP($BF$16,Sheet1!AH4:AK4,3,0),0) -> 0 | BG18: =+IFERROR(VLOOKUP($BG$16,Sheet1!AH4:AK4,3,0),0) -> 0 | BH18: =+IFERROR(VLOOKUP($BH$16,Sheet1!AH4:AK4,3,0),0) -> 0 | BI18: =+IFERROR(VLOOKUP($BI$16,Sheet1!AH4:AK4,3,0),0) -> 0 | BJ18: =+IFERROR(VLOOKUP($BJ$16,Sheet1!AH4:AK4,3,0),0) -> 251 | BK18: =+IFERROR(VLOOKUP($BK$16,Sheet1!AH4:AK4,3,0),0) -> 0 | BL18: =+IFERROR(VLOOKUP($BL$16,Sheet1!AL4:AO4,3,0),0) -> 0 | BM18: =+IFERROR(VLOOKUP($BM$16,Sheet1!AL4:AO4,3,0),0) -> 0 | BN18: =+IFERROR(VLOOKUP($BN$16,Sheet1!AL4:AO4,3,0),0) -> 0 | BO18: =+IFERROR(VLOOKUP($BO$16,Sheet1!AL4:AO4,3,0),0) -> 93 | BP18: =+IFERROR(VLOOKUP($BP$16,Sheet1!AL4:AO4,3,0),0) -> 0 | BQ18: =+IFERROR(VLOOKUP($BQ$16,Sheet1!AL4:AO4,3,0),0) -> 0 | BR18: =+IFERROR(VLOOKUP($BR$16,Sheet1!AL4:AO4,3,0),0) -> 0 | BS18: =+IFERROR(VLOOKUP($BS$16,Sheet1!AL4:AO4,3,0),0) -> 0 | BT18: =+IFERROR(VLOOKUP($BT$16,Sheet1!AL4:AO4,3,0),0) -> 0 | BU18: =+IFERROR(VLOOKUP($BU$16,Sheet1!AL4:AO4,3,0),0) -> 0 | BV18: =+IFERROR(VLOOKUP($BV$16,Sheet1!AL4:AO4,3,0),0) -> 0 | BW18: =+IFERROR(VLOOKUP($BW$16,Sheet1!AL4:AO4,3,0),0) -> 0 | BX18: =+IFERROR(VLOOKUP($BX$16,Sheet1!AP4:AS4,3,0),0) -> 0 | BY18: =+IFERROR(VLOOKUP($BY$16,Sheet1!AT4:AW4,3,0),0) -> 0 | BZ18: =+IFERROR(VLOOKUP($BZ$16,Sheet1!AX4:BA4,3,0),0) -> 0 | CA18: =+IFERROR(VLOOKUP($CA$16,Sheet1!BB4:BE4,3,0),0) -> 0 | CB18: =+IFERROR(VLOOKUP($CB$16,Sheet1!BF4:BI4,3,0),0) -> 0 | CC18: =+IFERROR(VLOOKUP($CC$16,Sheet1!BJ4:BM4,3,0),0) -> 0 | CD18: =+IFERROR(VLOOKUP($CD$16,Sheet1!BN4:BQ4,3,0),0) -> 0 | CE18: =+IFERROR(VLOOKUP($CE$16,Sheet1!BR4:BU4,3,0),0) -> 0 | CF18: =+IFERROR(VLOOKUP($CF$16,Sheet1!BV4:BY4,3,0),0) -> 0 | CG18: =Sheet1!E4 -> WOOD | CH18: =Sheet1!CX4 -> MD0100003 | CI18: =Sheet1!CY4 -> DRUM - 28 X 14 X 23 X 2 | CJ18: =Sheet1!CZ4 -> 500 | CK18: =Sheet1!BZ4 -> 4260 | CL18: =SUMPRODUCT($N$17:$CF$17,N18:CF18)+CK18 -> 80052 | CM18: =Sheet1!CB4 -> 0 | CN18: =CL18*CM18 -> 0 | CO18: 0.07 | CP18: =CL18*CO18 -> 5603.64 | CQ18: 0 | CR18: =CL18*CQ18 -> 0 | CS18: =CL18+CN18+CP18+CR18 -> 85655.64 | CT18: 0.02 | CU18: =CS18*CT18 -> 1713.1128 | CV18: 0.01 | CW18: =CS18*CV18 -> 856.5564 | CX18: =Sheet1!CM4 -> 0 | CY18: =CX18*CS18 -> 0
A19: =Sheet1!A5 -> ENQ-16531-25-26 | B19: 45839 | C19: =Sheet1!C5 -> FA0200011 | D19: =Sheet1!D5 -> 4 CORE X 2.5 SQ. MM. CU/ARD - WIRE (PVC) | E19: =CS19+CU19+CW19+CY19 -> 143036.05 | F19: =ROUNDUP(M35,0) -> 3560 | G19: =E19+F19 -> 146596.05 | H19: =Sheet1!CR5 -> 0.18 | I19: =G19*H19 -> 26387.289 | J19: =G19+I19 -> 172983.34 | K19: =Sheet1!CU5 -> 25 | L19: =Sheet1!CV5 -> KMS | M19: =J19*K19 -> 4324583.4 | N19: =+IFERROR(VLOOKUP($N$16,Sheet1!J5:L5,3,0),0) -> 0 | O19: =+IFERROR(VLOOKUP($O$16,Sheet1!J5:L5,3,0),0) -> 0 | P19: =+IFERROR(VLOOKUP($P$16,Sheet1!J5:M5,3,0),0) -> 89 | Q19: =+IFERROR(VLOOKUP($Q$16,Sheet1!J5:M5,3,0),0) -> 0 | R19: =+IFERROR(VLOOKUP($R$16,Sheet1!J5:M5,3,0),0) -> 0 | S19: =+IFERROR(VLOOKUP($S$16,Sheet1!J5:M5,3,0),0) -> 0 | T19: =+IFERROR(VLOOKUP($T$16,Sheet1!J5:M5,3,0),0) -> 0 | U19: =+IFERROR(VLOOKUP($U$16,Sheet1!J5:M5,3,0),0) -> 0 | V19: =+IFERROR(VLOOKUP($V$16,Sheet1!N5:Q5,3,0),0) -> 0 | W19: =+IFERROR(VLOOKUP($W$16,Sheet1!N5:Q5,3,0),0) -> 0 | X19: =+IFERROR(VLOOKUP($X$16,Sheet1!F5:I5,3,0),0) -> 0 | Y19: =+IFERROR(VLOOKUP($Y$16,Sheet1!F5:I5,3,0),0) -> 0 | Z19: =+IFERROR(VLOOKUP($Z$16,Sheet1!F5:I5,3,0),0) -> 0 | AA19: =+IFERROR(VLOOKUP($AA$16,Sheet1!F5:I5,3,0),0) -> 0 | AB19: =+IFERROR(VLOOKUP($AB$16,Sheet1!F5:I5,3,0),0) -> 0 | AC19: =+IFERROR(VLOOKUP($AC$16,Sheet1!F5:I5,3,0),0) -> 0 | AD19: =+IFERROR(VLOOKUP($AD$16,Sheet1!F5:I5,3,0),0) -> 0 | AE19: =+IFERROR(VLOOKUP($AE$16,Sheet1!F5:I5,3,0),0) -> 0 | AF19: =+IFERROR(VLOOKUP($AF$16,Sheet1!R5:U5,3,0),0) -> 0 | AG19: =+IFERROR(VLOOKUP($AG$16,Sheet1!R5:U5,3,0),0) -> 0 | AH19: =+IFERROR(VLOOKUP($AH$16,Sheet1!V5:Y5,3,0),0) -> 0 | AI19: =+IFERROR(VLOOKUP($AI$16,Sheet1!V5:Y5,3,0),0) -> 0 | AJ19: =+IFERROR(VLOOKUP($AJ$16,Sheet1!V5:Y5,3,0),0) -> 0 | AK19: =+IFERROR(VLOOKUP($AK$16,Sheet1!V5:Y5,3,0),0) -> 0 | AL19: =+IFERROR(VLOOKUP($AL$16,Sheet1!V5:Y5,3,0),0) -> 52 | AM19: =+IFERROR(VLOOKUP($AM$16,Sheet1!V5:Y5,3,0),0) -> 0 | AN19: =+IFERROR(VLOOKUP($AN$16,Sheet1!V5:Y5,3,0),0) -> 0 | AO19: =+IFERROR(VLOOKUP($AO$16,Sheet1!V5:Y5,3,0),0) -> 0 | AP19: =+IFERROR(VLOOKUP($AP$16,Sheet1!V5:Y5,3,0),0) -> 0 | AQ19: =+IFERROR(VLOOKUP($AQ$16,Sheet1!Z5:AB5,3,0),0) -> 3 | AR19: =+IFERROR(VLOOKUP($AR$16,Sheet1!AD5:AG5,3,0),0) -> 0 | AS19: =+IFERROR(VLOOKUP($AS$16,Sheet1!AD5:AG5,3,0),0) -> 27 | AT19: =+IFERROR(VLOOKUP($AT$16,Sheet1!AD5:AG5,3,0),0) -> 0 | AU19: =+IFERROR(VLOOKUP($AU$16,Sheet1!AD5:AG5,3,0),0) -> 0 | AV19: =+IFERROR(VLOOKUP($AV$16,Sheet1!AD5:AG5,3,0),0) -> 0 | AW19: =+IFERROR(VLOOKUP($AW$16,Sheet1!AD5:AG5,3,0),0) -> 0 | AX19: =+IFERROR(VLOOKUP($AX$16,Sheet1!AD5:AG5,3,0),0) -> 0 | AY19: =+IFERROR(VLOOKUP($AY$16,Sheet1!AD5:AG5,3,0),0) -> 0 | AZ19: =+IFERROR(VLOOKUP($AZ$16,Sheet1!AD5:AG5,3,0),0) -> 0 | BA19: =+IFERROR(VLOOKUP($BA$16,Sheet1!AH5:AK5,3,0),0) -> 0 | BB19: =+IFERROR(VLOOKUP($BB$16,Sheet1!AH5:AK5,3,0),0) -> 0 | BC19: =+IFERROR(VLOOKUP($BC$16,Sheet1!AH5:AK5,3,0),0) -> 0 | BD19: =+IFERROR(VLOOKUP($BD$16,Sheet1!AH5:AK5,3,0),0) -> 0 | BE19: =+IFERROR(VLOOKUP($BE$16,Sheet1!AH5:AK5,3,0),0) -> 0 | BF19: =+IFERROR(VLOOKUP($BF$16,Sheet1!AH5:AK5,3,0),0) -> 0 | BG19: =+IFERROR(VLOOKUP($BG$16,Sheet1!AH5:AK5,3,0),0) -> 0 | BH19: =+IFERROR(VLOOKUP($BH$16,Sheet1!AH5:AK5,3,0),0) -> 0 | BI19: =+IFERROR(VLOOKUP($BI$16,Sheet1!AH5:AK5,3,0),0) -> 0 | BJ19: =+IFERROR(VLOOKUP($BJ$16,Sheet1!AH5:AK5,3,0),0) -> 289 | BK19: =+IFERROR(VLOOKUP($BK$16,Sheet1!AH5:AK5,3,0),0) -> 0 | BL19: =+IFERROR(VLOOKUP($BL$16,Sheet1!AL5:AO5,3,0),0) -> 0 | BM19: =+IFERROR(VLOOKUP($BM$16,Sheet1!AL5:AO5,3,0),0) -> 0 | BN19: =+IFERROR(VLOOKUP($BN$16,Sheet1!AL5:AO5,3,0),0) -> 0 | BO19: =+IFERROR(VLOOKUP($BO$16,Sheet1!AL5:AO5,3,0),0) -> 104 | BP19: =+IFERROR(VLOOKUP($BP$16,Sheet1!AL5:AO5,3,0),0) -> 0 | BQ19: =+IFERROR(VLOOKUP($BQ$16,Sheet1!AL5:AO5,3,0),0) -> 0 | BR19: =+IFERROR(VLOOKUP($BR$16,Sheet1!AL5:AO5,3,0),0) -> 0 | BS19: =+IFERROR(VLOOKUP($BS$16,Sheet1!AL5:AO5,3,0),0) -> 0 | BT19: =+IFERROR(VLOOKUP($BT$16,Sheet1!AL5:AO5,3,0),0) -> 0 | BU19: =+IFERROR(VLOOKUP($BU$16,Sheet1!AL5:AO5,3,0),0) -> 0 | BV19: =+IFERROR(VLOOKUP($BV$16,Sheet1!AL5:AO5,3,0),0) -> 0 | BW19: =+IFERROR(VLOOKUP($BW$16,Sheet1!AL5:AO5,3,0),0) -> 0 | BX19: =+IFERROR(VLOOKUP($BX$16,Sheet1!AP5:AS5,3,0),0) -> 0 | BY19: =+IFERROR(VLOOKUP($BY$16,Sheet1!AT5:AW5,3,0),0) -> 0 | BZ19: =+IFERROR(VLOOKUP($BZ$16,Sheet1!AX5:BA5,3,0),0) -> 0 | CA19: =+IFERROR(VLOOKUP($CA$16,Sheet1!BB5:BE5,3,0),0) -> 0 | CB19: =+IFERROR(VLOOKUP($CB$16,Sheet1!BF5:BI5,3,0),0) -> 0 | CC19: =+IFERROR(VLOOKUP($CC$16,Sheet1!BJ5:BM5,3,0),0) -> 0 | CD19: =+IFERROR(VLOOKUP($CD$16,Sheet1!BN5:BQ5,3,0),0) -> 0 | CE19: =+IFERROR(VLOOKUP($CE$16,Sheet1!BR5:BU5,3,0),0) -> 0 | CF19: =+IFERROR(VLOOKUP($CF$16,Sheet1!BV5:BY5,3,0),0) -> 0 | CG19: =Sheet1!E5 -> WOOD | CH19: =Sheet1!CX5 -> MD0100005 | CI19: =Sheet1!CY5 -> DRUM - 36 X 14 X 23 X 2 | CJ19: =Sheet1!CZ5 -> 500 | CK19: =Sheet1!BZ5 -> 5170 | CL19: =SUMPRODUCT($N$17:$CF$17,N19:CF19)+CK19 -> 129785 | CM19: =Sheet1!CB5 -> 0 | CN19: =CL19*CM19 -> 0 | CO19: 0.07 | CP19: =CL19*CO19 -> 9084.95 | CQ19: 0 | CR19: =CL19*CQ19 -> 0 | CS19: =CL19+CN19+CP19+CR19 -> 138869.95 | CT19: 0.02 | CU19: =CS19*CT19 -> 2777.399 | CV19: 0.01 | CW19: =CS19*CV19 -> 1388.6995 | CX19: =Sheet1!CM5 -> 0 | CY19: =CX19*CS19 -> 0
A20: =Sheet1!A2 -> ENQ-16531-25-26 | B20: 45839 | C20: =Sheet1!C2 -> FA0200002 | D20: =Sheet1!D2 -> 10 CORE X 2.5 SQ. MM. CU/ARD - WIRE (PVC) | E20: =CS20+CU20+CW20+CY20 -> 317419.13 | F20: =ROUNDUP(M36,0) -> 3815 | G20: =E20+F20 -> 321234.13 | H20: =Sheet1!CR2 -> 0.18 | I20: =G20*H20 -> 57822.143 | J20: =G20+I20 -> 379056.27 | K20: =Sheet1!CU2 -> 35 | L20: =Sheet1!CV2 -> KMS | M20: =J20*K20 -> 13266969 | N20: =+IFERROR(VLOOKUP($N$16,Sheet1!J2:L2,3,0),0) -> 0 | O20: =+IFERROR(VLOOKUP($O$16,Sheet1!J2:L2,3,0),0) -> 0 | P20: =+IFERROR(VLOOKUP($P$16,Sheet1!J2:M2,3,0),0) -> 222 | Q20: =+IFERROR(VLOOKUP($Q$16,Sheet1!J2:M2,3,0),0) -> 0 | R20: =+IFERROR(VLOOKUP($R$16,Sheet1!J2:M2,3,0),0) -> 0 | S20: =+IFERROR(VLOOKUP($S$16,Sheet1!J2:M2,3,0),0) -> 0 | T20: =+IFERROR(VLOOKUP($T$16,Sheet1!J2:M2,3,0),0) -> 0 | U20: =+IFERROR(VLOOKUP($U$16,Sheet1!J2:M2,3,0),0) -> 0 | V20: =+IFERROR(VLOOKUP($V$16,Sheet1!N2:Q2,3,0),0) -> 0 | W20: =+IFERROR(VLOOKUP($W$16,Sheet1!N2:Q2,3,0),0) -> 0 | X20: =+IFERROR(VLOOKUP($X$16,Sheet1!F2:I2,3,0),0) -> 0 | Y20: =+IFERROR(VLOOKUP($Y$16,Sheet1!F2:I2,3,0),0) -> 0 | Z20: =+IFERROR(VLOOKUP($Z$16,Sheet1!F2:I2,3,0),0) -> 0 | AA20: =+IFERROR(VLOOKUP($AA$16,Sheet1!F2:I2,3,0),0) -> 0 | AB20: =+IFERROR(VLOOKUP($AB$16,Sheet1!F2:I2,3,0),0) -> 0 | AC20: =+IFERROR(VLOOKUP($AC$16,Sheet1!F2:I2,3,0),0) -> 0 | AD20: =+IFERROR(VLOOKUP($AD$16,Sheet1!F2:I2,3,0),0) -> 0 | AE20: =+IFERROR(VLOOKUP($AE$16,Sheet1!F2:I2,3,0),0) -> 0 | AF20: =+IFERROR(VLOOKUP($AF$16,Sheet1!R2:U2,3,0),0) -> 0 | AG20: =+IFERROR(VLOOKUP($AG$16,Sheet1!R2:U2,3,0),0) -> 0 | AH20: =+IFERROR(VLOOKUP($AH$16,Sheet1!V2:Y2,3,0),0) -> 0 | AI20: =+IFERROR(VLOOKUP($AI$16,Sheet1!V2:Y2,3,0),0) -> 0 | AJ20: =+IFERROR(VLOOKUP($AJ$16,Sheet1!V2:Y2,3,0),0) -> 0 | AK20: =+IFERROR(VLOOKUP($AK$16,Sheet1!V2:Y2,3,0),0) -> 0 | AL20: =+IFERROR(VLOOKUP($AL$16,Sheet1!V2:Y2,3,0),0) -> 130 | AM20: =+IFERROR(VLOOKUP($AM$16,Sheet1!V2:Y2,3,0),0) -> 0 | AN20: =+IFERROR(VLOOKUP($AN$16,Sheet1!V2:Y2,3,0),0) -> 0 | AO20: =+IFERROR(VLOOKUP($AO$16,Sheet1!V2:Y2,3,0),0) -> 0 | AP20: =+IFERROR(VLOOKUP($AP$16,Sheet1!V2:Y2,3,0),0) -> 0 | AQ20: =+IFERROR(VLOOKUP($AQ$16,Sheet1!Z2:AB2,3,0),0) -> 5 | AR20: =+IFERROR(VLOOKUP($AR$16,Sheet1!AD2:AG2,3,0),0) -> 0 | AS20: =+IFERROR(VLOOKUP($AS$16,Sheet1!AD2:AG2,3,0),0) -> 38 | AT20: =+IFERROR(VLOOKUP($AT$16,Sheet1!AD2:AG2,3,0),0) -> 0 | AU20: =+IFERROR(VLOOKUP($AU$16,Sheet1!AD2:AG2,3,0),0) -> 0 | AV20: =+IFERROR(VLOOKUP($AV$16,Sheet1!AD2:AG2,3,0),0) -> 0 | AW20: =+IFERROR(VLOOKUP($AW$16,Sheet1!AD2:AG2,3,0),0) -> 0 | AX20: =+IFERROR(VLOOKUP($AX$16,Sheet1!AD2:AG2,3,0),0) -> 0 | AY20: =+IFERROR(VLOOKUP($AY$16,Sheet1!AD2:AG2,3,0),0) -> 0 | AZ20: =+IFERROR(VLOOKUP($AZ$16,Sheet1!AD2:AG2,3,0),0) -> 0 | BA20: =+IFERROR(VLOOKUP($BA$16,Sheet1!AH2:AK2,3,0),0) -> 0 | BB20: =+IFERROR(VLOOKUP($BB$16,Sheet1!AH2:AK2,3,0),0) -> 0 | BC20: =+IFERROR(VLOOKUP($BC$16,Sheet1!AH2:AK2,3,0),0) -> 0 | BD20: =+IFERROR(VLOOKUP($BD$16,Sheet1!AH2:AK2,3,0),0) -> 0 | BE20: =+IFERROR(VLOOKUP($BE$16,Sheet1!AH2:AK2,3,0),0) -> 0 | BF20: =+IFERROR(VLOOKUP($BF$16,Sheet1!AH2:AK2,3,0),0) -> 0 | BG20: =+IFERROR(VLOOKUP($BG$16,Sheet1!AH2:AK2,3,0),0) -> 0 | BH20: =+IFERROR(VLOOKUP($BH$16,Sheet1!AH2:AK2,3,0),0) -> 0 | BI20: =+IFERROR(VLOOKUP($BI$16,Sheet1!AH2:AK2,3,0),0) -> 0 | BJ20: =+IFERROR(VLOOKUP($BJ$16,Sheet1!AH2:AK2,3,0),0) -> 492 | BK20: =+IFERROR(VLOOKUP($BK$16,Sheet1!AH2:AK2,3,0),0) -> 0 | BL20: =+IFERROR(VLOOKUP($BL$16,Sheet1!AL2:AO2,3,0),0) -> 0 | BM20: =+IFERROR(VLOOKUP($BM$16,Sheet1!AL2:AO2,3,0),0) -> 0 | BN20: =+IFERROR(VLOOKUP($BN$16,Sheet1!AL2:AO2,3,0),0) -> 0 | BO20: =+IFERROR(VLOOKUP($BO$16,Sheet1!AL2:AO2,3,0),0) -> 166 | BP20: =+IFERROR(VLOOKUP($BP$16,Sheet1!AL2:AO2,3,0),0) -> 0 | BQ20: =+IFERROR(VLOOKUP($BQ$16,Sheet1!AL2:AO2,3,0),0) -> 0 | BR20: =+IFERROR(VLOOKUP($BR$16,Sheet1!AL2:AO2,3,0),0) -> 0 | BS20: =+IFERROR(VLOOKUP($BS$16,Sheet1!AL2:AO2,3,0),0) -> 0 | BT20: =+IFERROR(VLOOKUP($BT$16,Sheet1!AL2:AO2,3,0),0) -> 0 | BU20: =+IFERROR(VLOOKUP($BU$16,Sheet1!AL2:AO2,3,0),0) -> 0 | BV20: =+IFERROR(VLOOKUP($BV$16,Sheet1!AL2:AO2,3,0),0) -> 0 | BW20: =+IFERROR(VLOOKUP($BW$16,Sheet1!AL2:AO2,3,0),0) -> 0 | BX20: =+IFERROR(VLOOKUP($BX$16,Sheet1!AP2:AS2,3,0),0) -> 0 | BY20: =+IFERROR(VLOOKUP($BY$16,Sheet1!AT2:AW2,3,0),0) -> 0 | BZ20: =+IFERROR(VLOOKUP($BZ$16,Sheet1!AX2:BA2,3,0),0) -> 0 | CA20: =+IFERROR(VLOOKUP($CA$16,Sheet1!BB2:BE2,3,0),0) -> 0 | CB20: =+IFERROR(VLOOKUP($CB$16,Sheet1!BF2:BI2,3,0),0) -> 0 | CC20: =+IFERROR(VLOOKUP($CC$16,Sheet1!BJ2:BM2,3,0),0) -> 0 | CD20: =+IFERROR(VLOOKUP($CD$16,Sheet1!BN2:BQ2,3,0),0) -> 0 | CE20: =+IFERROR(VLOOKUP($CE$16,Sheet1!BR2:BU2,3,0),0) -> 0 | CF20: =+IFERROR(VLOOKUP($CF$16,Sheet1!BV2:BY2,3,0),0) -> 0 | CG20: =Sheet1!E2 -> WOOD | CH20: =Sheet1!CX2 -> MD0100066 | CI20: =Sheet1!CY2 -> DRUM - 40 X 15 X 23 X 2 | CJ20: =Sheet1!CZ2 -> 500 | CK20: =Sheet1!BZ2 -> 5448 | CL20: =SUMPRODUCT($N$17:$CF$17,N20:CF20)+CK20 -> 288013 | CM20: =Sheet1!CB2 -> 0 | CN20: =CL20*CM20 -> 0 | CO20: 0.07 | CP20: =CL20*CO20 -> 20160.91 | CQ20: 0 | CR20: =CL20*CQ20 -> 0 | CS20: =CL20+CN20+CP20+CR20 -> 308173.91 | CT20: 0.02 | CU20: =CS20*CT20 -> 6163.4782 | CV20: 0.01 | CW20: =CS20*CV20 -> 3081.7391 | CX20: =Sheet1!CM2 -> 0 | CY20: =CX20*CS20 -> 0
A21: =Sheet1!A3 -> ENQ-16531-25-26 | B21: 45839 | C21: =Sheet1!C3 -> FA0200003 | D21: =Sheet1!D3 -> 12 CORE X 2.5 SQ. MM. CU/ARD - WIRE (PVC) | E21: =CS21+CU21+CW21+CY21 -> 368996.31 | F21: =ROUNDUP(M37,0) -> 5086 | G21: =E21+F21 -> 374082.31 | H21: =Sheet1!CR3 -> 0.18 | I21: =G21*H21 -> 67334.815 | J21: =G21+I21 -> 441417.12 | K21: =Sheet1!CU3 -> 35 | L21: =Sheet1!CV3 -> KMS | M21: =J21*K21 -> 15449599 | N21: =+IFERROR(VLOOKUP($N$16,Sheet1!J3:L3,3,0),0) -> 0 | O21: =+IFERROR(VLOOKUP($O$16,Sheet1!J3:L3,3,0),0) -> 0 | P21: =+IFERROR(VLOOKUP($P$16,Sheet1!J3:M3,3,0),0) -> 266 | Q21: =+IFERROR(VLOOKUP($Q$16,Sheet1!J3:M3,3,0),0) -> 0 | R21: =+IFERROR(VLOOKUP($R$16,Sheet1!J3:M3,3,0),0) -> 0 | S21: =+IFERROR(VLOOKUP($S$16,Sheet1!J3:M3,3,0),0) -> 0 | T21: =+IFERROR(VLOOKUP($T$16,Sheet1!J3:M3,3,0),0) -> 0 | U21: =+IFERROR(VLOOKUP($U$16,Sheet1!J3:M3,3,0),0) -> 0 | V21: =+IFERROR(VLOOKUP($V$16,Sheet1!N3:Q3,3,0),0) -> 0 | W21: =+IFERROR(VLOOKUP($W$16,Sheet1!N3:Q3,3,0),0) -> 0 | X21: =+IFERROR(VLOOKUP($X$16,Sheet1!F3:I3,3,0),0) -> 0 | Y21: =+IFERROR(VLOOKUP($Y$16,Sheet1!F3:I3,3,0),0) -> 0 | Z21: =+IFERROR(VLOOKUP($Z$16,Sheet1!F3:I3,3,0),0) -> 0 | AA21: =+IFERROR(VLOOKUP($AA$16,Sheet1!F3:I3,3,0),0) -> 0 | AB21: =+IFERROR(VLOOKUP($AB$16,Sheet1!F3:I3,3,0),0) -> 0 | AC21: =+IFERROR(VLOOKUP($AC$16,Sheet1!F3:I3,3,0),0) -> 0 | AD21: =+IFERROR(VLOOKUP($AD$16,Sheet1!F3:I3,3,0),0) -> 0 | AE21: =+IFERROR(VLOOKUP($AE$16,Sheet1!F3:I3,3,0),0) -> 0 | AF21: =+IFERROR(VLOOKUP($AF$16,Sheet1!R3:U3,3,0),0) -> 0 | AG21: =+IFERROR(VLOOKUP($AG$16,Sheet1!R3:U3,3,0),0) -> 0 | AH21: =+IFERROR(VLOOKUP($AH$16,Sheet1!V3:Y3,3,0),0) -> 0 | AI21: =+IFERROR(VLOOKUP($AI$16,Sheet1!V3:Y3,3,0),0) -> 0 | AJ21: =+IFERROR(VLOOKUP($AJ$16,Sheet1!V3:Y3,3,0),0) -> 0 | AK21: =+IFERROR(VLOOKUP($AK$16,Sheet1!V3:Y3,3,0),0) -> 0 | AL21: =+IFERROR(VLOOKUP($AL$16,Sheet1!V3:Y3,3,0),0) -> 156 | AM21: =+IFERROR(VLOOKUP($AM$16,Sheet1!V3:Y3,3,0),0) -> 0 | AN21: =+IFERROR(VLOOKUP($AN$16,Sheet1!V3:Y3,3,0),0) -> 0 | AO21: =+IFERROR(VLOOKUP($AO$16,Sheet1!V3:Y3,3,0),0) -> 0 | AP21: =+IFERROR(VLOOKUP($AP$16,Sheet1!V3:Y3,3,0),0) -> 0 | AQ21: =+IFERROR(VLOOKUP($AQ$16,Sheet1!Z3:AB3,3,0),0) -> 6 | AR21: =+IFERROR(VLOOKUP($AR$16,Sheet1!AD3:AG3,3,0),0) -> 0 | AS21: =+IFERROR(VLOOKUP($AS$16,Sheet1!AD3:AG3,3,0),0) -> 40 | AT21: =+IFERROR(VLOOKUP($AT$16,Sheet1!AD3:AG3,3,0),0) -> 0 | AU21: =+IFERROR(VLOOKUP($AU$16,Sheet1!AD3:AG3,3,0),0) -> 0 | AV21: =+IFERROR(VLOOKUP($AV$16,Sheet1!AD3:AG3,3,0),0) -> 0 | AW21: =+IFERROR(VLOOKUP($AW$16,Sheet1!AD3:AG3,3,0),0) -> 0 | AX21: =+IFERROR(VLOOKUP($AX$16,Sheet1!AD3:AG3,3,0),0) -> 0 | AY21: =+IFERROR(VLOOKUP($AY$16,Sheet1!AD3:AG3,3,0),0) -> 0 | AZ21: =+IFERROR(VLOOKUP($AZ$16,Sheet1!AD3:AG3,3,0),0) -> 0 | BA21: =+IFERROR(VLOOKUP($BA$16,Sheet1!AH3:AK3,3,0),0) -> 0 | BB21: =+IFERROR(VLOOKUP($BB$16,Sheet1!AH3:AK3,3,0),0) -> 0 | BC21: =+IFERROR(VLOOKUP($BC$16,Sheet1!AH3:AK3,3,0),0) -> 0 | BD21: =+IFERROR(VLOOKUP($BD$16,Sheet1!AH3:AK3,3,0),0) -> 0 | BE21: =+IFERROR(VLOOKUP($BE$16,Sheet1!AH3:AK3,3,0),0) -> 0 | BF21: =+IFERROR(VLOOKUP($BF$16,Sheet1!AH3:AK3,3,0),0) -> 0 | BG21: =+IFERROR(VLOOKUP($BG$16,Sheet1!AH3:AK3,3,0),0) -> 0 | BH21: =+IFERROR(VLOOKUP($BH$16,Sheet1!AH3:AK3,3,0),0) -> 0 | BI21: =+IFERROR(VLOOKUP($BI$16,Sheet1!AH3:AK3,3,0),0) -> 0 | BJ21: =+IFERROR(VLOOKUP($BJ$16,Sheet1!AH3:AK3,3,0),0) -> 508 | BK21: =+IFERROR(VLOOKUP($BK$16,Sheet1!AH3:AK3,3,0),0) -> 0 | BL21: =+IFERROR(VLOOKUP($BL$16,Sheet1!AL3:AO3,3,0),0) -> 0 | BM21: =+IFERROR(VLOOKUP($BM$16,Sheet1!AL3:AO3,3,0),0) -> 0 | BN21: =+IFERROR(VLOOKUP($BN$16,Sheet1!AL3:AO3,3,0),0) -> 0 | BO21: =+IFERROR(VLOOKUP($BO$16,Sheet1!AL3:AO3,3,0),0) -> 170 | BP21: =+IFERROR(VLOOKUP($BP$16,Sheet1!AL3:AO3,3,0),0) -> 0 | BQ21: =+IFERROR(VLOOKUP($BQ$16,Sheet1!AL3:AO3,3,0),0) -> 0 | BR21: =+IFERROR(VLOOKUP($BR$16,Sheet1!AL3:AO3,3,0),0) -> 0 | BS21: =+IFERROR(VLOOKUP($BS$16,Sheet1!AL3:AO3,3,0),0) -> 0 | BT21: =+IFERROR(VLOOKUP($BT$16,Sheet1!AL3:AO3,3,0),0) -> 0 | BU21: =+IFERROR(VLOOKUP($BU$16,Sheet1!AL3:AO3,3,0),0) -> 0 | BV21: =+IFERROR(VLOOKUP($BV$16,Sheet1!AL3:AO3,3,0),0) -> 0 | BW21: =+IFERROR(VLOOKUP($BW$16,Sheet1!AL3:AO3,3,0),0) -> 0 | BX21: =+IFERROR(VLOOKUP($BX$16,Sheet1!AP3:AS3,3,0),0) -> 0 | BY21: =+IFERROR(VLOOKUP($BY$16,Sheet1!AT3:AW3,3,0),0) -> 0 | BZ21: =+IFERROR(VLOOKUP($BZ$16,Sheet1!AX3:BA3,3,0),0) -> 0 | CA21: =+IFERROR(VLOOKUP($CA$16,Sheet1!BB3:BE3,3,0),0) -> 0 | CB21: =+IFERROR(VLOOKUP($CB$16,Sheet1!BF3:BI3,3,0),0) -> 0 | CC21: =+IFERROR(VLOOKUP($CC$16,Sheet1!BJ3:BM3,3,0),0) -> 0 | CD21: =+IFERROR(VLOOKUP($CD$16,Sheet1!BN3:BQ3,3,0),0) -> 0 | CE21: =+IFERROR(VLOOKUP($CE$16,Sheet1!BR3:BU3,3,0),0) -> 0 | CF21: =+IFERROR(VLOOKUP($CF$16,Sheet1!BV3:BY3,3,0),0) -> 0 | CG21: =Sheet1!E3 -> WOOD | CH21: =Sheet1!CX3 -> MD0100066 | CI21: =Sheet1!CY3 -> DRUM - 40 X 15 X 23 X 2 | CJ21: =Sheet1!CZ3 -> 500 | CK21: =Sheet1!BZ3 -> 5448 | CL21: =SUMPRODUCT($N$17:$CF$17,N21:CF21)+CK21 -> 334812 | CM21: =Sheet1!CB3 -> 0 | CN21: =CL21*CM21 -> 0 | CO21: 0.07 | CP21: =CL21*CO21 -> 23436.84 | CQ21: 0 | CR21: =CL21*CQ21 -> 0 | CS21: =CL21+CN21+CP21+CR21 -> 358248.84 | CT21: 0.02 | CU21: =CS21*CT21 -> 7164.9768 | CV21: 0.01 | CW21: =CS21*CV21 -> 3582.4884 | CX21: =Sheet1!CM3 -> 0 | CY21: =CX21*CS21 -> 0
A22: =Sheet1!A6 -> 0 | B22: =Sheet1!B6 -> 0 | C22: =Sheet1!C6 -> 0 | D22: =Sheet1!D6 -> 0 | E22: =CS22+CU22+CW22+CY22 -> 0 | F22: =Sheet1!CP6 -> 0 | G22: =E22+F22 -> 0 | H22: =Sheet1!CR6 -> 0 | I22: =G22*H22 -> 0 | J22: =G22+I22 -> 0 | K22: =Sheet1!CU6 -> 0 | L22: =Sheet1!CV6 -> 0 | M22: =J22*K22 -> 0 | N22: =+IFERROR(VLOOKUP($N$16,Sheet1!J6:L6,3,0),0) -> 0 | O22: =+IFERROR(VLOOKUP($O$16,Sheet1!J6:L6,3,0),0) -> 0 | P22: =+IFERROR(VLOOKUP($P$16,Sheet1!J6:M6,3,0),0) -> 0 | Q22: =+IFERROR(VLOOKUP($Q$16,Sheet1!J6:M6,3,0),0) -> 0 | R22: =+IFERROR(VLOOKUP($R$16,Sheet1!J6:M6,3,0),0) -> 0 | S22: =+IFERROR(VLOOKUP($S$16,Sheet1!J6:M6,3,0),0) -> 0 | T22: =+IFERROR(VLOOKUP($T$16,Sheet1!J6:M6,3,0),0) -> 0 | U22: =+IFERROR(VLOOKUP($U$16,Sheet1!J6:M6,3,0),0) -> 0 | V22: =+IFERROR(VLOOKUP($V$16,Sheet1!N6:Q6,3,0),0) -> 0 | W22: =+IFERROR(VLOOKUP($W$16,Sheet1!N6:Q6,3,0),0) -> 0 | X22: =+IFERROR(VLOOKUP($X$16,Sheet1!F6:I6,3,0),0) -> 0 | Y22: =+IFERROR(VLOOKUP($Y$16,Sheet1!F6:I6,3,0),0) -> 0 | Z22: =+IFERROR(VLOOKUP($Z$16,Sheet1!F6:I6,3,0),0) -> 0 | AA22: =+IFERROR(VLOOKUP($AA$16,Sheet1!F6:I6,3,0),0) -> 0 | AB22: =+IFERROR(VLOOKUP($AB$16,Sheet1!F6:I6,3,0),0) -> 0 | AC22: =+IFERROR(VLOOKUP($AC$16,Sheet1!F6:I6,3,0),0) -> 0 | AD22: =+IFERROR(VLOOKUP($AD$16,Sheet1!F6:I6,3,0),0) -> 0 | AE22: =+IFERROR(VLOOKUP($AE$16,Sheet1!F6:I6,3,0),0) -> 0 | AF22: =+IFERROR(VLOOKUP($AF$16,Sheet1!R6:U6,3,0),0) -> 0 | AG22: =+IFERROR(VLOOKUP($AG$16,Sheet1!R6:U6,3,0),0) -> 0 | AH22: =+IFERROR(VLOOKUP($AH$16,Sheet1!V6:Y6,3,0),0) -> 0 | AI22: =+IFERROR(VLOOKUP($AI$16,Sheet1!V6:Y6,3,0),0) -> 0 | AJ22: =+IFERROR(VLOOKUP($AJ$16,Sheet1!V6:Y6,3,0),0) -> 0 | AK22: =+IFERROR(VLOOKUP($AK$16,Sheet1!V6:Y6,3,0),0) -> 0 | AL22: =+IFERROR(VLOOKUP($AL$16,Sheet1!V6:Y6,3,0),0) -> 0 | AM22: =+IFERROR(VLOOKUP($AM$16,Sheet1!V6:Y6,3,0),0) -> 0 | AN22: =+IFERROR(VLOOKUP($AN$16,Sheet1!V6:Y6,3,0),0) -> 0 | AO22: =+IFERROR(VLOOKUP($AO$16,Sheet1!V6:Y6,3,0),0) -> 0 | AP22: =+IFERROR(VLOOKUP($AP$16,Sheet1!V6:Y6,3,0),0) -> 0 | AQ22: =+IFERROR(VLOOKUP($AQ$16,Sheet1!Z6:AB6,3,0),0) -> 0 | AR22: =+IFERROR(VLOOKUP($AR$16,Sheet1!AD6:AG6,3,0),0) -> 0 | AS22: =+IFERROR(VLOOKUP($AS$16,Sheet1!AD6:AG6,3,0),0) -> 0 | AT22: =+IFERROR(VLOOKUP($AT$16,Sheet1!AD6:AG6,3,0),0) -> 0 | AU22: =+IFERROR(VLOOKUP($AU$16,Sheet1!AD6:AG6,3,0),0) -> 0 | AV22: =+IFERROR(VLOOKUP($AV$16,Sheet1!AD6:AG6,3,0),0) -> 0 | AW22: =+IFERROR(VLOOKUP($AW$16,Sheet1!AD6:AG6,3,0),0) -> 0 | AX22: =+IFERROR(VLOOKUP($AX$16,Sheet1!AD6:AG6,3,0),0) -> 0 | AY22: =+IFERROR(VLOOKUP($AY$16,Sheet1!AD6:AG6,3,0),0) -> 0 | AZ22: =+IFERROR(VLOOKUP($AZ$16,Sheet1!AD6:AG6,3,0),0) -> 0 | BA22: =+IFERROR(VLOOKUP($BA$16,Sheet1!AH6:AK6,3,0),0) -> 0 | BB22: =+IFERROR(VLOOKUP($BB$16,Sheet1!AH6:AK6,3,0),0) -> 0 | BC22: =+IFERROR(VLOOKUP($BC$16,Sheet1!AH6:AK6,3,0),0) -> 0 | BD22: =+IFERROR(VLOOKUP($BD$16,Sheet1!AH6:AK6,3,0),0) -> 0 | BE22: =+IFERROR(VLOOKUP($BE$16,Sheet1!AH6:AK6,3,0),0) -> 0 | BF22: =+IFERROR(VLOOKUP($BF$16,Sheet1!AH6:AK6,3,0),0) -> 0 | BG22: =+IFERROR(VLOOKUP($BG$16,Sheet1!AH6:AK6,3,0),0) -> 0 | BH22: =+IFERROR(VLOOKUP($BH$16,Sheet1!AH6:AK6,3,0),0) -> 0 | BI22: =+IFERROR(VLOOKUP($BI$16,Sheet1!AH6:AK6,3,0),0) -> 0 | BJ22: =+IFERROR(VLOOKUP($BJ$16,Sheet1!AH6:AK6,3,0),0) -> 0 | BK22: =+IFERROR(VLOOKUP($BK$16,Sheet1!AH6:AK6,3,0),0) -> 0 | BL22: =+IFERROR(VLOOKUP($BL$16,Sheet1!AL6:AO6,3,0),0) -> 0 | BM22: =+IFERROR(VLOOKUP($BM$16,Sheet1!AL6:AO6,3,0),0) -> 0 | BN22: =+IFERROR(VLOOKUP($BN$16,Sheet1!AL6:AO6,3,0),0) -> 0 | BO22: =+IFERROR(VLOOKUP($BO$16,Sheet1!AL6:AO6,3,0),0) -> 0 | BP22: =+IFERROR(VLOOKUP($BP$16,Sheet1!AL6:AO6,3,0),0) -> 0 | BQ22: =+IFERROR(VLOOKUP($BQ$16,Sheet1!AL6:AO6,3,0),0) -> 0 | BR22: =+IFERROR(VLOOKUP($BR$16,Sheet1!AL6:AO6,3,0),0) -> 0 | BS22: =+IFERROR(VLOOKUP($BS$16,Sheet1!AL6:AO6,3,0),0) -> 0 | BT22: =+IFERROR(VLOOKUP($BT$16,Sheet1!AL6:AO6,3,0),0) -> 0 | BU22: =+IFERROR(VLOOKUP($BU$16,Sheet1!AL6:AO6,3,0),0) -> 0 | BV22: =+IFERROR(VLOOKUP($BV$16,Sheet1!AL6:AO6,3,0),0) -> 0 | BW22: =+IFERROR(VLOOKUP($BW$16,Sheet1!AL6:AO6,3,0),0) -> 0 | BX22: =+IFERROR(VLOOKUP($BX$16,Sheet1!AP6:AS6,3,0),0) -> 0 | BY22: =+IFERROR(VLOOKUP($BY$16,Sheet1!AT6:AW6,3,0),0) -> 0 | BZ22: =+IFERROR(VLOOKUP($BZ$16,Sheet1!AX6:BA6,3,0),0) -> 0 | CA22: =+IFERROR(VLOOKUP($CA$16,Sheet1!BB6:BE6,3,0),0) -> 0 | CB22: =+IFERROR(VLOOKUP($CB$16,Sheet1!BF6:BI6,3,0),0) -> 0 | CC22: =+IFERROR(VLOOKUP($CC$16,Sheet1!BJ6:BM6,3,0),0) -> 0 | CD22: =+IFERROR(VLOOKUP($CD$16,Sheet1!BN6:BQ6,3,0),0) -> 0 | CE22: =+IFERROR(VLOOKUP($CE$16,Sheet1!BR6:BU6,3,0),0) -> 0 | CF22: =+IFERROR(VLOOKUP($CF$16,Sheet1!BV6:BY6,3,0),0) -> 0 | CG22: =Sheet1!E6 -> 0 | CH22: =Sheet1!CX6 -> 0 | CI22: =Sheet1!CY6 -> 0 | CJ22: =Sheet1!CZ6 -> 0 | CK22: =Sheet1!BZ6 -> 0 | CL22: =SUMPRODUCT($N$17:$CF$17,N22:CF22)+CK22 -> 0 | CM22: =Sheet1!CB6 -> 0 | CN22: =CL22*CM22 -> 0 | CO22: =Sheet1!CD6 -> 0 | CP22: =CL22*CO22 -> 0 | CQ22: =Sheet1!CF6 -> 0 | CR22: =CL22*CQ22 -> 0 | CS22: =CL22+CN22+CP22+CR22 -> 0 | CT22: =Sheet1!CI6 -> 0 | CU22: =CS22*CT22 -> 0 | CV22: =Sheet1!CK6 -> 0 | CW22: =CS22*CV22 -> 0 | CX22: =Sheet1!CM6 -> 0 | CY22: =CX22*CS22 -> 0
A23: =Sheet1!A7 -> 0 | B23: =Sheet1!B7 -> 0 | C23: =Sheet1!C7 -> 0 | D23: =Sheet1!D7 -> 0 | E23: =CS23+CU23+CW23+CY23 -> 0 | F23: =Sheet1!CP7 -> 0 | G23: =E23+F23 -> 0 | H23: =Sheet1!CR7 -> 0 | I23: =G23*H23 -> 0 | J23: =G23+I23 -> 0 | K23: =Sheet1!CU7 -> 0 | L23: =Sheet1!CV7 -> 0 | M23: =J23*K23 -> 0 | N23: =+IFERROR(VLOOKUP($N$16,Sheet1!J7:L7,3,0),0) -> 0 | O23: =+IFERROR(VLOOKUP($O$16,Sheet1!J7:L7,3,0),0) -> 0 | P23: =+IFERROR(VLOOKUP($P$16,Sheet1!J7:M7,3,0),0) -> 0 | Q23: =+IFERROR(VLOOKUP($Q$16,Sheet1!J7:M7,3,0),0) -> 0 | R23: =+IFERROR(VLOOKUP($R$16,Sheet1!J7:M7,3,0),0) -> 0 | S23: =+IFERROR(VLOOKUP($S$16,Sheet1!J7:M7,3,0),0) -> 0 | T23: =+IFERROR(VLOOKUP($T$16,Sheet1!J7:M7,3,0),0) -> 0 | U23: =+IFERROR(VLOOKUP($U$16,Sheet1!J7:M7,3,0),0) -> 0 | V23: =+IFERROR(VLOOKUP($V$16,Sheet1!N7:Q7,3,0),0) -> 0 | W23: =+IFERROR(VLOOKUP($W$16,Sheet1!N7:Q7,3,0),0) -> 0 | X23: =+IFERROR(VLOOKUP($X$16,Sheet1!F7:I7,3,0),0) -> 0 | Y23: =+IFERROR(VLOOKUP($Y$16,Sheet1!F7:I7,3,0),0) -> 0 | Z23: =+IFERROR(VLOOKUP($Z$16,Sheet1!F7:I7,3,0),0) -> 0 | AA23: =+IFERROR(VLOOKUP($AA$16,Sheet1!F7:I7,3,0),0) -> 0 | AB23: =+IFERROR(VLOOKUP($AB$16,Sheet1!F7:I7,3,0),0) -> 0 | AC23: =+IFERROR(VLOOKUP($AC$16,Sheet1!F7:I7,3,0),0) -> 0 | AD23: =+IFERROR(VLOOKUP($AD$16,Sheet1!F7:I7,3,0),0) -> 0 | AE23: =+IFERROR(VLOOKUP($AE$16,Sheet1!F7:I7,3,0),0) -> 0 | AF23: =+IFERROR(VLOOKUP($AF$16,Sheet1!R7:U7,3,0),0) -> 0 | AG23: =+IFERROR(VLOOKUP($AG$16,Sheet1!R7:U7,3,0),0) -> 0 | AH23: =+IFERROR(VLOOKUP($AH$16,Sheet1!V7:Y7,3,0),0) -> 0 | AI23: =+IFERROR(VLOOKUP($AI$16,Sheet1!V7:Y7,3,0),0) -> 0 | AJ23: =+IFERROR(VLOOKUP($AJ$16,Sheet1!V7:Y7,3,0),0) -> 0 | AK23: =+IFERROR(VLOOKUP($AK$16,Sheet1!V7:Y7,3,0),0) -> 0 | AL23: =+IFERROR(VLOOKUP($AL$16,Sheet1!V7:Y7,3,0),0) -> 0 | AM23: =+IFERROR(VLOOKUP($AM$16,Sheet1!V7:Y7,3,0),0) -> 0 | AN23: =+IFERROR(VLOOKUP($AN$16,Sheet1!V7:Y7,3,0),0) -> 0 | AO23: =+IFERROR(VLOOKUP($AO$16,Sheet1!V7:Y7,3,0),0) -> 0 | AP23: =+IFERROR(VLOOKUP($AP$16,Sheet1!V7:Y7,3,0),0) -> 0 | AQ23: =+IFERROR(VLOOKUP($AQ$16,Sheet1!Z7:AB7,3,0),0) -> 0 | AR23: =+IFERROR(VLOOKUP($AR$16,Sheet1!AD7:AG7,3,0),0) -> 0 | AS23: =+IFERROR(VLOOKUP($AS$16,Sheet1!AD7:AG7,3,0),0) -> 0 | AT23: =+IFERROR(VLOOKUP($AT$16,Sheet1!AD7:AG7,3,0),0) -> 0 | AU23: =+IFERROR(VLOOKUP($AU$16,Sheet1!AD7:AG7,3,0),0) -> 0 | AV23: =+IFERROR(VLOOKUP($AV$16,Sheet1!AD7:AG7,3,0),0) -> 0 | AW23: =+IFERROR(VLOOKUP($AW$16,Sheet1!AD7:AG7,3,0),0) -> 0 | AX23: =+IFERROR(VLOOKUP($AX$16,Sheet1!AD7:AG7,3,0),0) -> 0 | AY23: =+IFERROR(VLOOKUP($AY$16,Sheet1!AD7:AG7,3,0),0) -> 0 | AZ23: =+IFERROR(VLOOKUP($AZ$16,Sheet1!AD7:AG7,3,0),0) -> 0 | BA23: =+IFERROR(VLOOKUP($BA$16,Sheet1!AH7:AK7,3,0),0) -> 0 | BB23: =+IFERROR(VLOOKUP($BB$16,Sheet1!AH7:AK7,3,0),0) -> 0 | BC23: =+IFERROR(VLOOKUP($BC$16,Sheet1!AH7:AK7,3,0),0) -> 0 | BD23: =+IFERROR(VLOOKUP($BD$16,Sheet1!AH7:AK7,3,0),0) -> 0 | BE23: =+IFERROR(VLOOKUP($BE$16,Sheet1!AH7:AK7,3,0),0) -> 0 | BF23: =+IFERROR(VLOOKUP($BF$16,Sheet1!AH7:AK7,3,0),0) -> 0 | BG23: =+IFERROR(VLOOKUP($BG$16,Sheet1!AH7:AK7,3,0),0) -> 0 | BH23: =+IFERROR(VLOOKUP($BH$16,Sheet1!AH7:AK7,3,0),0) -> 0 | BI23: =+IFERROR(VLOOKUP($BI$16,Sheet1!AH7:AK7,3,0),0) -> 0 | BJ23: =+IFERROR(VLOOKUP($BJ$16,Sheet1!AH7:AK7,3,0),0) -> 0 | BK23: =+IFERROR(VLOOKUP($BK$16,Sheet1!AH7:AK7,3,0),0) -> 0 | BL23: =+IFERROR(VLOOKUP($BL$16,Sheet1!AL7:AO7,3,0),0) -> 0 | BM23: =+IFERROR(VLOOKUP($BM$16,Sheet1!AL7:AO7,3,0),0) -> 0 | BN23: =+IFERROR(VLOOKUP($BN$16,Sheet1!AL7:AO7,3,0),0) -> 0 | BO23: =+IFERROR(VLOOKUP($BO$16,Sheet1!AL7:AO7,3,0),0) -> 0 | BP23: =+IFERROR(VLOOKUP($BP$16,Sheet1!AL7:AO7,3,0),0) -> 0 | BQ23: =+IFERROR(VLOOKUP($BQ$16,Sheet1!AL7:AO7,3,0),0) -> 0 | BR23: =+IFERROR(VLOOKUP($BR$16,Sheet1!AL7:AO7,3,0),0) -> 0 | BS23: =+IFERROR(VLOOKUP($BS$16,Sheet1!AL7:AO7,3,0),0) -> 0 | BT23: =+IFERROR(VLOOKUP($BT$16,Sheet1!AL7:AO7,3,0),0) -> 0 | BU23: =+IFERROR(VLOOKUP($BU$16,Sheet1!AL7:AO7,3,0),0) -> 0 | BV23: =+IFERROR(VLOOKUP($BV$16,Sheet1!AL7:AO7,3,0),0) -> 0 | BW23: =+IFERROR(VLOOKUP($BW$16,Sheet1!AL7:AO7,3,0),0) -> 0 | BX23: =+IFERROR(VLOOKUP($BX$16,Sheet1!AP7:AS7,3,0),0) -> 0 | BY23: =+IFERROR(VLOOKUP($BY$16,Sheet1!AT7:AW7,3,0),0) -> 0 | BZ23: =+IFERROR(VLOOKUP($BZ$16,Sheet1!AX7:BA7,3,0),0) -> 0 | CA23: =+IFERROR(VLOOKUP($CA$16,Sheet1!BB7:BE7,3,0),0) -> 0 | CB23: =+IFERROR(VLOOKUP($CB$16,Sheet1!BF7:BI7,3,0),0) -> 0 | CC23: =+IFERROR(VLOOKUP($CC$16,Sheet1!BJ7:BM7,3,0),0) -> 0 | CD23: =+IFERROR(VLOOKUP($CD$16,Sheet1!BN7:BQ7,3,0),0) -> 0 | CE23: =+IFERROR(VLOOKUP($CE$16,Sheet1!BR7:BU7,3,0),0) -> 0 | CF23: =+IFERROR(VLOOKUP($CF$16,Sheet1!BV7:BY7,3,0),0) -> 0 | CG23: =Sheet1!E7 -> 0 | CH23: =Sheet1!CX7 -> 0 | CI23: =Sheet1!CY7 -> 0 | CJ23: =Sheet1!CZ7 -> 0 | CK23: =Sheet1!BZ7 -> 0 | CL23: =SUMPRODUCT($N$17:$CF$17,N23:CF23)+CK23 -> 0 | CM23: =Sheet1!CB7 -> 0 | CN23: =CL23*CM23 -> 0 | CO23: =Sheet1!CD7 -> 0 | CP23: =CL23*CO23 -> 0 | CQ23: =Sheet1!CF7 -> 0 | CR23: =CL23*CQ23 -> 0 | CS23: =CL23+CN23+CP23+CR23 -> 0 | CT23: =Sheet1!CI7 -> 0 | CU23: =CS23*CT23 -> 0 | CV23: =Sheet1!CK7 -> 0 | CW23: =CS23*CV23 -> 0 | CX23: =Sheet1!CM7 -> 0 | CY23: =CX23*CS23 -> 0
A24: =Sheet1!A8 -> 0 | B24: =Sheet1!B8 -> 0 | C24: =Sheet1!C8 -> 0 | D24: =Sheet1!D8 -> 0 | E24: =CS24+CU24+CW24+CY24 -> 0 | F24: =Sheet1!CP8 -> 0 | G24: =E24+F24 -> 0 | H24: =Sheet1!CR8 -> 0 | I24: =G24*H24 -> 0 | J24: =G24+I24 -> 0 | K24: =Sheet1!CU8 -> 0 | L24: =Sheet1!CV8 -> 0 | M24: =J24*K24 -> 0 | N24: =+IFERROR(VLOOKUP($N$16,Sheet1!J8:L8,3,0),0) -> 0 | O24: =+IFERROR(VLOOKUP($O$16,Sheet1!J8:L8,3,0),0) -> 0 | P24: =+IFERROR(VLOOKUP($P$16,Sheet1!J8:M8,3,0),0) -> 0 | Q24: =+IFERROR(VLOOKUP($Q$16,Sheet1!J8:M8,3,0),0) -> 0 | R24: =+IFERROR(VLOOKUP($R$16,Sheet1!J8:M8,3,0),0) -> 0 | S24: =+IFERROR(VLOOKUP($S$16,Sheet1!J8:M8,3,0),0) -> 0 | T24: =+IFERROR(VLOOKUP($T$16,Sheet1!J8:M8,3,0),0) -> 0 | U24: =+IFERROR(VLOOKUP($U$16,Sheet1!J8:M8,3,0),0) -> 0 | V24: =+IFERROR(VLOOKUP($V$16,Sheet1!N8:Q8,3,0),0) -> 0 | W24: =+IFERROR(VLOOKUP($W$16,Sheet1!N8:Q8,3,0),0) -> 0 | X24: =+IFERROR(VLOOKUP($X$16,Sheet1!F8:I8,3,0),0) -> 0 | Y24: =+IFERROR(VLOOKUP($Y$16,Sheet1!F8:I8,3,0),0) -> 0 | Z24: =+IFERROR(VLOOKUP($Z$16,Sheet1!F8:I8,3,0),0) -> 0 | AA24: =+IFERROR(VLOOKUP($AA$16,Sheet1!F8:I8,3,0),0) -> 0 | AB24: =+IFERROR(VLOOKUP($AB$16,Sheet1!F8:I8,3,0),0) -> 0 | AC24: =+IFERROR(VLOOKUP($AC$16,Sheet1!F8:I8,3,0),0) -> 0 | AD24: =+IFERROR(VLOOKUP($AD$16,Sheet1!F8:I8,3,0),0) -> 0 | AE24: =+IFERROR(VLOOKUP($AE$16,Sheet1!F8:I8,3,0),0) -> 0 | AF24: =+IFERROR(VLOOKUP($AF$16,Sheet1!R8:U8,3,0),0) -> 0 | AG24: =+IFERROR(VLOOKUP($AG$16,Sheet1!R8:U8,3,0),0) -> 0 | AH24: =+IFERROR(VLOOKUP($AH$16,Sheet1!V8:Y8,3,0),0) -> 0 | AI24: =+IFERROR(VLOOKUP($AI$16,Sheet1!V8:Y8,3,0),0) -> 0 | AJ24: =+IFERROR(VLOOKUP($AJ$16,Sheet1!V8:Y8,3,0),0) -> 0 | AK24: =+IFERROR(VLOOKUP($AK$16,Sheet1!V8:Y8,3,0),0) -> 0 | AL24: =+IFERROR(VLOOKUP($AL$16,Sheet1!V8:Y8,3,0),0) -> 0 | AM24: =+IFERROR(VLOOKUP($AM$16,Sheet1!V8:Y8,3,0),0) -> 0 | AN24: =+IFERROR(VLOOKUP($AN$16,Sheet1!V8:Y8,3,0),0) -> 0 | AO24: =+IFERROR(VLOOKUP($AO$16,Sheet1!V8:Y8,3,0),0) -> 0 | AP24: =+IFERROR(VLOOKUP($AP$16,Sheet1!V8:Y8,3,0),0) -> 0 | AQ24: =+IFERROR(VLOOKUP($AQ$16,Sheet1!Z8:AB8,3,0),0) -> 0 | AR24: =+IFERROR(VLOOKUP($AR$16,Sheet1!AD8:AG8,3,0),0) -> 0 | AS24: =+IFERROR(VLOOKUP($AS$16,Sheet1!AD8:AG8,3,0),0) -> 0 | AT24: =+IFERROR(VLOOKUP($AT$16,Sheet1!AD8:AG8,3,0),0) -> 0 | AU24: =+IFERROR(VLOOKUP($AU$16,Sheet1!AD8:AG8,3,0),0) -> 0 | AV24: =+IFERROR(VLOOKUP($AV$16,Sheet1!AD8:AG8,3,0),0) -> 0 | AW24: =+IFERROR(VLOOKUP($AW$16,Sheet1!AD8:AG8,3,0),0) -> 0 | AX24: =+IFERROR(VLOOKUP($AX$16,Sheet1!AD8:AG8,3,0),0) -> 0 | AY24: =+IFERROR(VLOOKUP($AY$16,Sheet1!AD8:AG8,3,0),0) -> 0 | AZ24: =+IFERROR(VLOOKUP($AZ$16,Sheet1!AD8:AG8,3,0),0) -> 0 | BA24: =+IFERROR(VLOOKUP($BA$16,Sheet1!AH8:AK8,3,0),0) -> 0 | BB24: =+IFERROR(VLOOKUP($BB$16,Sheet1!AH8:AK8,3,0),0) -> 0 | BC24: =+IFERROR(VLOOKUP($BC$16,Sheet1!AH8:AK8,3,0),0) -> 0 | BD24: =+IFERROR(VLOOKUP($BD$16,Sheet1!AH8:AK8,3,0),0) -> 0 | BE24: =+IFERROR(VLOOKUP($BE$16,Sheet1!AH8:AK8,3,0),0) -> 0 | BF24: =+IFERROR(VLOOKUP($BF$16,Sheet1!AH8:AK8,3,0),0) -> 0 | BG24: =+IFERROR(VLOOKUP($BG$16,Sheet1!AH8:AK8,3,0),0) -> 0 | BH24: =+IFERROR(VLOOKUP($BH$16,Sheet1!AH8:AK8,3,0),0) -> 0 | BI24: =+IFERROR(VLOOKUP($BI$16,Sheet1!AH8:AK8,3,0),0) -> 0 | BJ24: =+IFERROR(VLOOKUP($BJ$16,Sheet1!AH8:AK8,3,0),0) -> 0 | BK24: =+IFERROR(VLOOKUP($BK$16,Sheet1!AH8:AK8,3,0),0) -> 0 | BL24: =+IFERROR(VLOOKUP($BL$16,Sheet1!AL8:AO8,3,0),0) -> 0 | BM24: =+IFERROR(VLOOKUP($BM$16,Sheet1!AL8:AO8,3,0),0) -> 0 | BN24: =+IFERROR(VLOOKUP($BN$16,Sheet1!AL8:AO8,3,0),0) -> 0 | BO24: =+IFERROR(VLOOKUP($BO$16,Sheet1!AL8:AO8,3,0),0) -> 0 | BP24: =+IFERROR(VLOOKUP($BP$16,Sheet1!AL8:AO8,3,0),0) -> 0 | BQ24: =+IFERROR(VLOOKUP($BQ$16,Sheet1!AL8:AO8,3,0),0) -> 0 | BR24: =+IFERROR(VLOOKUP($BR$16,Sheet1!AL8:AO8,3,0),0) -> 0 | BS24: =+IFERROR(VLOOKUP($BS$16,Sheet1!AL8:AO8,3,0),0) -> 0 | BT24: =+IFERROR(VLOOKUP($BT$16,Sheet1!AL8:AO8,3,0),0) -> 0 | BU24: =+IFERROR(VLOOKUP($BU$16,Sheet1!AL8:AO8,3,0),0) -> 0 | BV24: =+IFERROR(VLOOKUP($BV$16,Sheet1!AL8:AO8,3,0),0) -> 0 | BW24: =+IFERROR(VLOOKUP($BW$16,Sheet1!AL8:AO8,3,0),0) -> 0 | BX24: =+IFERROR(VLOOKUP($BX$16,Sheet1!AP8:AS8,3,0),0) -> 0 | BY24: =+IFERROR(VLOOKUP($BY$16,Sheet1!AT8:AW8,3,0),0) -> 0 | BZ24: =+IFERROR(VLOOKUP($BZ$16,Sheet1!AX8:BA8,3,0),0) -> 0 | CA24: =+IFERROR(VLOOKUP($CA$16,Sheet1!BB8:BE8,3,0),0) -> 0 | CB24: =+IFERROR(VLOOKUP($CB$16,Sheet1!BF8:BI8,3,0),0) -> 0 | CC24: =+IFERROR(VLOOKUP($CC$16,Sheet1!BJ8:BM8,3,0),0) -> 0 | CD24: =+IFERROR(VLOOKUP($CD$16,Sheet1!BN8:BQ8,3,0),0) -> 0 | CE24: =+IFERROR(VLOOKUP($CE$16,Sheet1!BR8:BU8,3,0),0) -> 0 | CF24: =+IFERROR(VLOOKUP($CF$16,Sheet1!BV8:BY8,3,0),0) -> 0 | CG24: =Sheet1!E8 -> 0 | CH24: =Sheet1!CX8 -> 0 | CI24: =Sheet1!CY8 -> 0 | CJ24: =Sheet1!CZ8 -> 0 | CK24: =Sheet1!BZ8 -> 0 | CL24: =SUMPRODUCT($N$17:$CF$17,N24:CF24)+CK24 -> 0 | CM24: =Sheet1!CB8 -> 0 | CN24: =CL24*CM24 -> 0 | CO24: =Sheet1!CD8 -> 0 | CP24: =CL24*CO24 -> 0 | CQ24: =Sheet1!CF8 -> 0 | CR24: =CL24*CQ24 -> 0 | CS24: =CL24+CN24+CP24+CR24 -> 0 | CT24: =Sheet1!CI8 -> 0 | CU24: =CS24*CT24 -> 0 | CV24: =Sheet1!CK8 -> 0 | CW24: =CS24*CV24 -> 0 | CX24: =Sheet1!CM8 -> 0 | CY24: =CX24*CS24 -> 0
A25: =Sheet1!A9 -> 0 | B25: =Sheet1!B9 -> 0 | C25: =Sheet1!C9 -> 0 | D25: =Sheet1!D9 -> 0 | E25: =CS25+CU25+CW25+CY25 -> 0 | F25: =Sheet1!CP9 -> 0 | G25: =E25+F25 -> 0 | H25: =Sheet1!CR9 -> 0 | I25: =G25*H25 -> 0 | J25: =G25+I25 -> 0 | K25: =Sheet1!CU9 -> 0 | L25: =Sheet1!CV9 -> 0 | M25: =J25*K25 -> 0 | N25: =+IFERROR(VLOOKUP($N$16,Sheet1!J9:L9,3,0),0) -> 0 | O25: =+IFERROR(VLOOKUP($O$16,Sheet1!J9:L9,3,0),0) -> 0 | P25: =+IFERROR(VLOOKUP($P$16,Sheet1!J9:M9,3,0),0) -> 0 | Q25: =+IFERROR(VLOOKUP($Q$16,Sheet1!J9:M9,3,0),0) -> 0 | R25: =+IFERROR(VLOOKUP($R$16,Sheet1!J9:M9,3,0),0) -> 0 | S25: =+IFERROR(VLOOKUP($S$16,Sheet1!J9:M9,3,0),0) -> 0 | T25: =+IFERROR(VLOOKUP($T$16,Sheet1!J9:M9,3,0),0) -> 0 | U25: =+IFERROR(VLOOKUP($U$16,Sheet1!J9:M9,3,0),0) -> 0 | V25: =+IFERROR(VLOOKUP($V$16,Sheet1!N9:Q9,3,0),0) -> 0 | W25: =+IFERROR(VLOOKUP($W$16,Sheet1!N9:Q9,3,0),0) -> 0 | X25: =+IFERROR(VLOOKUP($X$16,Sheet1!F9:I9,3,0),0) -> 0 | Y25: =+IFERROR(VLOOKUP($Y$16,Sheet1!F9:I9,3,0),0) -> 0 | Z25: =+IFERROR(VLOOKUP($Z$16,Sheet1!F9:I9,3,0),0) -> 0 | AA25: =+IFERROR(VLOOKUP($AA$16,Sheet1!F9:I9,3,0),0) -> 0 | AB25: =+IFERROR(VLOOKUP($AB$16,Sheet1!F9:I9,3,0),0) -> 0 | AC25: =+IFERROR(VLOOKUP($AC$16,Sheet1!F9:I9,3,0),0) -> 0 | AD25: =+IFERROR(VLOOKUP($AD$16,Sheet1!F9:I9,3,0),0) -> 0 | AE25: =+IFERROR(VLOOKUP($AE$16,Sheet1!F9:I9,3,0),0) -> 0 | AF25: =+IFERROR(VLOOKUP($AF$16,Sheet1!R9:U9,3,0),0) -> 0 | AG25: =+IFERROR(VLOOKUP($AG$16,Sheet1!R9:U9,3,0),0) -> 0 | AH25: =+IFERROR(VLOOKUP($AH$16,Sheet1!V9:Y9,3,0),0) -> 0 | AI25: =+IFERROR(VLOOKUP($AI$16,Sheet1!V9:Y9,3,0),0) -> 0 | AJ25: =+IFERROR(VLOOKUP($AJ$16,Sheet1!V9:Y9,3,0),0) -> 0 | AK25: =+IFERROR(VLOOKUP($AK$16,Sheet1!V9:Y9,3,0),0) -> 0 | AL25: =+IFERROR(VLOOKUP($AL$16,Sheet1!V9:Y9,3,0),0) -> 0 | AM25: =+IFERROR(VLOOKUP($AM$16,Sheet1!V9:Y9,3,0),0) -> 0 | AN25: =+IFERROR(VLOOKUP($AN$16,Sheet1!V9:Y9,3,0),0) -> 0 | AO25: =+IFERROR(VLOOKUP($AO$16,Sheet1!V9:Y9,3,0),0) -> 0 | AP25: =+IFERROR(VLOOKUP($AP$16,Sheet1!V9:Y9,3,0),0) -> 0 | AQ25: =+IFERROR(VLOOKUP($AQ$16,Sheet1!Z9:AB9,3,0),0) -> 0 | AR25: =+IFERROR(VLOOKUP($AR$16,Sheet1!AD9:AG9,3,0),0) -> 0 | AS25: =+IFERROR(VLOOKUP($AS$16,Sheet1!AD9:AG9,3,0),0) -> 0 | AT25: =+IFERROR(VLOOKUP($AT$16,Sheet1!AD9:AG9,3,0),0) -> 0 | AU25: =+IFERROR(VLOOKUP($AU$16,Sheet1!AD9:AG9,3,0),0) -> 0 | AV25: =+IFERROR(VLOOKUP($AV$16,Sheet1!AD9:AG9,3,0),0) -> 0 | AW25: =+IFERROR(VLOOKUP($AW$16,Sheet1!AD9:AG9,3,0),0) -> 0 | AX25: =+IFERROR(VLOOKUP($AX$16,Sheet1!AD9:AG9,3,0),0) -> 0 | AY25: =+IFERROR(VLOOKUP($AY$16,Sheet1!AD9:AG9,3,0),0) -> 0 | AZ25: =+IFERROR(VLOOKUP($AZ$16,Sheet1!AD9:AG9,3,0),0) -> 0 | BA25: =+IFERROR(VLOOKUP($BA$16,Sheet1!AH9:AK9,3,0),0) -> 0 | BB25: =+IFERROR(VLOOKUP($BB$16,Sheet1!AH9:AK9,3,0),0) -> 0 | BC25: =+IFERROR(VLOOKUP($BC$16,Sheet1!AH9:AK9,3,0),0) -> 0 | BD25: =+IFERROR(VLOOKUP($BD$16,Sheet1!AH9:AK9,3,0),0) -> 0 | BE25: =+IFERROR(VLOOKUP($BE$16,Sheet1!AH9:AK9,3,0),0) -> 0 | BF25: =+IFERROR(VLOOKUP($BF$16,Sheet1!AH9:AK9,3,0),0) -> 0 | BG25: =+IFERROR(VLOOKUP($BG$16,Sheet1!AH9:AK9,3,0),0) -> 0 | BH25: =+IFERROR(VLOOKUP($BH$16,Sheet1!AH9:AK9,3,0),0) -> 0 | BI25: =+IFERROR(VLOOKUP($BI$16,Sheet1!AH9:AK9,3,0),0) -> 0 | BJ25: =+IFERROR(VLOOKUP($BJ$16,Sheet1!AH9:AK9,3,0),0) -> 0 | BK25: =+IFERROR(VLOOKUP($BK$16,Sheet1!AH9:AK9,3,0),0) -> 0 | BL25: =+IFERROR(VLOOKUP($BL$16,Sheet1!AL9:AO9,3,0),0) -> 0 | BM25: =+IFERROR(VLOOKUP($BM$16,Sheet1!AL9:AO9,3,0),0) -> 0 | BN25: =+IFERROR(VLOOKUP($BN$16,Sheet1!AL9:AO9,3,0),0) -> 0 | BO25: =+IFERROR(VLOOKUP($BO$16,Sheet1!AL9:AO9,3,0),0) -> 0 | BP25: =+IFERROR(VLOOKUP($BP$16,Sheet1!AL9:AO9,3,0),0) -> 0 | BQ25: =+IFERROR(VLOOKUP($BQ$16,Sheet1!AL9:AO9,3,0),0) -> 0 | BR25: =+IFERROR(VLOOKUP($BR$16,Sheet1!AL9:AO9,3,0),0) -> 0 | BS25: =+IFERROR(VLOOKUP($BS$16,Sheet1!AL9:AO9,3,0),0) -> 0 | BT25: =+IFERROR(VLOOKUP($BT$16,Sheet1!AL9:AO9,3,0),0) -> 0 | BU25: =+IFERROR(VLOOKUP($BU$16,Sheet1!AL9:AO9,3,0),0) -> 0 | BV25: =+IFERROR(VLOOKUP($BV$16,Sheet1!AL9:AO9,3,0),0) -> 0 | BW25: =+IFERROR(VLOOKUP($BW$16,Sheet1!AL9:AO9,3,0),0) -> 0 | BX25: =+IFERROR(VLOOKUP($BX$16,Sheet1!AP9:AS9,3,0),0) -> 0 | BY25: =+IFERROR(VLOOKUP($BY$16,Sheet1!AT9:AW9,3,0),0) -> 0 | BZ25: =+IFERROR(VLOOKUP($BZ$16,Sheet1!AX9:BA9,3,0),0) -> 0 | CA25: =+IFERROR(VLOOKUP($CA$16,Sheet1!BB9:BE9,3,0),0) -> 0 | CB25: =+IFERROR(VLOOKUP($CB$16,Sheet1!BF9:BI9,3,0),0) -> 0 | CC25: =+IFERROR(VLOOKUP($CC$16,Sheet1!BJ9:BM9,3,0),0) -> 0 | CD25: =+IFERROR(VLOOKUP($CD$16,Sheet1!BN9:BQ9,3,0),0) -> 0 | CE25: =+IFERROR(VLOOKUP($CE$16,Sheet1!BR9:BU9,3,0),0) -> 0 | CF25: =+IFERROR(VLOOKUP($CF$16,Sheet1!BV9:BY9,3,0),0) -> 0 | CG25: =Sheet1!E9 -> 0 | CH25: =Sheet1!CX9 -> 0 | CI25: =Sheet1!CY9 -> 0 | CJ25: =Sheet1!CZ9 -> 0 | CK25: =Sheet1!BZ9 -> 0 | CL25: =SUMPRODUCT($N$17:$CF$17,N25:CF25)+CK25 -> 0 | CM25: =Sheet1!CB9 -> 0 | CN25: =CL25*CM25 -> 0 | CO25: =Sheet1!CD9 -> 0 | CP25: =CL25*CO25 -> 0 | CQ25: =Sheet1!CF9 -> 0 | CR25: =CL25*CQ25 -> 0 | CS25: =CL25+CN25+CP25+CR25 -> 0 | CT25: =Sheet1!CI9 -> 0 | CU25: =CS25*CT25 -> 0 | CV25: =Sheet1!CK9 -> 0 | CW25: =CS25*CV25 -> 0 | CX25: =Sheet1!CM9 -> 0 | CY25: =CX25*CS25 -> 0
