Workbook

Sheet Sheet1
A1: DOCKET NO. | B1: Base Date | C1: ITEM CODE | D1: PROPOSE ERP ITEM NAME | E1: Propose Drum Type | F1: Insulation Screening(Metallic) | G1: RM Rate(Insulation Screening(Metallic)) | H1: Weight (Insulation Screening (Metallic)) | I1: Cost Insulation Screening(Metallic) | J1: Conductor | K1: RM Rate(Conductor) | L1: Weight(Conductor) | M1: Cost(Conductor) | N1: AL ALLOY | O1: RM Rate(AL Alloy) | P1: Weight(Al Alloy) | Q1: Cost(AL Alloy) | R1: Insulation Screening(Non-Metallic) | S1: RM Rate(Insulation Screening(Non-Metallic)) | T1: Weight(Insulation Screening(Non-Metallic) | U1: Cost(Insulation Screening(Non-Metallic) | V1: Insulation | W1: RM Rate(Insulation) | X1: Weight(Insulation) | Y1: Cost(Insulation) | Z1: Poly Tape | AA1: RM Rate(Poly Tape) | AB1: Weight(Poly Tape) | AC1: Cost(Poly Tape) | AD1: Inner Sheath | AE1: RM Rate(Inner Sheath) | AF1: Weight(Inner Sheath) | AG1: Cost(Inner Sheath) | AH1: Armouring | AI1: RM Rate(Armouring) | AJ1: Weight(Armouring) | AK1: Cost(Armouring) | AL1: Outer Sheath | AM1: RM Rate(Outer Sheath) | AN1: Weight(Outer Sheath) | AO1: Cost(Outer Sheath) | AP1: Filler | AQ1: RM Rate(Filler) | AR1: Weight(Filler) | AS1: Cost(Filler) | AT1: Grease | AU1: RM Rate(Grease) | AV1: Weight(Grease) | AW1: Cost(Grease) | AX1: Water Swellable Tape | AY1: RM Rate(Water Swellable Tape) | AZ1: Weight(Water Swellable Tape) | BA1: Cost(Water Swellable Tape) | BB1: Semi Conducting Water Swellable Tape | BC1: RM Rate(Semi Conducting Water Swellable Tape) | BD1: Weight(Semi Conducting Water Swellable Tape) | BE1: Cost(Semi Conducting Water Swellable Tape) | BF1: Semicon Tape | BG1: RM Rate(Semicon Tape) | BH1: Weight(Semicon Tape) | BI1: Cost(Semicon Tape) | BJ1: Glass Fiber Tape | BK1: RM Rate(Glass Fiber Tape) | BL1: Weight(Glass Fiber Tape) | BM1: Cost(Glass Fiber Tape) | BN1: Copper Wire 0.8MM | BO1: RM Rate(Copper Wire 0.8MM) | BP1: Weight(Copper Wire 0.8MM) | BQ1: Cost(Copper Wire 0.8MM) | BR1: Rubberized Cotton Tape | BS1: RM Rate(Rubberized Cotton Tape) | BT1: Weight(Rubberized Cotton Tape) | BU1: Cost(Rubberized Cotton Tape) | BV1: Water Tight Compound | BW1: RM Rate(Water Tight Compound) | BX1: Weight(Water Tight Compound) | BY1: Cost(Water Tight Compound) | BZ1: Drum Cost Per KM | CA1: Total RM Cost | CB1: FIRM % | CC1: Firm Value | CD1: MFG% | CE1: MFG Value | CF1: PROF% | CG1: Profit Value | CH1: 1st EX-Works | CI1: Intt % | CJ1: Intt Value | CK1: insp% | CL1: Insp Value | CM1: TTR CHARGES% | CN1: TTR Value | CO1: EX-Works Per KM | CP1: Freight Per KM | CQ1: Price Including Freight Per KM | CR1: GST % | CS1: GST Value | CT1: Price Including GST & Freight Per KM | CU1: QTY | CV1: Unit | CW1: Total Price Of Full QTY(Including Freight&GST) | CX1: PARTY LENGTH (IF STANDER LENGTH NOT MATCH WITH PAR | CY1: DRUM CODE | CZ1: DRUM SIZE (FxbXtx Ft)
A2: ENQ-18390-25-26 | C2: FA1300009 | D2: 1 CORE X 300 SQ. MM. AL./ARM (XLPE) - 11 KV | E2: STEEL | F2: Copper Tape - 0.045 mm | H2: 41 | J2: Alumimium | L2: 810 | P2: 0 | R2: Extruded Semiconductive | T2: 112 | V2: HT-XLPE | X2: 267 | Z2: POLY TAPE | AB2: 0 | AD2: PVC Type ST-2 | AF2: 87 | AH2: Aluminium Round Wire | AJ2: 388 | AL2: FRLSH PVC Type ST-2 | AN2: 318 | AR2: 0 | AV2: 0 | AX2: Water swellable Tape | AZ2: 0 | BB2: Semi conducting Water Swellable tape | BD2: 38 | BH2: 0 | BL2: 0 | BP2: 0 | BR2: RUBBERIZED COTTON TAPE | BT2: 0 | BX2: 0 | BZ2: 27000 | CA2: 27000 | CH2: 27000 | CO2: 27000 | CQ2: 27000 | CR2: 0.18 | CS2: 4860 | CT2: 31860 | CU2: 3 | CV2: KMS | CW2: 95580 | CX2: 500 | CY2: SP0400152 | CZ2: CORRUGATED DISPATCH STEEL DRUM 1500 X 800 X 915
A3: ENQ-18390-25-26 | C3: FA1300016 | D3: 1 CORE X 630 SQ. MM. AL/ARM (XLPE) - 11 KV | E3: STEEL | F3: Copper Tape - 0.045 mm | H3: 54 | J3: Alumimium | L3: 1701 | P3: 0 | R3: Extruded Semiconductive | T3: 150 | V3: HT-XLPE | X3: 374 | Z3: POLY TAPE | AB3: 0 | AD3: PVC Type ST-2 | AF3: 134 | AH3: Aluminium Round Wire | AJ3: 511 | AL3: FRLSH PVC Type ST-2 | AN3: 472 | AR3: 0 | AV3: 0 | AX3: Water swellable Tape | AZ3: 0 | BB3: Semi conducting Water Swellable tape | BD3: 70 | BH3: 0 | BL3: 0 | BP3: 0 | BR3: RUBBERIZED COTTON TAPE | BT3: 0 | BX3: 0 | BZ3: 48450 | CA3: 48450 | CH3: 48450 | CO3: 48450 | CQ3: 48450 | CR3: 0.18 | CS3: 8721 | CT3: 57171 | CU3: 13 | CV3: KMS | CW3: 743223 | CX3: 500 | CY3: SP0400091 | CZ3: CORRUGATED DISPATCH STEEL DRUM 1800 X 900 X 1000
A4: ENQ-18390-25-26 | C4: FA1300018 | D4: 1 CORE X 400 SQ. MM. AL/ARM (XLPE) - 33 KV | E4: STEEL | F4: Copper Tape - 0.045 mm | H4: 60 | J4: Alumimium | L4: 1080 | P4: 0 | R4: Extruded Semiconductive | T4: 141 | V4: HT-XLPE | X4: 870 | Z4: POLY TAPE | AB4: 0 | AD4: PVC Type ST-2 | AF4: 147 | AH4: Aluminium Round Wire | AJ4: 702 | AL4: FRLSH PVC Type ST-2 | AN4: 575 | AR4: 0 | AV4: 0 | AX4: Water swellable Tape | AZ4: 54 | BB4: Semi conducting Water Swellable tape | BD4: 0 | BH4: 52 | BL4: 0 | BP4: 0 | BR4: RUBBERIZED COTTON TAPE | BT4: 0 | BX4: 0 | BZ4: 53200 | CA4: 53200 | CH4: 53200 | CO4: 53200 | CQ4: 53200 | CR4: 0.18 | CS4: 9576 | CT4: 62776 | CU4: 16 | CV4: KMS | CW4: 1004416 | CX4: 500 | CY4: SP0400112 | CZ4: CORRUGATED DISPATCH STEEL DRUM 2000 X 1000 X 1000 MM
A5: ENQ-18390-25-26 | C5: FA1300019 | D5: 1 CORE X 300 SQ. MM. AL/ARM (XLPE) - 33 KV | E5: STEEL | F5: Copper Tape - 0.045 mm | H5: 55 | J5: Alumimium | L5: 810 | P5: 0 | R5: Extruded Semiconductive | T5: 128 | V5: HT-XLPE | X5: 792 | Z5: POLY TAPE | AB5: 0 | AD5: PVC Type ST-2 | AF5: 138 | AH5: Aluminium Round Wire | AJ5: 648 | AL5: FRLSH PVC Type ST-2 | AN5: 542 | AR5: 0 | AV5: 0 | AX5: Water swellable Tape | AZ5: 0 | BB5: Semi conducting Water Swellable tape | BD5: 0 | BH5: 0 | BL5: 0 | BP5: 0 | BR5: RUBBERIZED COTTON TAPE | BT5: 0 | BX5: 0 | BZ5: 47500 | CA5: 47500 | CH5: 47500 | CO5: 47500 | CQ5: 47500 | CR5: 0.18 | CS5: 8550 | CT5: 56050 | CU5: 3 | CV5: KMS | CW5: 168150 | CX5: 500 | CY5: SP0400110 | CZ5: CORRUGATED DISPATCH STEEL DRUM 1600 X 900 X 1000 MM
A6: ENQ-18390-25-26 | C6: FA1300022 | D6: 3 CORE X 50 SQ. MM. AL/ARD - WIRE (XLPE) - 33 KV (E) | E6: STEEL | F6: Copper Tape - 0.045 mm | J6: Alumimium | R6: Extruded Semiconductive | V6: HT-XLPE | AD6: PVC Type ST-2-PRESSURE EXTRUDED | AH6: Galvanised Steel Round Wire | AL6: FRLSH PVC Type ST-2 | AP6: Polypropylene Filler | AX6: Water swellable Tape | BB6: Semi conducting Water Swellable tape | BR6: RUBBERIZED COTTON TAPE | BZ6: 106400 | CA6: 106400 | CH6: 106400 | CO6: 106400 | CQ6: 106400 | CR6: 0.18 | CS6: 19152 | CT6: 125552 | CU6: 2.5 | CV6: KMS | CW6: 313880 | CX6: 250 | CY6: SP0400112 | CZ6: CORRUGATED DISPATCH STEEL DRUM 2000 X 1000 X 1000 MM
A7: ENQ-18390-25-26 | C7: FA1300027 | D7: 1 CORE X 630 SQ. MM. AL/ARM (XLPE) - 33 KV | E7: STEEL | F7: Copper Tape - 0.045 mm | H7: 69 | J7: Alumimium | L7: 1701 | P7: 0 | R7: Extruded Semiconductive | T7: 172 | V7: HT-XLPE | X7: 1040 | Z7: POLY TAPE | AB7: 0 | AD7: PVC Type ST-2 | AF7: 193 | AH7: Aluminium Round Wire | AJ7: 800 | AL7: FRLSH PVC Type ST-2 | AN7: 738 | AR7: 0 | AV7: 0 | AX7: Water swellable Tape | AZ7: 0 | BB7: Semi conducting Water Swellable tape | BD7: 0 | BH7: 0 | BL7: 0 | BP7: 0 | BR7: RUBBERIZED COTTON TAPE | BT7: 0 | BX7: 0 | BZ7: 53200 | CA7: 53200 | CH7: 53200 | CO7: 53200 | CQ7: 53200 | CR7: 0.18 | CS7: 9576 | CT7: 62776 | CU7: 105 | CV7: KMS | CW7: 6591480 | CX7: 500 | CY7: SP0400123 | CZ7: CORRUGATED DISPATCH STEEL DRUM 2000 X 1000 X 1200 MM
A8: ENQ-18390-25-26 | C8: FA1300047 | D8: 1 CORE X 400 SQ. MM. AL/ARM (XLPE) - 11 KV | E8: STEEL | F8: Copper Tape - 0.045 mm | H8: 45 | J8: Alumimium | L8: 1080 | P8: 0 | R8: Extruded Semiconductive | T8: 122 | V8: HT-XLPE | X8: 305 | AB8: 0 | AD8: PVC Type ST-2 | AF8: 96 | AH8: Aluminium Round Wire | AJ8: 423 | AL8: FRLSH PVC Type ST-2 | AN8: 376 | AR8: 0 | AV8: 0 | AX8: Water swellable Tape | AZ8: 0 | BB8: Semi conducting Water Swellable tape | BD8: 54 | BH8: 0 | BL8: 0 | BP8: 0 | BT8: 0 | BX8: 0 | BZ8: 34200 | CA8: 34200 | CH8: 34200 | CO8: 34200 | CQ8: 34200 | CR8: 0.18 | CS8: 6156 | CT8: 40356 | CU8: 6.5 | CV8: KMS | CW8: 262314 | CX8: 500 | CY8: SP0400125 | CZ8: CORRUGATED DISPATCH STEEL DRUM 1600 X 700 X 915 MM
A9: ENQ-18390-25-26 | C9: FA1300066 | D9: 1 CORE X 1000 SQ. MM. AL/ARM (XLPE) - 11 KV | E9: STEEL | F9: Copper Tape - 0.045 mm | H9: 66 | J9: Alumimium | L9: 2732 | P9: 0 | R9: Extruded Semiconductive | T9: 200 | V9: HT-XLPE | X9: 465 | Z9: POLY TAPE | AB9: 0 | AD9: PVC Type ST-2 | AF9: 185 | AH9: Aluminium Round Wire | AJ9: 773 | AL9: FRLSH PVC Type ST-2 | AN9: 655 | AR9: 0 | AV9: 0 | AX9: Water swellable Tape | AZ9: 0 | BB9: Semi conducting Water Swellable tape | BD9: 99 | BH9: 59 | BL9: 0 | BP9: 0 | BR9: RUBBERIZED COTTON TAPE | BT9: 52 | BX9: 0 | BZ9: 66500 | CA9: 66500 | CH9: 66500 | CO9: 66500 | CQ9: 66500 | CR9: 0.18 | CS9: 11970 | CT9: 78470 | CU9: 7.5 | CV9: KMS | CW9: 588525 | CX9: 500 | CY9: SP0400107 | CZ9: CORRUGATED DISPATCH STEEL DRUM 2150 X 1080 X 1240 MM
A10: ENQ-18390-25-26 | C10: FA1300079 | D10: 3 CORE X 185 SQ. MM AL/ARM - WIRE (XLPE) - 33 KV | E10: STEEL | F10: Copper Tape - 0.045 mm | H10: 149 | J10: Alumimium | L10: 1499 | P10: 0 | R10: Extruded Semiconductive | T10: 326 | V10: HT-XLPE | X10: 2040 | AB10: 0 | AD10: PVC Type ST-2-PRESSURE EXTRUDED | AF10: 335 | AH10: Galvanised Steel Round Wire | AJ10: 5745 | AL10: FRLSH PVC Type ST-2 | AN10: 1411 | AP10: Polypropylene Filler | AR10: 1838 | AV10: 0 | AX10: Water swellable Tape | AZ10: 0 | BB10: Semi conducting Water Swellable tape | BD10: 0 | BH10: 0 | BL10: 0 | BP10: 0 | BR10: RUBBERIZED COTTON TAPE | BT10: 0 | BX10: 0 | BZ10: 171000 | CA10: 171000 | CH10: 171000 | CO10: 171000 | CQ10: 171000 | CR10: 0.18 | CS10: 30780 | CT10: 201780 | CU10: 28.5 | CV10: KMS | CW10: 5750730 | CX10: 250 | CY10: SP0400081 | CZ10: CORRUGATED DISPATCH STEEL DRUM 2500 X 1400 X 1250 MM
A11: ENQ-18390-25-26 | C11: FA1300080 | D11: 3 CORE X 400 SQ. MM AL/ARM - WIRE (XLPE) - 33 KV | E11: STEEL | F11: Copper Tape - 0.045 mm | H11: 179 | J11: Alumimium | L11: 3240 | P11: 0 | R11: Extruded Semiconductive | T11: 427 | V11: HT-XLPE | X11: 2621 | AB11: 0 | AD11: PVC Type ST-2-PRESSURE EXTRUDED | AF11: 405 | AH11: Galvanised Steel Round Wire | AJ11: 6975 | AL11: FRLSH PVC Type ST-2 | AN11: 1660 | AP11: Polypropylene Filler | AR11: 2672 | AV11: 0 | AX11: Water swellable Tape | AZ11: 120 | BB11: Semi conducting Water Swellable tape | BD11: 0 | BH11: 144 | BL11: 0 | BP11: 0 | BR11: RUBBERIZED COTTON TAPE | BT11: 0 | BX11: 0 | BZ11: 190000 | CA11: 190000 | CH11: 190000 | CO11: 190000 | CQ11: 190000 | CR11: 0.18 | CS11: 34200 | CT11: 224200 | CU11: 321.5 | CV11: KMS | CW11: 72080300 | CX11: 250 | CY11: SP0400137 | CZ11: CORRUGATED DISPATCH STEEL DRUM 2600 X 1600 X 1600 MM
A12: ENQ-18390-25-26 | C12: FA1300081 | D12: 3 CORE X 300 SQ. MM. AL/ARM - WIRE (XLPE) - 33 KV | E12: STEEL | F12: Copper Tape - 0.045 mm | H12: 165 | J12: Alumimium | L12: 2430 | P12: 0 | R12: Extruded Semiconductive | T12: 386 | V12: HT-XLPE | X12: 2385 | AB12: 0 | AD12: PVC Type ST-2-PRESSURE EXTRUDED | AF12: 378 | AH12: Galvanised Steel Round Wire | AJ12: 6463 | AL12: FRLSH PVC Type ST-2 | AN12: 1558 | AP12: Polypropylene Filler | AR12: 2315 | AV12: 0 | AX12: Water swellable Tape | AZ12: 0 | BB12: Semi conducting Water Swellable tape | BD12: 0 | BH12: 0 | BL12: 0 | BP12: 0 | BR12: RUBBERIZED COTTON TAPE | BT12: 0 | BX12: 0 | BZ12: 190000 | CA12: 190000 | CH12: 190000 | CO12: 190000 | CQ12: 190000 | CR12: 0.18 | CS12: 34200 | CT12: 224200 | CU12: 45 | CV12: KMS | CW12: 10089000 | CX12: 250 | CY12: SP0400137 | CZ12: CORRUGATED DISPATCH STEEL DRUM 2600 X 1600 X 1600
A13: ENQ-18390-25-26 | C13: FA1300083 | D13: 3 CORE X 400 SQ. MM. AL/ARM - WIRE (XLPE) - 11 KV | E13: STEEL | F13: Copper Tape - 0.045 mm | H13: 136 | J13: Alumimium | L13: 3240 | P13: 0 | R13: Extruded Semiconductive | T13: 366 | V13: HT-XLPE | X13: 908 | AB13: 0 | AD13: PVC Type ST-2-PRESSURE EXTRUDED | AF13: 305 | AH13: Galvanised Steel Round Wire | AJ13: 5335 | AL13: FRLSH PVC Type ST-2 | AN13: 1308 | AP13: Polypropylene Filler | AR13: 1535 | AV13: 0 | AX13: Water swellable Tape | AZ13: 0 | BB13: Semi conducting Water Swellable tape | BD13: 64 | BH13: 0 | BL13: 0 | BP13: 0 | BR13: RUBBERIZED COTTON TAPE | BT13: 0 | BX13: 0 | BZ13: 182400 | CA13: 182400 | CH13: 182400 | CO13: 182400 | CQ13: 182400 | CR13: 0.18 | CS13: 32832 | CT13: 215232 | CU13: 209 | CV13: KMS | CW13: 44983488 | CX13: 250 | CY13: SP0400105 | CZ13: CORRUGATED DISPATCH STEEL DRUM 2500 X 1500 X 1400
A14: ENQ-18390-25-26 | C14: FA1300090 | D14: 3 CORE X 185 SQ. MM AL/ARM - WIRE (XLPE) - 11 KV | E14: STEEL | F14: Copper Tape - 0.045 mm | H14: 105 | J14: Alumimium | L14: 1499 | P14: 0 | R14: Extruded Semiconductive | T14: 276 | V14: HT-XLPE | X14: 663 | AB14: 0 | AD14: PVC Type ST-2-PRESSURE EXTRUDED | AF14: 237 | AH14: Galvanised Steel Round Wire | AJ14: 3244 | AL14: FRLSH PVC Type ST-2 | AN14: 862 | AP14: Polypropylene Filler | AR14: 914 | AV14: 0 | AX14: Water swellable Tape | AZ14: 0 | BB14: Semi conducting Water Swellable tape | BD14: 0 | BH14: 0 | BL14: 0 | BP14: 0 | BR14: RUBBERIZED COTTON TAPE | BT14: 0 | BX14: 0 | BZ14: 76000 | CA14: 76000 | CH14: 76000 | CO14: 76000 | CQ14: 76000 | CR14: 0.18 | CS14: 13680 | CT14: 89680 | CU14: 17 | CV14: KMS | CW14: 1524560 | CX14: 250 | CY14: SP0400111 | CZ14: CORRUGATED DISPATCH STEEL DRUM 1900 X 1000 X 1000 MM
A15: ENQ-18390-25-26 | C15: FA1300091 | D15: 3 CORE X 300 SQ. MM. AL/ARM - WIRE (XLPE) - 11 KV | E15: STEEL | F15: Copper Tape - 0.045 mm | H15: 122 | J15: Alumimium | L15: 2430 | P15: 0 | R15: Extruded Semiconductive | T15: 337 | V15: HT-XLPE | X15: 802 | AB15: 0 | AD15: PVC Type ST-2-PRESSURE EXTRUDED | AF15: 277 | AH15: Galvanised Steel Round Wire | AJ15: 3753 | AL15: FRLSH PVC Type ST-2 | AN15: 1120 | AP15: Polypropylene Filler | AR15: 1258 | AV15: 0 | AX15: Water swellable Tape | AZ15: 0 | BB15: Semi conducting Water Swellable tape | BD15: 115 | BH15: 34 | BL15: 0 | BP15: 0 | BR15: RUBBERIZED COTTON TAPE | BT15: 0 | BX15: 0 | BZ15: 171000 | CA15: 171000 | CH15: 171000 | CO15: 171000 | CQ15: 171000 | CR15: 0.18 | CS15: 30780 | CT15: 201780 | CU15: 151 | CV15: KMS | CW15: 30468780 | CX15: 250 | CY15: SP0400136 | CZ15: CORRUGATED DISPATCH STEEL DRUM 2200 X 1300 X 1200 MM
A16: ENQ-18390-25-26 | C16: FA1300097 | D16: 3 CORE X 70 SQ. MM. AL/ARM - WIRE (XLPE) - 11 KV | E16: STEEL | F16: Copper Tape - 0.045 mm | H16: 80 | J16: Alumimium | L16: 567 | P16: 0 | R16: Extruded Semiconductive | T16: 188 | V16: HT-XLPE | X16: 474 | AB16: 0 | AD16: PVC Type ST-2-PRESSURE EXTRUDED | AF16: 142 | AH16: Galvanised Steel Round Wire | AJ16: 1964 | AL16: FRLSH PVC Type ST-2 | AN16: 557 | AP16: Polypropylene Filler | AR16: 533 | AV16: 0 | AX16: Water swellable Tape | AZ16: 0 | BB16: Semi conducting Water Swellable tape | BD16: 0 | BH16: 22 | BL16: 0 | BP16: 0 | BR16: RUBBERIZED COTTON TAPE | BT16: 0 | BX16: 0 | BZ16: 92000 | CA16: 92000 | CH16: 92000 | CO16: 92000 | CQ16: 92000 | CR16: 0.18 | CS16: 16560 | CT16: 108560 | CU16: 5.5 | CV16: KMS | CW16: 597080 | CX16: 250 | CY16: SP0400110 | CZ16: CORRUGATED DISPATCH STEEL DRUM 1600 X 900 X 1000 MM
A17: ENQ-18390-25-26 | C17: FA1300098 | D17: 3 CORE X 95 SQ. MM. AL/ARM - WIRE (XLPE) - 11 KV | E17: STEEL | F17: Copper Tape - 0.045 mm | H17: 86 | J17: Alumimium | L17: 770 | P17: 0 | R17: Extruded Semiconductive | T17: 205 | V17: HT-XLPE | X17: 520 | AB17: 0 | AD17: PVC Type ST-2-PRESSURE EXTRUDED | AF17: 173 | AH17: Galvanised Steel Round Wire | AJ17: 2124 | AL17: FRLSH PVC Type ST-2 | AN17: 635 | AP17: Polypropylene Filler | AR17: 613 | AV17: 0 | AX17: Water swellable Tape | AZ17: 75 | BB17: Semi conducting Water Swellable tape | BD17: 0 | BH17: 45 | BL17: 0 | BP17: 0 | BR17: RUBBERIZED COTTON TAPE | BT17: 35 | BX17: 0 | BZ17: 95000 | CA17: 95000 | CH17: 95000 | CO17: 95000 | CQ17: 95000 | CR17: 0.18 | CS17: 17100 | CT17: 112100 | CU17: 25.5 | CV17: KMS | CW17: 2858550 | CX17: 250 | CY17: SP0400118 | CZ17: CORRUGATED DISPATCH STEEL DRUM 1700 X 1000 X 1200
A18: ENQ-18390-25-26 | C18: FA1300114 | D18: 3 CORE X 35 SQ. MM. AL/ARM - WIRE (XLPE) - 11 KV | H18: 0 | L18: 284 | P18: 0 | T18: 150 | X18: 384 | AB18: 0 | AF18: 122 | AJ18: 1360 | AN18: 437 | AR18: 390 | AV18: 0 | AZ18: 0 | BD18: 0 | BH18: 0 | BL18: 0 | BP18: 0 | BT18: 0 | BX18: 0 | CR18: 0.18 | CU18: 7.5 | CV18: KMS | CX18: 250
A19: ENQ-18390-25-26 | C19: FA1300120 | D19: 3 CORE X 70 SQ. MM. AL/ARM - WIRE (XLPE) - 33 KV | E19: STEEL | F19: Copper Tape - 0.045 mm | H19: 134 | J19: Alumimium | L19: 567 | P19: 0 | R19: Extruded Semiconductive | T19: 245 | V19: HT-XLPE | X19: 1561 | AB19: 0 | AD19: PVC Type ST-2-PRESSURE EXTRUDED | AF19: 280 | AH19: Galvanised Steel Round Wire | AJ19: 3818 | AL19: FRLSH PVC Type ST-2 | AN19: 1124 | AP19: Polypropylene Filler | AR19: 1267 | AV19: 0 | AX19: Water swellable Tape | AZ19: 0 | BB19: Semi conducting Water Swellable tape | BD19: 0 | BH19: 0 | BL19: 0 | BP19: 0 | BR19: RUBBERIZED COTTON TAPE | BT19: 0 | BX19: 0 | BZ19: 171000 | CA19: 171000 | CH19: 171000 | CO19: 171000 | CQ19: 171000 | CR19: 0.18 | CS19: 30780 | CT19: 201780 | CU19: 2 | CV19: KMS | CW19: 403560 | CX19: 250 | CY19: SP0400136 | CZ19: CORRUGATED DISPATCH STEEL DRUM 2200 X 1300 X 1200 MM
A20: ENQ-18390-25-26 | C20: FA1300176 | D20: 3 CORE X 150 SQ. MM. AL/ARM - WIRE (XLPE) - 11 KV | E20: STEEL | F20: Copper Tape - 0.045 mm | H20: 99 | J20: Alumimium | L20: 1215 | P20: 0 | R20: Extruded Semiconductive | T20: 246 | V20: HT-XLPE | X20: 620 | AB20: 0 | AD20: PVC Type ST-2-PRESSURE EXTRUDED | AF20: 200 | AH20: Galvanised Steel Round Wire | AJ20: 2404 | AL20: FRLSH PVC Type ST-2 | AN20: 755 | AP20: Polypropylene Filler | AR20: 809 | AV20: 0 | AX20: Water swellable Tape | AZ20: 0 | BB20: Semi conducting Water Swellable tape | BD20: 162 | BH20: 0 | BL20: 0 | BP20: 0 | BR20: RUBBERIZED COTTON TAPE | BT20: 0 | BX20: 0 | BZ20: 108300 | CA20: 108300 | CH20: 108300 | CO20: 108300 | CQ20: 108300 | CR20: 0.18 | CS20: 19494 | CT20: 127794 | CU20: 4 | CV20: KMS | CW20: 511176 | CX20: 250 | CY20: SP0400111 | CZ20: CORRUGATED DISPATCH STEEL DRUM 1900 X 1000 X 1000 MM
A21: ENQ-18390-25-26 | C21: FA1300197 | D21: 3 CORE X 120 SQ. MM. AL/ARM - WIRE (XLPE) - 11 KV | E21: STEEL | F21: Copper Tape - 0.045 mm | H21: 93 | J21: Alumimium | L21: 972 | P21: 0 | R21: Extruded Semiconductive | T21: 232 | V21: HT-XLPE | X21: 567 | AB21: 0 | AD21: PVC Type ST-2-PRESSURE EXTRUDED | AF21: 185 | AH21: Galvanised Steel Round Wire | AJ21: 2244 | AL21: FRLSH PVC Type ST-2 | AN21: 669 | AP21: Polypropylene Filler | AR21: 704 | AV21: 0 | AX21: Water swellable Tape | AZ21: 0 | BB21: Semi conducting Water Swellable tape | BD21: 59 | BH21: 0 | BL21: 0 | BP21: 0 | BR21: RUBBERIZED COTTON TAPE | BT21: 0 | BX21: 0 | BZ21: 95000 | CA21: 95000 | CH21: 95000 | CO21: 95000 | CQ21: 95000 | CR21: 0.18 | CS21: 17100 | CT21: 112100 | CU21: 8 | CV21: KMS | CW21: 896800 | CX21: 250 | CY21: SP0400118 | CZ21: CORRUGATED DISPATCH STEEL DRUM 1700 X 1000 X 1200
A22: ENQ-18390-25-26 | C22: FA1300200 | D22: 3 CORE X 95 SQ. MM. AL/ARM WIRE (XLPE) - 33 KV | E22: STEEL | F22: Copper Tape - 0.045 mm | H22: 129 | J22: Alumimium | L22: 770 | P22: 0 | R22: Extruded Semiconductive | T22: 265 | V22: HT-XLPE | X22: 1670 | AB22: 0 | AD22: PVC Type ST-2-PRESSURE EXTRUDED | AF22: 292 | AH22: Galvanised Steel Round Wire | AJ22: 3945 | AL22: FRLSH PVC Type ST-2 | AN22: 1228 | AP22: Polypropylene Filler | AR22: 1389 | AV22: 0 | AX22: Water swellable Tape | AZ22: 0 | BB22: Semi conducting Water Swellable tape | BD22: 0 | BH22: 0 | BL22: 0 | BP22: 0 | BR22: RUBBERIZED COTTON TAPE | BT22: 0 | BX22: 0 | BZ22: 147200 | CA22: 147200 | CH22: 147200 | CO22: 147200 | CQ22: 147200 | CR22: 0.18 | CS22: 26496 | CT22: 173696 | CU22: 10.5 | CV22: KMS | CW22: 1823808 | CX22: 250 | CY22: SP0400136 | CZ22: CORRUGATED DISPATCH STEEL DRUM 2200 X 1300 X 1200 MM
A23: ENQ-18390-25-26 | C23: FA1300297 | D23: 3 CORE X 35 SQ. MM. AL/ARM - WIRE (XLPE) - 33 KV (E) | E23: STEEL | F23: Copper Tape - 0.045 mm | J23: Alumimium | R23: Extruded Semiconductive | V23: HT-XLPE | AD23: PVC Type ST-2-PRESSURE EXTRUDED | AH23: Galvanised Steel Round Wire | AL23: FRLSH PVC Type ST-2 | AP23: Polypropylene Filler | AX23: Water swellable Tape | BB23: Semi conducting Water Swellable tape | BR23: RUBBERIZED COTTON TAPE | BZ23: 80000 | CA23: 80000 | CH23: 80000 | CO23: 80000 | CQ23: 80000 | CR23: 0.18 | CS23: 14400 | CT23: 94400 | CU23: 2.5 | CV23: KMS | CW23: 236000 | CX23: 250 | CY23: SP0400112 | CZ23: CORRUGATED DISPATCH STEEL DRUM 2000 X 1000 X 1000 MM
A24: ENQ-18390-25-26 | C24: FA1300313 | D24: 3 CORE X 50 SQ. MM. AL/ARD - WIRE (XLPE) - 11 KV | E24: STEEL | F24: Copper Tape - 0.045 mm | J24: Alumimium | R24: Extruded Semiconductive | V24: HT-XLPE | AD24: PVC Type ST-2 | AH24: Galvanised Steel Round Wire | AL24: FRLSH PVC Type ST-2 | AP24: Polypropylene Filler | AX24: Water swellable Tape | BB24: Semi conducting Water Swellable tape | BR24: RUBBERIZED COTTON TAPE | CR24: 0.18 | CU24: 8 | CV24: KMS | CX24: 250

Sheet AUTO CALCULATION SHEET (2)
A2: Centralized Contracts Group; TP Odisha DISCOMs TPCODL TPNODL TPSODL TPWODL (TATA Power and Odisha Government Joint Venture)
A4: TENDER SPECIFICATION NO () | B4: TPCODL / CCG / FY 25-26 / 1000008015
A5: TENDER DESCRIPTION () | B5: Two Year Rate Contract for supply of HT Cables at TPCODL, TPNODL, TPSODL & TPWODL
A6: Last Date & Time of Submission () | B6: 19.02.2026 [16:00 Hrs] OPENING ON '19.02.2026 [16:30 Hrs]
A7: REVERSE AUCTION | B7: Bidders shall be allowed to participate in Reverse auction as per following criteria hence bidders are advised to quote their most competitive rates while submitting the bids to avoid disqualification from participation in Reverse Auction. No of bidders allowed to participate in RA process shall be: Total No of bidders on whom tender would be split PLUS 2 more bidders CCG reserves the right to split the order quantity wise among 3-5 Nos of Bidders.
A8: Price () | B8: The line-item prices shall be subject to Price Variation clause as per latest IEEMA Circular. (Base Date of IEEMA for price consideration shall be Dec-25).
A9: Validity () | B9: Bids shall remain valid for 180 days from the due date of submission of the bid.
A10: Delivery Period () | B10: The delivery period for a quantity of up to 40 KM shall be 90 days from the date of issuance of the RO or GTP drawing approval, whichever is later. For quantities exceeding 40 KM, the delivery period shall be mutually agreed upon between the BA and the DISCOM. DISCOMs may also plan delivery in a staggered manner based on business requirements, as per the mutual agreement. In such cases, a month-wise delivery plan along with delivery date will be specified in the SCC of the RO.
A11: Payment Terms () | B11: 100% payment will be made within 60 days of submission of error-free certified invoice complete in all respects. For MSME payment cycle shall be within 45 days.
A12: Standard length () | B12: Cable length on one drum shall be 250 meters for 3 core cables & 500 meters for 1 core cables max. +/- 5%. (As per PO Terms.) The cable shall be supplied in continuous standard length of 250 (3 cores) & 500 (Single core) running meters with +/- 5% tolerance.
A13: Packing () | B13: Steel drums shall be provided. The cable shall be wound on non-returnable steel drums without any extra cost to TPWODL/ TPCODL/ TPNODL/ TPSODL/TPC/TPDDL/TPADL as per IS 10418 and its latest amendments.
A14: Technical Specification
N18: Conductor | V18: AL ALLOY | X18: Insulation Screening (Metallic) | AF18: Insulation Screening (Non-Metallic) | AH18: Insulation | AQ18: POLY TAPE | AR18: Inner Sheath | BA18: Armouring | BL18: Rs. 15/kg extra | BX18: FILLER | BY18: GREASE | BZ18: Water swellable Tape | CA18: Semi conducting Water Swellable tape | CB18: SEMICON TAPE | CC18: GLASS FIBER TAPE | CD18: COPPER WIRE 0.8 MM | CE18: RUBBERIZED COTTON TAPE | CF18: Water Tight Compound | CG18: DRUM TYPE | CK18: DRUM COST PER KM | CL18: TOTAL RM COST | CM18: EXTRA CONSUMPTION | CN18: EXTRA CONSUMPTION VALUE | CZ18: $A$1
A19: DOCKET NO. | B19: BASE DATE | C19: ITEM CODE | D19: PROPOSE ERP ITEM NAME | E19: EX-WORKS (PER KM) | F19: FREIGHT PER KM | G19: PRICE INCLUDING FREIGHT (PER KM) | H19: GST % | I19: GST VALUE | J19: PRICE INCLUDING GST & FREIGHT (PER KM) | K19: QTY | L19: Unit | M19: TOTAL PRICE OF FULL QTY (INCLUDING FRIGHT & GST) | N19: Alumimium | O19: Alumimium ALLOY | P19: Copper | Q19: AL-59 | R19: AL-4 | S19: AL-7 | T19: Flexible Copper | U19: Galvanized steel wire | V19: Alumimium | W19: Alumimium ALLOY | X19: Coper tape - 0.1 mm | Y19: Copper Tape - 0.03 mm | Z19: Copper Tape - 0.035 mm | AA19: Copper Tape - 0.04 mm | AB19: Copper Tape - 0.045 mm | AC19: Copper Tape - 0.050 mm | AD19: Copper Tape - 0.060 mm | AE19: Copper Tape - 0.075 mm(DOUBLE) | AF19: Extruded semiconductive | AG19: Extruded Semiconductive(Stripable) | AH19: HT-XLPE | AI19: LT-XLPE | AJ19: TR XLPE | AK19: Type A PVC | AL19: Type C PVC (HR) | AM19: Type A PVC-1.45 | AN19: Type A PVC-FR | AO19: Type A PVC-FRLS | AP19: Type A PVC-1.38 | AQ19: POLY TAPE | AR19: FR PVC Type ST-1 | AS19: FR PVC Type ST-2 | AT19: FRLSH PVC Type ST-1 | AU19: FRLSH PVC Type ST-2 | AV19: PVC Type ST-1 | AW19: PVC Type ST-1-PRESSURE EXTRUDED | AX19: PVC Type ST-2 | AY19: PVC COMPOUND 1.48 | AZ19: PVC Type ST-2-PRESSURE EXTRUDED | BA19: ACSR CORE WIRE | BB19: ACSR DOG STEEL WIRE | BC19: Aluminium Flat Strip | BD19: Aluminium Round Wire | BE19: Alumimium Tape | BF19: Double Steel Tape | BG19: Galvanised Steel Flat Strip | BH19: Galvanised Steel Flat Strip (Double) | BI19: Galvanised Steel Flat Strip-B | BJ19: Galvanised Steel Round Wire | BK19: Galvanised Steel Round Wire (Double) | BL19: FR PVC Type ST-1 | BM19: FR PVC Type ST-2 | BN19: FRLSH PVC Type ST-1 | BO19: FRLSH PVC Type ST-2 | BP19: ZHFR | BQ19: PE-ST-3 | BR19: PE-ST-7 | BS19: PVC Type ST-1 | BT19: PVC Type ST-2 | BU19: PVC COMPOUND 1.48 | BV19: PVC Type ST-2-PRESSURE EXTRUDED | BW19: UV & Track Resistant XLPE | BX19: PP FILLER | BY19: NCWBT | BZ19: Water swellable Tape | CA19: Semi conducting Water Swellable tape | CB19: SEMICON TAPE | CC19: GLASS FIBER TAPE | CD19: COPPER WIRE 0.8 MM | CE19: RUBBERIZED COTTON TAPE | CF19: Water Tight Compound | CG19: PROPOSE DRUM TYPE | CH19: DRUM CODE | CI19: DRUM SIZE (FxbXtx Ft) | CJ19: PARTY STANDARD LENGTH (MTR) | CM19: Consider 1% extra cost for complete cable . | CN19: Consider 1% extra cost for complete cable . | CO19: MFG% | CP19: MFG VALUE | CQ19: PROF% | CR19: PROFIT VALUE | CS19: 1ST EX-WORKS | CT19: Intt % | CU19: INTT VALUE | CV19: insp% | CW19: INSP VALUE | CX19: TTR Charges% | CY19: TTR Charges VALUE
N20: 299 | O20: =+IFERROR(VLOOKUP($O$19,Sheet1!J:L,2,0),0) -> 0 | P20: =+IFERROR(VLOOKUP($P$19,Sheet1!J:M,2,0),0) -> 0 | Q20: =+IFERROR(VLOOKUP($Q$19,Sheet1!J:M,2,0),0) -> 0 | R20: =+IFERROR(VLOOKUP($R$19,Sheet1!J:M,2,0),0) -> 0 | S20: =+IFERROR(VLOOKUP($S$19,Sheet1!J:M,2,0),0) -> 0 | T20: =+IFERROR(VLOOKUP($T$19,Sheet1!J:M,2,0),0) -> 0 | U20: =+IFERROR(VLOOKUP($U$19,Sheet1!J:M,2,0),0) -> 0 | V20: =+IFERROR(VLOOKUP($V$19,Sheet1!N:Q,2,0),0) -> 0 | W20: =+IFERROR(VLOOKUP($W$19,Sheet1!N:O,2,0),0) -> 0 | X20: =+IFERROR(VLOOKUP($X$19,Sheet1!F:I,2,0),0) -> 0 | Y20: =+IFERROR(VLOOKUP($Y$19,Sheet1!F:I,2,0),0) -> 0 | Z20: =+IFERROR(VLOOKUP($Z$19,Sheet1!F:I,2,0),0) -> 0 | AA20: =+IFERROR(VLOOKUP($AA$19,Sheet1!F:I,2,0),0) -> 0 | AB20: 1211 | AC20: =+IFERROR(VLOOKUP($AC$19,Sheet1!F:I,2,0),0) -> 0 | AD20: =+IFERROR(VLOOKUP($AD$19,Sheet1!F:I,2,0),0) -> 0 | AE20: =+IFERROR(VLOOKUP($AE$19,Sheet1!F:I,2,0),0) -> 0 | AF20: 162 | AG20: =+IFERROR(VLOOKUP($AG$19,Sheet1!R:U,2,0),0) -> 0 | AH20: 125 | AI20: =+IFERROR(VLOOKUP($AI$19,Sheet1!V:Y,2,0),0) -> 0 | AJ20: =+IFERROR(VLOOKUP($AJ$19,Sheet1!V:Y,2,0),0) -> 0 | AK20: =+IFERROR(VLOOKUP($AK$19,Sheet1!V:Y,2,0),0) -> 0 | AL20: =+IFERROR(VLOOKUP($AL$19,Sheet1!V:Y,2,0),0) -> 0 | AM20: =+IFERROR(VLOOKUP($AM$19,Sheet1!V:Y,2,0),0) -> 0 | AN20: =+IFERROR(VLOOKUP($AN$19,Sheet1!V:Y,2,0),0) -> 0 | AO20: =+IFERROR(VLOOKUP($AO$19,Sheet1!V:Y,2,0),0) -> 0 | AP20: =+IFERROR(VLOOKUP($AP$19,Sheet1!V:Y,2,0),0) -> 0 | AQ20: 109 | AR20: =+IFERROR(VLOOKUP($AR$19,Sheet1!AD2:AG840,2,0),0) -> 0 | AS20: =+IFERROR(VLOOKUP($AS$19,Sheet1!AD2:AG840,2,0),0) -> 0 | AT20: =+IFERROR(VLOOKUP($AT$19,Sheet1!AD2:AG840,2,0),0) -> 0 | AU20: =+IFERROR(VLOOKUP($AU$19,Sheet1!AD2:AG840,2,0),0) -> 0 | AV20: =+IFERROR(VLOOKUP($AV$19,Sheet1!AD2:AG840,2,0),0) -> 0 | AW20: =+IFERROR(VLOOKUP($AW$19,Sheet1!AD2:AG840,2,0),0) -> 0 | AX20: 59 | AY20: =+IFERROR(VLOOKUP($AY$19,Sheet1!AD2:AG840,2,0),0) -> 0 | AZ20: =+IFERROR(VLOOKUP($AZ$19,Sheet1!AD2:AG840,2,0),0) -> 0 | BA20: =+IFERROR(VLOOKUP($BA$19,Sheet1!AH2:AK840,2,0),0) -> 0 | BB20: =+IFERROR(VLOOKUP($BB$19,Sheet1!AH2:AK840,2,0),0) -> 0 | BC20: =+IFERROR(VLOOKUP($BC$19,Sheet1!AH2:AK840,2,0),0) -> 0 | BD20: =N20+5 -> 304 | BE20: =+IFERROR(VLOOKUP($BE$19,Sheet1!AH2:AK840,2,0),0) -> 0 | BF20: =+IFERROR(VLOOKUP($BF$19,Sheet1!AH2:AK840,2,0),0) -> 0 | BG20: =+IFERROR(VLOOKUP($BG$19,Sheet1!AH2:AK840,2,0),0) -> 0 | BH20: =+IFERROR(VLOOKUP($BH$19,Sheet1!AH2:AK840,2,0),0) -> 0 | BI20: =+IFERROR(VLOOKUP($BI$19,Sheet1!AH2:AK840,2,0),0) -> 0 | BJ20: 81 | BK20: =+IFERROR(VLOOKUP($BK$19,Sheet1!AH2:AK840,2,0),0) -> 0 | BL20: =+IFERROR(VLOOKUP($BL$19,Sheet1!AL2:AO840,2,0),0) -> 0 | BM20: =+IFERROR(VLOOKUP($BM$19,Sheet1!AL2:AO840,2,0),0) -> 0 | BN20: =+IFERROR(VLOOKUP($BN$19,Sheet1!AL2:AO840,2,0),0) -> 0 | BO20: =76+15 -> 91 | BP20: =+IFERROR(VLOOKUP($BP$19,Sheet1!AL2:AO840,2,0),0) -> 0 | BQ20: =+IFERROR(VLOOKUP($BQ$19,Sheet1!AL2:AO840,2,0),0) -> 0 | BR20: =+IFERROR(VLOOKUP($BR$19,Sheet1!AL2:AO840,2,0),0) -> 0 | BS20: =+IFERROR(VLOOKUP($BS$19,Sheet1!AL2:AO840,2,0),0) -> 0 | BT20: =+IFERROR(VLOOKUP($BT$19,Sheet1!AL2:AO840,2,0),0) -> 0 | BU20: =+IFERROR(VLOOKUP($BU$19,Sheet1!AL2:AO840,2,0),0) -> 0 | BV20: =+IFERROR(VLOOKUP($BV$19,Sheet1!AL2:AO840,2,0),0) -> 0 | BW20: =+IFERROR(VLOOKUP($BW$19,Sheet1!AL2:AO840,2,0),0) -> 0 | BX20: 75 | BY20: 310 | BZ20: =+IFERROR(VLOOKUP($BZ$19,Sheet1!AX2:BA840,2,0),0) -> 0 | CA20: 393 | CB20: =+IFERROR(VLOOKUP($CB$19,Sheet1!BF2:BI840,2,0),0) -> 0 | CC20: =+IFERROR(VLOOKUP($CC$19,Sheet1!BJ2:BM840,2,0),0) -> 0 | CD20: =+IFERROR(VLOOKUP($CD$19,Sheet1!BN2:BQ840,2,0),0) -> 0 | CE20: 284 | CF20: =+IFERROR(VLOOKUP($CF$19,Sheet1!BV2:BY840,2,0),0) -> 0 | CI20: NON RETURNABLE STEEL DRUM
A21: =Sheet1!A13 -> ENQ-18390-25-26 | B21: 46357 | C21: =Sheet1!C13 -> FA1300083 | D21: =Sheet1!D13 -> 3 CORE X 400 SQ. MM. AL/ARM - WIRE (XLPE) - 11 KV | E21: =CS21+CU21+CW21+CY21 -> 2800573.7 | F21: =ROUNDUP(M49,0) -> 58278 | G21: =E21+F21 -> 2858851.7 | H21: =Sheet1!CR13 -> 0.18 | I21: =G21*H21 -> 514593.31 | J21: =G21+I21 -> 3373445.1 | K21: =Sheet1!CU13 -> 209 | L21: =Sheet1!CV13 -> KMS | M21: =J21*K21 -> 7.0505002e+08 | N21: =+IFERROR(VLOOKUP($N$19,Sheet1!J13:L13,3,0),0) -> 3240 | O21: =+IFERROR(VLOOKUP($O$19,Sheet1!J13:L13,3,0),0) -> 0 | P21: =+IFERROR(VLOOKUP($P$19,Sheet1!J13:M13,3,0),0) -> 0 | Q21: =+IFERROR(VLOOKUP($Q$19,Sheet1!J13:M13,3,0),0) -> 0 | R21: =+IFERROR(VLOOKUP($R$19,Sheet1!J13:M13,3,0),0) -> 0 | S21: =+IFERROR(VLOOKUP($S$19,Sheet1!J13:M13,3,0),0) -> 0 | T21: =+IFERROR(VLOOKUP($T$19,Sheet1!J13:M13,3,0),0) -> 0 | U21: =+IFERROR(VLOOKUP($U$19,Sheet1!J13:M13,3,0),0) -> 0 | V21: =+IFERROR(VLOOKUP($V$19,Sheet1!N13:Q13,3,0),0) -> 0 | W21: =+IFERROR(VLOOKUP($W$19,Sheet1!N13:Q13,3,0),0) -> 0 | X21: =+IFERROR(VLOOKUP($X$19,Sheet1!F13:I13,3,0),0) -> 0 | Y21: =+IFERROR(VLOOKUP($Y$19,Sheet1!F13:I13,3,0),0) -> 0 | Z21: =+IFERROR(VLOOKUP($Z$19,Sheet1!F13:I13,3,0),0) -> 0 | AA21: =+IFERROR(VLOOKUP($AA$19,Sheet1!F13:I13,3,0),0) -> 0 | AB21: 176 | AC21: =+IFERROR(VLOOKUP($AC$19,Sheet1!F13:I13,3,0),0) -> 0 | AD21: =+IFERROR(VLOOKUP($AD$19,Sheet1!F13:I13,3,0),0) -> 0 | AE21: =+IFERROR(VLOOKUP($AE$19,Sheet1!F13:I13,3,0),0) -> 0 | AF21: 518 | AG21: =+IFERROR(VLOOKUP($AG$19,Sheet1!R13:U13,3,0),0) -> 0 | AH21: 930 | AI21: =+IFERROR(VLOOKUP($AI$19,Sheet1!V13:Y13,3,0),0) -> 0 | AJ21: =+IFERROR(VLOOKUP($AJ$19,Sheet1!V13:Y13,3,0),0) -> 0 | AK21: =+IFERROR(VLOOKUP($AK$19,Sheet1!V13:Y13,3,0),0) -> 0 | AL21: =+IFERROR(VLOOKUP($AL$19,Sheet1!V13:Y13,3,0),0) -> 0 | AM21: =+IFERROR(VLOOKUP($AM$19,Sheet1!V13:Y13,3,0),0) -> 0 | AN21: =+IFERROR(VLOOKUP($AN$19,Sheet1!V13:Y13,3,0),0) -> 0 | AO21: =+IFERROR(VLOOKUP($AO$19,Sheet1!V13:Y13,3,0),0) -> 0 | AP21: =+IFERROR(VLOOKUP($AP$19,Sheet1!V13:Y13,3,0),0) -> 0 | AQ21: =+IFERROR(VLOOKUP($AQ$19,Sheet1!Z13:AB13,3,0),0) -> 0 | AR21: =+IFERROR(VLOOKUP($AR$19,Sheet1!AD13:AG13,3,0),0) -> 0 | AS21: =+IFERROR(VLOOKUP($AS$19,Sheet1!AD13:AG13,3,0),0) -> 0 | AT21: =+IFERROR(VLOOKUP($AT$19,Sheet1!AD13:AG13,3,0),0) -> 0 | AU21: =+IFERROR(VLOOKUP($AU$19,Sheet1!AD13:AG13,3,0),0) -> 0 | AV21: =+IFERROR(VLOOKUP($AV$19,Sheet1!AD13:AG13,3,0),0) -> 0 | AW21: =+IFERROR(VLOOKUP($AW$19,Sheet1!AD13:AG13,3,0),0) -> 0 | AX21: 1130 | AY21: =+IFERROR(VLOOKUP($AY$19,Sheet1!AD13:AG13,3,0),0) -> 0 | BA21: =+IFERROR(VLOOKUP($BA$19,Sheet1!AH13:AK13,3,0),0) -> 0 | BB21: =+IFERROR(VLOOKUP($BB$19,Sheet1!AH13:AK13,3,0),0) -> 0 | BC21: =+IFERROR(VLOOKUP($BC$19,Sheet1!AH13:AK13,3,0),0) -> 0 | BD21: =+IFERROR(VLOOKUP($BD$19,Sheet1!AH13:AK13,3,0),0) -> 0 | BE21: =+IFERROR(VLOOKUP($BE$19,Sheet1!AH13:AK13,3,0),0) -> 0 | BF21: =+IFERROR(VLOOKUP($BF$19,Sheet1!AH13:AK13,3,0),0) -> 0 | BG21: =+IFERROR(VLOOKUP($BG$19,Sheet1!AH13:AK13,3,0),0) -> 0 | BH21: =+IFERROR(VLOOKUP($BH$19,Sheet1!AH13:AK13,3,0),0) -> 0 | BI21: =+IFERROR(VLOOKUP($BI$19,Sheet1!AH13:AK13,3,0),0) -> 0 | BJ21: 5643 | BK21: =+IFERROR(VLOOKUP($BK$19,Sheet1!AH13:AK13,3,0),0) -> 0 | BL21: =+IFERROR(VLOOKUP($BL$19,Sheet1!AL13:AO13,3,0),0) -> 0 | BM21: =+IFERROR(VLOOKUP($BM$19,Sheet1!AL13:AO13,3,0),0) -> 0 | BN21: =+IFERROR(VLOOKUP($BN$19,Sheet1!AL13:AO13,3,0),0) -> 0 | BO21: 1377 | BP21: =+IFERROR(VLOOKUP($BP$19,Sheet1!AL13:AO13,3,0),0) -> 0 | BQ21: =+IFERROR(VLOOKUP($BQ$19,Sheet1!AL13:AO13,3,0),0) -> 0 | BR21: =+IFERROR(VLOOKUP($BR$19,Sheet1!AL13:AO13,3,0),0) -> 0 | BS21: =+IFERROR(VLOOKUP($BS$19,Sheet1!AL13:AO13,3,0),0) -> 0 | BT21: =+IFERROR(VLOOKUP($BT$19,Sheet1!AL13:AO13,3,0),0) -> 0 | BU21: =+IFERROR(VLOOKUP($BU$19,Sheet1!AL13:AO13,3,0),0) -> 0 | BV21: =+IFERROR(VLOOKUP($BV$19,Sheet1!AL13:AO13,3,0),0) -> 0 | BW21: =+IFERROR(VLOOKUP($BW$19,Sheet1!AL13:AO13,3,0),0) -> 0 | BX21: 1032 | BY21: 58 | BZ21: =+IFERROR(VLOOKUP($BZ$19,Sheet1!AX13:BA13,3,0),0) -> 0 | CA21: 95 | CB21: =+IFERROR(VLOOKUP($CB$19,Sheet1!BF13:BI13,3,0),0) -> 0 | CC21: =+IFERROR(VLOOKUP($CC$19,Sheet1!BJ13:BM13,3,0),0) -> 0 | CD21: =+IFERROR(VLOOKUP($CD$19,Sheet1!BN13:BQ13,3,0),0) -> 0 | CE21: 60 | CF21: =+IFERROR(VLOOKUP($CF$19,Sheet1!BV13:BY13,3,0),0) -> 0 | CG21: =Sheet1!E13 -> STEEL | CH21: SP0400136 | CI21: CORRUGATED DISPATCH STEEL DRUM 2200 X 1300 X 1200 MM | CJ21: =Sheet1!CX13 -> 250 | CK21: =26000/0.25 -> 104000 | CL21: =SUMPRODUCT($N$20:$CF$20,N21:CF21)+CK21 -> 2284877 | CM21: 0.01 | CN21: =CL21*CM21 -> 22848.77 | CO21: 0.18 | CP21: =CL21*CO21 -> 411277.86 | CQ21: =Sheet1!CF13 -> 0 | CR21: =CL21*CQ21 -> 0 | CS21: =CL21+CN21+CP21+CR21 -> 2719003.6 | CT21: 0.02 | CU21: =CS21*CT21 -> 54380.073 | CV21: 0.01 | CW21: =CS21*CV21 -> 27190.036 | CX21: =Sheet1!CM13 -> 0 | CY21: =CX21*CS21 -> 0
A22: =Sheet1!A15 -> ENQ-18390-25-26 | B22: 46357 | C22: =Sheet1!C15 -> FA1300091 | D22: =Sheet1!D15 -> 3 CORE X 300 SQ. MM. AL/ARM - WIRE (XLPE) - 11 KV | E22: =CS22+CU22+CW22+CY22 -> 2238616 | F22: =ROUNDUP(M50,0) -> 58097 | G22: =E22+F22 -> 2296713 | H22: =Sheet1!CR15 -> 0.18 | I22: =G22*H22 -> 413408.35 | J22: =G22+I22 -> 2710121.4 | K22: =Sheet1!CU15 -> 151 | L22: =Sheet1!CV15 -> KMS | M22: =J22*K22 -> 4.0922833e+08 | N22: =+IFERROR(VLOOKUP($N$19,Sheet1!J15:L15,3,0),0) -> 2430 | O22: =+IFERROR(VLOOKUP($O$19,Sheet1!J15:L15,3,0),0) -> 0 | P22: =+IFERROR(VLOOKUP($P$19,Sheet1!J15:M15,3,0),0) -> 0 | Q22: =+IFERROR(VLOOKUP($Q$19,Sheet1!J15:M15,3,0),0) -> 0 | R22: =+IFERROR(VLOOKUP($R$19,Sheet1!J15:M15,3,0),0) -> 0 | S22: =+IFERROR(VLOOKUP($S$19,Sheet1!J15:M15,3,0),0) -> 0 | T22: =+IFERROR(VLOOKUP($T$19,Sheet1!J15:M15,3,0),0) -> 0 | U22: =+IFERROR(VLOOKUP($U$19,Sheet1!J15:M15,3,0),0) -> 0 | V22: =+IFERROR(VLOOKUP($V$19,Sheet1!N15:Q15,3,0),0) -> 0 | W22: =+IFERROR(VLOOKUP($W$19,Sheet1!N15:Q15,3,0),0) -> 0 | X22: =+IFERROR(VLOOKUP($X$19,Sheet1!F15:I15,3,0),0) -> 0 | Y22: =+IFERROR(VLOOKUP($Y$19,Sheet1!F15:I15,3,0),0) -> 0 | Z22: =+IFERROR(VLOOKUP($Z$19,Sheet1!F15:I15,3,0),0) -> 0 | AA22: =+IFERROR(VLOOKUP($AA$19,Sheet1!F15:I15,3,0),0) -> 0 | AB22: 161 | AC22: =+IFERROR(VLOOKUP($AC$19,Sheet1!F15:I15,3,0),0) -> 0 | AD22: =+IFERROR(VLOOKUP($AD$19,Sheet1!F15:I15,3,0),0) -> 0 | AE22: =+IFERROR(VLOOKUP($AE$19,Sheet1!F15:I15,3,0),0) -> 0 | AF22: 465 | AG22: =+IFERROR(VLOOKUP($AG$19,Sheet1!R15:U15,3,0),0) -> 0 | AH22: 835 | AI22: =+IFERROR(VLOOKUP($AI$19,Sheet1!V15:Y15,3,0),0) -> 0 | AJ22: =+IFERROR(VLOOKUP($AJ$19,Sheet1!V15:Y15,3,0),0) -> 0 | AK22: =+IFERROR(VLOOKUP($AK$19,Sheet1!V15:Y15,3,0),0) -> 0 | AL22: =+IFERROR(VLOOKUP($AL$19,Sheet1!V15:Y15,3,0),0) -> 0 | AM22: =+IFERROR(VLOOKUP($AM$19,Sheet1!V15:Y15,3,0),0) -> 0 | AN22: =+IFERROR(VLOOKUP($AN$19,Sheet1!V15:Y15,3,0),0) -> 0 | AO22: =+IFERROR(VLOOKUP($AO$19,Sheet1!V15:Y15,3,0),0) -> 0 | AP22: =+IFERROR(VLOOKUP($AP$19,Sheet1!V15:Y15,3,0),0) -> 0 | AQ22: =+IFERROR(VLOOKUP($AQ$19,Sheet1!Z15:AB15,3,0),0) -> 0 | AR22: =+IFERROR(VLOOKUP($AR$19,Sheet1!AD15:AG15,3,0),0) -> 0 | AS22: =+IFERROR(VLOOKUP($AS$19,Sheet1!AD15:AG15,3,0),0) -> 0 | AT22: =+IFERROR(VLOOKUP($AT$19,Sheet1!AD15:AG15,3,0),0) -> 0 | AU22: =+IFERROR(VLOOKUP($AU$19,Sheet1!AD15:AG15,3,0),0) -> 0 | AV22: =+IFERROR(VLOOKUP($AV$19,Sheet1!AD15:AG15,3,0),0) -> 0 | AW22: =+IFERROR(VLOOKUP($AW$19,Sheet1!AD15:AG15,3,0),0) -> 0 | AX22: 974 | AY22: =+IFERROR(VLOOKUP($AY$19,Sheet1!AD15:AG15,3,0),0) -> 0 | BA22: =+IFERROR(VLOOKUP($BA$19,Sheet1!AH15:AK15,3,0),0) -> 0 | BB22: =+IFERROR(VLOOKUP($BB$19,Sheet1!AH15:AK15,3,0),0) -> 0 | BC22: =+IFERROR(VLOOKUP($BC$19,Sheet1!AH15:AK15,3,0),0) -> 0 | BD22: =+IFERROR(VLOOKUP($BD$19,Sheet1!AH15:AK15,3,0),0) -> 0 | BE22: =+IFERROR(VLOOKUP($BE$19,Sheet1!AH15:AK15,3,0),0) -> 0 | BF22: =+IFERROR(VLOOKUP($BF$19,Sheet1!AH15:AK15,3,0),0) -> 0 | BG22: =+IFERROR(VLOOKUP($BG$19,Sheet1!AH15:AK15,3,0),0) -> 0 | BH22: =+IFERROR(VLOOKUP($BH$19,Sheet1!AH15:AK15,3,0),0) -> 0 | BI22: =+IFERROR(VLOOKUP($BI$19,Sheet1!AH15:AK15,3,0),0) -> 0 | BJ22: 4072 | BK22: =+IFERROR(VLOOKUP($BK$19,Sheet1!AH15:AK15,3,0),0) -> 0 | BL22: =+IFERROR(VLOOKUP($BL$19,Sheet1!AL15:AO15,3,0),0) -> 0 | BM22: =+IFERROR(VLOOKUP($BM$19,Sheet1!AL15:AO15,3,0),0) -> 0 | BN22: =+IFERROR(VLOOKUP($BN$19,Sheet1!AL15:AO15,3,0),0) -> 0 | BO22: 1190 | BP22: =+IFERROR(VLOOKUP($BP$19,Sheet1!AL15:AO15,3,0),0) -> 0 | BQ22: =+IFERROR(VLOOKUP($BQ$19,Sheet1!AL15:AO15,3,0),0) -> 0 | BR22: =+IFERROR(VLOOKUP($BR$19,Sheet1!AL15:AO15,3,0),0) -> 0 | BS22: =+IFERROR(VLOOKUP($BS$19,Sheet1!AL15:AO15,3,0),0) -> 0 | BT22: =+IFERROR(VLOOKUP($BT$19,Sheet1!AL15:AO15,3,0),0) -> 0 | BU22: =+IFERROR(VLOOKUP($BU$19,Sheet1!AL15:AO15,3,0),0) -> 0 | BV22: =+IFERROR(VLOOKUP($BV$19,Sheet1!AL15:AO15,3,0),0) -> 0 | BW22: =+IFERROR(VLOOKUP($BW$19,Sheet1!AL15:AO15,3,0),0) -> 0 | BX22: 862 | BY22: 38 | BZ22: =+IFERROR(VLOOKUP($BZ$19,Sheet1!AX15:BA15,3,0),0) -> 0 | CA22: 86 | CB22: =+IFERROR(VLOOKUP($CB$19,Sheet1!BF15:BI15,3,0),0) -> 0 | CC22: =+IFERROR(VLOOKUP($CC$19,Sheet1!BJ15:BM15,3,0),0) -> 0 | CD22: =+IFERROR(VLOOKUP($CD$19,Sheet1!BN15:BQ15,3,0),0) -> 0 | CE22: 54 | CF22: =+IFERROR(VLOOKUP($CF$19,Sheet1!BV15:BY15,3,0),0) -> 0 | CG22: =Sheet1!E15 -> STEEL | CH22: SP0400136 | CI22: CORRUGATED DISPATCH STEEL DRUM 2200 X 1300 X 1200 MM | CJ22: =Sheet1!CX15 -> 250 | CK22: =26000/0.25 -> 104000 | CL22: =SUMPRODUCT($N$20:$CF$20,N22:CF22)+CK22 -> 1826398 | CM22: 0.01 | CN22: =CL22*CM22 -> 18263.98 | CO22: 0.18 | CP22: =CL22*CO22 -> 328751.64 | CQ22: =Sheet1!CF15 -> 0 | CR22: =CL22*CQ22 -> 0 | CS22: =CL22+CN22+CP22+CR22 -> 2173413.6 | CT22: 0.02 | CU22: =CS22*CT22 -> 43468.272 | CV22: 0.01 | CW22: =CS22*CV22 -> 21734.136 | CX22: =Sheet1!CM15 -> 0 | CY22: =CX22*CS22 -> 0
A23: =Sheet1!A14 -> ENQ-18390-25-26 | B23: 46357 | C23: =Sheet1!C14 -> FA1300090 | D23: =Sheet1!D14 -> 3 CORE X 185 SQ. MM AL/ARM - WIRE (XLPE) - 11 KV | E23: =CS23+CU23+CW23+CY23 -> 1652693.4 | F23: =ROUNDUP(M51,0) -> 34118 | G23: =E23+F23 -> 1686811.4 | H23: =Sheet1!CR14 -> 0.18 | I23: =G23*H23 -> 303626.06 | J23: =G23+I23 -> 1990437.5 | K23: =Sheet1!CU14 -> 17 | L23: =Sheet1!CV14 -> KMS | M23: =J23*K23 -> 33837437 | N23: =+IFERROR(VLOOKUP($N$19,Sheet1!J14:L14,3,0),0) -> 1499 | O23: =+IFERROR(VLOOKUP($O$19,Sheet1!J14:L14,3,0),0) -> 0 | P23: =+IFERROR(VLOOKUP($P$19,Sheet1!J14:M14,3,0),0) -> 0 | Q23: =+IFERROR(VLOOKUP($Q$19,Sheet1!J14:M14,3,0),0) -> 0 | R23: =+IFERROR(VLOOKUP($R$19,Sheet1!J14:M14,3,0),0) -> 0 | S23: =+IFERROR(VLOOKUP($S$19,Sheet1!J14:M14,3,0),0) -> 0 | T23: =+IFERROR(VLOOKUP($T$19,Sheet1!J14:M14,3,0),0) -> 0 | U23: =+IFERROR(VLOOKUP($U$19,Sheet1!J14:M14,3,0),0) -> 0 | V23: =+IFERROR(VLOOKUP($V$19,Sheet1!N14:Q14,3,0),0) -> 0 | W23: =+IFERROR(VLOOKUP($W$19,Sheet1!N14:Q14,3,0),0) -> 0 | X23: =+IFERROR(VLOOKUP($X$19,Sheet1!F14:I14,3,0),0) -> 0 | Y23: =+IFERROR(VLOOKUP($Y$19,Sheet1!F14:I14,3,0),0) -> 0 | Z23: =+IFERROR(VLOOKUP($Z$19,Sheet1!F14:I14,3,0),0) -> 0 | AA23: =+IFERROR(VLOOKUP($AA$19,Sheet1!F14:I14,3,0),0) -> 0 | AB23: 138 | AC23: =+IFERROR(VLOOKUP($AC$19,Sheet1!F14:I14,3,0),0) -> 0 | AD23: =+IFERROR(VLOOKUP($AD$19,Sheet1!F14:I14,3,0),0) -> 0 | AE23: =+IFERROR(VLOOKUP($AE$19,Sheet1!F14:I14,3,0),0) -> 0 | AF23: 387 | AG23: =+IFERROR(VLOOKUP($AG$19,Sheet1!R14:U14,3,0),0) -> 0 | AH23: 693 | AI23: =+IFERROR(VLOOKUP($AI$19,Sheet1!V14:Y14,3,0),0) -> 0 | AJ23: =+IFERROR(VLOOKUP($AJ$19,Sheet1!V14:Y14,3,0),0) -> 0 | AK23: =+IFERROR(VLOOKUP($AK$19,Sheet1!V14:Y14,3,0),0) -> 0 | AL23: =+IFERROR(VLOOKUP($AL$19,Sheet1!V14:Y14,3,0),0) -> 0 | AM23: =+IFERROR(VLOOKUP($AM$19,Sheet1!V14:Y14,3,0),0) -> 0 | AN23: =+IFERROR(VLOOKUP($AN$19,Sheet1!V14:Y14,3,0),0) -> 0 | AO23: =+IFERROR(VLOOKUP($AO$19,Sheet1!V14:Y14,3,0),0) -> 0 | AP23: =+IFERROR(VLOOKUP($AP$19,Sheet1!V14:Y14,3,0),0) -> 0 | AQ23: =+IFERROR(VLOOKUP($AQ$19,Sheet1!Z14:AB14,3,0),0) -> 0 | AR23: =+IFERROR(VLOOKUP($AR$19,Sheet1!AD14:AG14,3,0),0) -> 0 | AS23: =+IFERROR(VLOOKUP($AS$19,Sheet1!AD14:AG14,3,0),0) -> 0 | AT23: =+IFERROR(VLOOKUP($AT$19,Sheet1!AD14:AG14,3,0),0) -> 0 | AU23: =+IFERROR(VLOOKUP($AU$19,Sheet1!AD14:AG14,3,0),0) -> 0 | AV23: =+IFERROR(VLOOKUP($AV$19,Sheet1!AD14:AG14,3,0),0) -> 0 | AW23: =+IFERROR(VLOOKUP($AW$19,Sheet1!AD14:AG14,3,0),0) -> 0 | AX23: 809 | AY23: =+IFERROR(VLOOKUP($AY$19,Sheet1!AD14:AG14,3,0),0) -> 0 | BA23: =+IFERROR(VLOOKUP($BA$19,Sheet1!AH14:AK14,3,0),0) -> 0 | BB23: =+IFERROR(VLOOKUP($BB$19,Sheet1!AH14:AK14,3,0),0) -> 0 | BC23: =+IFERROR(VLOOKUP($BC$19,Sheet1!AH14:AK14,3,0),0) -> 0 | BD23: =+IFERROR(VLOOKUP($BD$19,Sheet1!AH14:AK14,3,0),0) -> 0 | BE23: =+IFERROR(VLOOKUP($BE$19,Sheet1!AH14:AK14,3,0),0) -> 0 | BF23: =+IFERROR(VLOOKUP($BF$19,Sheet1!AH14:AK14,3,0),0) -> 0 | BG23: =+IFERROR(VLOOKUP($BG$19,Sheet1!AH14:AK14,3,0),0) -> 0 | BH23: =+IFERROR(VLOOKUP($BH$19,Sheet1!AH14:AK14,3,0),0) -> 0 | BI23: =+IFERROR(VLOOKUP($BI$19,Sheet1!AH14:AK14,3,0),0) -> 0 | BJ23: 3500 | BK23: =+IFERROR(VLOOKUP($BK$19,Sheet1!AH14:AK14,3,0),0) -> 0 | BL23: =+IFERROR(VLOOKUP($BL$19,Sheet1!AL14:AO14,3,0),0) -> 0 | BM23: =+IFERROR(VLOOKUP($BM$19,Sheet1!AL14:AO14,3,0),0) -> 0 | BN23: =+IFERROR(VLOOKUP($BN$19,Sheet1!AL14:AO14,3,0),0) -> 0 | BO23: 945 | BP23: =+IFERROR(VLOOKUP($BP$19,Sheet1!AL14:AO14,3,0),0) -> 0 | BQ23: =+IFERROR(VLOOKUP($BQ$19,Sheet1!AL14:AO14,3,0),0) -> 0 | BR23: =+IFERROR(VLOOKUP($BR$19,Sheet1!AL14:AO14,3,0),0) -> 0 | BS23: =+IFERROR(VLOOKUP($BS$19,Sheet1!AL14:AO14,3,0),0) -> 0 | BT23: =+IFERROR(VLOOKUP($BT$19,Sheet1!AL14:AO14,3,0),0) -> 0 | BU23: =+IFERROR(VLOOKUP($BU$19,Sheet1!AL14:AO14,3,0),0) -> 0 | BV23: =+IFERROR(VLOOKUP($BV$19,Sheet1!AL14:AO14,3,0),0) -> 0 | BW23: =+IFERROR(VLOOKUP($BW$19,Sheet1!AL14:AO14,3,0),0) -> 0 | BX23: 615 | BY23: 35 | BZ23: =+IFERROR(VLOOKUP($BZ$19,Sheet1!AX14:BA14,3,0),0) -> 0 | CA23: 72 | CB23: =+IFERROR(VLOOKUP($CB$19,Sheet1!BF14:BI14,3,0),0) -> 0 | CC23: =+IFERROR(VLOOKUP($CC$19,Sheet1!BJ14:BM14,3,0),0) -> 0 | CD23: =+IFERROR(VLOOKUP($CD$19,Sheet1!BN14:BQ14,3,0),0) -> 0 | CE23: 48 | CF23: =+IFERROR(VLOOKUP($CF$19,Sheet1!BV14:BY14,3,0),0) -> 0 | CG23: =Sheet1!E14 -> STEEL | CH23: SP0400111 | CI23: CORRUGATED DISPATCH STEEL DRUM 1900 X 1000 X 1000 MM | CJ23: =Sheet1!CX14 -> 250 | CK23: =16900/0.25 -> 67600 | CL23: =SUMPRODUCT($N$20:$CF$20,N23:CF23)+CK23 -> 1348367 | CM23: 0.01 | CN23: =CL23*CM23 -> 13483.67 | CO23: 0.18 | CP23: =CL23*CO23 -> 242706.06 | CQ23: =Sheet1!CF14 -> 0 | CR23: =CL23*CQ23 -> 0 | CS23: =CL23+CN23+CP23+CR23 -> 1604556.7 | CT23: 0.02 | CU23: =CS23*CT23 -> 32091.135 | CV23: 0.01 | CW23: =CS23*CV23 -> 16045.567 | CX23: =Sheet1!CM14 -> 0 | CY23: =CX23*CS23 -> 0
A24: =Sheet1!A20 -> ENQ-18390-25-26 | B24: 46357 | C24: =Sheet1!C20 -> FA1300176 | D24: =Sheet1!D20 -> 3 CORE X 150 SQ. MM. AL/ARM - WIRE (XLPE) - 11 KV | E24: =CS24+CU24+CW24+CY24 -> 1369163.3 | F24: =ROUNDUP(M52,0) -> 36250 | G24: =E24+F24 -> 1405413.3 | H24: =Sheet1!CR20 -> 0.18 | I24: =G24*H24 -> 252974.39 | J24: =G24+I24 -> 1658387.7 | K24: =Sheet1!CU20 -> 4 | L24: =Sheet1!CV20 -> KMS | M24: =J24*K24 -> 6633550.7 | N24: =+IFERROR(VLOOKUP($N$19,Sheet1!J20:L20,3,0),0) -> 1215 | O24: =+IFERROR(VLOOKUP($O$19,Sheet1!J20:L20,3,0),0) -> 0 | P24: =+IFERROR(VLOOKUP($P$19,Sheet1!J20:M20,3,0),0) -> 0 | Q24: =+IFERROR(VLOOKUP($Q$19,Sheet1!J20:M20,3,0),0) -> 0 | R24: =+IFERROR(VLOOKUP($R$19,Sheet1!J20:M20,3,0),0) -> 0 | S24: =+IFERROR(VLOOKUP($S$19,Sheet1!J20:M20,3,0),0) -> 0 | T24: =+IFERROR(VLOOKUP($T$19,Sheet1!J20:M20,3,0),0) -> 0 | U24: =+IFERROR(VLOOKUP($U$19,Sheet1!J20:M20,3,0),0) -> 0 | V24: =+IFERROR(VLOOKUP($V$19,Sheet1!N20:Q20,3,0),0) -> 0 | W24: =+IFERROR(VLOOKUP($W$19,Sheet1!N20:Q20,3,0),0) -> 0 | X24: =+IFERROR(VLOOKUP($X$19,Sheet1!F20:I20,3,0),0) -> 0 | Y24: =+IFERROR(VLOOKUP($Y$19,Sheet1!F20:I20,3,0),0) -> 0 | Z24: =+IFERROR(VLOOKUP($Z$19,Sheet1!F20:I20,3,0),0) -> 0 | AA24: =+IFERROR(VLOOKUP($AA$19,Sheet1!F20:I20,3,0),0) -> 0 | AB24: 130 | AC24: =+IFERROR(VLOOKUP($AC$19,Sheet1!F20:I20,3,0),0) -> 0 | AD24: =+IFERROR(VLOOKUP($AD$19,Sheet1!F20:I20,3,0),0) -> 0 | AE24: =+IFERROR(VLOOKUP($AE$19,Sheet1!F20:I20,3,0),0) -> 0 | AF24: 359 | AG24: =+IFERROR(VLOOKUP($AG$19,Sheet1!R20:U20,3,0),0) -> 0 | AH24: 642 | AI24: =+IFERROR(VLOOKUP($AI$19,Sheet1!V20:Y20,3,0),0) -> 0 | AJ24: =+IFERROR(VLOOKUP($AJ$19,Sheet1!V20:Y20,3,0),0) -> 0 | AK24: =+IFERROR(VLOOKUP($AK$19,Sheet1!V20:Y20,3,0),0) -> 0 | AL24: =+IFERROR(VLOOKUP($AL$19,Sheet1!V20:Y20,3,0),0) -> 0 | AM24: =+IFERROR(VLOOKUP($AM$19,Sheet1!V20:Y20,3,0),0) -> 0 | AN24: =+IFERROR(VLOOKUP($AN$19,Sheet1!V20:Y20,3,0),0) -> 0 | AO24: =+IFERROR(VLOOKUP($AO$19,Sheet1!V20:Y20,3,0),0) -> 0 | AP24: =+IFERROR(VLOOKUP($AP$19,Sheet1!V20:Y20,3,0),0) -> 0 | AQ24: =+IFERROR(VLOOKUP($AQ$19,Sheet1!Z20:AB20,3,0),0) -> 0 | AR24: =+IFERROR(VLOOKUP($AR$19,Sheet1!AD20:AG20,3,0),0) -> 0 | AS24: =+IFERROR(VLOOKUP($AS$19,Sheet1!AD20:AG20,3,0),0) -> 0 | AT24: =+IFERROR(VLOOKUP($AT$19,Sheet1!AD20:AG20,3,0),0) -> 0 | AU24: =+IFERROR(VLOOKUP($AU$19,Sheet1!AD20:AG20,3,0),0) -> 0 | AV24: =+IFERROR(VLOOKUP($AV$19,Sheet1!AD20:AG20,3,0),0) -> 0 | AW24: =+IFERROR(VLOOKUP($AW$19,Sheet1!AD20:AG20,3,0),0) -> 0 | AX24: 666 | AY24: =+IFERROR(VLOOKUP($AY$19,Sheet1!AD20:AG20,3,0),0) -> 0 | BA24: =+IFERROR(VLOOKUP($BA$19,Sheet1!AH20:AK20,3,0),0) -> 0 | BB24: =+IFERROR(VLOOKUP($BB$19,Sheet1!AH20:AK20,3,0),0) -> 0 | BC24: =+IFERROR(VLOOKUP($BC$19,Sheet1!AH20:AK20,3,0),0) -> 0 | BD24: =+IFERROR(VLOOKUP($BD$19,Sheet1!AH20:AK20,3,0),0) -> 0 | BE24: =+IFERROR(VLOOKUP($BE$19,Sheet1!AH20:AK20,3,0),0) -> 0 | BF24: =+IFERROR(VLOOKUP($BF$19,Sheet1!AH20:AK20,3,0),0) -> 0 | BG24: =+IFERROR(VLOOKUP($BG$19,Sheet1!AH20:AK20,3,0),0) -> 0 | BH24: =+IFERROR(VLOOKUP($BH$19,Sheet1!AH20:AK20,3,0),0) -> 0 | BI24: =+IFERROR(VLOOKUP($BI$19,Sheet1!AH20:AK20,3,0),0) -> 0 | BJ24: 2605 | BK24: =+IFERROR(VLOOKUP($BK$19,Sheet1!AH20:AK20,3,0),0) -> 0 | BL24: =+IFERROR(VLOOKUP($BL$19,Sheet1!AL20:AO20,3,0),0) -> 0 | BM24: =+IFERROR(VLOOKUP($BM$19,Sheet1!AL20:AO20,3,0),0) -> 0 | BN24: =+IFERROR(VLOOKUP($BN$19,Sheet1!AL20:AO20,3,0),0) -> 0 | BO24: 812 | BP24: =+IFERROR(VLOOKUP($BP$19,Sheet1!AL20:AO20,3,0),0) -> 0 | BQ24: =+IFERROR(VLOOKUP($BQ$19,Sheet1!AL20:AO20,3,0),0) -> 0 | BR24: =+IFERROR(VLOOKUP($BR$19,Sheet1!AL20:AO20,3,0),0) -> 0 | BS24: =+IFERROR(VLOOKUP($BS$19,Sheet1!AL20:AO20,3,0),0) -> 0 | BT24: =+IFERROR(VLOOKUP($BT$19,Sheet1!AL20:AO20,3,0),0) -> 0 | BU24: =+IFERROR(VLOOKUP($BU$19,Sheet1!AL20:AO20,3,0),0) -> 0 | BV24: =+IFERROR(VLOOKUP($BV$19,Sheet1!AL20:AO20,3,0),0) -> 0 | BW24: =+IFERROR(VLOOKUP($BW$19,Sheet1!AL20:AO20,3,0),0) -> 0 | BX24: 567 | BY24: 18 | BZ24: =+IFERROR(VLOOKUP($BZ$19,Sheet1!AX20:BA20,3,0),0) -> 0 | CA24: 67 | CB24: =+IFERROR(VLOOKUP($CB$19,Sheet1!BF20:BI20,3,0),0) -> 0 | CC24: =+IFERROR(VLOOKUP($CC$19,Sheet1!BJ20:BM20,3,0),0) -> 0 | CD24: =+IFERROR(VLOOKUP($CD$19,Sheet1!BN20:BQ20,3,0),0) -> 0 | CE24: 44 | CF24: =+IFERROR(VLOOKUP($CF$19,Sheet1!BV20:BY20,3,0),0) -> 0 | CG24: =Sheet1!E20 -> STEEL | CH24: SP0400118 | CI24: CORRUGATED DISPATCH STEEL DRUM 1700 X 1000 X 1200 | CJ24: =Sheet1!CX20 -> 250 | CK24: =11700/0.25 -> 46800 | CL24: =SUMPRODUCT($N$20:$CF$20,N24:CF24)+CK24 -> 1117046 | CM24: 0.01 | CN24: =CL24*CM24 -> 11170.46 | CO24: 0.18 | CP24: =CL24*CO24 -> 201068.28 | CQ24: =Sheet1!CF20 -> 0 | CR24: =CL24*CQ24 -> 0 | CS24: =CL24+CN24+CP24+CR24 -> 1329284.7 | CT24: 0.02 | CU24: =CS24*CT24 -> 26585.695 | CV24: 0.01 | CW24: =CS24*CV24 -> 13292.847 | CX24: =Sheet1!CM20 -> 0 | CY24: =CX24*CS24 -> 0
A25: =Sheet1!A21 -> ENQ-18390-25-26 | B25: 46357 | C25: =Sheet1!C21 -> FA1300197 | D25: =Sheet1!D21 -> 3 CORE X 120 SQ. MM. AL/ARM - WIRE (XLPE) - 11 KV | E25: =CS25+CU25+CW25+CY25 -> 1221563.3 | F25: =ROUNDUP(M53,0) -> 36250 | G25: =E25+F25 -> 1257813.3 | H25: =Sheet1!CR21 -> 0.18 | I25: =G25*H25 -> 226406.39 | J25: =G25+I25 -> 1484219.6 | K25: =Sheet1!CU21 -> 8 | L25: =Sheet1!CV21 -> KMS | M25: =J25*K25 -> 11873757 | N25: =+IFERROR(VLOOKUP($N$19,Sheet1!J21:L21,3,0),0) -> 972 | O25: =+IFERROR(VLOOKUP($O$19,Sheet1!J21:L21,3,0),0) -> 0 | P25: =+IFERROR(VLOOKUP($P$19,Sheet1!J21:M21,3,0),0) -> 0 | Q25: =+IFERROR(VLOOKUP($Q$19,Sheet1!J21:M21,3,0),0) -> 0 | R25: =+IFERROR(VLOOKUP($R$19,Sheet1!J21:M21,3,0),0) -> 0 | S25: =+IFERROR(VLOOKUP($S$19,Sheet1!J21:M21,3,0),0) -> 0 | T25: =+IFERROR(VLOOKUP($T$19,Sheet1!J21:M21,3,0),0) -> 0 | U25: =+IFERROR(VLOOKUP($U$19,Sheet1!J21:M21,3,0),0) -> 0 | V25: =+IFERROR(VLOOKUP($V$19,Sheet1!N21:Q21,3,0),0) -> 0 | W25: =+IFERROR(VLOOKUP($W$19,Sheet1!N21:Q21,3,0),0) -> 0 | X25: =+IFERROR(VLOOKUP($X$19,Sheet1!F21:I21,3,0),0) -> 0 | Y25: =+IFERROR(VLOOKUP($Y$19,Sheet1!F21:I21,3,0),0) -> 0 | Z25: =+IFERROR(VLOOKUP($Z$19,Sheet1!F21:I21,3,0),0) -> 0 | AA25: =+IFERROR(VLOOKUP($AA$19,Sheet1!F21:I21,3,0),0) -> 0 | AB25: 123 | AC25: =+IFERROR(VLOOKUP($AC$19,Sheet1!F21:I21,3,0),0) -> 0 | AD25: =+IFERROR(VLOOKUP($AD$19,Sheet1!F21:I21,3,0),0) -> 0 | AE25: =+IFERROR(VLOOKUP($AE$19,Sheet1!F21:I21,3,0),0) -> 0 | AF25: 332 | AG25: =+IFERROR(VLOOKUP($AG$19,Sheet1!R21:U21,3,0),0) -> 0 | AH25: 593 | AI25: =+IFERROR(VLOOKUP($AI$19,Sheet1!V21:Y21,3,0),0) -> 0 | AJ25: =+IFERROR(VLOOKUP($AJ$19,Sheet1!V21:Y21,3,0),0) -> 0 | AK25: =+IFERROR(VLOOKUP($AK$19,Sheet1!V21:Y21,3,0),0) -> 0 | AL25: =+IFERROR(VLOOKUP($AL$19,Sheet1!V21:Y21,3,0),0) -> 0 | AM25: =+IFERROR(VLOOKUP($AM$19,Sheet1!V21:Y21,3,0),0) -> 0 | AN25: =+IFERROR(VLOOKUP($AN$19,Sheet1!V21:Y21,3,0),0) -> 0 | AO25: =+IFERROR(VLOOKUP($AO$19,Sheet1!V21:Y21,3,0),0) -> 0 | AP25: =+IFERROR(VLOOKUP($AP$19,Sheet1!V21:Y21,3,0),0) -> 0 | AQ25: =+IFERROR(VLOOKUP($AQ$19,Sheet1!Z21:AB21,3,0),0) -> 0 | AR25: =+IFERROR(VLOOKUP($AR$19,Sheet1!AD21:AG21,3,0),0) -> 0 | AS25: =+IFERROR(VLOOKUP($AS$19,Sheet1!AD21:AG21,3,0),0) -> 0 | AT25: =+IFERROR(VLOOKUP($AT$19,Sheet1!AD21:AG21,3,0),0) -> 0 | AU25: =+IFERROR(VLOOKUP($AU$19,Sheet1!AD21:AG21,3,0),0) -> 0 | AV25: =+IFERROR(VLOOKUP($AV$19,Sheet1!AD21:AG21,3,0),0) -> 0 | AW25: =+IFERROR(VLOOKUP($AW$19,Sheet1!AD21:AG21,3,0),0) -> 0 | AX25: 605 | AY25: =+IFERROR(VLOOKUP($AY$19,Sheet1!AD21:AG21,3,0),0) -> 0 | BA25: =+IFERROR(VLOOKUP($BA$19,Sheet1!AH21:AK21,3,0),0) -> 0 | BB25: =+IFERROR(VLOOKUP($BB$19,Sheet1!AH21:AK21,3,0),0) -> 0 | BC25: =+IFERROR(VLOOKUP($BC$19,Sheet1!AH21:AK21,3,0),0) -> 0 | BD25: =+IFERROR(VLOOKUP($BD$19,Sheet1!AH21:AK21,3,0),0) -> 0 | BE25: =+IFERROR(VLOOKUP($BE$19,Sheet1!AH21:AK21,3,0),0) -> 0 | BF25: =+IFERROR(VLOOKUP($BF$19,Sheet1!AH21:AK21,3,0),0) -> 0 | BG25: =+IFERROR(VLOOKUP($BG$19,Sheet1!AH21:AK21,3,0),0) -> 0 | BH25: =+IFERROR(VLOOKUP($BH$19,Sheet1!AH21:AK21,3,0),0) -> 0 | BI25: =+IFERROR(VLOOKUP($BI$19,Sheet1!AH21:AK21,3,0),0) -> 0 | BJ25: 2485 | BK25: =+IFERROR(VLOOKUP($BK$19,Sheet1!AH21:AK21,3,0),0) -> 0 | BL25: =+IFERROR(VLOOKUP($BL$19,Sheet1!AL21:AO21,3,0),0) -> 0 | BM25: =+IFERROR(VLOOKUP($BM$19,Sheet1!AL21:AO21,3,0),0) -> 0 | BN25: =+IFERROR(VLOOKUP($BN$19,Sheet1!AL21:AO21,3,0),0) -> 0 | BO25: 726 | BP25: =+IFERROR(VLOOKUP($BP$19,Sheet1!AL21:AO21,3,0),0) -> 0 | BQ25: =+IFERROR(VLOOKUP($BQ$19,Sheet1!AL21:AO21,3,0),0) -> 0 | BR25: =+IFERROR(VLOOKUP($BR$19,Sheet1!AL21:AO21,3,0),0) -> 0 | BS25: =+IFERROR(VLOOKUP($BS$19,Sheet1!AL21:AO21,3,0),0) -> 0 | BT25: =+IFERROR(VLOOKUP($BT$19,Sheet1!AL21:AO21,3,0),0) -> 0 | BU25: =+IFERROR(VLOOKUP($BU$19,Sheet1!AL21:AO21,3,0),0) -> 0 | BV25: =+IFERROR(VLOOKUP($BV$19,Sheet1!AL21:AO21,3,0),0) -> 0 | BW25: =+IFERROR(VLOOKUP($BW$19,Sheet1!AL21:AO21,3,0),0) -> 0 | BX25: 503 | BY25: 17 | BZ25: =+IFERROR(VLOOKUP($BZ$19,Sheet1!AX21:BA21,3,0),0) -> 0 | CA25: 62 | CB25: =+IFERROR(VLOOKUP($CB$19,Sheet1!BF21:BI21,3,0),0) -> 0 | CC25: =+IFERROR(VLOOKUP($CC$19,Sheet1!BJ21:BM21,3,0),0) -> 0 | CD25: =+IFERROR(VLOOKUP($CD$19,Sheet1!BN21:BQ21,3,0),0) -> 0 | CE25: 42 | CF25: =+IFERROR(VLOOKUP($CF$19,Sheet1!BV21:BY21,3,0),0) -> 0 | CG25: =Sheet1!E21 -> STEEL | CH25: SP0400118 | CI25: CORRUGATED DISPATCH STEEL DRUM 1700 X 1000 X 1200 | CJ25: =Sheet1!CX21 -> 250 | CK25: =11700/0.25 -> 46800 | CL25: =SUMPRODUCT($N$20:$CF$20,N25:CF25)+CK25 -> 996625 | CM25: 0.01 | CN25: =CL25*CM25 -> 9966.25 | CO25: 0.18 | CP25: =CL25*CO25 -> 179392.5 | CQ25: =Sheet1!CF21 -> 0 | CR25: =CL25*CQ25 -> 0 | CS25: =CL25+CN25+CP25+CR25 -> 1185983.8 | CT25: 0.02 | CU25: =CS25*CT25 -> 23719.675 | CV25: 0.01 | CW25: =CS25*CV25 -> 11859.837 | CX25: =Sheet1!CM21 -> 0 | CY25: =CX25*CS25 -> 0
A26: =Sheet1!A17 -> ENQ-18390-25-26 | B26: 46357 | C26: =Sheet1!C17 -> FA1300098 | D26: =Sheet1!D17 -> 3 CORE X 95 SQ. MM. AL/ARM - WIRE (XLPE) - 11 KV | E26: =CS26+CU26+CW26+CY26 -> 1179376.7 | F26: =ROUNDUP(M54,0) -> 25589 | G26: =E26+F26 -> 1204965.7 | H26: =Sheet1!CR17 -> 0.18 | I26: =G26*H26 -> 216893.83 | J26: =G26+I26 -> 1421859.5 | K26: =Sheet1!CU17 -> 25.5 | L26: =Sheet1!CV17 -> KMS | M26: =J26*K26 -> 36257418 | N26: =+IFERROR(VLOOKUP($N$19,Sheet1!J17:L17,3,0),0) -> 770 | O26: =+IFERROR(VLOOKUP($O$19,Sheet1!J17:L17,3,0),0) -> 0 | P26: =+IFERROR(VLOOKUP($P$19,Sheet1!J17:M17,3,0),0) -> 0 | Q26: =+IFERROR(VLOOKUP($Q$19,Sheet1!J17:M17,3,0),0) -> 0 | R26: =+IFERROR(VLOOKUP($R$19,Sheet1!J17:M17,3,0),0) -> 0 | S26: =+IFERROR(VLOOKUP($S$19,Sheet1!J17:M17,3,0),0) -> 0 | T26: =+IFERROR(VLOOKUP($T$19,Sheet1!J17:M17,3,0),0) -> 0 | U26: =+IFERROR(VLOOKUP($U$19,Sheet1!J17:M17,3,0),0) -> 0 | V26: =+IFERROR(VLOOKUP($V$19,Sheet1!N17:Q17,3,0),0) -> 0 | W26: =+IFERROR(VLOOKUP($W$19,Sheet1!N17:Q17,3,0),0) -> 0 | X26: =+IFERROR(VLOOKUP($X$19,Sheet1!F17:I17,3,0),0) -> 0 | Y26: =+IFERROR(VLOOKUP($Y$19,Sheet1!F17:I17,3,0),0) -> 0 | Z26: =+IFERROR(VLOOKUP($Z$19,Sheet1!F17:I17,3,0),0) -> 0 | AA26: =+IFERROR(VLOOKUP($AA$19,Sheet1!F17:I17,3,0),0) -> 0 | AB26: 115 | AC26: =+IFERROR(VLOOKUP($AC$19,Sheet1!F17:I17,3,0),0) -> 0 | AD26: =+IFERROR(VLOOKUP($AD$19,Sheet1!F17:I17,3,0),0) -> 0 | AE26: =+IFERROR(VLOOKUP($AE$19,Sheet1!F17:I17,3,0),0) -> 0 | AF26: 304 | AG26: =+IFERROR(VLOOKUP($AG$19,Sheet1!R17:U17,3,0),0) -> 0 | AH26: 542 | AI26: =+IFERROR(VLOOKUP($AI$19,Sheet1!V17:Y17,3,0),0) -> 0 | AJ26: =+IFERROR(VLOOKUP($AJ$19,Sheet1!V17:Y17,3,0),0) -> 0 | AK26: =+IFERROR(VLOOKUP($AK$19,Sheet1!V17:Y17,3,0),0) -> 0 | AL26: =+IFERROR(VLOOKUP($AL$19,Sheet1!V17:Y17,3,0),0) -> 0 | AM26: =+IFERROR(VLOOKUP($AM$19,Sheet1!V17:Y17,3,0),0) -> 0 | AN26: =+IFERROR(VLOOKUP($AN$19,Sheet1!V17:Y17,3,0),0) -> 0 | AO26: =+IFERROR(VLOOKUP($AO$19,Sheet1!V17:Y17,3,0),0) -> 0 | AP26: =+IFERROR(VLOOKUP($AP$19,Sheet1!V17:Y17,3,0),0) -> 0 | AQ26: =+IFERROR(VLOOKUP($AQ$19,Sheet1!Z17:AB17,3,0),0) -> 0 | AR26: =+IFERROR(VLOOKUP($AR$19,Sheet1!AD17:AG17,3,0),0) -> 0 | AS26: =+IFERROR(VLOOKUP($AS$19,Sheet1!AD17:AG17,3,0),0) -> 0 | AT26: =+IFERROR(VLOOKUP($AT$19,Sheet1!AD17:AG17,3,0),0) -> 0 | AU26: =+IFERROR(VLOOKUP($AU$19,Sheet1!AD17:AG17,3,0),0) -> 0 | AV26: =+IFERROR(VLOOKUP($AV$19,Sheet1!AD17:AG17,3,0),0) -> 0 | AW26: =+IFERROR(VLOOKUP($AW$19,Sheet1!AD17:AG17,3,0),0) -> 0 | AX26: 576 | AY26: =+IFERROR(VLOOKUP($AY$19,Sheet1!AD17:AG17,3,0),0) -> 0 | BA26: =+IFERROR(VLOOKUP($BA$19,Sheet1!AH17:AK17,3,0),0) -> 0 | BB26: =+IFERROR(VLOOKUP($BB$19,Sheet1!AH17:AK17,3,0),0) -> 0 | BC26: =+IFERROR(VLOOKUP($BC$19,Sheet1!AH17:AK17,3,0),0) -> 0 | BD26: =+IFERROR(VLOOKUP($BD$19,Sheet1!AH17:AK17,3,0),0) -> 0 | BE26: =+IFERROR(VLOOKUP($BE$19,Sheet1!AH17:AK17,3,0),0) -> 0 | BF26: =+IFERROR(VLOOKUP($BF$19,Sheet1!AH17:AK17,3,0),0) -> 0 | BG26: =+IFERROR(VLOOKUP($BG$19,Sheet1!AH17:AK17,3,0),0) -> 0 | BH26: =+IFERROR(VLOOKUP($BH$19,Sheet1!AH17:AK17,3,0),0) -> 0 | BI26: =+IFERROR(VLOOKUP($BI$19,Sheet1!AH17:AK17,3,0),0) -> 0 | BJ26: 2324 | BK26: =+IFERROR(VLOOKUP($BK$19,Sheet1!AH17:AK17,3,0),0) -> 0 | BL26: =+IFERROR(VLOOKUP($BL$19,Sheet1!AL17:AO17,3,0),0) -> 0 | BM26: =+IFERROR(VLOOKUP($BM$19,Sheet1!AL17:AO17,3,0),0) -> 0 | BN26: =+IFERROR(VLOOKUP($BN$19,Sheet1!AL17:AO17,3,0),0) -> 0 | BO26: 685 | BP26: =+IFERROR(VLOOKUP($BP$19,Sheet1!AL17:AO17,3,0),0) -> 0 | BQ26: =+IFERROR(VLOOKUP($BQ$19,Sheet1!AL17:AO17,3,0),0) -> 0 | BR26: =+IFERROR(VLOOKUP($BR$19,Sheet1!AL17:AO17,3,0),0) -> 0 | BS26: =+IFERROR(VLOOKUP($BS$19,Sheet1!AL17:AO17,3,0),0) -> 0 | BT26: =+IFERROR(VLOOKUP($BT$19,Sheet1!AL17:AO17,3,0),0) -> 0 | BU26: =+IFERROR(VLOOKUP($BU$19,Sheet1!AL17:AO17,3,0),0) -> 0 | BV26: =+IFERROR(VLOOKUP($BV$19,Sheet1!AL17:AO17,3,0),0) -> 0 | BW26: =+IFERROR(VLOOKUP($BW$19,Sheet1!AL17:AO17,3,0),0) -> 0 | BX26: 418 | BY26: 15 | BZ26: =+IFERROR(VLOOKUP($BZ$19,Sheet1!AX17:BA17,3,0),0) -> 75 | CA26: 57 | CB26: =+IFERROR(VLOOKUP($CB$19,Sheet1!BF17:BI17,3,0),0) -> 0 | CC26: =+IFERROR(VLOOKUP($CC$19,Sheet1!BJ17:BM17,3,0),0) -> 0 | CD26: =+IFERROR(VLOOKUP($CD$19,Sheet1!BN17:BQ17,3,0),0) -> 0 | CE26: 40 | CF26: =+IFERROR(VLOOKUP($CF$19,Sheet1!BV17:BY17,3,0),0) -> 0 | CG26: =Sheet1!E17 -> STEEL | CH26: SP0400110 | CI26: CORRUGATED DISPATCH STEEL DRUM 1600 X 900 X 1000 MM | CJ26: =Sheet1!CX17 -> 250 | CK26: =11700/0.25 -> 46800 | CL26: =SUMPRODUCT($N$20:$CF$20,N26:CF26)+CK26 -> 887617 | CM26: 0.01 | CN26: =CL26*CM26 -> 8876.17 | CO26: 0.28 | CP26: =CL26*CO26 -> 248532.76 | CQ26: =Sheet1!CF17 -> 0 | CR26: =CL26*CQ26 -> 0 | CS26: =CL26+CN26+CP26+CR26 -> 1145025.9 | CT26: 0.02 | CU26: =CS26*CT26 -> 22900.519 | CV26: 0.01 | CW26: =CS26*CV26 -> 11450.259 | CX26: =Sheet1!CM17 -> 0 | CY26: =CX26*CS26 -> 0
