Workbook

Sheet Sheet1
A1: DOCKET NO. | B1: Base Date | C1: ITEM CODE | D1: PROPOSE ERP ITEM NAME | E1: Propose Drum Type | F1: Insulation Screening(Metallic) | G1: RM Rate(Insulation Screening(Metallic)) | H1: Weight (Insulation Screening (Metallic)) | I1: Cost Insulation Screening(Metallic) | J1: Conductor | K1: RM Rate(Conductor) | L1: Weight(Conductor) | M1: Cost(Conductor) | N1: AL ALLOY | O1: RM Rate(AL Alloy) | P1: Weight(Al Alloy) | Q1: Cost(AL Alloy) | R1: Insulation Screening(Non-Metallic) | S1: RM Rate(Insulation Screening(Non-Metallic)) | T1: Weight(Insulation Screening(Non-Metallic) | U1: Cost(Insulation Screening(Non-Metallic) | V1: Insulation | W1: RM Rate(Insulation) | X1: Weight(Insulation) | Y1: Cost(Insulation) | Z1: Poly Tape | AA1: RM Rate(Poly Tape) | AB1: Weight(Poly Tape) | AC1: Cost(Poly Tape) | AD1: Inner Sheath | AE1: RM Rate(Inner Sheath) | AF1: Weight(Inner Sheath) | AG1: Cost(Inner Sheath) | AH1: Armouring | AI1: RM Rate(Armouring) | AJ1: Weight(Armouring) | AK1: Cost(Armouring) | AL1: Outer Sheath | AM1: RM Rate(Outer Sheath) | AN1: Weight(Outer Sheath) | AO1: Cost(Outer Sheath) | AP1: Filler | AQ1: RM Rate(Filler) | AR1: Weight(Filler) | AS1: Cost(Filler) | AT1: Grease | AU1: RM Rate(Grease) | AV1: Weight(Grease) | AW1: Cost(Grease) | AX1: Water Swellable Tape | AY1: RM Rate(Water Swellable Tape) | AZ1: Weight(Water Swellable Tape) | BA1: Cost(Water Swellable Tape) | BB1: Semi Conducting Water Swellable Tape | BC1: RM Rate(Semi Conducting Water Swellable Tape) | BD1: Weight(Semi Conducting Water Swellable Tape) | BE1: Cost(Semi Conducting Water Swellable Tape) | BF1: Semicon Tape | BG1: RM Rate(Semicon Tape) | BH1: Weight(Semicon Tape) | BI1: Cost(Semicon Tape) | BJ1: Glass Fiber Tape | BK1: RM Rate(Glass Fiber Tape) | BL1: Weight(Glass Fiber Tape) | BM1: Cost(Glass Fiber Tape) | BN1: Copper Wire 0.8MM | BO1: RM Rate(Copper Wire 0.8MM) | BP1: Weight(Copper Wire 0.8MM) | BQ1: Cost(Copper Wire 0.8MM) | BR1: Rubberized Cotton Tape | BS1: RM Rate(Rubberized Cotton Tape) | BT1: Weight(Rubberized Cotton Tape) | BU1: Cost(Rubberized Cotton Tape) | BV1: Water Tight Compound | BW1: RM Rate(Water Tight Compound) | BX1: Weight(Water Tight Compound) | BY1: Cost(Water Tight Compound) | BZ1: Drum Cost Per KM | CA1: Total RM Cost | CB1: FIRM % | CC1: Firm Value | CD1: MFG% | CE1: MFG Value | CF1: PROF% | CG1: Profit Value | CH1: 1st EX-Works | CI1: Intt % | CJ1: Intt Value | CK1: insp% | CL1: Insp Value | CM1: TTR CHARGES% | CN1: TTR Value | CO1: EX-Works Per KM | CP1: Freight Per KM | CQ1: Price Including Freight Per KM | CR1: GST % | CS1: GST Value | CT1: Price Including GST & Freight Per KM | CU1: QTY | CV1: Unit | CW1: Total Price Of Full QTY(Including Freight&GST) | CX1: DRUM CODE | CY1: DRUM SIZE (FxbXtx Ft) | CZ1: Party Standard Length(MTR)
A2: ENQ-16527-25-26 | C2: FA0900013 | D2: 4 CORE X 16 SQ. MM. ALU/ARD - STRIP (XLPE) | E2: WOOD | H2: 0 | J2: Alumimium | L2: 173 | P2: 0 | T2: 0 | V2: LT-XLPE | X2: 63 | AB2: 0 | AD2: PVC Type ST-2 | AF2: 40 | AH2: Galvanised Steel Flat Strip | AJ2: 300 | AL2: PVC Type ST-2 | AN2: 146 | AR2: 0 | AV2: 0 | AZ2: 0 | BD2: 0 | BH2: 0 | BL2: 0 | BP2: 0 | BR2: RUBBERIZED COTTON TAPE | BT2: 0 | BX2: 0 | BZ2: 5448 | CA2: 5448 | CH2: 5448 | CO2: 5448 | CQ2: 5448 | CR2: 0.18 | CS2: 980.64 | CT2: 6428.64 | CU2: 100 | CV2: KMS | CW2: 642864 | CX2: MD0100066 | CY2: DRUM - 40 X 15 X 23 X 2 | CZ2: 500
A3: ENQ-16527-25-26 | C3: FA0900018 | D3: 4 CORE X 35 SQ. MM. AL/ARD - STRIP (XLPE) | E3: WOOD | H3: 0 | J3: Alumimium | L3: 378 | P3: 0 | T3: 0 | V3: LT-XLPE | X3: 109 | AB3: 0 | AD3: PVC Type ST-2 | AF3: 51 | AH3: Galvanised Steel Flat Strip | AJ3: 407 | AL3: PVC Type ST-2 | AN3: 191 | AR3: 0 | AV3: 0 | AZ3: 0 | BD3: 0 | BH3: 0 | BL3: 0 | BP3: 0 | BR3: RUBBERIZED COTTON TAPE | BT3: 0 | BX3: 0 | BZ3: 8874 | CA3: 8874 | CH3: 8874 | CO3: 8874 | CQ3: 8874 | CR3: 0.18 | CS3: 1597.32 | CT3: 10471.32 | CU3: 60 | CV3: KMS | CW3: 628279 | CX3: MD0100015 | CY3: DRUM - 48 X 20 X 28 X 2.25 - RDSO | CZ3: 500
A4: ENQ-16527-25-26 | C4: FA0900036 | D4: 4 CORE X 50 SQ. MM. ALU/ARD - STRIP (XLPE) | E4: WOOD | H4: 0 | J4: Alumimium | L4: 540 | P4: 0 | T4: 0 | V4: LT-XLPE | X4: 124 | AB4: 0 | AD4: PVC Type ST-2 | AF4: 69 | AH4: Galvanised Steel Flat Strip | AJ4: 457 | AL4: PVC Type ST-2 | AN4: 240 | AR4: 0 | AV4: 0 | AZ4: 0 | BD4: 0 | BH4: 0 | BL4: 0 | BP4: 0 | BR4: RUBBERIZED COTTON TAPE | BT4: 0 | BX4: 0 | BZ4: 8874 | CA4: 8874 | CH4: 8874 | CO4: 8874 | CQ4: 8874 | CR4: 0.18 | CS4: 1597.32 | CT4: 10471.32 | CU4: 60 | CV4: KMS | CW4: 628279 | CX4: MD0100015 | CY4: DRUM - 48 X 20 X 28 X 2.25 - RDSO | CZ4: 500
A5: ENQ-16527-25-26 | C5: FA0900042 | D5: 2 CORE X 10 SQ. MM. ALU/ARD - WIRE (XLPE) | E5: WOOD | H5: 0 | J5: Alumimium | L5: 54 | P5: 0 | T5: 0 | V5: LT-XLPE | X5: 26 | AB5: 0 | AD5: PVC Type ST-2 | AF5: 74 | AH5: Galvanised Steel Round Wire | AJ5: 340 | AL5: PVC Type ST-2 | AN5: 127 | AR5: 0 | AV5: 0 | AZ5: 0 | BD5: 0 | BH5: 0 | BL5: 0 | BP5: 0 | BR5: RUBBERIZED COTTON TAPE | BT5: 0 | BX5: 0 | BZ5: 4313 | CA5: 4313 | CH5: 4313 | CO5: 4313 | CQ5: 4313 | CR5: 0.18 | CS5: 776.34 | CT5: 5089.34 | CU5: 100 | CV5: KMS | CW5: 508934 | CX5: MD0100075 | CY5: DRUM - 42 X 15 X 23 X 2 | CZ5: 1000
A6: ENQ-16527-25-26 | C6: FA1100012 | D6: 4 CORE X 95 SQ. MM. AL/ARD - STRIP (XLPE) | E6: WOOD | H6: 0 | J6: Alumimium | L6: 1026 | P6: 0 | T6: 0 | V6: LT-XLPE | X6: 187 | AB6: 0 | AD6: PVC Type ST-2 | AF6: 93 | AH6: Galvanised Steel Flat Strip | AJ6: 611 | AL6: PVC Type ST-2 | AN6: 348 | AR6: 0 | AV6: 0 | AZ6: 0 | BD6: 0 | BH6: 0 | BL6: 0 | BP6: 0 | BR6: RUBBERIZED COTTON TAPE | BT6: 0 | BX6: 0 | BZ6: 15824 | CA6: 15824 | CH6: 15824 | CO6: 15824 | CQ6: 15824 | CR6: 0.18 | CS6: 2848.32 | CT6: 18672.32 | CU6: 198 | CV6: KMS | CW6: 3697119 | CX6: MD0100061 | CY6: DRUM - 56 X 24 X 32 X 3 | CZ6: 500
A7: ENQ-16527-25-26 | C7: FA1100036 | D7: 4 CORE X 400 SQ. MM. AL/ARD - STRIP (XLPE) | E7: STEEL | H7: 0 | J7: Alumimium | L7: 4320 | P7: 0 | T7: 0 | V7: LT-XLPE | X7: 650 | AB7: 0 | AD7: PVC Type ST-2 | AF7: 308 | AH7: Galvanised Steel Flat Strip | AJ7: 1211 | AL7: PVC Type ST-2 | AN7: 999 | AR7: 0 | AV7: 0 | AZ7: 0 | BD7: 0 | BH7: 0 | BL7: 0 | BP7: 0 | BR7: RUBBERIZED COTTON TAPE | BT7: 0 | BX7: 0 | CR7: 0.18 | CU7: 27 | CV7: KMS | CZ7: 500
A8: ENQ-16527-25-26 | C8: FA1100067 | D8: 4 CORE X 150 SQ. MM. AL/ARD - STRIP (XLPE) | E8: WOOD | H8: 0 | J8: Alumimium | L8: 1620 | P8: 0 | T8: 0 | V8: LT-XLPE | X8: 297 | AB8: 0 | AD8: PVC Type ST-2 | AF8: 138 | AH8: Galvanised Steel Flat Strip | AJ8: 777 | AL8: PVC Type ST-2 | AN8: 479 | AR8: 0 | AV8: 0 | AZ8: 0 | BD8: 0 | BH8: 0 | BL8: 0 | BP8: 0 | BR8: RUBBERIZED COTTON TAPE | BT8: 0 | BX8: 0 | BZ8: 20094 | CA8: 20094 | CH8: 20094 | CO8: 20094 | CQ8: 20094 | CR8: 0.18 | CS8: 3616.92 | CT8: 23710.92 | CU8: 8 | CV8: KMS | CW8: 189687 | CX8: MD0100070 | CY8: DRUM - 68 X 24 X 32 X 3 | CZ8: 500
A9: ENQ-16527-25-26 | C9: FA1300004 | D9: 3 CORE X 300 SQ. MM. AL/ARM - STRIP (XLPE) - 11 KV | E9: STEEL | F9: Copper Tape - 0.04 mm | H9: 88 | J9: Alumimium | L9: 2430 | P9: 0 | R9: Extruded Semiconductive | T9: 337 | V9: HT-XLPE | X9: 802 | AB9: 0 | AD9: PVC Type ST-2 | AF9: 277 | AH9: Galvanised Steel Flat Strip | AJ9: 1125 | AL9: PVC Type ST-2 | AN9: 995 | AP9: FILLER | AR9: 1258 | AV9: 0 | AZ9: 0 | BD9: 0 | BH9: 0 | BL9: 88 | BP9: 0 | BR9: RUBBERIZED COTTON TAPE | BT9: 0 | BX9: 0 | BZ9: 60800 | CA9: 60800 | CH9: 60800 | CO9: 60800 | CQ9: 60800 | CR9: 0.18 | CS9: 10944 | CT9: 71744 | CU9: 111 | CV9: KMS | CW9: 7963584 | CX9: SP0400141 | CY9: CORRUGATED DISPATCH STEEL DRUM 2080 X 1000 X 1400 MM | CZ9: 500
A10: ENQ-16527-25-26 | C10: FA1300006 | D10: 3 CORE X 70 SQ. MM. AL/ARM - STRIP (XLPE) - 11 KV | E10: STEEL | F10: Copper Tape - 0.04 mm | H10: 58 | J10: Alumimium | L10: 567 | P10: 0 | R10: Extruded Semiconductive | T10: 188 | V10: HT-XLPE | X10: 474 | AB10: 0 | AD10: PVC Type ST-2 | AF10: 142 | AH10: Galvanised Steel Flat Strip | AJ10: 750 | AL10: PVC Type ST-2 | AN10: 474 | AP10: FILLER | AR10: 533 | AV10: 0 | AZ10: 0 | BD10: 0 | BH10: 0 | BL10: 0 | BP10: 0 | BR10: RUBBERIZED COTTON TAPE | BT10: 0 | BX10: 0 | CR10: 0.18 | CU10: 3 | CV10: KMS | CX10: SP0400118 | CY10: CORRUGATED DISPATCH STEEL DRUM 1700 X 1000 X 1200 | CZ10: 500

Sheet AUTO CALCULATION SHEET (2)
A2: Chandigarh Power Distribution Limited
A4: TENDER SPECIFICATION NO () | B4: CPDL/FY25-26/HT & LT Cable/008 Dated 08th July 2025
A5: TENDER DESCRIPTION () | B5: 02 Years Rate Contract for the Supply of HT and LT Cables in Chandigarh, CPDL.
A6: Last Date & Time of Submission () | B6: 29.07.2025(Up to 17:00 Hrs)
A7: REVERSE AUCTION | B7: Purchaser reserves the right to use Reverse Auction as an optional tool as an integral part of the entire tendering process. All techno-commercially qualified bidders shall participate in this event.
A8: Price () | B8: Prices quoted by the Bidder shall be variable as per PV clause mentioned in bid document. The price shall be variable and price variation clause shall be as per latest IEEMA price variation formula. All #0# denoted input prices in the formula (Al0, Cu0, Fe0, CC0, PVC0 etc.) shall be as per IEEMA Circulars of June-25 (Published in July 2025).
A9: Validity () | B9: Bids shall remain valid for 120 days from the due date of submission of the Bid & subsequent corrigendum / amendment / extension of due date of submission.
A10: Delivery Period () | B10: For LT Cable: Bidders shall supply material within 6 to 8 Weeks from the date of issuance of LOI / Release Order/manufacturing Clearance against Rate Contract. However, firm delivery dates will be mentioned in the LOI / Order. For HT Cable: Bidders shall supply material within 8 to 10 Weeks from the date of issuance of LOI / Release Order/manufacturing Clearance against Rate Contract. However, firm delivery dates will be mentioned in the LOI / Order.
A11: Payment Terms () | B11: (i) 20% of contract value will be paid as interest free advance against Corporate Guarantee / Advance Bank Guarantee of an Equivalent amount from nationalized / scheduled bank(s) as may be acceptable to the Company, initially valid for a period of nine months from the date of submission. (ii) 70% Payment shall be released on pro-rata basic within 90 days from the receipt of material at CPDL site with complete set of documents as mentioned in order. Supplier should submit the invoices along with all required documents at CPDL Office within 3 days. Any delay in submission of any of these documents will be to your account. It may please be noted that for payment purposes the date of receipt of documents will be considered on the basis of the date of receipt of last document, in case partial documents were received earlier. (iii) The remaining 10% shall be released after submission of Performance Bank Guarantee (PBG).
A12: Standard length () | B12: 11kV 3C X 300 Sq mm = mtr 11kV 3C X 70 Sq mm = 500 mtr+2% (mild steel drum=2489x1270x1295) 1.1 kV 4C X 150 Sq mm = 500 mtr (good Quality wood) 1.1 kV 4C X 95 Sq mm = 500 mtr+/-2% (good Quality wood) 1.1 kV 4C X 400 Sq mm = 500 mtr (non-returnable wooden drum) 1.1 kV 2C X 10sqmm = 1000 mtr+/-5% (good Quality wood) 1.1 kV 4C X 16sqmm = 500 mtr+/-2% (good Quality wood) 1.1 kV 4C X 35sqmm = 500 mtr+/-2% (good Quality wood) 1.1 kV 4C X 50sqmm = 500 mtr+/-2% (good Quality wood)
A13: Packing ()
A14: Technical Specification
N16: Conductor | V16: AL ALLOY | X16: Insulation Screening (Metallic) | AF16: Insulation Screening (Non-Metallic) | AH16: Insulation | AQ16: POLY TAPE | AR16: Inner Sheath | BA16: Armouring | BL16: Outer Sheath | BX16: FILLER | BY16: GREASE | BZ16: Water swellable Tape | CA16: Semi conducting Water Swellable tape | CB16: SEMICON TAPE | CC16: GLASS FIBER TAPE | CD16: COPPER WIRE 0.8 MM | CE16: RUBBERIZED COTTON TAPE | CF16: Water Tight Compound | CG16: DRUM TYPE | CK16: DRUM COST PER KM | CL16: TOTAL RM COST | CM16: EXTRA CONSUMPTION | CN16: EXTRA CONSUMPTION VALUE | CZ16: $A$1
A17: DOCKET NO. | B17: BASE DATE | C17: ITEM CODE | D17: PROPOSE ERP ITEM NAME | E17: EX-WORKS (PER KM) | F17: FREIGHT PER KM | G17: PRICE INCLUDING FREIGHT (PER KM) | H17: GST % | I17: GST VALUE | J17: PRICE INCLUDING GST & FREIGHT (PER KM) | K17: QTY | L17: Unit | M17: TOTAL PRICE OF FULL QTY (INCLUDING FRIGHT & GST) | N17: Alumimium | O17: Alumimium ALLOY | P17: Copper | Q17: AL-59 | R17: AL-4 | S17: AL-7 | T17: Flexible Copper | U17: Galvanized steel wire | V17: Alumimium | W17: Alumimium ALLOY | X17: Coper tape - 0.1 mm | Y17: Copper Tape - 0.03 mm | Z17: Copper Tape - 0.035 mm | AA17: Copper Tape - 0.04 mm | AB17: Copper Tape - 0.045 mm | AC17: Copper Tape - 0.050 mm | AD17: Copper Tape - 0.060 mm | AE17: Copper Tape - 0.075 mm(DOUBLE) | AF17: Extruded semiconductive | AG17: Extruded Semiconductive(Stripable) | AH17: HT-XLPE | AI17: LT-XLPE | AJ17: TR XLPE | AK17: Type A PVC | AL17: Type C PVC (HR) | AM17: Type A PVC-1.45 | AN17: Type A PVC-FR | AO17: Type A PVC-FRLS | AP17: Type A PVC-1.38 | AQ17: POLY TAPE | AR17: FR PVC Type ST-1 | AS17: FR PVC Type ST-2 | AT17: FRLSH PVC Type ST-1 | AU17: FRLSH PVC Type ST-2 | AV17: PVC Type ST-1 | AW17: PVC Type ST-1-PRESSURE EXTRUDED | AX17: PVC Type ST-2 | AY17: PVC COMPOUND 1.48 | AZ17: PVC Type ST-2-PRESSURE EXTRUDED | BA17: ACSR CORE WIRE | BB17: ACSR DOG STEEL WIRE | BC17: Aluminium Flat Strip | BD17: Aluminium Round Wire | BE17: Alumimium Tape | BF17: Double Steel Tape | BG17: Galvanised Steel Flat Strip | BH17: Galvanised Steel Flat Strip (Double) | BI17: Galvanised Steel Flat Strip-B | BJ17: Galvanised Steel Round Wire | BK17: Galvanised Steel Round Wire (Double) | BL17: FR PVC Type ST-1 | BM17: FR PVC Type ST-2 | BN17: FRLSH PVC Type ST-1 | BO17: FRLSH PVC Type ST-2 | BP17: ZHFR | BQ17: PE-ST-3 | BR17: PE-ST-7 | BS17: PVC Type ST-1 | BT17: PVC Type ST-2 | BU17: PVC COMPOUND 1.48 | BV17: PVC Type ST-2-PRESSURE EXTRUDED | BW17: UV & Track Resistant XLPE | BX17: FILLER | BY17: Grease | BZ17: Water swellable Tape | CA17: Semi conducting Water Swellable tape | CB17: SEMICON TAPE | CC17: GLASS FIBER TAPE | CD17: COPPER WIRE 0.8 MM | CE17: RUBBERIZED COTTON TAPE | CF17: Water Tight Compound | CG17: PROPOSE DRUM TYPE | CH17: DRUM CODE | CI17: DRUM SIZE (FxbXtx Ft) | CJ17: PARTY STANDARD LENGTH (MTR) | CO17: MFG% | CP17: MFG VALUE | CQ17: PROF% | CR17: PROFIT VALUE | CS17: 1ST EX-WORKS | CT17: Intt % | CU17: INTT VALUE | CV17: insp% | CW17: INSP VALUE | CX17: TTR Charges% | CY17: TTR Charges VALUE
N18: 255 | O18: =+IFERROR(VLOOKUP($O$17,Sheet1!J:L,2,0),0) -> 0 | P18: =+IFERROR(VLOOKUP($P$17,Sheet1!J:M,2,0),0) -> 0 | Q18: =+IFERROR(VLOOKUP($Q$17,Sheet1!J:M,2,0),0) -> 0 | R18: =+IFERROR(VLOOKUP($R$17,Sheet1!J:M,2,0),0) -> 0 | S18: =+IFERROR(VLOOKUP($S$17,Sheet1!J:M,2,0),0) -> 0 | T18: =+IFERROR(VLOOKUP($T$17,Sheet1!J:M,2,0),0) -> 0 | U18: =+IFERROR(VLOOKUP($U$17,Sheet1!J:M,2,0),0) -> 0 | V18: =+IFERROR(VLOOKUP($V$17,Sheet1!N:Q,2,0),0) -> 0 | W18: =+IFERROR(VLOOKUP($W$17,Sheet1!N:O,2,0),0) -> 0 | X18: =+IFERROR(VLOOKUP($X$17,Sheet1!F:I,2,0),0) -> 0 | Y18: =+IFERROR(VLOOKUP($Y$17,Sheet1!F:I,2,0),0) -> 0 | Z18: =+IFERROR(VLOOKUP($Z$17,Sheet1!F:I,2,0),0) -> 0 | AA18: 1017 | AB18: =+IFERROR(VLOOKUP($AB$17,Sheet1!F:I,2,0),0) -> 0 | AC18: =+IFERROR(VLOOKUP($AC$17,Sheet1!F:I,2,0),0) -> 0 | AD18: =+IFERROR(VLOOKUP($AD$17,Sheet1!F:I,2,0),0) -> 0 | AE18: =+IFERROR(VLOOKUP($AE$17,Sheet1!F:I,2,0),0) -> 0 | AF18: 170 | AG18: =+IFERROR(VLOOKUP($AG$17,Sheet1!R:U,2,0),0) -> 0 | AH18: 142 | AI18: 105 | AJ18: =+IFERROR(VLOOKUP($AJ$17,Sheet1!V:Y,2,0),0) -> 0 | AK18: =+IFERROR(VLOOKUP($AK$17,Sheet1!V:Y,2,0),0) -> 0 | AL18: =+IFERROR(VLOOKUP($AL$17,Sheet1!V:Y,2,0),0) -> 0 | AM18: =+IFERROR(VLOOKUP($AM$17,Sheet1!V:Y,2,0),0) -> 0 | AN18: =+IFERROR(VLOOKUP($AN$17,Sheet1!V:Y,2,0),0) -> 0 | AO18: =+IFERROR(VLOOKUP($AO$17,Sheet1!V:Y,2,0),0) -> 0 | AP18: =+IFERROR(VLOOKUP($AP$17,Sheet1!V:Y,2,0),0) -> 0 | AQ18: =+IFERROR(VLOOKUP($AQ$17,Sheet1!Z2:AA840,2,0),0) -> 0 | AR18: =+IFERROR(VLOOKUP($AR$17,Sheet1!AD2:AG840,2,0),0) -> 0 | AS18: =+IFERROR(VLOOKUP($AS$17,Sheet1!AD2:AG840,2,0),0) -> 0 | AT18: =+IFERROR(VLOOKUP($AT$17,Sheet1!AD2:AG840,2,0),0) -> 0 | AU18: =+IFERROR(VLOOKUP($AU$17,Sheet1!AD2:AG840,2,0),0) -> 0 | AV18: =+IFERROR(VLOOKUP($AV$17,Sheet1!AD2:AG840,2,0),0) -> 0 | AW18: =+IFERROR(VLOOKUP($AW$17,Sheet1!AD2:AG840,2,0),0) -> 0 | AX18: 62 | AY18: =+IFERROR(VLOOKUP($AY$17,Sheet1!AD2:AG840,2,0),0) -> 0 | AZ18: =+IFERROR(VLOOKUP($AZ$17,Sheet1!AD2:AG840,2,0),0) -> 0 | BA18: =+IFERROR(VLOOKUP($BA$17,Sheet1!AH2:AK840,2,0),0) -> 0 | BB18: =+IFERROR(VLOOKUP($BB$17,Sheet1!AH2:AK840,2,0),0) -> 0 | BC18: =+IFERROR(VLOOKUP($BC$17,Sheet1!AH2:AK840,2,0),0) -> 0 | BD18: =+IFERROR(VLOOKUP($BD$17,Sheet1!AH2:AK840,2,0),0) -> 0 | BE18: =+IFERROR(VLOOKUP($BE$17,Sheet1!AH2:AK840,2,0),0) -> 0 | BF18: =+IFERROR(VLOOKUP($BF$17,Sheet1!AH2:AK840,2,0),0) -> 0 | BG18: 74 | BH18: =+IFERROR(VLOOKUP($BH$17,Sheet1!AH2:AK840,2,0),0) -> 0 | BI18: =+IFERROR(VLOOKUP($BI$17,Sheet1!AH2:AK840,2,0),0) -> 0 | BJ18: =+IFERROR(VLOOKUP($BJ$17,Sheet1!AH2:AK840,2,0),0) -> 0 | BK18: =+IFERROR(VLOOKUP($BK$17,Sheet1!AH2:AK840,2,0),0) -> 0 | BL18: =+IFERROR(VLOOKUP($BL$17,Sheet1!AL2:AO840,2,0),0) -> 0 | BM18: =+IFERROR(VLOOKUP($BM$17,Sheet1!AL2:AO840,2,0),0) -> 0 | BN18: =+IFERROR(VLOOKUP($BN$17,Sheet1!AL2:AO840,2,0),0) -> 0 | BO18: =+IFERROR(VLOOKUP($BO$17,Sheet1!AL2:AO840,2,0),0) -> 0 | BP18: =+IFERROR(VLOOKUP($BP$17,Sheet1!AL2:AO840,2,0),0) -> 0 | BQ18: =+IFERROR(VLOOKUP($BQ$17,Sheet1!AL2:AO840,2,0),0) -> 0 | BR18: =+IFERROR(VLOOKUP($BR$17,Sheet1!AL2:AO840,2,0),0) -> 0 | BS18: =+IFERROR(VLOOKUP($BS$17,Sheet1!AL2:AO840,2,0),0) -> 0 | BT18: 62 | BU18: =+IFERROR(VLOOKUP($BU$17,Sheet1!AL2:AO840,2,0),0) -> 0 | BV18: =+IFERROR(VLOOKUP($BV$17,Sheet1!AL2:AO840,2,0),0) -> 0 | BW18: =+IFERROR(VLOOKUP($BW$17,Sheet1!AL2:AO840,2,0),0) -> 0 | BX18: 28 | BY18: =+IFERROR(VLOOKUP($BY$17,Sheet1!AT2:AW840,2,0),0) -> 0 | BZ18: =+IFERROR(VLOOKUP($BZ$17,Sheet1!AX2:BA840,2,0),0) -> 0 | CA18: =+IFERROR(VLOOKUP($CA$17,Sheet1!BB2:BE840,2,0),0) -> 0 | CB18: =+IFERROR(VLOOKUP($CB$17,Sheet1!BF2:BI840,2,0),0) -> 0 | CC18: =+IFERROR(VLOOKUP($CC$17,Sheet1!BJ2:BM840,2,0),0) -> 0 | CD18: =+IFERROR(VLOOKUP($CD$17,Sheet1!BN2:BQ840,2,0),0) -> 0 | CE18: 303 | CF18: =+IFERROR(VLOOKUP($CF$17,Sheet1!BV2:BY840,2,0),0) -> 0
A19: =Sheet1!A9 -> ENQ-16527-25-26 | B19: 45809 | C19: =Sheet1!C9 -> FA1300004 | D19: =Sheet1!D9 -> 3 CORE X 300 SQ. MM. AL/ARM - STRIP (XLPE) - 11 KV | E19: =CS19+CU19+CW19+CY19 -> 1666853.5 | F19: =ROUNDUP(M32,0) -> 54933 | G19: =E19+F19 -> 1721786.5 | H19: =Sheet1!CR9 -> 0.18 | I19: =G19*H19 -> 309921.58 | J19: =G19+I19 -> 2031708.1 | K19: =Sheet1!CU9 -> 111 | L19: =Sheet1!CV9 -> KMS | M19: =J19*K19 -> 2.255196e+08 | N19: =+IFERROR(VLOOKUP($N$17,Sheet1!J9:L9,3,0),0) -> 2430 | O19: =+IFERROR(VLOOKUP($O$17,Sheet1!J9:L9,3,0),0) -> 0 | P19: =+IFERROR(VLOOKUP($P$17,Sheet1!J9:M9,3,0),0) -> 0 | Q19: =+IFERROR(VLOOKUP($Q$17,Sheet1!J9:M9,3,0),0) -> 0 | R19: =+IFERROR(VLOOKUP($R$17,Sheet1!J9:M9,3,0),0) -> 0 | S19: =+IFERROR(VLOOKUP($S$17,Sheet1!J9:M9,3,0),0) -> 0 | T19: =+IFERROR(VLOOKUP($T$17,Sheet1!J9:M9,3,0),0) -> 0 | U19: =+IFERROR(VLOOKUP($U$17,Sheet1!J9:M9,3,0),0) -> 0 | V19: =+IFERROR(VLOOKUP($V$17,Sheet1!N9:Q9,3,0),0) -> 0 | W19: =+IFERROR(VLOOKUP($W$17,Sheet1!N9:Q9,3,0),0) -> 0 | X19: =+IFERROR(VLOOKUP($X$17,Sheet1!F9:I9,3,0),0) -> 0 | Y19: =+IFERROR(VLOOKUP($Y$17,Sheet1!F9:I9,3,0),0) -> 0 | Z19: =+IFERROR(VLOOKUP($Z$17,Sheet1!F9:I9,3,0),0) -> 0 | AA19: 119 | AB19: =+IFERROR(VLOOKUP($AB$17,Sheet1!F9:I9,3,0),0) -> 0 | AC19: =+IFERROR(VLOOKUP($AC$17,Sheet1!F9:I9,3,0),0) -> 0 | AD19: =+IFERROR(VLOOKUP($AD$17,Sheet1!F9:I9,3,0),0) -> 0 | AE19: =+IFERROR(VLOOKUP($AE$17,Sheet1!F9:I9,3,0),0) -> 0 | AF19: 328 | AG19: =+IFERROR(VLOOKUP($AG$17,Sheet1!R9:U9,3,0),0) -> 0 | AH19: 870 | AI19: =+IFERROR(VLOOKUP($AI$17,Sheet1!V9:Y9,3,0),0) -> 0 | AJ19: =+IFERROR(VLOOKUP($AJ$17,Sheet1!V9:Y9,3,0),0) -> 0 | AK19: =+IFERROR(VLOOKUP($AK$17,Sheet1!V9:Y9,3,0),0) -> 0 | AL19: =+IFERROR(VLOOKUP($AL$17,Sheet1!V9:Y9,3,0),0) -> 0 | AM19: =+IFERROR(VLOOKUP($AM$17,Sheet1!V9:Y9,3,0),0) -> 0 | AN19: =+IFERROR(VLOOKUP($AN$17,Sheet1!V9:Y9,3,0),0) -> 0 | AO19: =+IFERROR(VLOOKUP($AO$17,Sheet1!V9:Y9,3,0),0) -> 0 | AP19: =+IFERROR(VLOOKUP($AP$17,Sheet1!V9:Y9,3,0),0) -> 0 | AQ19: =+IFERROR(VLOOKUP($AQ$17,Sheet1!Z9:AB9,3,0),0) -> 0 | AR19: =+IFERROR(VLOOKUP($AR$17,Sheet1!AD9:AG9,3,0),0) -> 0 | AS19: =+IFERROR(VLOOKUP($AS$17,Sheet1!AD9:AG9,3,0),0) -> 0 | AT19: =+IFERROR(VLOOKUP($AT$17,Sheet1!AD9:AG9,3,0),0) -> 0 | AU19: =+IFERROR(VLOOKUP($AU$17,Sheet1!AD9:AG9,3,0),0) -> 0 | AV19: =+IFERROR(VLOOKUP($AV$17,Sheet1!AD9:AG9,3,0),0) -> 0 | AW19: =+IFERROR(VLOOKUP($AW$17,Sheet1!AD9:AG9,3,0),0) -> 0 | AX19: 300 | AY19: =+IFERROR(VLOOKUP($AY$17,Sheet1!AD9:AG9,3,0),0) -> 0 | AZ19: =+IFERROR(VLOOKUP($AZ$17,Sheet1!AD9:AG9,3,0),0) -> 0 | BA19: =+IFERROR(VLOOKUP($BA$17,Sheet1!AH9:AK9,3,0),0) -> 0 | BB19: =+IFERROR(VLOOKUP($BB$17,Sheet1!AH9:AK9,3,0),0) -> 0 | BC19: =+IFERROR(VLOOKUP($BC$17,Sheet1!AH9:AK9,3,0),0) -> 0 | BD19: =+IFERROR(VLOOKUP($BD$17,Sheet1!AH9:AK9,3,0),0) -> 0 | BE19: =+IFERROR(VLOOKUP($BE$17,Sheet1!AH9:AK9,3,0),0) -> 0 | BF19: =+IFERROR(VLOOKUP($BF$17,Sheet1!AH9:AK9,3,0),0) -> 0 | BG19: 1150 | BH19: =+IFERROR(VLOOKUP($BH$17,Sheet1!AH9:AK9,3,0),0) -> 0 | BI19: =+IFERROR(VLOOKUP($BI$17,Sheet1!AH9:AK9,3,0),0) -> 0 | BJ19: =+IFERROR(VLOOKUP($BJ$17,Sheet1!AH9:AK9,3,0),0) -> 0 | BK19: =+IFERROR(VLOOKUP($BK$17,Sheet1!AH9:AK9,3,0),0) -> 0 | BL19: =+IFERROR(VLOOKUP($BL$17,Sheet1!AL9:AO9,3,0),0) -> 0 | BM19: =+IFERROR(VLOOKUP($BM$17,Sheet1!AL9:AO9,3,0),0) -> 0 | BN19: =+IFERROR(VLOOKUP($BN$17,Sheet1!AL9:AO9,3,0),0) -> 0 | BO19: =+IFERROR(VLOOKUP($BO$17,Sheet1!AL9:AO9,3,0),0) -> 0 | BP19: =+IFERROR(VLOOKUP($BP$17,Sheet1!AL9:AO9,3,0),0) -> 0 | BQ19: =+IFERROR(VLOOKUP($BQ$17,Sheet1!AL9:AO9,3,0),0) -> 0 | BR19: =+IFERROR(VLOOKUP($BR$17,Sheet1!AL9:AO9,3,0),0) -> 0 | BS19: =+IFERROR(VLOOKUP($BS$17,Sheet1!AL9:AO9,3,0),0) -> 0 | BT19: 1012 | BU19: =+IFERROR(VLOOKUP($BU$17,Sheet1!AL9:AO9,3,0),0) -> 0 | BV19: =+IFERROR(VLOOKUP($BV$17,Sheet1!AL9:AO9,3,0),0) -> 0 | BW19: =+IFERROR(VLOOKUP($BW$17,Sheet1!AL9:AO9,3,0),0) -> 0 | BX19: 1310 | BY19: =+IFERROR(VLOOKUP($BY$17,Sheet1!AT9:AW9,3,0),0) -> 0 | BZ19: =+IFERROR(VLOOKUP($BZ$17,Sheet1!AX9:BA9,3,0),0) -> 0 | CA19: =+IFERROR(VLOOKUP($CA$17,Sheet1!BB9:BE9,3,0),0) -> 0 | CB19: =+IFERROR(VLOOKUP($CB$17,Sheet1!BF9:BI9,3,0),0) -> 0 | CC19: =+IFERROR(VLOOKUP($CC$17,Sheet1!BJ9:BM9,3,0),0) -> 0 | CD19: =+IFERROR(VLOOKUP($CD$17,Sheet1!BN9:BQ9,3,0),0) -> 0 | CE19: 49 | CF19: =+IFERROR(VLOOKUP($CF$17,Sheet1!BV9:BY9,3,0),0) -> 0 | CG19: =Sheet1!E9 -> STEEL | CH19: =Sheet1!CX9 -> SP0400141 | CI19: =Sheet1!CY9 -> CORRUGATED DISPATCH STEEL DRUM 2080 X 1000 X 1400 MM | CJ19: =Sheet1!CZ9 -> 500 | CK19: =30400/0.5 -> 60800 | CL19: =SUMPRODUCT($N$18:$CF$18,N19:CF19)+CK19 -> 1198744 | CM19: =Sheet1!CB9 -> 0 | CN19: =CL19*CM19 -> 0 | CO19: 0.35 | CP19: =CL19*CO19 -> 419560.4 | CQ19: 0 | CR19: =CL19*CQ19 -> 0 | CS19: =CL19+CN19+CP19+CR19 -> 1618304.4 | CT19: 0.02 | CU19: =CS19*CT19 -> 32366.088 | CV19: 0.01 | CW19: =CS19*CV19 -> 16183.044 | CX19: =Sheet1!CM9 -> 0 | CY19: =CX19*CS19 -> 0
A20: =Sheet1!A10 -> ENQ-16527-25-26 | B20: 45809 | C20: =Sheet1!C10 -> FA1300006 | D20: =Sheet1!D10 -> 3 CORE X 70 SQ. MM. AL/ARM - STRIP (XLPE) - 11 KV | E20: =CS20+CU20+CW20+CY20 -> 694910.72 | F20: =ROUNDUP(M33,0) -> 45167 | G20: =E20+F20 -> 740077.72 | H20: =Sheet1!CR10 -> 0.18 | I20: =G20*H20 -> 133213.99 | J20: =G20+I20 -> 873291.71 | K20: =Sheet1!CU10 -> 3 | L20: =Sheet1!CV10 -> KMS | M20: =J20*K20 -> 2619875.1 | N20: =+IFERROR(VLOOKUP($N$17,Sheet1!J10:L10,3,0),0) -> 567 | O20: =+IFERROR(VLOOKUP($O$17,Sheet1!J10:L10,3,0),0) -> 0 | P20: =+IFERROR(VLOOKUP($P$17,Sheet1!J10:M10,3,0),0) -> 0 | Q20: =+IFERROR(VLOOKUP($Q$17,Sheet1!J10:M10,3,0),0) -> 0 | R20: =+IFERROR(VLOOKUP($R$17,Sheet1!J10:M10,3,0),0) -> 0 | S20: =+IFERROR(VLOOKUP($S$17,Sheet1!J10:M10,3,0),0) -> 0 | T20: =+IFERROR(VLOOKUP($T$17,Sheet1!J10:M10,3,0),0) -> 0 | U20: =+IFERROR(VLOOKUP($U$17,Sheet1!J10:M10,3,0),0) -> 0 | V20: =+IFERROR(VLOOKUP($V$17,Sheet1!N10:Q10,3,0),0) -> 0 | W20: =+IFERROR(VLOOKUP($W$17,Sheet1!N10:Q10,3,0),0) -> 0 | X20: =+IFERROR(VLOOKUP($X$17,Sheet1!F10:I10,3,0),0) -> 0 | Y20: =+IFERROR(VLOOKUP($Y$17,Sheet1!F10:I10,3,0),0) -> 0 | Z20: =+IFERROR(VLOOKUP($Z$17,Sheet1!F10:I10,3,0),0) -> 0 | AA20: 78 | AB20: =+IFERROR(VLOOKUP($AB$17,Sheet1!F10:I10,3,0),0) -> 0 | AC20: =+IFERROR(VLOOKUP($AC$17,Sheet1!F10:I10,3,0),0) -> 0 | AD20: =+IFERROR(VLOOKUP($AD$17,Sheet1!F10:I10,3,0),0) -> 0 | AE20: =+IFERROR(VLOOKUP($AE$17,Sheet1!F10:I10,3,0),0) -> 0 | AF20: 190 | AG20: =+IFERROR(VLOOKUP($AG$17,Sheet1!R10:U10,3,0),0) -> 0 | AH20: 510 | AI20: =+IFERROR(VLOOKUP($AI$17,Sheet1!V10:Y10,3,0),0) -> 0 | AJ20: =+IFERROR(VLOOKUP($AJ$17,Sheet1!V10:Y10,3,0),0) -> 0 | AK20: =+IFERROR(VLOOKUP($AK$17,Sheet1!V10:Y10,3,0),0) -> 0 | AL20: =+IFERROR(VLOOKUP($AL$17,Sheet1!V10:Y10,3,0),0) -> 0 | AM20: =+IFERROR(VLOOKUP($AM$17,Sheet1!V10:Y10,3,0),0) -> 0 | AN20: =+IFERROR(VLOOKUP($AN$17,Sheet1!V10:Y10,3,0),0) -> 0 | AO20: =+IFERROR(VLOOKUP($AO$17,Sheet1!V10:Y10,3,0),0) -> 0 | AP20: =+IFERROR(VLOOKUP($AP$17,Sheet1!V10:Y10,3,0),0) -> 0 | AQ20: =+IFERROR(VLOOKUP($AQ$17,Sheet1!Z10:AB10,3,0),0) -> 0 | AR20: =+IFERROR(VLOOKUP($AR$17,Sheet1!AD10:AG10,3,0),0) -> 0 | AS20: =+IFERROR(VLOOKUP($AS$17,Sheet1!AD10:AG10,3,0),0) -> 0 | AT20: =+IFERROR(VLOOKUP($AT$17,Sheet1!AD10:AG10,3,0),0) -> 0 | AU20: =+IFERROR(VLOOKUP($AU$17,Sheet1!AD10:AG10,3,0),0) -> 0 | AV20: =+IFERROR(VLOOKUP($AV$17,Sheet1!AD10:AG10,3,0),0) -> 0 | AW20: =+IFERROR(VLOOKUP($AW$17,Sheet1!AD10:AG10,3,0),0) -> 0 | AX20: 155 | AY20: =+IFERROR(VLOOKUP($AY$17,Sheet1!AD10:AG10,3,0),0) -> 0 | AZ20: =+IFERROR(VLOOKUP($AZ$17,Sheet1!AD10:AG10,3,0),0) -> 0 | BA20: =+IFERROR(VLOOKUP($BA$17,Sheet1!AH10:AK10,3,0),0) -> 0 | BB20: =+IFERROR(VLOOKUP($BB$17,Sheet1!AH10:AK10,3,0),0) -> 0 | BC20: =+IFERROR(VLOOKUP($BC$17,Sheet1!AH10:AK10,3,0),0) -> 0 | BD20: =+IFERROR(VLOOKUP($BD$17,Sheet1!AH10:AK10,3,0),0) -> 0 | BE20: =+IFERROR(VLOOKUP($BE$17,Sheet1!AH10:AK10,3,0),0) -> 0 | BF20: =+IFERROR(VLOOKUP($BF$17,Sheet1!AH10:AK10,3,0),0) -> 0 | BG20: 775 | BH20: =+IFERROR(VLOOKUP($BH$17,Sheet1!AH10:AK10,3,0),0) -> 0 | BI20: =+IFERROR(VLOOKUP($BI$17,Sheet1!AH10:AK10,3,0),0) -> 0 | BJ20: =+IFERROR(VLOOKUP($BJ$17,Sheet1!AH10:AK10,3,0),0) -> 0 | BK20: =+IFERROR(VLOOKUP($BK$17,Sheet1!AH10:AK10,3,0),0) -> 0 | BL20: =+IFERROR(VLOOKUP($BL$17,Sheet1!AL10:AO10,3,0),0) -> 0 | BM20: =+IFERROR(VLOOKUP($BM$17,Sheet1!AL10:AO10,3,0),0) -> 0 | BN20: =+IFERROR(VLOOKUP($BN$17,Sheet1!AL10:AO10,3,0),0) -> 0 | BO20: =+IFERROR(VLOOKUP($BO$17,Sheet1!AL10:AO10,3,0),0) -> 0 | BP20: =+IFERROR(VLOOKUP($BP$17,Sheet1!AL10:AO10,3,0),0) -> 0 | BQ20: =+IFERROR(VLOOKUP($BQ$17,Sheet1!AL10:AO10,3,0),0) -> 0 | BR20: =+IFERROR(VLOOKUP($BR$17,Sheet1!AL10:AO10,3,0),0) -> 0 | BS20: =+IFERROR(VLOOKUP($BS$17,Sheet1!AL10:AO10,3,0),0) -> 0 | BT20: 490 | BU20: =+IFERROR(VLOOKUP($BU$17,Sheet1!AL10:AO10,3,0),0) -> 0 | BV20: =+IFERROR(VLOOKUP($BV$17,Sheet1!AL10:AO10,3,0),0) -> 0 | BW20: =+IFERROR(VLOOKUP($BW$17,Sheet1!AL10:AO10,3,0),0) -> 0 | BX20: 560 | BY20: =+IFERROR(VLOOKUP($BY$17,Sheet1!AT10:AW10,3,0),0) -> 0 | BZ20: =+IFERROR(VLOOKUP($BZ$17,Sheet1!AX10:BA10,3,0),0) -> 0 | CA20: =+IFERROR(VLOOKUP($CA$17,Sheet1!BB10:BE10,3,0),0) -> 0 | CB20: =+IFERROR(VLOOKUP($CB$17,Sheet1!BF10:BI10,3,0),0) -> 0 | CC20: =+IFERROR(VLOOKUP($CC$17,Sheet1!BJ10:BM10,3,0),0) -> 0 | CD20: =+IFERROR(VLOOKUP($CD$17,Sheet1!BN10:BQ10,3,0),0) -> 0 | CE20: 35 | CF20: =+IFERROR(VLOOKUP($CF$17,Sheet1!BV10:BY10,3,0),0) -> 0 | CG20: =Sheet1!E10 -> STEEL | CH20: =Sheet1!CX10 -> SP0400118 | CI20: =Sheet1!CY10 -> CORRUGATED DISPATCH STEEL DRUM 1700 X 1000 X 1200 | CJ20: =Sheet1!CZ10 -> 500 | CK20: =23750/0.5 -> 47500 | CL20: =SUMPRODUCT($N$18:$CF$18,N20:CF20)+CK20 -> 499756 | CM20: =Sheet1!CB10 -> 0 | CN20: =CL20*CM20 -> 0 | CO20: 0.35 | CP20: =CL20*CO20 -> 174914.6 | CQ20: 0 | CR20: =CL20*CQ20 -> 0 | CS20: =CL20+CN20+CP20+CR20 -> 674670.6 | CT20: 0.02 | CU20: =CS20*CT20 -> 13493.412 | CV20: 0.01 | CW20: =CS20*CV20 -> 6746.706 | CX20: =Sheet1!CM10 -> 0 | CY20: =CX20*CS20 -> 0
A21: =Sheet1!A7 -> ENQ-16527-25-26 | B21: 45809 | C21: =Sheet1!C7 -> FA1100036 | D21: =Sheet1!D7 -> 4 CORE X 400 SQ. MM. AL/ARD - STRIP (XLPE) | E21: =CS21+CU21+CW21+CY21 -> 1968518.3 | F21: =ROUNDUP(M34,0) -> 37686 | G21: =E21+F21 -> 2006204.3 | H21: =Sheet1!CR7 -> 0.18 | I21: =G21*H21 -> 361116.78 | J21: =G21+I21 -> 2367321.1 | K21: =Sheet1!CU7 -> 27 | L21: =Sheet1!CV7 -> KMS | M21: =J21*K21 -> 63917670 | N21: =+IFERROR(VLOOKUP($N$17,Sheet1!J7:L7,3,0),0) -> 4320 | O21: =+IFERROR(VLOOKUP($O$17,Sheet1!J7:L7,3,0),0) -> 0 | P21: =+IFERROR(VLOOKUP($P$17,Sheet1!J7:M7,3,0),0) -> 0 | Q21: =+IFERROR(VLOOKUP($Q$17,Sheet1!J7:M7,3,0),0) -> 0 | R21: =+IFERROR(VLOOKUP($R$17,Sheet1!J7:M7,3,0),0) -> 0 | S21: =+IFERROR(VLOOKUP($S$17,Sheet1!J7:M7,3,0),0) -> 0 | T21: =+IFERROR(VLOOKUP($T$17,Sheet1!J7:M7,3,0),0) -> 0 | U21: =+IFERROR(VLOOKUP($U$17,Sheet1!J7:M7,3,0),0) -> 0 | V21: =+IFERROR(VLOOKUP($V$17,Sheet1!N7:Q7,3,0),0) -> 0 | W21: =+IFERROR(VLOOKUP($W$17,Sheet1!N7:Q7,3,0),0) -> 0 | X21: =+IFERROR(VLOOKUP($X$17,Sheet1!F7:I7,3,0),0) -> 0 | Y21: =+IFERROR(VLOOKUP($Y$17,Sheet1!F7:I7,3,0),0) -> 0 | Z21: =+IFERROR(VLOOKUP($Z$17,Sheet1!F7:I7,3,0),0) -> 0 | AA21: =+IFERROR(VLOOKUP($AA$17,Sheet1!F7:I7,3,0),0) -> 0 | AB21: =+IFERROR(VLOOKUP($AB$17,Sheet1!F7:I7,3,0),0) -> 0 | AC21: =+IFERROR(VLOOKUP($AC$17,Sheet1!F7:I7,3,0),0) -> 0 | AD21: =+IFERROR(VLOOKUP($AD$17,Sheet1!F7:I7,3,0),0) -> 0 | AE21: =+IFERROR(VLOOKUP($AE$17,Sheet1!F7:I7,3,0),0) -> 0 | AF21: =+IFERROR(VLOOKUP($AF$17,Sheet1!R7:U7,3,0),0) -> 0 | AG21: =+IFERROR(VLOOKUP($AG$17,Sheet1!R7:U7,3,0),0) -> 0 | AH21: =+IFERROR(VLOOKUP($AH$17,Sheet1!V7:Y7,3,0),0) -> 0 | AI21: 700 | AJ21: =+IFERROR(VLOOKUP($AJ$17,Sheet1!V7:Y7,3,0),0) -> 0 | AK21: =+IFERROR(VLOOKUP($AK$17,Sheet1!V7:Y7,3,0),0) -> 0 | AL21: =+IFERROR(VLOOKUP($AL$17,Sheet1!V7:Y7,3,0),0) -> 0 | AM21: =+IFERROR(VLOOKUP($AM$17,Sheet1!V7:Y7,3,0),0) -> 0 | AN21: =+IFERROR(VLOOKUP($AN$17,Sheet1!V7:Y7,3,0),0) -> 0 | AO21: =+IFERROR(VLOOKUP($AO$17,Sheet1!V7:Y7,3,0),0) -> 0 | AP21: =+IFERROR(VLOOKUP($AP$17,Sheet1!V7:Y7,3,0),0) -> 0 | AQ21: =+IFERROR(VLOOKUP($AQ$17,Sheet1!Z7:AB7,3,0),0) -> 0 | AR21: =+IFERROR(VLOOKUP($AR$17,Sheet1!AD7:AG7,3,0),0) -> 0 | AS21: =+IFERROR(VLOOKUP($AS$17,Sheet1!AD7:AG7,3,0),0) -> 0 | AT21: =+IFERROR(VLOOKUP($AT$17,Sheet1!AD7:AG7,3,0),0) -> 0 | AU21: =+IFERROR(VLOOKUP($AU$17,Sheet1!AD7:AG7,3,0),0) -> 0 | AV21: =+IFERROR(VLOOKUP($AV$17,Sheet1!AD7:AG7,3,0),0) -> 0 | AW21: =+IFERROR(VLOOKUP($AW$17,Sheet1!AD7:AG7,3,0),0) -> 0 | AX21: 271 | AY21: =+IFERROR(VLOOKUP($AY$17,Sheet1!AD7:AG7,3,0),0) -> 0 | AZ21: =+IFERROR(VLOOKUP($AZ$17,Sheet1!AD7:AG7,3,0),0) -> 0 | BA21: =+IFERROR(VLOOKUP($BA$17,Sheet1!AH7:AK7,3,0),0) -> 0 | BB21: =+IFERROR(VLOOKUP($BB$17,Sheet1!AH7:AK7,3,0),0) -> 0 | BC21: =+IFERROR(VLOOKUP($BC$17,Sheet1!AH7:AK7,3,0),0) -> 0 | BD21: =+IFERROR(VLOOKUP($BD$17,Sheet1!AH7:AK7,3,0),0) -> 0 | BE21: =+IFERROR(VLOOKUP($BE$17,Sheet1!AH7:AK7,3,0),0) -> 0 | BF21: =+IFERROR(VLOOKUP($BF$17,Sheet1!AH7:AK7,3,0),0) -> 0 | BG21: 1102 | BH21: =+IFERROR(VLOOKUP($BH$17,Sheet1!AH7:AK7,3,0),0) -> 0 | BI21: =+IFERROR(VLOOKUP($BI$17,Sheet1!AH7:AK7,3,0),0) -> 0 | BJ21: =+IFERROR(VLOOKUP($BJ$17,Sheet1!AH7:AK7,3,0),0) -> 0 | BK21: =+IFERROR(VLOOKUP($BK$17,Sheet1!AH7:AK7,3,0),0) -> 0 | BL21: =+IFERROR(VLOOKUP($BL$17,Sheet1!AL7:AO7,3,0),0) -> 0 | BM21: =+IFERROR(VLOOKUP($BM$17,Sheet1!AL7:AO7,3,0),0) -> 0 | BN21: =+IFERROR(VLOOKUP($BN$17,Sheet1!AL7:AO7,3,0),0) -> 0 | BO21: =+IFERROR(VLOOKUP($BO$17,Sheet1!AL7:AO7,3,0),0) -> 0 | BP21: =+IFERROR(VLOOKUP($BP$17,Sheet1!AL7:AO7,3,0),0) -> 0 | BQ21: =+IFERROR(VLOOKUP($BQ$17,Sheet1!AL7:AO7,3,0),0) -> 0 | BR21: =+IFERROR(VLOOKUP($BR$17,Sheet1!AL7:AO7,3,0),0) -> 0 | BS21: =+IFERROR(VLOOKUP($BS$17,Sheet1!AL7:AO7,3,0),0) -> 0 | BT21: 940 | BU21: =+IFERROR(VLOOKUP($BU$17,Sheet1!AL7:AO7,3,0),0) -> 0 | BV21: =+IFERROR(VLOOKUP($BV$17,Sheet1!AL7:AO7,3,0),0) -> 0 | BW21: =+IFERROR(VLOOKUP($BW$17,Sheet1!AL7:AO7,3,0),0) -> 0 | BX21: =+IFERROR(VLOOKUP($BX$17,Sheet1!AP7:AS7,3,0),0) -> 0 | BY21: =+IFERROR(VLOOKUP($BY$17,Sheet1!AT7:AW7,3,0),0) -> 0 | BZ21: =+IFERROR(VLOOKUP($BZ$17,Sheet1!AX7:BA7,3,0),0) -> 0 | CA21: =+IFERROR(VLOOKUP($CA$17,Sheet1!BB7:BE7,3,0),0) -> 0 | CB21: =+IFERROR(VLOOKUP($CB$17,Sheet1!BF7:BI7,3,0),0) -> 0 | CC21: =+IFERROR(VLOOKUP($CC$17,Sheet1!BJ7:BM7,3,0),0) -> 0 | CD21: =+IFERROR(VLOOKUP($CD$17,Sheet1!BN7:BQ7,3,0),0) -> 0 | CE21: 87 | CF21: =+IFERROR(VLOOKUP($CF$17,Sheet1!BV7:BY7,3,0),0) -> 0 | CG21: =Sheet1!E7 -> STEEL | CH21: SP0400107 | CI21: CORRUGATED DISPATCH STEEL DRUM 2150 X 1080 X 1240 MM | CJ21: =Sheet1!CZ7 -> 500 | CK21: =28800/0.5 -> 57600 | CL21: =SUMPRODUCT($N$18:$CF$18,N21:CF21)+CK21 -> 1415691 | CM21: =Sheet1!CB7 -> 0 | CN21: =CL21*CM21 -> 0 | CO21: 0.35 | CP21: =CL21*CO21 -> 495491.85 | CQ21: 0 | CR21: =CL21*CQ21 -> 0 | CS21: =CL21+CN21+CP21+CR21 -> 1911182.9 | CT21: 0.02 | CU21: =CS21*CT21 -> 38223.657 | CV21: 0.01 | CW21: =CS21*CV21 -> 19111.828 | CX21: =Sheet1!CM7 -> 0 | CY21: =CX21*CS21 -> 0
A22: =Sheet1!A8 -> ENQ-16527-25-26 | B22: 45809 | C22: =Sheet1!C8 -> FA1100067 | D22: =Sheet1!D8 -> 4 CORE X 150 SQ. MM. AL/ARD - STRIP (XLPE) | E22: =CS22+CU22+CW22+CY22 -> 803410.04 | F22: =ROUNDUP(M35,0) -> 34688 | G22: =E22+F22 -> 838098.04 | H22: =Sheet1!CR8 -> 0.18 | I22: =G22*H22 -> 150857.65 | J22: =G22+I22 -> 988955.69 | K22: =Sheet1!CU8 -> 8 | L22: =Sheet1!CV8 -> KMS | M22: =J22*K22 -> 7911645.5 | N22: =+IFERROR(VLOOKUP($N$17,Sheet1!J8:L8,3,0),0) -> 1620 | O22: =+IFERROR(VLOOKUP($O$17,Sheet1!J8:L8,3,0),0) -> 0 | P22: =+IFERROR(VLOOKUP($P$17,Sheet1!J8:M8,3,0),0) -> 0 | Q22: =+IFERROR(VLOOKUP($Q$17,Sheet1!J8:M8,3,0),0) -> 0 | R22: =+IFERROR(VLOOKUP($R$17,Sheet1!J8:M8,3,0),0) -> 0 | S22: =+IFERROR(VLOOKUP($S$17,Sheet1!J8:M8,3,0),0) -> 0 | T22: =+IFERROR(VLOOKUP($T$17,Sheet1!J8:M8,3,0),0) -> 0 | U22: =+IFERROR(VLOOKUP($U$17,Sheet1!J8:M8,3,0),0) -> 0 | V22: =+IFERROR(VLOOKUP($V$17,Sheet1!N8:Q8,3,0),0) -> 0 | W22: =+IFERROR(VLOOKUP($W$17,Sheet1!N8:Q8,3,0),0) -> 0 | X22: =+IFERROR(VLOOKUP($X$17,Sheet1!F8:I8,3,0),0) -> 0 | Y22: =+IFERROR(VLOOKUP($Y$17,Sheet1!F8:I8,3,0),0) -> 0 | Z22: =+IFERROR(VLOOKUP($Z$17,Sheet1!F8:I8,3,0),0) -> 0 | AA22: =+IFERROR(VLOOKUP($AA$17,Sheet1!F8:I8,3,0),0) -> 0 | AB22: =+IFERROR(VLOOKUP($AB$17,Sheet1!F8:I8,3,0),0) -> 0 | AC22: =+IFERROR(VLOOKUP($AC$17,Sheet1!F8:I8,3,0),0) -> 0 | AD22: =+IFERROR(VLOOKUP($AD$17,Sheet1!F8:I8,3,0),0) -> 0 | AE22: =+IFERROR(VLOOKUP($AE$17,Sheet1!F8:I8,3,0),0) -> 0 | AF22: =+IFERROR(VLOOKUP($AF$17,Sheet1!R8:U8,3,0),0) -> 0 | AG22: =+IFERROR(VLOOKUP($AG$17,Sheet1!R8:U8,3,0),0) -> 0 | AH22: =+IFERROR(VLOOKUP($AH$17,Sheet1!V8:Y8,3,0),0) -> 0 | AI22: 327 | AJ22: =+IFERROR(VLOOKUP($AJ$17,Sheet1!V8:Y8,3,0),0) -> 0 | AK22: =+IFERROR(VLOOKUP($AK$17,Sheet1!V8:Y8,3,0),0) -> 0 | AL22: =+IFERROR(VLOOKUP($AL$17,Sheet1!V8:Y8,3,0),0) -> 0 | AM22: =+IFERROR(VLOOKUP($AM$17,Sheet1!V8:Y8,3,0),0) -> 0 | AN22: =+IFERROR(VLOOKUP($AN$17,Sheet1!V8:Y8,3,0),0) -> 0 | AO22: =+IFERROR(VLOOKUP($AO$17,Sheet1!V8:Y8,3,0),0) -> 0 | AP22: =+IFERROR(VLOOKUP($AP$17,Sheet1!V8:Y8,3,0),0) -> 0 | AQ22: =+IFERROR(VLOOKUP($AQ$17,Sheet1!Z8:AB8,3,0),0) -> 0 | AR22: =+IFERROR(VLOOKUP($AR$17,Sheet1!AD8:AG8,3,0),0) -> 0 | AS22: =+IFERROR(VLOOKUP($AS$17,Sheet1!AD8:AG8,3,0),0) -> 0 | AT22: =+IFERROR(VLOOKUP($AT$17,Sheet1!AD8:AG8,3,0),0) -> 0 | AU22: =+IFERROR(VLOOKUP($AU$17,Sheet1!AD8:AG8,3,0),0) -> 0 | AV22: =+IFERROR(VLOOKUP($AV$17,Sheet1!AD8:AG8,3,0),0) -> 0 | AW22: =+IFERROR(VLOOKUP($AW$17,Sheet1!AD8:AG8,3,0),0) -> 0 | AX22: 145 | AY22: =+IFERROR(VLOOKUP($AY$17,Sheet1!AD8:AG8,3,0),0) -> 0 | AZ22: =+IFERROR(VLOOKUP($AZ$17,Sheet1!AD8:AG8,3,0),0) -> 0 | BA22: =+IFERROR(VLOOKUP($BA$17,Sheet1!AH8:AK8,3,0),0) -> 0 | BB22: =+IFERROR(VLOOKUP($BB$17,Sheet1!AH8:AK8,3,0),0) -> 0 | BC22: =+IFERROR(VLOOKUP($BC$17,Sheet1!AH8:AK8,3,0),0) -> 0 | BD22: =+IFERROR(VLOOKUP($BD$17,Sheet1!AH8:AK8,3,0),0) -> 0 | BE22: =+IFERROR(VLOOKUP($BE$17,Sheet1!AH8:AK8,3,0),0) -> 0 | BF22: =+IFERROR(VLOOKUP($BF$17,Sheet1!AH8:AK8,3,0),0) -> 0 | BG22: 816 | BH22: =+IFERROR(VLOOKUP($BH$17,Sheet1!AH8:AK8,3,0),0) -> 0 | BI22: =+IFERROR(VLOOKUP($BI$17,Sheet1!AH8:AK8,3,0),0) -> 0 | BJ22: =+IFERROR(VLOOKUP($BJ$17,Sheet1!AH8:AK8,3,0),0) -> 0 | BK22: =+IFERROR(VLOOKUP($BK$17,Sheet1!AH8:AK8,3,0),0) -> 0 | BL22: =+IFERROR(VLOOKUP($BL$17,Sheet1!AL8:AO8,3,0),0) -> 0 | BM22: =+IFERROR(VLOOKUP($BM$17,Sheet1!AL8:AO8,3,0),0) -> 0 | BN22: =+IFERROR(VLOOKUP($BN$17,Sheet1!AL8:AO8,3,0),0) -> 0 | BO22: =+IFERROR(VLOOKUP($BO$17,Sheet1!AL8:AO8,3,0),0) -> 0 | BP22: =+IFERROR(VLOOKUP($BP$17,Sheet1!AL8:AO8,3,0),0) -> 0 | BQ22: =+IFERROR(VLOOKUP($BQ$17,Sheet1!AL8:AO8,3,0),0) -> 0 | BR22: =+IFERROR(VLOOKUP($BR$17,Sheet1!AL8:AO8,3,0),0) -> 0 | BS22: =+IFERROR(VLOOKUP($BS$17,Sheet1!AL8:AO8,3,0),0) -> 0 | BT22: 503 | BU22: =+IFERROR(VLOOKUP($BU$17,Sheet1!AL8:AO8,3,0),0) -> 0 | BV22: =+IFERROR(VLOOKUP($BV$17,Sheet1!AL8:AO8,3,0),0) -> 0 | BW22: =+IFERROR(VLOOKUP($BW$17,Sheet1!AL8:AO8,3,0),0) -> 0 | BX22: =+IFERROR(VLOOKUP($BX$17,Sheet1!AP8:AS8,3,0),0) -> 0 | BY22: =+IFERROR(VLOOKUP($BY$17,Sheet1!AT8:AW8,3,0),0) -> 0 | BZ22: =+IFERROR(VLOOKUP($BZ$17,Sheet1!AX8:BA8,3,0),0) -> 0 | CA22: =+IFERROR(VLOOKUP($CA$17,Sheet1!BB8:BE8,3,0),0) -> 0 | CB22: =+IFERROR(VLOOKUP($CB$17,Sheet1!BF8:BI8,3,0),0) -> 0 | CC22: =+IFERROR(VLOOKUP($CC$17,Sheet1!BJ8:BM8,3,0),0) -> 0 | CD22: =+IFERROR(VLOOKUP($CD$17,Sheet1!BN8:BQ8,3,0),0) -> 0 | CE22: 32 | CF22: =+IFERROR(VLOOKUP($CF$17,Sheet1!BV8:BY8,3,0),0) -> 0 | CG22: =Sheet1!E8 -> WOOD | CH22: =Sheet1!CX8 -> MD0100070 | CI22: =Sheet1!CY8 -> DRUM - 68 X 24 X 32 X 3 | CJ22: =Sheet1!CZ8 -> 500 | CK22: =Sheet1!BZ8 -> 20094 | CL22: =SUMPRODUCT($N$18:$CF$18,N22:CF22)+CK22 -> 577785 | CM22: =Sheet1!CB8 -> 0 | CN22: =CL22*CM22 -> 0 | CO22: 0.35 | CP22: =CL22*CO22 -> 202224.75 | CQ22: 0 | CR22: =CL22*CQ22 -> 0 | CS22: =CL22+CN22+CP22+CR22 -> 780009.75 | CT22: 0.02 | CU22: =CS22*CT22 -> 15600.195 | CV22: 0.01 | CW22: =CS22*CV22 -> 7800.0975 | CX22: =Sheet1!CM8 -> 0 | CY22: =CX22*CS22 -> 0
A23: =Sheet1!A6 -> ENQ-16527-25-26 | B23: 45809 | C23: =Sheet1!C6 -> FA1100012 | D23: =Sheet1!D6 -> 4 CORE X 95 SQ. MM. AL/ARD - STRIP (XLPE) | E23: =CS23+CU23+CW23+CY23 -> 527298.46 | F23: =ROUNDUP(M36,0) -> 18687 | G23: =E23+F23 -> 545985.46 | H23: =Sheet1!CR6 -> 0.18 | I23: =G23*H23 -> 98277.382 | J23: =G23+I23 -> 644262.84 | K23: =Sheet1!CU6 -> 198 | L23: =Sheet1!CV6 -> KMS | M23: =J23*K23 -> 1.2756404e+08 | N23: =+IFERROR(VLOOKUP($N$17,Sheet1!J6:L6,3,0),0) -> 1026 | O23: =+IFERROR(VLOOKUP($O$17,Sheet1!J6:L6,3,0),0) -> 0 | P23: =+IFERROR(VLOOKUP($P$17,Sheet1!J6:M6,3,0),0) -> 0 | Q23: =+IFERROR(VLOOKUP($Q$17,Sheet1!J6:M6,3,0),0) -> 0 | R23: =+IFERROR(VLOOKUP($R$17,Sheet1!J6:M6,3,0),0) -> 0 | S23: =+IFERROR(VLOOKUP($S$17,Sheet1!J6:M6,3,0),0) -> 0 | T23: =+IFERROR(VLOOKUP($T$17,Sheet1!J6:M6,3,0),0) -> 0 | U23: =+IFERROR(VLOOKUP($U$17,Sheet1!J6:M6,3,0),0) -> 0 | V23: =+IFERROR(VLOOKUP($V$17,Sheet1!N6:Q6,3,0),0) -> 0 | W23: =+IFERROR(VLOOKUP($W$17,Sheet1!N6:Q6,3,0),0) -> 0 | X23: =+IFERROR(VLOOKUP($X$17,Sheet1!F6:I6,3,0),0) -> 0 | Y23: =+IFERROR(VLOOKUP($Y$17,Sheet1!F6:I6,3,0),0) -> 0 | Z23: =+IFERROR(VLOOKUP($Z$17,Sheet1!F6:I6,3,0),0) -> 0 | AA23: =+IFERROR(VLOOKUP($AA$17,Sheet1!F6:I6,3,0),0) -> 0 | AB23: =+IFERROR(VLOOKUP($AB$17,Sheet1!F6:I6,3,0),0) -> 0 | AC23: =+IFERROR(VLOOKUP($AC$17,Sheet1!F6:I6,3,0),0) -> 0 | AD23: =+IFERROR(VLOOKUP($AD$17,Sheet1!F6:I6,3,0),0) -> 0 | AE23: =+IFERROR(VLOOKUP($AE$17,Sheet1!F6:I6,3,0),0) -> 0 | AF23: =+IFERROR(VLOOKUP($AF$17,Sheet1!R6:U6,3,0),0) -> 0 | AG23: =+IFERROR(VLOOKUP($AG$17,Sheet1!R6:U6,3,0),0) -> 0 | AH23: =+IFERROR(VLOOKUP($AH$17,Sheet1!V6:Y6,3,0),0) -> 0 | AI23: 200 | AJ23: =+IFERROR(VLOOKUP($AJ$17,Sheet1!V6:Y6,3,0),0) -> 0 | AK23: =+IFERROR(VLOOKUP($AK$17,Sheet1!V6:Y6,3,0),0) -> 0 | AL23: =+IFERROR(VLOOKUP($AL$17,Sheet1!V6:Y6,3,0),0) -> 0 | AM23: =+IFERROR(VLOOKUP($AM$17,Sheet1!V6:Y6,3,0),0) -> 0 | AN23: =+IFERROR(VLOOKUP($AN$17,Sheet1!V6:Y6,3,0),0) -> 0 | AO23: =+IFERROR(VLOOKUP($AO$17,Sheet1!V6:Y6,3,0),0) -> 0 | AP23: =+IFERROR(VLOOKUP($AP$17,Sheet1!V6:Y6,3,0),0) -> 0 | AQ23: =+IFERROR(VLOOKUP($AQ$17,Sheet1!Z6:AB6,3,0),0) -> 0 | AR23: =+IFERROR(VLOOKUP($AR$17,Sheet1!AD6:AG6,3,0),0) -> 0 | AS23: =+IFERROR(VLOOKUP($AS$17,Sheet1!AD6:AG6,3,0),0) -> 0 | AT23: =+IFERROR(VLOOKUP($AT$17,Sheet1!AD6:AG6,3,0),0) -> 0 | AU23: =+IFERROR(VLOOKUP($AU$17,Sheet1!AD6:AG6,3,0),0) -> 0 | AV23: =+IFERROR(VLOOKUP($AV$17,Sheet1!AD6:AG6,3,0),0) -> 0 | AW23: =+IFERROR(VLOOKUP($AW$17,Sheet1!AD6:AG6,3,0),0) -> 0 | AX23: 90 | AY23: =+IFERROR(VLOOKUP($AY$17,Sheet1!AD6:AG6,3,0),0) -> 0 | AZ23: =+IFERROR(VLOOKUP($AZ$17,Sheet1!AD6:AG6,3,0),0) -> 0 | BA23: =+IFERROR(VLOOKUP($BA$17,Sheet1!AH6:AK6,3,0),0) -> 0 | BB23: =+IFERROR(VLOOKUP($BB$17,Sheet1!AH6:AK6,3,0),0) -> 0 | BC23: =+IFERROR(VLOOKUP($BC$17,Sheet1!AH6:AK6,3,0),0) -> 0 | BD23: =+IFERROR(VLOOKUP($BD$17,Sheet1!AH6:AK6,3,0),0) -> 0 | BE23: =+IFERROR(VLOOKUP($BE$17,Sheet1!AH6:AK6,3,0),0) -> 0 | BF23: =+IFERROR(VLOOKUP($BF$17,Sheet1!AH6:AK6,3,0),0) -> 0 | BG23: 577 | BH23: =+IFERROR(VLOOKUP($BH$17,Sheet1!AH6:AK6,3,0),0) -> 0 | BI23: =+IFERROR(VLOOKUP($BI$17,Sheet1!AH6:AK6,3,0),0) -> 0 | BJ23: =+IFERROR(VLOOKUP($BJ$17,Sheet1!AH6:AK6,3,0),0) -> 0 | BK23: =+IFERROR(VLOOKUP($BK$17,Sheet1!AH6:AK6,3,0),0) -> 0 | BL23: =+IFERROR(VLOOKUP($BL$17,Sheet1!AL6:AO6,3,0),0) -> 0 | BM23: =+IFERROR(VLOOKUP($BM$17,Sheet1!AL6:AO6,3,0),0) -> 0 | BN23: =+IFERROR(VLOOKUP($BN$17,Sheet1!AL6:AO6,3,0),0) -> 0 | BO23: =+IFERROR(VLOOKUP($BO$17,Sheet1!AL6:AO6,3,0),0) -> 0 | BP23: =+IFERROR(VLOOKUP($BP$17,Sheet1!AL6:AO6,3,0),0) -> 0 | BQ23: =+IFERROR(VLOOKUP($BQ$17,Sheet1!AL6:AO6,3,0),0) -> 0 | BR23: =+IFERROR(VLOOKUP($BR$17,Sheet1!AL6:AO6,3,0),0) -> 0 | BS23: =+IFERROR(VLOOKUP($BS$17,Sheet1!AL6:AO6,3,0),0) -> 0 | BT23: 304 | BU23: =+IFERROR(VLOOKUP($BU$17,Sheet1!AL6:AO6,3,0),0) -> 0 | BV23: =+IFERROR(VLOOKUP($BV$17,Sheet1!AL6:AO6,3,0),0) -> 0 | BW23: =+IFERROR(VLOOKUP($BW$17,Sheet1!AL6:AO6,3,0),0) -> 0 | BX23: =+IFERROR(VLOOKUP($BX$17,Sheet1!AP6:AS6,3,0),0) -> 0 | BY23: =+IFERROR(VLOOKUP($BY$17,Sheet1!AT6:AW6,3,0),0) -> 0 | BZ23: =+IFERROR(VLOOKUP($BZ$17,Sheet1!AX6:BA6,3,0),0) -> 0 | CA23: =+IFERROR(VLOOKUP($CA$17,Sheet1!BB6:BE6,3,0),0) -> 0 | CB23: =+IFERROR(VLOOKUP($CB$17,Sheet1!BF6:BI6,3,0),0) -> 0 | CC23: =+IFERROR(VLOOKUP($CC$17,Sheet1!BJ6:BM6,3,0),0) -> 0 | CD23: =+IFERROR(VLOOKUP($CD$17,Sheet1!BN6:BQ6,3,0),0) -> 0 | CE23: 45 | CF23: =+IFERROR(VLOOKUP($CF$17,Sheet1!BV6:BY6,3,0),0) -> 0 | CG23: =Sheet1!E6 -> WOOD | CH23: =Sheet1!CX6 -> MD0100061 | CI23: =Sheet1!CY6 -> DRUM - 56 X 24 X 32 X 3 | CJ23: =Sheet1!CZ6 -> 500 | CK23: =Sheet1!BZ6 -> 15824 | CL23: =SUMPRODUCT($N$18:$CF$18,N23:CF23)+CK23 -> 379215 | CM23: =Sheet1!CB6 -> 0 | CN23: =CL23*CM23 -> 0 | CO23: 0.35 | CP23: =CL23*CO23 -> 132725.25 | CQ23: 0 | CR23: =CL23*CQ23 -> 0 | CS23: =CL23+CN23+CP23+CR23 -> 511940.25 | CT23: 0.02 | CU23: =CS23*CT23 -> 10238.805 | CV23: 0.01 | CW23: =CS23*CV23 -> 5119.4025 | CX23: =Sheet1!CM6 -> 0 | CY23: =CX23*CS23 -> 0
A24: =Sheet1!A4 -> ENQ-16527-25-26 | B24: 45809 | C24: =Sheet1!C4 -> FA0900036 | D24: =Sheet1!D4 -> 4 CORE X 50 SQ. MM. ALU/ARD - STRIP (XLPE) | E24: =CS24+CU24+CW24+CY24 -> 303622.63 | F24: =ROUNDUP(M37,0) -> 10792 | G24: =E24+F24 -> 314414.63 | H24: =Sheet1!CR4 -> 0.18 | I24: =G24*H24 -> 56594.633 | J24: =G24+I24 -> 371009.26 | K24: =Sheet1!CU4 -> 60 | L24: =Sheet1!CV4 -> KMS | M24: =J24*K24 -> 22260556 | N24: =+IFERROR(VLOOKUP($N$17,Sheet1!J4:L4,3,0),0) -> 540 | O24: =+IFERROR(VLOOKUP($O$17,Sheet1!J4:L4,3,0),0) -> 0 | P24: =+IFERROR(VLOOKUP($P$17,Sheet1!J4:M4,3,0),0) -> 0 | Q24: =+IFERROR(VLOOKUP($Q$17,Sheet1!J4:M4,3,0),0) -> 0 | R24: =+IFERROR(VLOOKUP($R$17,Sheet1!J4:M4,3,0),0) -> 0 | S24: =+IFERROR(VLOOKUP($S$17,Sheet1!J4:M4,3,0),0) -> 0 | T24: =+IFERROR(VLOOKUP($T$17,Sheet1!J4:M4,3,0),0) -> 0 | U24: =+IFERROR(VLOOKUP($U$17,Sheet1!J4:M4,3,0),0) -> 0 | V24: =+IFERROR(VLOOKUP($V$17,Sheet1!N4:Q4,3,0),0) -> 0 | W24: =+IFERROR(VLOOKUP($W$17,Sheet1!N4:Q4,3,0),0) -> 0 | X24: =+IFERROR(VLOOKUP($X$17,Sheet1!F4:I4,3,0),0) -> 0 | Y24: =+IFERROR(VLOOKUP($Y$17,Sheet1!F4:I4,3,0),0) -> 0 | Z24: =+IFERROR(VLOOKUP($Z$17,Sheet1!F4:I4,3,0),0) -> 0 | AA24: =+IFERROR(VLOOKUP($AA$17,Sheet1!F4:I4,3,0),0) -> 0 | AB24: =+IFERROR(VLOOKUP($AB$17,Sheet1!F4:I4,3,0),0) -> 0 | AC24: =+IFERROR(VLOOKUP($AC$17,Sheet1!F4:I4,3,0),0) -> 0 | AD24: =+IFERROR(VLOOKUP($AD$17,Sheet1!F4:I4,3,0),0) -> 0 | AE24: =+IFERROR(VLOOKUP($AE$17,Sheet1!F4:I4,3,0),0) -> 0 | AF24: =+IFERROR(VLOOKUP($AF$17,Sheet1!R4:U4,3,0),0) -> 0 | AG24: =+IFERROR(VLOOKUP($AG$17,Sheet1!R4:U4,3,0),0) -> 0 | AH24: =+IFERROR(VLOOKUP($AH$17,Sheet1!V4:Y4,3,0),0) -> 0 | AI24: 144 | AJ24: =+IFERROR(VLOOKUP($AJ$17,Sheet1!V4:Y4,3,0),0) -> 0 | AK24: =+IFERROR(VLOOKUP($AK$17,Sheet1!V4:Y4,3,0),0) -> 0 | AL24: =+IFERROR(VLOOKUP($AL$17,Sheet1!V4:Y4,3,0),0) -> 0 | AM24: =+IFERROR(VLOOKUP($AM$17,Sheet1!V4:Y4,3,0),0) -> 0 | AN24: =+IFERROR(VLOOKUP($AN$17,Sheet1!V4:Y4,3,0),0) -> 0 | AO24: =+IFERROR(VLOOKUP($AO$17,Sheet1!V4:Y4,3,0),0) -> 0 | AP24: =+IFERROR(VLOOKUP($AP$17,Sheet1!V4:Y4,3,0),0) -> 0 | AQ24: =+IFERROR(VLOOKUP($AQ$17,Sheet1!Z4:AB4,3,0),0) -> 0 | AR24: =+IFERROR(VLOOKUP($AR$17,Sheet1!AD4:AG4,3,0),0) -> 0 | AS24: =+IFERROR(VLOOKUP($AS$17,Sheet1!AD4:AG4,3,0),0) -> 0 | AT24: =+IFERROR(VLOOKUP($AT$17,Sheet1!AD4:AG4,3,0),0) -> 0 | AU24: =+IFERROR(VLOOKUP($AU$17,Sheet1!AD4:AG4,3,0),0) -> 0 | AV24: =+IFERROR(VLOOKUP($AV$17,Sheet1!AD4:AG4,3,0),0) -> 0 | AW24: =+IFERROR(VLOOKUP($AW$17,Sheet1!AD4:AG4,3,0),0) -> 0 | AX24: =+IFERROR(VLOOKUP($AX$17,Sheet1!AD4:AG4,3,0),0) -> 69 | AY24: =+IFERROR(VLOOKUP($AY$17,Sheet1!AD4:AG4,3,0),0) -> 0 | AZ24: =+IFERROR(VLOOKUP($AZ$17,Sheet1!AD4:AG4,3,0),0) -> 0 | BA24: =+IFERROR(VLOOKUP($BA$17,Sheet1!AH4:AK4,3,0),0) -> 0 | BB24: =+IFERROR(VLOOKUP($BB$17,Sheet1!AH4:AK4,3,0),0) -> 0 | BC24: =+IFERROR(VLOOKUP($BC$17,Sheet1!AH4:AK4,3,0),0) -> 0 | BD24: =+IFERROR(VLOOKUP($BD$17,Sheet1!AH4:AK4,3,0),0) -> 0 | BE24: =+IFERROR(VLOOKUP($BE$17,Sheet1!AH4:AK4,3,0),0) -> 0 | BF24: =+IFERROR(VLOOKUP($BF$17,Sheet1!AH4:AK4,3,0),0) -> 0 | BG24: 425 | BH24: =+IFERROR(VLOOKUP($BH$17,Sheet1!AH4:AK4,3,0),0) -> 0 | BI24: =+IFERROR(VLOOKUP($BI$17,Sheet1!AH4:AK4,3,0),0) -> 0 | BJ24: =+IFERROR(VLOOKUP($BJ$17,Sheet1!AH4:AK4,3,0),0) -> 0 | BK24: =+IFERROR(VLOOKUP($BK$17,Sheet1!AH4:AK4,3,0),0) -> 0 | BL24: =+IFERROR(VLOOKUP($BL$17,Sheet1!AL4:AO4,3,0),0) -> 0 | BM24: =+IFERROR(VLOOKUP($BM$17,Sheet1!AL4:AO4,3,0),0) -> 0 | BN24: =+IFERROR(VLOOKUP($BN$17,Sheet1!AL4:AO4,3,0),0) -> 0 | BO24: =+IFERROR(VLOOKUP($BO$17,Sheet1!AL4:AO4,3,0),0) -> 0 | BP24: =+IFERROR(VLOOKUP($BP$17,Sheet1!AL4:AO4,3,0),0) -> 0 | BQ24: =+IFERROR(VLOOKUP($BQ$17,Sheet1!AL4:AO4,3,0),0) -> 0 | BR24: =+IFERROR(VLOOKUP($BR$17,Sheet1!AL4:AO4,3,0),0) -> 0 | BS24: =+IFERROR(VLOOKUP($BS$17,Sheet1!AL4:AO4,3,0),0) -> 0 | BT24: 235 | BU24: =+IFERROR(VLOOKUP($BU$17,Sheet1!AL4:AO4,3,0),0) -> 0 | BV24: =+IFERROR(VLOOKUP($BV$17,Sheet1!AL4:AO4,3,0),0) -> 0 | BW24: =+IFERROR(VLOOKUP($BW$17,Sheet1!AL4:AO4,3,0),0) -> 0 | BX24: =+IFERROR(VLOOKUP($BX$17,Sheet1!AP4:AS4,3,0),0) -> 0 | BY24: =+IFERROR(VLOOKUP($BY$17,Sheet1!AT4:AW4,3,0),0) -> 0 | BZ24: =+IFERROR(VLOOKUP($BZ$17,Sheet1!AX4:BA4,3,0),0) -> 0 | CA24: =+IFERROR(VLOOKUP($CA$17,Sheet1!BB4:BE4,3,0),0) -> 0 | CB24: =+IFERROR(VLOOKUP($CB$17,Sheet1!BF4:BI4,3,0),0) -> 0 | CC24: =+IFERROR(VLOOKUP($CC$17,Sheet1!BJ4:BM4,3,0),0) -> 0 | CD24: =+IFERROR(VLOOKUP($CD$17,Sheet1!BN4:BQ4,3,0),0) -> 0 | CE24: 21 | CF24: =+IFERROR(VLOOKUP($CF$17,Sheet1!BV4:BY4,3,0),0) -> 0 | CG24: =Sheet1!E4 -> WOOD | CH24: =Sheet1!CX4 -> MD0100015 | CI24: =Sheet1!CY4 -> DRUM - 48 X 20 X 28 X 2.25 - RDSO | CJ24: =Sheet1!CZ4 -> 500 | CK24: =Sheet1!BZ4 -> 8874 | CL24: =SUMPRODUCT($N$18:$CF$18,N24:CF24)+CK24 -> 218355 | CM24: =Sheet1!CB4 -> 0 | CN24: =CL24*CM24 -> 0 | CO24: 0.35 | CP24: =CL24*CO24 -> 76424.25 | CQ24: 0 | CR24: =CL24*CQ24 -> 0 | CS24: =CL24+CN24+CP24+CR24 -> 294779.25 | CT24: 0.02 | CU24: =CS24*CT24 -> 5895.585 | CV24: 0.01 | CW24: =CS24*CV24 -> 2947.7925 | CX24: =Sheet1!CM4 -> 0 | CY24: =CX24*CS24 -> 0
A25: =Sheet1!A3 -> ENQ-16527-25-26 | B25: 45809 | C25: =Sheet1!C3 -> FA0900018 | D25: =Sheet1!D3 -> 4 CORE X 35 SQ. MM. AL/ARD - STRIP (XLPE) | E25: =CS25+CU25+CW25+CY25 -> 237497.4 | F25: =ROUNDUP(M38,0) -> 9250 | G25: =E25+F25 -> 246747.4 | H25: =Sheet1!CR3 -> 0.18 | I25: =G25*H25 -> 44414.532 | J25: =G25+I25 -> 291161.93 | K25: =Sheet1!CU3 -> 60 | L25: =Sheet1!CV3 -> KMS | M25: =J25*K25 -> 17469716 | N25: =+IFERROR(VLOOKUP($N$17,Sheet1!J3:L3,3,0),0) -> 378 | O25: =+IFERROR(VLOOKUP($O$17,Sheet1!J3:L3,3,0),0) -> 0 | P25: =+IFERROR(VLOOKUP($P$17,Sheet1!J3:M3,3,0),0) -> 0 | Q25: =+IFERROR(VLOOKUP($Q$17,Sheet1!J3:M3,3,0),0) -> 0 | R25: =+IFERROR(VLOOKUP($R$17,Sheet1!J3:M3,3,0),0) -> 0 | S25: =+IFERROR(VLOOKUP($S$17,Sheet1!J3:M3,3,0),0) -> 0 | T25: =+IFERROR(VLOOKUP($T$17,Sheet1!J3:M3,3,0),0) -> 0 | U25: =+IFERROR(VLOOKUP($U$17,Sheet1!J3:M3,3,0),0) -> 0 | V25: =+IFERROR(VLOOKUP($V$17,Sheet1!N3:Q3,3,0),0) -> 0 | W25: =+IFERROR(VLOOKUP($W$17,Sheet1!N3:Q3,3,0),0) -> 0 | X25: =+IFERROR(VLOOKUP($X$17,Sheet1!F3:I3,3,0),0) -> 0 | Y25: =+IFERROR(VLOOKUP($Y$17,Sheet1!F3:I3,3,0),0) -> 0 | Z25: =+IFERROR(VLOOKUP($Z$17,Sheet1!F3:I3,3,0),0) -> 0 | AA25: =+IFERROR(VLOOKUP($AA$17,Sheet1!F3:I3,3,0),0) -> 0 | AB25: =+IFERROR(VLOOKUP($AB$17,Sheet1!F3:I3,3,0),0) -> 0 | AC25: =+IFERROR(VLOOKUP($AC$17,Sheet1!F3:I3,3,0),0) -> 0 | AD25: =+IFERROR(VLOOKUP($AD$17,Sheet1!F3:I3,3,0),0) -> 0 | AE25: =+IFERROR(VLOOKUP($AE$17,Sheet1!F3:I3,3,0),0) -> 0 | AF25: =+IFERROR(VLOOKUP($AF$17,Sheet1!R3:U3,3,0),0) -> 0 | AG25: =+IFERROR(VLOOKUP($AG$17,Sheet1!R3:U3,3,0),0) -> 0 | AH25: =+IFERROR(VLOOKUP($AH$17,Sheet1!V3:Y3,3,0),0) -> 0 | AI25: 120 | AJ25: =+IFERROR(VLOOKUP($AJ$17,Sheet1!V3:Y3,3,0),0) -> 0 | AK25: =+IFERROR(VLOOKUP($AK$17,Sheet1!V3:Y3,3,0),0) -> 0 | AL25: =+IFERROR(VLOOKUP($AL$17,Sheet1!V3:Y3,3,0),0) -> 0 | AM25: =+IFERROR(VLOOKUP($AM$17,Sheet1!V3:Y3,3,0),0) -> 0 | AN25: =+IFERROR(VLOOKUP($AN$17,Sheet1!V3:Y3,3,0),0) -> 0 | AO25: =+IFERROR(VLOOKUP($AO$17,Sheet1!V3:Y3,3,0),0) -> 0 | AP25: =+IFERROR(VLOOKUP($AP$17,Sheet1!V3:Y3,3,0),0) -> 0 | AQ25: =+IFERROR(VLOOKUP($AQ$17,Sheet1!Z3:AB3,3,0),0) -> 0 | AR25: =+IFERROR(VLOOKUP($AR$17,Sheet1!AD3:AG3,3,0),0) -> 0 | AS25: =+IFERROR(VLOOKUP($AS$17,Sheet1!AD3:AG3,3,0),0) -> 0 | AT25: =+IFERROR(VLOOKUP($AT$17,Sheet1!AD3:AG3,3,0),0) -> 0 | AU25: =+IFERROR(VLOOKUP($AU$17,Sheet1!AD3:AG3,3,0),0) -> 0 | AV25: =+IFERROR(VLOOKUP($AV$17,Sheet1!AD3:AG3,3,0),0) -> 0 | AW25: =+IFERROR(VLOOKUP($AW$17,Sheet1!AD3:AG3,3,0),0) -> 0 | AX25: 54 | AY25: =+IFERROR(VLOOKUP($AY$17,Sheet1!AD3:AG3,3,0),0) -> 0 | AZ25: =+IFERROR(VLOOKUP($AZ$17,Sheet1!AD3:AG3,3,0),0) -> 0 | BA25: =+IFERROR(VLOOKUP($BA$17,Sheet1!AH3:AK3,3,0),0) -> 0 | BB25: =+IFERROR(VLOOKUP($BB$17,Sheet1!AH3:AK3,3,0),0) -> 0 | BC25: =+IFERROR(VLOOKUP($BC$17,Sheet1!AH3:AK3,3,0),0) -> 0 | BD25: =+IFERROR(VLOOKUP($BD$17,Sheet1!AH3:AK3,3,0),0) -> 0 | BE25: =+IFERROR(VLOOKUP($BE$17,Sheet1!AH3:AK3,3,0),0) -> 0 | BF25: =+IFERROR(VLOOKUP($BF$17,Sheet1!AH3:AK3,3,0),0) -> 0 | BG25: 428 | BH25: =+IFERROR(VLOOKUP($BH$17,Sheet1!AH3:AK3,3,0),0) -> 0 | BI25: =+IFERROR(VLOOKUP($BI$17,Sheet1!AH3:AK3,3,0),0) -> 0 | BJ25: =+IFERROR(VLOOKUP($BJ$17,Sheet1!AH3:AK3,3,0),0) -> 0 | BK25: =+IFERROR(VLOOKUP($BK$17,Sheet1!AH3:AK3,3,0),0) -> 0 | BL25: =+IFERROR(VLOOKUP($BL$17,Sheet1!AL3:AO3,3,0),0) -> 0 | BM25: =+IFERROR(VLOOKUP($BM$17,Sheet1!AL3:AO3,3,0),0) -> 0 | BN25: =+IFERROR(VLOOKUP($BN$17,Sheet1!AL3:AO3,3,0),0) -> 0 | BO25: =+IFERROR(VLOOKUP($BO$17,Sheet1!AL3:AO3,3,0),0) -> 0 | BP25: =+IFERROR(VLOOKUP($BP$17,Sheet1!AL3:AO3,3,0),0) -> 0 | BQ25: =+IFERROR(VLOOKUP($BQ$17,Sheet1!AL3:AO3,3,0),0) -> 0 | BR25: =+IFERROR(VLOOKUP($BR$17,Sheet1!AL3:AO3,3,0),0) -> 0 | BS25: =+IFERROR(VLOOKUP($BS$17,Sheet1!AL3:AO3,3,0),0) -> 0 | BT25: 201 | BU25: =+IFERROR(VLOOKUP($BU$17,Sheet1!AL3:AO3,3,0),0) -> 0 | BV25: =+IFERROR(VLOOKUP($BV$17,Sheet1!AL3:AO3,3,0),0) -> 0 | BW25: =+IFERROR(VLOOKUP($BW$17,Sheet1!AL3:AO3,3,0),0) -> 0 | BX25: =+IFERROR(VLOOKUP($BX$17,Sheet1!AP3:AS3,3,0),0) -> 0 | BY25: =+IFERROR(VLOOKUP($BY$17,Sheet1!AT3:AW3,3,0),0) -> 0 | BZ25: =+IFERROR(VLOOKUP($BZ$17,Sheet1!AX3:BA3,3,0),0) -> 0 | CA25: =+IFERROR(VLOOKUP($CA$17,Sheet1!BB3:BE3,3,0),0) -> 0 | CB25: =+IFERROR(VLOOKUP($CB$17,Sheet1!BF3:BI3,3,0),0) -> 0 | CC25: =+IFERROR(VLOOKUP($CC$17,Sheet1!BJ3:BM3,3,0),0) -> 0 | CD25: =+IFERROR(VLOOKUP($CD$17,Sheet1!BN3:BQ3,3,0),0) -> 0 | CE25: 18 | CF25: =+IFERROR(VLOOKUP($CF$17,Sheet1!BV3:BY3,3,0),0) -> 0 | CG25: =Sheet1!E3 -> WOOD | CH25: =Sheet1!CX3 -> MD0100015 | CI25: =Sheet1!CY3 -> DRUM - 48 X 20 X 28 X 2.25 - RDSO | CJ25: =Sheet1!CZ3 -> 500 | CK25: =Sheet1!BZ3 -> 8874 | CL25: =SUMPRODUCT($N$18:$CF$18,N25:CF25)+CK25 -> 170800 | CM25: =Sheet1!CB3 -> 0 | CN25: =CL25*CM25 -> 0 | CO25: 0.35 | CP25: =CL25*CO25 -> 59780 | CQ25: 0 | CR25: =CL25*CQ25 -> 0 | CS25: =CL25+CN25+CP25+CR25 -> 230580 | CT25: 0.02 | CU25: =CS25*CT25 -> 4611.6 | CV25: 0.01 | CW25: =CS25*CV25 -> 2305.8 | CX25: =Sheet1!CM3 -> 0 | CY25: =CX25*CS25 -> 0
A26: =Sheet1!A2 -> ENQ-16527-25-26 | B26: 45809 | C26: =Sheet1!C2 -> FA0900013 | D26: =Sheet1!D2 -> 4 CORE X 16 SQ. MM. ALU/ARD - STRIP (XLPE) | E26: =CS26+CU26+CW26+CY26 -> 134345.94 | F26: =ROUNDUP(M39,0) -> 6475 | G26: =E26+F26 -> 140820.94 | H26: =Sheet1!CR2 -> 0.18 | I26: =G26*H26 -> 25347.769 | J26: =G26+I26 -> 166168.71 | K26: =Sheet1!CU2 -> 100 | L26: =Sheet1!CV2 -> KMS | M26: =J26*K26 -> 16616871 | N26: =+IFERROR(VLOOKUP($N$17,Sheet1!J2:L2,3,0),0) -> 173 | O26: =+IFERROR(VLOOKUP($O$17,Sheet1!J2:L2,3,0),0) -> 0 | P26: =+IFERROR(VLOOKUP($P$17,Sheet1!J2:M2,3,0),0) -> 0 | Q26: =+IFERROR(VLOOKUP($Q$17,Sheet1!J2:M2,3,0),0) -> 0 | R26: =+IFERROR(VLOOKUP($R$17,Sheet1!J2:M2,3,0),0) -> 0 | S26: =+IFERROR(VLOOKUP($S$17,Sheet1!J2:M2,3,0),0) -> 0 | T26: =+IFERROR(VLOOKUP($T$17,Sheet1!J2:M2,3,0),0) -> 0 | U26: =+IFERROR(VLOOKUP($U$17,Sheet1!J2:M2,3,0),0) -> 0 | V26: =+IFERROR(VLOOKUP($V$17,Sheet1!N2:Q2,3,0),0) -> 0 | W26: =+IFERROR(VLOOKUP($W$17,Sheet1!N2:Q2,3,0),0) -> 0 | X26: =+IFERROR(VLOOKUP($X$17,Sheet1!F2:I2,3,0),0) -> 0 | Y26: =+IFERROR(VLOOKUP($Y$17,Sheet1!F2:I2,3,0),0) -> 0 | Z26: =+IFERROR(VLOOKUP($Z$17,Sheet1!F2:I2,3,0),0) -> 0 | AA26: =+IFERROR(VLOOKUP($AA$17,Sheet1!F2:I2,3,0),0) -> 0 | AB26: =+IFERROR(VLOOKUP($AB$17,Sheet1!F2:I2,3,0),0) -> 0 | AC26: =+IFERROR(VLOOKUP($AC$17,Sheet1!F2:I2,3,0),0) -> 0 | AD26: =+IFERROR(VLOOKUP($AD$17,Sheet1!F2:I2,3,0),0) -> 0 | AE26: =+IFERROR(VLOOKUP($AE$17,Sheet1!F2:I2,3,0),0) -> 0 | AF26: =+IFERROR(VLOOKUP($AF$17,Sheet1!R2:U2,3,0),0) -> 0 | AG26: =+IFERROR(VLOOKUP($AG$17,Sheet1!R2:U2,3,0),0) -> 0 | AH26: =+IFERROR(VLOOKUP($AH$17,Sheet1!V2:Y2,3,0),0) -> 0 | AI26: 70 | AJ26: =+IFERROR(VLOOKUP($AJ$17,Sheet1!V2:Y2,3,0),0) -> 0 | AK26: =+IFERROR(VLOOKUP($AK$17,Sheet1!V2:Y2,3,0),0) -> 0 | AL26: =+IFERROR(VLOOKUP($AL$17,Sheet1!V2:Y2,3,0),0) -> 0 | AM26: =+IFERROR(VLOOKUP($AM$17,Sheet1!V2:Y2,3,0),0) -> 0 | AN26: =+IFERROR(VLOOKUP($AN$17,Sheet1!V2:Y2,3,0),0) -> 0 | AO26: =+IFERROR(VLOOKUP($AO$17,Sheet1!V2:Y2,3,0),0) -> 0 | AP26: =+IFERROR(VLOOKUP($AP$17,Sheet1!V2:Y2,3,0),0) -> 0 | AQ26: =+IFERROR(VLOOKUP($AQ$17,Sheet1!Z2:AB2,3,0),0) -> 0 | AR26: =+IFERROR(VLOOKUP($AR$17,Sheet1!AD2:AG2,3,0),0) -> 0 | AS26: =+IFERROR(VLOOKUP($AS$17,Sheet1!AD2:AG2,3,0),0) -> 0 | AT26: =+IFERROR(VLOOKUP($AT$17,Sheet1!AD2:AG2,3,0),0) -> 0 | AU26: =+IFERROR(VLOOKUP($AU$17,Sheet1!AD2:AG2,3,0),0) -> 0 | AV26: =+IFERROR(VLOOKUP($AV$17,Sheet1!AD2:AG2,3,0),0) -> 0 | AW26: =+IFERROR(VLOOKUP($AW$17,Sheet1!AD2:AG2,3,0),0) -> 0 | AX26: 42 | AY26: =+IFERROR(VLOOKUP($AY$17,Sheet1!AD2:AG2,3,0),0) -> 0 | AZ26: =+IFERROR(VLOOKUP($AZ$17,Sheet1!AD2:AG2,3,0),0) -> 0 | BA26: =+IFERROR(VLOOKUP($BA$17,Sheet1!AH2:AK2,3,0),0) -> 0 | BB26: =+IFERROR(VLOOKUP($BB$17,Sheet1!AH2:AK2,3,0),0) -> 0 | BC26: =+IFERROR(VLOOKUP($BC$17,Sheet1!AH2:AK2,3,0),0) -> 0 | BD26: =+IFERROR(VLOOKUP($BD$17,Sheet1!AH2:AK2,3,0),0) -> 0 | BE26: =+IFERROR(VLOOKUP($BE$17,Sheet1!AH2:AK2,3,0),0) -> 0 | BF26: =+IFERROR(VLOOKUP($BF$17,Sheet1!AH2:AK2,3,0),0) -> 0 | BG26: 315 | BH26: =+IFERROR(VLOOKUP($BH$17,Sheet1!AH2:AK2,3,0),0) -> 0 | BI26: =+IFERROR(VLOOKUP($BI$17,Sheet1!AH2:AK2,3,0),0) -> 0 | BJ26: =+IFERROR(VLOOKUP($BJ$17,Sheet1!AH2:AK2,3,0),0) -> 0 | BK26: =+IFERROR(VLOOKUP($BK$17,Sheet1!AH2:AK2,3,0),0) -> 0 | BL26: =+IFERROR(VLOOKUP($BL$17,Sheet1!AL2:AO2,3,0),0) -> 0 | BM26: =+IFERROR(VLOOKUP($BM$17,Sheet1!AL2:AO2,3,0),0) -> 0 | BN26: =+IFERROR(VLOOKUP($BN$17,Sheet1!AL2:AO2,3,0),0) -> 0 | BO26: =+IFERROR(VLOOKUP($BO$17,Sheet1!AL2:AO2,3,0),0) -> 0 | BP26: =+IFERROR(VLOOKUP($BP$17,Sheet1!AL2:AO2,3,0),0) -> 0 | BQ26: =+IFERROR(VLOOKUP($BQ$17,Sheet1!AL2:AO2,3,0),0) -> 0 | BR26: =+IFERROR(VLOOKUP($BR$17,Sheet1!AL2:AO2,3,0),0) -> 0 | BS26: =+IFERROR(VLOOKUP($BS$17,Sheet1!AL2:AO2,3,0),0) -> 0 | BT26: 154 | BU26: =+IFERROR(VLOOKUP($BU$17,Sheet1!AL2:AO2,3,0),0) -> 0 | BV26: =+IFERROR(VLOOKUP($BV$17,Sheet1!AL2:AO2,3,0),0) -> 0 | BW26: =+IFERROR(VLOOKUP($BW$17,Sheet1!AL2:AO2,3,0),0) -> 0 | BX26: =+IFERROR(VLOOKUP($BX$17,Sheet1!AP2:AS2,3,0),0) -> 0 | BY26: =+IFERROR(VLOOKUP($BY$17,Sheet1!AT2:AW2,3,0),0) -> 0 | BZ26: =+IFERROR(VLOOKUP($BZ$17,Sheet1!AX2:BA2,3,0),0) -> 0 | CA26: =+IFERROR(VLOOKUP($CA$17,Sheet1!BB2:BE2,3,0),0) -> 0 | CB26: =+IFERROR(VLOOKUP($CB$17,Sheet1!BF2:BI2,3,0),0) -> 0 | CC26: =+IFERROR(VLOOKUP($CC$17,Sheet1!BJ2:BM2,3,0),0) -> 0 | CD26: =+IFERROR(VLOOKUP($CD$17,Sheet1!BN2:BQ2,3,0),0) -> 0 | CE26: 14 | CF26: =+IFERROR(VLOOKUP($CF$17,Sheet1!BV2:BY2,3,0),0) -> 0 | CG26: =Sheet1!E2 -> WOOD | CH26: =Sheet1!CX2 -> MD0100066 | CI26: =Sheet1!CY2 -> DRUM - 40 X 15 X 23 X 2 | CJ26: =Sheet1!CZ2 -> 500 | CK26: =Sheet1!BZ2 -> 5448 | CL26: =SUMPRODUCT($N$18:$CF$18,N26:CF26)+CK26 -> 96617 | CM26: =Sheet1!CB2 -> 0 | CN26: =CL26*CM26 -> 0 | CO26: 0.35 | CP26: =CL26*CO26 -> 33815.95 | CQ26: 0 | CR26: =CL26*CQ26 -> 0 | CS26: =CL26+CN26+CP26+CR26 -> 130432.95 | CT26: 0.02 | CU26: =CS26*CT26 -> 2608.659 | CV26: 0.01 | CW26: =CS26*CV26 -> 1304.3295 | CX26: =Sheet1!CM2 -> 0 | CY26: =CX26*CS26 -> 0
