Workbook

Sheet Sheet1
A1: DOCKET NO. | B1: Base Date | C1: ITEM CODE | D1: PROPOSE ERP ITEM NAME | E1: Propose Drum Type | F1: Insulation Screening(Metallic) | G1: RM Rate(Insulation Screening(Metallic)) | H1: Weight (Insulation Screening (Metallic)) | I1: Cost Insulation Screening(Metallic) | J1: Conductor | K1: RM Rate(Conductor) | L1: Weight(Conductor) | M1: Cost(Conductor) | N1: AL ALLOY | O1: RM Rate(AL Alloy) | P1: Weight(Al Alloy) | Q1: Cost(AL Alloy) | R1: Insulation Screening(Non-Metallic) | S1: RM Rate(Insulation Screening(Non-Metallic)) | T1: Weight(Insulation Screening(Non-Metallic) | U1: Cost(Insulation Screening(Non-Metallic) | V1: Insulation | W1: RM Rate(Insulation) | X1: Weight(Insulation) | Y1: Cost(Insulation) | Z1: Poly Tape | AA1: RM Rate(Poly Tape) | AB1: Weight(Poly Tape) | AC1: Cost(Poly Tape) | AD1: Inner Sheath | AE1: RM Rate(Inner Sheath) | AF1: Weight(Inner Sheath) | AG1: Cost(Inner Sheath) | AH1: Armouring | AI1: RM Rate(Armouring) | AJ1: Weight(Armouring) | AK1: Cost(Armouring) | AL1: Outer Sheath | AM1: RM Rate(Outer Sheath) | AN1: Weight(Outer Sheath) | AO1: Cost(Outer Sheath) | AP1: Filler | AQ1: RM Rate(Filler) | AR1: Weight(Filler) | AS1: Cost(Filler) | AT1: Grease | AU1: RM Rate(Grease) | AV1: Weight(Grease) | AW1: Cost(Grease) | AX1: Water Swellable Tape | AY1: RM Rate(Water Swellable Tape) | AZ1: Weight(Water Swellable Tape) | BA1: Cost(Water Swellable Tape) | BB1: Semi Conducting Water Swellable Tape | BC1: RM Rate(Semi Conducting Water Swellable Tape) | BD1: Weight(Semi Conducting Water Swellable Tape) | BE1: Cost(Semi Conducting Water Swellable Tape) | BF1: Semicon Tape | BG1: RM Rate(Semicon Tape) | BH1: Weight(Semicon Tape) | BI1: Cost(Semicon Tape) | BJ1: Glass Fiber Tape | BK1: RM Rate(Glass Fiber Tape) | BL1: Weight(Glass Fiber Tape) | BM1: Cost(Glass Fiber Tape) | BN1: Copper Wire 0.8MM | BO1: RM Rate(Copper Wire 0.8MM) | BP1: Weight(Copper Wire 0.8MM) | BQ1: Cost(Copper Wire 0.8MM) | BR1: Rubberized Cotton Tape | BS1: RM Rate(Rubberized Cotton Tape) | BT1: Weight(Rubberized Cotton Tape) | BU1: Cost(Rubberized Cotton Tape) | BV1: Water Tight Compound | BW1: RM Rate(Water Tight Compound) | BX1: Weight(Water Tight Compound) | BY1: Cost(Water Tight Compound) | BZ1: Drum Cost Per KM | CA1: Total RM Cost | CB1: FIRM % | CC1: Firm Value | CD1: MFG% | CE1: MFG Value | CF1: PROF% | CG1: Profit Value | CH1: 1st EX-Works | CI1: Intt % | CJ1: Intt Value | CK1: insp% | CL1: Insp Value | CM1: TTR CHARGES% | CN1: TTR Value | CO1: EX-Works Per KM | CP1: Freight Per KM | CQ1: Price Including Freight Per KM | CR1: GST % | CS1: GST Value | CT1: Price Including GST & Freight Per KM | CU1: QTY | CV1: Unit | CW1: Total Price Of Full QTY(Including Freight&GST) | CX1: PARTY LENGTH (IF STANDER LENGTH NOT MATCH WITH PAR | CY1: DRUM CODE | CZ1: DRUM SIZE (FxbXtx Ft)
A2: ENQ-18774-25-26 | C2: FA0700001 | D2: 1 CORE X 120 SQ. MM. AL/ARD (XLPE) | E2: STEEL | H2: 0 | J2: Alumimium | L2: 324 | P2: 0 | T2: 0 | V2: LT-XLPE | X2: 75 | AB2: 0 | AF2: 0 | AH2: Aluminium Round Wire | AJ2: 157 | AL2: FRLSH PVC Type ST-2 | AN2: 165 | AR2: 0 | AV2: 0 | AZ2: 0 | BD2: 0 | BH2: 0 | BL2: 0 | BP2: 0 | BR2: RUBBERIZED COTTON TAPE | BT2: 0 | BX2: 0 | CR2: 0.18 | CU2: 10 | CV2: KMS
A3: ENQ-18774-25-26 | C3: FA0700001 | D3: 1 CORE X 120 SQ. MM. AL/ARD (XLPE) | E3: STEEL | H3: 0 | J3: Alumimium | L3: 324 | P3: 0 | T3: 0 | V3: LT-XLPE | X3: 75 | AB3: 0 | AF3: 0 | AH3: Aluminium Round Wire | AJ3: 157 | AL3: FRLSH PVC Type ST-2 | AN3: 165 | AR3: 0 | AV3: 0 | AZ3: 0 | BD3: 0 | BH3: 0 | BL3: 0 | BP3: 0 | BR3: RUBBERIZED COTTON TAPE | BT3: 0 | BX3: 0 | CR3: 0.18 | CU3: 14 | CV3: KMS | CX3: 500
A4: ENQ-18774-25-26 | C4: FA0700002 | D4: 1 CORE X 630 SQ. MM. AL/ARD (XLPE) | E4: STEEL | H4: 0 | J4: Alumimium | L4: 1701 | P4: 0 | T4: 0 | V4: LT-XLPE | X4: 295 | AB4: 0 | AF4: 0 | AH4: Aluminium Round Wire | AJ4: 431 | AL4: FRLSH PVC Type ST-2 | AN4: 443 | AR4: 0 | AV4: 0 | AZ4: 0 | BD4: 0 | BH4: 0 | BL4: 0 | BP4: 0 | BR4: RUBBERIZED COTTON TAPE | BT4: 0 | BX4: 0 | CR4: 0.18 | CU4: 10 | CV4: KMS | CX4: 500
A5: ENQ-18774-25-26 | C5: FA0700008 | D5: 1 CORE X 300 SQ. MM. AL/ARD. (XLPE) | E5: STEEL | H5: 0 | J5: Alumimium | L5: 810 | P5: 0 | T5: 0 | V5: LT-XLPE | X5: 154 | AB5: 0 | AF5: 0 | AH5: Aluminium Round Wire | AJ5: 238 | AL5: FRLSH PVC Type ST-2 | AN5: 259 | AR5: 0 | AV5: 0 | AZ5: 0 | BD5: 0 | BH5: 0 | BL5: 0 | BP5: 0 | BR5: RUBBERIZED COTTON TAPE | BT5: 0 | BX5: 0 | CR5: 0.18 | CU5: 12 | CV5: KMS | CX5: 500
A6: ENQ-18774-25-26 | C6: FA0900036 | D6: 4 CORE X 50 SQ. MM. ALU/ARD - STRIP (XLPE) | E6: WOOD | H6: 0 | J6: Alumimium | L6: 540 | P6: 0 | T6: 0 | V6: LT-XLPE | X6: 128 | AB6: 0 | AD6: PVC Type ST-2 | AF6: 58 | AH6: Galvanised Steel Flat Strip | AJ6: 425 | AL6: PVC Type ST-2 | AN6: 226 | AR6: 0 | AV6: 0 | AZ6: 0 | BD6: 0 | BH6: 0 | BL6: 0 | BP6: 0 | BR6: RUBBERIZED COTTON TAPE | BT6: 0 | BX6: 0 | BZ6: 8874 | CA6: 8874 | CH6: 8874 | CO6: 8874 | CQ6: 8874 | CR6: 0.18 | CS6: 1597.32 | CT6: 10471.32 | CU6: 140 | CV6: KMS | CW6: 1465985 | CX6: 500 | CY6: MD0100015 | CZ6: DRUM - 48 X 20 X 28 X 2.25 - RDSO
A7: ENQ-18774-25-26 | C7: FA1100012 | D7: 4 CORE X 95 SQ. MM. AL/ARD - STRIP (XLPE) | E7: WOOD | H7: 0 | J7: Alumimium | L7: 1026 | P7: 0 | T7: 0 | V7: LT-XLPE | X7: 187 | AB7: 0 | AD7: PVC Type ST-2 | AF7: 93 | AH7: Galvanised Steel Flat Strip | AJ7: 611 | AL7: PVC Type ST-2 | AN7: 348 | AR7: 0 | AV7: 0 | AZ7: 0 | BD7: 0 | BH7: 0 | BL7: 0 | BP7: 0 | BR7: RUBBERIZED COTTON TAPE | BT7: 0 | BX7: 0 | BZ7: 15824 | CA7: 15824 | CH7: 15824 | CO7: 15824 | CQ7: 15824 | CR7: 0.18 | CS7: 2848.32 | CT7: 18672.32 | CU7: 600 | CV7: KMS | CW7: 11203392 | CX7: 500 | CY7: MD0100061 | CZ7: DRUM - 56 X 24 X 32 X 3
A8: ENQ-18774-25-26 | C8: FA1100025 | D8: 4 CORE X 300 SQ. MM. AL/ARD - STRIP (XLPE) | E8: STEEL | H8: 0 | J8: Alumimium | L8: 3240 | P8: 0 | T8: 0 | V8: LT-XLPE | X8: 518 | AB8: 0 | AD8: PVC Type ST-2 | AF8: 271 | AH8: Galvanised Steel Flat Strip | AJ8: 1070 | AL8: PVC Type ST-2 | AN8: 767 | AR8: 0 | AV8: 0 | AZ8: 0 | BD8: 0 | BH8: 0 | BL8: 0 | BP8: 0 | BR8: RUBBERIZED COTTON TAPE | BT8: 0 | BX8: 0 | CR8: 0.18 | CU8: 50 | CV8: KMS | CX8: 500
A9: ENQ-18774-25-26 | C9: FA1100067 | D9: 4 CORE X 150 SQ. MM. AL/ARD - STRIP (XLPE) | H9: 0 | L9: 1620 | P9: 0 | T9: 0 | X9: 297 | AB9: 0 | AF9: 138 | AJ9: 777 | AN9: 479 | AR9: 0 | AV9: 0 | AZ9: 0 | BD9: 0 | BH9: 0 | BL9: 0 | BP9: 0 | BT9: 0 | BX9: 0 | CR9: 0.18 | CU9: 100 | CV9: KMS | CX9: 500

Sheet AUTO CALCULATION SHEET (2)
A2: Noida Power Company Ltd.
A4: TENDER SPECIFICATION NO () | B4: NPCL/FY25-26/LTCAB/060
A5: TENDER DESCRIPTION () | B5: TENDER NOTIFICATION FOR TWO YEAR RATE CONTRACT OF SUPPLY OF LT ABC & LT CABLES LOT 2
A6: Last Date & Time of Submission () | B6: 18.03.2026 (up to 15:00 hours) OPENING ON '18.03.2026 up to 15:00 Hours
A7: REVERSE AUCTION | B7: Purchaser reserves the right to use Reverse Auction through SAP-SRM as an optional tool as an integral part of the entire tendering process. All techno-commercially qualified bidders shall participate in this event.
A8: Price () | B8: Prices are As per latest IEEMA Price Variation Clause. The prices shall variable be as per Latest IEEMA Price Variation formula as mentioned below; P=Po+AIF(Al-Alo)+XLFAL(Cc-Cco)+CCFAl(PVCc-PVCco)+FeF(Fe-Feo) All #0# denoted input prices in the formula (Al0, CC0, PVCc0, Fe0, etc.) shall be as per IEEMA Circulars of January 2026 (Published in February 2026). The prices shall variable be as per Latest IEEMA Price Variation formula as mentioned below; Formula for LV Aerial Bunch Cables P = P0 + Alph * n* (Al-Al0) + Alm(Al-Al0) + Alsl(Al-Al0) + Aln(Al-Al0) + CCFAlph *n* (CC-Cco)+CCFAlm(CC- Cco)+CCFAlsl (CC-Cco) + CCFAln(CC-Cco) This price shall be as per IEEMA Circulars of January 2026 (Published in February 2026).
A9: Validity () | B9: Bids shall remain valid for 120 days from the due date of submission of the Bid & subsequent corrigendum / amendment / extension of due date of submission.
A10: Delivery Period () | B10: 60 Days from the date of issuance of LOI / Order; however, firm delivery dates will be mentioned in the LOI / Order.
A11: Payment Terms () | B11: 15% Basic value of Release Order payment shall be paid as interest free advance against submission of Advance Bank Guarantee (ABG) of a nationalized/scheduled bank(s) located at State Capital/Delhi NCR, payable at Delhi/Noida / Corporate Guarantee as may be acceptable to the NPCL, for the equal amount valid up to the PO supply completion period plus 3 months claim period. In case of delay, the BG shall be extended suitably by the bidder. Bidder can request to submit Corporate guarantee in place of ABG, Same request can be considered with discretion of NPCL management only. 80% payment shall be released on pro-rata basic within 45 days from the receipt of material at NPCL site with complete set of documents as mentioned in order. Your invoices complete in all respect along with all required documents should reach our office within 3 days. Any delay in submission of any of these documents will be to your account. It may please be noted that for payment purposes the date of receipt of documents will be considered on the basis of the date of receipt of last document, in case partial documents were received earlier. Balance 5% payment shall be released against submission of the Performance Bank Guarantee (PBG) of 5% of PO/Contract value valid till 12 months from the date of commissioning or 18 months from the date of dispatch, whichever is earlier Plus 3 months towards the Claim Period.
A12: Standard length () | B12: 1cx120 = 500mtr+/-2% 3cx120+120+95 = 500mtr+/-2% The cable shall be supplied in continuous standard length of 500 running meters with +2% to tolerance
A13: Packing () | B13: 1cx120 = Good Quality Wood 3cx120+120+95 = the cable shall be supplied on suitable sized wooden non-returnable drum of robust construction for each length of cables as per IS 10418. The cable shall be wound on non-returnable wooden drum of good quality, heavy standard construction conforming to IS:10418:1982
A14: Technical Specification
N18: Conductor | V18: AL ALLOY | X18: Insulation Screening (Metallic) | AF18: Insulation Screening (Non-Metallic) | AH18: Insulation | AQ18: POLY TAPE | AR18: Inner Sheath | BA18: Armouring | BL18: Outer Sheath | BX18: FILLER | BY18: GREASE | BZ18: Water swellable Tape | CA18: Semi conducting Water Swellable tape | CB18: SEMICON TAPE | CC18: GLASS FIBER TAPE | CD18: COPPER WIRE 0.8 MM | CE18: RUBBERIZED COTTON TAPE | CF18: Water Tight Compound | CG18: DRUM TYPE | CK18: DRUM COST PER KM | CL18: TOTAL RM COST | CM18: EXTRA CONSUMPTION | CN18: EXTRA CONSUMPTION VALUE | CZ18: $A$1
A19: DOCKET NO. | B19: BASE DATE | C19: ITEM CODE | D19: PROPOSE ERP ITEM NAME | E19: EX-WORKS (PER KM) | F19: FREIGHT PER KM | G19: PRICE INCLUDING FREIGHT (PER KM) | H19: GST % | I19: GST VALUE | J19: PRICE INCLUDING GST & FREIGHT (PER KM) | K19: QTY | L19: Unit | M19: TOTAL PRICE OF FULL QTY (INCLUDING FRIGHT & GST) | N19: Alumimium | O19: Alumimium ALLOY | P19: Copper | Q19: AL-59 | R19: AL-4 | S19: AL-7 | T19: Flexible Copper | U19: Galvanized steel wire | V19: Alumimium | W19: Alumimium ALLOY | X19: Coper tape - 0.1 mm | Y19: Copper Tape - 0.03 mm | Z19: Copper Tape - 0.035 mm | AA19: Copper Tape - 0.04 mm | AB19: Copper Tape - 0.045 mm | AC19: Copper Tape - 0.050 mm | AD19: Copper Tape - 0.060 mm | AE19: Copper Tape - 0.075 mm(DOUBLE) | AF19: Extruded semiconductive | AG19: Extruded Semiconductive(Stripable) | AH19: HT-XLPE | AI19: LT-XLPE | AJ19: TR XLPE | AK19: Type A PVC | AL19: Type C PVC (HR) | AM19: Type A PVC-1.45 | AN19: Type A PVC-FR | AO19: Type A PVC-FRLS | AP19: Type A PVC-1.38 | AQ19: POLY TAPE | AR19: FR PVC Type ST-1 | AS19: FR PVC Type ST-2 | AT19: FRLSH PVC Type ST-1 | AU19: FRLSH PVC Type ST-2 | AV19: PVC Type ST-1 | AW19: PVC Type ST-1-PRESSURE EXTRUDED | AX19: PVC Type ST-2 | AY19: PVC COMPOUND 1.48 | AZ19: PVC Type ST-2-PRESSURE EXTRUDED | BA19: ACSR CORE WIRE | BB19: ACSR DOG STEEL WIRE | BC19: Aluminium Flat Strip | BD19: Aluminium Round Wire | BE19: Alumimium Tape | BF19: Double Steel Tape | BG19: Galvanised Steel Flat Strip | BH19: Galvanised Steel Flat Strip (Double) | BI19: Galvanised Steel Flat Strip-B | BJ19: Galvanised Steel Round Wire | BK19: Galvanised Steel Round Wire (Double) | BL19: FR PVC Type ST-1 | BM19: FR PVC Type ST-2 | BN19: FRLSH PVC Type ST-1 | BO19: FRLSH PVC Type ST-2 + UV resistance | BP19: ZHFR | BQ19: PE-ST-3 | BR19: PE-ST-7 | BS19: PVC Type ST-2 | BT19: FRLSH PVC Type ST-2 | BU19: PVC COMPOUND 1.48 | BV19: PVC Type ST-2-PRESSURE EXTRUDED | BW19: UV & Track Resistant XLPE | BX19: FILLER | BY19: Grease | BZ19: Water swellable Tape | CA19: Semi conducting Water Swellable tape | CB19: SEMICON TAPE | CC19: GLASS FIBER TAPE | CD19: COPPER WIRE 0.8 MM | CE19: RUBBERIZED COTTON TAPE | CF19: Water Tight Compound | CG19: PROPOSE DRUM TYPE | CH19: DRUM CODE | CI19: DRUM SIZE (FxbXtx Ft) | CJ19: PARTY STANDARD LENGTH (MTR) | CO19: MFG% | CP19: MFG VALUE | CQ19: PROF% | CR19: PROFIT VALUE | CS19: 1ST EX-WORKS | CT19: Intt % | CU19: INTT VALUE | CV19: insp% | CW19: INSP VALUE | CX19: TTR Charges% | CY19: TTR Charges VALUE
N20: 418 | O20: =N20+5 -> 423 | P20: =+IFERROR(VLOOKUP($P$19,Sheet1!J:M,2,0),0) -> 0 | Q20: =+IFERROR(VLOOKUP($Q$19,Sheet1!J:M,2,0),0) -> 0 | R20: =+IFERROR(VLOOKUP($R$19,Sheet1!J:M,2,0),0) -> 0 | S20: =+IFERROR(VLOOKUP($S$19,Sheet1!J:M,2,0),0) -> 0 | T20: =+IFERROR(VLOOKUP($T$19,Sheet1!J:M,2,0),0) -> 0 | U20: =+IFERROR(VLOOKUP($U$19,Sheet1!J:M,2,0),0) -> 0 | V20: =+IFERROR(VLOOKUP($V$19,Sheet1!N:Q,2,0),0) -> 0 | W20: =+IFERROR(VLOOKUP($W$19,Sheet1!N:O,2,0),0) -> 0 | X20: =+IFERROR(VLOOKUP($X$19,Sheet1!F:I,2,0),0) -> 0 | Y20: =+IFERROR(VLOOKUP($Y$19,Sheet1!F:I,2,0),0) -> 0 | Z20: =+IFERROR(VLOOKUP($Z$19,Sheet1!F:I,2,0),0) -> 0 | AA20: =+IFERROR(VLOOKUP($AA$19,Sheet1!F:I,2,0),0) -> 0 | AB20: =+IFERROR(VLOOKUP($AB$19,Sheet1!F:I,2,0),0) -> 0 | AC20: =+IFERROR(VLOOKUP($AC$19,Sheet1!F:I,2,0),0) -> 0 | AD20: =+IFERROR(VLOOKUP($AD$19,Sheet1!F:I,2,0),0) -> 0 | AE20: =+IFERROR(VLOOKUP($AE$19,Sheet1!F:I,2,0),0) -> 0 | AF20: =+IFERROR(VLOOKUP($AF$19,Sheet1!R:U,2,0),0) -> 0 | AG20: =+IFERROR(VLOOKUP($AG$19,Sheet1!R:U,2,0),0) -> 0 | AH20: =+IFERROR(VLOOKUP($AH$19,Sheet1!V:Y,2,0),0) -> 0 | AI20: 150 | AJ20: =+IFERROR(VLOOKUP($AJ$19,Sheet1!V:Y,2,0),0) -> 0 | AK20: =+IFERROR(VLOOKUP($AK$19,Sheet1!V:Y,2,0),0) -> 0 | AL20: =+IFERROR(VLOOKUP($AL$19,Sheet1!V:Y,2,0),0) -> 0 | AM20: =+IFERROR(VLOOKUP($AM$19,Sheet1!V:Y,2,0),0) -> 0 | AN20: =+IFERROR(VLOOKUP($AN$19,Sheet1!V:Y,2,0),0) -> 0 | AO20: =+IFERROR(VLOOKUP($AO$19,Sheet1!V:Y,2,0),0) -> 0 | AP20: =+IFERROR(VLOOKUP($AP$19,Sheet1!V:Y,2,0),0) -> 0 | AQ20: =+IFERROR(VLOOKUP($AQ$19,Sheet1!Z2:AA840,2,0),0) -> 0 | AR20: =+IFERROR(VLOOKUP($AR$19,Sheet1!AD2:AG840,2,0),0) -> 0 | AS20: =+IFERROR(VLOOKUP($AS$19,Sheet1!AD2:AG840,2,0),0) -> 0 | AT20: =+IFERROR(VLOOKUP($AT$19,Sheet1!AD2:AG840,2,0),0) -> 0 | AU20: =+IFERROR(VLOOKUP($AU$19,Sheet1!AD2:AG840,2,0),0) -> 0 | AV20: =+IFERROR(VLOOKUP($AV$19,Sheet1!AD2:AG840,2,0),0) -> 0 | AW20: =+IFERROR(VLOOKUP($AW$19,Sheet1!AD2:AG840,2,0),0) -> 0 | AX20: 59 | AY20: =+IFERROR(VLOOKUP($AY$19,Sheet1!AD2:AG840,2,0),0) -> 0 | AZ20: =+IFERROR(VLOOKUP($AZ$19,Sheet1!AD2:AG840,2,0),0) -> 0 | BA20: =+IFERROR(VLOOKUP($BA$19,Sheet1!AH2:AK840,2,0),0) -> 0 | BB20: =+IFERROR(VLOOKUP($BB$19,Sheet1!AH2:AK840,2,0),0) -> 0 | BC20: =+IFERROR(VLOOKUP($BC$19,Sheet1!AH2:AK840,2,0),0) -> 0 | BD20: =N20+5 -> 423 | BE20: =+IFERROR(VLOOKUP($BE$19,Sheet1!AH2:AK840,2,0),0) -> 0 | BF20: =+IFERROR(VLOOKUP($BF$19,Sheet1!AH2:AK840,2,0),0) -> 0 | BG20: 87 | BH20: =+IFERROR(VLOOKUP($BH$19,Sheet1!AH2:AK840,2,0),0) -> 0 | BI20: =+IFERROR(VLOOKUP($BI$19,Sheet1!AH2:AK840,2,0),0) -> 0 | BJ20: =+IFERROR(VLOOKUP($BJ$19,Sheet1!AH2:AK840,2,0),0) -> 0 | BK20: =+IFERROR(VLOOKUP($BK$19,Sheet1!AH2:AK840,2,0),0) -> 0 | BL20: =+IFERROR(VLOOKUP($BL$19,Sheet1!AL2:AO840,2,0),0) -> 0 | BM20: =+IFERROR(VLOOKUP($BM$19,Sheet1!AL2:AO840,2,0),0) -> 0 | BN20: =+IFERROR(VLOOKUP($BN$19,Sheet1!AL2:AO840,2,0),0) -> 0 | BO20: =98+5 -> 103 | BP20: =+IFERROR(VLOOKUP($BP$19,Sheet1!AL2:AO840,2,0),0) -> 0 | BQ20: =+IFERROR(VLOOKUP($BQ$19,Sheet1!AL2:AO840,2,0),0) -> 0 | BR20: =+IFERROR(VLOOKUP($BR$19,Sheet1!AL2:AO840,2,0),0) -> 0 | BS20: 79 | BT20: 98 | BU20: =+IFERROR(VLOOKUP($BU$19,Sheet1!AL2:AO840,2,0),0) -> 0 | BV20: =+IFERROR(VLOOKUP($BV$19,Sheet1!AL2:AO840,2,0),0) -> 0 | BW20: =+IFERROR(VLOOKUP($BW$19,Sheet1!AL2:AO840,2,0),0) -> 0 | BX20: =+IFERROR(VLOOKUP($BX$19,Sheet1!AP2:AS840,2,0),0) -> 0 | BY20: =+IFERROR(VLOOKUP($BY$19,Sheet1!AT2:AW840,2,0),0) -> 0 | BZ20: =+IFERROR(VLOOKUP($BZ$19,Sheet1!AX2:BA840,2,0),0) -> 0 | CA20: =+IFERROR(VLOOKUP($CA$19,Sheet1!BB2:BE840,2,0),0) -> 0 | CB20: =+IFERROR(VLOOKUP($CB$19,Sheet1!BF2:BI840,2,0),0) -> 0 | CC20: =+IFERROR(VLOOKUP($CC$19,Sheet1!BJ2:BM840,2,0),0) -> 0 | CD20: =+IFERROR(VLOOKUP($CD$19,Sheet1!BN2:BQ840,2,0),0) -> 0 | CE20: 294 | CF20: =+IFERROR(VLOOKUP($CF$19,Sheet1!BV2:BY840,2,0),0) -> 0
A21: =Sheet1!A6 -> ENQ-18774-25-26 | B21: 46143 | C21: =Sheet1!C6 -> FA0900036 | D21: =Sheet1!D6 -> 4 CORE X 50 SQ. MM. ALU/ARD - STRIP (XLPE) | E21: =CS21+CU21+CW21+CY21 -> 438368.97 | F21: =ROUNDUP(M39,0) -> 9643 | G21: =E21+F21 -> 448011.97 | H21: =Sheet1!CR6 -> 0.18 | I21: =G21*H21 -> 80642.155 | J21: =G21+I21 -> 528654.12 | K21: =Sheet1!CU6 -> 140 | L21: =Sheet1!CV6 -> KMS | M21: =J21*K21 -> 74011577 | N21: =+IFERROR(VLOOKUP($N$19,Sheet1!J6:L6,3,0),0) -> 540 | O21: =+IFERROR(VLOOKUP($O$19,Sheet1!J6:L6,3,0),0) -> 0 | P21: =+IFERROR(VLOOKUP($P$19,Sheet1!J6:M6,3,0),0) -> 0 | Q21: =+IFERROR(VLOOKUP($Q$19,Sheet1!J6:M6,3,0),0) -> 0 | R21: =+IFERROR(VLOOKUP($R$19,Sheet1!J6:M6,3,0),0) -> 0 | S21: =+IFERROR(VLOOKUP($S$19,Sheet1!J6:M6,3,0),0) -> 0 | T21: =+IFERROR(VLOOKUP($T$19,Sheet1!J6:M6,3,0),0) -> 0 | U21: =+IFERROR(VLOOKUP($U$19,Sheet1!J6:M6,3,0),0) -> 0 | V21: =+IFERROR(VLOOKUP($V$19,Sheet1!N6:Q6,3,0),0) -> 0 | W21: =+IFERROR(VLOOKUP($W$19,Sheet1!N6:Q6,3,0),0) -> 0 | X21: =+IFERROR(VLOOKUP($X$19,Sheet1!F6:I6,3,0),0) -> 0 | Y21: =+IFERROR(VLOOKUP($Y$19,Sheet1!F6:I6,3,0),0) -> 0 | Z21: =+IFERROR(VLOOKUP($Z$19,Sheet1!F6:I6,3,0),0) -> 0 | AA21: =+IFERROR(VLOOKUP($AA$19,Sheet1!F6:I6,3,0),0) -> 0 | AB21: =+IFERROR(VLOOKUP($AB$19,Sheet1!F6:I6,3,0),0) -> 0 | AC21: =+IFERROR(VLOOKUP($AC$19,Sheet1!F6:I6,3,0),0) -> 0 | AD21: =+IFERROR(VLOOKUP($AD$19,Sheet1!F6:I6,3,0),0) -> 0 | AE21: =+IFERROR(VLOOKUP($AE$19,Sheet1!F6:I6,3,0),0) -> 0 | AF21: =+IFERROR(VLOOKUP($AF$19,Sheet1!R6:U6,3,0),0) -> 0 | AG21: =+IFERROR(VLOOKUP($AG$19,Sheet1!R6:U6,3,0),0) -> 0 | AH21: =+IFERROR(VLOOKUP($AH$19,Sheet1!V6:Y6,3,0),0) -> 0 | AI21: 144 | AJ21: =+IFERROR(VLOOKUP($AJ$19,Sheet1!V6:Y6,3,0),0) -> 0 | AK21: =+IFERROR(VLOOKUP($AK$19,Sheet1!V6:Y6,3,0),0) -> 0 | AL21: =+IFERROR(VLOOKUP($AL$19,Sheet1!V6:Y6,3,0),0) -> 0 | AM21: =+IFERROR(VLOOKUP($AM$19,Sheet1!V6:Y6,3,0),0) -> 0 | AN21: =+IFERROR(VLOOKUP($AN$19,Sheet1!V6:Y6,3,0),0) -> 0 | AO21: =+IFERROR(VLOOKUP($AO$19,Sheet1!V6:Y6,3,0),0) -> 0 | AP21: =+IFERROR(VLOOKUP($AP$19,Sheet1!V6:Y6,3,0),0) -> 0 | AQ21: =+IFERROR(VLOOKUP($AQ$19,Sheet1!Z6:AB6,3,0),0) -> 0 | AR21: =+IFERROR(VLOOKUP($AR$19,Sheet1!AD6:AG6,3,0),0) -> 0 | AS21: =+IFERROR(VLOOKUP($AS$19,Sheet1!AD6:AG6,3,0),0) -> 0 | AT21: =+IFERROR(VLOOKUP($AT$19,Sheet1!AD6:AG6,3,0),0) -> 0 | AU21: =+IFERROR(VLOOKUP($AU$19,Sheet1!AD6:AG6,3,0),0) -> 0 | AV21: =+IFERROR(VLOOKUP($AV$19,Sheet1!AD6:AG6,3,0),0) -> 0 | AW21: =+IFERROR(VLOOKUP($AW$19,Sheet1!AD6:AG6,3,0),0) -> 0 | AX21: 60 | AY21: =+IFERROR(VLOOKUP($AY$19,Sheet1!AD6:AG6,3,0),0) -> 0 | AZ21: =+IFERROR(VLOOKUP($AZ$19,Sheet1!AD6:AG6,3,0),0) -> 0 | BA21: =+IFERROR(VLOOKUP($BA$19,Sheet1!AH6:AK6,3,0),0) -> 0 | BB21: =+IFERROR(VLOOKUP($BB$19,Sheet1!AH6:AK6,3,0),0) -> 0 | BC21: =+IFERROR(VLOOKUP($BC$19,Sheet1!AH6:AK6,3,0),0) -> 0 | BD21: =+IFERROR(VLOOKUP($BD$19,Sheet1!AH6:AK6,3,0),0) -> 0 | BE21: =+IFERROR(VLOOKUP($BE$19,Sheet1!AH6:AK6,3,0),0) -> 0 | BF21: =+IFERROR(VLOOKUP($BF$19,Sheet1!AH6:AK6,3,0),0) -> 0 | BG21: 446 | BH21: =+IFERROR(VLOOKUP($BH$19,Sheet1!AH6:AK6,3,0),0) -> 0 | BI21: =+IFERROR(VLOOKUP($BI$19,Sheet1!AH6:AK6,3,0),0) -> 0 | BJ21: =+IFERROR(VLOOKUP($BJ$19,Sheet1!AH6:AK6,3,0),0) -> 0 | BK21: =+IFERROR(VLOOKUP($BK$19,Sheet1!AH6:AK6,3,0),0) -> 0 | BL21: =+IFERROR(VLOOKUP($BL$19,Sheet1!AL6:AO6,3,0),0) -> 0 | BM21: =+IFERROR(VLOOKUP($BM$19,Sheet1!AL6:AO6,3,0),0) -> 0 | BN21: =+IFERROR(VLOOKUP($BN$19,Sheet1!AL6:AO6,3,0),0) -> 0 | BO21: 245 | BP21: =+IFERROR(VLOOKUP($BP$19,Sheet1!AL6:AO6,3,0),0) -> 0 | BQ21: =+IFERROR(VLOOKUP($BQ$19,Sheet1!AL6:AO6,3,0),0) -> 0 | BR21: =+IFERROR(VLOOKUP($BR$19,Sheet1!AL6:AO6,3,0),0) -> 0 | BU21: =+IFERROR(VLOOKUP($BU$19,Sheet1!AL6:AO6,3,0),0) -> 0 | BV21: =+IFERROR(VLOOKUP($BV$19,Sheet1!AL6:AO6,3,0),0) -> 0 | BW21: =+IFERROR(VLOOKUP($BW$19,Sheet1!AL6:AO6,3,0),0) -> 0 | BX21: =+IFERROR(VLOOKUP($BX$19,Sheet1!AP6:AS6,3,0),0) -> 0 | BY21: =+IFERROR(VLOOKUP($BY$19,Sheet1!AT6:AW6,3,0),0) -> 0 | BZ21: =+IFERROR(VLOOKUP($BZ$19,Sheet1!AX6:BA6,3,0),0) -> 0 | CA21: =+IFERROR(VLOOKUP($CA$19,Sheet1!BB6:BE6,3,0),0) -> 0 | CB21: =+IFERROR(VLOOKUP($CB$19,Sheet1!BF6:BI6,3,0),0) -> 0 | CC21: =+IFERROR(VLOOKUP($CC$19,Sheet1!BJ6:BM6,3,0),0) -> 0 | CD21: =+IFERROR(VLOOKUP($CD$19,Sheet1!BN6:BQ6,3,0),0) -> 0 | CE21: 36 | CF21: =+IFERROR(VLOOKUP($CF$19,Sheet1!BV6:BY6,3,0),0) -> 0 | CG21: =Sheet1!E6 -> WOOD | CH21: =Sheet1!CY6 -> MD0100015 | CI21: =Sheet1!CZ6 -> DRUM - 48 X 20 X 28 X 2.25 - RDSO | CJ21: =Sheet1!CX6 -> 500 | CK21: =2557/0.5 -> 5114 | CL21: =SUMPRODUCT($N$20:$CF$20,N21:CF21)+CK21 -> 330595 | CM21: =Sheet1!CB6 -> 0 | CN21: =CL21*CM21 -> 0 | CO21: 0.3 | CP21: =CL21*CO21 -> 99178.5 | CQ21: 0 | CR21: =CL21*CQ21 -> 0 | CS21: =CL21+CN21+CP21+CR21 -> 429773.5 | CT21: 0.02 | CU21: =CS21*CT21 -> 8595.47 | CV21: =Sheet1!CK6 -> 0 | CW21: =CS21*CV21 -> 0 | CX21: =Sheet1!CM6 -> 0 | CY21: =CX21*CS21 -> 0
A22: =Sheet1!A7 -> ENQ-18774-25-26 | B22: 46143 | C22: =Sheet1!C7 -> FA1100012 | D22: =Sheet1!D7 -> 4 CORE X 95 SQ. MM. AL/ARD - STRIP (XLPE) | E22: =CS22+CU22+CW22+CY22 -> 761698.16 | F22: =ROUNDUP(M40,0) -> 18750 | G22: =E22+F22 -> 780448.16 | H22: =Sheet1!CR7 -> 0.18 | I22: =G22*H22 -> 140480.67 | J22: =G22+I22 -> 920928.83 | K22: =Sheet1!CU7 -> 600 | L22: =Sheet1!CV7 -> KMS | M22: =J22*K22 -> 5.525573e+08 | N22: =+IFERROR(VLOOKUP($N$19,Sheet1!J7:L7,3,0),0) -> 1026 | O22: =+IFERROR(VLOOKUP($O$19,Sheet1!J7:L7,3,0),0) -> 0 | P22: =+IFERROR(VLOOKUP($P$19,Sheet1!J7:M7,3,0),0) -> 0 | Q22: =+IFERROR(VLOOKUP($Q$19,Sheet1!J7:M7,3,0),0) -> 0 | R22: =+IFERROR(VLOOKUP($R$19,Sheet1!J7:M7,3,0),0) -> 0 | S22: =+IFERROR(VLOOKUP($S$19,Sheet1!J7:M7,3,0),0) -> 0 | T22: =+IFERROR(VLOOKUP($T$19,Sheet1!J7:M7,3,0),0) -> 0 | U22: =+IFERROR(VLOOKUP($U$19,Sheet1!J7:M7,3,0),0) -> 0 | V22: =+IFERROR(VLOOKUP($V$19,Sheet1!N7:Q7,3,0),0) -> 0 | W22: =+IFERROR(VLOOKUP($W$19,Sheet1!N7:Q7,3,0),0) -> 0 | X22: =+IFERROR(VLOOKUP($X$19,Sheet1!F7:I7,3,0),0) -> 0 | Y22: =+IFERROR(VLOOKUP($Y$19,Sheet1!F7:I7,3,0),0) -> 0 | Z22: =+IFERROR(VLOOKUP($Z$19,Sheet1!F7:I7,3,0),0) -> 0 | AA22: =+IFERROR(VLOOKUP($AA$19,Sheet1!F7:I7,3,0),0) -> 0 | AB22: =+IFERROR(VLOOKUP($AB$19,Sheet1!F7:I7,3,0),0) -> 0 | AC22: =+IFERROR(VLOOKUP($AC$19,Sheet1!F7:I7,3,0),0) -> 0 | AD22: =+IFERROR(VLOOKUP($AD$19,Sheet1!F7:I7,3,0),0) -> 0 | AE22: =+IFERROR(VLOOKUP($AE$19,Sheet1!F7:I7,3,0),0) -> 0 | AF22: =+IFERROR(VLOOKUP($AF$19,Sheet1!R7:U7,3,0),0) -> 0 | AG22: =+IFERROR(VLOOKUP($AG$19,Sheet1!R7:U7,3,0),0) -> 0 | AH22: =+IFERROR(VLOOKUP($AH$19,Sheet1!V7:Y7,3,0),0) -> 0 | AI22: 204 | AJ22: =+IFERROR(VLOOKUP($AJ$19,Sheet1!V7:Y7,3,0),0) -> 0 | AK22: =+IFERROR(VLOOKUP($AK$19,Sheet1!V7:Y7,3,0),0) -> 0 | AL22: =+IFERROR(VLOOKUP($AL$19,Sheet1!V7:Y7,3,0),0) -> 0 | AM22: =+IFERROR(VLOOKUP($AM$19,Sheet1!V7:Y7,3,0),0) -> 0 | AN22: =+IFERROR(VLOOKUP($AN$19,Sheet1!V7:Y7,3,0),0) -> 0 | AO22: =+IFERROR(VLOOKUP($AO$19,Sheet1!V7:Y7,3,0),0) -> 0 | AP22: =+IFERROR(VLOOKUP($AP$19,Sheet1!V7:Y7,3,0),0) -> 0 | AQ22: =+IFERROR(VLOOKUP($AQ$19,Sheet1!Z7:AB7,3,0),0) -> 0 | AR22: =+IFERROR(VLOOKUP($AR$19,Sheet1!AD7:AG7,3,0),0) -> 0 | AS22: =+IFERROR(VLOOKUP($AS$19,Sheet1!AD7:AG7,3,0),0) -> 0 | AT22: =+IFERROR(VLOOKUP($AT$19,Sheet1!AD7:AG7,3,0),0) -> 0 | AU22: =+IFERROR(VLOOKUP($AU$19,Sheet1!AD7:AG7,3,0),0) -> 0 | AV22: =+IFERROR(VLOOKUP($AV$19,Sheet1!AD7:AG7,3,0),0) -> 0 | AW22: =+IFERROR(VLOOKUP($AW$19,Sheet1!AD7:AG7,3,0),0) -> 0 | AX22: 96 | AY22: =+IFERROR(VLOOKUP($AY$19,Sheet1!AD7:AG7,3,0),0) -> 0 | AZ22: =+IFERROR(VLOOKUP($AZ$19,Sheet1!AD7:AG7,3,0),0) -> 0 | BA22: =+IFERROR(VLOOKUP($BA$19,Sheet1!AH7:AK7,3,0),0) -> 0 | BB22: =+IFERROR(VLOOKUP($BB$19,Sheet1!AH7:AK7,3,0),0) -> 0 | BC22: =+IFERROR(VLOOKUP($BC$19,Sheet1!AH7:AK7,3,0),0) -> 0 | BD22: =+IFERROR(VLOOKUP($BD$19,Sheet1!AH7:AK7,3,0),0) -> 0 | BE22: =+IFERROR(VLOOKUP($BE$19,Sheet1!AH7:AK7,3,0),0) -> 0 | BF22: =+IFERROR(VLOOKUP($BF$19,Sheet1!AH7:AK7,3,0),0) -> 0 | BG22: 577 | BH22: =+IFERROR(VLOOKUP($BH$19,Sheet1!AH7:AK7,3,0),0) -> 0 | BI22: =+IFERROR(VLOOKUP($BI$19,Sheet1!AH7:AK7,3,0),0) -> 0 | BJ22: =+IFERROR(VLOOKUP($BJ$19,Sheet1!AH7:AK7,3,0),0) -> 0 | BK22: =+IFERROR(VLOOKUP($BK$19,Sheet1!AH7:AK7,3,0),0) -> 0 | BL22: =+IFERROR(VLOOKUP($BL$19,Sheet1!AL7:AO7,3,0),0) -> 0 | BM22: =+IFERROR(VLOOKUP($BM$19,Sheet1!AL7:AO7,3,0),0) -> 0 | BN22: =+IFERROR(VLOOKUP($BN$19,Sheet1!AL7:AO7,3,0),0) -> 0 | BO22: 310 | BP22: =+IFERROR(VLOOKUP($BP$19,Sheet1!AL7:AO7,3,0),0) -> 0 | BQ22: =+IFERROR(VLOOKUP($BQ$19,Sheet1!AL7:AO7,3,0),0) -> 0 | BR22: =+IFERROR(VLOOKUP($BR$19,Sheet1!AL7:AO7,3,0),0) -> 0 | BU22: =+IFERROR(VLOOKUP($BU$19,Sheet1!AL7:AO7,3,0),0) -> 0 | BV22: =+IFERROR(VLOOKUP($BV$19,Sheet1!AL7:AO7,3,0),0) -> 0 | BW22: =+IFERROR(VLOOKUP($BW$19,Sheet1!AL7:AO7,3,0),0) -> 0 | BX22: =+IFERROR(VLOOKUP($BX$19,Sheet1!AP7:AS7,3,0),0) -> 0 | BY22: =+IFERROR(VLOOKUP($BY$19,Sheet1!AT7:AW7,3,0),0) -> 0 | BZ22: =+IFERROR(VLOOKUP($BZ$19,Sheet1!AX7:BA7,3,0),0) -> 0 | CA22: =+IFERROR(VLOOKUP($CA$19,Sheet1!BB7:BE7,3,0),0) -> 0 | CB22: =+IFERROR(VLOOKUP($CB$19,Sheet1!BF7:BI7,3,0),0) -> 0 | CC22: =+IFERROR(VLOOKUP($CC$19,Sheet1!BJ7:BM7,3,0),0) -> 0 | CD22: =+IFERROR(VLOOKUP($CD$19,Sheet1!BN7:BQ7,3,0),0) -> 0 | CE22: 47 | CF22: =+IFERROR(VLOOKUP($CF$19,Sheet1!BV7:BY7,3,0),0) -> 0 | CG22: =Sheet1!E7 -> WOOD | CH22: =Sheet1!CY7 -> MD0100061 | CI22: =Sheet1!CZ7 -> DRUM - 56 X 24 X 32 X 3 | CJ22: =Sheet1!CX7 -> 500 | CK22: =6677/0.5 -> 13354 | CL22: =SUMPRODUCT($N$20:$CF$20,N22:CF22)+CK22 -> 574433 | CM22: =Sheet1!CB7 -> 0 | CN22: =CL22*CM22 -> 0 | CO22: 0.3 | CP22: =CL22*CO22 -> 172329.9 | CQ22: 0 | CR22: =CL22*CQ22 -> 0 | CS22: =CL22+CN22+CP22+CR22 -> 746762.9 | CT22: 0.02 | CU22: =CS22*CT22 -> 14935.258 | CV22: =Sheet1!CK7 -> 0 | CW22: =CS22*CV22 -> 0 | CX22: =Sheet1!CM7 -> 0 | CY22: =CX22*CS22 -> 0
A23: =Sheet1!A9 -> ENQ-18774-25-26 | B23: 46143 | C23: =Sheet1!C9 -> FA1100067 | D23: =Sheet1!D9 -> 4 CORE X 150 SQ. MM. AL/ARD - STRIP (XLPE) | E23: =CS23+CU23+CW23+CY23 -> 1166321.8 | F23: =ROUNDUP(M41,0) -> 25500 | G23: =E23+F23 -> 1191821.8 | H23: =Sheet1!CR9 -> 0.18 | I23: =G23*H23 -> 214527.92 | J23: =G23+I23 -> 1406349.7 | K23: =Sheet1!CU9 -> 100 | L23: =Sheet1!CV9 -> KMS | M23: =J23*K23 -> 1.4063497e+08 | N23: 1620 | O23: =+IFERROR(VLOOKUP($O$19,Sheet1!J9:L9,3,0),0) -> 0 | P23: =+IFERROR(VLOOKUP($P$19,Sheet1!J9:M9,3,0),0) -> 0 | Q23: =+IFERROR(VLOOKUP($Q$19,Sheet1!J9:M9,3,0),0) -> 0 | R23: =+IFERROR(VLOOKUP($R$19,Sheet1!J9:M9,3,0),0) -> 0 | S23: =+IFERROR(VLOOKUP($S$19,Sheet1!J9:M9,3,0),0) -> 0 | T23: =+IFERROR(VLOOKUP($T$19,Sheet1!J9:M9,3,0),0) -> 0 | U23: =+IFERROR(VLOOKUP($U$19,Sheet1!J9:M9,3,0),0) -> 0 | V23: =+IFERROR(VLOOKUP($V$19,Sheet1!N9:Q9,3,0),0) -> 0 | W23: =+IFERROR(VLOOKUP($W$19,Sheet1!N9:Q9,3,0),0) -> 0 | X23: =+IFERROR(VLOOKUP($X$19,Sheet1!F9:I9,3,0),0) -> 0 | Y23: =+IFERROR(VLOOKUP($Y$19,Sheet1!F9:I9,3,0),0) -> 0 | Z23: =+IFERROR(VLOOKUP($Z$19,Sheet1!F9:I9,3,0),0) -> 0 | AA23: =+IFERROR(VLOOKUP($AA$19,Sheet1!F9:I9,3,0),0) -> 0 | AB23: =+IFERROR(VLOOKUP($AB$19,Sheet1!F9:I9,3,0),0) -> 0 | AC23: =+IFERROR(VLOOKUP($AC$19,Sheet1!F9:I9,3,0),0) -> 0 | AD23: =+IFERROR(VLOOKUP($AD$19,Sheet1!F9:I9,3,0),0) -> 0 | AE23: =+IFERROR(VLOOKUP($AE$19,Sheet1!F9:I9,3,0),0) -> 0 | AF23: =+IFERROR(VLOOKUP($AF$19,Sheet1!R9:U9,3,0),0) -> 0 | AG23: =+IFERROR(VLOOKUP($AG$19,Sheet1!R9:U9,3,0),0) -> 0 | AH23: =+IFERROR(VLOOKUP($AH$19,Sheet1!V9:Y9,3,0),0) -> 0 | AI23: 315 | AJ23: =+IFERROR(VLOOKUP($AJ$19,Sheet1!V9:Y9,3,0),0) -> 0 | AK23: =+IFERROR(VLOOKUP($AK$19,Sheet1!V9:Y9,3,0),0) -> 0 | AL23: =+IFERROR(VLOOKUP($AL$19,Sheet1!V9:Y9,3,0),0) -> 0 | AM23: =+IFERROR(VLOOKUP($AM$19,Sheet1!V9:Y9,3,0),0) -> 0 | AN23: =+IFERROR(VLOOKUP($AN$19,Sheet1!V9:Y9,3,0),0) -> 0 | AO23: =+IFERROR(VLOOKUP($AO$19,Sheet1!V9:Y9,3,0),0) -> 0 | AP23: =+IFERROR(VLOOKUP($AP$19,Sheet1!V9:Y9,3,0),0) -> 0 | AQ23: =+IFERROR(VLOOKUP($AQ$19,Sheet1!Z9:AB9,3,0),0) -> 0 | AR23: =+IFERROR(VLOOKUP($AR$19,Sheet1!AD9:AG9,3,0),0) -> 0 | AS23: =+IFERROR(VLOOKUP($AS$19,Sheet1!AD9:AG9,3,0),0) -> 0 | AT23: =+IFERROR(VLOOKUP($AT$19,Sheet1!AD9:AG9,3,0),0) -> 0 | AU23: =+IFERROR(VLOOKUP($AU$19,Sheet1!AD9:AG9,3,0),0) -> 0 | AV23: =+IFERROR(VLOOKUP($AV$19,Sheet1!AD9:AG9,3,0),0) -> 0 | AW23: =+IFERROR(VLOOKUP($AW$19,Sheet1!AD9:AG9,3,0),0) -> 0 | AX23: 165 | AY23: =+IFERROR(VLOOKUP($AY$19,Sheet1!AD9:AG9,3,0),0) -> 0 | AZ23: =+IFERROR(VLOOKUP($AZ$19,Sheet1!AD9:AG9,3,0),0) -> 0 | BA23: =+IFERROR(VLOOKUP($BA$19,Sheet1!AH9:AK9,3,0),0) -> 0 | BB23: =+IFERROR(VLOOKUP($BB$19,Sheet1!AH9:AK9,3,0),0) -> 0 | BC23: =+IFERROR(VLOOKUP($BC$19,Sheet1!AH9:AK9,3,0),0) -> 0 | BD23: =+IFERROR(VLOOKUP($BD$19,Sheet1!AH9:AK9,3,0),0) -> 0 | BE23: =+IFERROR(VLOOKUP($BE$19,Sheet1!AH9:AK9,3,0),0) -> 0 | BF23: =+IFERROR(VLOOKUP($BF$19,Sheet1!AH9:AK9,3,0),0) -> 0 | BG23: 735 | BH23: =+IFERROR(VLOOKUP($BH$19,Sheet1!AH9:AK9,3,0),0) -> 0 | BI23: =+IFERROR(VLOOKUP($BI$19,Sheet1!AH9:AK9,3,0),0) -> 0 | BJ23: =+IFERROR(VLOOKUP($BJ$19,Sheet1!AH9:AK9,3,0),0) -> 0 | BK23: =+IFERROR(VLOOKUP($BK$19,Sheet1!AH9:AK9,3,0),0) -> 0 | BL23: =+IFERROR(VLOOKUP($BL$19,Sheet1!AL9:AO9,3,0),0) -> 0 | BM23: =+IFERROR(VLOOKUP($BM$19,Sheet1!AL9:AO9,3,0),0) -> 0 | BN23: =+IFERROR(VLOOKUP($BN$19,Sheet1!AL9:AO9,3,0),0) -> 0 | BO23: 453 | BP23: =+IFERROR(VLOOKUP($BP$19,Sheet1!AL9:AO9,3,0),0) -> 0 | BQ23: =+IFERROR(VLOOKUP($BQ$19,Sheet1!AL9:AO9,3,0),0) -> 0 | BR23: =+IFERROR(VLOOKUP($BR$19,Sheet1!AL9:AO9,3,0),0) -> 0 | BU23: =+IFERROR(VLOOKUP($BU$19,Sheet1!AL9:AO9,3,0),0) -> 0 | BV23: =+IFERROR(VLOOKUP($BV$19,Sheet1!AL9:AO9,3,0),0) -> 0 | BW23: =+IFERROR(VLOOKUP($BW$19,Sheet1!AL9:AO9,3,0),0) -> 0 | BX23: =+IFERROR(VLOOKUP($BX$19,Sheet1!AP9:AS9,3,0),0) -> 0 | BY23: =+IFERROR(VLOOKUP($BY$19,Sheet1!AT9:AW9,3,0),0) -> 0 | BZ23: =+IFERROR(VLOOKUP($BZ$19,Sheet1!AX9:BA9,3,0),0) -> 0 | CA23: =+IFERROR(VLOOKUP($CA$19,Sheet1!BB9:BE9,3,0),0) -> 0 | CB23: =+IFERROR(VLOOKUP($CB$19,Sheet1!BF9:BI9,3,0),0) -> 0 | CC23: =+IFERROR(VLOOKUP($CC$19,Sheet1!BJ9:BM9,3,0),0) -> 0 | CD23: =+IFERROR(VLOOKUP($CD$19,Sheet1!BN9:BQ9,3,0),0) -> 0 | CE23: 58 | CF23: =+IFERROR(VLOOKUP($CF$19,Sheet1!BV9:BY9,3,0),0) -> 0 | CG23: WOOD | CH23: MD0100070 | CI23: DRUM - 68 X 24 X 32 X 3 | CJ23: =Sheet1!CX9 -> 500 | CK23: =8889/0.5 -> 17778 | CL23: =SUMPRODUCT($N$20:$CF$20,N23:CF23)+CK23 -> 879579 | CM23: =Sheet1!CB9 -> 0 | CN23: =CL23*CM23 -> 0 | CO23: 0.3 | CP23: =CL23*CO23 -> 263873.7 | CQ23: 0 | CR23: =CL23*CQ23 -> 0 | CS23: =CL23+CN23+CP23+CR23 -> 1143452.7 | CT23: 0.02 | CU23: =CS23*CT23 -> 22869.054 | CV23: =Sheet1!CK9 -> 0 | CW23: =CS23*CV23 -> 0 | CX23: =Sheet1!CM9 -> 0 | CY23: =CX23*CS23 -> 0
A24: =Sheet1!A8 -> ENQ-18774-25-26 | B24: 46143 | C24: =Sheet1!C8 -> FA1100025 | D24: =Sheet1!D8 -> 4 CORE X 300 SQ. MM. AL/ARD - STRIP (XLPE) | E24: =CS24+CU24+CW24+CY24 -> 2214018.2 | F24: =ROUNDUP(M42,0) -> 45900 | G24: =E24+F24 -> 2259918.2 | H24: =Sheet1!CR8 -> 0.18 | I24: =G24*H24 -> 406785.28 | J24: =G24+I24 -> 2666703.5 | K24: =Sheet1!CU8 -> 50 | L24: =Sheet1!CV8 -> KMS | M24: =J24*K24 -> 1.3333518e+08 | N24: =+IFERROR(VLOOKUP($N$19,Sheet1!J8:L8,3,0),0) -> 3240 | O24: =+IFERROR(VLOOKUP($O$19,Sheet1!J8:L8,3,0),0) -> 0 | P24: =+IFERROR(VLOOKUP($P$19,Sheet1!J8:M8,3,0),0) -> 0 | Q24: =+IFERROR(VLOOKUP($Q$19,Sheet1!J8:M8,3,0),0) -> 0 | R24: =+IFERROR(VLOOKUP($R$19,Sheet1!J8:M8,3,0),0) -> 0 | S24: =+IFERROR(VLOOKUP($S$19,Sheet1!J8:M8,3,0),0) -> 0 | T24: =+IFERROR(VLOOKUP($T$19,Sheet1!J8:M8,3,0),0) -> 0 | U24: =+IFERROR(VLOOKUP($U$19,Sheet1!J8:M8,3,0),0) -> 0 | V24: =+IFERROR(VLOOKUP($V$19,Sheet1!N8:Q8,3,0),0) -> 0 | W24: =+IFERROR(VLOOKUP($W$19,Sheet1!N8:Q8,3,0),0) -> 0 | X24: =+IFERROR(VLOOKUP($X$19,Sheet1!F8:I8,3,0),0) -> 0 | Y24: =+IFERROR(VLOOKUP($Y$19,Sheet1!F8:I8,3,0),0) -> 0 | Z24: =+IFERROR(VLOOKUP($Z$19,Sheet1!F8:I8,3,0),0) -> 0 | AA24: =+IFERROR(VLOOKUP($AA$19,Sheet1!F8:I8,3,0),0) -> 0 | AB24: =+IFERROR(VLOOKUP($AB$19,Sheet1!F8:I8,3,0),0) -> 0 | AC24: =+IFERROR(VLOOKUP($AC$19,Sheet1!F8:I8,3,0),0) -> 0 | AD24: =+IFERROR(VLOOKUP($AD$19,Sheet1!F8:I8,3,0),0) -> 0 | AE24: =+IFERROR(VLOOKUP($AE$19,Sheet1!F8:I8,3,0),0) -> 0 | AF24: =+IFERROR(VLOOKUP($AF$19,Sheet1!R8:U8,3,0),0) -> 0 | AG24: =+IFERROR(VLOOKUP($AG$19,Sheet1!R8:U8,3,0),0) -> 0 | AH24: =+IFERROR(VLOOKUP($AH$19,Sheet1!V8:Y8,3,0),0) -> 0 | AI24: 560 | AJ24: =+IFERROR(VLOOKUP($AJ$19,Sheet1!V8:Y8,3,0),0) -> 0 | AK24: =+IFERROR(VLOOKUP($AK$19,Sheet1!V8:Y8,3,0),0) -> 0 | AL24: =+IFERROR(VLOOKUP($AL$19,Sheet1!V8:Y8,3,0),0) -> 0 | AM24: =+IFERROR(VLOOKUP($AM$19,Sheet1!V8:Y8,3,0),0) -> 0 | AN24: =+IFERROR(VLOOKUP($AN$19,Sheet1!V8:Y8,3,0),0) -> 0 | AO24: =+IFERROR(VLOOKUP($AO$19,Sheet1!V8:Y8,3,0),0) -> 0 | AP24: =+IFERROR(VLOOKUP($AP$19,Sheet1!V8:Y8,3,0),0) -> 0 | AQ24: =+IFERROR(VLOOKUP($AQ$19,Sheet1!Z8:AB8,3,0),0) -> 0 | AR24: =+IFERROR(VLOOKUP($AR$19,Sheet1!AD8:AG8,3,0),0) -> 0 | AS24: =+IFERROR(VLOOKUP($AS$19,Sheet1!AD8:AG8,3,0),0) -> 0 | AT24: =+IFERROR(VLOOKUP($AT$19,Sheet1!AD8:AG8,3,0),0) -> 0 | AU24: =+IFERROR(VLOOKUP($AU$19,Sheet1!AD8:AG8,3,0),0) -> 0 | AV24: =+IFERROR(VLOOKUP($AV$19,Sheet1!AD8:AG8,3,0),0) -> 0 | AW24: =+IFERROR(VLOOKUP($AW$19,Sheet1!AD8:AG8,3,0),0) -> 0 | AX24: 240 | AY24: =+IFERROR(VLOOKUP($AY$19,Sheet1!AD8:AG8,3,0),0) -> 0 | AZ24: =+IFERROR(VLOOKUP($AZ$19,Sheet1!AD8:AG8,3,0),0) -> 0 | BA24: =+IFERROR(VLOOKUP($BA$19,Sheet1!AH8:AK8,3,0),0) -> 0 | BB24: =+IFERROR(VLOOKUP($BB$19,Sheet1!AH8:AK8,3,0),0) -> 0 | BC24: =+IFERROR(VLOOKUP($BC$19,Sheet1!AH8:AK8,3,0),0) -> 0 | BD24: =+IFERROR(VLOOKUP($BD$19,Sheet1!AH8:AK8,3,0),0) -> 0 | BE24: =+IFERROR(VLOOKUP($BE$19,Sheet1!AH8:AK8,3,0),0) -> 0 | BF24: =+IFERROR(VLOOKUP($BF$19,Sheet1!AH8:AK8,3,0),0) -> 0 | BG24: 971 | BH24: =+IFERROR(VLOOKUP($BH$19,Sheet1!AH8:AK8,3,0),0) -> 0 | BI24: =+IFERROR(VLOOKUP($BI$19,Sheet1!AH8:AK8,3,0),0) -> 0 | BJ24: =+IFERROR(VLOOKUP($BJ$19,Sheet1!AH8:AK8,3,0),0) -> 0 | BK24: =+IFERROR(VLOOKUP($BK$19,Sheet1!AH8:AK8,3,0),0) -> 0 | BL24: =+IFERROR(VLOOKUP($BL$19,Sheet1!AL8:AO8,3,0),0) -> 0 | BM24: =+IFERROR(VLOOKUP($BM$19,Sheet1!AL8:AO8,3,0),0) -> 0 | BN24: =+IFERROR(VLOOKUP($BN$19,Sheet1!AL8:AO8,3,0),0) -> 0 | BO24: 740 | BP24: =+IFERROR(VLOOKUP($BP$19,Sheet1!AL8:AO8,3,0),0) -> 0 | BQ24: =+IFERROR(VLOOKUP($BQ$19,Sheet1!AL8:AO8,3,0),0) -> 0 | BR24: =+IFERROR(VLOOKUP($BR$19,Sheet1!AL8:AO8,3,0),0) -> 0 | BU24: =+IFERROR(VLOOKUP($BU$19,Sheet1!AL8:AO8,3,0),0) -> 0 | BV24: =+IFERROR(VLOOKUP($BV$19,Sheet1!AL8:AO8,3,0),0) -> 0 | BW24: =+IFERROR(VLOOKUP($BW$19,Sheet1!AL8:AO8,3,0),0) -> 0 | BX24: =+IFERROR(VLOOKUP($BX$19,Sheet1!AP8:AS8,3,0),0) -> 0 | BY24: =+IFERROR(VLOOKUP($BY$19,Sheet1!AT8:AW8,3,0),0) -> 0 | BZ24: =+IFERROR(VLOOKUP($BZ$19,Sheet1!AX8:BA8,3,0),0) -> 0 | CA24: =+IFERROR(VLOOKUP($CA$19,Sheet1!BB8:BE8,3,0),0) -> 0 | CB24: =+IFERROR(VLOOKUP($CB$19,Sheet1!BF8:BI8,3,0),0) -> 0 | CC24: =+IFERROR(VLOOKUP($CC$19,Sheet1!BJ8:BM8,3,0),0) -> 0 | CD24: =+IFERROR(VLOOKUP($CD$19,Sheet1!BN8:BQ8,3,0),0) -> 0 | CE24: 80 | CF24: =+IFERROR(VLOOKUP($CF$19,Sheet1!BV8:BY8,3,0),0) -> 0 | CG24: =Sheet1!E8 -> STEEL | CH24: SP0400123 | CI24: CORRUGATED DISPATCH STEEL DRUM 2000 X 1000 X 1200 MM | CJ24: =Sheet1!CX8 -> 500 | CK24: =16500/0.5 -> 33000 | CL24: =SUMPRODUCT($N$20:$CF$20,N24:CF24)+CK24 -> 1669697 | CM24: =Sheet1!CB8 -> 0 | CN24: =CL24*CM24 -> 0 | CO24: 0.3 | CP24: =CL24*CO24 -> 500909.1 | CQ24: 0 | CR24: =CL24*CQ24 -> 0 | CS24: =CL24+CN24+CP24+CR24 -> 2170606.1 | CT24: 0.02 | CU24: =CS24*CT24 -> 43412.122 | CV24: =Sheet1!CK8 -> 0 | CW24: =CS24*CV24 -> 0 | CX24: =Sheet1!CM8 -> 0 | CY24: =CX24*CS24 -> 0
A25: ENQ-18774-25-26 | B25: 46143 | C25: =Sheet1!C10 -> 0 | D25: 3 CORE X 120 SQ MM + 1 CORE X 120 SQ MM + 1 CORE X 95 SQ MM (AB CABLES) (Insulated | E25: =CS25+CU25+CW25+CY25 -> 1013619.6 | F25: =ROUNDUP(M43,0) -> 18750 | G25: =E25+F25 -> 1032369.6 | H25: 0.18 | I25: =G25*H25 -> 185826.53 | J25: =G25+I25 -> 1218196.1 | K25: 48 | L25: KMS | M25: =J25*K25 -> 58473414 | N25: 1296 | O25: 270 | P25: =+IFERROR(VLOOKUP($P$19,Sheet1!J10:M10,3,0),0) -> 0 | Q25: =+IFERROR(VLOOKUP($Q$19,Sheet1!J10:M10,3,0),0) -> 0 | R25: =+IFERROR(VLOOKUP($R$19,Sheet1!J10:M10,3,0),0) -> 0 | S25: =+IFERROR(VLOOKUP($S$19,Sheet1!J10:M10,3,0),0) -> 0 | T25: =+IFERROR(VLOOKUP($T$19,Sheet1!J10:M10,3,0),0) -> 0 | U25: =+IFERROR(VLOOKUP($U$19,Sheet1!J10:M10,3,0),0) -> 0 | V25: =+IFERROR(VLOOKUP($V$19,Sheet1!N10:Q10,3,0),0) -> 0 | W25: =+IFERROR(VLOOKUP($W$19,Sheet1!N10:Q10,3,0),0) -> 0 | X25: =+IFERROR(VLOOKUP($X$19,Sheet1!F10:I10,3,0),0) -> 0 | Y25: =+IFERROR(VLOOKUP($Y$19,Sheet1!F10:I10,3,0),0) -> 0 | Z25: =+IFERROR(VLOOKUP($Z$19,Sheet1!F10:I10,3,0),0) -> 0 | AA25: =+IFERROR(VLOOKUP($AA$19,Sheet1!F10:I10,3,0),0) -> 0 | AB25: =+IFERROR(VLOOKUP($AB$19,Sheet1!F10:I10,3,0),0) -> 0 | AC25: =+IFERROR(VLOOKUP($AC$19,Sheet1!F10:I10,3,0),0) -> 0 | AD25: =+IFERROR(VLOOKUP($AD$19,Sheet1!F10:I10,3,0),0) -> 0 | AE25: =+IFERROR(VLOOKUP($AE$19,Sheet1!F10:I10,3,0),0) -> 0 | AF25: =+IFERROR(VLOOKUP($AF$19,Sheet1!R10:U10,3,0),0) -> 0 | AG25: =+IFERROR(VLOOKUP($AG$19,Sheet1!R10:U10,3,0),0) -> 0 | AH25: =+IFERROR(VLOOKUP($AH$19,Sheet1!V10:Y10,3,0),0) -> 0 | AI25: 364 | AJ25: =+IFERROR(VLOOKUP($AJ$19,Sheet1!V10:Y10,3,0),0) -> 0 | AK25: =+IFERROR(VLOOKUP($AK$19,Sheet1!V10:Y10,3,0),0) -> 0 | AL25: =+IFERROR(VLOOKUP($AL$19,Sheet1!V10:Y10,3,0),0) -> 0 | AM25: =+IFERROR(VLOOKUP($AM$19,Sheet1!V10:Y10,3,0),0) -> 0 | AN25: =+IFERROR(VLOOKUP($AN$19,Sheet1!V10:Y10,3,0),0) -> 0 | AO25: =+IFERROR(VLOOKUP($AO$19,Sheet1!V10:Y10,3,0),0) -> 0 | AP25: =+IFERROR(VLOOKUP($AP$19,Sheet1!V10:Y10,3,0),0) -> 0 | AQ25: =+IFERROR(VLOOKUP($AQ$19,Sheet1!Z10:AB10,3,0),0) -> 0 | AR25: =+IFERROR(VLOOKUP($AR$19,Sheet1!AD10:AG10,3,0),0) -> 0 | AS25: =+IFERROR(VLOOKUP($AS$19,Sheet1!AD10:AG10,3,0),0) -> 0 | AT25: =+IFERROR(VLOOKUP($AT$19,Sheet1!AD10:AG10,3,0),0) -> 0 | AU25: =+IFERROR(VLOOKUP($AU$19,Sheet1!AD10:AG10,3,0),0) -> 0 | AV25: =+IFERROR(VLOOKUP($AV$19,Sheet1!AD10:AG10,3,0),0) -> 0 | AW25: =+IFERROR(VLOOKUP($AW$19,Sheet1!AD10:AG10,3,0),0) -> 0 | AX25: =+IFERROR(VLOOKUP($AX$19,Sheet1!AD10:AG10,3,0),0) -> 0 | AY25: =+IFERROR(VLOOKUP($AY$19,Sheet1!AD10:AG10,3,0),0) -> 0 | AZ25: =+IFERROR(VLOOKUP($AZ$19,Sheet1!AD10:AG10,3,0),0) -> 0 | BA25: =+IFERROR(VLOOKUP($BA$19,Sheet1!AH10:AK10,3,0),0) -> 0 | BB25: =+IFERROR(VLOOKUP($BB$19,Sheet1!AH10:AK10,3,0),0) -> 0 | BC25: =+IFERROR(VLOOKUP($BC$19,Sheet1!AH10:AK10,3,0),0) -> 0 | BD25: =+IFERROR(VLOOKUP($BD$19,Sheet1!AH10:AK10,3,0),0) -> 0 | BE25: =+IFERROR(VLOOKUP($BE$19,Sheet1!AH10:AK10,3,0),0) -> 0 | BF25: =+IFERROR(VLOOKUP($BF$19,Sheet1!AH10:AK10,3,0),0) -> 0 | BG25: =+IFERROR(VLOOKUP($BG$19,Sheet1!AH10:AK10,3,0),0) -> 0 | BH25: =+IFERROR(VLOOKUP($BH$19,Sheet1!AH10:AK10,3,0),0) -> 0 | BI25: =+IFERROR(VLOOKUP($BI$19,Sheet1!AH10:AK10,3,0),0) -> 0 | BJ25: =+IFERROR(VLOOKUP($BJ$19,Sheet1!AH10:AK10,3,0),0) -> 0 | BK25: =+IFERROR(VLOOKUP($BK$19,Sheet1!AH10:AK10,3,0),0) -> 0 | BL25: =+IFERROR(VLOOKUP($BL$19,Sheet1!AL10:AO10,3,0),0) -> 0 | BM25: =+IFERROR(VLOOKUP($BM$19,Sheet1!AL10:AO10,3,0),0) -> 0 | BN25: =+IFERROR(VLOOKUP($BN$19,Sheet1!AL10:AO10,3,0),0) -> 0 | BO25: =+IFERROR(VLOOKUP($BO$19,Sheet1!AL10:AO10,3,0),0) -> 0 | BP25: =+IFERROR(VLOOKUP($BP$19,Sheet1!AL10:AO10,3,0),0) -> 0 | BQ25: =+IFERROR(VLOOKUP($BQ$19,Sheet1!AL10:AO10,3,0),0) -> 0 | BR25: =+IFERROR(VLOOKUP($BR$19,Sheet1!AL10:AO10,3,0),0) -> 0 | BS25: 457 | BT25: =+IFERROR(VLOOKUP($BT$19,Sheet1!AL10:AO10,3,0),0) -> 0 | BU25: =+IFERROR(VLOOKUP($BU$19,Sheet1!AL10:AO10,3,0),0) -> 0 | BV25: =+IFERROR(VLOOKUP($BV$19,Sheet1!AL10:AO10,3,0),0) -> 0 | BW25: =+IFERROR(VLOOKUP($BW$19,Sheet1!AL10:AO10,3,0),0) -> 0 | BX25: =+IFERROR(VLOOKUP($BX$19,Sheet1!AP10:AS10,3,0),0) -> 0 | BY25: =+IFERROR(VLOOKUP($BY$19,Sheet1!AT10:AW10,3,0),0) -> 0 | BZ25: =+IFERROR(VLOOKUP($BZ$19,Sheet1!AX10:BA10,3,0),0) -> 0 | CA25: =+IFERROR(VLOOKUP($CA$19,Sheet1!BB10:BE10,3,0),0) -> 0 | CB25: =+IFERROR(VLOOKUP($CB$19,Sheet1!BF10:BI10,3,0),0) -> 0 | CC25: =+IFERROR(VLOOKUP($CC$19,Sheet1!BJ10:BM10,3,0),0) -> 0 | CD25: =+IFERROR(VLOOKUP($CD$19,Sheet1!BN10:BQ10,3,0),0) -> 0 | CE25: =+IFERROR(VLOOKUP($CE$19,Sheet1!BR10:BU10,3,0),0) -> 0 | CF25: =+IFERROR(VLOOKUP($CF$19,Sheet1!BV10:BY10,3,0),0) -> 0 | CG25: WOOD | CH25: MD0100070 | CI25: DRUM - 68 X 24 X 32 X 3 | CJ25: 500 | CK25: =8889/0.5 -> 17778 | CL25: =SUMPRODUCT($N$20:$CF$20,N25:CF25)+CK25 -> 764419 | CM25: =Sheet1!CB10 -> 0 | CN25: =CL25*CM25 -> 0 | CO25: 0.3 | CP25: =CL25*CO25 -> 229325.7 | CQ25: 0 | CR25: =CL25*CQ25 -> 0 | CS25: =CL25+CN25+CP25+CR25 -> 993744.7 | CT25: 0.02 | CU25: =CS25*CT25 -> 19874.894 | CV25: =Sheet1!CK10 -> 0 | CW25: =CS25*CV25 -> 0 | CX25: =Sheet1!CM10 -> 0 | CY25: =CX25*CS25 -> 0
A26: =Sheet1!A2 -> ENQ-18774-25-26 | B26: 46143 | C26: =Sheet1!C2 -> FA0700001 | D26: =Sheet1!D2 -> 1 CORE X 120 SQ. MM. AL/ARD (XLPE) | E26: =CS26+CU26+CW26+CY26 -> 329829.24 | F26: =ROUNDUP(M44,0) -> 10715 | G26: =E26+F26 -> 340544.24 | H26: =Sheet1!CR2 -> 0.18 | I26: =G26*H26 -> 61297.963 | J26: =G26+I26 -> 401842.2 | K26: 14 | L26: =Sheet1!CV2 -> KMS | M26: =J26*K26 -> 5625790.8 | N26: =+IFERROR(VLOOKUP($N$19,Sheet1!J2:L2,3,0),0) -> 324 | O26: =+IFERROR(VLOOKUP($O$19,Sheet1!J2:L2,3,0),0) -> 0 | P26: =+IFERROR(VLOOKUP($P$19,Sheet1!J2:M2,3,0),0) -> 0 | Q26: =+IFERROR(VLOOKUP($Q$19,Sheet1!J2:M2,3,0),0) -> 0 | R26: =+IFERROR(VLOOKUP($R$19,Sheet1!J2:M2,3,0),0) -> 0 | S26: =+IFERROR(VLOOKUP($S$19,Sheet1!J2:M2,3,0),0) -> 0 | T26: =+IFERROR(VLOOKUP($T$19,Sheet1!J2:M2,3,0),0) -> 0 | U26: =+IFERROR(VLOOKUP($U$19,Sheet1!J2:M2,3,0),0) -> 0 | V26: =+IFERROR(VLOOKUP($V$19,Sheet1!N2:Q2,3,0),0) -> 0 | W26: =+IFERROR(VLOOKUP($W$19,Sheet1!N2:Q2,3,0),0) -> 0 | X26: =+IFERROR(VLOOKUP($X$19,Sheet1!F2:I2,3,0),0) -> 0 | Y26: =+IFERROR(VLOOKUP($Y$19,Sheet1!F2:I2,3,0),0) -> 0 | Z26: =+IFERROR(VLOOKUP($Z$19,Sheet1!F2:I2,3,0),0) -> 0 | AA26: =+IFERROR(VLOOKUP($AA$19,Sheet1!F2:I2,3,0),0) -> 0 | AB26: =+IFERROR(VLOOKUP($AB$19,Sheet1!F2:I2,3,0),0) -> 0 | AC26: =+IFERROR(VLOOKUP($AC$19,Sheet1!F2:I2,3,0),0) -> 0 | AD26: =+IFERROR(VLOOKUP($AD$19,Sheet1!F2:I2,3,0),0) -> 0 | AE26: =+IFERROR(VLOOKUP($AE$19,Sheet1!F2:I2,3,0),0) -> 0 | AF26: =+IFERROR(VLOOKUP($AF$19,Sheet1!R2:U2,3,0),0) -> 0 | AG26: =+IFERROR(VLOOKUP($AG$19,Sheet1!R2:U2,3,0),0) -> 0 | AH26: =+IFERROR(VLOOKUP($AH$19,Sheet1!V2:Y2,3,0),0) -> 0 | AI26: =+IFERROR(VLOOKUP($AI$19,Sheet1!V2:Y2,3,0),0) -> 75 | AJ26: =+IFERROR(VLOOKUP($AJ$19,Sheet1!V2:Y2,3,0),0) -> 0 | AK26: =+IFERROR(VLOOKUP($AK$19,Sheet1!V2:Y2,3,0),0) -> 0 | AL26: =+IFERROR(VLOOKUP($AL$19,Sheet1!V2:Y2,3,0),0) -> 0 | AM26: =+IFERROR(VLOOKUP($AM$19,Sheet1!V2:Y2,3,0),0) -> 0 | AN26: =+IFERROR(VLOOKUP($AN$19,Sheet1!V2:Y2,3,0),0) -> 0 | AO26: =+IFERROR(VLOOKUP($AO$19,Sheet1!V2:Y2,3,0),0) -> 0 | AP26: =+IFERROR(VLOOKUP($AP$19,Sheet1!V2:Y2,3,0),0) -> 0 | AQ26: =+IFERROR(VLOOKUP($AQ$19,Sheet1!Z2:AB2,3,0),0) -> 0 | AR26: =+IFERROR(VLOOKUP($AR$19,Sheet1!AD2:AG2,3,0),0) -> 0 | AS26: =+IFERROR(VLOOKUP($AS$19,Sheet1!AD2:AG2,3,0),0) -> 0 | AT26: =+IFERROR(VLOOKUP($AT$19,Sheet1!AD2:AG2,3,0),0) -> 0 | AU26: =+IFERROR(VLOOKUP($AU$19,Sheet1!AD2:AG2,3,0),0) -> 0 | AV26: =+IFERROR(VLOOKUP($AV$19,Sheet1!AD2:AG2,3,0),0) -> 0 | AW26: =+IFERROR(VLOOKUP($AW$19,Sheet1!AD2:AG2,3,0),0) -> 0 | AX26: =+IFERROR(VLOOKUP($AX$19,Sheet1!AD2:AG2,3,0),0) -> 0 | AY26: =+IFERROR(VLOOKUP($AY$19,Sheet1!AD2:AG2,3,0),0) -> 0 | AZ26: =+IFERROR(VLOOKUP($AZ$19,Sheet1!AD2:AG2,3,0),0) -> 0 | BA26: =+IFERROR(VLOOKUP($BA$19,Sheet1!AH2:AK2,3,0),0) -> 0 | BB26: =+IFERROR(VLOOKUP($BB$19,Sheet1!AH2:AK2,3,0),0) -> 0 | BC26: =+IFERROR(VLOOKUP($BC$19,Sheet1!AH2:AK2,3,0),0) -> 0 | BD26: 176 | BE26: =+IFERROR(VLOOKUP($BE$19,Sheet1!AH2:AK2,3,0),0) -> 0 | BF26: =+IFERROR(VLOOKUP($BF$19,Sheet1!AH2:AK2,3,0),0) -> 0 | BG26: =+IFERROR(VLOOKUP($BG$19,Sheet1!AH2:AK2,3,0),0) -> 0 | BH26: =+IFERROR(VLOOKUP($BH$19,Sheet1!AH2:AK2,3,0),0) -> 0 | BI26: =+IFERROR(VLOOKUP($BI$19,Sheet1!AH2:AK2,3,0),0) -> 0 | BJ26: =+IFERROR(VLOOKUP($BJ$19,Sheet1!AH2:AK2,3,0),0) -> 0 | BK26: =+IFERROR(VLOOKUP($BK$19,Sheet1!AH2:AK2,3,0),0) -> 0 | BL26: =+IFERROR(VLOOKUP($BL$19,Sheet1!AL2:AO2,3,0),0) -> 0 | BM26: =+IFERROR(VLOOKUP($BM$19,Sheet1!AL2:AO2,3,0),0) -> 0 | BN26: =+IFERROR(VLOOKUP($BN$19,Sheet1!AL2:AO2,3,0),0) -> 0 | BO26: =+IFERROR(VLOOKUP($BO$19,Sheet1!AL2:AO2,3,0),0) -> 0 | BP26: =+IFERROR(VLOOKUP($BP$19,Sheet1!AL2:AO2,3,0),0) -> 0 | BQ26: =+IFERROR(VLOOKUP($BQ$19,Sheet1!AL2:AO2,3,0),0) -> 0 | BR26: =+IFERROR(VLOOKUP($BR$19,Sheet1!AL2:AO2,3,0),0) -> 0 | BT26: 175 | BU26: =+IFERROR(VLOOKUP($BU$19,Sheet1!AL2:AO2,3,0),0) -> 0 | BV26: =+IFERROR(VLOOKUP($BV$19,Sheet1!AL2:AO2,3,0),0) -> 0 | BW26: =+IFERROR(VLOOKUP($BW$19,Sheet1!AL2:AO2,3,0),0) -> 0 | BX26: =+IFERROR(VLOOKUP($BX$19,Sheet1!AP2:AS2,3,0),0) -> 0 | BY26: =+IFERROR(VLOOKUP($BY$19,Sheet1!AT2:AW2,3,0),0) -> 0 | BZ26: =+IFERROR(VLOOKUP($BZ$19,Sheet1!AX2:BA2,3,0),0) -> 0 | CA26: =+IFERROR(VLOOKUP($CA$19,Sheet1!BB2:BE2,3,0),0) -> 0 | CB26: =+IFERROR(VLOOKUP($CB$19,Sheet1!BF2:BI2,3,0),0) -> 0 | CC26: =+IFERROR(VLOOKUP($CC$19,Sheet1!BJ2:BM2,3,0),0) -> 0 | CD26: =+IFERROR(VLOOKUP($CD$19,Sheet1!BN2:BQ2,3,0),0) -> 0 | CE26: 15 | CF26: =+IFERROR(VLOOKUP($CF$19,Sheet1!BV2:BY2,3,0),0) -> 0 | CG26: =Sheet1!E2 -> STEEL | CH26: MD0200017 | CI26: STEEL DRUM 42" X 18 X 23 | CJ26: 500 | CK26: =3025/0.5 -> 6050 | CL26: =SUMPRODUCT($N$20:$CF$20,N26:CF26)+CK26 -> 248740 | CM26: =Sheet1!CB2 -> 0 | CN26: =CL26*CM26 -> 0 | CO26: 0.3 | CP26: =CL26*CO26 -> 74622 | CQ26: 0 | CR26: =CL26*CQ26 -> 0 | CS26: =CL26+CN26+CP26+CR26 -> 323362 | CT26: 0.02 | CU26: =CS26*CT26 -> 6467.24 | CV26: =Sheet1!CK2 -> 0 | CW26: =CS26*CV26 -> 0 | CX26: =Sheet1!CM2 -> 0 | CY26: =CX26*CS26 -> 0
A27: =Sheet1!A3 -> ENQ-18774-25-26 | B27: 46143 | C27: FA0600003 | D27: 1 CORE X 120 SQ. MM. ALU/UNARD (XLPE) | E27: =CS27+CU27+CW27+CY27 -> 219442.39 | F27: =ROUNDUP(M45,0) -> 7500 | G27: =E27+F27 -> 226942.39 | H27: =Sheet1!CR3 -> 0.18 | I27: =G27*H27 -> 40849.631 | J27: =G27+I27 -> 267792.02 | K27: 10 | L27: =Sheet1!CV3 -> KMS | M27: =J27*K27 -> 2677920.2 | N27: =+IFERROR(VLOOKUP($N$19,Sheet1!J3:L3,3,0),0) -> 324 | O27: =+IFERROR(VLOOKUP($O$19,Sheet1!J3:L3,3,0),0) -> 0 | P27: =+IFERROR(VLOOKUP($P$19,Sheet1!J3:M3,3,0),0) -> 0 | Q27: =+IFERROR(VLOOKUP($Q$19,Sheet1!J3:M3,3,0),0) -> 0 | R27: =+IFERROR(VLOOKUP($R$19,Sheet1!J3:M3,3,0),0) -> 0 | S27: =+IFERROR(VLOOKUP($S$19,Sheet1!J3:M3,3,0),0) -> 0 | T27: =+IFERROR(VLOOKUP($T$19,Sheet1!J3:M3,3,0),0) -> 0 | U27: =+IFERROR(VLOOKUP($U$19,Sheet1!J3:M3,3,0),0) -> 0 | V27: =+IFERROR(VLOOKUP($V$19,Sheet1!N3:Q3,3,0),0) -> 0 | W27: =+IFERROR(VLOOKUP($W$19,Sheet1!N3:Q3,3,0),0) -> 0 | X27: =+IFERROR(VLOOKUP($X$19,Sheet1!F3:I3,3,0),0) -> 0 | Y27: =+IFERROR(VLOOKUP($Y$19,Sheet1!F3:I3,3,0),0) -> 0 | Z27: =+IFERROR(VLOOKUP($Z$19,Sheet1!F3:I3,3,0),0) -> 0 | AA27: =+IFERROR(VLOOKUP($AA$19,Sheet1!F3:I3,3,0),0) -> 0 | AB27: =+IFERROR(VLOOKUP($AB$19,Sheet1!F3:I3,3,0),0) -> 0 | AC27: =+IFERROR(VLOOKUP($AC$19,Sheet1!F3:I3,3,0),0) -> 0 | AD27: =+IFERROR(VLOOKUP($AD$19,Sheet1!F3:I3,3,0),0) -> 0 | AE27: =+IFERROR(VLOOKUP($AE$19,Sheet1!F3:I3,3,0),0) -> 0 | AF27: =+IFERROR(VLOOKUP($AF$19,Sheet1!R3:U3,3,0),0) -> 0 | AG27: =+IFERROR(VLOOKUP($AG$19,Sheet1!R3:U3,3,0),0) -> 0 | AH27: =+IFERROR(VLOOKUP($AH$19,Sheet1!V3:Y3,3,0),0) -> 0 | AI27: 60 | AJ27: =+IFERROR(VLOOKUP($AJ$19,Sheet1!V3:Y3,3,0),0) -> 0 | AK27: =+IFERROR(VLOOKUP($AK$19,Sheet1!V3:Y3,3,0),0) -> 0 | AL27: =+IFERROR(VLOOKUP($AL$19,Sheet1!V3:Y3,3,0),0) -> 0 | AM27: =+IFERROR(VLOOKUP($AM$19,Sheet1!V3:Y3,3,0),0) -> 0 | AN27: =+IFERROR(VLOOKUP($AN$19,Sheet1!V3:Y3,3,0),0) -> 0 | AO27: =+IFERROR(VLOOKUP($AO$19,Sheet1!V3:Y3,3,0),0) -> 0 | AP27: =+IFERROR(VLOOKUP($AP$19,Sheet1!V3:Y3,3,0),0) -> 0 | AQ27: =+IFERROR(VLOOKUP($AQ$19,Sheet1!Z3:AB3,3,0),0) -> 0 | AR27: =+IFERROR(VLOOKUP($AR$19,Sheet1!AD3:AG3,3,0),0) -> 0 | AS27: =+IFERROR(VLOOKUP($AS$19,Sheet1!AD3:AG3,3,0),0) -> 0 | AT27: =+IFERROR(VLOOKUP($AT$19,Sheet1!AD3:AG3,3,0),0) -> 0 | AU27: =+IFERROR(VLOOKUP($AU$19,Sheet1!AD3:AG3,3,0),0) -> 0 | AV27: =+IFERROR(VLOOKUP($AV$19,Sheet1!AD3:AG3,3,0),0) -> 0 | AW27: =+IFERROR(VLOOKUP($AW$19,Sheet1!AD3:AG3,3,0),0) -> 0 | AX27: =+IFERROR(VLOOKUP($AX$19,Sheet1!AD3:AG3,3,0),0) -> 0 | AY27: =+IFERROR(VLOOKUP($AY$19,Sheet1!AD3:AG3,3,0),0) -> 0 | AZ27: =+IFERROR(VLOOKUP($AZ$19,Sheet1!AD3:AG3,3,0),0) -> 0 | BA27: =+IFERROR(VLOOKUP($BA$19,Sheet1!AH3:AK3,3,0),0) -> 0 | BB27: =+IFERROR(VLOOKUP($BB$19,Sheet1!AH3:AK3,3,0),0) -> 0 | BC27: =+IFERROR(VLOOKUP($BC$19,Sheet1!AH3:AK3,3,0),0) -> 0 | BE27: =+IFERROR(VLOOKUP($BE$19,Sheet1!AH3:AK3,3,0),0) -> 0 | BF27: =+IFERROR(VLOOKUP($BF$19,Sheet1!AH3:AK3,3,0),0) -> 0 | BG27: =+IFERROR(VLOOKUP($BG$19,Sheet1!AH3:AK3,3,0),0) -> 0 | BH27: =+IFERROR(VLOOKUP($BH$19,Sheet1!AH3:AK3,3,0),0) -> 0 | BI27: =+IFERROR(VLOOKUP($BI$19,Sheet1!AH3:AK3,3,0),0) -> 0 | BJ27: =+IFERROR(VLOOKUP($BJ$19,Sheet1!AH3:AK3,3,0),0) -> 0 | BK27: =+IFERROR(VLOOKUP($BK$19,Sheet1!AH3:AK3,3,0),0) -> 0 | BL27: =+IFERROR(VLOOKUP($BL$19,Sheet1!AL3:AO3,3,0),0) -> 0 | BM27: =+IFERROR(VLOOKUP($BM$19,Sheet1!AL3:AO3,3,0),0) -> 0 | BN27: =+IFERROR(VLOOKUP($BN$19,Sheet1!AL3:AO3,3,0),0) -> 0 | BO27: =+IFERROR(VLOOKUP($BO$19,Sheet1!AL3:AO3,3,0),0) -> 0 | BP27: =+IFERROR(VLOOKUP($BP$19,Sheet1!AL3:AO3,3,0),0) -> 0 | BQ27: =+IFERROR(VLOOKUP($BQ$19,Sheet1!AL3:AO3,3,0),0) -> 0 | BR27: =+IFERROR(VLOOKUP($BR$19,Sheet1!AL3:AO3,3,0),0) -> 0 | BT27: 170 | BU27: =+IFERROR(VLOOKUP($BU$19,Sheet1!AL3:AO3,3,0),0) -> 0 | BV27: =+IFERROR(VLOOKUP($BV$19,Sheet1!AL3:AO3,3,0),0) -> 0 | BW27: =+IFERROR(VLOOKUP($BW$19,Sheet1!AL3:AO3,3,0),0) -> 0 | BX27: =+IFERROR(VLOOKUP($BX$19,Sheet1!AP3:AS3,3,0),0) -> 0 | BY27: =+IFERROR(VLOOKUP($BY$19,Sheet1!AT3:AW3,3,0),0) -> 0 | BZ27: =+IFERROR(VLOOKUP($BZ$19,Sheet1!AX3:BA3,3,0),0) -> 0 | CA27: =+IFERROR(VLOOKUP($CA$19,Sheet1!BB3:BE3,3,0),0) -> 0 | CB27: =+IFERROR(VLOOKUP($CB$19,Sheet1!BF3:BI3,3,0),0) -> 0 | CC27: =+IFERROR(VLOOKUP($CC$19,Sheet1!BJ3:BM3,3,0),0) -> 0 | CD27: =+IFERROR(VLOOKUP($CD$19,Sheet1!BN3:BQ3,3,0),0) -> 0 | CE27: =+IFERROR(VLOOKUP($CE$19,Sheet1!BR3:BU3,3,0),0) -> 0 | CF27: =+IFERROR(VLOOKUP($CF$19,Sheet1!BV3:BY3,3,0),0) -> 0 | CG27: WOOD | CH27: MD0100066 | CI27: DRUM - 40 X 15 X 23 X 2 | CJ27: =Sheet1!CX3 -> 500 | CK27: =2200/0.5 -> 4400 | CL27: =SUMPRODUCT($N$20:$CF$20,N27:CF27)+CK27 -> 165492 | CM27: =Sheet1!CB3 -> 0 | CN27: =CL27*CM27 -> 0 | CO27: 0.3 | CP27: =CL27*CO27 -> 49647.6 | CQ27: 0 | CR27: =CL27*CQ27 -> 0 | CS27: =CL27+CN27+CP27+CR27 -> 215139.6 | CT27: 0.02 | CU27: =CS27*CT27 -> 4302.792 | CV27: =Sheet1!CK3 -> 0 | CW27: =CS27*CV27 -> 0 | CX27: =Sheet1!CM3 -> 0 | CY27: =CX27*CS27 -> 0
A28: =Sheet1!A5 -> ENQ-18774-25-26 | B28: 46143 | C28: =Sheet1!C5 -> FA0700008 | D28: =Sheet1!D5 -> 1 CORE X 300 SQ. MM. AL/ARD. (XLPE) | E28: =CS28+CU28+CW28+CY28 -> 683481.4 | F28: =ROUNDUP(M46,0) -> 12500 | G28: =E28+F28 -> 695981.4 | H28: =Sheet1!CR5 -> 0.18 | I28: =G28*H28 -> 125276.65 | J28: =G28+I28 -> 821258.05 | K28: =Sheet1!CU5 -> 12 | L28: =Sheet1!CV5 -> KMS | M28: =J28*K28 -> 9855096.6 | N28: =+IFERROR(VLOOKUP($N$19,Sheet1!J5:L5,3,0),0) -> 810 | O28: =+IFERROR(VLOOKUP($O$19,Sheet1!J5:L5,3,0),0) -> 0 | P28: =+IFERROR(VLOOKUP($P$19,Sheet1!J5:M5,3,0),0) -> 0 | Q28: =+IFERROR(VLOOKUP($Q$19,Sheet1!J5:M5,3,0),0) -> 0 | R28: =+IFERROR(VLOOKUP($R$19,Sheet1!J5:M5,3,0),0) -> 0 | S28: =+IFERROR(VLOOKUP($S$19,Sheet1!J5:M5,3,0),0) -> 0 | T28: =+IFERROR(VLOOKUP($T$19,Sheet1!J5:M5,3,0),0) -> 0 | U28: =+IFERROR(VLOOKUP($U$19,Sheet1!J5:M5,3,0),0) -> 0 | V28: =+IFERROR(VLOOKUP($V$19,Sheet1!N5:Q5,3,0),0) -> 0 | W28: =+IFERROR(VLOOKUP($W$19,Sheet1!N5:Q5,3,0),0) -> 0 | X28: =+IFERROR(VLOOKUP($X$19,Sheet1!F5:I5,3,0),0) -> 0 | Y28: =+IFERROR(VLOOKUP($Y$19,Sheet1!F5:I5,3,0),0) -> 0 | Z28: =+IFERROR(VLOOKUP($Z$19,Sheet1!F5:I5,3,0),0) -> 0 | AA28: =+IFERROR(VLOOKUP($AA$19,Sheet1!F5:I5,3,0),0) -> 0 | AB28: =+IFERROR(VLOOKUP($AB$19,Sheet1!F5:I5,3,0),0) -> 0 | AC28: =+IFERROR(VLOOKUP($AC$19,Sheet1!F5:I5,3,0),0) -> 0 | AD28: =+IFERROR(VLOOKUP($AD$19,Sheet1!F5:I5,3,0),0) -> 0 | AE28: =+IFERROR(VLOOKUP($AE$19,Sheet1!F5:I5,3,0),0) -> 0 | AF28: =+IFERROR(VLOOKUP($AF$19,Sheet1!R5:U5,3,0),0) -> 0 | AG28: =+IFERROR(VLOOKUP($AG$19,Sheet1!R5:U5,3,0),0) -> 0 | AH28: =+IFERROR(VLOOKUP($AH$19,Sheet1!V5:Y5,3,0),0) -> 0 | AI28: 158 | AJ28: =+IFERROR(VLOOKUP($AJ$19,Sheet1!V5:Y5,3,0),0) -> 0 | AK28: =+IFERROR(VLOOKUP($AK$19,Sheet1!V5:Y5,3,0),0) -> 0 | AL28: =+IFERROR(VLOOKUP($AL$19,Sheet1!V5:Y5,3,0),0) -> 0 | AM28: =+IFERROR(VLOOKUP($AM$19,Sheet1!V5:Y5,3,0),0) -> 0 | AN28: =+IFERROR(VLOOKUP($AN$19,Sheet1!V5:Y5,3,0),0) -> 0 | AO28: =+IFERROR(VLOOKUP($AO$19,Sheet1!V5:Y5,3,0),0) -> 0 | AP28: =+IFERROR(VLOOKUP($AP$19,Sheet1!V5:Y5,3,0),0) -> 0 | AQ28: =+IFERROR(VLOOKUP($AQ$19,Sheet1!Z5:AB5,3,0),0) -> 0 | AR28: =+IFERROR(VLOOKUP($AR$19,Sheet1!AD5:AG5,3,0),0) -> 0 | AS28: =+IFERROR(VLOOKUP($AS$19,Sheet1!AD5:AG5,3,0),0) -> 0 | AT28: =+IFERROR(VLOOKUP($AT$19,Sheet1!AD5:AG5,3,0),0) -> 0 | AU28: =+IFERROR(VLOOKUP($AU$19,Sheet1!AD5:AG5,3,0),0) -> 0 | AV28: =+IFERROR(VLOOKUP($AV$19,Sheet1!AD5:AG5,3,0),0) -> 0 | AW28: =+IFERROR(VLOOKUP($AW$19,Sheet1!AD5:AG5,3,0),0) -> 0 | AX28: =+IFERROR(VLOOKUP($AX$19,Sheet1!AD5:AG5,3,0),0) -> 0 | AY28: =+IFERROR(VLOOKUP($AY$19,Sheet1!AD5:AG5,3,0),0) -> 0 | AZ28: =+IFERROR(VLOOKUP($AZ$19,Sheet1!AD5:AG5,3,0),0) -> 0 | BA28: =+IFERROR(VLOOKUP($BA$19,Sheet1!AH5:AK5,3,0),0) -> 0 | BB28: =+IFERROR(VLOOKUP($BB$19,Sheet1!AH5:AK5,3,0),0) -> 0 | BC28: =+IFERROR(VLOOKUP($BC$19,Sheet1!AH5:AK5,3,0),0) -> 0 | BD28: 264 | BE28: =+IFERROR(VLOOKUP($BE$19,Sheet1!AH5:AK5,3,0),0) -> 0 | BF28: =+IFERROR(VLOOKUP($BF$19,Sheet1!AH5:AK5,3,0),0) -> 0 | BG28: =+IFERROR(VLOOKUP($BG$19,Sheet1!AH5:AK5,3,0),0) -> 0 | BH28: =+IFERROR(VLOOKUP($BH$19,Sheet1!AH5:AK5,3,0),0) -> 0 | BI28: =+IFERROR(VLOOKUP($BI$19,Sheet1!AH5:AK5,3,0),0) -> 0 | BJ28: =+IFERROR(VLOOKUP($BJ$19,Sheet1!AH5:AK5,3,0),0) -> 0 | BK28: =+IFERROR(VLOOKUP($BK$19,Sheet1!AH5:AK5,3,0),0) -> 0 | BL28: =+IFERROR(VLOOKUP($BL$19,Sheet1!AL5:AO5,3,0),0) -> 0 | BM28: =+IFERROR(VLOOKUP($BM$19,Sheet1!AL5:AO5,3,0),0) -> 0 | BN28: =+IFERROR(VLOOKUP($BN$19,Sheet1!AL5:AO5,3,0),0) -> 0 | BO28: =+IFERROR(VLOOKUP($BO$19,Sheet1!AL5:AO5,3,0),0) -> 0 | BP28: =+IFERROR(VLOOKUP($BP$19,Sheet1!AL5:AO5,3,0),0) -> 0 | BQ28: =+IFERROR(VLOOKUP($BQ$19,Sheet1!AL5:AO5,3,0),0) -> 0 | BR28: =+IFERROR(VLOOKUP($BR$19,Sheet1!AL5:AO5,3,0),0) -> 0 | BT28: 265 | BU28: =+IFERROR(VLOOKUP($BU$19,Sheet1!AL5:AO5,3,0),0) -> 0 | BV28: =+IFERROR(VLOOKUP($BV$19,Sheet1!AL5:AO5,3,0),0) -> 0 | BW28: =+IFERROR(VLOOKUP($BW$19,Sheet1!AL5:AO5,3,0),0) -> 0 | BX28: =+IFERROR(VLOOKUP($BX$19,Sheet1!AP5:AS5,3,0),0) -> 0 | BY28: =+IFERROR(VLOOKUP($BY$19,Sheet1!AT5:AW5,3,0),0) -> 0 | BZ28: =+IFERROR(VLOOKUP($BZ$19,Sheet1!AX5:BA5,3,0),0) -> 0 | CA28: =+IFERROR(VLOOKUP($CA$19,Sheet1!BB5:BE5,3,0),0) -> 0 | CB28: =+IFERROR(VLOOKUP($CB$19,Sheet1!BF5:BI5,3,0),0) -> 0 | CC28: =+IFERROR(VLOOKUP($CC$19,Sheet1!BJ5:BM5,3,0),0) -> 0 | CD28: =+IFERROR(VLOOKUP($CD$19,Sheet1!BN5:BQ5,3,0),0) -> 0 | CE28: 21 | CF28: =+IFERROR(VLOOKUP($CF$19,Sheet1!BV5:BY5,3,0),0) -> 0 | CG28: =Sheet1!E5 -> STEEL | CH28: MD0200018 | CI28: STEEL DRUM - 48" X 24 X 38 | CJ28: =Sheet1!CX5 -> 500 | CK28: =4675/0.5 -> 9350 | CL28: =SUMPRODUCT($N$20:$CF$20,N28:CF28)+CK28 -> 515446 | CM28: =Sheet1!CB5 -> 0 | CN28: =CL28*CM28 -> 0 | CO28: 0.3 | CP28: =CL28*CO28 -> 154633.8 | CQ28: 0 | CR28: =CL28*CQ28 -> 0 | CS28: =CL28+CN28+CP28+CR28 -> 670079.8 | CT28: 0.02 | CU28: =CS28*CT28 -> 13401.596 | CV28: =Sheet1!CK5 -> 0 | CW28: =CS28*CV28 -> 0 | CX28: =Sheet1!CM5 -> 0 | CY28: =CX28*CS28 -> 0
